Workbook

Sheet Cover
B2: SaaS company — financial model
B3: 5-year financial model · monthly detail · Low / Base / High scenarios · US dollars
B5: Active scenario | D5: =Dashboard!C4&" (change on the Dashboard, cell B4)" -> Base (change on the Dashboard, cell B4)
B6: Model checks | D6: =Checks!B22 -> PASS
B7: Prepared | D7: 20 October 2026
B9: Contents
C10: PRESENTATION
B11: 1 | C11: =HYPERLINK("#'Dashboard'!A1","Dashboard") -> Dashboard | D11: Scenario switch, key numbers, core financials, 4 charts
B12: 2 | C12: =HYPERLINK("#'Summary'!A1","Summary") -> Summary | D12: Income statement, cash flow, balance sheet — 5 years and any year by month
B13: 3 | C13: =HYPERLINK("#'Scenarios'!A1","Scenarios") -> Scenarios | D13: Low / Base / High side by side: drivers, outputs, charts
B14: 4 | C14: =HYPERLINK("#'Break-even'!A1","Break-even") -> Break-even | D14: Startup costs, funding need, break-even timing and revenue
B15: 5 | C15: =HYPERLINK("#'Valuation'!A1","Valuation") -> Valuation | D15: Free cash flow, DCF (perpetual growth and exit multiple), WACC × growth sensitivity
B16: 6 | C16: =HYPERLINK("#'Sources & Uses'!A1","Sources & Uses") -> Sources & Uses | D16: Funding structure, sources and uses of cash for the first months
B17: 7 | C17: =HYPERLINK("#'KPIs'!A1","KPIs") -> KPIs | D17: Industry metrics, financial ratios, DuPont analysis
C18: INPUTS
B19: 8 | C19: =HYPERLINK("#'Inputs'!A1","Inputs") -> Inputs | D19: Every assumption, Low / Base / High, with units and comments
C20: STATEMENTS
B21: 9 | C21: =HYPERLINK("#'P&L'!A1","P&L") -> P&L | D21: Annual profit & loss
B22: 10 | C22: =HYPERLINK("#'Cash Flow'!A1","Cash Flow") -> Cash Flow | D22: Annual cash flow statement
B23: 11 | C23: =HYPERLINK("#'Balance Sheet'!A1","Balance Sheet") -> Balance Sheet | D23: Balance sheet at year end
C24: CALCULATIONS
B25: 12 | C25: =HYPERLINK("#'Monthly'!A1","Monthly") -> Monthly | D25: Month-by-month engine of the model
B26: 13 | C26: =HYPERLINK("#'Headcount'!A1","Headcount") -> Headcount | D26: Team and payroll by month
C27: CONTROL
B28: 14 | C28: =HYPERLINK("#'Checks'!A1","Checks") -> Checks | D28: Live integrity checks; overall verdict
B30: How to read this file
C31: 1,000 | D31: Input you can change (yellow cell, blue figure) — on Inputs, plus the two view switches
C32: 1,000 | D32: Formula — calculated, do not overwrite
C33: 1,000 | D33: Link to another sheet
C34: 1,000 | D34: Active value the model uses
B36: Prototype of workbook standard v1 (internal review). Numbers come from the production engine; the Scenarios sheet's Low / Base / High columns are a build-time snapshot.

Sheet Dashboard
A1: Dashboard | W1: =HYPERLINK("#'Cover'!A1","◂ Contents") -> ◂ Contents
A2: SaaS company — financial model
A4: Active scenario | B4: 2 | C4: =CHOOSE(B4,"Low","Base","High") -> Base | D4: 1 = Low · 2 = Base · 3 = High — every sheet follows this cell | S4: Model checks | T4: =Checks!B22 -> PASS
A6: REVENUE · YEAR 5 | C6: EBITDA MARGIN · YEAR 5 | H6: NET INCOME · YEAR 5 | L6: LOWEST CASH BALANCE | P6: FUNDING REQUIRED | T6: ENTERPRISE VALUE (DCF)
A7: ='P&L'!F5 -> 26732395 | C7: ='P&L'!F16 -> 0.25044286 | H7: ='P&L'!F22 -> 5289000.5 | L7: =MIN(Monthly!$C$76:$BJ$76) -> 1760226.5 | P7: ='Break-even'!B12 -> 1145773.5 | T7: =Valuation!B30 -> 40195041
A8: =IF('P&L'!B5>0,"CAGR "&TEXT(('P&L'!F5/'P&L'!B5)^(1/4)-1,"0%"),"") -> CAGR 27% | C8: ="EBITDA "&TEXT('P&L'!F15/1000000,"$0.0")&"M" -> EBITDA $6.7M | H8: ="Net margin "&TEXT('P&L'!F23,"0%") -> Net margin 20% | L8: ="in month "&MATCH(MIN(Monthly!$C$76:$BJ$76),Monthly!$C$76:$BJ$76,0) -> in month 1 | P8: =IF('Break-even'!B17>=0,"Covered by funding raised","Shortfall "&TEXT(-'Break-even'!B17/1000000,"$0.0")&"M") -> Shortfall $0.1M | T8: ="Average of 2 methods" -> Average of 2 methods
A10: Core financials ($'000) — active scenario
B11: ='P&L'!B4 -> Year 1 | C11: ='P&L'!C4 -> Year 2 | D11: ='P&L'!D4 -> Year 3 | E11: ='P&L'!E4 -> Year 4 | F11: ='P&L'!F4 -> Year 5
A12: Revenue | B12: ='P&L'!B5 -> 10216766 | C12: ='P&L'!C5 -> 12946280 | D12: ='P&L'!D5 -> 16448495 | E12: ='P&L'!E5 -> 20947000 | F12: ='P&L'!F5 -> 26732395
A13: Gross profit | B13: ='P&L'!B7 -> 9115572.1 | C13: ='P&L'!C7 -> 11555505 | D13: ='P&L'!D7 -> 14686438 | E13: ='P&L'!E7 -> 18708530 | F13: ='P&L'!F7 -> 23881957
A14: Gross margin | B14: ='P&L'!B8 -> 0.89221699 | C14: ='P&L'!C8 -> 0.8925734 | D14: ='P&L'!D8 -> 0.89287426 | E14: ='P&L'!E8 -> 0.89313648 | F14: ='P&L'!F8 -> 0.89337139
A15: Operating expenses | B15: ='P&L'!B14 -> -7622400 | C15: ='P&L'!C14 -> -9305892 | D15: ='P&L'!D14 -> -11392489 | E15: ='P&L'!E14 -> -13979315 | F15: ='P&L'!F14 -> -17187019
A16: EBITDA | B16: ='P&L'!B15 -> 1493172.1 | C16: ='P&L'!C15 -> 2249612.9 | D16: ='P&L'!D15 -> 3293948.5 | E16: ='P&L'!E15 -> 4729214.2 | F16: ='P&L'!F15 -> 6694937.4
A17: EBITDA margin | B17: ='P&L'!B16 -> 0.14614919 | C17: ='P&L'!C16 -> 0.1737652 | D17: ='P&L'!D16 -> 0.20025835 | E17: ='P&L'!E16 -> 0.22577048 | F17: ='P&L'!F16 -> 0.25044286
A18: Net income | B18: ='P&L'!B22 -> 1140105.9 | C18: ='P&L'!C22 -> 1737694.2 | D18: ='P&L'!D22 -> 2562719.3 | E18: ='P&L'!E22 -> 3736079.2 | F18: ='P&L'!F22 -> 5289000.5
A19: Net margin | B19: ='P&L'!B23 -> 0.11159167 | C19: ='P&L'!C23 -> 0.13422344 | D19: ='P&L'!D23 -> 0.15580266 | E19: ='P&L'!E23 -> 0.17835868 | F19: ='P&L'!F23 -> 0.19784986
A20: Operating cash flow | B20: ='Cash Flow'!B11 -> 2273134.7 | C20: ='Cash Flow'!C11 -> 2078342.8 | D20: ='Cash Flow'!D11 -> 2985771.8 | E20: ='Cash Flow'!E11 -> 4215445.8 | F20: ='Cash Flow'!F11 -> 5905773.3
A21: Investing cash flow | B21: ='Cash Flow'!B12 -> -150000 | C21: ='Cash Flow'!C12 -> 0 | D21: ='Cash Flow'!D12 -> 0 | E21: ='Cash Flow'!E12 -> 0 | F21: ='Cash Flow'!F12 -> 0
A22: Financing cash flow | B22: ='Cash Flow'!B16 -> 1000000 | C22: ='Cash Flow'!C16 -> 0 | D22: ='Cash Flow'!D16 -> 0 | E22: ='Cash Flow'!E16 -> 0 | F22: ='Cash Flow'!F16 -> 0
A23: Net change in cash | B23: ='Cash Flow'!B17 -> 3123134.7 | C23: ='Cash Flow'!C17 -> 2078342.8 | D23: ='Cash Flow'!D17 -> 2985771.8 | E23: ='Cash Flow'!E17 -> 4215445.8 | F23: ='Cash Flow'!F17 -> 5905773.3
A24: Year-end cash | B24: ='Balance Sheet'!B5 -> 3123134.7 | C24: ='Balance Sheet'!C5 -> 5201477.5 | D24: ='Balance Sheet'!D5 -> 8187249.2 | E24: ='Balance Sheet'!E5 -> 12402695 | F24: ='Balance Sheet'!F5 -> 18308468
A26: SaaS metrics
B27: ='P&L'!B4 -> Year 1 | C27: ='P&L'!C4 -> Year 2 | D27: ='P&L'!D4 -> Year 3 | E27: ='P&L'!E4 -> Year 4 | F27: ='P&L'!F4 -> Year 5
A28: Paying customers (year end) | B28: =KPIs!B27 -> 3608.1828 | C28: =KPIs!C27 -> 4380.8763 | D28: =KPIs!D27 -> 5357.1408 | E28: =KPIs!E27 -> 6586.8077 | F28: =KPIs!F27 -> 8133.3379
A29: ARR (year-end MRR × 12) | B29: =KPIs!B31 -> 11385918 | C29: =KPIs!C31 -> 14445582 | D29: =KPIs!D31 -> 18373030 | E29: =KPIs!E31 -> 23420246 | F29: =KPIs!F31 -> 29914934
A30: LTV ÷ CAC | B30: =KPIs!B40 -> 26.069112 | C30: =KPIs!C40 -> 28.160132 | D30: =KPIs!D40 -> 30.323023 | E30: =KPIs!E40 -> 32.59655 | F30: =KPIs!F40 -> 35.017261
A31: Team (FTE, year end) | B31: =INDEX(Headcount!$C$12:$BJ$12,12) -> 48 | C31: =INDEX(Headcount!$C$12:$BJ$12,24) -> 57.3 | D31: =INDEX(Headcount!$C$12:$BJ$12,36) -> 68.415 | E31: =INDEX(Headcount!$C$12:$BJ$12,48) -> 81.70125 | F31: =INDEX(Headcount!$C$12:$BJ$12,60) -> 97.585238
A33: Funding & valuation ($'000) — active scenario
A34: Equity raised | F34: =Inputs!E46 -> 1000000
A35: Loan drawn | F35: =Inputs!E47 -> 0
A36: Funding required (incl. cash buffer) | F36: ='Break-even'!B12 -> 1145773.5
A37: Funding surplus / (shortfall) | F37: ='Break-even'!B17 -> -145773.53
A38: ="Lowest cash balance (month "&MATCH(MIN(Monthly!$C$76:$BJ$76),Monthly!$C$76:$BJ$76,0)&")" -> Lowest cash balance (month 1) | F38: =MIN(Monthly!$C$76:$BJ$76) -> 1760226.5
A39: First month with positive EBITDA | F39: ='Break-even'!B21 -> 1
A40: Cash invested paid back | F40: =IF(ISNUMBER('Break-even'!B23),"Month "&'Break-even'!B23,'Break-even'!B23) -> No investment to pay back
A41: Enterprise value — perpetual growth | F41: =Valuation!B27 -> 45888961
A42: Enterprise value — exit multiple | F42: =Valuation!C27 -> 34501121
A43: Enterprise value — average | F43: =Valuation!B30 -> 40195041

Sheet Summary
A1: Financial statements summary | U1: =HYPERLINK("#'Cover'!A1","◂ Contents") -> ◂ Contents
A2: SaaS company — financial model | P2: Select detailed year: | R2: 1
A5: Income statement ($'000) — 5 years | H5: ="Income statement ($'000) — Year "&$R$2&", by month" -> Income statement ($'000) — Year 1, by month
B6: ='P&L'!B4 -> Year 1 | C6: ='P&L'!C4 -> Year 2 | D6: ='P&L'!D4 -> Year 3 | E6: ='P&L'!E4 -> Year 4 | F6: ='P&L'!F4 -> Year 5 | H6: =INDEX(Monthly!$C$3:$BJ$3,($R$2-1)*12+1) -> M1 | I6: =INDEX(Monthly!$C$3:$BJ$3,($R$2-1)*12+2) -> M2 | J6: =INDEX(Monthly!$C$3:$BJ$3,($R$2-1)*12+3) -> M3 | K6: =INDEX(Monthly!$C$3:$BJ$3,($R$2-1)*12+4) -> M4 | L6: =INDEX(Monthly!$C$3:$BJ$3,($R$2-1)*12+5) -> M5 | M6: =INDEX(Monthly!$C$3:$BJ$3,($R$2-1)*12+6) -> M6 | N6: =INDEX(Monthly!$C$3:$BJ$3,($R$2-1)*12+7) -> M7 | O6: =INDEX(Monthly!$C$3:$BJ$3,($R$2-1)*12+8) -> M8 | P6: =INDEX(Monthly!$C$3:$BJ$3,($R$2-1)*12+9) -> M9 | Q6: =INDEX(Monthly!$C$3:$BJ$3,($R$2-1)*12+10) -> M10 | R6: =INDEX(Monthly!$C$3:$BJ$3,($R$2-1)*12+11) -> M11 | S6: =INDEX(Monthly!$C$3:$BJ$3,($R$2-1)*12+12) -> M12
A7: Revenue | B7: ='P&L'!B5 -> 10216766 | C7: ='P&L'!C5 -> 12946280 | D7: ='P&L'!D5 -> 16448495 | E7: ='P&L'!E5 -> 20947000 | F7: ='P&L'!F5 -> 26732395 | H7: =INDEX(Monthly!$C$24:$BJ$24,($R$2-1)*12+1) -> 758750 | I7: =INDEX(Monthly!$C$24:$BJ$24,($R$2-1)*12+2) -> 776162.5 | J7: =INDEX(Monthly!$C$24:$BJ$24,($R$2-1)*12+3) -> 793400.88 | K7: =INDEX(Monthly!$C$24:$BJ$24,($R$2-1)*12+4) -> 810466.87 | L7: =INDEX(Monthly!$C$24:$BJ$24,($R$2-1)*12+5) -> 827362.2 | M7: =INDEX(Monthly!$C$24:$BJ$24,($R$2-1)*12+6) -> 844088.58 | N7: =INDEX(Monthly!$C$24:$BJ$24,($R$2-1)*12+7) -> 860647.69 | O7: =INDEX(Monthly!$C$24:$BJ$24,($R$2-1)*12+8) -> 877041.21 | P7: =INDEX(Monthly!$C$24:$BJ$24,($R$2-1)*12+9) -> 893270.8 | Q7: =INDEX(Monthly!$C$24:$BJ$24,($R$2-1)*12+10) -> 909338.09 | R7: =INDEX(Monthly!$C$24:$BJ$24,($R$2-1)*12+11) -> 925244.71 | S7: =INDEX(Monthly!$C$24:$BJ$24,($R$2-1)*12+12) -> 940992.26
A8: Cost of revenue | B8: ='P&L'!B6 -> -1101193.7 | C8: ='P&L'!C6 -> -1390774.9 | D8: ='P&L'!D6 -> -1762057.1 | E8: ='P&L'!E6 -> -2238470.1 | F8: ='P&L'!F6 -> -2850438 | H8: =INDEX(Monthly!$C$25:$BJ$25,($R$2-1)*12+1) -> -81930 | I8: =INDEX(Monthly!$C$25:$BJ$25,($R$2-1)*12+2) -> -83780.425 | J8: =INDEX(Monthly!$C$25:$BJ$25,($R$2-1)*12+3) -> -85611.8 | K8: =INDEX(Monthly!$C$25:$BJ$25,($R$2-1)*12+4) -> -87424.323 | L8: =INDEX(Monthly!$C$25:$BJ$25,($R$2-1)*12+5) -> -89218.192 | M8: =INDEX(Monthly!$C$25:$BJ$25,($R$2-1)*12+6) -> -90993.6 | N8: =INDEX(Monthly!$C$25:$BJ$25,($R$2-1)*12+7) -> -92750.74 | O8: =INDEX(Monthly!$C$25:$BJ$25,($R$2-1)*12+8) -> -94489.803 | P8: =INDEX(Monthly!$C$25:$BJ$25,($R$2-1)*12+9) -> -96210.977 | Q8: =INDEX(Monthly!$C$25:$BJ$25,($R$2-1)*12+10) -> -97914.447 | R8: =INDEX(Monthly!$C$25:$BJ$25,($R$2-1)*12+11) -> -99600.4 | S8: =INDEX(Monthly!$C$25:$BJ$25,($R$2-1)*12+12) -> -101269.02
A9: Gross profit | B9: ='P&L'!B7 -> 9115572.1 | C9: ='P&L'!C7 -> 11555505 | D9: ='P&L'!D7 -> 14686438 | E9: ='P&L'!E7 -> 18708530 | F9: ='P&L'!F7 -> 23881957 | H9: =INDEX(Monthly!$C$26:$BJ$26,($R$2-1)*12+1) -> 676820 | I9: =INDEX(Monthly!$C$26:$BJ$26,($R$2-1)*12+2) -> 692382.07 | J9: =INDEX(Monthly!$C$26:$BJ$26,($R$2-1)*12+3) -> 707789.08 | K9: =INDEX(Monthly!$C$26:$BJ$26,($R$2-1)*12+4) -> 723042.54 | L9: =INDEX(Monthly!$C$26:$BJ$26,($R$2-1)*12+5) -> 738144.01 | M9: =INDEX(Monthly!$C$26:$BJ$26,($R$2-1)*12+6) -> 753094.98 | N9: =INDEX(Monthly!$C$26:$BJ$26,($R$2-1)*12+7) -> 767896.95 | O9: =INDEX(Monthly!$C$26:$BJ$26,($R$2-1)*12+8) -> 782551.41 | P9: =INDEX(Monthly!$C$26:$BJ$26,($R$2-1)*12+9) -> 797059.82 | Q9: =INDEX(Monthly!$C$26:$BJ$26,($R$2-1)*12+10) -> 811423.65 | R9: =INDEX(Monthly!$C$26:$BJ$26,($R$2-1)*12+11) -> 825644.31 | S9: =INDEX(Monthly!$C$26:$BJ$26,($R$2-1)*12+12) -> 839723.25
A10: Gross margin | B10: ='P&L'!B8 -> 0.89221699 | C10: ='P&L'!C8 -> 0.8925734 | D10: ='P&L'!D8 -> 0.89287426 | E10: ='P&L'!E8 -> 0.89313648 | F10: ='P&L'!F8 -> 0.89337139 | H10: =IF(H7=0,0,H9/H7) -> 0.89201977 | I10: =IF(I7=0,0,I9/I7) -> 0.89205814 | J10: =IF(J7=0,0,J9/J7) -> 0.89209515 | K10: =IF(K7=0,0,K9/K7) -> 0.89213091 | L10: =IF(L7=0,0,L9/L7) -> 0.8921655 | M10: =IF(M7=0,0,M9/M7) -> 0.89219899 | N10: =IF(N7=0,0,N9/N7) -> 0.89223147 | O10: =IF(O7=0,0,O9/O7) -> 0.89226298 | ... S10: =IF(S7=0,0,S9/S7) -> 0.89238061
A11: Operating expenses | B11: ='P&L'!B14 -> -7622400 | C11: ='P&L'!C14 -> -9305892 | D11: ='P&L'!D14 -> -11392489 | E11: ='P&L'!E14 -> -13979315 | F11: ='P&L'!F14 -> -17187019 | H11: =INDEX(Monthly!$C$34:$BJ$34,($R$2-1)*12+1) -> -635200 | I11: =INDEX(Monthly!$C$34:$BJ$34,($R$2-1)*12+2) -> -635200 | J11: =INDEX(Monthly!$C$34:$BJ$34,($R$2-1)*12+3) -> -635200 | K11: =INDEX(Monthly!$C$34:$BJ$34,($R$2-1)*12+4) -> -635200 | L11: =INDEX(Monthly!$C$34:$BJ$34,($R$2-1)*12+5) -> -635200 | M11: =INDEX(Monthly!$C$34:$BJ$34,($R$2-1)*12+6) -> -635200 | N11: =INDEX(Monthly!$C$34:$BJ$34,($R$2-1)*12+7) -> -635200 | O11: =INDEX(Monthly!$C$34:$BJ$34,($R$2-1)*12+8) -> -635200 | P11: =INDEX(Monthly!$C$34:$BJ$34,($R$2-1)*12+9) -> -635200 | Q11: =INDEX(Monthly!$C$34:$BJ$34,($R$2-1)*12+10) -> -635200 | R11: =INDEX(Monthly!$C$34:$BJ$34,($R$2-1)*12+11) -> -635200 | S11: =INDEX(Monthly!$C$34:$BJ$34,($R$2-1)*12+12) -> -635200
A12: EBITDA | B12: ='P&L'!B15 -> 1493172.1 | C12: ='P&L'!C15 -> 2249612.9 | D12: ='P&L'!D15 -> 3293948.5 | E12: ='P&L'!E15 -> 4729214.2 | F12: ='P&L'!F15 -> 6694937.4 | H12: =INDEX(Monthly!$C$35:$BJ$35,($R$2-1)*12+1) -> 41620 | I12: =INDEX(Monthly!$C$35:$BJ$35,($R$2-1)*12+2) -> 57182.075 | J12: =INDEX(Monthly!$C$35:$BJ$35,($R$2-1)*12+3) -> 72589.075 | K12: =INDEX(Monthly!$C$35:$BJ$35,($R$2-1)*12+4) -> 87842.543 | L12: =INDEX(Monthly!$C$35:$BJ$35,($R$2-1)*12+5) -> 102944.01 | M12: =INDEX(Monthly!$C$35:$BJ$35,($R$2-1)*12+6) -> 117894.98 | N12: =INDEX(Monthly!$C$35:$BJ$35,($R$2-1)*12+7) -> 132696.95 | O12: =INDEX(Monthly!$C$35:$BJ$35,($R$2-1)*12+8) -> 147351.41 | P12: =INDEX(Monthly!$C$35:$BJ$35,($R$2-1)*12+9) -> 161859.82 | Q12: =INDEX(Monthly!$C$35:$BJ$35,($R$2-1)*12+10) -> 176223.65 | R12: =INDEX(Monthly!$C$35:$BJ$35,($R$2-1)*12+11) -> 190444.31 | S12: =INDEX(Monthly!$C$35:$BJ$35,($R$2-1)*12+12) -> 204523.25
A13: EBITDA margin | B13: ='P&L'!B16 -> 0.14614919 | C13: ='P&L'!C16 -> 0.1737652 | D13: ='P&L'!D16 -> 0.20025835 | E13: ='P&L'!E16 -> 0.22577048 | F13: ='P&L'!F16 -> 0.25044286 | H13: =IF(H7=0,0,H12/H7) -> 0.054853377 | I13: =IF(I7=0,0,I12/I7) -> 0.073672813 | J13: =IF(J7=0,0,J12/J7) -> 0.091491045 | K13: =IF(K7=0,0,K12/K7) -> 0.10838511 | L13: =IF(L7=0,0,L12/L7) -> 0.12442435 | M13: =IF(M7=0,0,M12/M7) -> 0.13967133 | N13: =IF(N7=0,0,N12/N7) -> 0.15418266 | O13: =IF(O7=0,0,O12/O7) -> 0.16800968 | ... S13: =IF(S7=0,0,S12/S7) -> 0.21734849
A14: Depreciation | B14: ='P&L'!B17 -> -50000 | C14: ='P&L'!C17 -> -50000 | D14: ='P&L'!D17 -> -50000 | E14: ='P&L'!E17 -> 0 | F14: ='P&L'!F17 -> 0 | H14: =INDEX(Monthly!$C$49:$BJ$49,($R$2-1)*12+1) -> -4166.6667 | I14: =INDEX(Monthly!$C$49:$BJ$49,($R$2-1)*12+2) -> -4166.6667 | J14: =INDEX(Monthly!$C$49:$BJ$49,($R$2-1)*12+3) -> -4166.6667 | K14: =INDEX(Monthly!$C$49:$BJ$49,($R$2-1)*12+4) -> -4166.6667 | L14: =INDEX(Monthly!$C$49:$BJ$49,($R$2-1)*12+5) -> -4166.6667 | M14: =INDEX(Monthly!$C$49:$BJ$49,($R$2-1)*12+6) -> -4166.6667 | N14: =INDEX(Monthly!$C$49:$BJ$49,($R$2-1)*12+7) -> -4166.6667 | O14: =INDEX(Monthly!$C$49:$BJ$49,($R$2-1)*12+8) -> -4166.6667 | P14: =INDEX(Monthly!$C$49:$BJ$49,($R$2-1)*12+9) -> -4166.6667 | Q14: =INDEX(Monthly!$C$49:$BJ$49,($R$2-1)*12+10) -> -4166.6667 | R14: =INDEX(Monthly!$C$49:$BJ$49,($R$2-1)*12+11) -> -4166.6667 | S14: =INDEX(Monthly!$C$49:$BJ$49,($R$2-1)*12+12) -> -4166.6667
A15: EBIT | B15: ='P&L'!B18 -> 1443172.1 | C15: ='P&L'!C18 -> 2199612.9 | D15: ='P&L'!D18 -> 3243948.5 | E15: ='P&L'!E18 -> 4729214.2 | F15: ='P&L'!F18 -> 6694937.4 | H15: =INDEX(Monthly!$C$38:$BJ$38,($R$2-1)*12+1) -> 37453.333 | I15: =INDEX(Monthly!$C$38:$BJ$38,($R$2-1)*12+2) -> 53015.408 | J15: =INDEX(Monthly!$C$38:$BJ$38,($R$2-1)*12+3) -> 68422.408 | K15: =INDEX(Monthly!$C$38:$BJ$38,($R$2-1)*12+4) -> 83675.876 | L15: =INDEX(Monthly!$C$38:$BJ$38,($R$2-1)*12+5) -> 98777.339 | M15: =INDEX(Monthly!$C$38:$BJ$38,($R$2-1)*12+6) -> 113728.31 | N15: =INDEX(Monthly!$C$38:$BJ$38,($R$2-1)*12+7) -> 128530.28 | O15: =INDEX(Monthly!$C$38:$BJ$38,($R$2-1)*12+8) -> 143184.74 | P15: =INDEX(Monthly!$C$38:$BJ$38,($R$2-1)*12+9) -> 157693.16 | Q15: =INDEX(Monthly!$C$38:$BJ$38,($R$2-1)*12+10) -> 172056.98 | R15: =INDEX(Monthly!$C$38:$BJ$38,($R$2-1)*12+11) -> 186277.65 | S15: =INDEX(Monthly!$C$38:$BJ$38,($R$2-1)*12+12) -> 200356.58
A16: Interest | B16: ='P&L'!B19 -> 0 | C16: ='P&L'!C19 -> 0 | D16: ='P&L'!D19 -> 0 | E16: ='P&L'!E19 -> 0 | F16: ='P&L'!F19 -> 0 | H16: =INDEX(Monthly!$C$39:$BJ$39,($R$2-1)*12+1) -> 0 | I16: =INDEX(Monthly!$C$39:$BJ$39,($R$2-1)*12+2) -> 0 | J16: =INDEX(Monthly!$C$39:$BJ$39,($R$2-1)*12+3) -> 0 | K16: =INDEX(Monthly!$C$39:$BJ$39,($R$2-1)*12+4) -> 0 | L16: =INDEX(Monthly!$C$39:$BJ$39,($R$2-1)*12+5) -> 0 | M16: =INDEX(Monthly!$C$39:$BJ$39,($R$2-1)*12+6) -> 0 | N16: =INDEX(Monthly!$C$39:$BJ$39,($R$2-1)*12+7) -> 0 | O16: =INDEX(Monthly!$C$39:$BJ$39,($R$2-1)*12+8) -> 0 | P16: =INDEX(Monthly!$C$39:$BJ$39,($R$2-1)*12+9) -> 0 | Q16: =INDEX(Monthly!$C$39:$BJ$39,($R$2-1)*12+10) -> 0 | R16: =INDEX(Monthly!$C$39:$BJ$39,($R$2-1)*12+11) -> 0 | S16: =INDEX(Monthly!$C$39:$BJ$39,($R$2-1)*12+12) -> 0
A17: Pre-tax income | B17: ='P&L'!B20 -> 1443172.1 | C17: ='P&L'!C20 -> 2199612.9 | D17: ='P&L'!D20 -> 3243948.5 | E17: ='P&L'!E20 -> 4729214.2 | F17: ='P&L'!F20 -> 6694937.4 | H17: =INDEX(Monthly!$C$40:$BJ$40,($R$2-1)*12+1) -> 37453.333 | I17: =INDEX(Monthly!$C$40:$BJ$40,($R$2-1)*12+2) -> 53015.408 | J17: =INDEX(Monthly!$C$40:$BJ$40,($R$2-1)*12+3) -> 68422.408 | K17: =INDEX(Monthly!$C$40:$BJ$40,($R$2-1)*12+4) -> 83675.876 | L17: =INDEX(Monthly!$C$40:$BJ$40,($R$2-1)*12+5) -> 98777.339 | M17: =INDEX(Monthly!$C$40:$BJ$40,($R$2-1)*12+6) -> 113728.31 | N17: =INDEX(Monthly!$C$40:$BJ$40,($R$2-1)*12+7) -> 128530.28 | O17: =INDEX(Monthly!$C$40:$BJ$40,($R$2-1)*12+8) -> 143184.74 | P17: =INDEX(Monthly!$C$40:$BJ$40,($R$2-1)*12+9) -> 157693.16 | Q17: =INDEX(Monthly!$C$40:$BJ$40,($R$2-1)*12+10) -> 172056.98 | R17: =INDEX(Monthly!$C$40:$BJ$40,($R$2-1)*12+11) -> 186277.65 | S17: =INDEX(Monthly!$C$40:$BJ$40,($R$2-1)*12+12) -> 200356.58
A18: Income tax | B18: ='P&L'!B21 -> -303066.13 | C18: ='P&L'!C21 -> -461918.7 | D18: ='P&L'!D21 -> -681229.18 | E18: ='P&L'!E21 -> -993134.99 | F18: ='P&L'!F21 -> -1405936.8 | H18: =INDEX(Monthly!$C$43:$BJ$43,($R$2-1)*12+1) -> -7865.2 | I18: =INDEX(Monthly!$C$43:$BJ$43,($R$2-1)*12+2) -> -11133.236 | J18: =INDEX(Monthly!$C$43:$BJ$43,($R$2-1)*12+3) -> -14368.706 | K18: =INDEX(Monthly!$C$43:$BJ$43,($R$2-1)*12+4) -> -17571.934 | L18: =INDEX(Monthly!$C$43:$BJ$43,($R$2-1)*12+5) -> -20743.241 | M18: =INDEX(Monthly!$C$43:$BJ$43,($R$2-1)*12+6) -> -23882.945 | N18: =INDEX(Monthly!$C$43:$BJ$43,($R$2-1)*12+7) -> -26991.359 | O18: =INDEX(Monthly!$C$43:$BJ$43,($R$2-1)*12+8) -> -30068.796 | P18: =INDEX(Monthly!$C$43:$BJ$43,($R$2-1)*12+9) -> -33115.563 | Q18: =INDEX(Monthly!$C$43:$BJ$43,($R$2-1)*12+10) -> -36131.966 | R18: =INDEX(Monthly!$C$43:$BJ$43,($R$2-1)*12+11) -> -39118.306 | S18: =INDEX(Monthly!$C$43:$BJ$43,($R$2-1)*12+12) -> -42074.882
A19: Net income | B19: ='P&L'!B22 -> 1140105.9 | C19: ='P&L'!C22 -> 1737694.2 | D19: ='P&L'!D22 -> 2562719.3 | E19: ='P&L'!E22 -> 3736079.2 | F19: ='P&L'!F22 -> 5289000.5 | H19: =INDEX(Monthly!$C$44:$BJ$44,($R$2-1)*12+1) -> 29588.133 | I19: =INDEX(Monthly!$C$44:$BJ$44,($R$2-1)*12+2) -> 41882.173 | J19: =INDEX(Monthly!$C$44:$BJ$44,($R$2-1)*12+3) -> 54053.703 | K19: =INDEX(Monthly!$C$44:$BJ$44,($R$2-1)*12+4) -> 66103.942 | L19: =INDEX(Monthly!$C$44:$BJ$44,($R$2-1)*12+5) -> 78034.098 | M19: =INDEX(Monthly!$C$44:$BJ$44,($R$2-1)*12+6) -> 89845.364 | N19: =INDEX(Monthly!$C$44:$BJ$44,($R$2-1)*12+7) -> 101538.92 | O19: =INDEX(Monthly!$C$44:$BJ$44,($R$2-1)*12+8) -> 113115.95 | P19: =INDEX(Monthly!$C$44:$BJ$44,($R$2-1)*12+9) -> 124577.59 | Q19: =INDEX(Monthly!$C$44:$BJ$44,($R$2-1)*12+10) -> 135925.01 | R19: =INDEX(Monthly!$C$44:$BJ$44,($R$2-1)*12+11) -> 147159.34 | S19: =INDEX(Monthly!$C$44:$BJ$44,($R$2-1)*12+12) -> 158281.7
A20: Net margin | B20: ='P&L'!B23 -> 0.11159167 | C20: ='P&L'!C23 -> 0.13422344 | D20: ='P&L'!D23 -> 0.15580266 | E20: ='P&L'!E23 -> 0.17835868 | F20: ='P&L'!F23 -> 0.19784986 | H20: =IF(H7=0,0,H19/H7) -> 0.038995892 | I20: =IF(I7=0,0,I19/I7) -> 0.053960572 | J20: =IF(J7=0,0,J19/J7) -> 0.068129119 | K20: =IF(K7=0,0,K19/K7) -> 0.081562794 | L20: =IF(L7=0,0,L19/L7) -> 0.094316731 | M20: =IF(M7=0,0,M19/M7) -> 0.10644068 | N20: =IF(N7=0,0,N19/N7) -> 0.11797966 | O20: =IF(O7=0,0,O19/O7) -> 0.12897449 | ... S20: =IF(S7=0,0,S19/S7) -> 0.16820723
A22: Cash flow ($'000) — 5 years | H22: ="Cash flow ($'000) — Year "&$R$2&", by month" -> Cash flow ($'000) — Year 1, by month
B23: ='P&L'!B4 -> Year 1 | C23: ='P&L'!C4 -> Year 2 | D23: ='P&L'!D4 -> Year 3 | E23: ='P&L'!E4 -> Year 4 | F23: ='P&L'!F4 -> Year 5 | H23: =INDEX(Monthly!$C$3:$BJ$3,($R$2-1)*12+1) -> M1 | I23: =INDEX(Monthly!$C$3:$BJ$3,($R$2-1)*12+2) -> M2 | J23: =INDEX(Monthly!$C$3:$BJ$3,($R$2-1)*12+3) -> M3 | K23: =INDEX(Monthly!$C$3:$BJ$3,($R$2-1)*12+4) -> M4 | L23: =INDEX(Monthly!$C$3:$BJ$3,($R$2-1)*12+5) -> M5 | M23: =INDEX(Monthly!$C$3:$BJ$3,($R$2-1)*12+6) -> M6 | N23: =INDEX(Monthly!$C$3:$BJ$3,($R$2-1)*12+7) -> M7 | O23: =INDEX(Monthly!$C$3:$BJ$3,($R$2-1)*12+8) -> M8 | P23: =INDEX(Monthly!$C$3:$BJ$3,($R$2-1)*12+9) -> M9 | Q23: =INDEX(Monthly!$C$3:$BJ$3,($R$2-1)*12+10) -> M10 | R23: =INDEX(Monthly!$C$3:$BJ$3,($R$2-1)*12+11) -> M11 | S23: =INDEX(Monthly!$C$3:$BJ$3,($R$2-1)*12+12) -> M12
A24: Operating cash flow | B24: ='Cash Flow'!B11 -> 2273134.7 | C24: ='Cash Flow'!C11 -> 2078342.8 | D24: ='Cash Flow'!D11 -> 2985771.8 | E24: ='Cash Flow'!E11 -> 4215445.8 | F24: ='Cash Flow'!F11 -> 5905773.3 | H24: =INDEX(Monthly!$C$70:$BJ$70,($R$2-1)*12+1) -> 910226.47 | I24: =INDEX(Monthly!$C$70:$BJ$70,($R$2-1)*12+2) -> 65787.181 | J24: =INDEX(Monthly!$C$70:$BJ$70,($R$2-1)*12+3) -> 77760.782 | K24: =INDEX(Monthly!$C$70:$BJ$70,($R$2-1)*12+4) -> 89615.079 | L24: =INDEX(Monthly!$C$70:$BJ$70,($R$2-1)*12+5) -> 101351.26 | M24: =INDEX(Monthly!$C$70:$BJ$70,($R$2-1)*12+6) -> 112970.5 | N24: =INDEX(Monthly!$C$70:$BJ$70,($R$2-1)*12+7) -> 124473.96 | O24: =INDEX(Monthly!$C$70:$BJ$70,($R$2-1)*12+8) -> 135862.79 | P24: =INDEX(Monthly!$C$70:$BJ$70,($R$2-1)*12+9) -> 147138.14 | Q24: =INDEX(Monthly!$C$70:$BJ$70,($R$2-1)*12+10) -> 158301.13 | R24: =INDEX(Monthly!$C$70:$BJ$70,($R$2-1)*12+11) -> 169352.88 | S24: =INDEX(Monthly!$C$70:$BJ$70,($R$2-1)*12+12) -> 180294.49
A25: Capital spending | B25: ='Cash Flow'!B12 -> -150000 | C25: ='Cash Flow'!C12 -> 0 | D25: ='Cash Flow'!D12 -> 0 | E25: ='Cash Flow'!E12 -> 0 | F25: ='Cash Flow'!F12 -> 0 | H25: =INDEX(Monthly!$C$71:$BJ$71,($R$2-1)*12+1) -> -150000 | I25: =INDEX(Monthly!$C$71:$BJ$71,($R$2-1)*12+2) -> 0 | J25: =INDEX(Monthly!$C$71:$BJ$71,($R$2-1)*12+3) -> 0 | K25: =INDEX(Monthly!$C$71:$BJ$71,($R$2-1)*12+4) -> 0 | L25: =INDEX(Monthly!$C$71:$BJ$71,($R$2-1)*12+5) -> 0 | M25: =INDEX(Monthly!$C$71:$BJ$71,($R$2-1)*12+6) -> 0 | N25: =INDEX(Monthly!$C$71:$BJ$71,($R$2-1)*12+7) -> 0 | O25: =INDEX(Monthly!$C$71:$BJ$71,($R$2-1)*12+8) -> 0 | P25: =INDEX(Monthly!$C$71:$BJ$71,($R$2-1)*12+9) -> 0 | Q25: =INDEX(Monthly!$C$71:$BJ$71,($R$2-1)*12+10) -> 0 | R25: =INDEX(Monthly!$C$71:$BJ$71,($R$2-1)*12+11) -> 0 | S25: =INDEX(Monthly!$C$71:$BJ$71,($R$2-1)*12+12) -> 0
A26: Equity raised | B26: ='Cash Flow'!B13 -> 1000000 | C26: ='Cash Flow'!C13 -> 0 | D26: ='Cash Flow'!D13 -> 0 | E26: ='Cash Flow'!E13 -> 0 | F26: ='Cash Flow'!F13 -> 0 | H26: =INDEX(Monthly!$C$72:$BJ$72,($R$2-1)*12+1) -> 1000000 | I26: =INDEX(Monthly!$C$72:$BJ$72,($R$2-1)*12+2) -> 0 | J26: =INDEX(Monthly!$C$72:$BJ$72,($R$2-1)*12+3) -> 0 | K26: =INDEX(Monthly!$C$72:$BJ$72,($R$2-1)*12+4) -> 0 | L26: =INDEX(Monthly!$C$72:$BJ$72,($R$2-1)*12+5) -> 0 | M26: =INDEX(Monthly!$C$72:$BJ$72,($R$2-1)*12+6) -> 0 | N26: =INDEX(Monthly!$C$72:$BJ$72,($R$2-1)*12+7) -> 0 | O26: =INDEX(Monthly!$C$72:$BJ$72,($R$2-1)*12+8) -> 0 | P26: =INDEX(Monthly!$C$72:$BJ$72,($R$2-1)*12+9) -> 0 | Q26: =INDEX(Monthly!$C$72:$BJ$72,($R$2-1)*12+10) -> 0 | R26: =INDEX(Monthly!$C$72:$BJ$72,($R$2-1)*12+11) -> 0 | S26: =INDEX(Monthly!$C$72:$BJ$72,($R$2-1)*12+12) -> 0
A27: Loan drawdown | B27: ='Cash Flow'!B14 -> 0 | C27: ='Cash Flow'!C14 -> 0 | D27: ='Cash Flow'!D14 -> 0 | E27: ='Cash Flow'!E14 -> 0 | F27: ='Cash Flow'!F14 -> 0 | H27: =INDEX(Monthly!$C$55:$BJ$55,($R$2-1)*12+1) -> 0 | I27: =INDEX(Monthly!$C$55:$BJ$55,($R$2-1)*12+2) -> 0 | J27: =INDEX(Monthly!$C$55:$BJ$55,($R$2-1)*12+3) -> 0 | K27: =INDEX(Monthly!$C$55:$BJ$55,($R$2-1)*12+4) -> 0 | L27: =INDEX(Monthly!$C$55:$BJ$55,($R$2-1)*12+5) -> 0 | M27: =INDEX(Monthly!$C$55:$BJ$55,($R$2-1)*12+6) -> 0 | N27: =INDEX(Monthly!$C$55:$BJ$55,($R$2-1)*12+7) -> 0 | O27: =INDEX(Monthly!$C$55:$BJ$55,($R$2-1)*12+8) -> 0 | P27: =INDEX(Monthly!$C$55:$BJ$55,($R$2-1)*12+9) -> 0 | Q27: =INDEX(Monthly!$C$55:$BJ$55,($R$2-1)*12+10) -> 0 | R27: =INDEX(Monthly!$C$55:$BJ$55,($R$2-1)*12+11) -> 0 | S27: =INDEX(Monthly!$C$55:$BJ$55,($R$2-1)*12+12) -> 0
A28: Loan repayment | B28: ='Cash Flow'!B15 -> 0 | C28: ='Cash Flow'!C15 -> 0 | D28: ='Cash Flow'!D15 -> 0 | E28: ='Cash Flow'!E15 -> 0 | F28: ='Cash Flow'!F15 -> 0 | H28: =INDEX(Monthly!$C$56:$BJ$56,($R$2-1)*12+1) -> 0 | I28: =INDEX(Monthly!$C$56:$BJ$56,($R$2-1)*12+2) -> 0 | J28: =INDEX(Monthly!$C$56:$BJ$56,($R$2-1)*12+3) -> 0 | K28: =INDEX(Monthly!$C$56:$BJ$56,($R$2-1)*12+4) -> 0 | L28: =INDEX(Monthly!$C$56:$BJ$56,($R$2-1)*12+5) -> 0 | M28: =INDEX(Monthly!$C$56:$BJ$56,($R$2-1)*12+6) -> 0 | N28: =INDEX(Monthly!$C$56:$BJ$56,($R$2-1)*12+7) -> 0 | O28: =INDEX(Monthly!$C$56:$BJ$56,($R$2-1)*12+8) -> 0 | P28: =INDEX(Monthly!$C$56:$BJ$56,($R$2-1)*12+9) -> 0 | Q28: =INDEX(Monthly!$C$56:$BJ$56,($R$2-1)*12+10) -> 0 | R28: =INDEX(Monthly!$C$56:$BJ$56,($R$2-1)*12+11) -> 0 | S28: =INDEX(Monthly!$C$56:$BJ$56,($R$2-1)*12+12) -> 0
A29: Financing cash flow | B29: ='Cash Flow'!B16 -> 1000000 | C29: ='Cash Flow'!C16 -> 0 | D29: ='Cash Flow'!D16 -> 0 | E29: ='Cash Flow'!E16 -> 0 | F29: ='Cash Flow'!F16 -> 0 | H29: =INDEX(Monthly!$C$73:$BJ$73,($R$2-1)*12+1) -> 1000000 | I29: =INDEX(Monthly!$C$73:$BJ$73,($R$2-1)*12+2) -> 0 | J29: =INDEX(Monthly!$C$73:$BJ$73,($R$2-1)*12+3) -> 0 | K29: =INDEX(Monthly!$C$73:$BJ$73,($R$2-1)*12+4) -> 0 | L29: =INDEX(Monthly!$C$73:$BJ$73,($R$2-1)*12+5) -> 0 | M29: =INDEX(Monthly!$C$73:$BJ$73,($R$2-1)*12+6) -> 0 | N29: =INDEX(Monthly!$C$73:$BJ$73,($R$2-1)*12+7) -> 0 | O29: =INDEX(Monthly!$C$73:$BJ$73,($R$2-1)*12+8) -> 0 | P29: =INDEX(Monthly!$C$73:$BJ$73,($R$2-1)*12+9) -> 0 | Q29: =INDEX(Monthly!$C$73:$BJ$73,($R$2-1)*12+10) -> 0 | R29: =INDEX(Monthly!$C$73:$BJ$73,($R$2-1)*12+11) -> 0 | S29: =INDEX(Monthly!$C$73:$BJ$73,($R$2-1)*12+12) -> 0
A30: Net change in cash | B30: ='Cash Flow'!B17 -> 3123134.7 | C30: ='Cash Flow'!C17 -> 2078342.8 | D30: ='Cash Flow'!D17 -> 2985771.8 | E30: ='Cash Flow'!E17 -> 4215445.8 | F30: ='Cash Flow'!F17 -> 5905773.3 | H30: =INDEX(Monthly!$C$74:$BJ$74,($R$2-1)*12+1) -> 1760226.5 | I30: =INDEX(Monthly!$C$74:$BJ$74,($R$2-1)*12+2) -> 65787.181 | J30: =INDEX(Monthly!$C$74:$BJ$74,($R$2-1)*12+3) -> 77760.782 | K30: =INDEX(Monthly!$C$74:$BJ$74,($R$2-1)*12+4) -> 89615.079 | L30: =INDEX(Monthly!$C$74:$BJ$74,($R$2-1)*12+5) -> 101351.26 | M30: =INDEX(Monthly!$C$74:$BJ$74,($R$2-1)*12+6) -> 112970.5 | N30: =INDEX(Monthly!$C$74:$BJ$74,($R$2-1)*12+7) -> 124473.96 | O30: =INDEX(Monthly!$C$74:$BJ$74,($R$2-1)*12+8) -> 135862.79 | P30: =INDEX(Monthly!$C$74:$BJ$74,($R$2-1)*12+9) -> 147138.14 | Q30: =INDEX(Monthly!$C$74:$BJ$74,($R$2-1)*12+10) -> 158301.13 | R30: =INDEX(Monthly!$C$74:$BJ$74,($R$2-1)*12+11) -> 169352.88 | S30: =INDEX(Monthly!$C$74:$BJ$74,($R$2-1)*12+12) -> 180294.49
A31: Closing cash | B31: ='Cash Flow'!B19 -> 3123134.7 | C31: ='Cash Flow'!C19 -> 5201477.5 | D31: ='Cash Flow'!D19 -> 8187249.2 | E31: ='Cash Flow'!E19 -> 12402695 | F31: ='Cash Flow'!F19 -> 18308468 | H31: =INDEX(Monthly!$C$76:$BJ$76,($R$2-1)*12+1) -> 1760226.5 | I31: =INDEX(Monthly!$C$76:$BJ$76,($R$2-1)*12+2) -> 1826013.6 | J31: =INDEX(Monthly!$C$76:$BJ$76,($R$2-1)*12+3) -> 1903774.4 | K31: =INDEX(Monthly!$C$76:$BJ$76,($R$2-1)*12+4) -> 1993389.5 | L31: =INDEX(Monthly!$C$76:$BJ$76,($R$2-1)*12+5) -> 2094740.8 | M31: =INDEX(Monthly!$C$76:$BJ$76,($R$2-1)*12+6) -> 2207711.3 | N31: =INDEX(Monthly!$C$76:$BJ$76,($R$2-1)*12+7) -> 2332185.2 | O31: =INDEX(Monthly!$C$76:$BJ$76,($R$2-1)*12+8) -> 2468048 | P31: =INDEX(Monthly!$C$76:$BJ$76,($R$2-1)*12+9) -> 2615186.2 | Q31: =INDEX(Monthly!$C$76:$BJ$76,($R$2-1)*12+10) -> 2773487.3 | R31: =INDEX(Monthly!$C$76:$BJ$76,($R$2-1)*12+11) -> 2942840.2 | S31: =INDEX(Monthly!$C$76:$BJ$76,($R$2-1)*12+12) -> 3123134.7
A39: Balance sheet at year end ($'000) | H39: ="Balance sheet at month end ($'000) — Year "&$R$2 -> Balance sheet at month end ($'000) — Year 1
B40: ='P&L'!B4 -> Year 1 | C40: ='P&L'!C4 -> Year 2 | D40: ='P&L'!D4 -> Year 3 | E40: ='P&L'!E4 -> Year 4 | F40: ='P&L'!F4 -> Year 5 | H40: =INDEX(Monthly!$C$3:$BJ$3,($R$2-1)*12+1) -> M1 | I40: =INDEX(Monthly!$C$3:$BJ$3,($R$2-1)*12+2) -> M2 | J40: =INDEX(Monthly!$C$3:$BJ$3,($R$2-1)*12+3) -> M3 | K40: =INDEX(Monthly!$C$3:$BJ$3,($R$2-1)*12+4) -> M4 | L40: =INDEX(Monthly!$C$3:$BJ$3,($R$2-1)*12+5) -> M5 | M40: =INDEX(Monthly!$C$3:$BJ$3,($R$2-1)*12+6) -> M6 | N40: =INDEX(Monthly!$C$3:$BJ$3,($R$2-1)*12+7) -> M7 | O40: =INDEX(Monthly!$C$3:$BJ$3,($R$2-1)*12+8) -> M8 | P40: =INDEX(Monthly!$C$3:$BJ$3,($R$2-1)*12+9) -> M9 | Q40: =INDEX(Monthly!$C$3:$BJ$3,($R$2-1)*12+10) -> M10 | R40: =INDEX(Monthly!$C$3:$BJ$3,($R$2-1)*12+11) -> M11 | S40: =INDEX(Monthly!$C$3:$BJ$3,($R$2-1)*12+12) -> M12
A41: Cash | B41: ='Balance Sheet'!B5 -> 3123134.7 | C41: ='Balance Sheet'!C5 -> 5201477.5 | D41: ='Balance Sheet'!D5 -> 8187249.2 | E41: ='Balance Sheet'!E5 -> 12402695 | F41: ='Balance Sheet'!F5 -> 18308468 | H41: =INDEX(Monthly!$C$76:$BJ$76,($R$2-1)*12+1) -> 1760226.5 | I41: =INDEX(Monthly!$C$76:$BJ$76,($R$2-1)*12+2) -> 1826013.6 | J41: =INDEX(Monthly!$C$76:$BJ$76,($R$2-1)*12+3) -> 1903774.4 | K41: =INDEX(Monthly!$C$76:$BJ$76,($R$2-1)*12+4) -> 1993389.5 | L41: =INDEX(Monthly!$C$76:$BJ$76,($R$2-1)*12+5) -> 2094740.8 | M41: =INDEX(Monthly!$C$76:$BJ$76,($R$2-1)*12+6) -> 2207711.3 | N41: =INDEX(Monthly!$C$76:$BJ$76,($R$2-1)*12+7) -> 2332185.2 | O41: =INDEX(Monthly!$C$76:$BJ$76,($R$2-1)*12+8) -> 2468048 | P41: =INDEX(Monthly!$C$76:$BJ$76,($R$2-1)*12+9) -> 2615186.2 | Q41: =INDEX(Monthly!$C$76:$BJ$76,($R$2-1)*12+10) -> 2773487.3 | R41: =INDEX(Monthly!$C$76:$BJ$76,($R$2-1)*12+11) -> 2942840.2 | S41: =INDEX(Monthly!$C$76:$BJ$76,($R$2-1)*12+12) -> 3123134.7
A42: Accounts receivable | B42: ='Balance Sheet'!B6 -> 156832.04 | C42: ='Balance Sheet'!C6 -> 198958.68 | D42: ='Balance Sheet'!D6 -> 253031.66 | E42: ='Balance Sheet'!E6 -> 322519.09 | F42: ='Balance Sheet'!F6 -> 411930.95 | H42: =INDEX(Monthly!$C$60:$BJ$60,($R$2-1)*12+1) -> 126458.33 | I42: =INDEX(Monthly!$C$60:$BJ$60,($R$2-1)*12+2) -> 129360.42 | J42: =INDEX(Monthly!$C$60:$BJ$60,($R$2-1)*12+3) -> 132233.48 | K42: =INDEX(Monthly!$C$60:$BJ$60,($R$2-1)*12+4) -> 135077.81 | L42: =INDEX(Monthly!$C$60:$BJ$60,($R$2-1)*12+5) -> 137893.7 | M42: =INDEX(Monthly!$C$60:$BJ$60,($R$2-1)*12+6) -> 140681.43 | N42: =INDEX(Monthly!$C$60:$BJ$60,($R$2-1)*12+7) -> 143441.28 | O42: =INDEX(Monthly!$C$60:$BJ$60,($R$2-1)*12+8) -> 146173.54 | P42: =INDEX(Monthly!$C$60:$BJ$60,($R$2-1)*12+9) -> 148878.47 | Q42: =INDEX(Monthly!$C$60:$BJ$60,($R$2-1)*12+10) -> 151556.35 | R42: =INDEX(Monthly!$C$60:$BJ$60,($R$2-1)*12+11) -> 154207.45 | S42: =INDEX(Monthly!$C$60:$BJ$60,($R$2-1)*12+12) -> 156832.04
A43: Inventory | B43: ='Balance Sheet'!B7 -> 0 | C43: ='Balance Sheet'!C7 -> 0 | D43: ='Balance Sheet'!D7 -> 0 | E43: ='Balance Sheet'!E7 -> 0 | F43: ='Balance Sheet'!F7 -> 0 | H43: =INDEX(Monthly!$C$61:$BJ$61,($R$2-1)*12+1) -> 0 | I43: =INDEX(Monthly!$C$61:$BJ$61,($R$2-1)*12+2) -> 0 | J43: =INDEX(Monthly!$C$61:$BJ$61,($R$2-1)*12+3) -> 0 | K43: =INDEX(Monthly!$C$61:$BJ$61,($R$2-1)*12+4) -> 0 | L43: =INDEX(Monthly!$C$61:$BJ$61,($R$2-1)*12+5) -> 0 | M43: =INDEX(Monthly!$C$61:$BJ$61,($R$2-1)*12+6) -> 0 | N43: =INDEX(Monthly!$C$61:$BJ$61,($R$2-1)*12+7) -> 0 | O43: =INDEX(Monthly!$C$61:$BJ$61,($R$2-1)*12+8) -> 0 | P43: =INDEX(Monthly!$C$61:$BJ$61,($R$2-1)*12+9) -> 0 | Q43: =INDEX(Monthly!$C$61:$BJ$61,($R$2-1)*12+10) -> 0 | R43: =INDEX(Monthly!$C$61:$BJ$61,($R$2-1)*12+11) -> 0 | S43: =INDEX(Monthly!$C$61:$BJ$61,($R$2-1)*12+12) -> 0
A44: Net fixed assets | B44: ='Balance Sheet'!B8 -> 100000 | C44: ='Balance Sheet'!C8 -> 50000 | D44: ='Balance Sheet'!D8 -> 0 | E44: ='Balance Sheet'!E8 -> 0 | F44: ='Balance Sheet'!F8 -> 0 | H44: =INDEX(Monthly!$C$51:$BJ$51,($R$2-1)*12+1) -> 145833.33 | I44: =INDEX(Monthly!$C$51:$BJ$51,($R$2-1)*12+2) -> 141666.67 | J44: =INDEX(Monthly!$C$51:$BJ$51,($R$2-1)*12+3) -> 137500 | K44: =INDEX(Monthly!$C$51:$BJ$51,($R$2-1)*12+4) -> 133333.33 | L44: =INDEX(Monthly!$C$51:$BJ$51,($R$2-1)*12+5) -> 129166.67 | M44: =INDEX(Monthly!$C$51:$BJ$51,($R$2-1)*12+6) -> 125000 | N44: =INDEX(Monthly!$C$51:$BJ$51,($R$2-1)*12+7) -> 120833.33 | O44: =INDEX(Monthly!$C$51:$BJ$51,($R$2-1)*12+8) -> 116666.67 | P44: =INDEX(Monthly!$C$51:$BJ$51,($R$2-1)*12+9) -> 112500 | Q44: =INDEX(Monthly!$C$51:$BJ$51,($R$2-1)*12+10) -> 108333.33 | R44: =INDEX(Monthly!$C$51:$BJ$51,($R$2-1)*12+11) -> 104166.67 | S44: =INDEX(Monthly!$C$51:$BJ$51,($R$2-1)*12+12) -> 100000
A45: Total assets | B45: ='Balance Sheet'!B9 -> 3379966.7 | C45: ='Balance Sheet'!C9 -> 5450436.1 | D45: ='Balance Sheet'!D9 -> 8440280.9 | E45: ='Balance Sheet'!E9 -> 12725214 | F45: ='Balance Sheet'!F9 -> 18720399 | H45: =INDEX(Monthly!$C$94:$BJ$94,($R$2-1)*12+1) -> 2032518.1 | I45: =INDEX(Monthly!$C$94:$BJ$94,($R$2-1)*12+2) -> 2097040.7 | J45: =INDEX(Monthly!$C$94:$BJ$94,($R$2-1)*12+3) -> 2173507.9 | K45: =INDEX(Monthly!$C$94:$BJ$94,($R$2-1)*12+4) -> 2261800.7 | L45: =INDEX(Monthly!$C$94:$BJ$94,($R$2-1)*12+5) -> 2361801.1 | M45: =INDEX(Monthly!$C$94:$BJ$94,($R$2-1)*12+6) -> 2473392.7 | N45: =INDEX(Monthly!$C$94:$BJ$94,($R$2-1)*12+7) -> 2596459.8 | O45: =INDEX(Monthly!$C$94:$BJ$94,($R$2-1)*12+8) -> 2730888.2 | P45: =INDEX(Monthly!$C$94:$BJ$94,($R$2-1)*12+9) -> 2876564.6 | Q45: =INDEX(Monthly!$C$94:$BJ$94,($R$2-1)*12+10) -> 3033377 | R45: =INDEX(Monthly!$C$94:$BJ$94,($R$2-1)*12+11) -> 3201214.3 | S45: =INDEX(Monthly!$C$94:$BJ$94,($R$2-1)*12+12) -> 3379966.7
A46: Accounts payable | B46: ='Balance Sheet'!B10 -> 101269.02 | C46: ='Balance Sheet'!C10 -> 128077.78 | D46: ='Balance Sheet'!D10 -> 162458.51 | E46: ='Balance Sheet'!E10 -> 206590.9 | F46: ='Balance Sheet'!F10 -> 263306.81 | H46: =INDEX(Monthly!$C$62:$BJ$62,($R$2-1)*12+1) -> 81930 | I46: =INDEX(Monthly!$C$62:$BJ$62,($R$2-1)*12+2) -> 83780.425 | J46: =INDEX(Monthly!$C$62:$BJ$62,($R$2-1)*12+3) -> 85611.8 | K46: =INDEX(Monthly!$C$62:$BJ$62,($R$2-1)*12+4) -> 87424.323 | L46: =INDEX(Monthly!$C$62:$BJ$62,($R$2-1)*12+5) -> 89218.192 | M46: =INDEX(Monthly!$C$62:$BJ$62,($R$2-1)*12+6) -> 90993.6 | N46: =INDEX(Monthly!$C$62:$BJ$62,($R$2-1)*12+7) -> 92750.74 | O46: =INDEX(Monthly!$C$62:$BJ$62,($R$2-1)*12+8) -> 94489.803 | P46: =INDEX(Monthly!$C$62:$BJ$62,($R$2-1)*12+9) -> 96210.977 | Q46: =INDEX(Monthly!$C$62:$BJ$62,($R$2-1)*12+10) -> 97914.447 | R46: =INDEX(Monthly!$C$62:$BJ$62,($R$2-1)*12+11) -> 99600.4 | S46: =INDEX(Monthly!$C$62:$BJ$62,($R$2-1)*12+12) -> 101269.02
A47: Deferred revenue | B47: ='Balance Sheet'!B11 -> 1138591.8 | C47: ='Balance Sheet'!C11 -> 1444558.2 | D47: ='Balance Sheet'!D11 -> 1837303 | E47: ='Balance Sheet'!E11 -> 2342024.6 | F47: ='Balance Sheet'!F11 -> 2991493.4 | H47: =INDEX(Monthly!$C$66:$BJ$66,($R$2-1)*12+1) -> 921000 | I47: =INDEX(Monthly!$C$66:$BJ$66,($R$2-1)*12+2) -> 941790 | J47: =INDEX(Monthly!$C$66:$BJ$66,($R$2-1)*12+3) -> 962372.1 | K47: =INDEX(Monthly!$C$66:$BJ$66,($R$2-1)*12+4) -> 982748.38 | L47: =INDEX(Monthly!$C$66:$BJ$66,($R$2-1)*12+5) -> 1002920.9 | M47: =INDEX(Monthly!$C$66:$BJ$66,($R$2-1)*12+6) -> 1022891.7 | N47: =INDEX(Monthly!$C$66:$BJ$66,($R$2-1)*12+7) -> 1042662.8 | O47: =INDEX(Monthly!$C$66:$BJ$66,($R$2-1)*12+8) -> 1062236.1 | P47: =INDEX(Monthly!$C$66:$BJ$66,($R$2-1)*12+9) -> 1081613.8 | Q47: =INDEX(Monthly!$C$66:$BJ$66,($R$2-1)*12+10) -> 1100797.6 | R47: =INDEX(Monthly!$C$66:$BJ$66,($R$2-1)*12+11) -> 1119789.7 | S47: =INDEX(Monthly!$C$66:$BJ$66,($R$2-1)*12+12) -> 1138591.8
A48: Loan | B48: ='Balance Sheet'!B12 -> 0 | C48: ='Balance Sheet'!C12 -> 0 | D48: ='Balance Sheet'!D12 -> 0 | E48: ='Balance Sheet'!E12 -> 0 | F48: ='Balance Sheet'!F12 -> 0 | H48: =INDEX(Monthly!$C$57:$BJ$57,($R$2-1)*12+1) -> 0 | I48: =INDEX(Monthly!$C$57:$BJ$57,($R$2-1)*12+2) -> 0 | J48: =INDEX(Monthly!$C$57:$BJ$57,($R$2-1)*12+3) -> 0 | K48: =INDEX(Monthly!$C$57:$BJ$57,($R$2-1)*12+4) -> 0 | L48: =INDEX(Monthly!$C$57:$BJ$57,($R$2-1)*12+5) -> 0 | M48: =INDEX(Monthly!$C$57:$BJ$57,($R$2-1)*12+6) -> 0 | N48: =INDEX(Monthly!$C$57:$BJ$57,($R$2-1)*12+7) -> 0 | O48: =INDEX(Monthly!$C$57:$BJ$57,($R$2-1)*12+8) -> 0 | P48: =INDEX(Monthly!$C$57:$BJ$57,($R$2-1)*12+9) -> 0 | Q48: =INDEX(Monthly!$C$57:$BJ$57,($R$2-1)*12+10) -> 0 | R48: =INDEX(Monthly!$C$57:$BJ$57,($R$2-1)*12+11) -> 0 | S48: =INDEX(Monthly!$C$57:$BJ$57,($R$2-1)*12+12) -> 0
A49: Total liabilities | B49: ='Balance Sheet'!B13 -> 1239860.8 | C49: ='Balance Sheet'!C13 -> 1572636 | D49: ='Balance Sheet'!D13 -> 1999761.5 | E49: ='Balance Sheet'!E13 -> 2548615.5 | F49: ='Balance Sheet'!F13 -> 3254800.2 | H49: =INDEX(Monthly!$C$95:$BJ$95,($R$2-1)*12+1) -> 1002930 | I49: =INDEX(Monthly!$C$95:$BJ$95,($R$2-1)*12+2) -> 1025570.4 | J49: =INDEX(Monthly!$C$95:$BJ$95,($R$2-1)*12+3) -> 1047983.9 | K49: =INDEX(Monthly!$C$95:$BJ$95,($R$2-1)*12+4) -> 1070172.7 | L49: =INDEX(Monthly!$C$95:$BJ$95,($R$2-1)*12+5) -> 1092139.1 | M49: =INDEX(Monthly!$C$95:$BJ$95,($R$2-1)*12+6) -> 1113885.3 | N49: =INDEX(Monthly!$C$95:$BJ$95,($R$2-1)*12+7) -> 1135413.5 | O49: =INDEX(Monthly!$C$95:$BJ$95,($R$2-1)*12+8) -> 1156725.9 | P49: =INDEX(Monthly!$C$95:$BJ$95,($R$2-1)*12+9) -> 1177824.8 | Q49: =INDEX(Monthly!$C$95:$BJ$95,($R$2-1)*12+10) -> 1198712.1 | R49: =INDEX(Monthly!$C$95:$BJ$95,($R$2-1)*12+11) -> 1219390.1 | S49: =INDEX(Monthly!$C$95:$BJ$95,($R$2-1)*12+12) -> 1239860.8
A50: Paid-in capital | B50: ='Balance Sheet'!B14 -> 1000000 | C50: ='Balance Sheet'!C14 -> 1000000 | D50: ='Balance Sheet'!D14 -> 1000000 | E50: ='Balance Sheet'!E14 -> 1000000 | F50: ='Balance Sheet'!F14 -> 1000000 | H50: =INDEX(Monthly!$C$92:$BJ$92,($R$2-1)*12+1) -> 1000000 | I50: =INDEX(Monthly!$C$92:$BJ$92,($R$2-1)*12+2) -> 1000000 | J50: =INDEX(Monthly!$C$92:$BJ$92,($R$2-1)*12+3) -> 1000000 | K50: =INDEX(Monthly!$C$92:$BJ$92,($R$2-1)*12+4) -> 1000000 | L50: =INDEX(Monthly!$C$92:$BJ$92,($R$2-1)*12+5) -> 1000000 | M50: =INDEX(Monthly!$C$92:$BJ$92,($R$2-1)*12+6) -> 1000000 | N50: =INDEX(Monthly!$C$92:$BJ$92,($R$2-1)*12+7) -> 1000000 | O50: =INDEX(Monthly!$C$92:$BJ$92,($R$2-1)*12+8) -> 1000000 | P50: =INDEX(Monthly!$C$92:$BJ$92,($R$2-1)*12+9) -> 1000000 | Q50: =INDEX(Monthly!$C$92:$BJ$92,($R$2-1)*12+10) -> 1000000 | R50: =INDEX(Monthly!$C$92:$BJ$92,($R$2-1)*12+11) -> 1000000 | S50: =INDEX(Monthly!$C$92:$BJ$92,($R$2-1)*12+12) -> 1000000
...

Sheet Scenarios
A1: Scenario analysis | I1: =HYPERLINK("#'Cover'!A1","◂ Contents") -> ◂ Contents
A2: SaaS company — financial model
A3: Low / Base / High columns: values the model engine computed for each scenario when the file was built (prototype snapshot — the production version keeps them live). Active = live, follows Dashboard!B4.
A5: Key drivers by scenario (from Inputs)
A6: Driver | B6: Low | C6: Base | D6: High | E6: Active | F6: Unit
A7: =Inputs!A8 -> Average MRR per new customer (ARPA) | B7: =Inputs!B8 -> 230 | C7: =Inputs!C8 -> 250 | D7: =Inputs!D8 -> 270 | E7: =Inputs!E8 -> 250 | F7: =Inputs!F8 -> $ / month
A8: =Inputs!A10 -> Customer churn per month | B8: =Inputs!B10 -> 0.02 | C8: =Inputs!C10 -> 0.015 | D8: =Inputs!D10 -> 0.01 | E8: =Inputs!E10 -> 0.015 | F8: =Inputs!F10 -> %
A9: =Inputs!A12 -> Organic / referral new customers per month (year 1) | B9: =Inputs!B12 -> 30 | C9: =Inputs!C12 -> 40 | D9: =Inputs!D12 -> 50 | E9: =Inputs!E12 -> 40 | F9: =Inputs!F12 -> # / month
A10: =Inputs!A16 -> Paid customer acquisition cost (CAC) | B10: =Inputs!B16 -> 1200 | C10: =Inputs!C16 -> 1000 | D10: =Inputs!D16 -> 800 | E10: =Inputs!E16 -> 1000 | F10: =Inputs!F16 -> $
A11: =Inputs!A9 -> Price increase per year for new customers | B11: =Inputs!B9 -> 0 | C11: =Inputs!C9 -> 0.03 | D11: =Inputs!D9 -> 0.05 | E11: =Inputs!E9 -> 0.03 | F11: =Inputs!F9 -> %
A12: =Inputs!A11 -> Expansion MRR per month, % of opening MRR | B12: =Inputs!B11 -> 0 | C12: =Inputs!C11 -> 0.005 | D12: =Inputs!D11 -> 0.01 | E12: =Inputs!E11 -> 0.005 | F12: =Inputs!F11 -> %
A13: =Inputs!A18 -> Hosting & payment fees, % of revenue | B13: =Inputs!B18 -> 0.12 | C13: =Inputs!C18 -> 0.1 | D13: =Inputs!D18 -> 0.08 | E13: =Inputs!E18 -> 0.1 | F13: =Inputs!F18 -> %
A14: =Inputs!A64 -> Discount rate (WACC) | B14: =Inputs!B64 -> 0.15 | C14: =Inputs!C64 -> 0.12 | D14: =Inputs!D64 -> 0.1 | E14: =Inputs!E64 -> 0.12 | F14: =Inputs!F64 -> %
A15: =Inputs!A66 -> Exit multiple (EV ÷ final-year EBITDA) | B15: =Inputs!B66 -> 5 | C15: =Inputs!C66 -> 6 | D15: =Inputs!D66 -> 8 | E15: =Inputs!E66 -> 6 | F15: =Inputs!F66 -> x
A17: Outputs by scenario
B18: Low | C18: Base | D18: High | E18: Active
A19: Revenue — 5-year total | B19: 52979171 | C19: 87290935 | D19: 1.4747377e+08 | E19: =SUM('P&L'!B5:F5) -> 87290935
A20: Revenue — year 5 | B20: 13174504 | C20: 26732395 | D20: 53852064 | E20: ='P&L'!F5 -> 26732395
A21: EBITDA — 5-year total | B21: -13556478 | C21: 18460885 | D21: 75555334 | E21: =SUM('P&L'!B15:F15) -> 18460885
A22: EBITDA margin — year 5 | B22: -0.43761018 | C22: 0.25044286 | D22: 0.5969312 | E22: ='P&L'!F16 -> 0.25044286
A23: Net income — 5-year total | B23: -13706478 | C23: 14465599 | D23: 59570214 | E23: =SUM('P&L'!B22:F22) -> 14465599
A24: Year-end cash — year 5 | B24: -11344393 | C24: 18308468 | D24: 66488118 | E24: ='Balance Sheet'!F5 -> 18308468
A25: Lowest cash balance | B25: -11344393 | C25: 1760226.5 | D25: 1891837.2 | E25: =MIN(Monthly!$C$76:$BJ$76) -> 1760226.5
A26: Funding required (incl. buffer) | B26: 14250393 | C26: 1145773.5 | D26: 1014162.8 | E26: ='Break-even'!B12 -> 1145773.5
A27: Enterprise value (DCF, average) | B27: -24094296 | C27: 40195041 | D27: 2.4963975e+08 | E27: =Valuation!B30 -> 40195041
A29: Revenue by year and scenario ($'000)
B30: ='P&L'!B4 -> Year 1 | C30: ='P&L'!C4 -> Year 2 | D30: ='P&L'!D4 -> Year 3 | E30: ='P&L'!E4 -> Year 4 | F30: ='P&L'!F4 -> Year 5
A31: Revenue — Low | B31: 8588999.9 | C31: 9317509.2 | D31: 10310936 | E31: 11587222 | F31: 13174504
A32: Revenue — Base | B32: 10216766 | C32: 12946280 | D32: 16448495 | E32: 20947000 | F32: 26732395
A33: Revenue — High | B33: 12150000 | C33: 17947980 | D33: 26041848 | E33: 37481874 | F33: 53852064
A35: EBITDA by year and scenario ($'000)
B36: ='P&L'!B4 -> Year 1 | C36: ='P&L'!C4 -> Year 2 | D36: ='P&L'!D4 -> Year 3 | E36: ='P&L'!E4 -> Year 4 | F36: ='P&L'!F4 -> Year 5
A37: EBITDA — Low | B37: -176110.52 | C37: -1228016.7 | D37: -2453356.1 | E37: -3933697.9 | F37: -5765297.2
A38: EBITDA — Base | B38: 1493172.1 | C38: 2249612.9 | D38: 3293948.5 | E38: 4729214.2 | F38: 6694937.4
A39: EBITDA — High | B39: 3491692.1 | C39: 7119867.4 | D39: 12449911 | E39: 20347886 | F39: 32145977
A41: Net income by year and scenario ($'000)
B42: ='P&L'!B4 -> Year 1 | C42: ='P&L'!C4 -> Year 2 | D42: ='P&L'!D4 -> Year 3 | E42: ='P&L'!E4 -> Year 4 | F42: ='P&L'!F4 -> Year 5
A43: Net income — Low | B43: -226110.52 | C43: -1278016.7 | D43: -2503356.1 | E43: -3933697.9 | F43: -5765297.2
A44: Net income — Base | B44: 1140105.9 | C44: 1737694.2 | D44: 2562719.3 | E44: 3736079.2 | F44: 5289000.5
A45: Net income — High | B45: 2718936.7 | C45: 5585195.2 | D45: 9795930 | E45: 16074830 | F45: 25395322
...

Sheet Break-even
A1: Startup costs, funding need and break-even | H1: =HYPERLINK("#'Cover'!A1","◂ Contents") -> ◂ Contents
A2: Live for the selected scenario. Periods are counted in months from the start of the plan.
A3: Scenario shown | B3: =CHOOSE(Dashboard!$B$4,"Low","Base","High") -> Base
A5: Startup costs & funding need (up to the lowest cash point)
A6: Lowest cash point (month #) | B6: =MATCH(MIN(Monthly!$C$76:$BJ$76),Monthly!$C$76:$BJ$76,0) -> 1
A7: Capital spending up to the lowest cash point | B7: =SUMPRODUCT(--(Monthly!$C$4:$BJ$4<=$B$6),Monthly!$C$47:$BJ$47) -> 150000
A8: Operating cash burn up to the lowest cash point | B8: =-SUMPRODUCT(--(Monthly!$C$4:$BJ$4<=$B$6),Monthly!$C$70:$BJ$70) -> -910226.47 | D8: Losses and working capital before the business funds itself
A9: Loan repayments up to the lowest cash point | B9: =-SUMPRODUCT(--(Monthly!$C$4:$BJ$4<=$B$6),Monthly!$C$56:$BJ$56) -> 0
A10: Total uses of funds | B10: =B7+B8+B9 -> -760226.47
A11: Minimum cash buffer to keep | B11: =Inputs!$E$61 -> 1906000 | D11: Input on the Inputs sheet
A12: Funding required (uses + buffer) | B12: =B10+B11 -> 1145773.5
A14: Equity raised | B14: =Inputs!$E$46 -> 1000000
A15: Loan drawn | B15: =Inputs!$E$47 -> 0
A16: Total sources of funds | B16: =B14+B15 -> 1000000
A17: Funding surplus / (shortfall) | B17: =B16-B12 -> -145773.53 | D17: Negative = raise at least this much more
A18: Lowest cash balance in the plan | B18: =MIN(Monthly!$C$76:$BJ$76) -> 1760226.5 | D18: Equals sources minus uses
A20: Break-even timing
A21: First month with positive EBITDA (month #) | B21: =IFERROR(MATCH(1,Monthly!$C$77:$BJ$77,0),"Not within horizon") -> 1
A22: First month with positive net income (month #) | B22: =IFERROR(MATCH(1,Monthly!$C$84:$BJ$84,0),"Not within horizon") -> 1
A23: Cash invested paid back (month #) | B23: =IF(MIN(Monthly!$C$86:$BJ$86)>=0,"No investment to pay back",IFERROR(MATCH(1,Monthly!$C$88:$BJ$88,0),"Not within horizon")) -> No investment to pay back | D23: Cumulative operating + investing cash flow back to zero
A25: Annual break-even revenue
A26: Year # | B26: 1 | C26: 2 | D26: 3 | E26: 4 | F26: 5
B27: Year 1 | C27: Year 2 | D27: Year 3 | E27: Year 4 | F27: Year 5
A28: Revenue | B28: =SUMIF(Monthly!$C$5:$BJ$5,B$26,Monthly!$C$24:$BJ$24) -> 10216766 | C28: =SUMIF(Monthly!$C$5:$BJ$5,C$26,Monthly!$C$24:$BJ$24) -> 12946280 | D28: =SUMIF(Monthly!$C$5:$BJ$5,D$26,Monthly!$C$24:$BJ$24) -> 16448495 | E28: =SUMIF(Monthly!$C$5:$BJ$5,E$26,Monthly!$C$24:$BJ$24) -> 20947000 | F28: =SUMIF(Monthly!$C$5:$BJ$5,F$26,Monthly!$C$24:$BJ$24) -> 26732395
A29: Gross profit | B29: =SUMIF(Monthly!$C$5:$BJ$5,B$26,Monthly!$C$26:$BJ$26) -> 9115572.1 | C29: =SUMIF(Monthly!$C$5:$BJ$5,C$26,Monthly!$C$26:$BJ$26) -> 11555505 | D29: =SUMIF(Monthly!$C$5:$BJ$5,D$26,Monthly!$C$26:$BJ$26) -> 14686438 | E29: =SUMIF(Monthly!$C$5:$BJ$5,E$26,Monthly!$C$26:$BJ$26) -> 18708530 | F29: =SUMIF(Monthly!$C$5:$BJ$5,F$26,Monthly!$C$26:$BJ$26) -> 23881957
A30: Gross margin (contribution) | B30: =IF(B28=0,0,B29/B28) -> 0.89221699 | C30: =IF(C28=0,0,C29/C28) -> 0.8925734 | D30: =IF(D28=0,0,D29/D28) -> 0.89287426 | E30: =IF(E28=0,0,E29/E28) -> 0.89313648 | F30: =IF(F28=0,0,F29/F28) -> 0.89337139
A31: Operating expenses (treated as fixed) | B31: =-SUMIF(Monthly!$C$5:$BJ$5,B$26,Monthly!$C$34:$BJ$34) -> 7622400 | C31: =-SUMIF(Monthly!$C$5:$BJ$5,C$26,Monthly!$C$34:$BJ$34) -> 9305892 | D31: =-SUMIF(Monthly!$C$5:$BJ$5,D$26,Monthly!$C$34:$BJ$34) -> 11392489 | E31: =-SUMIF(Monthly!$C$5:$BJ$5,E$26,Monthly!$C$34:$BJ$34) -> 13979315 | F31: =-SUMIF(Monthly!$C$5:$BJ$5,F$26,Monthly!$C$34:$BJ$34) -> 17187019
A32: Break-even revenue (EBITDA = 0) | B32: =IF(B30>0,B31/B30,"n/a") -> 8543213.2 | C32: =IF(C30>0,C31/C30,"n/a") -> 10425912 | D32: =IF(D30>0,D31/D30,"n/a") -> 12759343 | E32: =IF(E30>0,E31/E30,"n/a") -> 15651936 | F32: =IF(F30>0,F31/F30,"n/a") -> 19238381
A33: Margin of safety (revenue above break-even) | B33: =IF(AND(ISNUMBER(B32),B28>0),(B28-B32)/B28,"n/a") -> 0.16380454 | C33: =IF(AND(ISNUMBER(C32),C28>0),(C28-C32)/C28,"n/a") -> 0.19467889 | D33: =IF(AND(ISNUMBER(D32),D28>0),(D28-D32)/D28,"n/a") -> 0.22428506 | E33: =IF(AND(ISNUMBER(E32),E28>0),(E28-E32)/E28,"n/a") -> 0.25278385 | F33: =IF(AND(ISNUMBER(F32),F28>0),(F28-F32)/F28,"n/a") -> 0.28033454
A35: Simplification: cost of sales is treated as variable and operating expenses as fixed, so break-even revenue = operating expenses ÷ gross margin.

Sheet Valuation
A1: Discounted cash flow valuation | H1: =HYPERLINK("#'Cover'!A1","◂ Contents") -> ◂ Contents
A2: Enterprise value at the start of the plan, before the funding raised in period 1. Year-end discounting.
A3: Scenario shown | B3: =CHOOSE(Dashboard!$B$4,"Low","Base","High") -> Base
A5: Assumptions (active scenario, from the Inputs sheet)
A6: Discount rate (WACC) | B6: =Inputs!$E$64 -> 0.12
A7: Terminal growth rate | B7: =Inputs!$E$65 -> 0.02
A8: Exit multiple (EV ÷ final-year EBITDA) | B8: =Inputs!$E$66 -> 6
A9: Tax rate (for the interest tax shield) | B9: =Inputs!$E$58 -> 0.21
A10: Sensitivity step: WACC | B10: =Inputs!$E$67 -> 0.01
A11: Sensitivity step: terminal growth | B11: =Inputs!$E$68 -> 0.005
A13: Free cash flow by year
A14: Year # | B14: 1 | C14: 2 | D14: 3 | E14: 4 | F14: 5
B15: Year 1 | C15: Year 2 | D15: Year 3 | E15: Year 4 | F15: Year 5
A16: EBITDA | B16: =SUMIF(Monthly!$C$5:$BJ$5,B$14,Monthly!$C$35:$BJ$35) -> 1493172.1 | C16: =SUMIF(Monthly!$C$5:$BJ$5,C$14,Monthly!$C$35:$BJ$35) -> 2249612.9 | D16: =SUMIF(Monthly!$C$5:$BJ$5,D$14,Monthly!$C$35:$BJ$35) -> 3293948.5 | E16: =SUMIF(Monthly!$C$5:$BJ$5,E$14,Monthly!$C$35:$BJ$35) -> 4729214.2 | F16: =SUMIF(Monthly!$C$5:$BJ$5,F$14,Monthly!$C$35:$BJ$35) -> 6694937.4
A17: Unlevered free cash flow | B17: =SUMIF(Monthly!$C$5:$BJ$5,B$14,Monthly!$C$89:$BJ$89) -> 2123134.7 | C17: =SUMIF(Monthly!$C$5:$BJ$5,C$14,Monthly!$C$89:$BJ$89) -> 2078342.8 | D17: =SUMIF(Monthly!$C$5:$BJ$5,D$14,Monthly!$C$89:$BJ$89) -> 2985771.8 | E17: =SUMIF(Monthly!$C$5:$BJ$5,E$14,Monthly!$C$89:$BJ$89) -> 4215445.8 | F17: =SUMIF(Monthly!$C$5:$BJ$5,F$14,Monthly!$C$89:$BJ$89) -> 5905773.3
A18: Discount factor | B18: =1/(1+Inputs!$E$64)^B$14 -> 0.89285714 | C18: =1/(1+Inputs!$E$64)^C$14 -> 0.79719388 | D18: =1/(1+Inputs!$E$64)^D$14 -> 0.71178025 | E18: =1/(1+Inputs!$E$64)^E$14 -> 0.63551808 | F18: =1/(1+Inputs!$E$64)^F$14 -> 0.56742686
A19: Present value of free cash flow | B19: =B17*B18 -> 1895656 | C19: =C17*C18 -> 1656842.1 | D19: =D17*D18 -> 2125213.4 | E19: =E17*E18 -> 2678992 | F19: =F17*F18 -> 3351094.4
A21: Enterprise value
B22: Perpetual growth | C22: Exit multiple
A23: Present value of the plan's free cash flows | B23: =SUM($B$19:$F$19) -> 11707798 | C23: =B23 -> 11707798
A24: Final-year free cash flow | final-year EBITDA | B24: =$F$17 -> 5905773.3 | C24: =$F$16 -> 6694937.4
A25: Terminal value at the end of year 5 | B25: =IF($B$6>$B$7,B24*(1+$B$7)/($B$6-$B$7),0) -> 60238888 | C25: =C24*$B$8 -> 40169624
A26: Present value of the terminal value | B26: =B25/(1+$B$6)^$F$14 -> 34181163 | C26: =C25/(1+$B$6)^$F$14 -> 22793324
A27: Enterprise value | B27: =B23+B26 -> 45888961 | C27: =C23+C26 -> 34501121
A28: Terminal value share of enterprise value | B28: =IF(B27<>0,B26/B27,0) -> 0.74486679 | C28: =IF(C27<>0,C26/C27,0) -> 0.66065457
A29: Cross-check: implied exit multiple | implied perpetual growth | B29: =IF(C24>0,B25/C24,"n/a") -> 8.9976776 | C29: =IF(C25+B24<>0,(C25*$B$6-B24)/(C25+B24),"n/a") -> -0.02355744
A30: Enterprise value — average of the two methods | B30: =AVERAGE(B27,C27) -> 40195041
A32: Sensitivity: enterprise value (perpetual growth) by WACC and terminal growth
A33: WACC ↓ · terminal growth → | B33: =$B$7+(-2)*$B$11 -> 0.01 | C33: =$B$7+(-1)*$B$11 -> 0.015 | D33: =$B$7+(0)*$B$11 -> 0.02 | E33: =$B$7+(1)*$B$11 -> 0.025 | F33: =$B$7+(2)*$B$11 -> 0.03
A34: =$B$6+(-2)*$B$10 -> 0.1 | B34: =IF($A34>B$33,SUMPRODUCT($B$17:$F$17/(1+$A34)^$B$14:$F$14)+$F$17*(1+B$33)/($A34-B$33)/(1+$A34)^$F$14,"n/a") -> 53589362 | C34: =IF($A34>C$33,SUMPRODUCT($B$17:$F$17/(1+$A34)^$B$14:$F$14)+$F$17*(1+C$33)/($A34-C$33)/(1+$A34)^$F$14,"n/a") -> 56225782 | D34: =IF($A34>D$33,SUMPRODUCT($B$17:$F$17/(1+$A34)^$B$14:$F$14)+$F$17*(1+D$33)/($A34-D$33)/(1+$A34)^$F$14,"n/a") -> 59191755 | E34: =IF($A34>E$33,SUMPRODUCT($B$17:$F$17/(1+$A34)^$B$14:$F$14)+$F$17*(1+E$33)/($A34-E$33)/(1+$A34)^$F$14,"n/a") -> 62553191 | F34: =IF($A34>F$33,SUMPRODUCT($B$17:$F$17/(1+$A34)^$B$14:$F$14)+$F$17*(1+F$33)/($A34-F$33)/(1+$A34)^$F$14,"n/a") -> 66394831
A35: =$B$6+(-1)*$B$10 -> 0.11 | B35: =IF($A35>B$33,SUMPRODUCT($B$17:$F$17/(1+$A35)^$B$14:$F$14)+$F$17*(1+B$33)/($A35-B$33)/(1+$A35)^$F$14,"n/a") -> 47462737 | C35: =IF($A35>C$33,SUMPRODUCT($B$17:$F$17/(1+$A35)^$B$14:$F$14)+$F$17*(1+C$33)/($A35-C$33)/(1+$A35)^$F$14,"n/a") -> 49510272 | D35: =IF($A35>D$33,SUMPRODUCT($B$17:$F$17/(1+$A35)^$B$14:$F$14)+$F$17*(1+D$33)/($A35-D$33)/(1+$A35)^$F$14,"n/a") -> 51785310 | E35: =IF($A35>E$33,SUMPRODUCT($B$17:$F$17/(1+$A35)^$B$14:$F$14)+$F$17*(1+E$33)/($A35-E$33)/(1+$A35)^$F$14,"n/a") -> 54328000 | F35: =IF($A35>F$33,SUMPRODUCT($B$17:$F$17/(1+$A35)^$B$14:$F$14)+$F$17*(1+F$33)/($A35-F$33)/(1+$A35)^$F$14,"n/a") -> 57188527
A36: =$B$6+(0)*$B$10 -> 0.12 | B36: =IF($A36>B$33,SUMPRODUCT($B$17:$F$17/(1+$A36)^$B$14:$F$14)+$F$17*(1+B$33)/($A36-B$33)/(1+$A36)^$F$14,"n/a") -> 42476937 | C36: =IF($A36>C$33,SUMPRODUCT($B$17:$F$17/(1+$A36)^$B$14:$F$14)+$F$17*(1+C$33)/($A36-C$33)/(1+$A36)^$F$14,"n/a") -> 44101710 | D36: =IF($A36>D$33,SUMPRODUCT($B$17:$F$17/(1+$A36)^$B$14:$F$14)+$F$17*(1+D$33)/($A36-D$33)/(1+$A36)^$F$14,"n/a") -> 45888961 | E36: =IF($A36>E$33,SUMPRODUCT($B$17:$F$17/(1+$A36)^$B$14:$F$14)+$F$17*(1+E$33)/($A36-E$33)/(1+$A36)^$F$14,"n/a") -> 47864343 | F36: =IF($A36>F$33,SUMPRODUCT($B$17:$F$17/(1+$A36)^$B$14:$F$14)+$F$17*(1+F$33)/($A36-F$33)/(1+$A36)^$F$14,"n/a") -> 50059212
A37: =$B$6+(1)*$B$10 -> 0.13 | B37: =IF($A37>B$33,SUMPRODUCT($B$17:$F$17/(1+$A37)^$B$14:$F$14)+$F$17*(1+B$33)/($A37-B$33)/(1+$A37)^$F$14,"n/a") -> 38345574 | C37: =IF($A37>C$33,SUMPRODUCT($B$17:$F$17/(1+$A37)^$B$14:$F$14)+$F$17*(1+C$33)/($A37-C$33)/(1+$A37)^$F$14,"n/a") -> 39657937 | D37: =IF($A37>D$33,SUMPRODUCT($B$17:$F$17/(1+$A37)^$B$14:$F$14)+$F$17*(1+D$33)/($A37-D$33)/(1+$A37)^$F$14,"n/a") -> 41089605 | E37: =IF($A37>E$33,SUMPRODUCT($B$17:$F$17/(1+$A37)^$B$14:$F$14)+$F$17*(1+E$33)/($A37-E$33)/(1+$A37)^$F$14,"n/a") -> 42657623 | F37: =IF($A37>F$33,SUMPRODUCT($B$17:$F$17/(1+$A37)^$B$14:$F$14)+$F$17*(1+F$33)/($A37-F$33)/(1+$A37)^$F$14,"n/a") -> 44382443
A38: =$B$6+(2)*$B$10 -> 0.14 | B38: =IF($A38>B$33,SUMPRODUCT($B$17:$F$17/(1+$A38)^$B$14:$F$14)+$F$17*(1+B$33)/($A38-B$33)/(1+$A38)^$F$14,"n/a") -> 34870439 | C38: =IF($A38>C$33,SUMPRODUCT($B$17:$F$17/(1+$A38)^$B$14:$F$14)+$F$17*(1+C$33)/($A38-C$33)/(1+$A38)^$F$14,"n/a") -> 35946345 | D38: =IF($A38>D$33,SUMPRODUCT($B$17:$F$17/(1+$A38)^$B$14:$F$14)+$F$17*(1+D$33)/($A38-D$33)/(1+$A38)^$F$14,"n/a") -> 37111909 | E38: =IF($A38>E$33,SUMPRODUCT($B$17:$F$17/(1+$A38)^$B$14:$F$14)+$F$17*(1+E$33)/($A38-E$33)/(1+$A38)^$F$14,"n/a") -> 38378826 | F38: =IF($A38>F$33,SUMPRODUCT($B$17:$F$17/(1+$A38)^$B$14:$F$14)+$F$17*(1+F$33)/($A38-F$33)/(1+$A38)^$F$14,"n/a") -> 39760918
A40: Free cash flow = operating cash flow + interest × (1 − tax rate) − capital spending. Cells marked n/a: WACC not above growth.

Sheet Sources & Uses
A1: Sources and uses of funds | I1: =HYPERLINK("#'Cover'!A1","◂ Contents") -> ◂ Contents
A2: SaaS company — financial model
A5: Funding structure ($'000) — raised at the start of the plan
B6: Amount | C6: Share
A7: Equity | B7: =Inputs!E46 -> 1000000 | C7: =IF($B$9=0,0,B7/$B$9) -> 1
A8: Debt (loan) | B8: =Inputs!E47 -> 0 | C8: =IF($B$9=0,0,B8/$B$9) -> 0
A9: Total funding | B9: =B7+B8 -> 1000000 | C9: =IF($B$9=0,0,B9/$B$9) -> 1
A10: Gearing (debt ÷ equity) | B10: =IF(B7=0,0,B8/B7) -> 0
A11: Funding required by the plan (Break-even sheet) | B11: ='Break-even'!B12 -> 1145773.5
A12: Surplus / (shortfall) | B12: ='Break-even'!B17 -> -145773.53
A14: ="Sources and uses — first "&$B$15&" months ($'000)" -> Sources and uses — first 12 months ($'000)
A15: Period covered (months from the start) | B15: 12
A16: Sources | B16: Amount | C16: Share | E16: Uses | F16: Amount | G16: Share
A17: Equity raised | B17: =SUMPRODUCT(--(Monthly!$C$4:$BJ$4<=$B$15),Monthly!$C$72:$BJ$72) -> 1000000 | C17: =IF($B$21=0,0,B17/$B$21) -> 0.30551752 | E17: Cash used by operations | F17: =MAX(0,-SUMPRODUCT(--(Monthly!$C$4:$BJ$4<=$B$15),Monthly!$C$70:$BJ$70)) -> 0 | G17: =IF($F$21=0,0,F17/$F$21) -> 0
A18: Loan drawdowns | B18: =SUMPRODUCT(--(Monthly!$C$4:$BJ$4<=$B$15),Monthly!$C$55:$BJ$55) -> 0 | C18: =IF($B$21=0,0,B18/$B$21) -> 0 | E18: Capital spending | F18: =-SUMPRODUCT(--(Monthly!$C$4:$BJ$4<=$B$15),Monthly!$C$71:$BJ$71) -> 150000 | G18: =IF($F$21=0,0,F18/$F$21) -> 0.045827629
A19: Cash generated by operations | B19: =MAX(0,SUMPRODUCT(--(Monthly!$C$4:$BJ$4<=$B$15),Monthly!$C$70:$BJ$70)) -> 2273134.7 | C19: =IF($B$21=0,0,B19/$B$21) -> 0.69448248 | E19: Loan repayments | F19: =-SUMPRODUCT(--(Monthly!$C$4:$BJ$4<=$B$15),Monthly!$C$56:$BJ$56) -> 0 | G19: =IF($F$21=0,0,F19/$F$21) -> 0
E20: Cash at the end of the period | F20: =INDEX(Monthly!$C$76:$BJ$76,$B$15) -> 3123134.7 | G20: =IF($F$21=0,0,F20/$F$21) -> 0.95417237
A21: Total sources | B21: =SUM(B17:B20) -> 3273134.7 | C21: =IF(B21=0,0,1) -> 1 | E21: Total uses | F21: =SUM(F17:F20) -> 3273134.7 | G21: =IF(F21=0,0,1) -> 1
A22: Sources − uses (must be 0; opening cash is 0) | B22: =B21-F21 -> 0

Sheet KPIs
A1: KPIs & ratios | I1: =HYPERLINK("#'Cover'!A1","◂ Contents") -> ◂ Contents
A2: Industry metrics and financial ratios for the active scenario.
A4: Financial ratios
B5: ='P&L'!B4 -> Year 1 | C5: ='P&L'!C4 -> Year 2 | D5: ='P&L'!D4 -> Year 3 | E5: ='P&L'!E4 -> Year 4 | F5: ='P&L'!F4 -> Year 5 | G5: Target
A6: Revenue growth | B6: - | C6: =IF('P&L'!B5=0,0,'P&L'!C5/'P&L'!B5-1) -> 0.26716027 | D6: =IF('P&L'!C5=0,0,'P&L'!D5/'P&L'!C5-1) -> 0.27051902 | E6: =IF('P&L'!D5=0,0,'P&L'!E5/'P&L'!D5-1) -> 0.27349038 | F6: =IF('P&L'!E5=0,0,'P&L'!F5/'P&L'!E5-1) -> 0.27619206
A7: Gross margin | B7: ='P&L'!B8 -> 0.89221699 | C7: ='P&L'!C8 -> 0.8925734 | D7: ='P&L'!D8 -> 0.89287426 | E7: ='P&L'!E8 -> 0.89313648 | F7: ='P&L'!F8 -> 0.89337139
A8: EBITDA margin | B8: ='P&L'!B16 -> 0.14614919 | C8: ='P&L'!C16 -> 0.1737652 | D8: ='P&L'!D16 -> 0.20025835 | E8: ='P&L'!E16 -> 0.22577048 | F8: ='P&L'!F16 -> 0.25044286
A9: Net margin | B9: ='P&L'!B23 -> 0.11159167 | C9: ='P&L'!C23 -> 0.13422344 | D9: ='P&L'!D23 -> 0.15580266 | E9: ='P&L'!E23 -> 0.17835868 | F9: ='P&L'!F23 -> 0.19784986
A10: Payroll, % of revenue | B10: =IF('P&L'!B5=0,0,-'P&L'!B9/'P&L'!B5) -> 0.61428442 | C10: =IF('P&L'!C5=0,0,-'P&L'!C9/'P&L'!C5) -> 0.60239329 | D10: =IF('P&L'!D5=0,0,-'P&L'!D9/'P&L'!D5) -> 0.58926621 | E10: =IF('P&L'!E5=0,0,-'P&L'!E9/'P&L'!E5) -> 0.57517035 | F10: =IF('P&L'!F5=0,0,-'P&L'!F9/'P&L'!F5) -> 0.56030797
A11: Paid marketing, % of revenue | B11: =IF('P&L'!B5=0,0,-'P&L'!B10/'P&L'!B5) -> 0.070472399 | C11: =IF('P&L'!C5=0,0,-'P&L'!C10/'P&L'!C5) -> 0.066737319 | D11: =IF('P&L'!D5=0,0,-'P&L'!D10/'P&L'!D5) -> 0.063033124 | E11: =IF('P&L'!E5=0,0,-'P&L'!E10/'P&L'!E5) -> 0.059395618 | F11: =IF('P&L'!F5=0,0,-'P&L'!F10/'P&L'!F5) -> 0.055849542
A12: Operating expenses, % of revenue | B12: =IF('P&L'!B5=0,0,-'P&L'!B14/'P&L'!B5) -> 0.7460678 | C12: =IF('P&L'!C5=0,0,-'P&L'!C14/'P&L'!C5) -> 0.7188082 | D12: =IF('P&L'!D5=0,0,-'P&L'!D14/'P&L'!D5) -> 0.69261591 | E12: =IF('P&L'!E5=0,0,-'P&L'!E14/'P&L'!E5) -> 0.667366 | F12: =IF('P&L'!F5=0,0,-'P&L'!F14/'P&L'!F5) -> 0.64292853
