Workbook

Sheet Cover
B2: Auto repair shop financial model (planning)
B3: 5-year financial model · monthly detail · Low / Base / High scenarios · US dollars · Full plan
B5: Purpose | D5: Revenue and profit plan
B6: Active scenario | D6: =Dashboard!C4&" (change it on the Dashboard, cell B4)" -> Base (change it on the Dashboard, cell B4)
B7: Model checks | D7: =Checks!B25 -> PASS
B8: Prepared | D8: 22 October 2026
B10: Contents
C11: PRESENTATION
B12: 1 | C12: =HYPERLINK("#Dashboard!A1","Dashboard") -> Dashboard | D12: Scenario switch, key numbers, core financials
B13: 2 | C13: =HYPERLINK("#Summary!A1","Summary") -> Summary | D13: Income statement, cash flow and balance sheet — every year and any year by month
B14: 3 | C14: =HYPERLINK("#Scenarios!A1","Scenarios") -> Scenarios | D14: Low / Base / High side by side: drivers, outputs, charts
B15: 4 | C15: =HYPERLINK("#'Break-even'!A1","Break-even") -> Break-even | D15: Startup costs, funding need, break-even timing and revenue
B16: 5 | C16: =HYPERLINK("#Valuation!A1","Valuation") -> Valuation | D16: Free cash flow, DCF (perpetual growth and exit multiple), WACC × growth sensitivity
B17: 6 | C17: =HYPERLINK("#'Sources & Uses'!A1","Sources & Uses") -> Sources & Uses | D17: Funding structure, sources and uses of cash for the first months
B18: 7 | C18: =HYPERLINK("#KPIs!A1","KPIs") -> KPIs | D18: Financial ratios, DuPont analysis, industry metrics
C19: INPUTS
B20: 8 | C20: =HYPERLINK("#Inputs!A1","Inputs") -> Inputs | D20: Every assumption, Low / Base / High, with units and comments
C21: STATEMENTS
B22: 9 | C22: =HYPERLINK("#'P&L'!A1","P&L") -> P&L | D22: Annual profit & loss
B23: 10 | C23: =HYPERLINK("#'Cash Flow'!A1","Cash Flow") -> Cash Flow | D23: Annual cash flow statement
B24: 11 | C24: =HYPERLINK("#'Balance Sheet'!A1","Balance Sheet") -> Balance Sheet | D24: Balance sheet at year end
C25: CALCULATIONS
B26: 12 | C26: =HYPERLINK("#Monthly!A1","Monthly") -> Monthly | D26: Month-by-month engine of the model
B27: 13 | C27: =HYPERLINK("#Headcount!A1","Headcount") -> Headcount | D27: Team and payroll
B28: 14 | C28: =HYPERLINK("#'Scenario calc'!A1","Scenario calc") -> Scenario calc | D28: Low, Base and High calculated side by side for the Scenarios sheet
C29: CONTROL
B30: 15 | C30: =HYPERLINK("#Checks!A1","Checks") -> Checks | D30: Live integrity checks and the overall verdict
B32: How to read this file
C33: 1000 | D33: Input you can change — yellow cell with a blue figure (Inputs sheet and the view switches)
C34: 1000 | D34: Formula — calculated, do not overwrite
C35: 1000 | D35: Link to another sheet
C36: 1000 | D36: Active value the model uses (follows the scenario)

Sheet Dashboard
A1: Dashboard | W1: =HYPERLINK("#'Cover'!A1","◂ Contents") -> ◂ Contents
A2: Auto repair shop financial model (planning)
A4: Active scenario | B4: 2 | C4: =CHOOSE(B4,"Low","Base","High") -> Base | D4: 1 = Low · 2 = Base · 3 = High — every sheet follows this cell | S4: Model checks | T4: =Checks!B25 -> PASS
A6: REVENUE · YEAR 5 | C6: EBITDA MARGIN · YEAR 5 | H6: NET INCOME · YEAR 5 | L6: LOWEST CASH BALANCE | P6: FUNDING REQUIRED | T6: ENTERPRISE VALUE (DCF)
A7: =F12 -> 2372818.7 | C7: =F17 -> 0.19822375 | H7: =F18 -> 319393.4 | L7: =F39 -> 83558.366 | P7: =F37 -> 824441.63 | T7: =F44 -> 644631.29
A8: =IF(AND(B12>0,F12>=0),(F12/B12)^(1/4)-1,"CAGR n/a") -> 0.17043825 | C8: =F16 -> 470349.01 | H8: =F19 -> 0.13460506 | L8: ='Break-even'!B6 -> 10 | P8: =IF(F38>=0,"Covered by funding raised",-F38) -> 94441.634 | T8: Average of 2 methods
A10: Core financials ($'000) — active scenario
B11: 1 | C11: 2 | D11: 3 | E11: 4 | F11: 5
A12: Revenue | B12: =SUMIF(Monthly!$C$5:$BJ$5,B$11,Monthly!$C$28:$BJ$28) -> 1264359.4 | C12: =SUMIF(Monthly!$C$5:$BJ$5,C$11,Monthly!$C$28:$BJ$28) -> 1987198.3 | D12: =SUMIF(Monthly!$C$5:$BJ$5,D$11,Monthly!$C$28:$BJ$28) -> 2108218.7 | E12: =SUMIF(Monthly!$C$5:$BJ$5,E$11,Monthly!$C$28:$BJ$28) -> 2236609.2 | F12: =SUMIF(Monthly!$C$5:$BJ$5,F$11,Monthly!$C$28:$BJ$28) -> 2372818.7
A13: Gross profit | B13: =SUMIF(Monthly!$C$5:$BJ$5,B$11,Monthly!$C$36:$BJ$36) -> 481658.44 | C13: =SUMIF(Monthly!$C$5:$BJ$5,C$11,Monthly!$C$36:$BJ$36) -> 999978.46 | D13: =SUMIF(Monthly!$C$5:$BJ$5,D$11,Monthly!$C$36:$BJ$36) -> 1075151.6 | E13: =SUMIF(Monthly!$C$5:$BJ$5,E$11,Monthly!$C$36:$BJ$36) -> 1155330.9 | F13: =SUMIF(Monthly!$C$5:$BJ$5,F$11,Monthly!$C$36:$BJ$36) -> 1240834.3
A14: Gross margin | B14: =IF(B12=0,0,B13/B12) -> 0.38095058 | C14: =IF(C12=0,0,C13/C12) -> 0.5032102 | D14: =IF(D12=0,0,D13/D12) -> 0.50998104 | E14: =IF(E12=0,0,E13/E12) -> 0.51655467 | F14: =IF(F12=0,0,F13/F12) -> 0.52293683
A15: Operating expenses | B15: =SUMIF(Monthly!$C$5:$BJ$5,B$11,Monthly!$C$45:$BJ$45) -> -712680.78 | C15: =SUMIF(Monthly!$C$5:$BJ$5,C$11,Monthly!$C$45:$BJ$45) -> -735288.45 | D15: =SUMIF(Monthly!$C$5:$BJ$5,D$11,Monthly!$C$45:$BJ$45) -> -743733.24 | E15: =SUMIF(Monthly!$C$5:$BJ$5,E$11,Monthly!$C$45:$BJ$45) -> -755634.75 | F15: =SUMIF(Monthly!$C$5:$BJ$5,F$11,Monthly!$C$45:$BJ$45) -> -770485.29
A16: EBITDA | B16: =SUMIF(Monthly!$C$5:$BJ$5,B$11,Monthly!$C$46:$BJ$46) -> -231022.34 | C16: =SUMIF(Monthly!$C$5:$BJ$5,C$11,Monthly!$C$46:$BJ$46) -> 264690.01 | D16: =SUMIF(Monthly!$C$5:$BJ$5,D$11,Monthly!$C$46:$BJ$46) -> 331418.32 | E16: =SUMIF(Monthly!$C$5:$BJ$5,E$11,Monthly!$C$46:$BJ$46) -> 399696.18 | F16: =SUMIF(Monthly!$C$5:$BJ$5,F$11,Monthly!$C$46:$BJ$46) -> 470349.01
A17: EBITDA margin | B17: =IF(B12=0,0,B16/B12) -> -0.18271889 | C17: =IF(C12=0,0,C16/C12) -> 0.13319758 | D17: =IF(D12=0,0,D16/D12) -> 0.15720301 | E17: =IF(E12=0,0,E16/E12) -> 0.17870631 | F17: =IF(F12=0,0,F16/F12) -> 0.19822375
A18: Net income | B18: =SUMIF(Monthly!$C$5:$BJ$5,B$11,Monthly!$C$55:$BJ$55) -> -299921.9 | C18: =SUMIF(Monthly!$C$5:$BJ$5,C$11,Monthly!$C$55:$BJ$55) -> 196493.58 | D18: =SUMIF(Monthly!$C$5:$BJ$5,D$11,Monthly!$C$55:$BJ$55) -> 230229.53 | E18: =SUMIF(Monthly!$C$5:$BJ$5,E$11,Monthly!$C$55:$BJ$55) -> 263013.37 | F18: =SUMIF(Monthly!$C$5:$BJ$5,F$11,Monthly!$C$55:$BJ$55) -> 319393.4
A19: Net margin | B19: =IF(B12=0,0,B18/B12) -> -0.23721254 | C19: =IF(C12=0,0,C18/C12) -> 0.098879705 | D19: =IF(D12=0,0,D18/D12) -> 0.10920571 | E19: =IF(E12=0,0,E18/E12) -> 0.11759469 | F19: =IF(F12=0,0,F18/F12) -> 0.13460506
A20: Operating cash flow | B20: =SUMIF(Monthly!$C$5:$BJ$5,B$11,Monthly!$C$85:$BJ$85) -> -223610.34 | C20: =SUMIF(Monthly!$C$5:$BJ$5,C$11,Monthly!$C$85:$BJ$85) -> 248240.76 | D20: =SUMIF(Monthly!$C$5:$BJ$5,D$11,Monthly!$C$85:$BJ$85) -> 284136.04 | E20: =SUMIF(Monthly!$C$5:$BJ$5,E$11,Monthly!$C$85:$BJ$85) -> 319470.09 | F20: =SUMIF(Monthly!$C$5:$BJ$5,F$11,Monthly!$C$85:$BJ$85) -> 378402.78
A21: Investing cash flow | B21: =SUMIF(Monthly!$C$5:$BJ$5,B$11,Monthly!$C$86:$BJ$86) -> -382000 | C21: =SUMIF(Monthly!$C$5:$BJ$5,C$11,Monthly!$C$86:$BJ$86) -> -20000 | D21: =SUMIF(Monthly!$C$5:$BJ$5,D$11,Monthly!$C$86:$BJ$86) -> -20000 | E21: =SUMIF(Monthly!$C$5:$BJ$5,E$11,Monthly!$C$86:$BJ$86) -> -20000 | F21: =SUMIF(Monthly!$C$5:$BJ$5,F$11,Monthly!$C$86:$BJ$86) -> -20000
A22: Financing cash flow | B22: =SUMIF(Monthly!$C$5:$BJ$5,B$11,Monthly!$C$88:$BJ$88) -> 697261.9 | C22: =SUMIF(Monthly!$C$5:$BJ$5,C$11,Monthly!$C$88:$BJ$88) -> -35714.286 | D22: =SUMIF(Monthly!$C$5:$BJ$5,D$11,Monthly!$C$88:$BJ$88) -> -35714.286 | E22: =SUMIF(Monthly!$C$5:$BJ$5,E$11,Monthly!$C$88:$BJ$88) -> -35714.286 | F22: =SUMIF(Monthly!$C$5:$BJ$5,F$11,Monthly!$C$88:$BJ$88) -> -35714.286
A23: Net change in cash | B23: =SUMIF(Monthly!$C$5:$BJ$5,B$11,Monthly!$C$89:$BJ$89) -> 91651.565 | C23: =SUMIF(Monthly!$C$5:$BJ$5,C$11,Monthly!$C$89:$BJ$89) -> 192526.47 | D23: =SUMIF(Monthly!$C$5:$BJ$5,D$11,Monthly!$C$89:$BJ$89) -> 228421.75 | E23: =SUMIF(Monthly!$C$5:$BJ$5,E$11,Monthly!$C$89:$BJ$89) -> 263755.81 | F23: =SUMIF(Monthly!$C$5:$BJ$5,F$11,Monthly!$C$89:$BJ$89) -> 322688.49
A24: Year-end cash | B24: =INDEX(Monthly!$C$91:$BJ$91,B$11*12) -> 91651.565 | C24: =INDEX(Monthly!$C$91:$BJ$91,C$11*12) -> 284178.03 | D24: =INDEX(Monthly!$C$91:$BJ$91,D$11*12) -> 512599.78 | E24: =INDEX(Monthly!$C$91:$BJ$91,E$11*12) -> 776355.59 | F24: =INDEX(Monthly!$C$91:$BJ$91,F$11*12) -> 1099044.1
A26: Auto repair metrics
B27: 1 | C27: 2 | D27: 3 | E27: 4 | F27: 5
A28: Billed labor hours | B28: =KPIs!B31 -> 5467.5 | C28: =KPIs!C31 -> 8343 | D28: =KPIs!D31 -> 8593.29 | E28: =KPIs!E31 -> 8851.0887 | F28: =KPIs!F31 -> 9116.6214
A29: Shop capacity used | B29: =KPIs!B33 -> 0.51775568 | C29: =KPIs!C33 -> 0.79005682 | D29: =KPIs!D33 -> 0.81375852 | E29: =KPIs!E33 -> 0.83817128 | F29: =KPIs!F33 -> 0.86331642
A30: Revenue per repair order | B30: =KPIs!B40 -> 462.5 | C30: =KPIs!C40 -> 476.375 | D30: =KPIs!D40 -> 490.66625 | E30: =KPIs!E40 -> 505.38624 | F30: =KPIs!F40 -> 520.54782
A31: Revenue per billed hour | B31: =KPIs!B41 -> 231.25 | C31: =KPIs!C41 -> 238.1875 | D31: =KPIs!D41 -> 245.33312 | E31: =KPIs!E41 -> 252.69312 | F31: =KPIs!F41 -> 260.27391
A32: Team (FTE, year end) | B32: =INDEX(Headcount!$C$11:$BJ$11,B$27*12) -> 8 | C32: =INDEX(Headcount!$C$11:$BJ$11,C$27*12) -> 8 | D32: =INDEX(Headcount!$C$11:$BJ$11,D$27*12) -> 8 | E32: =INDEX(Headcount!$C$11:$BJ$11,E$27*12) -> 8 | F32: =INDEX(Headcount!$C$11:$BJ$11,F$27*12) -> 8
A34: Funding & valuation ($'000) — active scenario
A35: Equity raised | F35: =Inputs!$E$67 -> 480000
A36: Loan drawn | F36: =Inputs!$E$68 -> 250000
A37: Funding required (incl. cash buffer) | F37: ='Break-even'!B12 -> 824441.63
A38: Funding surplus / (shortfall) | F38: ='Break-even'!B17 -> -94441.634
A39: ="Lowest cash balance (month "&'Break-even'!B6&")" -> Lowest cash balance (month 10) | F39: ='Break-even'!B18 -> 83558.366
A40: First month with positive EBITDA | F40: ='Break-even'!B21 -> 10
A41: Cash invested paid back | F41: ='Break-even'!B23 -> 41
A42: Enterprise value — perpetual growth | F42: =Valuation!B27 -> 601563.28
A43: Enterprise value — exit multiple | F43: =Valuation!C27 -> 687699.3
A44: Enterprise value — average | F44: =Valuation!B30 -> 644631.29

Sheet Summary
A1: Financial statements summary | U1: =HYPERLINK("#'Cover'!A1","◂ Contents") -> ◂ Contents
A2: Auto repair shop financial model (planning) | P2: Select detailed year: | R2: 1
A5: Income statement ($'000) — by year | H5: ="Income statement ($'000) — Year "&$R$2&", by month" -> Income statement ($'000) — Year 1, by month
B6: 1 | C6: 2 | D6: 3 | E6: 4 | F6: 5 | H6: =INDEX(Monthly!$C$4:$BJ$4,($R$2-1)*12+1) -> 1 | I6: =INDEX(Monthly!$C$4:$BJ$4,($R$2-1)*12+2) -> 2 | J6: =INDEX(Monthly!$C$4:$BJ$4,($R$2-1)*12+3) -> 3 | K6: =INDEX(Monthly!$C$4:$BJ$4,($R$2-1)*12+4) -> 4 | L6: =INDEX(Monthly!$C$4:$BJ$4,($R$2-1)*12+5) -> 5 | M6: =INDEX(Monthly!$C$4:$BJ$4,($R$2-1)*12+6) -> 6 | N6: =INDEX(Monthly!$C$4:$BJ$4,($R$2-1)*12+7) -> 7 | O6: =INDEX(Monthly!$C$4:$BJ$4,($R$2-1)*12+8) -> 8 | P6: =INDEX(Monthly!$C$4:$BJ$4,($R$2-1)*12+9) -> 9 | Q6: =INDEX(Monthly!$C$4:$BJ$4,($R$2-1)*12+10) -> 10 | R6: =INDEX(Monthly!$C$4:$BJ$4,($R$2-1)*12+11) -> 11 | S6: =INDEX(Monthly!$C$4:$BJ$4,($R$2-1)*12+12) -> 12
A7: Revenue | B7: ='P&L'!B5 -> 1264359.4 | C7: ='P&L'!C5 -> 1987198.3 | D7: ='P&L'!D5 -> 2108218.7 | E7: ='P&L'!E5 -> 2236609.2 | F7: ='P&L'!F5 -> 2372818.7 | H7: =INDEX(Monthly!$C$28:$BJ$28,($R$2-1)*12+1) -> 62437.5 | I7: =INDEX(Monthly!$C$28:$BJ$28,($R$2-1)*12+2) -> 70242.188 | J7: =INDEX(Monthly!$C$28:$BJ$28,($R$2-1)*12+3) -> 78046.875 | K7: =INDEX(Monthly!$C$28:$BJ$28,($R$2-1)*12+4) -> 85851.562 | L7: =INDEX(Monthly!$C$28:$BJ$28,($R$2-1)*12+5) -> 93656.25 | M7: =INDEX(Monthly!$C$28:$BJ$28,($R$2-1)*12+6) -> 101460.94 | N7: =INDEX(Monthly!$C$28:$BJ$28,($R$2-1)*12+7) -> 109265.62 | O7: =INDEX(Monthly!$C$28:$BJ$28,($R$2-1)*12+8) -> 117070.31 | P7: =INDEX(Monthly!$C$28:$BJ$28,($R$2-1)*12+9) -> 124875 | Q7: =INDEX(Monthly!$C$28:$BJ$28,($R$2-1)*12+10) -> 132679.69 | R7: =INDEX(Monthly!$C$28:$BJ$28,($R$2-1)*12+11) -> 140484.38 | S7: =INDEX(Monthly!$C$28:$BJ$28,($R$2-1)*12+12) -> 148289.06
A8: Cost of sales | B8: ='P&L'!B6 -> -782700.94 | C8: ='P&L'!C6 -> -987219.85 | D8: ='P&L'!D6 -> -1033067.1 | E8: ='P&L'!E6 -> -1081278.3 | F8: ='P&L'!F6 -> -1131984.4 | H8: =INDEX(Monthly!$C$35:$BJ$35,($R$2-1)*12+1) -> -53878.75 | I8: =INDEX(Monthly!$C$35:$BJ$35,($R$2-1)*12+2) -> -55941.719 | J8: =INDEX(Monthly!$C$35:$BJ$35,($R$2-1)*12+3) -> -58004.688 | K8: =INDEX(Monthly!$C$35:$BJ$35,($R$2-1)*12+4) -> -60067.656 | L8: =INDEX(Monthly!$C$35:$BJ$35,($R$2-1)*12+5) -> -62130.625 | M8: =INDEX(Monthly!$C$35:$BJ$35,($R$2-1)*12+6) -> -64193.594 | N8: =INDEX(Monthly!$C$35:$BJ$35,($R$2-1)*12+7) -> -66256.562 | O8: =INDEX(Monthly!$C$35:$BJ$35,($R$2-1)*12+8) -> -68319.531 | P8: =INDEX(Monthly!$C$35:$BJ$35,($R$2-1)*12+9) -> -70382.5 | Q8: =INDEX(Monthly!$C$35:$BJ$35,($R$2-1)*12+10) -> -72445.469 | R8: =INDEX(Monthly!$C$35:$BJ$35,($R$2-1)*12+11) -> -74508.438 | S8: =INDEX(Monthly!$C$35:$BJ$35,($R$2-1)*12+12) -> -76571.406
A9: Gross profit | B9: ='P&L'!B7 -> 481658.44 | C9: ='P&L'!C7 -> 999978.46 | D9: ='P&L'!D7 -> 1075151.6 | E9: ='P&L'!E7 -> 1155330.9 | F9: ='P&L'!F7 -> 1240834.3 | H9: =INDEX(Monthly!$C$36:$BJ$36,($R$2-1)*12+1) -> 8558.75 | I9: =INDEX(Monthly!$C$36:$BJ$36,($R$2-1)*12+2) -> 14300.469 | J9: =INDEX(Monthly!$C$36:$BJ$36,($R$2-1)*12+3) -> 20042.188 | K9: =INDEX(Monthly!$C$36:$BJ$36,($R$2-1)*12+4) -> 25783.906 | L9: =INDEX(Monthly!$C$36:$BJ$36,($R$2-1)*12+5) -> 31525.625 | M9: =INDEX(Monthly!$C$36:$BJ$36,($R$2-1)*12+6) -> 37267.344 | N9: =INDEX(Monthly!$C$36:$BJ$36,($R$2-1)*12+7) -> 43009.062 | O9: =INDEX(Monthly!$C$36:$BJ$36,($R$2-1)*12+8) -> 48750.781 | P9: =INDEX(Monthly!$C$36:$BJ$36,($R$2-1)*12+9) -> 54492.5 | Q9: =INDEX(Monthly!$C$36:$BJ$36,($R$2-1)*12+10) -> 60234.219 | R9: =INDEX(Monthly!$C$36:$BJ$36,($R$2-1)*12+11) -> 65975.938 | S9: =INDEX(Monthly!$C$36:$BJ$36,($R$2-1)*12+12) -> 71717.656
A10: Gross margin | B10: ='P&L'!B8 -> 0.38095058 | C10: ='P&L'!C8 -> 0.5032102 | D10: ='P&L'!D8 -> 0.50998104 | E10: ='P&L'!E8 -> 0.51655467 | F10: ='P&L'!F8 -> 0.52293683 | H10: =IF(H7=0,0,H9/H7) -> 0.13707708 | I10: =IF(I7=0,0,I9/I7) -> 0.20358803 | J10: =IF(J7=0,0,J9/J7) -> 0.2567968 | K10: =IF(K7=0,0,K9/K7) -> 0.30033124 | L10: =IF(L7=0,0,L9/L7) -> 0.33660994 | M10: =IF(M7=0,0,M9/M7) -> 0.36730731 | N10: =IF(N7=0,0,N9/N7) -> 0.39361933 | O10: =IF(O7=0,0,O9/O7) -> 0.41642309 | ... S10: =IF(S7=0,0,S9/S7) -> 0.48363416
A11: Total operating expenses | B11: ='P&L'!B15 -> -712680.78 | C11: ='P&L'!C15 -> -735288.45 | D11: ='P&L'!D15 -> -743733.24 | E11: ='P&L'!E15 -> -755634.75 | F11: ='P&L'!F15 -> -770485.29 | H11: =INDEX(Monthly!$C$45:$BJ$45,($R$2-1)*12+1) -> -58102.292 | I11: =INDEX(Monthly!$C$45:$BJ$45,($R$2-1)*12+2) -> -58336.432 | J11: =INDEX(Monthly!$C$45:$BJ$45,($R$2-1)*12+3) -> -58570.573 | K11: =INDEX(Monthly!$C$45:$BJ$45,($R$2-1)*12+4) -> -58804.714 | L11: =INDEX(Monthly!$C$45:$BJ$45,($R$2-1)*12+5) -> -59038.854 | M11: =INDEX(Monthly!$C$45:$BJ$45,($R$2-1)*12+6) -> -59272.995 | N11: =INDEX(Monthly!$C$45:$BJ$45,($R$2-1)*12+7) -> -59507.135 | O11: =INDEX(Monthly!$C$45:$BJ$45,($R$2-1)*12+8) -> -59741.276 | P11: =INDEX(Monthly!$C$45:$BJ$45,($R$2-1)*12+9) -> -59975.417 | Q11: =INDEX(Monthly!$C$45:$BJ$45,($R$2-1)*12+10) -> -60209.557 | R11: =INDEX(Monthly!$C$45:$BJ$45,($R$2-1)*12+11) -> -60443.698 | S11: =INDEX(Monthly!$C$45:$BJ$45,($R$2-1)*12+12) -> -60677.839
A12: EBITDA | B12: ='P&L'!B16 -> -231022.34 | C12: ='P&L'!C16 -> 264690.01 | D12: ='P&L'!D16 -> 331418.32 | E12: ='P&L'!E16 -> 399696.18 | F12: ='P&L'!F16 -> 470349.01 | H12: =INDEX(Monthly!$C$46:$BJ$46,($R$2-1)*12+1) -> -49543.542 | I12: =INDEX(Monthly!$C$46:$BJ$46,($R$2-1)*12+2) -> -44035.964 | J12: =INDEX(Monthly!$C$46:$BJ$46,($R$2-1)*12+3) -> -38528.385 | K12: =INDEX(Monthly!$C$46:$BJ$46,($R$2-1)*12+4) -> -33020.807 | L12: =INDEX(Monthly!$C$46:$BJ$46,($R$2-1)*12+5) -> -27513.229 | M12: =INDEX(Monthly!$C$46:$BJ$46,($R$2-1)*12+6) -> -22005.651 | N12: =INDEX(Monthly!$C$46:$BJ$46,($R$2-1)*12+7) -> -16498.073 | O12: =INDEX(Monthly!$C$46:$BJ$46,($R$2-1)*12+8) -> -10990.495 | P12: =INDEX(Monthly!$C$46:$BJ$46,($R$2-1)*12+9) -> -5482.9167 | Q12: =INDEX(Monthly!$C$46:$BJ$46,($R$2-1)*12+10) -> 24.661458 | R12: =INDEX(Monthly!$C$46:$BJ$46,($R$2-1)*12+11) -> 5532.2396 | S12: =INDEX(Monthly!$C$46:$BJ$46,($R$2-1)*12+12) -> 11039.818
A13: EBITDA margin | B13: ='P&L'!B17 -> -0.18271889 | C13: ='P&L'!C17 -> 0.13319758 | D13: ='P&L'!D17 -> 0.15720301 | E13: ='P&L'!E17 -> 0.17870631 | F13: ='P&L'!F17 -> 0.19822375 | H13: =IF(H7=0,0,H12/H7) -> -0.79349016 | I13: =IF(I7=0,0,I12/I7) -> -0.62691618 | J13: =IF(J7=0,0,J12/J7) -> -0.49365699 | K13: =IF(K7=0,0,K12/K7) -> -0.38462675 | L13: =IF(L7=0,0,L12/L7) -> -0.29376821 | M13: =IF(M7=0,0,M12/M7) -> -0.21688791 | N13: =IF(N7=0,0,N12/N7) -> -0.15099051 | O13: =IF(O7=0,0,O12/O7) -> -0.093879435 | ... S13: =IF(S7=0,0,S12/S7) -> 0.074447957
A14: Depreciation | B14: ='P&L'!B18 -> -47750 | C14: ='P&L'!C18 -> -50250 | D14: ='P&L'!D18 -> -52750 | E14: ='P&L'!E18 -> -55250 | F14: ='P&L'!F18 -> -57750 | H14: =INDEX(Monthly!$C$66:$BJ$66,($R$2-1)*12+1) -> -3979.1667 | I14: =INDEX(Monthly!$C$66:$BJ$66,($R$2-1)*12+2) -> -3979.1667 | J14: =INDEX(Monthly!$C$66:$BJ$66,($R$2-1)*12+3) -> -3979.1667 | K14: =INDEX(Monthly!$C$66:$BJ$66,($R$2-1)*12+4) -> -3979.1667 | L14: =INDEX(Monthly!$C$66:$BJ$66,($R$2-1)*12+5) -> -3979.1667 | M14: =INDEX(Monthly!$C$66:$BJ$66,($R$2-1)*12+6) -> -3979.1667 | N14: =INDEX(Monthly!$C$66:$BJ$66,($R$2-1)*12+7) -> -3979.1667 | O14: =INDEX(Monthly!$C$66:$BJ$66,($R$2-1)*12+8) -> -3979.1667 | P14: =INDEX(Monthly!$C$66:$BJ$66,($R$2-1)*12+9) -> -3979.1667 | Q14: =INDEX(Monthly!$C$66:$BJ$66,($R$2-1)*12+10) -> -3979.1667 | R14: =INDEX(Monthly!$C$66:$BJ$66,($R$2-1)*12+11) -> -3979.1667 | S14: =INDEX(Monthly!$C$66:$BJ$66,($R$2-1)*12+12) -> -3979.1667
A15: EBIT | B15: ='P&L'!B19 -> -278772.34 | C15: ='P&L'!C19 -> 214440.01 | D15: ='P&L'!D19 -> 278668.32 | E15: ='P&L'!E19 -> 344446.18 | F15: ='P&L'!F19 -> 412599.01 | H15: =INDEX(Monthly!$C$49:$BJ$49,($R$2-1)*12+1) -> -53522.708 | I15: =INDEX(Monthly!$C$49:$BJ$49,($R$2-1)*12+2) -> -48015.13 | J15: =INDEX(Monthly!$C$49:$BJ$49,($R$2-1)*12+3) -> -42507.552 | K15: =INDEX(Monthly!$C$49:$BJ$49,($R$2-1)*12+4) -> -36999.974 | L15: =INDEX(Monthly!$C$49:$BJ$49,($R$2-1)*12+5) -> -31492.396 | M15: =INDEX(Monthly!$C$49:$BJ$49,($R$2-1)*12+6) -> -25984.818 | N15: =INDEX(Monthly!$C$49:$BJ$49,($R$2-1)*12+7) -> -20477.24 | O15: =INDEX(Monthly!$C$49:$BJ$49,($R$2-1)*12+8) -> -14969.661 | P15: =INDEX(Monthly!$C$49:$BJ$49,($R$2-1)*12+9) -> -9462.0833 | Q15: =INDEX(Monthly!$C$49:$BJ$49,($R$2-1)*12+10) -> -3954.5052 | R15: =INDEX(Monthly!$C$49:$BJ$49,($R$2-1)*12+11) -> 1553.0729 | S15: =INDEX(Monthly!$C$49:$BJ$49,($R$2-1)*12+12) -> 7060.651
A16: Interest | B16: ='P&L'!B20 -> -21149.554 | C16: ='P&L'!C20 -> -17946.429 | D16: ='P&L'!D20 -> -14732.143 | E16: ='P&L'!E20 -> -11517.857 | F16: ='P&L'!F20 -> -8303.5714 | H16: =INDEX(Monthly!$C$50:$BJ$50,($R$2-1)*12+1) -> -1875 | I16: =INDEX(Monthly!$C$50:$BJ$50,($R$2-1)*12+2) -> -1863.8393 | J16: =INDEX(Monthly!$C$50:$BJ$50,($R$2-1)*12+3) -> -1841.5179 | K16: =INDEX(Monthly!$C$50:$BJ$50,($R$2-1)*12+4) -> -1819.1964 | L16: =INDEX(Monthly!$C$50:$BJ$50,($R$2-1)*12+5) -> -1796.875 | M16: =INDEX(Monthly!$C$50:$BJ$50,($R$2-1)*12+6) -> -1774.5536 | N16: =INDEX(Monthly!$C$50:$BJ$50,($R$2-1)*12+7) -> -1752.2321 | O16: =INDEX(Monthly!$C$50:$BJ$50,($R$2-1)*12+8) -> -1729.9107 | P16: =INDEX(Monthly!$C$50:$BJ$50,($R$2-1)*12+9) -> -1707.5893 | Q16: =INDEX(Monthly!$C$50:$BJ$50,($R$2-1)*12+10) -> -1685.2679 | R16: =INDEX(Monthly!$C$50:$BJ$50,($R$2-1)*12+11) -> -1662.9464 | S16: =INDEX(Monthly!$C$50:$BJ$50,($R$2-1)*12+12) -> -1640.625
A17: Pre-tax income | B17: ='P&L'!B21 -> -299921.9 | C17: ='P&L'!C21 -> 196493.58 | D17: ='P&L'!D21 -> 263936.18 | E17: ='P&L'!E21 -> 332928.32 | F17: ='P&L'!F21 -> 404295.44 | H17: =INDEX(Monthly!$C$51:$BJ$51,($R$2-1)*12+1) -> -55397.708 | I17: =INDEX(Monthly!$C$51:$BJ$51,($R$2-1)*12+2) -> -49878.969 | J17: =INDEX(Monthly!$C$51:$BJ$51,($R$2-1)*12+3) -> -44349.07 | K17: =INDEX(Monthly!$C$51:$BJ$51,($R$2-1)*12+4) -> -38819.17 | L17: =INDEX(Monthly!$C$51:$BJ$51,($R$2-1)*12+5) -> -33289.271 | M17: =INDEX(Monthly!$C$51:$BJ$51,($R$2-1)*12+6) -> -27759.371 | N17: =INDEX(Monthly!$C$51:$BJ$51,($R$2-1)*12+7) -> -22229.472 | O17: =INDEX(Monthly!$C$51:$BJ$51,($R$2-1)*12+8) -> -16699.572 | P17: =INDEX(Monthly!$C$51:$BJ$51,($R$2-1)*12+9) -> -11169.673 | Q17: =INDEX(Monthly!$C$51:$BJ$51,($R$2-1)*12+10) -> -5639.7731 | R17: =INDEX(Monthly!$C$51:$BJ$51,($R$2-1)*12+11) -> -109.87351 | S17: =INDEX(Monthly!$C$51:$BJ$51,($R$2-1)*12+12) -> 5420.026
A18: Income tax | B18: ='P&L'!B22 -> 0 | C18: ='P&L'!C22 -> 0 | D18: ='P&L'!D22 -> -33706.652 | E18: ='P&L'!E22 -> -69914.948 | F18: ='P&L'!F22 -> -84902.043 | H18: =INDEX(Monthly!$C$54:$BJ$54,($R$2-1)*12+1) -> 0 | I18: =INDEX(Monthly!$C$54:$BJ$54,($R$2-1)*12+2) -> 0 | J18: =INDEX(Monthly!$C$54:$BJ$54,($R$2-1)*12+3) -> 0 | K18: =INDEX(Monthly!$C$54:$BJ$54,($R$2-1)*12+4) -> 0 | L18: =INDEX(Monthly!$C$54:$BJ$54,($R$2-1)*12+5) -> 0 | M18: =INDEX(Monthly!$C$54:$BJ$54,($R$2-1)*12+6) -> 0 | N18: =INDEX(Monthly!$C$54:$BJ$54,($R$2-1)*12+7) -> 0 | O18: =INDEX(Monthly!$C$54:$BJ$54,($R$2-1)*12+8) -> 0 | P18: =INDEX(Monthly!$C$54:$BJ$54,($R$2-1)*12+9) -> 0 | Q18: =INDEX(Monthly!$C$54:$BJ$54,($R$2-1)*12+10) -> 0 | R18: =INDEX(Monthly!$C$54:$BJ$54,($R$2-1)*12+11) -> 0 | S18: =INDEX(Monthly!$C$54:$BJ$54,($R$2-1)*12+12) -> 0
A19: Net income | B19: ='P&L'!B23 -> -299921.9 | C19: ='P&L'!C23 -> 196493.58 | D19: ='P&L'!D23 -> 230229.53 | E19: ='P&L'!E23 -> 263013.37 | F19: ='P&L'!F23 -> 319393.4 | H19: =INDEX(Monthly!$C$55:$BJ$55,($R$2-1)*12+1) -> -55397.708 | I19: =INDEX(Monthly!$C$55:$BJ$55,($R$2-1)*12+2) -> -49878.969 | J19: =INDEX(Monthly!$C$55:$BJ$55,($R$2-1)*12+3) -> -44349.07 | K19: =INDEX(Monthly!$C$55:$BJ$55,($R$2-1)*12+4) -> -38819.17 | L19: =INDEX(Monthly!$C$55:$BJ$55,($R$2-1)*12+5) -> -33289.271 | M19: =INDEX(Monthly!$C$55:$BJ$55,($R$2-1)*12+6) -> -27759.371 | N19: =INDEX(Monthly!$C$55:$BJ$55,($R$2-1)*12+7) -> -22229.472 | O19: =INDEX(Monthly!$C$55:$BJ$55,($R$2-1)*12+8) -> -16699.572 | P19: =INDEX(Monthly!$C$55:$BJ$55,($R$2-1)*12+9) -> -11169.673 | Q19: =INDEX(Monthly!$C$55:$BJ$55,($R$2-1)*12+10) -> -5639.7731 | R19: =INDEX(Monthly!$C$55:$BJ$55,($R$2-1)*12+11) -> -109.87351 | S19: =INDEX(Monthly!$C$55:$BJ$55,($R$2-1)*12+12) -> 5420.026
A20: Net margin | B20: ='P&L'!B24 -> -0.23721254 | C20: ='P&L'!C24 -> 0.098879705 | D20: ='P&L'!D24 -> 0.10920571 | E20: ='P&L'!E24 -> 0.11759469 | F20: ='P&L'!F24 -> 0.13460506 | H20: =IF(H7=0,0,H19/H7) -> -0.88725058 | I20: =IF(I7=0,0,I19/I7) -> -0.71009989 | J20: =IF(J7=0,0,J19/J7) -> -0.56823633 | K20: =IF(K7=0,0,K19/K7) -> -0.45216615 | L20: =IF(L7=0,0,L19/L7) -> -0.355441 | M20: =IF(M7=0,0,M19/M7) -> -0.27359664 | N20: =IF(N7=0,0,N19/N7) -> -0.20344433 | O20: =IF(O7=0,0,O19/O7) -> -0.14264566 | ... S20: =IF(S7=0,0,S19/S7) -> 0.03655041
A22: Cash flow ($'000) — by year | H22: ="Cash flow ($'000) — Year "&$R$2&", by month" -> Cash flow ($'000) — Year 1, by month
B23: 1 | C23: 2 | D23: 3 | E23: 4 | F23: 5 | H23: =INDEX(Monthly!$C$4:$BJ$4,($R$2-1)*12+1) -> 1 | I23: =INDEX(Monthly!$C$4:$BJ$4,($R$2-1)*12+2) -> 2 | J23: =INDEX(Monthly!$C$4:$BJ$4,($R$2-1)*12+3) -> 3 | K23: =INDEX(Monthly!$C$4:$BJ$4,($R$2-1)*12+4) -> 4 | L23: =INDEX(Monthly!$C$4:$BJ$4,($R$2-1)*12+5) -> 5 | M23: =INDEX(Monthly!$C$4:$BJ$4,($R$2-1)*12+6) -> 6 | N23: =INDEX(Monthly!$C$4:$BJ$4,($R$2-1)*12+7) -> 7 | O23: =INDEX(Monthly!$C$4:$BJ$4,($R$2-1)*12+8) -> 8 | P23: =INDEX(Monthly!$C$4:$BJ$4,($R$2-1)*12+9) -> 9 | Q23: =INDEX(Monthly!$C$4:$BJ$4,($R$2-1)*12+10) -> 10 | R23: =INDEX(Monthly!$C$4:$BJ$4,($R$2-1)*12+11) -> 11 | S23: =INDEX(Monthly!$C$4:$BJ$4,($R$2-1)*12+12) -> 12
A24: Operating cash flow | B24: ='Cash Flow'!B10 -> -223610.34 | C24: ='Cash Flow'!C10 -> 248240.76 | D24: ='Cash Flow'!D10 -> 284136.04 | E24: ='Cash Flow'!E10 -> 319470.09 | F24: ='Cash Flow'!F10 -> 378402.78 | H24: =INDEX(Monthly!$C$85:$BJ$85,($R$2-1)*12+1) -> -27131 | I24: =INDEX(Monthly!$C$85:$BJ$85,($R$2-1)*12+2) -> -45511.256 | J24: =INDEX(Monthly!$C$85:$BJ$85,($R$2-1)*12+3) -> -39981.356 | K24: =INDEX(Monthly!$C$85:$BJ$85,($R$2-1)*12+4) -> -34451.457 | L24: =INDEX(Monthly!$C$85:$BJ$85,($R$2-1)*12+5) -> -28921.557 | M24: =INDEX(Monthly!$C$85:$BJ$85,($R$2-1)*12+6) -> -23391.658 | N24: =INDEX(Monthly!$C$85:$BJ$85,($R$2-1)*12+7) -> -17861.758 | O24: =INDEX(Monthly!$C$85:$BJ$85,($R$2-1)*12+8) -> -12331.859 | P24: =INDEX(Monthly!$C$85:$BJ$85,($R$2-1)*12+9) -> -6801.9591 | Q24: =INDEX(Monthly!$C$85:$BJ$85,($R$2-1)*12+10) -> -1272.0595 | R24: =INDEX(Monthly!$C$85:$BJ$85,($R$2-1)*12+11) -> 4257.84 | S24: =INDEX(Monthly!$C$85:$BJ$85,($R$2-1)*12+12) -> 9787.7396
A25: Capital spending | B25: ='Cash Flow'!B11 -> -382000 | C25: ='Cash Flow'!C11 -> -20000 | D25: ='Cash Flow'!D11 -> -20000 | E25: ='Cash Flow'!E11 -> -20000 | F25: ='Cash Flow'!F11 -> -20000 | H25: =INDEX(Monthly!$C$86:$BJ$86,($R$2-1)*12+1) -> -382000 | I25: =INDEX(Monthly!$C$86:$BJ$86,($R$2-1)*12+2) -> 0 | J25: =INDEX(Monthly!$C$86:$BJ$86,($R$2-1)*12+3) -> 0 | K25: =INDEX(Monthly!$C$86:$BJ$86,($R$2-1)*12+4) -> 0 | L25: =INDEX(Monthly!$C$86:$BJ$86,($R$2-1)*12+5) -> 0 | M25: =INDEX(Monthly!$C$86:$BJ$86,($R$2-1)*12+6) -> 0 | N25: =INDEX(Monthly!$C$86:$BJ$86,($R$2-1)*12+7) -> 0 | O25: =INDEX(Monthly!$C$86:$BJ$86,($R$2-1)*12+8) -> 0 | P25: =INDEX(Monthly!$C$86:$BJ$86,($R$2-1)*12+9) -> 0 | Q25: =INDEX(Monthly!$C$86:$BJ$86,($R$2-1)*12+10) -> 0 | R25: =INDEX(Monthly!$C$86:$BJ$86,($R$2-1)*12+11) -> 0 | S25: =INDEX(Monthly!$C$86:$BJ$86,($R$2-1)*12+12) -> 0
A26: Equity raised | B26: ='Cash Flow'!B12 -> 480000 | C26: ='Cash Flow'!C12 -> 0 | D26: ='Cash Flow'!D12 -> 0 | E26: ='Cash Flow'!E12 -> 0 | F26: ='Cash Flow'!F12 -> 0 | H26: =INDEX(Monthly!$C$87:$BJ$87,($R$2-1)*12+1) -> 480000 | I26: =INDEX(Monthly!$C$87:$BJ$87,($R$2-1)*12+2) -> 0 | J26: =INDEX(Monthly!$C$87:$BJ$87,($R$2-1)*12+3) -> 0 | K26: =INDEX(Monthly!$C$87:$BJ$87,($R$2-1)*12+4) -> 0 | L26: =INDEX(Monthly!$C$87:$BJ$87,($R$2-1)*12+5) -> 0 | M26: =INDEX(Monthly!$C$87:$BJ$87,($R$2-1)*12+6) -> 0 | N26: =INDEX(Monthly!$C$87:$BJ$87,($R$2-1)*12+7) -> 0 | O26: =INDEX(Monthly!$C$87:$BJ$87,($R$2-1)*12+8) -> 0 | P26: =INDEX(Monthly!$C$87:$BJ$87,($R$2-1)*12+9) -> 0 | Q26: =INDEX(Monthly!$C$87:$BJ$87,($R$2-1)*12+10) -> 0 | R26: =INDEX(Monthly!$C$87:$BJ$87,($R$2-1)*12+11) -> 0 | S26: =INDEX(Monthly!$C$87:$BJ$87,($R$2-1)*12+12) -> 0
A27: Loan drawdown | B27: ='Cash Flow'!B13 -> 250000 | C27: ='Cash Flow'!C13 -> 0 | D27: ='Cash Flow'!D13 -> 0 | E27: ='Cash Flow'!E13 -> 0 | F27: ='Cash Flow'!F13 -> 0 | H27: =INDEX(Monthly!$C$72:$BJ$72,($R$2-1)*12+1) -> 250000 | I27: =INDEX(Monthly!$C$72:$BJ$72,($R$2-1)*12+2) -> 0 | J27: =INDEX(Monthly!$C$72:$BJ$72,($R$2-1)*12+3) -> 0 | K27: =INDEX(Monthly!$C$72:$BJ$72,($R$2-1)*12+4) -> 0 | L27: =INDEX(Monthly!$C$72:$BJ$72,($R$2-1)*12+5) -> 0 | M27: =INDEX(Monthly!$C$72:$BJ$72,($R$2-1)*12+6) -> 0 | N27: =INDEX(Monthly!$C$72:$BJ$72,($R$2-1)*12+7) -> 0 | O27: =INDEX(Monthly!$C$72:$BJ$72,($R$2-1)*12+8) -> 0 | P27: =INDEX(Monthly!$C$72:$BJ$72,($R$2-1)*12+9) -> 0 | Q27: =INDEX(Monthly!$C$72:$BJ$72,($R$2-1)*12+10) -> 0 | R27: =INDEX(Monthly!$C$72:$BJ$72,($R$2-1)*12+11) -> 0 | S27: =INDEX(Monthly!$C$72:$BJ$72,($R$2-1)*12+12) -> 0
A28: Loan repayment | B28: ='Cash Flow'!B14 -> -32738.095 | C28: ='Cash Flow'!C14 -> -35714.286 | D28: ='Cash Flow'!D14 -> -35714.286 | E28: ='Cash Flow'!E14 -> -35714.286 | F28: ='Cash Flow'!F14 -> -35714.286 | H28: =INDEX(Monthly!$C$73:$BJ$73,($R$2-1)*12+1) -> 0 | I28: =INDEX(Monthly!$C$73:$BJ$73,($R$2-1)*12+2) -> -2976.1905 | J28: =INDEX(Monthly!$C$73:$BJ$73,($R$2-1)*12+3) -> -2976.1905 | K28: =INDEX(Monthly!$C$73:$BJ$73,($R$2-1)*12+4) -> -2976.1905 | L28: =INDEX(Monthly!$C$73:$BJ$73,($R$2-1)*12+5) -> -2976.1905 | M28: =INDEX(Monthly!$C$73:$BJ$73,($R$2-1)*12+6) -> -2976.1905 | N28: =INDEX(Monthly!$C$73:$BJ$73,($R$2-1)*12+7) -> -2976.1905 | O28: =INDEX(Monthly!$C$73:$BJ$73,($R$2-1)*12+8) -> -2976.1905 | P28: =INDEX(Monthly!$C$73:$BJ$73,($R$2-1)*12+9) -> -2976.1905 | Q28: =INDEX(Monthly!$C$73:$BJ$73,($R$2-1)*12+10) -> -2976.1905 | R28: =INDEX(Monthly!$C$73:$BJ$73,($R$2-1)*12+11) -> -2976.1905 | S28: =INDEX(Monthly!$C$73:$BJ$73,($R$2-1)*12+12) -> -2976.1905
A29: Financing cash flow | B29: ='Cash Flow'!B15 -> 697261.9 | C29: ='Cash Flow'!C15 -> -35714.286 | D29: ='Cash Flow'!D15 -> -35714.286 | E29: ='Cash Flow'!E15 -> -35714.286 | F29: ='Cash Flow'!F15 -> -35714.286 | H29: =INDEX(Monthly!$C$88:$BJ$88,($R$2-1)*12+1) -> 730000 | I29: =INDEX(Monthly!$C$88:$BJ$88,($R$2-1)*12+2) -> -2976.1905 | J29: =INDEX(Monthly!$C$88:$BJ$88,($R$2-1)*12+3) -> -2976.1905 | K29: =INDEX(Monthly!$C$88:$BJ$88,($R$2-1)*12+4) -> -2976.1905 | L29: =INDEX(Monthly!$C$88:$BJ$88,($R$2-1)*12+5) -> -2976.1905 | M29: =INDEX(Monthly!$C$88:$BJ$88,($R$2-1)*12+6) -> -2976.1905 | N29: =INDEX(Monthly!$C$88:$BJ$88,($R$2-1)*12+7) -> -2976.1905 | O29: =INDEX(Monthly!$C$88:$BJ$88,($R$2-1)*12+8) -> -2976.1905 | P29: =INDEX(Monthly!$C$88:$BJ$88,($R$2-1)*12+9) -> -2976.1905 | Q29: =INDEX(Monthly!$C$88:$BJ$88,($R$2-1)*12+10) -> -2976.1905 | R29: =INDEX(Monthly!$C$88:$BJ$88,($R$2-1)*12+11) -> -2976.1905 | S29: =INDEX(Monthly!$C$88:$BJ$88,($R$2-1)*12+12) -> -2976.1905
A30: Net change in cash | B30: ='Cash Flow'!B16 -> 91651.565 | C30: ='Cash Flow'!C16 -> 192526.47 | D30: ='Cash Flow'!D16 -> 228421.75 | E30: ='Cash Flow'!E16 -> 263755.81 | F30: ='Cash Flow'!F16 -> 322688.49 | H30: =INDEX(Monthly!$C$89:$BJ$89,($R$2-1)*12+1) -> 320869 | I30: =INDEX(Monthly!$C$89:$BJ$89,($R$2-1)*12+2) -> -48487.446 | J30: =INDEX(Monthly!$C$89:$BJ$89,($R$2-1)*12+3) -> -42957.547 | K30: =INDEX(Monthly!$C$89:$BJ$89,($R$2-1)*12+4) -> -37427.647 | L30: =INDEX(Monthly!$C$89:$BJ$89,($R$2-1)*12+5) -> -31897.748 | M30: =INDEX(Monthly!$C$89:$BJ$89,($R$2-1)*12+6) -> -26367.848 | N30: =INDEX(Monthly!$C$89:$BJ$89,($R$2-1)*12+7) -> -20837.949 | O30: =INDEX(Monthly!$C$89:$BJ$89,($R$2-1)*12+8) -> -15308.049 | P30: =INDEX(Monthly!$C$89:$BJ$89,($R$2-1)*12+9) -> -9778.1496 | Q30: =INDEX(Monthly!$C$89:$BJ$89,($R$2-1)*12+10) -> -4248.25 | R30: =INDEX(Monthly!$C$89:$BJ$89,($R$2-1)*12+11) -> 1281.6496 | S30: =INDEX(Monthly!$C$89:$BJ$89,($R$2-1)*12+12) -> 6811.5491
A31: Closing cash | B31: ='Cash Flow'!B18 -> 91651.565 | C31: ='Cash Flow'!C18 -> 284178.03 | D31: ='Cash Flow'!D18 -> 512599.78 | E31: ='Cash Flow'!E18 -> 776355.59 | F31: ='Cash Flow'!F18 -> 1099044.1 | H31: =INDEX(Monthly!$C$91:$BJ$91,($R$2-1)*12+1) -> 320869 | I31: =INDEX(Monthly!$C$91:$BJ$91,($R$2-1)*12+2) -> 272381.55 | J31: =INDEX(Monthly!$C$91:$BJ$91,($R$2-1)*12+3) -> 229424.01 | K31: =INDEX(Monthly!$C$91:$BJ$91,($R$2-1)*12+4) -> 191996.36 | L31: =INDEX(Monthly!$C$91:$BJ$91,($R$2-1)*12+5) -> 160098.61 | M31: =INDEX(Monthly!$C$91:$BJ$91,($R$2-1)*12+6) -> 133730.76 | N31: =INDEX(Monthly!$C$91:$BJ$91,($R$2-1)*12+7) -> 112892.81 | O31: =INDEX(Monthly!$C$91:$BJ$91,($R$2-1)*12+8) -> 97584.766 | P31: =INDEX(Monthly!$C$91:$BJ$91,($R$2-1)*12+9) -> 87806.616 | Q31: =INDEX(Monthly!$C$91:$BJ$91,($R$2-1)*12+10) -> 83558.366 | R31: =INDEX(Monthly!$C$91:$BJ$91,($R$2-1)*12+11) -> 84840.016 | S31: =INDEX(Monthly!$C$91:$BJ$91,($R$2-1)*12+12) -> 91651.565
A39: Balance sheet at year end ($'000) | H39: ="Balance sheet at month end ($'000) — Year "&$R$2 -> Balance sheet at month end ($'000) — Year 1
B40: 1 | C40: 2 | D40: 3 | E40: 4 | F40: 5 | H40: =INDEX(Monthly!$C$4:$BJ$4,($R$2-1)*12+1) -> 1 | I40: =INDEX(Monthly!$C$4:$BJ$4,($R$2-1)*12+2) -> 2 | J40: =INDEX(Monthly!$C$4:$BJ$4,($R$2-1)*12+3) -> 3 | K40: =INDEX(Monthly!$C$4:$BJ$4,($R$2-1)*12+4) -> 4 | L40: =INDEX(Monthly!$C$4:$BJ$4,($R$2-1)*12+5) -> 5 | M40: =INDEX(Monthly!$C$4:$BJ$4,($R$2-1)*12+6) -> 6 | N40: =INDEX(Monthly!$C$4:$BJ$4,($R$2-1)*12+7) -> 7 | O40: =INDEX(Monthly!$C$4:$BJ$4,($R$2-1)*12+8) -> 8 | P40: =INDEX(Monthly!$C$4:$BJ$4,($R$2-1)*12+9) -> 9 | Q40: =INDEX(Monthly!$C$4:$BJ$4,($R$2-1)*12+10) -> 10 | R40: =INDEX(Monthly!$C$4:$BJ$4,($R$2-1)*12+11) -> 11 | S40: =INDEX(Monthly!$C$4:$BJ$4,($R$2-1)*12+12) -> 12
A41: Cash | B41: ='Balance Sheet'!B5 -> 91651.565 | C41: ='Balance Sheet'!C5 -> 284178.03 | D41: ='Balance Sheet'!D5 -> 512599.78 | E41: ='Balance Sheet'!E5 -> 776355.59 | F41: ='Balance Sheet'!F5 -> 1099044.1 | H41: =INDEX(Monthly!$C$91:$BJ$91,($R$2-1)*12+1) -> 320869 | I41: =INDEX(Monthly!$C$91:$BJ$91,($R$2-1)*12+2) -> 272381.55 | J41: =INDEX(Monthly!$C$91:$BJ$91,($R$2-1)*12+3) -> 229424.01 | K41: =INDEX(Monthly!$C$91:$BJ$91,($R$2-1)*12+4) -> 191996.36 | L41: =INDEX(Monthly!$C$91:$BJ$91,($R$2-1)*12+5) -> 160098.61 | M41: =INDEX(Monthly!$C$91:$BJ$91,($R$2-1)*12+6) -> 133730.76 | N41: =INDEX(Monthly!$C$91:$BJ$91,($R$2-1)*12+7) -> 112892.81 | O41: =INDEX(Monthly!$C$91:$BJ$91,($R$2-1)*12+8) -> 97584.766 | P41: =INDEX(Monthly!$C$91:$BJ$91,($R$2-1)*12+9) -> 87806.616 | Q41: =INDEX(Monthly!$C$91:$BJ$91,($R$2-1)*12+10) -> 83558.366 | R41: =INDEX(Monthly!$C$91:$BJ$91,($R$2-1)*12+11) -> 84840.016 | S41: =INDEX(Monthly!$C$91:$BJ$91,($R$2-1)*12+12) -> 91651.565
A42: Accounts receivable | B42: ='Balance Sheet'!B6 -> 14828.906 | C42: ='Balance Sheet'!C6 -> 16559.986 | D42: ='Balance Sheet'!D6 -> 17568.489 | E42: ='Balance Sheet'!E6 -> 18638.41 | F42: ='Balance Sheet'!F6 -> 19773.489 | H42: =INDEX(Monthly!$C$77:$BJ$77,($R$2-1)*12+1) -> 6243.75 | I42: =INDEX(Monthly!$C$77:$BJ$77,($R$2-1)*12+2) -> 7024.2188 | J42: =INDEX(Monthly!$C$77:$BJ$77,($R$2-1)*12+3) -> 7804.6875 | K42: =INDEX(Monthly!$C$77:$BJ$77,($R$2-1)*12+4) -> 8585.1562 | L42: =INDEX(Monthly!$C$77:$BJ$77,($R$2-1)*12+5) -> 9365.625 | M42: =INDEX(Monthly!$C$77:$BJ$77,($R$2-1)*12+6) -> 10146.094 | N42: =INDEX(Monthly!$C$77:$BJ$77,($R$2-1)*12+7) -> 10926.562 | O42: =INDEX(Monthly!$C$77:$BJ$77,($R$2-1)*12+8) -> 11707.031 | P42: =INDEX(Monthly!$C$77:$BJ$77,($R$2-1)*12+9) -> 12487.5 | Q42: =INDEX(Monthly!$C$77:$BJ$77,($R$2-1)*12+10) -> 13267.969 | R42: =INDEX(Monthly!$C$77:$BJ$77,($R$2-1)*12+11) -> 14048.438 | S42: =INDEX(Monthly!$C$77:$BJ$77,($R$2-1)*12+12) -> 14828.906
A43: Inventory | B43: ='Balance Sheet'!B7 -> 20419.042 | C43: ='Balance Sheet'!C7 -> 21938.219 | D43: ='Balance Sheet'!D7 -> 22957.047 | E43: ='Balance Sheet'!E7 -> 24028.406 | F43: ='Balance Sheet'!F7 -> 25155.209 | H43: =INDEX(Monthly!$C$78:$BJ$78,($R$2-1)*12+1) -> 14367.667 | I43: =INDEX(Monthly!$C$78:$BJ$78,($R$2-1)*12+2) -> 14917.792 | J43: =INDEX(Monthly!$C$78:$BJ$78,($R$2-1)*12+3) -> 15467.917 | K43: =INDEX(Monthly!$C$78:$BJ$78,($R$2-1)*12+4) -> 16018.042 | L43: =INDEX(Monthly!$C$78:$BJ$78,($R$2-1)*12+5) -> 16568.167 | M43: =INDEX(Monthly!$C$78:$BJ$78,($R$2-1)*12+6) -> 17118.292 | N43: =INDEX(Monthly!$C$78:$BJ$78,($R$2-1)*12+7) -> 17668.417 | O43: =INDEX(Monthly!$C$78:$BJ$78,($R$2-1)*12+8) -> 18218.542 | P43: =INDEX(Monthly!$C$78:$BJ$78,($R$2-1)*12+9) -> 18768.667 | Q43: =INDEX(Monthly!$C$78:$BJ$78,($R$2-1)*12+10) -> 19318.792 | R43: =INDEX(Monthly!$C$78:$BJ$78,($R$2-1)*12+11) -> 19868.917 | S43: =INDEX(Monthly!$C$78:$BJ$78,($R$2-1)*12+12) -> 20419.042
A44: Net fixed assets | B44: ='Balance Sheet'!B8 -> 334250 | C44: ='Balance Sheet'!C8 -> 304000 | D44: ='Balance Sheet'!D8 -> 271250 | E44: ='Balance Sheet'!E8 -> 236000 | F44: ='Balance Sheet'!F8 -> 198250 | H44: =INDEX(Monthly!$C$68:$BJ$68,($R$2-1)*12+1) -> 378020.83 | I44: =INDEX(Monthly!$C$68:$BJ$68,($R$2-1)*12+2) -> 374041.67 | J44: =INDEX(Monthly!$C$68:$BJ$68,($R$2-1)*12+3) -> 370062.5 | K44: =INDEX(Monthly!$C$68:$BJ$68,($R$2-1)*12+4) -> 366083.33 | L44: =INDEX(Monthly!$C$68:$BJ$68,($R$2-1)*12+5) -> 362104.17 | M44: =INDEX(Monthly!$C$68:$BJ$68,($R$2-1)*12+6) -> 358125 | N44: =INDEX(Monthly!$C$68:$BJ$68,($R$2-1)*12+7) -> 354145.83 | O44: =INDEX(Monthly!$C$68:$BJ$68,($R$2-1)*12+8) -> 350166.67 | P44: =INDEX(Monthly!$C$68:$BJ$68,($R$2-1)*12+9) -> 346187.5 | Q44: =INDEX(Monthly!$C$68:$BJ$68,($R$2-1)*12+10) -> 342208.33 | R44: =INDEX(Monthly!$C$68:$BJ$68,($R$2-1)*12+11) -> 338229.17 | S44: =INDEX(Monthly!$C$68:$BJ$68,($R$2-1)*12+12) -> 334250
A45: Total assets | B45: ='Balance Sheet'!B9 -> 461149.51 | C45: ='Balance Sheet'!C9 -> 626676.24 | D45: ='Balance Sheet'!D9 -> 824375.32 | E45: ='Balance Sheet'!E9 -> 1055022.4 | F45: ='Balance Sheet'!F9 -> 1342222.8 | H45: =INDEX(Monthly!$C$105:$BJ$105,($R$2-1)*12+1) -> 719501.25 | I45: =INDEX(Monthly!$C$105:$BJ$105,($R$2-1)*12+2) -> 668365.23 | J45: =INDEX(Monthly!$C$105:$BJ$105,($R$2-1)*12+3) -> 622759.11 | K45: =INDEX(Monthly!$C$105:$BJ$105,($R$2-1)*12+4) -> 582682.89 | L45: =INDEX(Monthly!$C$105:$BJ$105,($R$2-1)*12+5) -> 548136.57 | M45: =INDEX(Monthly!$C$105:$BJ$105,($R$2-1)*12+6) -> 519120.15 | N45: =INDEX(Monthly!$C$105:$BJ$105,($R$2-1)*12+7) -> 495633.63 | O45: =INDEX(Monthly!$C$105:$BJ$105,($R$2-1)*12+8) -> 477677.01 | P45: =INDEX(Monthly!$C$105:$BJ$105,($R$2-1)*12+9) -> 465250.28 | Q45: =INDEX(Monthly!$C$105:$BJ$105,($R$2-1)*12+10) -> 458353.46 | R45: =INDEX(Monthly!$C$105:$BJ$105,($R$2-1)*12+11) -> 456986.54 | S45: =INDEX(Monthly!$C$105:$BJ$105,($R$2-1)*12+12) -> 461149.51
A46: Accounts payable | B46: ='Balance Sheet'!B10 -> 63809.505 | C46: ='Balance Sheet'!C10 -> 68556.934 | D46: ='Balance Sheet'!D10 -> 71740.773 | E46: ='Balance Sheet'!E10 -> 75088.769 | F46: ='Balance Sheet'!F10 -> 78610.028 | H46: =INDEX(Monthly!$C$79:$BJ$79,($R$2-1)*12+1) -> 44898.958 | I46: =INDEX(Monthly!$C$79:$BJ$79,($R$2-1)*12+2) -> 46618.099 | J46: =INDEX(Monthly!$C$79:$BJ$79,($R$2-1)*12+3) -> 48337.24 | K46: =INDEX(Monthly!$C$79:$BJ$79,($R$2-1)*12+4) -> 50056.38 | L46: =INDEX(Monthly!$C$79:$BJ$79,($R$2-1)*12+5) -> 51775.521 | M46: =INDEX(Monthly!$C$79:$BJ$79,($R$2-1)*12+6) -> 53494.661 | N46: =INDEX(Monthly!$C$79:$BJ$79,($R$2-1)*12+7) -> 55213.802 | O46: =INDEX(Monthly!$C$79:$BJ$79,($R$2-1)*12+8) -> 56932.943 | P46: =INDEX(Monthly!$C$79:$BJ$79,($R$2-1)*12+9) -> 58652.083 | Q46: =INDEX(Monthly!$C$79:$BJ$79,($R$2-1)*12+10) -> 60371.224 | R46: =INDEX(Monthly!$C$79:$BJ$79,($R$2-1)*12+11) -> 62090.365 | S46: =INDEX(Monthly!$C$79:$BJ$79,($R$2-1)*12+12) -> 63809.505
A47: Loan | B47: ='Balance Sheet'!B11 -> 217261.9 | C47: ='Balance Sheet'!C11 -> 181547.62 | D47: ='Balance Sheet'!D11 -> 145833.33 | E47: ='Balance Sheet'!E11 -> 110119.05 | F47: ='Balance Sheet'!F11 -> 74404.762 | H47: =INDEX(Monthly!$C$74:$BJ$74,($R$2-1)*12+1) -> 250000 | I47: =INDEX(Monthly!$C$74:$BJ$74,($R$2-1)*12+2) -> 247023.81 | J47: =INDEX(Monthly!$C$74:$BJ$74,($R$2-1)*12+3) -> 244047.62 | K47: =INDEX(Monthly!$C$74:$BJ$74,($R$2-1)*12+4) -> 241071.43 | L47: =INDEX(Monthly!$C$74:$BJ$74,($R$2-1)*12+5) -> 238095.24 | M47: =INDEX(Monthly!$C$74:$BJ$74,($R$2-1)*12+6) -> 235119.05 | N47: =INDEX(Monthly!$C$74:$BJ$74,($R$2-1)*12+7) -> 232142.86 | O47: =INDEX(Monthly!$C$74:$BJ$74,($R$2-1)*12+8) -> 229166.67 | P47: =INDEX(Monthly!$C$74:$BJ$74,($R$2-1)*12+9) -> 226190.48 | Q47: =INDEX(Monthly!$C$74:$BJ$74,($R$2-1)*12+10) -> 223214.29 | R47: =INDEX(Monthly!$C$74:$BJ$74,($R$2-1)*12+11) -> 220238.1 | S47: =INDEX(Monthly!$C$74:$BJ$74,($R$2-1)*12+12) -> 217261.9
A48: Total liabilities | B48: ='Balance Sheet'!B12 -> 281071.41 | C48: ='Balance Sheet'!C12 -> 250104.55 | D48: ='Balance Sheet'!D12 -> 217574.11 | E48: ='Balance Sheet'!E12 -> 185207.82 | F48: ='Balance Sheet'!F12 -> 153014.79 | H48: =INDEX(Monthly!$C$106:$BJ$106,($R$2-1)*12+1) -> 294898.96 | I48: =INDEX(Monthly!$C$106:$BJ$106,($R$2-1)*12+2) -> 293641.91 | J48: =INDEX(Monthly!$C$106:$BJ$106,($R$2-1)*12+3) -> 292384.86 | K48: =INDEX(Monthly!$C$106:$BJ$106,($R$2-1)*12+4) -> 291127.81 | L48: =INDEX(Monthly!$C$106:$BJ$106,($R$2-1)*12+5) -> 289870.76 | M48: =INDEX(Monthly!$C$106:$BJ$106,($R$2-1)*12+6) -> 288613.71 | N48: =INDEX(Monthly!$C$106:$BJ$106,($R$2-1)*12+7) -> 287356.66 | O48: =INDEX(Monthly!$C$106:$BJ$106,($R$2-1)*12+8) -> 286099.61 | P48: =INDEX(Monthly!$C$106:$BJ$106,($R$2-1)*12+9) -> 284842.56 | Q48: =INDEX(Monthly!$C$106:$BJ$106,($R$2-1)*12+10) -> 283585.51 | R48: =INDEX(Monthly!$C$106:$BJ$106,($R$2-1)*12+11) -> 282328.46 | S48: =INDEX(Monthly!$C$106:$BJ$106,($R$2-1)*12+12) -> 281071.41
A49: Paid-in capital | B49: ='Balance Sheet'!B13 -> 480000 | C49: ='Balance Sheet'!C13 -> 480000 | D49: ='Balance Sheet'!D13 -> 480000 | E49: ='Balance Sheet'!E13 -> 480000 | F49: ='Balance Sheet'!F13 -> 480000 | H49: =INDEX(Monthly!$C$103:$BJ$103,($R$2-1)*12+1) -> 480000 | I49: =INDEX(Monthly!$C$103:$BJ$103,($R$2-1)*12+2) -> 480000 | J49: =INDEX(Monthly!$C$103:$BJ$103,($R$2-1)*12+3) -> 480000 | K49: =INDEX(Monthly!$C$103:$BJ$103,($R$2-1)*12+4) -> 480000 | L49: =INDEX(Monthly!$C$103:$BJ$103,($R$2-1)*12+5) -> 480000 | M49: =INDEX(Monthly!$C$103:$BJ$103,($R$2-1)*12+6) -> 480000 | N49: =INDEX(Monthly!$C$103:$BJ$103,($R$2-1)*12+7) -> 480000 | O49: =INDEX(Monthly!$C$103:$BJ$103,($R$2-1)*12+8) -> 480000 | P49: =INDEX(Monthly!$C$103:$BJ$103,($R$2-1)*12+9) -> 480000 | Q49: =INDEX(Monthly!$C$103:$BJ$103,($R$2-1)*12+10) -> 480000 | R49: =INDEX(Monthly!$C$103:$BJ$103,($R$2-1)*12+11) -> 480000 | S49: =INDEX(Monthly!$C$103:$BJ$103,($R$2-1)*12+12) -> 480000
A50: Retained earnings | B50: ='Balance Sheet'!B14 -> -299921.9 | C50: ='Balance Sheet'!C14 -> -103428.31 | D50: ='Balance Sheet'!D14 -> 126801.21 | E50: ='Balance Sheet'!E14 -> 389814.59 | F50: ='Balance Sheet'!F14 -> 709207.99 | H50: =INDEX(Monthly!$C$104:$BJ$104,($R$2-1)*12+1) -> -55397.708 | I50: =INDEX(Monthly!$C$104:$BJ$104,($R$2-1)*12+2) -> -105276.68 | J50: =INDEX(Monthly!$C$104:$BJ$104,($R$2-1)*12+3) -> -149625.75 | K50: =INDEX(Monthly!$C$104:$BJ$104,($R$2-1)*12+4) -> -188444.92 | L50: =INDEX(Monthly!$C$104:$BJ$104,($R$2-1)*12+5) -> -221734.19 | M50: =INDEX(Monthly!$C$104:$BJ$104,($R$2-1)*12+6) -> -249493.56 | N50: =INDEX(Monthly!$C$104:$BJ$104,($R$2-1)*12+7) -> -271723.03 | O50: =INDEX(Monthly!$C$104:$BJ$104,($R$2-1)*12+8) -> -288422.6 | P50: =INDEX(Monthly!$C$104:$BJ$104,($R$2-1)*12+9) -> -299592.28 | Q50: =INDEX(Monthly!$C$104:$BJ$104,($R$2-1)*12+10) -> -305232.05 | R50: =INDEX(Monthly!$C$104:$BJ$104,($R$2-1)*12+11) -> -305341.92 | S50: =INDEX(Monthly!$C$104:$BJ$104,($R$2-1)*12+12) -> -299921.9
...

Sheet Scenarios
A1: Scenarios — Low / Base / High | H1: =HYPERLINK("#'Cover'!A1","◂ Contents") -> ◂ Contents
A2: All three scenarios calculated side by side, live: change any input and every column updates. Active = the scenario chosen on the Dashboard.
A5: Key drivers
A6: Driver | B6: Low | C6: Base | D6: High | E6: Active
A7: Repair orders per operating day at maturity (year 1) (orders) | B7: =Inputs!$B$7 -> 11 | C7: =Inputs!$C$7 -> 13.5 | D7: =Inputs!$D$7 -> 16 | E7: =Inputs!$E$7 -> 13.5
A8: Effective labor rate per billed hour (year 1) ($) | B8: =Inputs!$B$21 -> 118 | C8: =Inputs!$C$21 -> 125 | D8: =Inputs!$D$21 -> 132 | E8: =Inputs!$E$21 -> 125
A9: Service bays (lifts) (bays) | B9: =Inputs!$B$15 -> 6 | C9: =Inputs!$C$15 -> 6 | D9: =Inputs!$D$15 -> 6 | E9: =Inputs!$E$15 -> 6
A10: Parts gross margin, % of parts sales (%) | B10: =Inputs!$B$27 -> 0.44 | C10: =Inputs!$C$27 -> 0.47 | D10: =Inputs!$D$27 -> 0.5 | E10: =Inputs!$E$27 -> 0.47
A11: Shop rent or land cost per month ($) | B11: =Inputs!$B$36 -> 18000 | C11: =Inputs!$C$36 -> 18000 | D11: =Inputs!$D$36 -> 18000 | E11: =Inputs!$E$36 -> 18000
A12: Lift & bay equipment per bay (month 1) ($) | B12: =Inputs!$B$44 -> 22000 | C12: =Inputs!$C$44 -> 22000 | D12: =Inputs!$D$44 -> 22000 | E12: =Inputs!$E$44 -> 22000
A13: Equity raised at start ($) | B13: =Inputs!$B$67 -> 480000 | C13: =Inputs!$C$67 -> 480000 | D13: =Inputs!$D$67 -> 480000 | E13: =Inputs!$E$67 -> 480000
A15: Results by scenario ($'000)
A16: Output | B16: Low | C16: Base | D16: High | E16: Active
A17: Revenue — final year | B17: =F30 -> 1474694.1 | C17: =F31 -> 2372818.7 | D17: =F32 -> 3288753.2 | E17: ='P&L'!F5 -> 2372818.7
A18: Revenue — whole plan | B18: =SUM(B30:F30) -> 6525711.6 | C18: =SUM(B31:F31) -> 9969204.3 | D18: =SUM(B32:F32) -> 13811972 | E18: =SUM('P&L'!$B$5:$F$5) -> 9969204.3
A19: EBITDA — final year | B19: =F36 -> -217532.97 | C19: =F37 -> 470349.01 | D19: =F38 -> 1158398.3 | E19: ='P&L'!F16 -> 470349.01
A20: EBITDA margin — final year | B20: =IF(B17=0,0,B19/B17) -> -0.14751058 | C20: =IF(C17=0,0,C19/C17) -> 0.19822375 | D20: =IF(D17=0,0,D19/D17) -> 0.35223023 | E20: =IF(E17=0,0,E19/E17) -> 0.19822375
A21: Net income — final year | B21: =F42 -> -283586.54 | C21: =F43 -> 319393.4 | D21: =F44 -> 862952.33 | E21: ='P&L'!F23 -> 319393.4
A22: Net income — whole plan | B22: =SUM(B42:F42) -> -1711891.7 | C22: =SUM(B43:F43) -> 709207.99 | D22: =SUM(B44:F44) -> 3004950.9 | E22: =SUM('P&L'!$B$23:$F$23) -> 709207.99
A23: Cash at the end of the plan | B23: =F48 -> -1323478.8 | C23: =F49 -> 1099044.1 | D23: =F50 -> 3396116.6 | E23: ='Balance Sheet'!F5 -> 1099044.1
A24: Lowest cash balance | B24: =MIN('Scenario calc'!$C$93:$BJ$93) -> -1323478.8 | C24: =MIN('Scenario calc'!$C$215:$BJ$215) -> 83558.366 | D24: =MIN('Scenario calc'!$C$337:$BJ$337) -> 316875.55 | E24: ='Break-even'!B18 -> 83558.366
A25: Lowest cash point (month #) | B25: =MATCH(MIN('Scenario calc'!$C$93:$BJ$93),'Scenario calc'!$C$93:$BJ$93,0) -> 60 | C25: =MATCH(MIN('Scenario calc'!$C$215:$BJ$215),'Scenario calc'!$C$215:$BJ$215,0) -> 10 | D25: =MATCH(MIN('Scenario calc'!$C$337:$BJ$337),'Scenario calc'!$C$337:$BJ$337,0) -> 4 | E25: ='Break-even'!B6 -> 10
A26: Funding required (incl. cash buffer) | B26: =SUMPRODUCT(--('Scenario calc'!$C$6:$BJ$6<=B25),'Scenario calc'!$C$65:$BJ$65)-SUMPRODUCT(--('Scenario calc'!$C$6:$BJ$6<=B25),'Scenario calc'!$C$87:$BJ$87)-SUMPRODUCT(--('Scenario calc'!$C$6:$BJ$6<=B25),'Scenario calc'!$C$75:$BJ$75)+Inputs!$B$82 -> 2231478.8 | C26: =SUMPRODUCT(--('Scenario calc'!$C$128:$BJ$128<=C25),'Scenario calc'!$C$187:$BJ$187)-SUMPRODUCT(--('Scenario calc'!$C$128:$BJ$128<=C25),'Scenario calc'!$C$209:$BJ$209)-SUMPRODUCT(--('Scenario calc'!$C$128:$BJ$128<=C25),'Scenario calc'!$C$197:$BJ$197)+Inputs!$C$82 -> 824441.63 | D26: =SUMPRODUCT(--('Scenario calc'!$C$250:$BJ$250<=D25),'Scenario calc'!$C$309:$BJ$309)-SUMPRODUCT(--('Scenario calc'!$C$250:$BJ$250<=D25),'Scenario calc'!$C$331:$BJ$331)-SUMPRODUCT(--('Scenario calc'!$C$250:$BJ$250<=D25),'Scenario calc'!$C$319:$BJ$319)+Inputs!$D$82 -> 591124.45 | E26: ='Break-even'!B12 -> 824441.63
A28: Revenue by year ($'000)
A29: Scenario | B29: 1 | C29: 2 | D29: 3 | E29: 4 | F29: 5
A30: Low | B30: =SUMIF('Scenario calc'!$C$7:$BJ$7,B$29,'Scenario calc'!$C$30:$BJ$30) -> 766147.8 | C30: =SUMIF('Scenario calc'!$C$7:$BJ$7,C$29,'Scenario calc'!$C$30:$BJ$30) -> 1379139.9 | D30: =SUMIF('Scenario calc'!$C$7:$BJ$7,D$29,'Scenario calc'!$C$30:$BJ$30) -> 1445636.8 | E30: =SUMIF('Scenario calc'!$C$7:$BJ$7,E$29,'Scenario calc'!$C$30:$BJ$30) -> 1460093.1 | F30: =SUMIF('Scenario calc'!$C$7:$BJ$7,F$29,'Scenario calc'!$C$30:$BJ$30) -> 1474694.1
A31: Base | B31: =SUMIF('Scenario calc'!$C$129:$BJ$129,B$29,'Scenario calc'!$C$152:$BJ$152) -> 1264359.4 | C31: =SUMIF('Scenario calc'!$C$129:$BJ$129,C$29,'Scenario calc'!$C$152:$BJ$152) -> 1987198.3 | D31: =SUMIF('Scenario calc'!$C$129:$BJ$129,D$29,'Scenario calc'!$C$152:$BJ$152) -> 2108218.7 | E31: =SUMIF('Scenario calc'!$C$129:$BJ$129,E$29,'Scenario calc'!$C$152:$BJ$152) -> 2236609.2 | F31: =SUMIF('Scenario calc'!$C$129:$BJ$129,F$29,'Scenario calc'!$C$152:$BJ$152) -> 2372818.7
A32: High | B32: =SUMIF('Scenario calc'!$C$251:$BJ$251,B$29,'Scenario calc'!$C$274:$BJ$274) -> 1874160 | C32: =SUMIF('Scenario calc'!$C$251:$BJ$251,C$29,'Scenario calc'!$C$274:$BJ$274) -> 2609777.7 | D32: =SUMIF('Scenario calc'!$C$251:$BJ$251,D$29,'Scenario calc'!$C$274:$BJ$274) -> 2877018.9 | E32: =SUMIF('Scenario calc'!$C$251:$BJ$251,E$29,'Scenario calc'!$C$274:$BJ$274) -> 3162262.7 | F32: =SUMIF('Scenario calc'!$C$251:$BJ$251,F$29,'Scenario calc'!$C$274:$BJ$274) -> 3288753.2
A34: EBITDA by year ($'000)
A35: Scenario | B35: 1 | C35: 2 | D35: 3 | E35: 4 | F35: 5
A36: Low | B36: =SUMIF('Scenario calc'!$C$7:$BJ$7,B$35,'Scenario calc'!$C$48:$BJ$48) -> -599131.83 | C36: =SUMIF('Scenario calc'!$C$7:$BJ$7,C$35,'Scenario calc'!$C$48:$BJ$48) -> -193996.8 | D36: =SUMIF('Scenario calc'!$C$7:$BJ$7,D$35,'Scenario calc'!$C$48:$BJ$48) -> -171788.17 | E36: =SUMIF('Scenario calc'!$C$7:$BJ$7,E$35,'Scenario calc'!$C$48:$BJ$48) -> -192042.36 | F36: =SUMIF('Scenario calc'!$C$7:$BJ$7,F$35,'Scenario calc'!$C$48:$BJ$48) -> -217532.97
A37: Base | B37: =SUMIF('Scenario calc'!$C$129:$BJ$129,B$35,'Scenario calc'!$C$170:$BJ$170) -> -231022.34 | C37: =SUMIF('Scenario calc'!$C$129:$BJ$129,C$35,'Scenario calc'!$C$170:$BJ$170) -> 264690.01 | D37: =SUMIF('Scenario calc'!$C$129:$BJ$129,D$35,'Scenario calc'!$C$170:$BJ$170) -> 331418.32 | E37: =SUMIF('Scenario calc'!$C$129:$BJ$129,E$35,'Scenario calc'!$C$170:$BJ$170) -> 399696.18 | F37: =SUMIF('Scenario calc'!$C$129:$BJ$129,F$35,'Scenario calc'!$C$170:$BJ$170) -> 470349.01
A38: High | B38: =SUMIF('Scenario calc'!$C$251:$BJ$251,B$35,'Scenario calc'!$C$292:$BJ$292) -> 232857.52 | C38: =SUMIF('Scenario calc'!$C$251:$BJ$251,C$35,'Scenario calc'!$C$292:$BJ$292) -> 743169.36 | D38: =SUMIF('Scenario calc'!$C$251:$BJ$251,D$35,'Scenario calc'!$C$292:$BJ$292) -> 912841.9 | E38: =SUMIF('Scenario calc'!$C$251:$BJ$251,E$35,'Scenario calc'!$C$292:$BJ$292) -> 1093867.8 | F38: =SUMIF('Scenario calc'!$C$251:$BJ$251,F$35,'Scenario calc'!$C$292:$BJ$292) -> 1158398.3
A40: Net income by year ($'000)
A41: Scenario | B41: 1 | C41: 2 | D41: 3 | E41: 4 | F41: 5
A42: Low | B42: =SUMIF('Scenario calc'!$C$7:$BJ$7,B$41,'Scenario calc'!$C$57:$BJ$57) -> -668031.38 | C42: =SUMIF('Scenario calc'!$C$7:$BJ$7,C$41,'Scenario calc'!$C$57:$BJ$57) -> -262193.23 | D42: =SUMIF('Scenario calc'!$C$7:$BJ$7,D$41,'Scenario calc'!$C$57:$BJ$57) -> -239270.32 | E42: =SUMIF('Scenario calc'!$C$7:$BJ$7,E$41,'Scenario calc'!$C$57:$BJ$57) -> -258810.22 | F42: =SUMIF('Scenario calc'!$C$7:$BJ$7,F$41,'Scenario calc'!$C$57:$BJ$57) -> -283586.54
A43: Base | B43: =SUMIF('Scenario calc'!$C$129:$BJ$129,B$41,'Scenario calc'!$C$179:$BJ$179) -> -299921.9 | C43: =SUMIF('Scenario calc'!$C$129:$BJ$129,C$41,'Scenario calc'!$C$179:$BJ$179) -> 196493.58 | D43: =SUMIF('Scenario calc'!$C$129:$BJ$129,D$41,'Scenario calc'!$C$179:$BJ$179) -> 230229.53 | E43: =SUMIF('Scenario calc'!$C$129:$BJ$129,E$41,'Scenario calc'!$C$179:$BJ$179) -> 263013.37 | F43: =SUMIF('Scenario calc'!$C$129:$BJ$129,F$41,'Scenario calc'!$C$179:$BJ$179) -> 319393.4
A44: High | B44: =SUMIF('Scenario calc'!$C$251:$BJ$251,B$41,'Scenario calc'!$C$301:$BJ$301) -> 129526.79 | C44: =SUMIF('Scenario calc'!$C$251:$BJ$251,C$41,'Scenario calc'!$C$301:$BJ$301) -> 533228.62 | D44: =SUMIF('Scenario calc'!$C$251:$BJ$251,D$41,'Scenario calc'!$C$301:$BJ$301) -> 667834.21 | E44: =SUMIF('Scenario calc'!$C$251:$BJ$251,E$41,'Scenario calc'!$C$301:$BJ$301) -> 811408.92 | F44: =SUMIF('Scenario calc'!$C$251:$BJ$251,F$41,'Scenario calc'!$C$301:$BJ$301) -> 862952.33
A46: Cash at year end by year ($'000)
A47: Scenario | B47: 1 | C47: 2 | D47: 3 | E47: 4 | F47: 5
...

Sheet Break-even
A1: Startup costs, funding need and break-even | H1: =HYPERLINK("#'Cover'!A1","◂ Contents") -> ◂ Contents
A2: Live for the selected scenario. Periods are counted in months from the start of the plan.
A3: Scenario shown | B3: =CHOOSE(Dashboard!$B$4,"Low","Base","High") -> Base
A5: Startup costs & funding need (up to the lowest cash point)
A6: Lowest cash point (month #) | B6: =MATCH(MIN(Monthly!$C$91:$BJ$91),Monthly!$C$91:$BJ$91,0) -> 10
A7: Capital spending up to the lowest cash point | B7: =SUMPRODUCT(--(Monthly!$C$4:$BJ$4<=$B$6),Monthly!$C$63:$BJ$63) -> 382000
A8: Operating cash burn up to the lowest cash point | B8: =-SUMPRODUCT(--(Monthly!$C$4:$BJ$4<=$B$6),Monthly!$C$85:$BJ$85) -> 237655.92 | D8: Losses and working capital before the business funds itself
A9: Loan repayments up to the lowest cash point | B9: =-SUMPRODUCT(--(Monthly!$C$4:$BJ$4<=$B$6),Monthly!$C$73:$BJ$73) -> 26785.714
A10: Total uses of funds | B10: =B7+B8+B9 -> 646441.63
A11: Minimum cash buffer to keep | B11: =Inputs!$E$82 -> 178000 | D11: Input on the Inputs sheet
A12: Funding required (uses + buffer) | B12: =B10+B11 -> 824441.63
A14: Equity raised | B14: =Inputs!$E$67 -> 480000
A15: Loan drawn | B15: =Inputs!$E$68 -> 250000
A16: Total sources of funds | B16: =B14+B15 -> 730000
A17: Funding surplus / (shortfall) | B17: =B16-B12 -> -94441.634 | D17: Negative = raise at least this much more
A18: Lowest cash balance in the plan | B18: =MIN(Monthly!$C$91:$BJ$91) -> 83558.366 | D18: Equals sources minus uses
A20: Break-even timing
A21: First month with positive EBITDA (month #) | B21: =IFERROR(MATCH(1,Monthly!$C$92:$BJ$92,0),"Not within horizon") -> 10
A22: First month with positive net income (month #) | B22: =IFERROR(MATCH(1,Monthly!$C$95:$BJ$95,0),"Not within horizon") -> 12
A23: Cash invested paid back (month #) | B23: =IF(MIN(Monthly!$C$97:$BJ$97)>=0,"No investment to pay back",IFERROR(MATCH(1,Monthly!$C$99:$BJ$99,0),"Not within horizon")) -> 41 | D23: Cumulative operating + investing cash flow back to zero
A25: Annual break-even revenue
A26: Year # | B26: 1 | C26: 2 | D26: 3 | E26: 4 | F26: 5
B27: Year 1 | C27: Year 2 | D27: Year 3 | E27: Year 4 | F27: Year 5
A28: Revenue | B28: =SUMIF(Monthly!$C$5:$BJ$5,B$26,Monthly!$C$28:$BJ$28) -> 1264359.4 | C28: =SUMIF(Monthly!$C$5:$BJ$5,C$26,Monthly!$C$28:$BJ$28) -> 1987198.3 | D28: =SUMIF(Monthly!$C$5:$BJ$5,D$26,Monthly!$C$28:$BJ$28) -> 2108218.7 | E28: =SUMIF(Monthly!$C$5:$BJ$5,E$26,Monthly!$C$28:$BJ$28) -> 2236609.2 | F28: =SUMIF(Monthly!$C$5:$BJ$5,F$26,Monthly!$C$28:$BJ$28) -> 2372818.7
A29: Gross profit | B29: =SUMIF(Monthly!$C$5:$BJ$5,B$26,Monthly!$C$36:$BJ$36) -> 481658.44 | C29: =SUMIF(Monthly!$C$5:$BJ$5,C$26,Monthly!$C$36:$BJ$36) -> 999978.46 | D29: =SUMIF(Monthly!$C$5:$BJ$5,D$26,Monthly!$C$36:$BJ$36) -> 1075151.6 | E29: =SUMIF(Monthly!$C$5:$BJ$5,E$26,Monthly!$C$36:$BJ$36) -> 1155330.9 | F29: =SUMIF(Monthly!$C$5:$BJ$5,F$26,Monthly!$C$36:$BJ$36) -> 1240834.3
A30: Gross margin (contribution) | B30: =IF(B28=0,0,B29/B28) -> 0.38095058 | C30: =IF(C28=0,0,C29/C28) -> 0.5032102 | D30: =IF(D28=0,0,D29/D28) -> 0.50998104 | E30: =IF(E28=0,0,E29/E28) -> 0.51655467 | F30: =IF(F28=0,0,F29/F28) -> 0.52293683
A31: Operating expenses (treated as fixed) | B31: =-SUMIF(Monthly!$C$5:$BJ$5,B$26,Monthly!$C$45:$BJ$45) -> 712680.78 | C31: =-SUMIF(Monthly!$C$5:$BJ$5,C$26,Monthly!$C$45:$BJ$45) -> 735288.45 | D31: =-SUMIF(Monthly!$C$5:$BJ$5,D$26,Monthly!$C$45:$BJ$45) -> 743733.24 | E31: =-SUMIF(Monthly!$C$5:$BJ$5,E$26,Monthly!$C$45:$BJ$45) -> 755634.75 | F31: =-SUMIF(Monthly!$C$5:$BJ$5,F$26,Monthly!$C$45:$BJ$45) -> 770485.29
A32: Break-even revenue (EBITDA = 0) | B32: =IF(B30>0,B31/B30,"n/a") -> 1870795.9 | C32: =IF(C30>0,C31/C30,"n/a") -> 1461195.4 | D32: =IF(D30>0,D31/D30,"n/a") -> 1458354.7 | E32: =IF(E30>0,E31/E30,"n/a") -> 1462836 | F32: =IF(F30>0,F31/F30,"n/a") -> 1473381.2
A33: Margin of safety (revenue above break-even) | B33: =IF(AND(ISNUMBER(B32),B28>0),(B28-B32)/B28,"n/a") -> -0.47963936 | C33: =IF(AND(ISNUMBER(C32),C28>0),(C28-C32)/C28,"n/a") -> 0.26469571 | D33: =IF(AND(ISNUMBER(D32),D28>0),(D28-D32)/D28,"n/a") -> 0.30825266 | E33: =IF(AND(ISNUMBER(E32),E28>0),(E28-E32)/E28,"n/a") -> 0.34595817 | F33: =IF(AND(ISNUMBER(F32),F28>0),(F28-F32)/F28,"n/a") -> 0.37905868
A35: Simplification: cost of sales is treated as variable and operating expenses as fixed, so break-even revenue = operating expenses ÷ gross margin.

Sheet Valuation
A1: Discounted cash flow valuation | H1: =HYPERLINK("#'Cover'!A1","◂ Contents") -> ◂ Contents
A2: Enterprise value at the start of the plan, before the funding raised in period 1. Year-end discounting.
A3: Scenario shown | B3: =CHOOSE(Dashboard!$B$4,"Low","Base","High") -> Base
A5: Assumptions (active scenario, from the Inputs sheet)
A6: Discount rate (WACC) | B6: =Inputs!$E$85 -> 0.25
A7: Terminal growth rate | B7: =Inputs!$E$86 -> 0.02
A8: Exit multiple (EV ÷ final-year EBITDA) | B8: =Inputs!$E$87 -> 4
A9: Tax rate (for the interest tax shield) | B9: =Inputs!$E$79 -> 0.21
A10: Sensitivity step: WACC | B10: =Inputs!$E$88 -> 0.01
A11: Sensitivity step: terminal growth | B11: =Inputs!$E$89 -> 0.005
A13: Free cash flow by year
A14: Year # | B14: 1 | C14: 2 | D14: 3 | E14: 4 | F14: 5
B15: Year 1 | C15: Year 2 | D15: Year 3 | E15: Year 4 | F15: Year 5
A16: EBITDA | B16: =SUMIF(Monthly!$C$5:$BJ$5,B$14,Monthly!$C$46:$BJ$46) -> -231022.34 | C16: =SUMIF(Monthly!$C$5:$BJ$5,C$14,Monthly!$C$46:$BJ$46) -> 264690.01 | D16: =SUMIF(Monthly!$C$5:$BJ$5,D$14,Monthly!$C$46:$BJ$46) -> 331418.32 | E16: =SUMIF(Monthly!$C$5:$BJ$5,E$14,Monthly!$C$46:$BJ$46) -> 399696.18 | F16: =SUMIF(Monthly!$C$5:$BJ$5,F$14,Monthly!$C$46:$BJ$46) -> 470349.01
A17: Unlevered free cash flow | B17: =SUMIF(Monthly!$C$5:$BJ$5,B$14,Monthly!$C$100:$BJ$100) -> -588902.19 | C17: =SUMIF(Monthly!$C$5:$BJ$5,C$14,Monthly!$C$100:$BJ$100) -> 242418.43 | D17: =SUMIF(Monthly!$C$5:$BJ$5,D$14,Monthly!$C$100:$BJ$100) -> 275774.43 | E17: =SUMIF(Monthly!$C$5:$BJ$5,E$14,Monthly!$C$100:$BJ$100) -> 308569.2 | F17: =SUMIF(Monthly!$C$5:$BJ$5,F$14,Monthly!$C$100:$BJ$100) -> 364962.6
A18: Discount factor | B18: =1/(1+Inputs!$E$85)^B$14 -> 0.8 | C18: =1/(1+Inputs!$E$85)^C$14 -> 0.64 | D18: =1/(1+Inputs!$E$85)^D$14 -> 0.512 | E18: =1/(1+Inputs!$E$85)^E$14 -> 0.4096 | F18: =1/(1+Inputs!$E$85)^F$14 -> 0.32768
A19: Present value of free cash flow | B19: =B17*B18 -> -471121.75 | C19: =C17*C18 -> 155147.8 | D19: =D17*D18 -> 141196.51 | E19: =E17*E18 -> 126389.94 | F19: =F17*F18 -> 119590.94
A21: Enterprise value
B22: Perpetual growth | C22: Exit multiple
A23: Present value of the plan's free cash flows | B23: =SUM($B$19:$F$19) -> 71203.439 | C23: =B23 -> 71203.439
A24: Final-year free cash flow | final-year EBITDA | B24: =$F$17 -> 364962.6 | C24: =$F$16 -> 470349.01
A25: Terminal value at the end of year 5 | B25: =IF($B$6>$B$7,B24*(1+$B$7)/($B$6-$B$7),0) -> 1618529.8 | C25: =C24*$B$8 -> 1881396.1
A26: Present value of the terminal value | B26: =B25/(1+$B$6)^$F$14 -> 530359.84 | C26: =C25/(1+$B$6)^$F$14 -> 616495.86
A27: Enterprise value | B27: =B23+B26 -> 601563.28 | C27: =C23+C26 -> 687699.3
A28: Terminal value share of enterprise value | B28: =IF(B27<>0,B26/B27,0) -> 0.881636 | C28: =IF(C27<>0,C26/C27,0) -> 0.89646138
A29: Cross-check: implied exit multiple | implied perpetual growth | B29: =IF(C24>0,B25/C24,"n/a") -> 3.4411251 | C29: =IF(C25+B24<>0,(C25*$B$6-B24)/(C25+B24),"n/a") -> 0.046914332
A30: Enterprise value — average of the two methods | B30: =AVERAGE(B27,C27) -> 644631.29
A32: Sensitivity: enterprise value (perpetual growth) by WACC and terminal growth
A33: WACC ↓ · terminal growth → | B33: =$B$7+(-2)*$B$11 -> 0.01 | C33: =$B$7+(-1)*$B$11 -> 0.015 | D33: =$B$7+(0)*$B$11 -> 0.02 | E33: =$B$7+(1)*$B$11 -> 0.025 | F33: =$B$7+(2)*$B$11 -> 0.03
A34: =$B$6+(-2)*$B$10 -> 0.23 | B34: =IF($A34>B$33,SUMPRODUCT($B$17:$F$17/(1+$A34)^$B$14:$F$14)+$F$17*(1+B$33)/($A34-B$33)/(1+$A34)^$F$14,"n/a") -> 689240.24 | C34: =IF($A34>C$33,SUMPRODUCT($B$17:$F$17/(1+$A34)^$B$14:$F$14)+$F$17*(1+C$33)/($A34-C$33)/(1+$A34)^$F$14,"n/a") -> 706095.55 | D34: =IF($A34>D$33,SUMPRODUCT($B$17:$F$17/(1+$A34)^$B$14:$F$14)+$F$17*(1+D$33)/($A34-D$33)/(1+$A34)^$F$14,"n/a") -> 723753.5 | E34: =IF($A34>E$33,SUMPRODUCT($B$17:$F$17/(1+$A34)^$B$14:$F$14)+$F$17*(1+E$33)/($A34-E$33)/(1+$A34)^$F$14,"n/a") -> 742272.81 | F34: =IF($A34>F$33,SUMPRODUCT($B$17:$F$17/(1+$A34)^$B$14:$F$14)+$F$17*(1+F$33)/($A34-F$33)/(1+$A34)^$F$14,"n/a") -> 761718.08
A35: =$B$6+(-1)*$B$10 -> 0.24 | B35: =IF($A35>B$33,SUMPRODUCT($B$17:$F$17/(1+$A35)^$B$14:$F$14)+$F$17*(1+B$33)/($A35-B$33)/(1+$A35)^$F$14,"n/a") -> 629067.87 | C35: =IF($A35>C$33,SUMPRODUCT($B$17:$F$17/(1+$A35)^$B$14:$F$14)+$F$17*(1+C$33)/($A35-C$33)/(1+$A35)^$F$14,"n/a") -> 643982.81 | D35: =IF($A35>D$33,SUMPRODUCT($B$17:$F$17/(1+$A35)^$B$14:$F$14)+$F$17*(1+D$33)/($A35-D$33)/(1+$A35)^$F$14,"n/a") -> 659575.69 | E35: =IF($A35>E$33,SUMPRODUCT($B$17:$F$17/(1+$A35)^$B$14:$F$14)+$F$17*(1+E$33)/($A35-E$33)/(1+$A35)^$F$14,"n/a") -> 675893.82 | F35: =IF($A35>F$33,SUMPRODUCT($B$17:$F$17/(1+$A35)^$B$14:$F$14)+$F$17*(1+F$33)/($A35-F$33)/(1+$A35)^$F$14,"n/a") -> 692989.01
