Workbook

Sheet Cover
B2: Bakery financial model (growing)
B3: 3-year financial model · monthly detail · Low / Base / High scenarios · US dollars · Full plan
B5: Purpose | D5: Revenue and profit plan
B6: Active scenario | D6: =Dashboard!C4&" (change it on the Dashboard, cell B4)" -> Base (change it on the Dashboard, cell B4)
B7: Model checks | D7: =Checks!B24 -> PASS
B8: Prepared | D8: 21 October 2026
B10: Contents
C11: PRESENTATION
B12: 1 | C12: =HYPERLINK("#Dashboard!A1","Dashboard") -> Dashboard | D12: Scenario switch, key numbers, core financials
B13: 2 | C13: =HYPERLINK("#Summary!A1","Summary") -> Summary | D13: Income statement, cash flow and balance sheet — every year and any year by month
B14: 3 | C14: =HYPERLINK("#'Break-even'!A1","Break-even") -> Break-even | D14: Startup costs, funding need, break-even timing and revenue
B15: 4 | C15: =HYPERLINK("#Valuation!A1","Valuation") -> Valuation | D15: Free cash flow, DCF (perpetual growth and exit multiple), WACC × growth sensitivity
B16: 5 | C16: =HYPERLINK("#'Sources & Uses'!A1","Sources & Uses") -> Sources & Uses | D16: Funding structure, sources and uses of cash for the first months
B17: 6 | C17: =HYPERLINK("#KPIs!A1","KPIs") -> KPIs | D17: Financial ratios, DuPont analysis, industry metrics
C18: INPUTS
B19: 7 | C19: =HYPERLINK("#Inputs!A1","Inputs") -> Inputs | D19: Every assumption, Low / Base / High, with units and comments
C20: STATEMENTS
B21: 8 | C21: =HYPERLINK("#'P&L'!A1","P&L") -> P&L | D21: Annual profit & loss
B22: 9 | C22: =HYPERLINK("#'Cash Flow'!A1","Cash Flow") -> Cash Flow | D22: Annual cash flow statement
B23: 10 | C23: =HYPERLINK("#'Balance Sheet'!A1","Balance Sheet") -> Balance Sheet | D23: Balance sheet at year end
C24: CALCULATIONS
B25: 11 | C25: =HYPERLINK("#Monthly!A1","Monthly") -> Monthly | D25: Month-by-month engine of the model
B26: 12 | C26: =HYPERLINK("#Headcount!A1","Headcount") -> Headcount | D26: Team and payroll
C27: CONTROL
B28: 13 | C28: =HYPERLINK("#Checks!A1","Checks") -> Checks | D28: Live integrity checks and the overall verdict
B30: How to read this file
C31: 1000 | D31: Input you can change — yellow cell with a blue figure (Inputs sheet and the view switches)
C32: 1000 | D32: Formula — calculated, do not overwrite
C33: 1000 | D33: Link to another sheet
C34: 1000 | D34: Active value the model uses (follows the scenario)

Sheet Dashboard
A1: Dashboard | W1: =HYPERLINK("#'Cover'!A1","◂ Contents") -> ◂ Contents
A2: Bakery financial model (growing)
A4: Active scenario | B4: 2 | C4: =CHOOSE(B4,"Low","Base","High") -> Base | D4: 1 = Low · 2 = Base · 3 = High — every sheet follows this cell | S4: Model checks | T4: =Checks!B24 -> PASS
A6: REVENUE · YEAR 3 | C6: EBITDA MARGIN · YEAR 3 | H6: NET INCOME · YEAR 3 | L6: LOWEST CASH BALANCE | P6: FUNDING REQUIRED | T6: ENTERPRISE VALUE (DCF)
A7: =D12 -> 1890162.9 | C7: =D17 -> 0.12348307 | H7: =D18 -> 169019.96 | L7: =F39 -> 43218.391 | P7: =F37 -> 329781.61 | T7: =F44 -> 1043766.4
A8: =IF(AND(B12>0,D12>=0),(D12/B12)^(1/2)-1,"CAGR n/a") -> 0.094434492 | C8: =D16 -> 233403.12 | H8: =D19 -> 0.089420843 | L8: ='Break-even'!B6 -> 1 | P8: =IF(F38>=0,"Covered by funding raised",-F38) -> 189781.61 | T8: Average of 2 methods
A10: Core financials ($'000) — active scenario
B11: 1 | C11: 2 | D11: 3
A12: Revenue | B12: =SUMIF(Monthly!$C$5:$AL$5,B$11,Monthly!$C$22:$AL$22) -> 1578046.1 | C12: =SUMIF(Monthly!$C$5:$AL$5,C$11,Monthly!$C$22:$AL$22) -> 1736372.4 | D12: =SUMIF(Monthly!$C$5:$AL$5,D$11,Monthly!$C$22:$AL$22) -> 1890162.9
A13: Gross profit | B13: =SUMIF(Monthly!$C$5:$AL$5,B$11,Monthly!$C$29:$AL$29) -> 1077227.7 | C13: =SUMIF(Monthly!$C$5:$AL$5,C$11,Monthly!$C$29:$AL$29) -> 1183311.2 | D13: =SUMIF(Monthly!$C$5:$AL$5,D$11,Monthly!$C$29:$AL$29) -> 1285883.7
A14: Gross margin | B14: =IF(B12=0,0,B13/B12) -> 0.68263384 | C14: =IF(C12=0,0,C13/C12) -> 0.68148469 | D14: =IF(D12=0,0,D13/D12) -> 0.68030311
A15: Operating expenses | B15: =SUMIF(Monthly!$C$5:$AL$5,B$11,Monthly!$C$40:$AL$40) -> -931495.62 | C15: =SUMIF(Monthly!$C$5:$AL$5,C$11,Monthly!$C$40:$AL$40) -> -990021.96 | D15: =SUMIF(Monthly!$C$5:$AL$5,D$11,Monthly!$C$40:$AL$40) -> -1052480.5
A16: EBITDA | B16: =SUMIF(Monthly!$C$5:$AL$5,B$11,Monthly!$C$41:$AL$41) -> 145732.04 | C16: =SUMIF(Monthly!$C$5:$AL$5,C$11,Monthly!$C$41:$AL$41) -> 193289.21 | D16: =SUMIF(Monthly!$C$5:$AL$5,D$11,Monthly!$C$41:$AL$41) -> 233403.12
A17: EBITDA margin | B17: =IF(B12=0,0,B16/B12) -> 0.092349671 | C17: =IF(C12=0,0,C16/C12) -> 0.11131783 | D17: =IF(D12=0,0,D16/D12) -> 0.12348307
A18: Net income | B18: =SUMIF(Monthly!$C$5:$AL$5,B$11,Monthly!$C$50:$AL$50) -> 100050.56 | C18: =SUMIF(Monthly!$C$5:$AL$5,C$11,Monthly!$C$50:$AL$50) -> 137835.57 | D18: =SUMIF(Monthly!$C$5:$AL$5,D$11,Monthly!$C$50:$AL$50) -> 169019.96
A19: Net margin | B19: =IF(B12=0,0,B18/B12) -> 0.063401547 | C19: =IF(C12=0,0,C18/C12) -> 0.079381341 | D19: =IF(D12=0,0,D18/D12) -> 0.089420843
A20: Operating cash flow | B20: =SUMIF(Monthly!$C$5:$AL$5,B$11,Monthly!$C$74:$AL$74) -> 101363.96 | C20: =SUMIF(Monthly!$C$5:$AL$5,C$11,Monthly!$C$74:$AL$74) -> 150896.6 | D20: =SUMIF(Monthly!$C$5:$AL$5,D$11,Monthly!$C$74:$AL$74) -> 184000.33
A21: Investing cash flow | B21: =SUMIF(Monthly!$C$5:$AL$5,B$11,Monthly!$C$75:$AL$75) -> -90000 | C21: =SUMIF(Monthly!$C$5:$AL$5,C$11,Monthly!$C$75:$AL$75) -> -14000 | D21: =SUMIF(Monthly!$C$5:$AL$5,D$11,Monthly!$C$75:$AL$75) -> -14000
A22: Financing cash flow | B22: =SUMIF(Monthly!$C$5:$AL$5,B$11,Monthly!$C$77:$AL$77) -> 125333.33 | C22: =SUMIF(Monthly!$C$5:$AL$5,C$11,Monthly!$C$77:$AL$77) -> -16000 | D22: =SUMIF(Monthly!$C$5:$AL$5,D$11,Monthly!$C$77:$AL$77) -> -16000
A23: Net change in cash | B23: =SUMIF(Monthly!$C$5:$AL$5,B$11,Monthly!$C$78:$AL$78) -> 136697.29 | C23: =SUMIF(Monthly!$C$5:$AL$5,C$11,Monthly!$C$78:$AL$78) -> 120896.6 | D23: =SUMIF(Monthly!$C$5:$AL$5,D$11,Monthly!$C$78:$AL$78) -> 154000.33
A24: Year-end cash | B24: =INDEX(Monthly!$C$80:$AL$80,B$11*12) -> 136697.29 | C24: =INDEX(Monthly!$C$80:$AL$80,C$11*12) -> 257593.89 | D24: =INDEX(Monthly!$C$80:$AL$80,D$11*12) -> 411594.23
A26: Bakery metrics
B27: 1 | C27: 2 | D27: 3
A28: Retail counter revenue | B28: =KPIs!B35 -> 1134382.1 | C28: =KPIs!C35 -> 1218082.9 | D28: =KPIs!D35 -> 1292264.2
A29: Wholesale revenue | B29: =KPIs!B36 -> 443664 | C29: =KPIs!C36 -> 518289.41 | D29: =KPIs!D36 -> 597898.66
A30: Customers per day (average) | B30: =KPIs!B31 -> 316.16 | C30: =KPIs!C31 -> 329.6 | D30: =KPIs!D31 -> 339.488
A31: Wholesale accounts (year end) | B31: =KPIs!B33 -> 16 | C31: =KPIs!C33 -> 17.92 | D31: =KPIs!D33 -> 20.0704
A32: Team (FTE, year end) | B32: =INDEX(Headcount!$C$11:$AL$11,B$27*12) -> 13.5 | C32: =INDEX(Headcount!$C$11:$AL$11,C$27*12) -> 14.22 | D32: =INDEX(Headcount!$C$11:$AL$11,D$27*12) -> 14.9832
A34: Funding & valuation ($'000) — active scenario
A35: Equity raised | F35: =Inputs!$E$58 -> 60000
A36: Loan drawn | F36: =Inputs!$E$59 -> 80000
A37: Funding required (incl. cash buffer) | F37: ='Break-even'!B12 -> 329781.61
A38: Funding surplus / (shortfall) | F38: ='Break-even'!B17 -> -189781.61
A39: ="Lowest cash balance (month "&'Break-even'!B6&")" -> Lowest cash balance (month 1) | F39: ='Break-even'!B18 -> 43218.391
A40: First month with positive EBITDA | F40: ='Break-even'!B21 -> 1
A41: Cash invested paid back | F41: ='Break-even'!B23 -> 12
A42: Enterprise value — perpetual growth | F42: =Valuation!B27 -> 1035783.3
A43: Enterprise value — exit multiple | F43: =Valuation!C27 -> 1051749.5
A44: Enterprise value — average | F44: =Valuation!B30 -> 1043766.4

Sheet Summary
A1: Financial statements summary | U1: =HYPERLINK("#'Cover'!A1","◂ Contents") -> ◂ Contents
A2: Bakery financial model (growing) | P2: Select detailed year: | R2: 1
A5: Income statement ($'000) — by year | H5: ="Income statement ($'000) — Year "&$R$2&", by month" -> Income statement ($'000) — Year 1, by month
B6: 1 | C6: 2 | D6: 3 | H6: =INDEX(Monthly!$C$4:$AL$4,($R$2-1)*12+1) -> 1 | I6: =INDEX(Monthly!$C$4:$AL$4,($R$2-1)*12+2) -> 2 | J6: =INDEX(Monthly!$C$4:$AL$4,($R$2-1)*12+3) -> 3 | K6: =INDEX(Monthly!$C$4:$AL$4,($R$2-1)*12+4) -> 4 | L6: =INDEX(Monthly!$C$4:$AL$4,($R$2-1)*12+5) -> 5 | M6: =INDEX(Monthly!$C$4:$AL$4,($R$2-1)*12+6) -> 6 | N6: =INDEX(Monthly!$C$4:$AL$4,($R$2-1)*12+7) -> 7 | O6: =INDEX(Monthly!$C$4:$AL$4,($R$2-1)*12+8) -> 8 | P6: =INDEX(Monthly!$C$4:$AL$4,($R$2-1)*12+9) -> 9 | Q6: =INDEX(Monthly!$C$4:$AL$4,($R$2-1)*12+10) -> 10 | R6: =INDEX(Monthly!$C$4:$AL$4,($R$2-1)*12+11) -> 11 | S6: =INDEX(Monthly!$C$4:$AL$4,($R$2-1)*12+12) -> 12
A7: Revenue | B7: ='P&L'!B5 -> 1578046.1 | C7: ='P&L'!C5 -> 1736372.4 | D7: ='P&L'!D5 -> 1890162.9 | H7: =INDEX(Monthly!$C$22:$AL$22,($R$2-1)*12+1) -> 116363.52 | I7: =INDEX(Monthly!$C$22:$AL$22,($R$2-1)*12+2) -> 122828.16 | J7: =INDEX(Monthly!$C$22:$AL$22,($R$2-1)*12+3) -> 129292.8 | K7: =INDEX(Monthly!$C$22:$AL$22,($R$2-1)*12+4) -> 129292.8 | L7: =INDEX(Monthly!$C$22:$AL$22,($R$2-1)*12+5) -> 129292.8 | M7: =INDEX(Monthly!$C$22:$AL$22,($R$2-1)*12+6) -> 129292.8 | N7: =INDEX(Monthly!$C$22:$AL$22,($R$2-1)*12+7) -> 129292.8 | O7: =INDEX(Monthly!$C$22:$AL$22,($R$2-1)*12+8) -> 129292.8 | P7: =INDEX(Monthly!$C$22:$AL$22,($R$2-1)*12+9) -> 129292.8 | Q7: =INDEX(Monthly!$C$22:$AL$22,($R$2-1)*12+10) -> 129292.8 | R7: =INDEX(Monthly!$C$22:$AL$22,($R$2-1)*12+11) -> 152256 | S7: =INDEX(Monthly!$C$22:$AL$22,($R$2-1)*12+12) -> 152256
A8: Cost of sales | B8: ='P&L'!B6 -> -500818.42 | C8: ='P&L'!C6 -> -553061.18 | D8: ='P&L'!D6 -> -604279.19 | H8: =INDEX(Monthly!$C$28:$AL$28,($R$2-1)*12+1) -> -36994.826 | I8: =INDEX(Monthly!$C$28:$AL$28,($R$2-1)*12+2) -> -39050.094 | J8: =INDEX(Monthly!$C$28:$AL$28,($R$2-1)*12+3) -> -41105.362 | K8: =INDEX(Monthly!$C$28:$AL$28,($R$2-1)*12+4) -> -41105.362 | L8: =INDEX(Monthly!$C$28:$AL$28,($R$2-1)*12+5) -> -41105.362 | M8: =INDEX(Monthly!$C$28:$AL$28,($R$2-1)*12+6) -> -41105.362 | N8: =INDEX(Monthly!$C$28:$AL$28,($R$2-1)*12+7) -> -41105.362 | O8: =INDEX(Monthly!$C$28:$AL$28,($R$2-1)*12+8) -> -41105.362 | P8: =INDEX(Monthly!$C$28:$AL$28,($R$2-1)*12+9) -> -41105.362 | Q8: =INDEX(Monthly!$C$28:$AL$28,($R$2-1)*12+10) -> -41105.362 | R8: =INDEX(Monthly!$C$28:$AL$28,($R$2-1)*12+11) -> -47965.303 | S8: =INDEX(Monthly!$C$28:$AL$28,($R$2-1)*12+12) -> -47965.303
A9: Gross profit | B9: ='P&L'!B7 -> 1077227.7 | C9: ='P&L'!C7 -> 1183311.2 | D9: ='P&L'!D7 -> 1285883.7 | H9: =INDEX(Monthly!$C$29:$AL$29,($R$2-1)*12+1) -> 79368.694 | I9: =INDEX(Monthly!$C$29:$AL$29,($R$2-1)*12+2) -> 83778.066 | J9: =INDEX(Monthly!$C$29:$AL$29,($R$2-1)*12+3) -> 88187.438 | K9: =INDEX(Monthly!$C$29:$AL$29,($R$2-1)*12+4) -> 88187.438 | L9: =INDEX(Monthly!$C$29:$AL$29,($R$2-1)*12+5) -> 88187.438 | M9: =INDEX(Monthly!$C$29:$AL$29,($R$2-1)*12+6) -> 88187.438 | N9: =INDEX(Monthly!$C$29:$AL$29,($R$2-1)*12+7) -> 88187.438 | O9: =INDEX(Monthly!$C$29:$AL$29,($R$2-1)*12+8) -> 88187.438 | P9: =INDEX(Monthly!$C$29:$AL$29,($R$2-1)*12+9) -> 88187.438 | Q9: =INDEX(Monthly!$C$29:$AL$29,($R$2-1)*12+10) -> 88187.438 | R9: =INDEX(Monthly!$C$29:$AL$29,($R$2-1)*12+11) -> 104290.7 | S9: =INDEX(Monthly!$C$29:$AL$29,($R$2-1)*12+12) -> 104290.7
A10: Gross margin | B10: ='P&L'!B8 -> 0.68263384 | C10: ='P&L'!C8 -> 0.68148469 | D10: ='P&L'!D8 -> 0.68030311 | H10: =IF(H7=0,0,H9/H7) -> 0.6820754 | I10: =IF(I7=0,0,I9/I7) -> 0.6820754 | J10: =IF(J7=0,0,J9/J7) -> 0.6820754 | K10: =IF(K7=0,0,K9/K7) -> 0.6820754 | L10: =IF(L7=0,0,L9/L7) -> 0.6820754 | M10: =IF(M7=0,0,M9/M7) -> 0.6820754 | N10: =IF(N7=0,0,N9/N7) -> 0.6820754 | O10: =IF(O7=0,0,O9/O7) -> 0.6820754 | ... S10: =IF(S7=0,0,S9/S7) -> 0.68496937
A11: Total operating expenses | B11: ='P&L'!B17 -> -931495.62 | C11: ='P&L'!C17 -> -990021.96 | D11: ='P&L'!D17 -> -1052480.5 | H11: =INDEX(Monthly!$C$40:$AL$40,($R$2-1)*12+1) -> -76716.628 | I11: =INDEX(Monthly!$C$40:$AL$40,($R$2-1)*12+2) -> -77130.514 | J11: =INDEX(Monthly!$C$40:$AL$40,($R$2-1)*12+3) -> -77544.401 | K11: =INDEX(Monthly!$C$40:$AL$40,($R$2-1)*12+4) -> -77544.401 | L11: =INDEX(Monthly!$C$40:$AL$40,($R$2-1)*12+5) -> -77544.401 | M11: =INDEX(Monthly!$C$40:$AL$40,($R$2-1)*12+6) -> -77544.401 | N11: =INDEX(Monthly!$C$40:$AL$40,($R$2-1)*12+7) -> -77544.401 | O11: =INDEX(Monthly!$C$40:$AL$40,($R$2-1)*12+8) -> -77544.401 | P11: =INDEX(Monthly!$C$40:$AL$40,($R$2-1)*12+9) -> -77544.401 | Q11: =INDEX(Monthly!$C$40:$AL$40,($R$2-1)*12+10) -> -77544.401 | R11: =INDEX(Monthly!$C$40:$AL$40,($R$2-1)*12+11) -> -78646.635 | S11: =INDEX(Monthly!$C$40:$AL$40,($R$2-1)*12+12) -> -78646.635
A12: EBITDA | B12: ='P&L'!B18 -> 145732.04 | C12: ='P&L'!C18 -> 193289.21 | D12: ='P&L'!D18 -> 233403.12 | H12: =INDEX(Monthly!$C$41:$AL$41,($R$2-1)*12+1) -> 2652.0663 | I12: =INDEX(Monthly!$C$41:$AL$41,($R$2-1)*12+2) -> 6647.5515 | J12: =INDEX(Monthly!$C$41:$AL$41,($R$2-1)*12+3) -> 10643.037 | K12: =INDEX(Monthly!$C$41:$AL$41,($R$2-1)*12+4) -> 10643.037 | L12: =INDEX(Monthly!$C$41:$AL$41,($R$2-1)*12+5) -> 10643.037 | M12: =INDEX(Monthly!$C$41:$AL$41,($R$2-1)*12+6) -> 10643.037 | N12: =INDEX(Monthly!$C$41:$AL$41,($R$2-1)*12+7) -> 10643.037 | O12: =INDEX(Monthly!$C$41:$AL$41,($R$2-1)*12+8) -> 10643.037 | P12: =INDEX(Monthly!$C$41:$AL$41,($R$2-1)*12+9) -> 10643.037 | Q12: =INDEX(Monthly!$C$41:$AL$41,($R$2-1)*12+10) -> 10643.037 | R12: =INDEX(Monthly!$C$41:$AL$41,($R$2-1)*12+11) -> 25644.062 | S12: =INDEX(Monthly!$C$41:$AL$41,($R$2-1)*12+12) -> 25644.062
A13: EBITDA margin | B13: ='P&L'!B19 -> 0.092349671 | C13: ='P&L'!C19 -> 0.11131783 | D13: ='P&L'!D19 -> 0.12348307 | H13: =IF(H7=0,0,H12/H7) -> 0.022791218 | I13: =IF(I7=0,0,I12/I7) -> 0.054120745 | J13: =IF(J7=0,0,J12/J7) -> 0.082317319 | K13: =IF(K7=0,0,K12/K7) -> 0.082317319 | L13: =IF(L7=0,0,L12/L7) -> 0.082317319 | M13: =IF(M7=0,0,M12/M7) -> 0.082317319 | N13: =IF(N7=0,0,N12/N7) -> 0.082317319 | O13: =IF(O7=0,0,O12/O7) -> 0.082317319 | ... S13: =IF(S7=0,0,S12/S7) -> 0.16842727
A14: Depreciation | B14: ='P&L'!B20 -> -12857.143 | C14: ='P&L'!C20 -> -13940.476 | D14: ='P&L'!D20 -> -15940.476 | H14: =INDEX(Monthly!$C$55:$AL$55,($R$2-1)*12+1) -> -1071.4286 | I14: =INDEX(Monthly!$C$55:$AL$55,($R$2-1)*12+2) -> -1071.4286 | J14: =INDEX(Monthly!$C$55:$AL$55,($R$2-1)*12+3) -> -1071.4286 | K14: =INDEX(Monthly!$C$55:$AL$55,($R$2-1)*12+4) -> -1071.4286 | L14: =INDEX(Monthly!$C$55:$AL$55,($R$2-1)*12+5) -> -1071.4286 | M14: =INDEX(Monthly!$C$55:$AL$55,($R$2-1)*12+6) -> -1071.4286 | N14: =INDEX(Monthly!$C$55:$AL$55,($R$2-1)*12+7) -> -1071.4286 | O14: =INDEX(Monthly!$C$55:$AL$55,($R$2-1)*12+8) -> -1071.4286 | P14: =INDEX(Monthly!$C$55:$AL$55,($R$2-1)*12+9) -> -1071.4286 | Q14: =INDEX(Monthly!$C$55:$AL$55,($R$2-1)*12+10) -> -1071.4286 | R14: =INDEX(Monthly!$C$55:$AL$55,($R$2-1)*12+11) -> -1071.4286 | S14: =INDEX(Monthly!$C$55:$AL$55,($R$2-1)*12+12) -> -1071.4286
A15: EBIT | B15: ='P&L'!B21 -> 132874.89 | C15: ='P&L'!C21 -> 179348.73 | D15: ='P&L'!D21 -> 217462.64 | H15: =INDEX(Monthly!$C$44:$AL$44,($R$2-1)*12+1) -> 1580.6377 | I15: =INDEX(Monthly!$C$44:$AL$44,($R$2-1)*12+2) -> 5576.1229 | J15: =INDEX(Monthly!$C$44:$AL$44,($R$2-1)*12+3) -> 9571.6081 | K15: =INDEX(Monthly!$C$44:$AL$44,($R$2-1)*12+4) -> 9571.6081 | L15: =INDEX(Monthly!$C$44:$AL$44,($R$2-1)*12+5) -> 9571.6081 | M15: =INDEX(Monthly!$C$44:$AL$44,($R$2-1)*12+6) -> 9571.6081 | N15: =INDEX(Monthly!$C$44:$AL$44,($R$2-1)*12+7) -> 9571.6081 | O15: =INDEX(Monthly!$C$44:$AL$44,($R$2-1)*12+8) -> 9571.6081 | P15: =INDEX(Monthly!$C$44:$AL$44,($R$2-1)*12+9) -> 9571.6081 | Q15: =INDEX(Monthly!$C$44:$AL$44,($R$2-1)*12+10) -> 9571.6081 | R15: =INDEX(Monthly!$C$44:$AL$44,($R$2-1)*12+11) -> 24572.634 | S15: =INDEX(Monthly!$C$44:$AL$44,($R$2-1)*12+12) -> 24572.634
A16: Interest | B16: ='P&L'!B22 -> -6228.6111 | C16: ='P&L'!C22 -> -4873.3333 | D16: ='P&L'!D22 -> -3513.3333 | H16: =INDEX(Monthly!$C$45:$AL$45,($R$2-1)*12+1) -> -566.66667 | I16: =INDEX(Monthly!$C$45:$AL$45,($R$2-1)*12+2) -> -561.94444 | J16: =INDEX(Monthly!$C$45:$AL$45,($R$2-1)*12+3) -> -552.5 | K16: =INDEX(Monthly!$C$45:$AL$45,($R$2-1)*12+4) -> -543.05556 | L16: =INDEX(Monthly!$C$45:$AL$45,($R$2-1)*12+5) -> -533.61111 | M16: =INDEX(Monthly!$C$45:$AL$45,($R$2-1)*12+6) -> -524.16667 | N16: =INDEX(Monthly!$C$45:$AL$45,($R$2-1)*12+7) -> -514.72222 | O16: =INDEX(Monthly!$C$45:$AL$45,($R$2-1)*12+8) -> -505.27778 | P16: =INDEX(Monthly!$C$45:$AL$45,($R$2-1)*12+9) -> -495.83333 | Q16: =INDEX(Monthly!$C$45:$AL$45,($R$2-1)*12+10) -> -486.38889 | R16: =INDEX(Monthly!$C$45:$AL$45,($R$2-1)*12+11) -> -476.94444 | S16: =INDEX(Monthly!$C$45:$AL$45,($R$2-1)*12+12) -> -467.5
A17: Pre-tax income | B17: ='P&L'!B23 -> 126646.28 | C17: ='P&L'!C23 -> 174475.4 | D17: ='P&L'!D23 -> 213949.31 | H17: =INDEX(Monthly!$C$46:$AL$46,($R$2-1)*12+1) -> 1013.9711 | I17: =INDEX(Monthly!$C$46:$AL$46,($R$2-1)*12+2) -> 5014.1785 | J17: =INDEX(Monthly!$C$46:$AL$46,($R$2-1)*12+3) -> 9019.1081 | K17: =INDEX(Monthly!$C$46:$AL$46,($R$2-1)*12+4) -> 9028.5525 | L17: =INDEX(Monthly!$C$46:$AL$46,($R$2-1)*12+5) -> 9037.997 | M17: =INDEX(Monthly!$C$46:$AL$46,($R$2-1)*12+6) -> 9047.4414 | N17: =INDEX(Monthly!$C$46:$AL$46,($R$2-1)*12+7) -> 9056.8859 | O17: =INDEX(Monthly!$C$46:$AL$46,($R$2-1)*12+8) -> 9066.3303 | P17: =INDEX(Monthly!$C$46:$AL$46,($R$2-1)*12+9) -> 9075.7747 | Q17: =INDEX(Monthly!$C$46:$AL$46,($R$2-1)*12+10) -> 9085.2192 | R17: =INDEX(Monthly!$C$46:$AL$46,($R$2-1)*12+11) -> 24095.689 | S17: =INDEX(Monthly!$C$46:$AL$46,($R$2-1)*12+12) -> 24105.134
A18: Income tax | B18: ='P&L'!B24 -> -26595.719 | C18: ='P&L'!C24 -> -36639.834 | D18: ='P&L'!D24 -> -44929.355 | H18: =INDEX(Monthly!$C$49:$AL$49,($R$2-1)*12+1) -> -212.93393 | I18: =INDEX(Monthly!$C$49:$AL$49,($R$2-1)*12+2) -> -1052.9775 | J18: =INDEX(Monthly!$C$49:$AL$49,($R$2-1)*12+3) -> -1894.0127 | K18: =INDEX(Monthly!$C$49:$AL$49,($R$2-1)*12+4) -> -1895.996 | L18: =INDEX(Monthly!$C$49:$AL$49,($R$2-1)*12+5) -> -1897.9794 | M18: =INDEX(Monthly!$C$49:$AL$49,($R$2-1)*12+6) -> -1899.9627 | N18: =INDEX(Monthly!$C$49:$AL$49,($R$2-1)*12+7) -> -1901.946 | O18: =INDEX(Monthly!$C$49:$AL$49,($R$2-1)*12+8) -> -1903.9294 | P18: =INDEX(Monthly!$C$49:$AL$49,($R$2-1)*12+9) -> -1905.9127 | Q18: =INDEX(Monthly!$C$49:$AL$49,($R$2-1)*12+10) -> -1907.896 | R18: =INDEX(Monthly!$C$49:$AL$49,($R$2-1)*12+11) -> -5060.0948 | S18: =INDEX(Monthly!$C$49:$AL$49,($R$2-1)*12+12) -> -5062.0781
A19: Net income | B19: ='P&L'!B25 -> 100050.56 | C19: ='P&L'!C25 -> 137835.57 | D19: ='P&L'!D25 -> 169019.96 | H19: =INDEX(Monthly!$C$50:$AL$50,($R$2-1)*12+1) -> 801.03715 | I19: =INDEX(Monthly!$C$50:$AL$50,($R$2-1)*12+2) -> 3961.201 | J19: =INDEX(Monthly!$C$50:$AL$50,($R$2-1)*12+3) -> 7125.0954 | K19: =INDEX(Monthly!$C$50:$AL$50,($R$2-1)*12+4) -> 7132.5565 | L19: =INDEX(Monthly!$C$50:$AL$50,($R$2-1)*12+5) -> 7140.0176 | M19: =INDEX(Monthly!$C$50:$AL$50,($R$2-1)*12+6) -> 7147.4787 | N19: =INDEX(Monthly!$C$50:$AL$50,($R$2-1)*12+7) -> 7154.9398 | O19: =INDEX(Monthly!$C$50:$AL$50,($R$2-1)*12+8) -> 7162.4009 | P19: =INDEX(Monthly!$C$50:$AL$50,($R$2-1)*12+9) -> 7169.862 | Q19: =INDEX(Monthly!$C$50:$AL$50,($R$2-1)*12+10) -> 7177.3232 | R19: =INDEX(Monthly!$C$50:$AL$50,($R$2-1)*12+11) -> 19035.595 | S19: =INDEX(Monthly!$C$50:$AL$50,($R$2-1)*12+12) -> 19043.056
A20: Net margin | B20: ='P&L'!B26 -> 0.063401547 | C20: ='P&L'!C26 -> 0.079381341 | D20: ='P&L'!D26 -> 0.089420843 | H20: =IF(H7=0,0,H19/H7) -> 0.0068839199 | I20: =IF(I7=0,0,I19/I7) -> 0.032249942 | J20: =IF(J7=0,0,J19/J7) -> 0.055108215 | K20: =IF(K7=0,0,K19/K7) -> 0.055165922 | L20: =IF(L7=0,0,L19/L7) -> 0.055223629 | M20: =IF(M7=0,0,M19/M7) -> 0.055281336 | N20: =IF(N7=0,0,N19/N7) -> 0.055339043 | O20: =IF(O7=0,0,O19/O7) -> 0.05539675 | ... S20: =IF(S7=0,0,S19/S7) -> 0.12507261
A22: Cash flow ($'000) — by year | H22: ="Cash flow ($'000) — Year "&$R$2&", by month" -> Cash flow ($'000) — Year 1, by month
B23: 1 | C23: 2 | D23: 3 | H23: =INDEX(Monthly!$C$4:$AL$4,($R$2-1)*12+1) -> 1 | I23: =INDEX(Monthly!$C$4:$AL$4,($R$2-1)*12+2) -> 2 | J23: =INDEX(Monthly!$C$4:$AL$4,($R$2-1)*12+3) -> 3 | K23: =INDEX(Monthly!$C$4:$AL$4,($R$2-1)*12+4) -> 4 | L23: =INDEX(Monthly!$C$4:$AL$4,($R$2-1)*12+5) -> 5 | M23: =INDEX(Monthly!$C$4:$AL$4,($R$2-1)*12+6) -> 6 | N23: =INDEX(Monthly!$C$4:$AL$4,($R$2-1)*12+7) -> 7 | O23: =INDEX(Monthly!$C$4:$AL$4,($R$2-1)*12+8) -> 8 | P23: =INDEX(Monthly!$C$4:$AL$4,($R$2-1)*12+9) -> 9 | Q23: =INDEX(Monthly!$C$4:$AL$4,($R$2-1)*12+10) -> 10 | R23: =INDEX(Monthly!$C$4:$AL$4,($R$2-1)*12+11) -> 11 | S23: =INDEX(Monthly!$C$4:$AL$4,($R$2-1)*12+12) -> 12
A24: Operating cash flow | B24: ='Cash Flow'!B10 -> 101363.96 | C24: ='Cash Flow'!C10 -> 150896.6 | D24: ='Cash Flow'!D10 -> 184000.33 | H24: =INDEX(Monthly!$C$74:$AL$74,($R$2-1)*12+1) -> -6781.6092 | I24: =INDEX(Monthly!$C$74:$AL$74,($R$2-1)*12+2) -> 4551.8476 | J24: =INDEX(Monthly!$C$74:$AL$74,($R$2-1)*12+3) -> 7715.742 | K24: =INDEX(Monthly!$C$74:$AL$74,($R$2-1)*12+4) -> 8203.9851 | L24: =INDEX(Monthly!$C$74:$AL$74,($R$2-1)*12+5) -> 8211.4462 | M24: =INDEX(Monthly!$C$74:$AL$74,($R$2-1)*12+6) -> 8218.9073 | N24: =INDEX(Monthly!$C$74:$AL$74,($R$2-1)*12+7) -> 8226.3684 | O24: =INDEX(Monthly!$C$74:$AL$74,($R$2-1)*12+8) -> 8233.8295 | P24: =INDEX(Monthly!$C$74:$AL$74,($R$2-1)*12+9) -> 8241.2906 | Q24: =INDEX(Monthly!$C$74:$AL$74,($R$2-1)*12+10) -> 8248.7517 | R24: =INDEX(Monthly!$C$74:$AL$74,($R$2-1)*12+11) -> 18178.914 | S24: =INDEX(Monthly!$C$74:$AL$74,($R$2-1)*12+12) -> 20114.484
A25: Capital spending | B25: ='Cash Flow'!B11 -> -90000 | C25: ='Cash Flow'!C11 -> -14000 | D25: ='Cash Flow'!D11 -> -14000 | H25: =INDEX(Monthly!$C$75:$AL$75,($R$2-1)*12+1) -> -90000 | I25: =INDEX(Monthly!$C$75:$AL$75,($R$2-1)*12+2) -> 0 | J25: =INDEX(Monthly!$C$75:$AL$75,($R$2-1)*12+3) -> 0 | K25: =INDEX(Monthly!$C$75:$AL$75,($R$2-1)*12+4) -> 0 | L25: =INDEX(Monthly!$C$75:$AL$75,($R$2-1)*12+5) -> 0 | M25: =INDEX(Monthly!$C$75:$AL$75,($R$2-1)*12+6) -> 0 | N25: =INDEX(Monthly!$C$75:$AL$75,($R$2-1)*12+7) -> 0 | O25: =INDEX(Monthly!$C$75:$AL$75,($R$2-1)*12+8) -> 0 | P25: =INDEX(Monthly!$C$75:$AL$75,($R$2-1)*12+9) -> 0 | Q25: =INDEX(Monthly!$C$75:$AL$75,($R$2-1)*12+10) -> 0 | R25: =INDEX(Monthly!$C$75:$AL$75,($R$2-1)*12+11) -> 0 | S25: =INDEX(Monthly!$C$75:$AL$75,($R$2-1)*12+12) -> 0
A26: Equity raised | B26: ='Cash Flow'!B12 -> 60000 | C26: ='Cash Flow'!C12 -> 0 | D26: ='Cash Flow'!D12 -> 0 | H26: =INDEX(Monthly!$C$76:$AL$76,($R$2-1)*12+1) -> 60000 | I26: =INDEX(Monthly!$C$76:$AL$76,($R$2-1)*12+2) -> 0 | J26: =INDEX(Monthly!$C$76:$AL$76,($R$2-1)*12+3) -> 0 | K26: =INDEX(Monthly!$C$76:$AL$76,($R$2-1)*12+4) -> 0 | L26: =INDEX(Monthly!$C$76:$AL$76,($R$2-1)*12+5) -> 0 | M26: =INDEX(Monthly!$C$76:$AL$76,($R$2-1)*12+6) -> 0 | N26: =INDEX(Monthly!$C$76:$AL$76,($R$2-1)*12+7) -> 0 | O26: =INDEX(Monthly!$C$76:$AL$76,($R$2-1)*12+8) -> 0 | P26: =INDEX(Monthly!$C$76:$AL$76,($R$2-1)*12+9) -> 0 | Q26: =INDEX(Monthly!$C$76:$AL$76,($R$2-1)*12+10) -> 0 | R26: =INDEX(Monthly!$C$76:$AL$76,($R$2-1)*12+11) -> 0 | S26: =INDEX(Monthly!$C$76:$AL$76,($R$2-1)*12+12) -> 0
A27: Loan drawdown | B27: ='Cash Flow'!B13 -> 80000 | C27: ='Cash Flow'!C13 -> 0 | D27: ='Cash Flow'!D13 -> 0 | H27: =INDEX(Monthly!$C$61:$AL$61,($R$2-1)*12+1) -> 80000 | I27: =INDEX(Monthly!$C$61:$AL$61,($R$2-1)*12+2) -> 0 | J27: =INDEX(Monthly!$C$61:$AL$61,($R$2-1)*12+3) -> 0 | K27: =INDEX(Monthly!$C$61:$AL$61,($R$2-1)*12+4) -> 0 | L27: =INDEX(Monthly!$C$61:$AL$61,($R$2-1)*12+5) -> 0 | M27: =INDEX(Monthly!$C$61:$AL$61,($R$2-1)*12+6) -> 0 | N27: =INDEX(Monthly!$C$61:$AL$61,($R$2-1)*12+7) -> 0 | O27: =INDEX(Monthly!$C$61:$AL$61,($R$2-1)*12+8) -> 0 | P27: =INDEX(Monthly!$C$61:$AL$61,($R$2-1)*12+9) -> 0 | Q27: =INDEX(Monthly!$C$61:$AL$61,($R$2-1)*12+10) -> 0 | R27: =INDEX(Monthly!$C$61:$AL$61,($R$2-1)*12+11) -> 0 | S27: =INDEX(Monthly!$C$61:$AL$61,($R$2-1)*12+12) -> 0
A28: Loan repayment | B28: ='Cash Flow'!B14 -> -14666.667 | C28: ='Cash Flow'!C14 -> -16000 | D28: ='Cash Flow'!D14 -> -16000 | H28: =INDEX(Monthly!$C$62:$AL$62,($R$2-1)*12+1) -> 0 | I28: =INDEX(Monthly!$C$62:$AL$62,($R$2-1)*12+2) -> -1333.3333 | J28: =INDEX(Monthly!$C$62:$AL$62,($R$2-1)*12+3) -> -1333.3333 | K28: =INDEX(Monthly!$C$62:$AL$62,($R$2-1)*12+4) -> -1333.3333 | L28: =INDEX(Monthly!$C$62:$AL$62,($R$2-1)*12+5) -> -1333.3333 | M28: =INDEX(Monthly!$C$62:$AL$62,($R$2-1)*12+6) -> -1333.3333 | N28: =INDEX(Monthly!$C$62:$AL$62,($R$2-1)*12+7) -> -1333.3333 | O28: =INDEX(Monthly!$C$62:$AL$62,($R$2-1)*12+8) -> -1333.3333 | P28: =INDEX(Monthly!$C$62:$AL$62,($R$2-1)*12+9) -> -1333.3333 | Q28: =INDEX(Monthly!$C$62:$AL$62,($R$2-1)*12+10) -> -1333.3333 | R28: =INDEX(Monthly!$C$62:$AL$62,($R$2-1)*12+11) -> -1333.3333 | S28: =INDEX(Monthly!$C$62:$AL$62,($R$2-1)*12+12) -> -1333.3333
A29: Financing cash flow | B29: ='Cash Flow'!B15 -> 125333.33 | C29: ='Cash Flow'!C15 -> -16000 | D29: ='Cash Flow'!D15 -> -16000 | H29: =INDEX(Monthly!$C$77:$AL$77,($R$2-1)*12+1) -> 140000 | I29: =INDEX(Monthly!$C$77:$AL$77,($R$2-1)*12+2) -> -1333.3333 | J29: =INDEX(Monthly!$C$77:$AL$77,($R$2-1)*12+3) -> -1333.3333 | K29: =INDEX(Monthly!$C$77:$AL$77,($R$2-1)*12+4) -> -1333.3333 | L29: =INDEX(Monthly!$C$77:$AL$77,($R$2-1)*12+5) -> -1333.3333 | M29: =INDEX(Monthly!$C$77:$AL$77,($R$2-1)*12+6) -> -1333.3333 | N29: =INDEX(Monthly!$C$77:$AL$77,($R$2-1)*12+7) -> -1333.3333 | O29: =INDEX(Monthly!$C$77:$AL$77,($R$2-1)*12+8) -> -1333.3333 | P29: =INDEX(Monthly!$C$77:$AL$77,($R$2-1)*12+9) -> -1333.3333 | Q29: =INDEX(Monthly!$C$77:$AL$77,($R$2-1)*12+10) -> -1333.3333 | R29: =INDEX(Monthly!$C$77:$AL$77,($R$2-1)*12+11) -> -1333.3333 | S29: =INDEX(Monthly!$C$77:$AL$77,($R$2-1)*12+12) -> -1333.3333
A30: Net change in cash | B30: ='Cash Flow'!B16 -> 136697.29 | C30: ='Cash Flow'!C16 -> 120896.6 | D30: ='Cash Flow'!D16 -> 154000.33 | H30: =INDEX(Monthly!$C$78:$AL$78,($R$2-1)*12+1) -> 43218.391 | I30: =INDEX(Monthly!$C$78:$AL$78,($R$2-1)*12+2) -> 3218.5143 | J30: =INDEX(Monthly!$C$78:$AL$78,($R$2-1)*12+3) -> 6382.4087 | K30: =INDEX(Monthly!$C$78:$AL$78,($R$2-1)*12+4) -> 6870.6517 | L30: =INDEX(Monthly!$C$78:$AL$78,($R$2-1)*12+5) -> 6878.1128 | M30: =INDEX(Monthly!$C$78:$AL$78,($R$2-1)*12+6) -> 6885.574 | N30: =INDEX(Monthly!$C$78:$AL$78,($R$2-1)*12+7) -> 6893.0351 | O30: =INDEX(Monthly!$C$78:$AL$78,($R$2-1)*12+8) -> 6900.4962 | P30: =INDEX(Monthly!$C$78:$AL$78,($R$2-1)*12+9) -> 6907.9573 | Q30: =INDEX(Monthly!$C$78:$AL$78,($R$2-1)*12+10) -> 6915.4184 | R30: =INDEX(Monthly!$C$78:$AL$78,($R$2-1)*12+11) -> 16845.58 | S30: =INDEX(Monthly!$C$78:$AL$78,($R$2-1)*12+12) -> 18781.151
A31: Closing cash | B31: ='Cash Flow'!B18 -> 136697.29 | C31: ='Cash Flow'!C18 -> 257593.89 | D31: ='Cash Flow'!D18 -> 411594.23 | H31: =INDEX(Monthly!$C$80:$AL$80,($R$2-1)*12+1) -> 43218.391 | I31: =INDEX(Monthly!$C$80:$AL$80,($R$2-1)*12+2) -> 46436.905 | J31: =INDEX(Monthly!$C$80:$AL$80,($R$2-1)*12+3) -> 52819.314 | K31: =INDEX(Monthly!$C$80:$AL$80,($R$2-1)*12+4) -> 59689.965 | L31: =INDEX(Monthly!$C$80:$AL$80,($R$2-1)*12+5) -> 66568.078 | M31: =INDEX(Monthly!$C$80:$AL$80,($R$2-1)*12+6) -> 73453.652 | N31: =INDEX(Monthly!$C$80:$AL$80,($R$2-1)*12+7) -> 80346.687 | O31: =INDEX(Monthly!$C$80:$AL$80,($R$2-1)*12+8) -> 87247.183 | P31: =INDEX(Monthly!$C$80:$AL$80,($R$2-1)*12+9) -> 94155.141 | Q31: =INDEX(Monthly!$C$80:$AL$80,($R$2-1)*12+10) -> 101070.56 | R31: =INDEX(Monthly!$C$80:$AL$80,($R$2-1)*12+11) -> 117916.14 | S31: =INDEX(Monthly!$C$80:$AL$80,($R$2-1)*12+12) -> 136697.29
A39: Balance sheet at year end ($'000) | H39: ="Balance sheet at month end ($'000) — Year "&$R$2 -> Balance sheet at month end ($'000) — Year 1
B40: 1 | C40: 2 | D40: 3 | H40: =INDEX(Monthly!$C$4:$AL$4,($R$2-1)*12+1) -> 1 | I40: =INDEX(Monthly!$C$4:$AL$4,($R$2-1)*12+2) -> 2 | J40: =INDEX(Monthly!$C$4:$AL$4,($R$2-1)*12+3) -> 3 | K40: =INDEX(Monthly!$C$4:$AL$4,($R$2-1)*12+4) -> 4 | L40: =INDEX(Monthly!$C$4:$AL$4,($R$2-1)*12+5) -> 5 | M40: =INDEX(Monthly!$C$4:$AL$4,($R$2-1)*12+6) -> 6 | N40: =INDEX(Monthly!$C$4:$AL$4,($R$2-1)*12+7) -> 7 | O40: =INDEX(Monthly!$C$4:$AL$4,($R$2-1)*12+8) -> 8 | P40: =INDEX(Monthly!$C$4:$AL$4,($R$2-1)*12+9) -> 9 | Q40: =INDEX(Monthly!$C$4:$AL$4,($R$2-1)*12+10) -> 10 | R40: =INDEX(Monthly!$C$4:$AL$4,($R$2-1)*12+11) -> 11 | S40: =INDEX(Monthly!$C$4:$AL$4,($R$2-1)*12+12) -> 12
A41: Cash | B41: ='Balance Sheet'!B5 -> 136697.29 | C41: ='Balance Sheet'!C5 -> 257593.89 | D41: ='Balance Sheet'!D5 -> 411594.23 | H41: =INDEX(Monthly!$C$80:$AL$80,($R$2-1)*12+1) -> 43218.391 | I41: =INDEX(Monthly!$C$80:$AL$80,($R$2-1)*12+2) -> 46436.905 | J41: =INDEX(Monthly!$C$80:$AL$80,($R$2-1)*12+3) -> 52819.314 | K41: =INDEX(Monthly!$C$80:$AL$80,($R$2-1)*12+4) -> 59689.965 | L41: =INDEX(Monthly!$C$80:$AL$80,($R$2-1)*12+5) -> 66568.078 | M41: =INDEX(Monthly!$C$80:$AL$80,($R$2-1)*12+6) -> 73453.652 | N41: =INDEX(Monthly!$C$80:$AL$80,($R$2-1)*12+7) -> 80346.687 | O41: =INDEX(Monthly!$C$80:$AL$80,($R$2-1)*12+8) -> 87247.183 | P41: =INDEX(Monthly!$C$80:$AL$80,($R$2-1)*12+9) -> 94155.141 | Q41: =INDEX(Monthly!$C$80:$AL$80,($R$2-1)*12+10) -> 101070.56 | R41: =INDEX(Monthly!$C$80:$AL$80,($R$2-1)*12+11) -> 117916.14 | S41: =INDEX(Monthly!$C$80:$AL$80,($R$2-1)*12+12) -> 136697.29
A42: Accounts receivable | B42: ='Balance Sheet'!B6 -> 35526.4 | C42: ='Balance Sheet'!C6 -> 38499.785 | D42: ='Balance Sheet'!D6 -> 41778.639 | H42: =INDEX(Monthly!$C$66:$AL$66,($R$2-1)*12+1) -> 27151.488 | I42: =INDEX(Monthly!$C$66:$AL$66,($R$2-1)*12+2) -> 28659.904 | J42: =INDEX(Monthly!$C$66:$AL$66,($R$2-1)*12+3) -> 30168.32 | K42: =INDEX(Monthly!$C$66:$AL$66,($R$2-1)*12+4) -> 30168.32 | L42: =INDEX(Monthly!$C$66:$AL$66,($R$2-1)*12+5) -> 30168.32 | M42: =INDEX(Monthly!$C$66:$AL$66,($R$2-1)*12+6) -> 30168.32 | N42: =INDEX(Monthly!$C$66:$AL$66,($R$2-1)*12+7) -> 30168.32 | O42: =INDEX(Monthly!$C$66:$AL$66,($R$2-1)*12+8) -> 30168.32 | P42: =INDEX(Monthly!$C$66:$AL$66,($R$2-1)*12+9) -> 30168.32 | Q42: =INDEX(Monthly!$C$66:$AL$66,($R$2-1)*12+10) -> 30168.32 | R42: =INDEX(Monthly!$C$66:$AL$66,($R$2-1)*12+11) -> 35526.4 | S42: =INDEX(Monthly!$C$66:$AL$66,($R$2-1)*12+12) -> 35526.4
A43: Inventory | B43: ='Balance Sheet'!B7 -> 4796.5303 | C43: ='Balance Sheet'!C7 -> 5215.3191 | D43: ='Balance Sheet'!D7 -> 5679.0702 | H43: =INDEX(Monthly!$C$67:$AL$67,($R$2-1)*12+1) -> 3699.4826 | I43: =INDEX(Monthly!$C$67:$AL$67,($R$2-1)*12+2) -> 3905.0094 | J43: =INDEX(Monthly!$C$67:$AL$67,($R$2-1)*12+3) -> 4110.5362 | K43: =INDEX(Monthly!$C$67:$AL$67,($R$2-1)*12+4) -> 4110.5362 | L43: =INDEX(Monthly!$C$67:$AL$67,($R$2-1)*12+5) -> 4110.5362 | M43: =INDEX(Monthly!$C$67:$AL$67,($R$2-1)*12+6) -> 4110.5362 | N43: =INDEX(Monthly!$C$67:$AL$67,($R$2-1)*12+7) -> 4110.5362 | O43: =INDEX(Monthly!$C$67:$AL$67,($R$2-1)*12+8) -> 4110.5362 | P43: =INDEX(Monthly!$C$67:$AL$67,($R$2-1)*12+9) -> 4110.5362 | Q43: =INDEX(Monthly!$C$67:$AL$67,($R$2-1)*12+10) -> 4110.5362 | R43: =INDEX(Monthly!$C$67:$AL$67,($R$2-1)*12+11) -> 4796.5303 | S43: =INDEX(Monthly!$C$67:$AL$67,($R$2-1)*12+12) -> 4796.5303
A44: Net fixed assets | B44: ='Balance Sheet'!B8 -> 77142.857 | C44: ='Balance Sheet'!C8 -> 77202.381 | D44: ='Balance Sheet'!D8 -> 75261.905 | H44: =INDEX(Monthly!$C$57:$AL$57,($R$2-1)*12+1) -> 88928.571 | I44: =INDEX(Monthly!$C$57:$AL$57,($R$2-1)*12+2) -> 87857.143 | J44: =INDEX(Monthly!$C$57:$AL$57,($R$2-1)*12+3) -> 86785.714 | K44: =INDEX(Monthly!$C$57:$AL$57,($R$2-1)*12+4) -> 85714.286 | L44: =INDEX(Monthly!$C$57:$AL$57,($R$2-1)*12+5) -> 84642.857 | M44: =INDEX(Monthly!$C$57:$AL$57,($R$2-1)*12+6) -> 83571.429 | N44: =INDEX(Monthly!$C$57:$AL$57,($R$2-1)*12+7) -> 82500 | O44: =INDEX(Monthly!$C$57:$AL$57,($R$2-1)*12+8) -> 81428.571 | P44: =INDEX(Monthly!$C$57:$AL$57,($R$2-1)*12+9) -> 80357.143 | Q44: =INDEX(Monthly!$C$57:$AL$57,($R$2-1)*12+10) -> 79285.714 | R44: =INDEX(Monthly!$C$57:$AL$57,($R$2-1)*12+11) -> 78214.286 | S44: =INDEX(Monthly!$C$57:$AL$57,($R$2-1)*12+12) -> 77142.857
A45: Total assets | B45: ='Balance Sheet'!B9 -> 254163.08 | C45: ='Balance Sheet'!C9 -> 378511.38 | D45: ='Balance Sheet'!D9 -> 534313.84 | H45: =INDEX(Monthly!$C$94:$AL$94,($R$2-1)*12+1) -> 162997.93 | I45: =INDEX(Monthly!$C$94:$AL$94,($R$2-1)*12+2) -> 166858.96 | J45: =INDEX(Monthly!$C$94:$AL$94,($R$2-1)*12+3) -> 173883.88 | K45: =INDEX(Monthly!$C$94:$AL$94,($R$2-1)*12+4) -> 179683.11 | L45: =INDEX(Monthly!$C$94:$AL$94,($R$2-1)*12+5) -> 185489.79 | M45: =INDEX(Monthly!$C$94:$AL$94,($R$2-1)*12+6) -> 191303.94 | N45: =INDEX(Monthly!$C$94:$AL$94,($R$2-1)*12+7) -> 197125.54 | O45: =INDEX(Monthly!$C$94:$AL$94,($R$2-1)*12+8) -> 202954.61 | P45: =INDEX(Monthly!$C$94:$AL$94,($R$2-1)*12+9) -> 208791.14 | Q45: =INDEX(Monthly!$C$94:$AL$94,($R$2-1)*12+10) -> 214635.13 | R45: =INDEX(Monthly!$C$94:$AL$94,($R$2-1)*12+11) -> 236453.36 | S45: =INDEX(Monthly!$C$94:$AL$94,($R$2-1)*12+12) -> 254163.08
A46: Accounts payable | B46: ='Balance Sheet'!B10 -> 28779.182 | C46: ='Balance Sheet'!C10 -> 31291.915 | D46: ='Balance Sheet'!D10 -> 34074.421 | H46: =INDEX(Monthly!$C$68:$AL$68,($R$2-1)*12+1) -> 22196.896 | I46: =INDEX(Monthly!$C$68:$AL$68,($R$2-1)*12+2) -> 23430.057 | J46: =INDEX(Monthly!$C$68:$AL$68,($R$2-1)*12+3) -> 24663.217 | K46: =INDEX(Monthly!$C$68:$AL$68,($R$2-1)*12+4) -> 24663.217 | L46: =INDEX(Monthly!$C$68:$AL$68,($R$2-1)*12+5) -> 24663.217 | M46: =INDEX(Monthly!$C$68:$AL$68,($R$2-1)*12+6) -> 24663.217 | N46: =INDEX(Monthly!$C$68:$AL$68,($R$2-1)*12+7) -> 24663.217 | O46: =INDEX(Monthly!$C$68:$AL$68,($R$2-1)*12+8) -> 24663.217 | P46: =INDEX(Monthly!$C$68:$AL$68,($R$2-1)*12+9) -> 24663.217 | Q46: =INDEX(Monthly!$C$68:$AL$68,($R$2-1)*12+10) -> 24663.217 | R46: =INDEX(Monthly!$C$68:$AL$68,($R$2-1)*12+11) -> 28779.182 | S46: =INDEX(Monthly!$C$68:$AL$68,($R$2-1)*12+12) -> 28779.182
A47: Loan | B47: ='Balance Sheet'!B11 -> 65333.333 | C47: ='Balance Sheet'!C11 -> 49333.333 | D47: ='Balance Sheet'!D11 -> 33333.333 | H47: =INDEX(Monthly!$C$63:$AL$63,($R$2-1)*12+1) -> 80000 | I47: =INDEX(Monthly!$C$63:$AL$63,($R$2-1)*12+2) -> 78666.667 | J47: =INDEX(Monthly!$C$63:$AL$63,($R$2-1)*12+3) -> 77333.333 | K47: =INDEX(Monthly!$C$63:$AL$63,($R$2-1)*12+4) -> 76000 | L47: =INDEX(Monthly!$C$63:$AL$63,($R$2-1)*12+5) -> 74666.667 | M47: =INDEX(Monthly!$C$63:$AL$63,($R$2-1)*12+6) -> 73333.333 | N47: =INDEX(Monthly!$C$63:$AL$63,($R$2-1)*12+7) -> 72000 | O47: =INDEX(Monthly!$C$63:$AL$63,($R$2-1)*12+8) -> 70666.667 | P47: =INDEX(Monthly!$C$63:$AL$63,($R$2-1)*12+9) -> 69333.333 | Q47: =INDEX(Monthly!$C$63:$AL$63,($R$2-1)*12+10) -> 68000 | R47: =INDEX(Monthly!$C$63:$AL$63,($R$2-1)*12+11) -> 66666.667 | S47: =INDEX(Monthly!$C$63:$AL$63,($R$2-1)*12+12) -> 65333.333
A48: Total liabilities | B48: ='Balance Sheet'!B12 -> 94112.515 | C48: ='Balance Sheet'!C12 -> 80625.248 | D48: ='Balance Sheet'!D12 -> 67407.755 | H48: =INDEX(Monthly!$C$95:$AL$95,($R$2-1)*12+1) -> 102196.9 | I48: =INDEX(Monthly!$C$95:$AL$95,($R$2-1)*12+2) -> 102096.72 | J48: =INDEX(Monthly!$C$95:$AL$95,($R$2-1)*12+3) -> 101996.55 | K48: =INDEX(Monthly!$C$95:$AL$95,($R$2-1)*12+4) -> 100663.22 | L48: =INDEX(Monthly!$C$95:$AL$95,($R$2-1)*12+5) -> 99329.884 | M48: =INDEX(Monthly!$C$95:$AL$95,($R$2-1)*12+6) -> 97996.551 | N48: =INDEX(Monthly!$C$95:$AL$95,($R$2-1)*12+7) -> 96663.217 | O48: =INDEX(Monthly!$C$95:$AL$95,($R$2-1)*12+8) -> 95329.884 | P48: =INDEX(Monthly!$C$95:$AL$95,($R$2-1)*12+9) -> 93996.551 | Q48: =INDEX(Monthly!$C$95:$AL$95,($R$2-1)*12+10) -> 92663.217 | R48: =INDEX(Monthly!$C$95:$AL$95,($R$2-1)*12+11) -> 95445.848 | S48: =INDEX(Monthly!$C$95:$AL$95,($R$2-1)*12+12) -> 94112.515
A49: Paid-in capital | B49: ='Balance Sheet'!B13 -> 60000 | C49: ='Balance Sheet'!C13 -> 60000 | D49: ='Balance Sheet'!D13 -> 60000 | H49: =INDEX(Monthly!$C$92:$AL$92,($R$2-1)*12+1) -> 60000 | I49: =INDEX(Monthly!$C$92:$AL$92,($R$2-1)*12+2) -> 60000 | J49: =INDEX(Monthly!$C$92:$AL$92,($R$2-1)*12+3) -> 60000 | K49: =INDEX(Monthly!$C$92:$AL$92,($R$2-1)*12+4) -> 60000 | L49: =INDEX(Monthly!$C$92:$AL$92,($R$2-1)*12+5) -> 60000 | M49: =INDEX(Monthly!$C$92:$AL$92,($R$2-1)*12+6) -> 60000 | N49: =INDEX(Monthly!$C$92:$AL$92,($R$2-1)*12+7) -> 60000 | O49: =INDEX(Monthly!$C$92:$AL$92,($R$2-1)*12+8) -> 60000 | P49: =INDEX(Monthly!$C$92:$AL$92,($R$2-1)*12+9) -> 60000 | Q49: =INDEX(Monthly!$C$92:$AL$92,($R$2-1)*12+10) -> 60000 | R49: =INDEX(Monthly!$C$92:$AL$92,($R$2-1)*12+11) -> 60000 | S49: =INDEX(Monthly!$C$92:$AL$92,($R$2-1)*12+12) -> 60000
A50: Retained earnings | B50: ='Balance Sheet'!B14 -> 100050.56 | C50: ='Balance Sheet'!C14 -> 237886.13 | D50: ='Balance Sheet'!D14 -> 406906.08 | H50: =INDEX(Monthly!$C$93:$AL$93,($R$2-1)*12+1) -> 801.03715 | I50: =INDEX(Monthly!$C$93:$AL$93,($R$2-1)*12+2) -> 4762.2381 | J50: =INDEX(Monthly!$C$93:$AL$93,($R$2-1)*12+3) -> 11887.334 | K50: =INDEX(Monthly!$C$93:$AL$93,($R$2-1)*12+4) -> 19019.89 | L50: =INDEX(Monthly!$C$93:$AL$93,($R$2-1)*12+5) -> 26159.908 | M50: =INDEX(Monthly!$C$93:$AL$93,($R$2-1)*12+6) -> 33307.386 | N50: =INDEX(Monthly!$C$93:$AL$93,($R$2-1)*12+7) -> 40462.326 | O50: =INDEX(Monthly!$C$93:$AL$93,($R$2-1)*12+8) -> 47624.727 | P50: =INDEX(Monthly!$C$93:$AL$93,($R$2-1)*12+9) -> 54794.589 | Q50: =INDEX(Monthly!$C$93:$AL$93,($R$2-1)*12+10) -> 61971.912 | R50: =INDEX(Monthly!$C$93:$AL$93,($R$2-1)*12+11) -> 81007.507 | S50: =INDEX(Monthly!$C$93:$AL$93,($R$2-1)*12+12) -> 100050.56
...

Sheet Break-even
A1: Startup costs, funding need and break-even | F1: =HYPERLINK("#'Cover'!A1","◂ Contents") -> ◂ Contents
A2: Live for the selected scenario. Periods are counted in months from the start of the plan.
A3: Scenario shown | B3: =CHOOSE(Dashboard!$B$4,"Low","Base","High") -> Base
A5: Startup costs & funding need (up to the lowest cash point)
A6: Lowest cash point (month #) | B6: =MATCH(MIN(Monthly!$C$80:$AL$80),Monthly!$C$80:$AL$80,0) -> 1
A7: Capital spending up to the lowest cash point | B7: =SUMPRODUCT(--(Monthly!$C$4:$AL$4<=$B$6),Monthly!$C$53:$AL$53) -> 90000
A8: Operating cash burn up to the lowest cash point | B8: =-SUMPRODUCT(--(Monthly!$C$4:$AL$4<=$B$6),Monthly!$C$74:$AL$74) -> 6781.6092 | D8: Losses and working capital before the business funds itself
A9: Loan repayments up to the lowest cash point | B9: =-SUMPRODUCT(--(Monthly!$C$4:$AL$4<=$B$6),Monthly!$C$62:$AL$62) -> 0
A10: Total uses of funds | B10: =B7+B8+B9 -> 96781.609
A11: Minimum cash buffer to keep | B11: =Inputs!$E$73 -> 233000 | D11: Input on the Inputs sheet
A12: Funding required (uses + buffer) | B12: =B10+B11 -> 329781.61
A14: Equity raised | B14: =Inputs!$E$58 -> 60000
A15: Loan drawn | B15: =Inputs!$E$59 -> 80000
A16: Total sources of funds | B16: =B14+B15 -> 140000
A17: Funding surplus / (shortfall) | B17: =B16-B12 -> -189781.61 | D17: Negative = raise at least this much more
A18: Lowest cash balance in the plan | B18: =MIN(Monthly!$C$80:$AL$80) -> 43218.391 | D18: Equals sources minus uses
A20: Break-even timing
A21: First month with positive EBITDA (month #) | B21: =IFERROR(MATCH(1,Monthly!$C$81:$AL$81,0),"Not within horizon") -> 1
A22: First month with positive net income (month #) | B22: =IFERROR(MATCH(1,Monthly!$C$84:$AL$84,0),"Not within horizon") -> 1
A23: Cash invested paid back (month #) | B23: =IF(MIN(Monthly!$C$86:$AL$86)>=0,"No investment to pay back",IFERROR(MATCH(1,Monthly!$C$88:$AL$88,0),"Not within horizon")) -> 12 | D23: Cumulative operating + investing cash flow back to zero
A25: Annual break-even revenue
A26: Year # | B26: 1 | C26: 2 | D26: 3
B27: Year 1 | C27: Year 2 | D27: Year 3
A28: Revenue | B28: =SUMIF(Monthly!$C$5:$AL$5,B$26,Monthly!$C$22:$AL$22) -> 1578046.1 | C28: =SUMIF(Monthly!$C$5:$AL$5,C$26,Monthly!$C$22:$AL$22) -> 1736372.4 | D28: =SUMIF(Monthly!$C$5:$AL$5,D$26,Monthly!$C$22:$AL$22) -> 1890162.9
A29: Gross profit | B29: =SUMIF(Monthly!$C$5:$AL$5,B$26,Monthly!$C$29:$AL$29) -> 1077227.7 | C29: =SUMIF(Monthly!$C$5:$AL$5,C$26,Monthly!$C$29:$AL$29) -> 1183311.2 | D29: =SUMIF(Monthly!$C$5:$AL$5,D$26,Monthly!$C$29:$AL$29) -> 1285883.7
A30: Gross margin (contribution) | B30: =IF(B28=0,0,B29/B28) -> 0.68263384 | C30: =IF(C28=0,0,C29/C28) -> 0.68148469 | D30: =IF(D28=0,0,D29/D28) -> 0.68030311
A31: Operating expenses (treated as fixed) | B31: =-SUMIF(Monthly!$C$5:$AL$5,B$26,Monthly!$C$40:$AL$40) -> 931495.62 | C31: =-SUMIF(Monthly!$C$5:$AL$5,C$26,Monthly!$C$40:$AL$40) -> 990021.96 | D31: =-SUMIF(Monthly!$C$5:$AL$5,D$26,Monthly!$C$40:$AL$40) -> 1052480.5
A32: Break-even revenue (EBITDA = 0) | B32: =IF(B30>0,B31/B30,"n/a") -> 1364561.2 | C32: =IF(C30>0,C31/C30,"n/a") -> 1452742.8 | D32: =IF(D30>0,D31/D30,"n/a") -> 1547075.9
A33: Margin of safety (revenue above break-even) | B33: =IF(AND(ISNUMBER(B32),B28>0),(B28-B32)/B28,"n/a") -> 0.13528434 | C33: =IF(AND(ISNUMBER(C32),C28>0),(C28-C32)/C28,"n/a") -> 0.16334605 | D33: =IF(AND(ISNUMBER(D32),D28>0),(D28-D32)/D28,"n/a") -> 0.18151185
A35: Simplification: cost of sales is treated as variable and operating expenses as fixed, so break-even revenue = operating expenses ÷ gross margin.

Sheet Valuation
A1: Discounted cash flow valuation | H1: =HYPERLINK("#'Cover'!A1","◂ Contents") -> ◂ Contents
A2: Enterprise value at the start of the plan, before the funding raised in period 1. Year-end discounting.
A3: Scenario shown | B3: =CHOOSE(Dashboard!$B$4,"Low","Base","High") -> Base
A5: Assumptions (active scenario, from the Inputs sheet)
A6: Discount rate (WACC) | B6: =Inputs!$E$76 -> 0.16
A7: Terminal growth rate | B7: =Inputs!$E$77 -> 0.02
A8: Exit multiple (EV ÷ final-year EBITDA) | B8: =Inputs!$E$78 -> 5.5
A9: Tax rate (for the interest tax shield) | B9: =Inputs!$E$70 -> 0.21
A10: Sensitivity step: WACC | B10: =Inputs!$E$79 -> 0.01
A11: Sensitivity step: terminal growth | B11: =Inputs!$E$80 -> 0.005
A13: Free cash flow by year
A14: Year # | B14: 1 | C14: 2 | D14: 3
B15: Year 1 | C15: Year 2 | D15: Year 3
A16: EBITDA | B16: =SUMIF(Monthly!$C$5:$AL$5,B$14,Monthly!$C$41:$AL$41) -> 145732.04 | C16: =SUMIF(Monthly!$C$5:$AL$5,C$14,Monthly!$C$41:$AL$41) -> 193289.21 | D16: =SUMIF(Monthly!$C$5:$AL$5,D$14,Monthly!$C$41:$AL$41) -> 233403.12
A17: Unlevered free cash flow | B17: =SUMIF(Monthly!$C$5:$AL$5,B$14,Monthly!$C$89:$AL$89) -> 16284.56 | C17: =SUMIF(Monthly!$C$5:$AL$5,C$14,Monthly!$C$89:$AL$89) -> 140746.53 | D17: =SUMIF(Monthly!$C$5:$AL$5,D$14,Monthly!$C$89:$AL$89) -> 172775.87
A18: Discount factor | B18: =1/(1+Inputs!$E$76)^B$14 -> 0.86206897 | C18: =1/(1+Inputs!$E$76)^C$14 -> 0.7431629 | D18: =1/(1+Inputs!$E$76)^D$14 -> 0.64065767
A19: Present value of free cash flow | B19: =B17*B18 -> 14038.414 | C19: =C17*C18 -> 104597.6 | D19: =D17*D18 -> 110690.19
A21: Enterprise value
B22: Perpetual growth | C22: Exit multiple
A23: Present value of the plan's free cash flows | B23: =SUM($B$19:$D$19) -> 229326.2 | C23: =B23 -> 229326.2
A24: Final-year free cash flow | final-year EBITDA | B24: =$D$17 -> 172775.87 | C24: =$D$16 -> 233403.12
A25: Terminal value at the end of year 3 | B25: =IF($B$6>$B$7,B24*(1+$B$7)/($B$6-$B$7),0) -> 1258795.6 | C25: =C24*$B$8 -> 1283717.2
A26: Present value of the terminal value | B26: =B25/(1+$B$6)^$D$14 -> 806457.06 | C26: =C25/(1+$B$6)^$D$14 -> 822423.25
A27: Enterprise value | B27: =B23+B26 -> 1035783.3 | C27: =C23+C26 -> 1051749.5
A28: Terminal value share of enterprise value | B28: =IF(B27<>0,B26/B27,0) -> 0.77859634 | C28: =IF(C27<>0,C26/C27,0) -> 0.78195738
A29: Cross-check: implied exit multiple | implied perpetual growth | B29: =IF(C24>0,B25/C24,"n/a") -> 5.3932253 | C29: =IF(C25+B24<>0,(C25*$B$6-B24)/(C25+B24),"n/a") -> 0.022395493
A30: Enterprise value — average of the two methods | B30: =AVERAGE(B27,C27) -> 1043766.4
A32: Sensitivity: enterprise value (perpetual growth) by WACC and terminal growth
A33: WACC ↓ · terminal growth → | B33: =$B$7+(-2)*$B$11 -> 0.01 | C33: =$B$7+(-1)*$B$11 -> 0.015 | D33: =$B$7+(0)*$B$11 -> 0.02 | E33: =$B$7+(1)*$B$11 -> 0.025 | F33: =$B$7+(2)*$B$11 -> 0.03
A34: =$B$6+(-2)*$B$10 -> 0.14 | B34: =IF($A34>B$33,SUMPRODUCT($B$17:$D$17/(1+$A34)^$B$14:$D$14)+$D$17*(1+B$33)/($A34-B$33)/(1+$A34)^$D$14,"n/a") -> 1145241.7 | C34: =IF($A34>C$33,SUMPRODUCT($B$17:$D$17/(1+$A34)^$B$14:$D$14)+$D$17*(1+C$33)/($A34-C$33)/(1+$A34)^$D$14,"n/a") -> 1186147.9 | D34: =IF($A34>D$33,SUMPRODUCT($B$17:$D$17/(1+$A34)^$B$14:$D$14)+$D$17*(1+D$33)/($A34-D$33)/(1+$A34)^$D$14,"n/a") -> 1230463.1 | E34: =IF($A34>E$33,SUMPRODUCT($B$17:$D$17/(1+$A34)^$B$14:$D$14)+$D$17*(1+E$33)/($A34-E$33)/(1+$A34)^$D$14,"n/a") -> 1278631.7 | F34: =IF($A34>F$33,SUMPRODUCT($B$17:$D$17/(1+$A34)^$B$14:$D$14)+$D$17*(1+F$33)/($A34-F$33)/(1+$A34)^$D$14,"n/a") -> 1331179.3
A35: =$B$6+(-1)*$B$10 -> 0.15 | B35: =IF($A35>B$33,SUMPRODUCT($B$17:$D$17/(1+$A35)^$B$14:$D$14)+$D$17*(1+B$33)/($A35-B$33)/(1+$A35)^$D$14,"n/a") -> 1053752.1 | C35: =IF($A35>C$33,SUMPRODUCT($B$17:$D$17/(1+$A35)^$B$14:$D$14)+$D$17*(1+C$33)/($A35-C$33)/(1+$A35)^$D$14,"n/a") -> 1088313.8 | D35: =IF($A35>D$33,SUMPRODUCT($B$17:$D$17/(1+$A35)^$B$14:$D$14)+$D$17*(1+D$33)/($A35-D$33)/(1+$A35)^$D$14,"n/a") -> 1125534.1 | E35: =IF($A35>E$33,SUMPRODUCT($B$17:$D$17/(1+$A35)^$B$14:$D$14)+$D$17*(1+E$33)/($A35-E$33)/(1+$A35)^$D$14,"n/a") -> 1165732.1 | F35: =IF($A35>F$33,SUMPRODUCT($B$17:$D$17/(1+$A35)^$B$14:$D$14)+$D$17*(1+F$33)/($A35-F$33)/(1+$A35)^$D$14,"n/a") -> 1209279.9
A36: =$B$6+(0)*$B$10 -> 0.16 | B36: =IF($A36>B$33,SUMPRODUCT($B$17:$D$17/(1+$A36)^$B$14:$D$14)+$D$17*(1+B$33)/($A36-B$33)/(1+$A36)^$D$14,"n/a") -> 974640.12 | C36: =IF($A36>C$33,SUMPRODUCT($B$17:$D$17/(1+$A36)^$B$14:$D$14)+$D$17*(1+C$33)/($A36-C$33)/(1+$A36)^$D$14,"n/a") -> 1004157.5 | D36: =IF($A36>D$33,SUMPRODUCT($B$17:$D$17/(1+$A36)^$B$14:$D$14)+$D$17*(1+D$33)/($A36-D$33)/(1+$A36)^$D$14,"n/a") -> 1035783.3 | E36: =IF($A36>E$33,SUMPRODUCT($B$17:$D$17/(1+$A36)^$B$14:$D$14)+$D$17*(1+E$33)/($A36-E$33)/(1+$A36)^$D$14,"n/a") -> 1069751.7 | F36: =IF($A36>F$33,SUMPRODUCT($B$17:$D$17/(1+$A36)^$B$14:$D$14)+$D$17*(1+F$33)/($A36-F$33)/(1+$A36)^$D$14,"n/a") -> 1106333.1
A37: =$B$6+(1)*$B$10 -> 0.17 | B37: =IF($A37>B$33,SUMPRODUCT($B$17:$D$17/(1+$A37)^$B$14:$D$14)+$D$17*(1+B$33)/($A37-B$33)/(1+$A37)^$D$14,"n/a") -> 905580.13 | C37: =IF($A37>C$33,SUMPRODUCT($B$17:$D$17/(1+$A37)^$B$14:$D$14)+$D$17*(1+C$33)/($A37-C$33)/(1+$A37)^$D$14,"n/a") -> 931026.73 | D37: =IF($A37>D$33,SUMPRODUCT($B$17:$D$17/(1+$A37)^$B$14:$D$14)+$D$17*(1+D$33)/($A37-D$33)/(1+$A37)^$D$14,"n/a") -> 958169.76 | E37: =IF($A37>E$33,SUMPRODUCT($B$17:$D$17/(1+$A37)^$B$14:$D$14)+$D$17*(1+E$33)/($A37-E$33)/(1+$A37)^$D$14,"n/a") -> 987184.73 | F37: =IF($A37>F$33,SUMPRODUCT($B$17:$D$17/(1+$A37)^$B$14:$D$14)+$D$17*(1+F$33)/($A37-F$33)/(1+$A37)^$D$14,"n/a") -> 1018272.2
A38: =$B$6+(2)*$B$10 -> 0.18 | B38: =IF($A38>B$33,SUMPRODUCT($B$17:$D$17/(1+$A38)^$B$14:$D$14)+$D$17*(1+B$33)/($A38-B$33)/(1+$A38)^$D$14,"n/a") -> 844793.84 | C38: =IF($A38>C$33,SUMPRODUCT($B$17:$D$17/(1+$A38)^$B$14:$D$14)+$D$17*(1+C$33)/($A38-C$33)/(1+$A38)^$D$14,"n/a") -> 866912.37 | D38: =IF($A38>D$33,SUMPRODUCT($B$17:$D$17/(1+$A38)^$B$14:$D$14)+$D$17*(1+D$33)/($A38-D$33)/(1+$A38)^$D$14,"n/a") -> 890413.3 | E38: =IF($A38>E$33,SUMPRODUCT($B$17:$D$17/(1+$A38)^$B$14:$D$14)+$D$17*(1+E$33)/($A38-E$33)/(1+$A38)^$D$14,"n/a") -> 915430.43 | F38: =IF($A38>F$33,SUMPRODUCT($B$17:$D$17/(1+$A38)^$B$14:$D$14)+$D$17*(1+F$33)/($A38-F$33)/(1+$A38)^$D$14,"n/a") -> 942115.36
A40: Free cash flow = operating cash flow + interest × (1 − tax rate) − capital spending. Cells marked n/a: WACC not above growth.

Sheet Sources & Uses
A1: Sources and uses of funds | E1: =HYPERLINK("#'Cover'!A1","◂ Contents") -> ◂ Contents
A2: Live for the selected scenario. Where the money comes from and where it goes in the period set below.
A3: Scenario shown | B3: =CHOOSE(Dashboard!$B$4,"Low","Base","High") -> Base
A5: Funding structure ($'000) — raised at the start of the plan
B6: Amount | C6: Share
A7: Equity | B7: =Inputs!$E$58 -> 60000 | C7: =IF($B$9=0,0,B7/$B$9) -> 0.42857143
A8: Debt (loan) | B8: =Inputs!$E$59 -> 80000 | C8: =IF($B$9=0,0,B8/$B$9) -> 0.57142857
A9: Total funding | B9: =B7+B8 -> 140000 | C9: =IF(B9=0,0,1) -> 1
A10: Gearing (debt ÷ equity) | B10: =IF(B7<=0,IF(B8>0,"n/a",0),B8/B7) -> 1.3333333 | D10: n/a: debt without positive equity
A11: Funding required by the plan (Break-even sheet) | B11: ='Break-even'!B12 -> 329781.61
A12: Funding surplus / (shortfall) | B12: ='Break-even'!B17 -> -189781.61
A14: ="Sources and uses of cash in the first "&$B$16&IF($B$16=1," month"," months")&" ($'000)" -> Sources and uses of cash in the first 12 months ($'000)
A15: Period covered (months from the start) | B15: 12 | D15: 1 to 36 (capped)
A16: Months used | B16: =MIN(36,MAX(1,ROUND(B15,0))) -> 12
A17: Sources | B17: Amount | C17: Share
A18: Equity raised | B18: =SUMPRODUCT(--(Monthly!$C$4:$AL$4<=$B$16),Monthly!$C$76:$AL$76) -> 60000 | C18: =IF($B$21=0,0,B18/$B$21) -> 0.24858724
A19: Loan drawdowns | B19: =SUMPRODUCT(--(Monthly!$C$4:$AL$4<=$B$16),Monthly!$C$61:$AL$61) -> 80000 | C19: =IF($B$21=0,0,B19/$B$21) -> 0.33144965
A20: Cash generated by operations | B20: =MAX(0,SUMPRODUCT(--(Monthly!$C$4:$AL$4<=$B$16),Monthly!$C$74:$AL$74)) -> 101363.96 | C20: =IF($B$21=0,0,B20/$B$21) -> 0.41996311
A21: Total sources | B21: =SUM(B18:B20) -> 241363.96 | C21: =IF(B21=0,0,1) -> 1
A23: Uses | B23: Amount | C23: Share
A24: Cash used by operations | B24: =MAX(0,-SUMPRODUCT(--(Monthly!$C$4:$AL$4<=$B$16),Monthly!$C$74:$AL$74)) -> 0 | C24: =IF($B$28=0,0,B24/$B$28) -> 0
A25: Capital spending | B25: =-SUMPRODUCT(--(Monthly!$C$4:$AL$4<=$B$16),Monthly!$C$75:$AL$75) -> 90000 | C25: =IF($B$28=0,0,B25/$B$28) -> 0.37288086
A26: Loan repayments | B26: =-SUMPRODUCT(--(Monthly!$C$4:$AL$4<=$B$16),Monthly!$C$62:$AL$62) -> 14666.667 | C26: =IF($B$28=0,0,B26/$B$28) -> 0.06076577
A27: Cash at the end of the period | B27: =INDEX(Monthly!$C$80:$AL$80,$B$16) -> 136697.29 | C27: =IF($B$28=0,0,B27/$B$28) -> 0.56635337
A28: Total uses | B28: =SUM(B24:B27) -> 241363.96 | C28: =IF(B28=0,0,1) -> 1
A29: Sources − uses (must be 0; opening cash is 0) | B29: =B21-B28 -> 0

Sheet KPIs
A1: KPIs & ratios | G1: =HYPERLINK("#'Cover'!A1","◂ Contents") -> ◂ Contents
A2: Bakery financial model (growing) — industry metrics and financial ratios for the active scenario
A4: Financial ratios
B5: 1 | C5: 2 | D5: 3 | E5: Target
A6: Revenue growth | B6: =IF(N('P&L'!A5)<=0,"n/a",'P&L'!B5/'P&L'!A5-1) -> n/a | C6: =IF(N('P&L'!B5)<=0,"n/a",'P&L'!C5/'P&L'!B5-1) -> 0.10033058 | D6: =IF(N('P&L'!C5)<=0,"n/a",'P&L'!D5/'P&L'!C5-1) -> 0.088570003
A7: Gross margin | B7: =IF('P&L'!B5<=0,"n/a",'P&L'!B7/'P&L'!B5) -> 0.68263384 | C7: =IF('P&L'!C5<=0,"n/a",'P&L'!C7/'P&L'!C5) -> 0.68148469 | D7: =IF('P&L'!D5<=0,"n/a",'P&L'!D7/'P&L'!D5) -> 0.68030311
A8: EBITDA margin | B8: =IF('P&L'!B5<=0,"n/a",'P&L'!B18/'P&L'!B5) -> 0.092349671 | C8: =IF('P&L'!C5<=0,"n/a",'P&L'!C18/'P&L'!C5) -> 0.11131783 | D8: =IF('P&L'!D5<=0,"n/a",'P&L'!D18/'P&L'!D5) -> 0.12348307
A9: Net margin | B9: =IF('P&L'!B5<=0,"n/a",'P&L'!B25/'P&L'!B5) -> 0.063401547 | C9: =IF('P&L'!C5<=0,"n/a",'P&L'!C25/'P&L'!C5) -> 0.079381341 | D9: =IF('P&L'!D5<=0,"n/a",'P&L'!D25/'P&L'!D5) -> 0.089420843
A10: Payroll, % of revenue | B10: =IF('P&L'!B5<=0,"n/a",-SUMIF(Headcount!$C$5:$AL$5,B$5,Headcount!$C$17:$AL$17)/'P&L'!B5) -> 0.37616139 | C10: =IF('P&L'!C5<=0,"n/a",-SUMIF(Headcount!$C$5:$AL$5,C$5,Headcount!$C$17:$AL$17)/'P&L'!C5) -> 0.3695379 | D10: =IF('P&L'!D5<=0,"n/a",-SUMIF(Headcount!$C$5:$AL$5,D$5,Headcount!$C$17:$AL$17)/'P&L'!D5) -> 0.36712665
A11: Marketing, % of revenue | B11: =IF('P&L'!B5<=0,"n/a",-'P&L'!B14/'P&L'!B5) -> 0.02 | C11: =IF('P&L'!C5<=0,"n/a",-'P&L'!C14/'P&L'!C5) -> 0.02 | D11: =IF('P&L'!D5<=0,"n/a",-'P&L'!D14/'P&L'!D5) -> 0.02
A12: Operating expenses, % of revenue | B12: =IF('P&L'!B5<=0,"n/a",-'P&L'!B17/'P&L'!B5) -> 0.59028417 | C12: =IF('P&L'!C5<=0,"n/a",-'P&L'!C17/'P&L'!C5) -> 0.57016685 | D12: =IF('P&L'!D5<=0,"n/a",-'P&L'!D17/'P&L'!D5) -> 0.55682003
A13: Current ratio (current assets ÷ current liabilities) | B13: =IF(('Balance Sheet'!B12-'Balance Sheet'!B11)<=0,"n/a",('Balance Sheet'!B5+'Balance Sheet'!B6+'Balance Sheet'!B7)/('Balance Sheet'!B12-'Balance Sheet'!B11)) -> 6.1509817 | C13: =IF(('Balance Sheet'!C12-'Balance Sheet'!C11)<=0,"n/a",('Balance Sheet'!C5+'Balance Sheet'!C6+'Balance Sheet'!C7)/('Balance Sheet'!C12-'Balance Sheet'!C11)) -> 9.6289728 | D13: =IF(('Balance Sheet'!D12-'Balance Sheet'!D11)<=0,"n/a",('Balance Sheet'!D5+'Balance Sheet'!D6+'Balance Sheet'!D7)/('Balance Sheet'!D12-'Balance Sheet'!D11)) -> 13.472039
A14: Debt ÷ equity (loan ÷ total equity) | B14: =IF('Balance Sheet'!B15<=0,"n/a",'Balance Sheet'!B11/'Balance Sheet'!B15) -> 0.40820433 | C14: =IF('Balance Sheet'!C15<=0,"n/a",'Balance Sheet'!C11/'Balance Sheet'!C15) -> 0.16561138 | D14: =IF('Balance Sheet'!D15<=0,"n/a",'Balance Sheet'!D11/'Balance Sheet'!D15) -> 0.071391945
A15: Return on assets (net income ÷ year-end assets) | B15: =IF('Balance Sheet'!B9<=0,"n/a",'P&L'!B25/'Balance Sheet'!B9) -> 0.39364712 | C15: =IF('Balance Sheet'!C9<=0,"n/a",'P&L'!C25/'Balance Sheet'!C9) -> 0.36415171 | D15: =IF('Balance Sheet'!D9<=0,"n/a",'P&L'!D25/'Balance Sheet'!D9) -> 0.31633086
A16: Return on equity (net income ÷ year-end equity) | B16: =IF('Balance Sheet'!B15<=0,"n/a",'P&L'!B25/'Balance Sheet'!B15) -> 0.62511847 | C16: =IF('Balance Sheet'!C15<=0,"n/a",'P&L'!C25/'Balance Sheet'!C15) -> 0.46271227 | D16: =IF('Balance Sheet'!D15<=0,"n/a",'P&L'!D25/'Balance Sheet'!D15) -> 0.3619999
A18: DuPont analysis — return on equity = net margin × asset turnover × equity multiplier
B19: 1 | C19: 2 | D19: 3
A20: Net margin | B20: =IF('P&L'!B5<=0,"n/a",'P&L'!B25/'P&L'!B5) -> 0.063401547 | C20: =IF('P&L'!C5<=0,"n/a",'P&L'!C25/'P&L'!C5) -> 0.079381341 | D20: =IF('P&L'!D5<=0,"n/a",'P&L'!D25/'P&L'!D5) -> 0.089420843
A21: × Asset turnover (revenue ÷ assets) | B21: =IF('Balance Sheet'!B9<=0,"n/a",'P&L'!B5/'Balance Sheet'!B9) -> 6.2087936 | C21: =IF('Balance Sheet'!C9<=0,"n/a",'P&L'!C5/'Balance Sheet'!C9) -> 4.5873716 | D21: =IF('Balance Sheet'!D9<=0,"n/a",'P&L'!D5/'Balance Sheet'!D9) -> 3.5375518
A22: × Equity multiplier (assets ÷ equity) | B22: =IF('Balance Sheet'!B15<=0,"n/a",'Balance Sheet'!B9/'Balance Sheet'!B15) -> 1.5880174 | C22: =IF('Balance Sheet'!C15<=0,"n/a",'Balance Sheet'!C9/'Balance Sheet'!C15) -> 1.2706579 | D22: =IF('Balance Sheet'!D15<=0,"n/a",'Balance Sheet'!D9/'Balance Sheet'!D15) -> 1.1443711
A23: Return on equity (product of the three) | B23: =IF(AND(ISNUMBER(B20),ISNUMBER(B21),ISNUMBER(B22)),B20*B21*B22,"n/a") -> 0.62511847 | C23: =IF(AND(ISNUMBER(C20),ISNUMBER(C21),ISNUMBER(C22)),C20*C21*C22,"n/a") -> 0.46271227 | D23: =IF(AND(ISNUMBER(D20),ISNUMBER(D21),ISNUMBER(D22)),D20*D21*D22,"n/a") -> 0.3619999
A24: Check: product − return on equity (must be 0) | B24: =IF(AND(ISNUMBER(B23),ISNUMBER(B16)),B23-B16,IF(ISNUMBER(B23),1,IF(AND(ISNUMBER(B16),ISNUMBER(B20),ISNUMBER(B21)),1,0))) -> 0 | C24: =IF(AND(ISNUMBER(C23),ISNUMBER(C16)),C23-C16,IF(ISNUMBER(C23),1,IF(AND(ISNUMBER(C16),ISNUMBER(C20),ISNUMBER(C21)),1,0))) -> 0 | D24: =IF(AND(ISNUMBER(D23),ISNUMBER(D16)),D23-D16,IF(ISNUMBER(D23),1,IF(AND(ISNUMBER(D16),ISNUMBER(D20),ISNUMBER(D21)),1,0))) -> 0
A26: Bakery metrics ($'000; per-unit rows in $)
A27: Year # | B27: 1 | C27: 2 | D27: 3
B28: Year 1 | C28: Year 2 | D28: Year 3 | E28: Target
A29: Opening days in the year | B29: =SUMIF(Monthly!$C$5:$AL$5,B$27,Monthly!$C$11:$AL$11) -> 312 | C29: =SUMIF(Monthly!$C$5:$AL$5,C$27,Monthly!$C$11:$AL$11) -> 312 | D29: =SUMIF(Monthly!$C$5:$AL$5,D$27,Monthly!$C$11:$AL$11) -> 312
A30: Retail transactions | B30: =SUMIF(Monthly!$C$5:$AL$5,B$27,Monthly!$C$12:$AL$12) -> 98641.92 | C30: =SUMIF(Monthly!$C$5:$AL$5,C$27,Monthly!$C$12:$AL$12) -> 102835.2 | D30: =SUMIF(Monthly!$C$5:$AL$5,D$27,Monthly!$C$12:$AL$12) -> 105920.26
A31: Customers per day (average) | B31: =IF(B29=0,0,B30/B29) -> 316.16 | C31: =IF(C29=0,0,C30/C29) -> 329.6 | D31: =IF(D29=0,0,D30/D29) -> 339.488
A32: Average ticket ($) | B32: =IF(B30=0,0,B35/B30) -> 11.5 | C32: =IF(C30=0,0,C35/C30) -> 11.845 | D32: =IF(D30=0,0,D35/D30) -> 12.20035
A33: Wholesale accounts (year end) | B33: =INDEX(Monthly!$C$17:$AL$17,B$27*12) -> 16 | C33: =INDEX(Monthly!$C$17:$AL$17,C$27*12) -> 17.92 | D33: =INDEX(Monthly!$C$17:$AL$17,D$27*12) -> 20.0704
A34: Revenue | B34: =SUMIF(Monthly!$C$5:$AL$5,B$27,Monthly!$C$22:$AL$22) -> 1578046.1 | C34: =SUMIF(Monthly!$C$5:$AL$5,C$27,Monthly!$C$22:$AL$22) -> 1736372.4 | D34: =SUMIF(Monthly!$C$5:$AL$5,D$27,Monthly!$C$22:$AL$22) -> 1890162.9
A35: Retail counter revenue | B35: =SUMIF(Monthly!$C$5:$AL$5,B$27,Monthly!$C$14:$AL$14) -> 1134382.1 | C35: =SUMIF(Monthly!$C$5:$AL$5,C$27,Monthly!$C$14:$AL$14) -> 1218082.9 | D35: =SUMIF(Monthly!$C$5:$AL$5,D$27,Monthly!$C$14:$AL$14) -> 1292264.2
A36: Wholesale revenue | B36: =SUMIF(Monthly!$C$5:$AL$5,B$27,Monthly!$C$19:$AL$19) -> 443664 | C36: =SUMIF(Monthly!$C$5:$AL$5,C$27,Monthly!$C$19:$AL$19) -> 518289.41 | D36: =SUMIF(Monthly!$C$5:$AL$5,D$27,Monthly!$C$19:$AL$19) -> 597898.66
A37: Wholesale share of revenue | B37: =IF(B34=0,0,B36/B34) -> 0.28114768 | C37: =IF(C34=0,0,C36/C34) -> 0.29848978 | D37: =IF(D34=0,0,D36/D34) -> 0.31632124
A38: Retail revenue per opening day ($) | B38: =IF(B29=0,0,B35/B29) -> 3635.84 | C38: =IF(C29=0,0,C35/C29) -> 3904.112 | D38: =IF(D29=0,0,D35/D29) -> 4141.8724
A39: Waste cost (unsold retail production) | B39: =-SUMIF(Monthly!$C$5:$AL$5,B$27,Monthly!$C$26:$AL$26) -> 26925.992 | C39: =-SUMIF(Monthly!$C$5:$AL$5,C$27,Monthly!$C$26:$AL$26) -> 28912.738 | D39: =-SUMIF(Monthly!$C$5:$AL$5,D$27,Monthly!$C$26:$AL$26) -> 30673.524
A40: Waste cost, % of retail revenue | B40: =IF(B35=0,0,B39/B35) -> 0.023736264 | C40: =IF(C35=0,0,C39/C35) -> 0.023736264 | D40: =IF(D35=0,0,D39/D35) -> 0.023736264
A41: Wholesale delivery cost | B41: =-SUMIF(Monthly!$C$5:$AL$5,B$27,Monthly!$C$35:$AL$35) -> 36972 | C41: =-SUMIF(Monthly!$C$5:$AL$5,C$27,Monthly!$C$35:$AL$35) -> 41932.8 | D41: =-SUMIF(Monthly!$C$5:$AL$5,D$27,Monthly!$C$35:$AL$35) -> 46964.736
A42: Gross profit | B42: =SUMIF(Monthly!$C$5:$AL$5,B$27,Monthly!$C$29:$AL$29) -> 1077227.7 | C42: =SUMIF(Monthly!$C$5:$AL$5,C$27,Monthly!$C$29:$AL$29) -> 1183311.2 | D42: =SUMIF(Monthly!$C$5:$AL$5,D$27,Monthly!$C$29:$AL$29) -> 1285883.7
A43: Gross margin | B43: =IF(B34=0,0,B42/B34) -> 0.68263384 | C43: =IF(C34=0,0,C42/C34) -> 0.68148469 | D43: =IF(D34=0,0,D42/D34) -> 0.68030311
...

Sheet Inputs
A1: Inputs — Low / Base / High | I1: =HYPERLINK("#'Cover'!A1","◂ Contents") -> ◂ Contents
A2: Illustrative assumptions — replace them with your own numbers.
A5: Driver | B5: Low | C5: Base | D5: High | E5: Active | F5: Unit | G5: Source / comment
A6: Retail counter
A7: Customers per day at full traffic | B7: 300 | C7: 320 | D7: 340 | E7: =CHOOSE(Dashboard!$B$4,B7,C7,D7) -> 320 | F7: # | G7: Low ≤ Base ≤ High
A8: Months to reach full traffic | B8: 3 | C8: 2 | D8: 1 | E8: =CHOOSE(Dashboard!$B$4,B8,C8,D8) -> 2 | F8: months | G8: Low ≥ Base ≥ High (lower is better)
A9: Opening traffic, % of full | B9: 0.85 | C9: 0.9 | D9: 0.95 | E9: =CHOOSE(Dashboard!$B$4,B9,C9,D9) -> 0.9 | F9: % | G9: Low ≤ Base ≤ High
A10: Traffic growth per year (after year 1) | B10: 0.01 | C10: 0.03 | D10: 0.05 | E10: =CHOOSE(Dashboard!$B$4,B10,C10,D10) -> 0.03 | F10: % | G10: Low ≤ Base ≤ High
A11: Average ticket per customer (year 1) | B11: 11 | C11: 11.5 | D11: 12 | E11: =CHOOSE(Dashboard!$B$4,B11,C11,D11) -> 11.5 | F11: $ | G11: Low ≤ Base ≤ High
A12: Price increase per year | B12: 0.02 | C12: 0.03 | D12: 0.04 | E12: =CHOOSE(Dashboard!$B$4,B12,C12,D12) -> 0.03 | F12: % | G12: Low ≤ Base ≤ High
A13: Opening days per week | B13: 6 | C13: 6 | D13: 6 | E13: =CHOOSE(Dashboard!$B$4,B13,C13,D13) -> 6 | F13: days
A14: Holiday uplift, Nov-Dec (monthly models) | B14: 0.2 | C14: 0.2 | D14: 0.2 | E14: =CHOOSE(Dashboard!$B$4,B14,C14,D14) -> 0.2 | F14: %
A16: Wholesale
A17: Wholesale accounts at full ramp (year 1) | B17: 13 | C17: 16 | D17: 19 | E17: =CHOOSE(Dashboard!$B$4,B17,C17,D17) -> 16 | F17: # | G17: Low ≤ Base ≤ High
A18: Wholesale accounts growth per year | B18: 0.08 | C18: 0.12 | D18: 0.16 | E18: =CHOOSE(Dashboard!$B$4,B18,C18,D18) -> 0.12 | F18: % | G18: Low ≤ Base ≤ High
A19: Order value per account per week (year 1) | B19: 500 | C19: 540 | D19: 580 | E19: =CHOOSE(Dashboard!$B$4,B19,C19,D19) -> 540 | F19: $ | G19: Low ≤ Base ≤ High
A20: Deliveries per account per week | B20: 5 | C20: 5 | D20: 5 | E20: =CHOOSE(Dashboard!$B$4,B20,C20,D20) -> 5 | F20: #
A21: Delivery cost per drop (driver, fuel, van) | B21: 9.5 | C21: 9 | D21: 8.5 | E21: =CHOOSE(Dashboard!$B$4,B21,C21,D21) -> 9 | F21: $ | G21: Low ≥ Base ≥ High (lower is better)
A23: Cost of sales
A24: Ingredients, % of retail sales | B24: 0.255 | C24: 0.24 | D24: 0.225 | E24: =CHOOSE(Dashboard!$B$4,B24,C24,D24) -> 0.24 | F24: % | G24: Low ≥ Base ≥ High (lower is better)
