Workbook

Sheet Cover
B2: Bakery financial model (growing)
B3: 5-year financial model · monthly detail · Low / Base / High scenarios · US dollars · Full plan
B5: Purpose | D5: Revenue and profit plan
B6: Active scenario | D6: =Dashboard!C4&" (change it on the Dashboard, cell B4)" -> Base (change it on the Dashboard, cell B4)
B7: Model checks | D7: =Checks!B25 -> PASS
B8: Prepared | D8: 21 October 2026
B10: Contents
C11: PRESENTATION
B12: 1 | C12: =HYPERLINK("#Dashboard!A1","Dashboard") -> Dashboard | D12: Scenario switch, key numbers, core financials
B13: 2 | C13: =HYPERLINK("#Summary!A1","Summary") -> Summary | D13: Income statement, cash flow and balance sheet — every year and any year by month
B14: 3 | C14: =HYPERLINK("#Scenarios!A1","Scenarios") -> Scenarios | D14: Low / Base / High side by side: drivers, outputs, charts
B15: 4 | C15: =HYPERLINK("#'Break-even'!A1","Break-even") -> Break-even | D15: Startup costs, funding need, break-even timing and revenue
B16: 5 | C16: =HYPERLINK("#Valuation!A1","Valuation") -> Valuation | D16: Free cash flow, DCF (perpetual growth and exit multiple), WACC × growth sensitivity
B17: 6 | C17: =HYPERLINK("#'Sources & Uses'!A1","Sources & Uses") -> Sources & Uses | D17: Funding structure, sources and uses of cash for the first months
B18: 7 | C18: =HYPERLINK("#KPIs!A1","KPIs") -> KPIs | D18: Financial ratios, DuPont analysis, industry metrics
C19: INPUTS
B20: 8 | C20: =HYPERLINK("#Inputs!A1","Inputs") -> Inputs | D20: Every assumption, Low / Base / High, with units and comments
C21: STATEMENTS
B22: 9 | C22: =HYPERLINK("#'P&L'!A1","P&L") -> P&L | D22: Annual profit & loss
B23: 10 | C23: =HYPERLINK("#'Cash Flow'!A1","Cash Flow") -> Cash Flow | D23: Annual cash flow statement
B24: 11 | C24: =HYPERLINK("#'Balance Sheet'!A1","Balance Sheet") -> Balance Sheet | D24: Balance sheet at year end
C25: CALCULATIONS
B26: 12 | C26: =HYPERLINK("#Monthly!A1","Monthly") -> Monthly | D26: Month-by-month engine of the model
B27: 13 | C27: =HYPERLINK("#Headcount!A1","Headcount") -> Headcount | D27: Team and payroll
B28: 14 | C28: =HYPERLINK("#'Scenario calc'!A1","Scenario calc") -> Scenario calc | D28: Low, Base and High calculated side by side for the Scenarios sheet
C29: CONTROL
B30: 15 | C30: =HYPERLINK("#Checks!A1","Checks") -> Checks | D30: Live integrity checks and the overall verdict
B32: How to read this file
C33: 1000 | D33: Input you can change — yellow cell with a blue figure (Inputs sheet and the view switches)
C34: 1000 | D34: Formula — calculated, do not overwrite
C35: 1000 | D35: Link to another sheet
C36: 1000 | D36: Active value the model uses (follows the scenario)

Sheet Dashboard
A1: Dashboard | W1: =HYPERLINK("#'Cover'!A1","◂ Contents") -> ◂ Contents
A2: Bakery financial model (growing)
A4: Active scenario | B4: 2 | C4: =CHOOSE(B4,"Low","Base","High") -> Base | D4: 1 = Low · 2 = Base · 3 = High — every sheet follows this cell | S4: Model checks | T4: =Checks!B25 -> PASS
A6: REVENUE · YEAR 5 | C6: EBITDA MARGIN · YEAR 5 | H6: NET INCOME · YEAR 5 | L6: LOWEST CASH BALANCE | P6: FUNDING REQUIRED | T6: ENTERPRISE VALUE (DCF)
A7: =F12 -> 2250134.1 | C7: =F17 -> 0.1467825 | H7: =F18 -> 244541.73 | L7: =F39 -> 35320.959 | P7: =F37 -> 337679.04 | T7: =F44 -> 1316371.7
A8: =IF(AND(B12>0,F12>=0),(F12/B12)^(1/4)-1,"CAGR n/a") -> 0.092852837 | C8: =F16 -> 330280.3 | H8: =F19 -> 0.10867874 | L8: ='Break-even'!B6 -> 1 | P8: =IF(F38>=0,"Covered by funding raised",-F38) -> 197679.04 | T8: Average of 2 methods
A10: Core financials ($'000) — active scenario
B11: 1 | C11: 2 | D11: 3 | E11: 4 | F11: 5
A12: Revenue | B12: =SUMIF(Monthly!$C$5:$BJ$5,B$11,Monthly!$C$22:$BJ$22) -> 1577472 | C12: =SUMIF(Monthly!$C$5:$BJ$5,C$11,Monthly!$C$22:$BJ$22) -> 1736372.4 | D12: =SUMIF(Monthly!$C$5:$BJ$5,D$11,Monthly!$C$22:$BJ$22) -> 1890162.9 | E12: =SUMIF(Monthly!$C$5:$BJ$5,E$11,Monthly!$C$22:$BJ$22) -> 2060699 | F12: =SUMIF(Monthly!$C$5:$BJ$5,F$11,Monthly!$C$22:$BJ$22) -> 2250134.1
A13: Gross profit | B13: =SUMIF(Monthly!$C$5:$BJ$5,B$11,Monthly!$C$29:$BJ$29) -> 1076825.1 | C13: =SUMIF(Monthly!$C$5:$BJ$5,C$11,Monthly!$C$29:$BJ$29) -> 1183311.2 | D13: =SUMIF(Monthly!$C$5:$BJ$5,D$11,Monthly!$C$29:$BJ$29) -> 1285883.7 | E13: =SUMIF(Monthly!$C$5:$BJ$5,E$11,Monthly!$C$29:$BJ$29) -> 1399389 | F13: =SUMIF(Monthly!$C$5:$BJ$5,F$11,Monthly!$C$29:$BJ$29) -> 1525212.7
A14: Gross margin | B14: =IF(B12=0,0,B13/B12) -> 0.68262706 | C14: =IF(C12=0,0,C13/C12) -> 0.68148469 | D14: =IF(D12=0,0,D13/D12) -> 0.68030311 | E14: =IF(E12=0,0,E13/E12) -> 0.67908462 | F14: =IF(F12=0,0,F13/F12) -> 0.67783194
A15: Operating expenses | B15: =SUMIF(Monthly!$C$5:$BJ$5,B$11,Monthly!$C$40:$BJ$40) -> -931468.06 | C15: =SUMIF(Monthly!$C$5:$BJ$5,C$11,Monthly!$C$40:$BJ$40) -> -990021.96 | D15: =SUMIF(Monthly!$C$5:$BJ$5,D$11,Monthly!$C$40:$BJ$40) -> -1052480.5 | E15: =SUMIF(Monthly!$C$5:$BJ$5,E$11,Monthly!$C$40:$BJ$40) -> -1120604.2 | F15: =SUMIF(Monthly!$C$5:$BJ$5,F$11,Monthly!$C$40:$BJ$40) -> -1194932.4
A16: EBITDA | B16: =SUMIF(Monthly!$C$5:$BJ$5,B$11,Monthly!$C$41:$BJ$41) -> 145357.01 | C16: =SUMIF(Monthly!$C$5:$BJ$5,C$11,Monthly!$C$41:$BJ$41) -> 193289.21 | D16: =SUMIF(Monthly!$C$5:$BJ$5,D$11,Monthly!$C$41:$BJ$41) -> 233403.12 | E16: =SUMIF(Monthly!$C$5:$BJ$5,E$11,Monthly!$C$41:$BJ$41) -> 278784.79 | F16: =SUMIF(Monthly!$C$5:$BJ$5,F$11,Monthly!$C$41:$BJ$41) -> 330280.3
A17: EBITDA margin | B17: =IF(B12=0,0,B16/B12) -> 0.092145541 | C17: =IF(C12=0,0,C16/C12) -> 0.11131783 | D17: =IF(D12=0,0,D16/D12) -> 0.12348307 | E17: =IF(E12=0,0,E16/E12) -> 0.13528652 | F17: =IF(F12=0,0,F16/F12) -> 0.1467825
A18: Net income | B18: =SUMIF(Monthly!$C$5:$BJ$5,B$11,Monthly!$C$50:$BJ$50) -> 99754.292 | C18: =SUMIF(Monthly!$C$5:$BJ$5,C$11,Monthly!$C$50:$BJ$50) -> 137835.57 | D18: =SUMIF(Monthly!$C$5:$BJ$5,D$11,Monthly!$C$50:$BJ$50) -> 169019.96 | E18: =SUMIF(Monthly!$C$5:$BJ$5,E$11,Monthly!$C$50:$BJ$50) -> 204365.88 | F18: =SUMIF(Monthly!$C$5:$BJ$5,F$11,Monthly!$C$50:$BJ$50) -> 244541.73
A19: Net margin | B19: =IF(B12=0,0,B18/B12) -> 0.063236807 | C19: =IF(C12=0,0,C18/C12) -> 0.079381341 | D19: =IF(D12=0,0,D18/D12) -> 0.089420843 | E19: =IF(E12=0,0,E18/E12) -> 0.099173086 | F19: =IF(F12=0,0,F18/F12) -> 0.10867874
A20: Operating cash flow | B20: =SUMIF(Monthly!$C$5:$BJ$5,B$11,Monthly!$C$74:$BJ$74) -> 90917.287 | C20: =SUMIF(Monthly!$C$5:$BJ$5,C$11,Monthly!$C$74:$BJ$74) -> 150047.06 | D20: =SUMIF(Monthly!$C$5:$BJ$5,D$11,Monthly!$C$74:$BJ$74) -> 183063.52 | E20: =SUMIF(Monthly!$C$5:$BJ$5,E$11,Monthly!$C$74:$BJ$74) -> 220221.66 | F20: =SUMIF(Monthly!$C$5:$BJ$5,F$11,Monthly!$C$74:$BJ$74) -> 262187.19
A21: Investing cash flow | B21: =SUMIF(Monthly!$C$5:$BJ$5,B$11,Monthly!$C$75:$BJ$75) -> -90000 | C21: =SUMIF(Monthly!$C$5:$BJ$5,C$11,Monthly!$C$75:$BJ$75) -> -14000 | D21: =SUMIF(Monthly!$C$5:$BJ$5,D$11,Monthly!$C$75:$BJ$75) -> -14000 | E21: =SUMIF(Monthly!$C$5:$BJ$5,E$11,Monthly!$C$75:$BJ$75) -> -14000 | F21: =SUMIF(Monthly!$C$5:$BJ$5,F$11,Monthly!$C$75:$BJ$75) -> -14000
A22: Financing cash flow | B22: =SUMIF(Monthly!$C$5:$BJ$5,B$11,Monthly!$C$77:$BJ$77) -> 125333.33 | C22: =SUMIF(Monthly!$C$5:$BJ$5,C$11,Monthly!$C$77:$BJ$77) -> -16000 | D22: =SUMIF(Monthly!$C$5:$BJ$5,D$11,Monthly!$C$77:$BJ$77) -> -16000 | E22: =SUMIF(Monthly!$C$5:$BJ$5,E$11,Monthly!$C$77:$BJ$77) -> -16000 | F22: =SUMIF(Monthly!$C$5:$BJ$5,F$11,Monthly!$C$77:$BJ$77) -> -16000
A23: Net change in cash | B23: =SUMIF(Monthly!$C$5:$BJ$5,B$11,Monthly!$C$78:$BJ$78) -> 126250.62 | C23: =SUMIF(Monthly!$C$5:$BJ$5,C$11,Monthly!$C$78:$BJ$78) -> 120047.06 | D23: =SUMIF(Monthly!$C$5:$BJ$5,D$11,Monthly!$C$78:$BJ$78) -> 153063.52 | E23: =SUMIF(Monthly!$C$5:$BJ$5,E$11,Monthly!$C$78:$BJ$78) -> 190221.66 | F23: =SUMIF(Monthly!$C$5:$BJ$5,F$11,Monthly!$C$78:$BJ$78) -> 232187.19
A24: Year-end cash | B24: =INDEX(Monthly!$C$80:$BJ$80,B$11*12) -> 126250.62 | C24: =INDEX(Monthly!$C$80:$BJ$80,C$11*12) -> 246297.68 | D24: =INDEX(Monthly!$C$80:$BJ$80,D$11*12) -> 399361.2 | E24: =INDEX(Monthly!$C$80:$BJ$80,E$11*12) -> 589582.86 | F24: =INDEX(Monthly!$C$80:$BJ$80,F$11*12) -> 821770.05
A26: Bakery metrics
B27: 1 | C27: 2 | D27: 3 | E27: 4 | F27: 5
A28: Retail counter revenue | B28: =KPIs!B35 -> 1133808 | C28: =KPIs!C35 -> 1218082.9 | D28: =KPIs!D35 -> 1292264.2 | E28: =KPIs!E35 -> 1370963.1 | F28: =KPIs!F35 -> 1454454.7
A29: Wholesale revenue | B29: =KPIs!B36 -> 443664 | C29: =KPIs!C36 -> 518289.41 | D29: =KPIs!D36 -> 597898.66 | E29: =KPIs!E36 -> 689735.9 | F29: =KPIs!F36 -> 795679.33
A30: Customers per day (average) | B30: =KPIs!B31 -> 316 | C30: =KPIs!C31 -> 329.6 | D30: =KPIs!D31 -> 339.488 | E30: =KPIs!E31 -> 349.67264 | F30: =KPIs!F31 -> 360.16282
A31: Wholesale accounts | B31: =KPIs!B33 -> 16 | C31: =KPIs!C33 -> 17.92 | D31: =KPIs!D33 -> 20.0704 | E31: =KPIs!E33 -> 22.478848 | F31: =KPIs!F33 -> 25.17631
A32: Team (FTE, year end) | B32: =INDEX(Headcount!$C$11:$BJ$11,B$27*12) -> 13.5 | C32: =INDEX(Headcount!$C$11:$BJ$11,C$27*12) -> 14.22 | D32: =INDEX(Headcount!$C$11:$BJ$11,D$27*12) -> 14.9832 | E32: =INDEX(Headcount!$C$11:$BJ$11,E$27*12) -> 15.792192 | F32: =INDEX(Headcount!$C$11:$BJ$11,F$27*12) -> 16.649724
A34: Funding & valuation ($'000) — active scenario
A35: Equity raised | F35: =Inputs!$E$58 -> 60000
A36: Loan drawn | F36: =Inputs!$E$59 -> 80000
A37: Funding required (incl. cash buffer) | F37: ='Break-even'!B12 -> 337679.04
A38: Funding surplus / (shortfall) | F38: ='Break-even'!B17 -> -197679.04
A39: ="Lowest cash balance (month "&'Break-even'!B6&")" -> Lowest cash balance (month 1) | F39: ='Break-even'!B18 -> 35320.959
A40: First month with positive EBITDA | F40: ='Break-even'!B21 -> 1
A41: Cash invested paid back | F41: ='Break-even'!B23 -> 12
A42: Enterprise value — perpetual growth | F42: =Valuation!B27 -> 1315477.9
A43: Enterprise value — exit multiple | F43: =Valuation!C27 -> 1317265.5
A44: Enterprise value — average | F44: =Valuation!B30 -> 1316371.7

Sheet Summary
A1: Financial statements summary | U1: =HYPERLINK("#'Cover'!A1","◂ Contents") -> ◂ Contents
A2: Bakery financial model (growing) | P2: Select detailed year: | R2: 1
A5: Income statement ($'000) — by year | H5: ="Income statement ($'000) — Year "&$R$2&", by month" -> Income statement ($'000) — Year 1, by month
B6: 1 | C6: 2 | D6: 3 | E6: 4 | F6: 5 | H6: =INDEX(Monthly!$C$4:$BJ$4,($R$2-1)*12+1) -> 1 | I6: =INDEX(Monthly!$C$4:$BJ$4,($R$2-1)*12+2) -> 2 | J6: =INDEX(Monthly!$C$4:$BJ$4,($R$2-1)*12+3) -> 3 | K6: =INDEX(Monthly!$C$4:$BJ$4,($R$2-1)*12+4) -> 4 | L6: =INDEX(Monthly!$C$4:$BJ$4,($R$2-1)*12+5) -> 5 | M6: =INDEX(Monthly!$C$4:$BJ$4,($R$2-1)*12+6) -> 6 | N6: =INDEX(Monthly!$C$4:$BJ$4,($R$2-1)*12+7) -> 7 | O6: =INDEX(Monthly!$C$4:$BJ$4,($R$2-1)*12+8) -> 8 | P6: =INDEX(Monthly!$C$4:$BJ$4,($R$2-1)*12+9) -> 9 | Q6: =INDEX(Monthly!$C$4:$BJ$4,($R$2-1)*12+10) -> 10 | R6: =INDEX(Monthly!$C$4:$BJ$4,($R$2-1)*12+11) -> 11 | S6: =INDEX(Monthly!$C$4:$BJ$4,($R$2-1)*12+12) -> 12
A7: Revenue | B7: ='P&L'!B5 -> 1577472 | C7: ='P&L'!C5 -> 1736372.4 | D7: ='P&L'!D5 -> 1890162.9 | E7: ='P&L'!E5 -> 2060699 | F7: ='P&L'!F5 -> 2250134.1 | H7: =INDEX(Monthly!$C$22:$BJ$22,($R$2-1)*12+1) -> 115980.8 | I7: =INDEX(Monthly!$C$22:$BJ$22,($R$2-1)*12+2) -> 122636.8 | J7: =INDEX(Monthly!$C$22:$BJ$22,($R$2-1)*12+3) -> 129292.8 | K7: =INDEX(Monthly!$C$22:$BJ$22,($R$2-1)*12+4) -> 129292.8 | L7: =INDEX(Monthly!$C$22:$BJ$22,($R$2-1)*12+5) -> 129292.8 | M7: =INDEX(Monthly!$C$22:$BJ$22,($R$2-1)*12+6) -> 129292.8 | N7: =INDEX(Monthly!$C$22:$BJ$22,($R$2-1)*12+7) -> 129292.8 | O7: =INDEX(Monthly!$C$22:$BJ$22,($R$2-1)*12+8) -> 129292.8 | P7: =INDEX(Monthly!$C$22:$BJ$22,($R$2-1)*12+9) -> 129292.8 | Q7: =INDEX(Monthly!$C$22:$BJ$22,($R$2-1)*12+10) -> 129292.8 | R7: =INDEX(Monthly!$C$22:$BJ$22,($R$2-1)*12+11) -> 152256 | S7: =INDEX(Monthly!$C$22:$BJ$22,($R$2-1)*12+12) -> 152256
A8: Cost of sales | B8: ='P&L'!B6 -> -500646.93 | C8: ='P&L'!C6 -> -553061.18 | D8: ='P&L'!D6 -> -604279.19 | E8: ='P&L'!E6 -> -661309.99 | F8: ='P&L'!F6 -> -724921.33 | H8: =INDEX(Monthly!$C$28:$BJ$28,($R$2-1)*12+1) -> -36880.494 | I8: =INDEX(Monthly!$C$28:$BJ$28,($R$2-1)*12+2) -> -38992.928 | J8: =INDEX(Monthly!$C$28:$BJ$28,($R$2-1)*12+3) -> -41105.362 | K8: =INDEX(Monthly!$C$28:$BJ$28,($R$2-1)*12+4) -> -41105.362 | L8: =INDEX(Monthly!$C$28:$BJ$28,($R$2-1)*12+5) -> -41105.362 | M8: =INDEX(Monthly!$C$28:$BJ$28,($R$2-1)*12+6) -> -41105.362 | N8: =INDEX(Monthly!$C$28:$BJ$28,($R$2-1)*12+7) -> -41105.362 | O8: =INDEX(Monthly!$C$28:$BJ$28,($R$2-1)*12+8) -> -41105.362 | P8: =INDEX(Monthly!$C$28:$BJ$28,($R$2-1)*12+9) -> -41105.362 | Q8: =INDEX(Monthly!$C$28:$BJ$28,($R$2-1)*12+10) -> -41105.362 | R8: =INDEX(Monthly!$C$28:$BJ$28,($R$2-1)*12+11) -> -47965.303 | S8: =INDEX(Monthly!$C$28:$BJ$28,($R$2-1)*12+12) -> -47965.303
A9: Gross profit | B9: ='P&L'!B7 -> 1076825.1 | C9: ='P&L'!C7 -> 1183311.2 | D9: ='P&L'!D7 -> 1285883.7 | E9: ='P&L'!E7 -> 1399389 | F9: ='P&L'!F7 -> 1525212.7 | H9: =INDEX(Monthly!$C$29:$BJ$29,($R$2-1)*12+1) -> 79100.306 | I9: =INDEX(Monthly!$C$29:$BJ$29,($R$2-1)*12+2) -> 83643.872 | J9: =INDEX(Monthly!$C$29:$BJ$29,($R$2-1)*12+3) -> 88187.438 | K9: =INDEX(Monthly!$C$29:$BJ$29,($R$2-1)*12+4) -> 88187.438 | L9: =INDEX(Monthly!$C$29:$BJ$29,($R$2-1)*12+5) -> 88187.438 | M9: =INDEX(Monthly!$C$29:$BJ$29,($R$2-1)*12+6) -> 88187.438 | N9: =INDEX(Monthly!$C$29:$BJ$29,($R$2-1)*12+7) -> 88187.438 | O9: =INDEX(Monthly!$C$29:$BJ$29,($R$2-1)*12+8) -> 88187.438 | P9: =INDEX(Monthly!$C$29:$BJ$29,($R$2-1)*12+9) -> 88187.438 | Q9: =INDEX(Monthly!$C$29:$BJ$29,($R$2-1)*12+10) -> 88187.438 | R9: =INDEX(Monthly!$C$29:$BJ$29,($R$2-1)*12+11) -> 104290.7 | S9: =INDEX(Monthly!$C$29:$BJ$29,($R$2-1)*12+12) -> 104290.7
A10: Gross margin | B10: ='P&L'!B8 -> 0.68262706 | C10: ='P&L'!C8 -> 0.68148469 | D10: ='P&L'!D8 -> 0.68030311 | E10: ='P&L'!E8 -> 0.67908462 | F10: ='P&L'!F8 -> 0.67783194 | H10: =IF(H7=0,0,H9/H7) -> 0.68201208 | I10: =IF(I7=0,0,I9/I7) -> 0.68204545 | J10: =IF(J7=0,0,J9/J7) -> 0.6820754 | K10: =IF(K7=0,0,K9/K7) -> 0.6820754 | L10: =IF(L7=0,0,L9/L7) -> 0.6820754 | M10: =IF(M7=0,0,M9/M7) -> 0.6820754 | N10: =IF(N7=0,0,N9/N7) -> 0.6820754 | O10: =IF(O7=0,0,O9/O7) -> 0.6820754 | ... S10: =IF(S7=0,0,S9/S7) -> 0.68496937
A11: Total operating expenses | B11: ='P&L'!B17 -> -931468.06 | C11: ='P&L'!C17 -> -990021.96 | D11: ='P&L'!D17 -> -1052480.5 | E11: ='P&L'!E17 -> -1120604.2 | F11: ='P&L'!F17 -> -1194932.4 | H11: =INDEX(Monthly!$C$40:$BJ$40,($R$2-1)*12+1) -> -76698.257 | I11: =INDEX(Monthly!$C$40:$BJ$40,($R$2-1)*12+2) -> -77121.329 | J11: =INDEX(Monthly!$C$40:$BJ$40,($R$2-1)*12+3) -> -77544.401 | K11: =INDEX(Monthly!$C$40:$BJ$40,($R$2-1)*12+4) -> -77544.401 | L11: =INDEX(Monthly!$C$40:$BJ$40,($R$2-1)*12+5) -> -77544.401 | M11: =INDEX(Monthly!$C$40:$BJ$40,($R$2-1)*12+6) -> -77544.401 | N11: =INDEX(Monthly!$C$40:$BJ$40,($R$2-1)*12+7) -> -77544.401 | O11: =INDEX(Monthly!$C$40:$BJ$40,($R$2-1)*12+8) -> -77544.401 | P11: =INDEX(Monthly!$C$40:$BJ$40,($R$2-1)*12+9) -> -77544.401 | Q11: =INDEX(Monthly!$C$40:$BJ$40,($R$2-1)*12+10) -> -77544.401 | R11: =INDEX(Monthly!$C$40:$BJ$40,($R$2-1)*12+11) -> -78646.635 | S11: =INDEX(Monthly!$C$40:$BJ$40,($R$2-1)*12+12) -> -78646.635
A12: EBITDA | B12: ='P&L'!B18 -> 145357.01 | C12: ='P&L'!C18 -> 193289.21 | D12: ='P&L'!D18 -> 233403.12 | E12: ='P&L'!E18 -> 278784.79 | F12: ='P&L'!F18 -> 330280.3 | H12: =INDEX(Monthly!$C$41:$BJ$41,($R$2-1)*12+1) -> 2402.0492 | I12: =INDEX(Monthly!$C$41:$BJ$41,($R$2-1)*12+2) -> 6522.5429 | J12: =INDEX(Monthly!$C$41:$BJ$41,($R$2-1)*12+3) -> 10643.037 | K12: =INDEX(Monthly!$C$41:$BJ$41,($R$2-1)*12+4) -> 10643.037 | L12: =INDEX(Monthly!$C$41:$BJ$41,($R$2-1)*12+5) -> 10643.037 | M12: =INDEX(Monthly!$C$41:$BJ$41,($R$2-1)*12+6) -> 10643.037 | N12: =INDEX(Monthly!$C$41:$BJ$41,($R$2-1)*12+7) -> 10643.037 | O12: =INDEX(Monthly!$C$41:$BJ$41,($R$2-1)*12+8) -> 10643.037 | P12: =INDEX(Monthly!$C$41:$BJ$41,($R$2-1)*12+9) -> 10643.037 | Q12: =INDEX(Monthly!$C$41:$BJ$41,($R$2-1)*12+10) -> 10643.037 | R12: =INDEX(Monthly!$C$41:$BJ$41,($R$2-1)*12+11) -> 25644.062 | S12: =INDEX(Monthly!$C$41:$BJ$41,($R$2-1)*12+12) -> 25644.062
A13: EBITDA margin | B13: ='P&L'!B19 -> 0.092145541 | C13: ='P&L'!C19 -> 0.11131783 | D13: ='P&L'!D19 -> 0.12348307 | E13: ='P&L'!E19 -> 0.13528652 | F13: ='P&L'!F19 -> 0.1467825 | H13: =IF(H7=0,0,H12/H7) -> 0.020710749 | I13: =IF(I7=0,0,I12/I7) -> 0.053185854 | J13: =IF(J7=0,0,J12/J7) -> 0.082317319 | K13: =IF(K7=0,0,K12/K7) -> 0.082317319 | L13: =IF(L7=0,0,L12/L7) -> 0.082317319 | M13: =IF(M7=0,0,M12/M7) -> 0.082317319 | N13: =IF(N7=0,0,N12/N7) -> 0.082317319 | O13: =IF(O7=0,0,O12/O7) -> 0.082317319 | ... S13: =IF(S7=0,0,S12/S7) -> 0.16842727
A14: Depreciation | B14: ='P&L'!B20 -> -12857.143 | C14: ='P&L'!C20 -> -13940.476 | D14: ='P&L'!D20 -> -15940.476 | E14: ='P&L'!E20 -> -17940.476 | F14: ='P&L'!F20 -> -19940.476 | H14: =INDEX(Monthly!$C$55:$BJ$55,($R$2-1)*12+1) -> -1071.4286 | I14: =INDEX(Monthly!$C$55:$BJ$55,($R$2-1)*12+2) -> -1071.4286 | J14: =INDEX(Monthly!$C$55:$BJ$55,($R$2-1)*12+3) -> -1071.4286 | K14: =INDEX(Monthly!$C$55:$BJ$55,($R$2-1)*12+4) -> -1071.4286 | L14: =INDEX(Monthly!$C$55:$BJ$55,($R$2-1)*12+5) -> -1071.4286 | M14: =INDEX(Monthly!$C$55:$BJ$55,($R$2-1)*12+6) -> -1071.4286 | N14: =INDEX(Monthly!$C$55:$BJ$55,($R$2-1)*12+7) -> -1071.4286 | O14: =INDEX(Monthly!$C$55:$BJ$55,($R$2-1)*12+8) -> -1071.4286 | P14: =INDEX(Monthly!$C$55:$BJ$55,($R$2-1)*12+9) -> -1071.4286 | Q14: =INDEX(Monthly!$C$55:$BJ$55,($R$2-1)*12+10) -> -1071.4286 | R14: =INDEX(Monthly!$C$55:$BJ$55,($R$2-1)*12+11) -> -1071.4286 | S14: =INDEX(Monthly!$C$55:$BJ$55,($R$2-1)*12+12) -> -1071.4286
A15: EBIT | B15: ='P&L'!B21 -> 132499.87 | C15: ='P&L'!C21 -> 179348.73 | D15: ='P&L'!D21 -> 217462.64 | E15: ='P&L'!E21 -> 260844.32 | F15: ='P&L'!F21 -> 310339.82 | H15: =INDEX(Monthly!$C$44:$BJ$44,($R$2-1)*12+1) -> 1330.6206 | I15: =INDEX(Monthly!$C$44:$BJ$44,($R$2-1)*12+2) -> 5451.1144 | J15: =INDEX(Monthly!$C$44:$BJ$44,($R$2-1)*12+3) -> 9571.6081 | K15: =INDEX(Monthly!$C$44:$BJ$44,($R$2-1)*12+4) -> 9571.6081 | L15: =INDEX(Monthly!$C$44:$BJ$44,($R$2-1)*12+5) -> 9571.6081 | M15: =INDEX(Monthly!$C$44:$BJ$44,($R$2-1)*12+6) -> 9571.6081 | N15: =INDEX(Monthly!$C$44:$BJ$44,($R$2-1)*12+7) -> 9571.6081 | O15: =INDEX(Monthly!$C$44:$BJ$44,($R$2-1)*12+8) -> 9571.6081 | P15: =INDEX(Monthly!$C$44:$BJ$44,($R$2-1)*12+9) -> 9571.6081 | Q15: =INDEX(Monthly!$C$44:$BJ$44,($R$2-1)*12+10) -> 9571.6081 | R15: =INDEX(Monthly!$C$44:$BJ$44,($R$2-1)*12+11) -> 24572.634 | S15: =INDEX(Monthly!$C$44:$BJ$44,($R$2-1)*12+12) -> 24572.634
A16: Interest | B16: ='P&L'!B22 -> -6228.6111 | C16: ='P&L'!C22 -> -4873.3333 | D16: ='P&L'!D22 -> -3513.3333 | E16: ='P&L'!E22 -> -2153.3333 | F16: ='P&L'!F22 -> -793.33333 | H16: =INDEX(Monthly!$C$45:$BJ$45,($R$2-1)*12+1) -> -566.66667 | I16: =INDEX(Monthly!$C$45:$BJ$45,($R$2-1)*12+2) -> -561.94444 | J16: =INDEX(Monthly!$C$45:$BJ$45,($R$2-1)*12+3) -> -552.5 | K16: =INDEX(Monthly!$C$45:$BJ$45,($R$2-1)*12+4) -> -543.05556 | L16: =INDEX(Monthly!$C$45:$BJ$45,($R$2-1)*12+5) -> -533.61111 | M16: =INDEX(Monthly!$C$45:$BJ$45,($R$2-1)*12+6) -> -524.16667 | N16: =INDEX(Monthly!$C$45:$BJ$45,($R$2-1)*12+7) -> -514.72222 | O16: =INDEX(Monthly!$C$45:$BJ$45,($R$2-1)*12+8) -> -505.27778 | P16: =INDEX(Monthly!$C$45:$BJ$45,($R$2-1)*12+9) -> -495.83333 | Q16: =INDEX(Monthly!$C$45:$BJ$45,($R$2-1)*12+10) -> -486.38889 | R16: =INDEX(Monthly!$C$45:$BJ$45,($R$2-1)*12+11) -> -476.94444 | S16: =INDEX(Monthly!$C$45:$BJ$45,($R$2-1)*12+12) -> -467.5
A17: Pre-tax income | B17: ='P&L'!B23 -> 126271.26 | C17: ='P&L'!C23 -> 174475.4 | D17: ='P&L'!D23 -> 213949.31 | E17: ='P&L'!E23 -> 258690.98 | F17: ='P&L'!F23 -> 309546.49 | H17: =INDEX(Monthly!$C$46:$BJ$46,($R$2-1)*12+1) -> 763.95398 | I17: =INDEX(Monthly!$C$46:$BJ$46,($R$2-1)*12+2) -> 4889.1699 | J17: =INDEX(Monthly!$C$46:$BJ$46,($R$2-1)*12+3) -> 9019.1081 | K17: =INDEX(Monthly!$C$46:$BJ$46,($R$2-1)*12+4) -> 9028.5525 | L17: =INDEX(Monthly!$C$46:$BJ$46,($R$2-1)*12+5) -> 9037.997 | M17: =INDEX(Monthly!$C$46:$BJ$46,($R$2-1)*12+6) -> 9047.4414 | N17: =INDEX(Monthly!$C$46:$BJ$46,($R$2-1)*12+7) -> 9056.8859 | O17: =INDEX(Monthly!$C$46:$BJ$46,($R$2-1)*12+8) -> 9066.3303 | P17: =INDEX(Monthly!$C$46:$BJ$46,($R$2-1)*12+9) -> 9075.7747 | Q17: =INDEX(Monthly!$C$46:$BJ$46,($R$2-1)*12+10) -> 9085.2192 | R17: =INDEX(Monthly!$C$46:$BJ$46,($R$2-1)*12+11) -> 24095.689 | S17: =INDEX(Monthly!$C$46:$BJ$46,($R$2-1)*12+12) -> 24105.134
A18: Income tax | B18: ='P&L'!B24 -> -26516.964 | C18: ='P&L'!C24 -> -36639.834 | D18: ='P&L'!D24 -> -44929.355 | E18: ='P&L'!E24 -> -54325.106 | F18: ='P&L'!F24 -> -65004.763 | H18: =INDEX(Monthly!$C$49:$BJ$49,($R$2-1)*12+1) -> -160.43034 | I18: =INDEX(Monthly!$C$49:$BJ$49,($R$2-1)*12+2) -> -1026.7257 | J18: =INDEX(Monthly!$C$49:$BJ$49,($R$2-1)*12+3) -> -1894.0127 | K18: =INDEX(Monthly!$C$49:$BJ$49,($R$2-1)*12+4) -> -1895.996 | L18: =INDEX(Monthly!$C$49:$BJ$49,($R$2-1)*12+5) -> -1897.9794 | M18: =INDEX(Monthly!$C$49:$BJ$49,($R$2-1)*12+6) -> -1899.9627 | N18: =INDEX(Monthly!$C$49:$BJ$49,($R$2-1)*12+7) -> -1901.946 | O18: =INDEX(Monthly!$C$49:$BJ$49,($R$2-1)*12+8) -> -1903.9294 | P18: =INDEX(Monthly!$C$49:$BJ$49,($R$2-1)*12+9) -> -1905.9127 | Q18: =INDEX(Monthly!$C$49:$BJ$49,($R$2-1)*12+10) -> -1907.896 | R18: =INDEX(Monthly!$C$49:$BJ$49,($R$2-1)*12+11) -> -5060.0948 | S18: =INDEX(Monthly!$C$49:$BJ$49,($R$2-1)*12+12) -> -5062.0781
A19: Net income | B19: ='P&L'!B25 -> 99754.292 | C19: ='P&L'!C25 -> 137835.57 | D19: ='P&L'!D25 -> 169019.96 | E19: ='P&L'!E25 -> 204365.88 | F19: ='P&L'!F25 -> 244541.73 | H19: =INDEX(Monthly!$C$50:$BJ$50,($R$2-1)*12+1) -> 603.52364 | I19: =INDEX(Monthly!$C$50:$BJ$50,($R$2-1)*12+2) -> 3862.4442 | J19: =INDEX(Monthly!$C$50:$BJ$50,($R$2-1)*12+3) -> 7125.0954 | K19: =INDEX(Monthly!$C$50:$BJ$50,($R$2-1)*12+4) -> 7132.5565 | L19: =INDEX(Monthly!$C$50:$BJ$50,($R$2-1)*12+5) -> 7140.0176 | M19: =INDEX(Monthly!$C$50:$BJ$50,($R$2-1)*12+6) -> 7147.4787 | N19: =INDEX(Monthly!$C$50:$BJ$50,($R$2-1)*12+7) -> 7154.9398 | O19: =INDEX(Monthly!$C$50:$BJ$50,($R$2-1)*12+8) -> 7162.4009 | P19: =INDEX(Monthly!$C$50:$BJ$50,($R$2-1)*12+9) -> 7169.862 | Q19: =INDEX(Monthly!$C$50:$BJ$50,($R$2-1)*12+10) -> 7177.3232 | R19: =INDEX(Monthly!$C$50:$BJ$50,($R$2-1)*12+11) -> 19035.595 | S19: =INDEX(Monthly!$C$50:$BJ$50,($R$2-1)*12+12) -> 19043.056
A20: Net margin | B20: ='P&L'!B26 -> 0.063236807 | C20: ='P&L'!C26 -> 0.079381341 | D20: ='P&L'!D26 -> 0.089420843 | E20: ='P&L'!E26 -> 0.099173086 | F20: ='P&L'!F26 -> 0.10867874 | H20: =IF(H7=0,0,H19/H7) -> 0.0052036513 | I20: =IF(I7=0,0,I19/I7) -> 0.031494985 | J20: =IF(J7=0,0,J19/J7) -> 0.055108215 | K20: =IF(K7=0,0,K19/K7) -> 0.055165922 | L20: =IF(L7=0,0,L19/L7) -> 0.055223629 | M20: =IF(M7=0,0,M19/M7) -> 0.055281336 | N20: =IF(N7=0,0,N19/N7) -> 0.055339043 | O20: =IF(O7=0,0,O19/O7) -> 0.05539675 | ... S20: =IF(S7=0,0,S19/S7) -> 0.12507261
A22: Cash flow ($'000) — by year | H22: ="Cash flow ($'000) — Year "&$R$2&", by month" -> Cash flow ($'000) — Year 1, by month
B23: 1 | C23: 2 | D23: 3 | E23: 4 | F23: 5 | H23: =INDEX(Monthly!$C$4:$BJ$4,($R$2-1)*12+1) -> 1 | I23: =INDEX(Monthly!$C$4:$BJ$4,($R$2-1)*12+2) -> 2 | J23: =INDEX(Monthly!$C$4:$BJ$4,($R$2-1)*12+3) -> 3 | K23: =INDEX(Monthly!$C$4:$BJ$4,($R$2-1)*12+4) -> 4 | L23: =INDEX(Monthly!$C$4:$BJ$4,($R$2-1)*12+5) -> 5 | M23: =INDEX(Monthly!$C$4:$BJ$4,($R$2-1)*12+6) -> 6 | N23: =INDEX(Monthly!$C$4:$BJ$4,($R$2-1)*12+7) -> 7 | O23: =INDEX(Monthly!$C$4:$BJ$4,($R$2-1)*12+8) -> 8 | P23: =INDEX(Monthly!$C$4:$BJ$4,($R$2-1)*12+9) -> 9 | Q23: =INDEX(Monthly!$C$4:$BJ$4,($R$2-1)*12+10) -> 10 | R23: =INDEX(Monthly!$C$4:$BJ$4,($R$2-1)*12+11) -> 11 | S23: =INDEX(Monthly!$C$4:$BJ$4,($R$2-1)*12+12) -> 12
A24: Operating cash flow | B24: ='Cash Flow'!B10 -> 90917.287 | C24: ='Cash Flow'!C10 -> 150047.06 | D24: ='Cash Flow'!D10 -> 183063.52 | E24: ='Cash Flow'!E10 -> 220221.66 | F24: ='Cash Flow'!F10 -> 262187.19 | H24: =INDEX(Monthly!$C$74:$BJ$74,($R$2-1)*12+1) -> -14679.041 | I24: =INDEX(Monthly!$C$74:$BJ$74,($R$2-1)*12+2) -> 3993.2899 | J24: =INDEX(Monthly!$C$74:$BJ$74,($R$2-1)*12+3) -> 7255.9411 | K24: =INDEX(Monthly!$C$74:$BJ$74,($R$2-1)*12+4) -> 8203.9851 | L24: =INDEX(Monthly!$C$74:$BJ$74,($R$2-1)*12+5) -> 8211.4462 | M24: =INDEX(Monthly!$C$74:$BJ$74,($R$2-1)*12+6) -> 8218.9073 | N24: =INDEX(Monthly!$C$74:$BJ$74,($R$2-1)*12+7) -> 8226.3684 | O24: =INDEX(Monthly!$C$74:$BJ$74,($R$2-1)*12+8) -> 8233.8295 | P24: =INDEX(Monthly!$C$74:$BJ$74,($R$2-1)*12+9) -> 8241.2906 | Q24: =INDEX(Monthly!$C$74:$BJ$74,($R$2-1)*12+10) -> 8248.7517 | R24: =INDEX(Monthly!$C$74:$BJ$74,($R$2-1)*12+11) -> 16648.034 | S24: =INDEX(Monthly!$C$74:$BJ$74,($R$2-1)*12+12) -> 20114.484
A25: Capital spending | B25: ='Cash Flow'!B11 -> -90000 | C25: ='Cash Flow'!C11 -> -14000 | D25: ='Cash Flow'!D11 -> -14000 | E25: ='Cash Flow'!E11 -> -14000 | F25: ='Cash Flow'!F11 -> -14000 | H25: =INDEX(Monthly!$C$75:$BJ$75,($R$2-1)*12+1) -> -90000 | I25: =INDEX(Monthly!$C$75:$BJ$75,($R$2-1)*12+2) -> 0 | J25: =INDEX(Monthly!$C$75:$BJ$75,($R$2-1)*12+3) -> 0 | K25: =INDEX(Monthly!$C$75:$BJ$75,($R$2-1)*12+4) -> 0 | L25: =INDEX(Monthly!$C$75:$BJ$75,($R$2-1)*12+5) -> 0 | M25: =INDEX(Monthly!$C$75:$BJ$75,($R$2-1)*12+6) -> 0 | N25: =INDEX(Monthly!$C$75:$BJ$75,($R$2-1)*12+7) -> 0 | O25: =INDEX(Monthly!$C$75:$BJ$75,($R$2-1)*12+8) -> 0 | P25: =INDEX(Monthly!$C$75:$BJ$75,($R$2-1)*12+9) -> 0 | Q25: =INDEX(Monthly!$C$75:$BJ$75,($R$2-1)*12+10) -> 0 | R25: =INDEX(Monthly!$C$75:$BJ$75,($R$2-1)*12+11) -> 0 | S25: =INDEX(Monthly!$C$75:$BJ$75,($R$2-1)*12+12) -> 0
A26: Equity raised | B26: ='Cash Flow'!B12 -> 60000 | C26: ='Cash Flow'!C12 -> 0 | D26: ='Cash Flow'!D12 -> 0 | E26: ='Cash Flow'!E12 -> 0 | F26: ='Cash Flow'!F12 -> 0 | H26: =INDEX(Monthly!$C$76:$BJ$76,($R$2-1)*12+1) -> 60000 | I26: =INDEX(Monthly!$C$76:$BJ$76,($R$2-1)*12+2) -> 0 | J26: =INDEX(Monthly!$C$76:$BJ$76,($R$2-1)*12+3) -> 0 | K26: =INDEX(Monthly!$C$76:$BJ$76,($R$2-1)*12+4) -> 0 | L26: =INDEX(Monthly!$C$76:$BJ$76,($R$2-1)*12+5) -> 0 | M26: =INDEX(Monthly!$C$76:$BJ$76,($R$2-1)*12+6) -> 0 | N26: =INDEX(Monthly!$C$76:$BJ$76,($R$2-1)*12+7) -> 0 | O26: =INDEX(Monthly!$C$76:$BJ$76,($R$2-1)*12+8) -> 0 | P26: =INDEX(Monthly!$C$76:$BJ$76,($R$2-1)*12+9) -> 0 | Q26: =INDEX(Monthly!$C$76:$BJ$76,($R$2-1)*12+10) -> 0 | R26: =INDEX(Monthly!$C$76:$BJ$76,($R$2-1)*12+11) -> 0 | S26: =INDEX(Monthly!$C$76:$BJ$76,($R$2-1)*12+12) -> 0
A27: Loan drawdown | B27: ='Cash Flow'!B13 -> 80000 | C27: ='Cash Flow'!C13 -> 0 | D27: ='Cash Flow'!D13 -> 0 | E27: ='Cash Flow'!E13 -> 0 | F27: ='Cash Flow'!F13 -> 0 | H27: =INDEX(Monthly!$C$61:$BJ$61,($R$2-1)*12+1) -> 80000 | I27: =INDEX(Monthly!$C$61:$BJ$61,($R$2-1)*12+2) -> 0 | J27: =INDEX(Monthly!$C$61:$BJ$61,($R$2-1)*12+3) -> 0 | K27: =INDEX(Monthly!$C$61:$BJ$61,($R$2-1)*12+4) -> 0 | L27: =INDEX(Monthly!$C$61:$BJ$61,($R$2-1)*12+5) -> 0 | M27: =INDEX(Monthly!$C$61:$BJ$61,($R$2-1)*12+6) -> 0 | N27: =INDEX(Monthly!$C$61:$BJ$61,($R$2-1)*12+7) -> 0 | O27: =INDEX(Monthly!$C$61:$BJ$61,($R$2-1)*12+8) -> 0 | P27: =INDEX(Monthly!$C$61:$BJ$61,($R$2-1)*12+9) -> 0 | Q27: =INDEX(Monthly!$C$61:$BJ$61,($R$2-1)*12+10) -> 0 | R27: =INDEX(Monthly!$C$61:$BJ$61,($R$2-1)*12+11) -> 0 | S27: =INDEX(Monthly!$C$61:$BJ$61,($R$2-1)*12+12) -> 0
A28: Loan repayment | B28: ='Cash Flow'!B14 -> -14666.667 | C28: ='Cash Flow'!C14 -> -16000 | D28: ='Cash Flow'!D14 -> -16000 | E28: ='Cash Flow'!E14 -> -16000 | F28: ='Cash Flow'!F14 -> -16000 | H28: =INDEX(Monthly!$C$62:$BJ$62,($R$2-1)*12+1) -> 0 | I28: =INDEX(Monthly!$C$62:$BJ$62,($R$2-1)*12+2) -> -1333.3333 | J28: =INDEX(Monthly!$C$62:$BJ$62,($R$2-1)*12+3) -> -1333.3333 | K28: =INDEX(Monthly!$C$62:$BJ$62,($R$2-1)*12+4) -> -1333.3333 | L28: =INDEX(Monthly!$C$62:$BJ$62,($R$2-1)*12+5) -> -1333.3333 | M28: =INDEX(Monthly!$C$62:$BJ$62,($R$2-1)*12+6) -> -1333.3333 | N28: =INDEX(Monthly!$C$62:$BJ$62,($R$2-1)*12+7) -> -1333.3333 | O28: =INDEX(Monthly!$C$62:$BJ$62,($R$2-1)*12+8) -> -1333.3333 | P28: =INDEX(Monthly!$C$62:$BJ$62,($R$2-1)*12+9) -> -1333.3333 | Q28: =INDEX(Monthly!$C$62:$BJ$62,($R$2-1)*12+10) -> -1333.3333 | R28: =INDEX(Monthly!$C$62:$BJ$62,($R$2-1)*12+11) -> -1333.3333 | S28: =INDEX(Monthly!$C$62:$BJ$62,($R$2-1)*12+12) -> -1333.3333
A29: Financing cash flow | B29: ='Cash Flow'!B15 -> 125333.33 | C29: ='Cash Flow'!C15 -> -16000 | D29: ='Cash Flow'!D15 -> -16000 | E29: ='Cash Flow'!E15 -> -16000 | F29: ='Cash Flow'!F15 -> -16000 | H29: =INDEX(Monthly!$C$77:$BJ$77,($R$2-1)*12+1) -> 140000 | I29: =INDEX(Monthly!$C$77:$BJ$77,($R$2-1)*12+2) -> -1333.3333 | J29: =INDEX(Monthly!$C$77:$BJ$77,($R$2-1)*12+3) -> -1333.3333 | K29: =INDEX(Monthly!$C$77:$BJ$77,($R$2-1)*12+4) -> -1333.3333 | L29: =INDEX(Monthly!$C$77:$BJ$77,($R$2-1)*12+5) -> -1333.3333 | M29: =INDEX(Monthly!$C$77:$BJ$77,($R$2-1)*12+6) -> -1333.3333 | N29: =INDEX(Monthly!$C$77:$BJ$77,($R$2-1)*12+7) -> -1333.3333 | O29: =INDEX(Monthly!$C$77:$BJ$77,($R$2-1)*12+8) -> -1333.3333 | P29: =INDEX(Monthly!$C$77:$BJ$77,($R$2-1)*12+9) -> -1333.3333 | Q29: =INDEX(Monthly!$C$77:$BJ$77,($R$2-1)*12+10) -> -1333.3333 | R29: =INDEX(Monthly!$C$77:$BJ$77,($R$2-1)*12+11) -> -1333.3333 | S29: =INDEX(Monthly!$C$77:$BJ$77,($R$2-1)*12+12) -> -1333.3333
A30: Net change in cash | B30: ='Cash Flow'!B16 -> 126250.62 | C30: ='Cash Flow'!C16 -> 120047.06 | D30: ='Cash Flow'!D16 -> 153063.52 | E30: ='Cash Flow'!E16 -> 190221.66 | F30: ='Cash Flow'!F16 -> 232187.19 | H30: =INDEX(Monthly!$C$78:$BJ$78,($R$2-1)*12+1) -> 35320.959 | I30: =INDEX(Monthly!$C$78:$BJ$78,($R$2-1)*12+2) -> 2659.9566 | J30: =INDEX(Monthly!$C$78:$BJ$78,($R$2-1)*12+3) -> 5922.6078 | K30: =INDEX(Monthly!$C$78:$BJ$78,($R$2-1)*12+4) -> 6870.6517 | L30: =INDEX(Monthly!$C$78:$BJ$78,($R$2-1)*12+5) -> 6878.1128 | M30: =INDEX(Monthly!$C$78:$BJ$78,($R$2-1)*12+6) -> 6885.574 | N30: =INDEX(Monthly!$C$78:$BJ$78,($R$2-1)*12+7) -> 6893.0351 | O30: =INDEX(Monthly!$C$78:$BJ$78,($R$2-1)*12+8) -> 6900.4962 | P30: =INDEX(Monthly!$C$78:$BJ$78,($R$2-1)*12+9) -> 6907.9573 | Q30: =INDEX(Monthly!$C$78:$BJ$78,($R$2-1)*12+10) -> 6915.4184 | R30: =INDEX(Monthly!$C$78:$BJ$78,($R$2-1)*12+11) -> 15314.7 | S30: =INDEX(Monthly!$C$78:$BJ$78,($R$2-1)*12+12) -> 18781.151
A31: Closing cash | B31: ='Cash Flow'!B18 -> 126250.62 | C31: ='Cash Flow'!C18 -> 246297.68 | D31: ='Cash Flow'!D18 -> 399361.2 | E31: ='Cash Flow'!E18 -> 589582.86 | F31: ='Cash Flow'!F18 -> 821770.05 | H31: =INDEX(Monthly!$C$80:$BJ$80,($R$2-1)*12+1) -> 35320.959 | I31: =INDEX(Monthly!$C$80:$BJ$80,($R$2-1)*12+2) -> 37980.916 | J31: =INDEX(Monthly!$C$80:$BJ$80,($R$2-1)*12+3) -> 43903.523 | K31: =INDEX(Monthly!$C$80:$BJ$80,($R$2-1)*12+4) -> 50774.175 | L31: =INDEX(Monthly!$C$80:$BJ$80,($R$2-1)*12+5) -> 57652.288 | M31: =INDEX(Monthly!$C$80:$BJ$80,($R$2-1)*12+6) -> 64537.862 | N31: =INDEX(Monthly!$C$80:$BJ$80,($R$2-1)*12+7) -> 71430.897 | O31: =INDEX(Monthly!$C$80:$BJ$80,($R$2-1)*12+8) -> 78331.393 | P31: =INDEX(Monthly!$C$80:$BJ$80,($R$2-1)*12+9) -> 85239.35 | Q31: =INDEX(Monthly!$C$80:$BJ$80,($R$2-1)*12+10) -> 92154.769 | R31: =INDEX(Monthly!$C$80:$BJ$80,($R$2-1)*12+11) -> 107469.47 | S31: =INDEX(Monthly!$C$80:$BJ$80,($R$2-1)*12+12) -> 126250.62
A39: Balance sheet at year end ($'000) | H39: ="Balance sheet at month end ($'000) — Year "&$R$2 -> Balance sheet at month end ($'000) — Year 1
B40: 1 | C40: 2 | D40: 3 | E40: 4 | F40: 5 | H40: =INDEX(Monthly!$C$4:$BJ$4,($R$2-1)*12+1) -> 1 | I40: =INDEX(Monthly!$C$4:$BJ$4,($R$2-1)*12+2) -> 2 | J40: =INDEX(Monthly!$C$4:$BJ$4,($R$2-1)*12+3) -> 3 | K40: =INDEX(Monthly!$C$4:$BJ$4,($R$2-1)*12+4) -> 4 | L40: =INDEX(Monthly!$C$4:$BJ$4,($R$2-1)*12+5) -> 5 | M40: =INDEX(Monthly!$C$4:$BJ$4,($R$2-1)*12+6) -> 6 | N40: =INDEX(Monthly!$C$4:$BJ$4,($R$2-1)*12+7) -> 7 | O40: =INDEX(Monthly!$C$4:$BJ$4,($R$2-1)*12+8) -> 8 | P40: =INDEX(Monthly!$C$4:$BJ$4,($R$2-1)*12+9) -> 9 | Q40: =INDEX(Monthly!$C$4:$BJ$4,($R$2-1)*12+10) -> 10 | R40: =INDEX(Monthly!$C$4:$BJ$4,($R$2-1)*12+11) -> 11 | S40: =INDEX(Monthly!$C$4:$BJ$4,($R$2-1)*12+12) -> 12
A41: Cash | B41: ='Balance Sheet'!B5 -> 126250.62 | C41: ='Balance Sheet'!C5 -> 246297.68 | D41: ='Balance Sheet'!D5 -> 399361.2 | E41: ='Balance Sheet'!E5 -> 589582.86 | F41: ='Balance Sheet'!F5 -> 821770.05 | H41: =INDEX(Monthly!$C$80:$BJ$80,($R$2-1)*12+1) -> 35320.959 | I41: =INDEX(Monthly!$C$80:$BJ$80,($R$2-1)*12+2) -> 37980.916 | J41: =INDEX(Monthly!$C$80:$BJ$80,($R$2-1)*12+3) -> 43903.523 | K41: =INDEX(Monthly!$C$80:$BJ$80,($R$2-1)*12+4) -> 50774.175 | L41: =INDEX(Monthly!$C$80:$BJ$80,($R$2-1)*12+5) -> 57652.288 | M41: =INDEX(Monthly!$C$80:$BJ$80,($R$2-1)*12+6) -> 64537.862 | N41: =INDEX(Monthly!$C$80:$BJ$80,($R$2-1)*12+7) -> 71430.897 | O41: =INDEX(Monthly!$C$80:$BJ$80,($R$2-1)*12+8) -> 78331.393 | P41: =INDEX(Monthly!$C$80:$BJ$80,($R$2-1)*12+9) -> 85239.35 | Q41: =INDEX(Monthly!$C$80:$BJ$80,($R$2-1)*12+10) -> 92154.769 | R41: =INDEX(Monthly!$C$80:$BJ$80,($R$2-1)*12+11) -> 107469.47 | S41: =INDEX(Monthly!$C$80:$BJ$80,($R$2-1)*12+12) -> 126250.62
A42: Accounts receivable | B42: ='Balance Sheet'!B6 -> 45676.8 | C42: ='Balance Sheet'!C6 -> 49499.724 | D42: ='Balance Sheet'!D6 -> 53715.392 | E42: ='Balance Sheet'!E6 -> 58372.29 | F42: ='Balance Sheet'!F6 -> 63525.625 | H42: =INDEX(Monthly!$C$66:$BJ$66,($R$2-1)*12+1) -> 34794.24 | I42: =INDEX(Monthly!$C$66:$BJ$66,($R$2-1)*12+2) -> 36791.04 | J42: =INDEX(Monthly!$C$66:$BJ$66,($R$2-1)*12+3) -> 38787.84 | K42: =INDEX(Monthly!$C$66:$BJ$66,($R$2-1)*12+4) -> 38787.84 | L42: =INDEX(Monthly!$C$66:$BJ$66,($R$2-1)*12+5) -> 38787.84 | M42: =INDEX(Monthly!$C$66:$BJ$66,($R$2-1)*12+6) -> 38787.84 | N42: =INDEX(Monthly!$C$66:$BJ$66,($R$2-1)*12+7) -> 38787.84 | O42: =INDEX(Monthly!$C$66:$BJ$66,($R$2-1)*12+8) -> 38787.84 | P42: =INDEX(Monthly!$C$66:$BJ$66,($R$2-1)*12+9) -> 38787.84 | Q42: =INDEX(Monthly!$C$66:$BJ$66,($R$2-1)*12+10) -> 38787.84 | R42: =INDEX(Monthly!$C$66:$BJ$66,($R$2-1)*12+11) -> 45676.8 | S42: =INDEX(Monthly!$C$66:$BJ$66,($R$2-1)*12+12) -> 45676.8
A43: Inventory | B43: ='Balance Sheet'!B7 -> 4796.5303 | C43: ='Balance Sheet'!C7 -> 5215.3191 | D43: ='Balance Sheet'!D7 -> 5679.0702 | E43: ='Balance Sheet'!E7 -> 6193.5106 | F43: ='Balance Sheet'!F7 -> 6765.175 | H43: =INDEX(Monthly!$C$67:$BJ$67,($R$2-1)*12+1) -> 3688.0494 | I43: =INDEX(Monthly!$C$67:$BJ$67,($R$2-1)*12+2) -> 3899.2928 | J43: =INDEX(Monthly!$C$67:$BJ$67,($R$2-1)*12+3) -> 4110.5362 | K43: =INDEX(Monthly!$C$67:$BJ$67,($R$2-1)*12+4) -> 4110.5362 | L43: =INDEX(Monthly!$C$67:$BJ$67,($R$2-1)*12+5) -> 4110.5362 | M43: =INDEX(Monthly!$C$67:$BJ$67,($R$2-1)*12+6) -> 4110.5362 | N43: =INDEX(Monthly!$C$67:$BJ$67,($R$2-1)*12+7) -> 4110.5362 | O43: =INDEX(Monthly!$C$67:$BJ$67,($R$2-1)*12+8) -> 4110.5362 | P43: =INDEX(Monthly!$C$67:$BJ$67,($R$2-1)*12+9) -> 4110.5362 | Q43: =INDEX(Monthly!$C$67:$BJ$67,($R$2-1)*12+10) -> 4110.5362 | R43: =INDEX(Monthly!$C$67:$BJ$67,($R$2-1)*12+11) -> 4796.5303 | S43: =INDEX(Monthly!$C$67:$BJ$67,($R$2-1)*12+12) -> 4796.5303
A44: Net fixed assets | B44: ='Balance Sheet'!B8 -> 77142.857 | C44: ='Balance Sheet'!C8 -> 77202.381 | D44: ='Balance Sheet'!D8 -> 75261.905 | E44: ='Balance Sheet'!E8 -> 71321.429 | F44: ='Balance Sheet'!F8 -> 65380.952 | H44: =INDEX(Monthly!$C$57:$BJ$57,($R$2-1)*12+1) -> 88928.571 | I44: =INDEX(Monthly!$C$57:$BJ$57,($R$2-1)*12+2) -> 87857.143 | J44: =INDEX(Monthly!$C$57:$BJ$57,($R$2-1)*12+3) -> 86785.714 | K44: =INDEX(Monthly!$C$57:$BJ$57,($R$2-1)*12+4) -> 85714.286 | L44: =INDEX(Monthly!$C$57:$BJ$57,($R$2-1)*12+5) -> 84642.857 | M44: =INDEX(Monthly!$C$57:$BJ$57,($R$2-1)*12+6) -> 83571.429 | N44: =INDEX(Monthly!$C$57:$BJ$57,($R$2-1)*12+7) -> 82500 | O44: =INDEX(Monthly!$C$57:$BJ$57,($R$2-1)*12+8) -> 81428.571 | P44: =INDEX(Monthly!$C$57:$BJ$57,($R$2-1)*12+9) -> 80357.143 | Q44: =INDEX(Monthly!$C$57:$BJ$57,($R$2-1)*12+10) -> 79285.714 | R44: =INDEX(Monthly!$C$57:$BJ$57,($R$2-1)*12+11) -> 78214.286 | S44: =INDEX(Monthly!$C$57:$BJ$57,($R$2-1)*12+12) -> 77142.857
A45: Total assets | B45: ='Balance Sheet'!B9 -> 253866.81 | C45: ='Balance Sheet'!C9 -> 378215.11 | D45: ='Balance Sheet'!D9 -> 534017.57 | E45: ='Balance Sheet'!E9 -> 725470.09 | F45: ='Balance Sheet'!F9 -> 957441.8 | H45: =INDEX(Monthly!$C$94:$BJ$94,($R$2-1)*12+1) -> 162731.82 | I45: =INDEX(Monthly!$C$94:$BJ$94,($R$2-1)*12+2) -> 166528.39 | J45: =INDEX(Monthly!$C$94:$BJ$94,($R$2-1)*12+3) -> 173587.61 | K45: =INDEX(Monthly!$C$94:$BJ$94,($R$2-1)*12+4) -> 179386.84 | L45: =INDEX(Monthly!$C$94:$BJ$94,($R$2-1)*12+5) -> 185193.52 | M45: =INDEX(Monthly!$C$94:$BJ$94,($R$2-1)*12+6) -> 191007.67 | N45: =INDEX(Monthly!$C$94:$BJ$94,($R$2-1)*12+7) -> 196829.27 | O45: =INDEX(Monthly!$C$94:$BJ$94,($R$2-1)*12+8) -> 202658.34 | P45: =INDEX(Monthly!$C$94:$BJ$94,($R$2-1)*12+9) -> 208494.87 | Q45: =INDEX(Monthly!$C$94:$BJ$94,($R$2-1)*12+10) -> 214338.86 | R45: =INDEX(Monthly!$C$94:$BJ$94,($R$2-1)*12+11) -> 236157.09 | S45: =INDEX(Monthly!$C$94:$BJ$94,($R$2-1)*12+12) -> 253866.81
A46: Accounts payable | B46: ='Balance Sheet'!B10 -> 28779.182 | C46: ='Balance Sheet'!C10 -> 31291.915 | D46: ='Balance Sheet'!D10 -> 34074.421 | E46: ='Balance Sheet'!E10 -> 37161.063 | F46: ='Balance Sheet'!F10 -> 40591.05 | H46: =INDEX(Monthly!$C$68:$BJ$68,($R$2-1)*12+1) -> 22128.296 | I46: =INDEX(Monthly!$C$68:$BJ$68,($R$2-1)*12+2) -> 23395.757 | J46: =INDEX(Monthly!$C$68:$BJ$68,($R$2-1)*12+3) -> 24663.217 | K46: =INDEX(Monthly!$C$68:$BJ$68,($R$2-1)*12+4) -> 24663.217 | L46: =INDEX(Monthly!$C$68:$BJ$68,($R$2-1)*12+5) -> 24663.217 | M46: =INDEX(Monthly!$C$68:$BJ$68,($R$2-1)*12+6) -> 24663.217 | N46: =INDEX(Monthly!$C$68:$BJ$68,($R$2-1)*12+7) -> 24663.217 | O46: =INDEX(Monthly!$C$68:$BJ$68,($R$2-1)*12+8) -> 24663.217 | P46: =INDEX(Monthly!$C$68:$BJ$68,($R$2-1)*12+9) -> 24663.217 | Q46: =INDEX(Monthly!$C$68:$BJ$68,($R$2-1)*12+10) -> 24663.217 | R46: =INDEX(Monthly!$C$68:$BJ$68,($R$2-1)*12+11) -> 28779.182 | S46: =INDEX(Monthly!$C$68:$BJ$68,($R$2-1)*12+12) -> 28779.182
A47: Loan | B47: ='Balance Sheet'!B11 -> 65333.333 | C47: ='Balance Sheet'!C11 -> 49333.333 | D47: ='Balance Sheet'!D11 -> 33333.333 | E47: ='Balance Sheet'!E11 -> 17333.333 | F47: ='Balance Sheet'!F11 -> 1333.3333 | H47: =INDEX(Monthly!$C$63:$BJ$63,($R$2-1)*12+1) -> 80000 | I47: =INDEX(Monthly!$C$63:$BJ$63,($R$2-1)*12+2) -> 78666.667 | J47: =INDEX(Monthly!$C$63:$BJ$63,($R$2-1)*12+3) -> 77333.333 | K47: =INDEX(Monthly!$C$63:$BJ$63,($R$2-1)*12+4) -> 76000 | L47: =INDEX(Monthly!$C$63:$BJ$63,($R$2-1)*12+5) -> 74666.667 | M47: =INDEX(Monthly!$C$63:$BJ$63,($R$2-1)*12+6) -> 73333.333 | N47: =INDEX(Monthly!$C$63:$BJ$63,($R$2-1)*12+7) -> 72000 | O47: =INDEX(Monthly!$C$63:$BJ$63,($R$2-1)*12+8) -> 70666.667 | P47: =INDEX(Monthly!$C$63:$BJ$63,($R$2-1)*12+9) -> 69333.333 | Q47: =INDEX(Monthly!$C$63:$BJ$63,($R$2-1)*12+10) -> 68000 | R47: =INDEX(Monthly!$C$63:$BJ$63,($R$2-1)*12+11) -> 66666.667 | S47: =INDEX(Monthly!$C$63:$BJ$63,($R$2-1)*12+12) -> 65333.333
A48: Total liabilities | B48: ='Balance Sheet'!B12 -> 94112.515 | C48: ='Balance Sheet'!C12 -> 80625.248 | D48: ='Balance Sheet'!D12 -> 67407.755 | E48: ='Balance Sheet'!E12 -> 54494.397 | F48: ='Balance Sheet'!F12 -> 41924.384 | H48: =INDEX(Monthly!$C$95:$BJ$95,($R$2-1)*12+1) -> 102128.3 | I48: =INDEX(Monthly!$C$95:$BJ$95,($R$2-1)*12+2) -> 102062.42 | J48: =INDEX(Monthly!$C$95:$BJ$95,($R$2-1)*12+3) -> 101996.55 | K48: =INDEX(Monthly!$C$95:$BJ$95,($R$2-1)*12+4) -> 100663.22 | L48: =INDEX(Monthly!$C$95:$BJ$95,($R$2-1)*12+5) -> 99329.884 | M48: =INDEX(Monthly!$C$95:$BJ$95,($R$2-1)*12+6) -> 97996.551 | N48: =INDEX(Monthly!$C$95:$BJ$95,($R$2-1)*12+7) -> 96663.217 | O48: =INDEX(Monthly!$C$95:$BJ$95,($R$2-1)*12+8) -> 95329.884 | P48: =INDEX(Monthly!$C$95:$BJ$95,($R$2-1)*12+9) -> 93996.551 | Q48: =INDEX(Monthly!$C$95:$BJ$95,($R$2-1)*12+10) -> 92663.217 | R48: =INDEX(Monthly!$C$95:$BJ$95,($R$2-1)*12+11) -> 95445.848 | S48: =INDEX(Monthly!$C$95:$BJ$95,($R$2-1)*12+12) -> 94112.515
A49: Paid-in capital | B49: ='Balance Sheet'!B13 -> 60000 | C49: ='Balance Sheet'!C13 -> 60000 | D49: ='Balance Sheet'!D13 -> 60000 | E49: ='Balance Sheet'!E13 -> 60000 | F49: ='Balance Sheet'!F13 -> 60000 | H49: =INDEX(Monthly!$C$92:$BJ$92,($R$2-1)*12+1) -> 60000 | I49: =INDEX(Monthly!$C$92:$BJ$92,($R$2-1)*12+2) -> 60000 | J49: =INDEX(Monthly!$C$92:$BJ$92,($R$2-1)*12+3) -> 60000 | K49: =INDEX(Monthly!$C$92:$BJ$92,($R$2-1)*12+4) -> 60000 | L49: =INDEX(Monthly!$C$92:$BJ$92,($R$2-1)*12+5) -> 60000 | M49: =INDEX(Monthly!$C$92:$BJ$92,($R$2-1)*12+6) -> 60000 | N49: =INDEX(Monthly!$C$92:$BJ$92,($R$2-1)*12+7) -> 60000 | O49: =INDEX(Monthly!$C$92:$BJ$92,($R$2-1)*12+8) -> 60000 | P49: =INDEX(Monthly!$C$92:$BJ$92,($R$2-1)*12+9) -> 60000 | Q49: =INDEX(Monthly!$C$92:$BJ$92,($R$2-1)*12+10) -> 60000 | R49: =INDEX(Monthly!$C$92:$BJ$92,($R$2-1)*12+11) -> 60000 | S49: =INDEX(Monthly!$C$92:$BJ$92,($R$2-1)*12+12) -> 60000
A50: Retained earnings | B50: ='Balance Sheet'!B14 -> 99754.292 | C50: ='Balance Sheet'!C14 -> 237589.86 | D50: ='Balance Sheet'!D14 -> 406609.81 | E50: ='Balance Sheet'!E14 -> 610975.69 | F50: ='Balance Sheet'!F14 -> 855517.42 | H50: =INDEX(Monthly!$C$93:$BJ$93,($R$2-1)*12+1) -> 603.52364 | I50: =INDEX(Monthly!$C$93:$BJ$93,($R$2-1)*12+2) -> 4465.9679 | J50: =INDEX(Monthly!$C$93:$BJ$93,($R$2-1)*12+3) -> 11591.063 | K50: =INDEX(Monthly!$C$93:$BJ$93,($R$2-1)*12+4) -> 18723.62 | L50: =INDEX(Monthly!$C$93:$BJ$93,($R$2-1)*12+5) -> 25863.637 | M50: =INDEX(Monthly!$C$93:$BJ$93,($R$2-1)*12+6) -> 33011.116 | N50: =INDEX(Monthly!$C$93:$BJ$93,($R$2-1)*12+7) -> 40166.056 | O50: =INDEX(Monthly!$C$93:$BJ$93,($R$2-1)*12+8) -> 47328.457 | P50: =INDEX(Monthly!$C$93:$BJ$93,($R$2-1)*12+9) -> 54498.319 | Q50: =INDEX(Monthly!$C$93:$BJ$93,($R$2-1)*12+10) -> 61675.642 | R50: =INDEX(Monthly!$C$93:$BJ$93,($R$2-1)*12+11) -> 80711.237 | S50: =INDEX(Monthly!$C$93:$BJ$93,($R$2-1)*12+12) -> 99754.292
...

Sheet Scenarios
A1: Scenarios — Low / Base / High | H1: =HYPERLINK("#'Cover'!A1","◂ Contents") -> ◂ Contents
A2: All three scenarios calculated side by side, live: change any input and every column updates. Active = the scenario chosen on the Dashboard.
A5: Key drivers
A6: Driver | B6: Low | C6: Base | D6: High | E6: Active
A7: Customers per day at full traffic (#) | B7: =Inputs!$B$7 -> 300 | C7: =Inputs!$C$7 -> 320 | D7: =Inputs!$D$7 -> 340 | E7: =Inputs!$E$7 -> 320
A8: Average ticket per customer (year 1) ($) | B8: =Inputs!$B$11 -> 11 | C8: =Inputs!$C$11 -> 11.5 | D8: =Inputs!$D$11 -> 12 | E8: =Inputs!$E$11 -> 11.5
A9: Wholesale accounts at full ramp (year 1) (#) | B9: =Inputs!$B$17 -> 13 | C9: =Inputs!$C$17 -> 16 | D9: =Inputs!$D$17 -> 19 | E9: =Inputs!$E$17 -> 16
A10: Order value per account per week (year 1) ($) | B10: =Inputs!$B$19 -> 500 | C10: =Inputs!$C$19 -> 540 | D10: =Inputs!$D$19 -> 580 | E10: =Inputs!$E$19 -> 540
A11: Retail production baked but not sold (waste) (%) | B11: =Inputs!$B$26 -> 0.11 | C11: =Inputs!$C$26 -> 0.09 | D11: =Inputs!$D$26 -> 0.07 | E11: =Inputs!$E$26 -> 0.09
A12: Rent per month ($) | B12: =Inputs!$B$30 -> 12000 | C12: =Inputs!$C$30 -> 12000 | D12: =Inputs!$D$30 -> 12000 | E12: =Inputs!$E$30 -> 12000
A13: Fit-out & equipment: ovens, mixers, cases ($) | B13: =Inputs!$B$38 -> 90000 | C13: =Inputs!$C$38 -> 90000 | D13: =Inputs!$D$38 -> 90000 | E13: =Inputs!$E$38 -> 90000
A14: Equity raised at start ($) | B14: =Inputs!$B$58 -> 60000 | C14: =Inputs!$C$58 -> 60000 | D14: =Inputs!$D$58 -> 60000 | E14: =Inputs!$E$58 -> 60000
A16: Results by scenario ($'000)
A17: Output | B17: Low | C17: Base | D17: High | E17: Active
A18: Revenue — final year | B18: =F31 -> 1657475.5 | C18: =F32 -> 2250134.1 | D18: =F33 -> 3023920.1 | E18: ='P&L'!F5 -> 2250134.1
A19: Revenue — whole plan | B19: =SUM(B31:F31) -> 7504388.9 | C19: =SUM(B32:F32) -> 9514840.3 | D19: =SUM(B33:F33) -> 11959331 | E19: =SUM('P&L'!$B$5:$F$5) -> 9514840.3
A20: EBITDA — final year | B20: =F37 -> -71930.045 | C20: =F38 -> 330280.3 | D20: =F39 -> 874226.08 | E20: ='P&L'!F18 -> 330280.3
A21: EBITDA margin — final year | B21: =IF(B18=0,0,B20/B18) -> -0.04339735 | C21: =IF(C18=0,0,C20/C18) -> 0.1467825 | D21: =IF(D18=0,0,D20/D18) -> 0.28910356 | E21: =IF(E18=0,0,E20/E18) -> 0.1467825
A22: Net income — final year | B22: =F43 -> -92663.854 | C22: =F44 -> 244541.73 | D22: =F45 -> 674258.89 | E22: ='P&L'!F25 -> 244541.73
A23: Net income — whole plan | B23: =SUM(B43:F43) -> -333349.89 | C23: =SUM(B44:F44) -> 855517.42 | D23: =SUM(B45:F45) -> 2264810.6 | E23: =SUM('P&L'!$B$25:$F$25) -> 855517.42
A24: Cash at the end of the plan | B24: =F49 -> -357950.96 | C24: =F50 -> 821770.05 | D24: =F51 -> 2218597.8 | E24: ='Balance Sheet'!F5 -> 821770.05
A25: Lowest cash balance | B25: =MIN('Scenario calc'!$C$82:$BJ$82) -> -361898 | C25: =MIN('Scenario calc'!$C$193:$BJ$193) -> 35320.959 | D25: =MIN('Scenario calc'!$C$304:$BJ$304) -> 45608.962 | E25: ='Break-even'!B18 -> 35320.959
A26: Lowest cash point (month #) | B26: =MATCH(MIN('Scenario calc'!$C$82:$BJ$82),'Scenario calc'!$C$82:$BJ$82,0) -> 58 | C26: =MATCH(MIN('Scenario calc'!$C$193:$BJ$193),'Scenario calc'!$C$193:$BJ$193,0) -> 1 | D26: =MATCH(MIN('Scenario calc'!$C$304:$BJ$304),'Scenario calc'!$C$304:$BJ$304,0) -> 1 | E26: ='Break-even'!B6 -> 1
A27: Funding required (incl. cash buffer) | B27: =SUMPRODUCT(--('Scenario calc'!$C$6:$BJ$6<=B26),'Scenario calc'!$C$55:$BJ$55)-SUMPRODUCT(--('Scenario calc'!$C$6:$BJ$6<=B26),'Scenario calc'!$C$76:$BJ$76)-SUMPRODUCT(--('Scenario calc'!$C$6:$BJ$6<=B26),'Scenario calc'!$C$64:$BJ$64)+Inputs!$B$73 -> 734898 | C27: =SUMPRODUCT(--('Scenario calc'!$C$117:$BJ$117<=C26),'Scenario calc'!$C$166:$BJ$166)-SUMPRODUCT(--('Scenario calc'!$C$117:$BJ$117<=C26),'Scenario calc'!$C$187:$BJ$187)-SUMPRODUCT(--('Scenario calc'!$C$117:$BJ$117<=C26),'Scenario calc'!$C$175:$BJ$175)+Inputs!$C$73 -> 337679.04 | D27: =SUMPRODUCT(--('Scenario calc'!$C$228:$BJ$228<=D26),'Scenario calc'!$C$277:$BJ$277)-SUMPRODUCT(--('Scenario calc'!$C$228:$BJ$228<=D26),'Scenario calc'!$C$298:$BJ$298)-SUMPRODUCT(--('Scenario calc'!$C$228:$BJ$228<=D26),'Scenario calc'!$C$286:$BJ$286)+Inputs!$D$73 -> 327391.04 | E27: ='Break-even'!B12 -> 337679.04
A29: Revenue by year ($'000)
A30: Scenario | B30: 1 | C30: 2 | D30: 3 | E30: 4 | F30: 5
A31: Low | B31: =SUMIF('Scenario calc'!$C$7:$BJ$7,B$30,'Scenario calc'!$C$24:$BJ$24) -> 1333410 | C31: =SUMIF('Scenario calc'!$C$7:$BJ$7,C$30,'Scenario calc'!$C$24:$BJ$24) -> 1433034.7 | D31: =SUMIF('Scenario calc'!$C$7:$BJ$7,D$30,'Scenario calc'!$C$24:$BJ$24) -> 1502897.5 | E31: =SUMIF('Scenario calc'!$C$7:$BJ$7,E$30,'Scenario calc'!$C$24:$BJ$24) -> 1577571.2 | F31: =SUMIF('Scenario calc'!$C$7:$BJ$7,F$30,'Scenario calc'!$C$24:$BJ$24) -> 1657475.5
A32: Base | B32: =SUMIF('Scenario calc'!$C$118:$BJ$118,B$30,'Scenario calc'!$C$135:$BJ$135) -> 1577472 | C32: =SUMIF('Scenario calc'!$C$118:$BJ$118,C$30,'Scenario calc'!$C$135:$BJ$135) -> 1736372.4 | D32: =SUMIF('Scenario calc'!$C$118:$BJ$118,D$30,'Scenario calc'!$C$135:$BJ$135) -> 1890162.9 | E32: =SUMIF('Scenario calc'!$C$118:$BJ$118,E$30,'Scenario calc'!$C$135:$BJ$135) -> 2060699 | F32: =SUMIF('Scenario calc'!$C$118:$BJ$118,F$30,'Scenario calc'!$C$135:$BJ$135) -> 2250134.1
A33: High | B33: =SUMIF('Scenario calc'!$C$229:$BJ$229,B$30,'Scenario calc'!$C$246:$BJ$246) -> 1838308.3 | C33: =SUMIF('Scenario calc'!$C$229:$BJ$229,C$30,'Scenario calc'!$C$246:$BJ$246) -> 2081387.8 | D33: =SUMIF('Scenario calc'!$C$229:$BJ$229,D$30,'Scenario calc'!$C$246:$BJ$246) -> 2351961.9 | E33: =SUMIF('Scenario calc'!$C$229:$BJ$229,E$30,'Scenario calc'!$C$246:$BJ$246) -> 2663752.4 | F33: =SUMIF('Scenario calc'!$C$229:$BJ$229,F$30,'Scenario calc'!$C$246:$BJ$246) -> 3023920.1
A35: EBITDA by year ($'000)
A36: Scenario | B36: 1 | C36: 2 | D36: 3 | E36: 4 | F36: 5
A37: Low | B37: =SUMIF('Scenario calc'!$C$7:$BJ$7,B$36,'Scenario calc'!$C$43:$BJ$43) -> -38197.939 | C37: =SUMIF('Scenario calc'!$C$7:$BJ$7,C$36,'Scenario calc'!$C$43:$BJ$43) -> -28572.905 | D37: =SUMIF('Scenario calc'!$C$7:$BJ$7,D$36,'Scenario calc'!$C$43:$BJ$43) -> -41038.323 | E37: =SUMIF('Scenario calc'!$C$7:$BJ$7,E$36,'Scenario calc'!$C$43:$BJ$43) -> -55429.69 | F37: =SUMIF('Scenario calc'!$C$7:$BJ$7,F$36,'Scenario calc'!$C$43:$BJ$43) -> -71930.045
A38: Base | B38: =SUMIF('Scenario calc'!$C$118:$BJ$118,B$36,'Scenario calc'!$C$154:$BJ$154) -> 145357.01 | C38: =SUMIF('Scenario calc'!$C$118:$BJ$118,C$36,'Scenario calc'!$C$154:$BJ$154) -> 193289.21 | D38: =SUMIF('Scenario calc'!$C$118:$BJ$118,D$36,'Scenario calc'!$C$154:$BJ$154) -> 233403.12 | E38: =SUMIF('Scenario calc'!$C$118:$BJ$118,E$36,'Scenario calc'!$C$154:$BJ$154) -> 278784.79 | F38: =SUMIF('Scenario calc'!$C$118:$BJ$118,F$36,'Scenario calc'!$C$154:$BJ$154) -> 330280.3
A39: High | B39: =SUMIF('Scenario calc'!$C$229:$BJ$229,B$36,'Scenario calc'!$C$265:$BJ$265) -> 350866.4 | C39: =SUMIF('Scenario calc'!$C$229:$BJ$229,C$36,'Scenario calc'!$C$265:$BJ$265) -> 455669.07 | D39: =SUMIF('Scenario calc'!$C$229:$BJ$229,D$36,'Scenario calc'!$C$265:$BJ$265) -> 573037.01 | E39: =SUMIF('Scenario calc'!$C$229:$BJ$229,E$36,'Scenario calc'!$C$265:$BJ$265) -> 711231.3 | F39: =SUMIF('Scenario calc'!$C$229:$BJ$229,F$36,'Scenario calc'!$C$265:$BJ$265) -> 874226.08
A41: Net income by year ($'000)
A42: Scenario | B42: 1 | C42: 2 | D42: 3 | E42: 4 | F42: 5
A43: Low | B43: =SUMIF('Scenario calc'!$C$7:$BJ$7,B$42,'Scenario calc'!$C$52:$BJ$52) -> -57283.693 | C43: =SUMIF('Scenario calc'!$C$7:$BJ$7,C$42,'Scenario calc'!$C$52:$BJ$52) -> -47386.715 | D43: =SUMIF('Scenario calc'!$C$7:$BJ$7,D$42,'Scenario calc'!$C$52:$BJ$52) -> -60492.133 | E43: =SUMIF('Scenario calc'!$C$7:$BJ$7,E$42,'Scenario calc'!$C$52:$BJ$52) -> -75523.499 | F43: =SUMIF('Scenario calc'!$C$7:$BJ$7,F$42,'Scenario calc'!$C$52:$BJ$52) -> -92663.854
A44: Base | B44: =SUMIF('Scenario calc'!$C$118:$BJ$118,B$42,'Scenario calc'!$C$163:$BJ$163) -> 99754.292 | C44: =SUMIF('Scenario calc'!$C$118:$BJ$118,C$42,'Scenario calc'!$C$163:$BJ$163) -> 137835.57 | D44: =SUMIF('Scenario calc'!$C$118:$BJ$118,D$42,'Scenario calc'!$C$163:$BJ$163) -> 169019.96 | E44: =SUMIF('Scenario calc'!$C$118:$BJ$118,E$42,'Scenario calc'!$C$163:$BJ$163) -> 204365.88 | F44: =SUMIF('Scenario calc'!$C$118:$BJ$118,F$42,'Scenario calc'!$C$163:$BJ$163) -> 244541.73
A45: High | B45: =SUMIF('Scenario calc'!$C$229:$BJ$229,B$42,'Scenario calc'!$C$274:$BJ$274) -> 262106.71 | C45: =SUMIF('Scenario calc'!$C$229:$BJ$229,C$42,'Scenario calc'!$C$274:$BJ$274) -> 345115.65 | D45: =SUMIF('Scenario calc'!$C$229:$BJ$229,D$42,'Scenario calc'!$C$274:$BJ$274) -> 437330.73 | E45: =SUMIF('Scenario calc'!$C$229:$BJ$229,E$42,'Scenario calc'!$C$274:$BJ$274) -> 545998.61 | F45: =SUMIF('Scenario calc'!$C$229:$BJ$229,F$42,'Scenario calc'!$C$274:$BJ$274) -> 674258.89
A47: Cash at year end by year ($'000)
...

Sheet Break-even
A1: Startup costs, funding need and break-even | H1: =HYPERLINK("#'Cover'!A1","◂ Contents") -> ◂ Contents
A2: Live for the selected scenario. Periods are counted in months from the start of the plan.
A3: Scenario shown | B3: =CHOOSE(Dashboard!$B$4,"Low","Base","High") -> Base
A5: Startup costs & funding need (up to the lowest cash point)
A6: Lowest cash point (month #) | B6: =MATCH(MIN(Monthly!$C$80:$BJ$80),Monthly!$C$80:$BJ$80,0) -> 1
A7: Capital spending up to the lowest cash point | B7: =SUMPRODUCT(--(Monthly!$C$4:$BJ$4<=$B$6),Monthly!$C$53:$BJ$53) -> 90000
A8: Operating cash burn up to the lowest cash point | B8: =-SUMPRODUCT(--(Monthly!$C$4:$BJ$4<=$B$6),Monthly!$C$74:$BJ$74) -> 14679.041 | D8: Losses and working capital before the business funds itself
A9: Loan repayments up to the lowest cash point | B9: =-SUMPRODUCT(--(Monthly!$C$4:$BJ$4<=$B$6),Monthly!$C$62:$BJ$62) -> 0
A10: Total uses of funds | B10: =B7+B8+B9 -> 104679.04
A11: Minimum cash buffer to keep | B11: =Inputs!$E$73 -> 233000 | D11: Input on the Inputs sheet
A12: Funding required (uses + buffer) | B12: =B10+B11 -> 337679.04
A14: Equity raised | B14: =Inputs!$E$58 -> 60000
A15: Loan drawn | B15: =Inputs!$E$59 -> 80000
A16: Total sources of funds | B16: =B14+B15 -> 140000
A17: Funding surplus / (shortfall) | B17: =B16-B12 -> -197679.04 | D17: Negative = raise at least this much more
A18: Lowest cash balance in the plan | B18: =MIN(Monthly!$C$80:$BJ$80) -> 35320.959 | D18: Equals sources minus uses
A20: Break-even timing
A21: First month with positive EBITDA (month #) | B21: =IFERROR(MATCH(1,Monthly!$C$81:$BJ$81,0),"Not within horizon") -> 1
A22: First month with positive net income (month #) | B22: =IFERROR(MATCH(1,Monthly!$C$84:$BJ$84,0),"Not within horizon") -> 1
A23: Cash invested paid back (month #) | B23: =IF(MIN(Monthly!$C$86:$BJ$86)>=0,"No investment to pay back",IFERROR(MATCH(1,Monthly!$C$88:$BJ$88,0),"Not within horizon")) -> 12 | D23: Cumulative operating + investing cash flow back to zero
A25: Annual break-even revenue
A26: Year # | B26: 1 | C26: 2 | D26: 3 | E26: 4 | F26: 5
B27: Year 1 | C27: Year 2 | D27: Year 3 | E27: Year 4 | F27: Year 5
A28: Revenue | B28: =SUMIF(Monthly!$C$5:$BJ$5,B$26,Monthly!$C$22:$BJ$22) -> 1577472 | C28: =SUMIF(Monthly!$C$5:$BJ$5,C$26,Monthly!$C$22:$BJ$22) -> 1736372.4 | D28: =SUMIF(Monthly!$C$5:$BJ$5,D$26,Monthly!$C$22:$BJ$22) -> 1890162.9 | E28: =SUMIF(Monthly!$C$5:$BJ$5,E$26,Monthly!$C$22:$BJ$22) -> 2060699 | F28: =SUMIF(Monthly!$C$5:$BJ$5,F$26,Monthly!$C$22:$BJ$22) -> 2250134.1
A29: Gross profit | B29: =SUMIF(Monthly!$C$5:$BJ$5,B$26,Monthly!$C$29:$BJ$29) -> 1076825.1 | C29: =SUMIF(Monthly!$C$5:$BJ$5,C$26,Monthly!$C$29:$BJ$29) -> 1183311.2 | D29: =SUMIF(Monthly!$C$5:$BJ$5,D$26,Monthly!$C$29:$BJ$29) -> 1285883.7 | E29: =SUMIF(Monthly!$C$5:$BJ$5,E$26,Monthly!$C$29:$BJ$29) -> 1399389 | F29: =SUMIF(Monthly!$C$5:$BJ$5,F$26,Monthly!$C$29:$BJ$29) -> 1525212.7
A30: Gross margin (contribution) | B30: =IF(B28=0,0,B29/B28) -> 0.68262706 | C30: =IF(C28=0,0,C29/C28) -> 0.68148469 | D30: =IF(D28=0,0,D29/D28) -> 0.68030311 | E30: =IF(E28=0,0,E29/E28) -> 0.67908462 | F30: =IF(F28=0,0,F29/F28) -> 0.67783194
A31: Operating expenses (treated as fixed) | B31: =-SUMIF(Monthly!$C$5:$BJ$5,B$26,Monthly!$C$40:$BJ$40) -> 931468.06 | C31: =-SUMIF(Monthly!$C$5:$BJ$5,C$26,Monthly!$C$40:$BJ$40) -> 990021.96 | D31: =-SUMIF(Monthly!$C$5:$BJ$5,D$26,Monthly!$C$40:$BJ$40) -> 1052480.5 | E31: =-SUMIF(Monthly!$C$5:$BJ$5,E$26,Monthly!$C$40:$BJ$40) -> 1120604.2 | F31: =-SUMIF(Monthly!$C$5:$BJ$5,F$26,Monthly!$C$40:$BJ$40) -> 1194932.4
A32: Break-even revenue (EBITDA = 0) | B32: =IF(B30>0,B31/B30,"n/a") -> 1364534.3 | C32: =IF(C30>0,C31/C30,"n/a") -> 1452742.8 | D32: =IF(D30>0,D31/D30,"n/a") -> 1547075.9 | E32: =IF(E30>0,E31/E30,"n/a") -> 1650168.7 | F32: =IF(F30>0,F31/F30,"n/a") -> 1762874.2
A33: Margin of safety (revenue above break-even) | B33: =IF(AND(ISNUMBER(B32),B28>0),(B28-B32)/B28,"n/a") -> 0.13498665 | C33: =IF(AND(ISNUMBER(C32),C28>0),(C28-C32)/C28,"n/a") -> 0.16334605 | D33: =IF(AND(ISNUMBER(D32),D28>0),(D28-D32)/D28,"n/a") -> 0.18151185 | E33: =IF(AND(ISNUMBER(E32),E28>0),(E28-E32)/E28,"n/a") -> 0.19921894 | F33: =IF(AND(ISNUMBER(F32),F28>0),(F28-F32)/F28,"n/a") -> 0.21654704
A35: Simplification: cost of sales is treated as variable and operating expenses as fixed, so break-even revenue = operating expenses ÷ gross margin.

Sheet Valuation
A1: Discounted cash flow valuation | H1: =HYPERLINK("#'Cover'!A1","◂ Contents") -> ◂ Contents
A2: Enterprise value at the start of the plan, before the funding raised in period 1. Year-end discounting.
A3: Scenario shown | B3: =CHOOSE(Dashboard!$B$4,"Low","Base","High") -> Base
A5: Assumptions (active scenario, from the Inputs sheet)
A6: Discount rate (WACC) | B6: =Inputs!$E$76 -> 0.16
A7: Terminal growth rate | B7: =Inputs!$E$77 -> 0.02
A8: Exit multiple (EV ÷ final-year EBITDA) | B8: =Inputs!$E$78 -> 5.5
A9: Tax rate (for the interest tax shield) | B9: =Inputs!$E$70 -> 0.21
A10: Sensitivity step: WACC | B10: =Inputs!$E$79 -> 0.01
A11: Sensitivity step: terminal growth | B11: =Inputs!$E$80 -> 0.005
A13: Free cash flow by year
A14: Year # | B14: 1 | C14: 2 | D14: 3 | E14: 4 | F14: 5
B15: Year 1 | C15: Year 2 | D15: Year 3 | E15: Year 4 | F15: Year 5
A16: EBITDA | B16: =SUMIF(Monthly!$C$5:$BJ$5,B$14,Monthly!$C$41:$BJ$41) -> 145357.01 | C16: =SUMIF(Monthly!$C$5:$BJ$5,C$14,Monthly!$C$41:$BJ$41) -> 193289.21 | D16: =SUMIF(Monthly!$C$5:$BJ$5,D$14,Monthly!$C$41:$BJ$41) -> 233403.12 | E16: =SUMIF(Monthly!$C$5:$BJ$5,E$14,Monthly!$C$41:$BJ$41) -> 278784.79 | F16: =SUMIF(Monthly!$C$5:$BJ$5,F$14,Monthly!$C$41:$BJ$41) -> 330280.3
A17: Unlevered free cash flow | B17: =SUMIF(Monthly!$C$5:$BJ$5,B$14,Monthly!$C$89:$BJ$89) -> 5837.8896 | C17: =SUMIF(Monthly!$C$5:$BJ$5,C$14,Monthly!$C$89:$BJ$89) -> 139897 | D17: =SUMIF(Monthly!$C$5:$BJ$5,D$14,Monthly!$C$89:$BJ$89) -> 171839.05 | E17: =SUMIF(Monthly!$C$5:$BJ$5,E$14,Monthly!$C$89:$BJ$89) -> 207922.79 | F17: =SUMIF(Monthly!$C$5:$BJ$5,F$14,Monthly!$C$89:$BJ$89) -> 248813.92
A18: Discount factor | B18: =1/(1+Inputs!$E$76)^B$14 -> 0.86206897 | C18: =1/(1+Inputs!$E$76)^C$14 -> 0.7431629 | D18: =1/(1+Inputs!$E$76)^D$14 -> 0.64065767 | E18: =1/(1+Inputs!$E$76)^E$14 -> 0.5522911 | F18: =1/(1+Inputs!$E$76)^F$14 -> 0.47611302
A19: Present value of free cash flow | B19: =B17*B18 -> 5032.6634 | C19: =C17*C18 -> 103966.26 | D19: =D17*D18 -> 110090.01 | E19: =E17*E18 -> 114833.91 | F19: =F17*F18 -> 118463.55
A21: Enterprise value
B22: Perpetual growth | C22: Exit multiple
A23: Present value of the plan's free cash flows | B23: =SUM($B$19:$F$19) -> 452386.38 | C23: =B23 -> 452386.38
A24: Final-year free cash flow | final-year EBITDA | B24: =$F$17 -> 248813.92 | C24: =$F$16 -> 330280.3
A25: Terminal value at the end of year 5 | B25: =IF($B$6>$B$7,B24*(1+$B$7)/($B$6-$B$7),0) -> 1812787.2 | C25: =C24*$B$8 -> 1816541.6
A26: Present value of the terminal value | B26: =B25/(1+$B$6)^$F$14 -> 863091.56 | C26: =C25/(1+$B$6)^$F$14 -> 864879.12
A27: Enterprise value | B27: =B23+B26 -> 1315477.9 | C27: =C23+C26 -> 1317265.5
A28: Terminal value share of enterprise value | B28: =IF(B27<>0,B26/B27,0) -> 0.65610493 | C28: =IF(C27<>0,C26/C27,0) -> 0.6565716
A29: Cross-check: implied exit multiple | implied perpetual growth | B29: =IF(C24>0,B25/C24,"n/a") -> 5.4886324 | C29: =IF(C25+B24<>0,(C25*$B$6-B24)/(C25+B24),"n/a") -> 0.020254498
A30: Enterprise value — average of the two methods | B30: =AVERAGE(B27,C27) -> 1316371.7
A32: Sensitivity: enterprise value (perpetual growth) by WACC and terminal growth
A33: WACC ↓ · terminal growth → | B33: =$B$7+(-2)*$B$11 -> 0.01 | C33: =$B$7+(-1)*$B$11 -> 0.015 | D33: =$B$7+(0)*$B$11 -> 0.02 | E33: =$B$7+(1)*$B$11 -> 0.025 | F33: =$B$7+(2)*$B$11 -> 0.03
A34: =$B$6+(-2)*$B$10 -> 0.14 | B34: =IF($A34>B$33,SUMPRODUCT($B$17:$F$17/(1+$A34)^$B$14:$F$14)+$F$17*(1+B$33)/($A34-B$33)/(1+$A34)^$F$14,"n/a") -> 1485074.6 | C34: =IF($A34>C$33,SUMPRODUCT($B$17:$F$17/(1+$A34)^$B$14:$F$14)+$F$17*(1+C$33)/($A34-C$33)/(1+$A34)^$F$14,"n/a") -> 1530403.1 | D34: =IF($A34>D$33,SUMPRODUCT($B$17:$F$17/(1+$A34)^$B$14:$F$14)+$F$17*(1+D$33)/($A34-D$33)/(1+$A34)^$F$14,"n/a") -> 1579509.1 | E34: =IF($A34>E$33,SUMPRODUCT($B$17:$F$17/(1+$A34)^$B$14:$F$14)+$F$17*(1+E$33)/($A34-E$33)/(1+$A34)^$F$14,"n/a") -> 1632885.1 | F34: =IF($A34>F$33,SUMPRODUCT($B$17:$F$17/(1+$A34)^$B$14:$F$14)+$F$17*(1+F$33)/($A34-F$33)/(1+$A34)^$F$14,"n/a") -> 1691113.5
A35: =$B$6+(-1)*$B$10 -> 0.15 | B35: =IF($A35>B$33,SUMPRODUCT($B$17:$F$17/(1+$A35)^$B$14:$F$14)+$F$17*(1+B$33)/($A35-B$33)/(1+$A35)^$F$14,"n/a") -> 1358870.2 | C35: =IF($A35>C$33,SUMPRODUCT($B$17:$F$17/(1+$A35)^$B$14:$F$14)+$F$17*(1+C$33)/($A35-C$33)/(1+$A35)^$F$14,"n/a") -> 1396505.2 | D35: =IF($A35>D$33,SUMPRODUCT($B$17:$F$17/(1+$A35)^$B$14:$F$14)+$F$17*(1+D$33)/($A35-D$33)/(1+$A35)^$F$14,"n/a") -> 1437035.1 | E35: =IF($A35>E$33,SUMPRODUCT($B$17:$F$17/(1+$A35)^$B$14:$F$14)+$F$17*(1+E$33)/($A35-E$33)/(1+$A35)^$F$14,"n/a") -> 1480807.5 | F35: =IF($A35>F$33,SUMPRODUCT($B$17:$F$17/(1+$A35)^$B$14:$F$14)+$F$17*(1+F$33)/($A35-F$33)/(1+$A35)^$F$14,"n/a") -> 1528227.6
A36: =$B$6+(0)*$B$10 -> 0.16 | B36: =IF($A36>B$33,SUMPRODUCT($B$17:$F$17/(1+$A36)^$B$14:$F$14)+$F$17*(1+B$33)/($A36-B$33)/(1+$A36)^$F$14,"n/a") -> 1250040.9 | C36: =IF($A36>C$33,SUMPRODUCT($B$17:$F$17/(1+$A36)^$B$14:$F$14)+$F$17*(1+C$33)/($A36-C$33)/(1+$A36)^$F$14,"n/a") -> 1281631.2 | D36: =IF($A36>D$33,SUMPRODUCT($B$17:$F$17/(1+$A36)^$B$14:$F$14)+$F$17*(1+D$33)/($A36-D$33)/(1+$A36)^$F$14,"n/a") -> 1315477.9 | E36: =IF($A36>E$33,SUMPRODUCT($B$17:$F$17/(1+$A36)^$B$14:$F$14)+$F$17*(1+E$33)/($A36-E$33)/(1+$A36)^$F$14,"n/a") -> 1351831.8 | F36: =IF($A36>F$33,SUMPRODUCT($B$17:$F$17/(1+$A36)^$B$14:$F$14)+$F$17*(1+F$33)/($A36-F$33)/(1+$A36)^$F$14,"n/a") -> 1390982.2
