Workbook

Sheet Cover
B2: Car wash financial model (planning)
B3: 3-year financial model · monthly detail · Low / Base / High scenarios · US dollars · Full plan
B5: Purpose | D5: Revenue and profit plan
B6: Active scenario | D6: =Dashboard!C4&" (change it on the Dashboard, cell B4)" -> Base (change it on the Dashboard, cell B4)
B7: Model checks | D7: =Checks!B25 -> PASS
B8: Prepared | D8: 21 October 2026
B10: Contents
C11: PRESENTATION
B12: 1 | C12: =HYPERLINK("#Dashboard!A1","Dashboard") -> Dashboard | D12: Scenario switch, key numbers, core financials
B13: 2 | C13: =HYPERLINK("#Summary!A1","Summary") -> Summary | D13: Income statement, cash flow and balance sheet — every year and any year by month
B14: 3 | C14: =HYPERLINK("#Scenarios!A1","Scenarios") -> Scenarios | D14: Low / Base / High side by side: drivers, outputs, charts
B15: 4 | C15: =HYPERLINK("#'Break-even'!A1","Break-even") -> Break-even | D15: Startup costs, funding need, break-even timing and revenue
B16: 5 | C16: =HYPERLINK("#Valuation!A1","Valuation") -> Valuation | D16: Free cash flow, DCF (perpetual growth and exit multiple), WACC × growth sensitivity
B17: 6 | C17: =HYPERLINK("#'Sources & Uses'!A1","Sources & Uses") -> Sources & Uses | D17: Funding structure, sources and uses of cash for the first months
B18: 7 | C18: =HYPERLINK("#KPIs!A1","KPIs") -> KPIs | D18: Financial ratios, DuPont analysis, industry metrics
C19: INPUTS
B20: 8 | C20: =HYPERLINK("#Inputs!A1","Inputs") -> Inputs | D20: Every assumption, Low / Base / High, with units and comments
C21: STATEMENTS
B22: 9 | C22: =HYPERLINK("#'P&L'!A1","P&L") -> P&L | D22: Annual profit & loss
B23: 10 | C23: =HYPERLINK("#'Cash Flow'!A1","Cash Flow") -> Cash Flow | D23: Annual cash flow statement
B24: 11 | C24: =HYPERLINK("#'Balance Sheet'!A1","Balance Sheet") -> Balance Sheet | D24: Balance sheet at year end
C25: CALCULATIONS
B26: 12 | C26: =HYPERLINK("#Monthly!A1","Monthly") -> Monthly | D26: Month-by-month engine of the model
B27: 13 | C27: =HYPERLINK("#Headcount!A1","Headcount") -> Headcount | D27: Team and payroll
B28: 14 | C28: =HYPERLINK("#'Scenario calc'!A1","Scenario calc") -> Scenario calc | D28: Low, Base and High calculated side by side for the Scenarios sheet
C29: CONTROL
B30: 15 | C30: =HYPERLINK("#Checks!A1","Checks") -> Checks | D30: Live integrity checks and the overall verdict
B32: How to read this file
C33: 1000 | D33: Input you can change — yellow cell with a blue figure (Inputs sheet and the view switches)
C34: 1000 | D34: Formula — calculated, do not overwrite
C35: 1000 | D35: Link to another sheet
C36: 1000 | D36: Active value the model uses (follows the scenario)

Sheet Dashboard
A1: Dashboard | W1: =HYPERLINK("#'Cover'!A1","◂ Contents") -> ◂ Contents
A2: Car wash financial model (planning)
A4: Active scenario | B4: 2 | C4: =CHOOSE(B4,"Low","Base","High") -> Base | D4: 1 = Low · 2 = Base · 3 = High — every sheet follows this cell | S4: Model checks | T4: =Checks!B25 -> PASS
A6: REVENUE · YEAR 3 | C6: EBITDA MARGIN · YEAR 3 | H6: NET INCOME · YEAR 3 | L6: LOWEST CASH BALANCE | P6: FUNDING REQUIRED | T6: ENTERPRISE VALUE (DCF)
A7: =D12 -> 2170291.6 | C7: =D17 -> 0.31439407 | H7: =D18 -> 140618.48 | L7: =F39 -> 179017.17 | P7: =F37 -> 5201982.8 | T7: =F44 -> -1510350.7
A8: =IF(AND(B12>0,D12>=0),(D12/B12)^(1/2)-1,"CAGR n/a") -> 0.3560774 | C8: =D16 -> 682326.82 | H8: =D19 -> 0.064792437 | L8: ='Break-even'!B6 -> 26 | P8: =IF(F38>=0,"Covered by funding raised",-F38) -> 101982.83 | T8: Average of 2 methods
A10: Core financials ($'000) — active scenario
B11: 1 | C11: 2 | D11: 3
A12: Revenue | B12: =SUMIF(Monthly!$C$5:$AL$5,B$11,Monthly!$C$37:$AL$37) -> 1180182.4 | C12: =SUMIF(Monthly!$C$5:$AL$5,C$11,Monthly!$C$37:$AL$37) -> 1846649 | D12: =SUMIF(Monthly!$C$5:$AL$5,D$11,Monthly!$C$37:$AL$37) -> 2170291.6
A13: Gross profit | B13: =SUMIF(Monthly!$C$5:$AL$5,B$11,Monthly!$C$46:$AL$46) -> 999760.79 | C13: =SUMIF(Monthly!$C$5:$AL$5,C$11,Monthly!$C$46:$AL$46) -> 1551921 | D13: =SUMIF(Monthly!$C$5:$AL$5,D$11,Monthly!$C$46:$AL$46) -> 1813150.4
A14: Gross margin | B14: =IF(B12=0,0,B13/B12) -> 0.84712397 | C14: =IF(C12=0,0,C13/C12) -> 0.84039848 | D14: =IF(D12=0,0,D13/D12) -> 0.83544089
A15: Operating expenses | B15: =SUMIF(Monthly!$C$5:$AL$5,B$11,Monthly!$C$54:$AL$54) -> -1123040 | C15: =SUMIF(Monthly!$C$5:$AL$5,C$11,Monthly!$C$54:$AL$54) -> -1123611.2 | D15: =SUMIF(Monthly!$C$5:$AL$5,D$11,Monthly!$C$54:$AL$54) -> -1130823.5
A16: EBITDA | B16: =SUMIF(Monthly!$C$5:$AL$5,B$11,Monthly!$C$55:$AL$55) -> -123279.21 | C16: =SUMIF(Monthly!$C$5:$AL$5,C$11,Monthly!$C$55:$AL$55) -> 428309.82 | D16: =SUMIF(Monthly!$C$5:$AL$5,D$11,Monthly!$C$55:$AL$55) -> 682326.82
A17: EBITDA margin | B17: =IF(B12=0,0,B16/B12) -> -0.10445776 | C17: =IF(C12=0,0,C16/C12) -> 0.23193894 | D17: =IF(D12=0,0,D16/D12) -> 0.31439407
A18: Net income | B18: =SUMIF(Monthly!$C$5:$AL$5,B$11,Monthly!$C$64:$AL$64) -> -709232.33 | C18: =SUMIF(Monthly!$C$5:$AL$5,C$11,Monthly!$C$64:$AL$64) -> -135565.18 | D18: =SUMIF(Monthly!$C$5:$AL$5,D$11,Monthly!$C$64:$AL$64) -> 140618.48
A19: Net margin | B19: =IF(B12=0,0,B18/B12) -> -0.60095146 | C19: =IF(C12=0,0,C18/C12) -> -0.073411448 | D19: =IF(D12=0,0,D18/D12) -> 0.064792437
A20: Operating cash flow | B20: =SUMIF(Monthly!$C$5:$AL$5,B$11,Monthly!$C$94:$AL$94) -> -367780.64 | C20: =SUMIF(Monthly!$C$5:$AL$5,C$11,Monthly!$C$94:$AL$94) -> 209654.47 | D20: =SUMIF(Monthly!$C$5:$AL$5,D$11,Monthly!$C$94:$AL$94) -> 489150.48
A21: Investing cash flow | B21: =SUMIF(Monthly!$C$5:$AL$5,B$11,Monthly!$C$95:$AL$95) -> -4100000 | C21: =SUMIF(Monthly!$C$5:$AL$5,C$11,Monthly!$C$95:$AL$95) -> -40000 | D21: =SUMIF(Monthly!$C$5:$AL$5,D$11,Monthly!$C$95:$AL$95) -> -40000
A22: Financing cash flow | B22: =SUMIF(Monthly!$C$5:$AL$5,B$11,Monthly!$C$97:$AL$97) -> 4825000 | C22: =SUMIF(Monthly!$C$5:$AL$5,C$11,Monthly!$C$97:$AL$97) -> -300000 | D22: =SUMIF(Monthly!$C$5:$AL$5,D$11,Monthly!$C$97:$AL$97) -> -300000
A23: Net change in cash | B23: =SUMIF(Monthly!$C$5:$AL$5,B$11,Monthly!$C$98:$AL$98) -> 357219.36 | C23: =SUMIF(Monthly!$C$5:$AL$5,C$11,Monthly!$C$98:$AL$98) -> -130345.53 | D23: =SUMIF(Monthly!$C$5:$AL$5,D$11,Monthly!$C$98:$AL$98) -> 149150.48
A24: Year-end cash | B24: =INDEX(Monthly!$C$100:$AL$100,B$11*12) -> 357219.36 | C24: =INDEX(Monthly!$C$100:$AL$100,C$11*12) -> 226873.84 | D24: =INDEX(Monthly!$C$100:$AL$100,D$11*12) -> 376024.31
A26: Car wash metrics
B27: 1 | C27: 2 | D27: 3
A28: Unlimited members (year end) | B28: =KPIs!B29 -> 972.08918 | C28: =KPIs!C29 -> 1660.5559 | D28: =KPIs!D29 -> 2124.5009
A29: Washes per operating day | B29: =KPIs!B37 -> 255.65215 | C29: =KPIs!C37 -> 409.62871 | D29: =KPIs!D37 -> 485.27721
A30: Tunnel capacity used | B30: =KPIs!B39 -> 0.30183253 | C30: =KPIs!C39 -> 0.48362304 | D30: =KPIs!D39 -> 0.57293649
A31: Revenue per wash | B31: =KPIs!B45 -> 13.265403 | C31: =KPIs!C45 -> 12.954323 | D31: =KPIs!D45 -> 12.851356
A32: Team (FTE, year end) | B32: =INDEX(Headcount!$C$10:$AL$10,B$27*12) -> 11 | C32: =INDEX(Headcount!$C$10:$AL$10,C$27*12) -> 11 | D32: =INDEX(Headcount!$C$10:$AL$10,D$27*12) -> 11
A34: Funding & valuation ($'000) — active scenario
A35: Equity raised | F35: =Inputs!$E$69 -> 2100000
A36: Loan drawn | F36: =Inputs!$E$70 -> 3000000
A37: Funding required (incl. cash buffer) | F37: ='Break-even'!B12 -> 5201982.8
A38: Funding surplus / (shortfall) | F38: ='Break-even'!B17 -> -101982.83
A39: ="Lowest cash balance (month "&'Break-even'!B6&")" -> Lowest cash balance (month 26) | F39: ='Break-even'!B18 -> 179017.17
A40: First month with positive EBITDA | F40: ='Break-even'!B21 -> 8
A41: Cash invested paid back | F41: ='Break-even'!B23 -> Not within horizon
A42: Enterprise value — perpetual growth | F42: =Valuation!B27 -> -1525694.7
A43: Enterprise value — exit multiple | F43: =Valuation!C27 -> -1495006.7
A44: Enterprise value — average | F44: =Valuation!B30 -> -1510350.7

Sheet Summary
A1: Financial statements summary | U1: =HYPERLINK("#'Cover'!A1","◂ Contents") -> ◂ Contents
A2: Car wash financial model (planning) | P2: Select detailed year: | R2: 1
A5: Income statement ($'000) — by year | H5: ="Income statement ($'000) — Year "&$R$2&", by month" -> Income statement ($'000) — Year 1, by month
B6: 1 | C6: 2 | D6: 3 | H6: =INDEX(Monthly!$C$4:$AL$4,($R$2-1)*12+1) -> 1 | I6: =INDEX(Monthly!$C$4:$AL$4,($R$2-1)*12+2) -> 2 | J6: =INDEX(Monthly!$C$4:$AL$4,($R$2-1)*12+3) -> 3 | K6: =INDEX(Monthly!$C$4:$AL$4,($R$2-1)*12+4) -> 4 | L6: =INDEX(Monthly!$C$4:$AL$4,($R$2-1)*12+5) -> 5 | M6: =INDEX(Monthly!$C$4:$AL$4,($R$2-1)*12+6) -> 6 | N6: =INDEX(Monthly!$C$4:$AL$4,($R$2-1)*12+7) -> 7 | O6: =INDEX(Monthly!$C$4:$AL$4,($R$2-1)*12+8) -> 8 | P6: =INDEX(Monthly!$C$4:$AL$4,($R$2-1)*12+9) -> 9 | Q6: =INDEX(Monthly!$C$4:$AL$4,($R$2-1)*12+10) -> 10 | R6: =INDEX(Monthly!$C$4:$AL$4,($R$2-1)*12+11) -> 11 | S6: =INDEX(Monthly!$C$4:$AL$4,($R$2-1)*12+12) -> 12
A7: Revenue | B7: ='P&L'!B5 -> 1180182.4 | C7: ='P&L'!C5 -> 1846649 | D7: ='P&L'!D5 -> 2170291.6 | H7: =INDEX(Monthly!$C$37:$AL$37,($R$2-1)*12+1) -> 47943.358 | I7: =INDEX(Monthly!$C$37:$AL$37,($R$2-1)*12+2) -> 54448.936 | J7: =INDEX(Monthly!$C$37:$AL$37,($R$2-1)*12+3) -> 72773.402 | K7: =INDEX(Monthly!$C$37:$AL$37,($R$2-1)*12+4) -> 81051.899 | L7: =INDEX(Monthly!$C$37:$AL$37,($R$2-1)*12+5) -> 89490.276 | M7: =INDEX(Monthly!$C$37:$AL$37,($R$2-1)*12+6) -> 98082.139 | N7: =INDEX(Monthly!$C$37:$AL$37,($R$2-1)*12+7) -> 106821.35 | O7: =INDEX(Monthly!$C$37:$AL$37,($R$2-1)*12+8) -> 115702.01 | P7: =INDEX(Monthly!$C$37:$AL$37,($R$2-1)*12+9) -> 124718.46 | Q7: =INDEX(Monthly!$C$37:$AL$37,($R$2-1)*12+10) -> 133865.28 | R7: =INDEX(Monthly!$C$37:$AL$37,($R$2-1)*12+11) -> 136545.55 | S7: =INDEX(Monthly!$C$37:$AL$37,($R$2-1)*12+12) -> 118739.73
A8: Cost of sales | B8: ='P&L'!B6 -> -180421.6 | C8: ='P&L'!C6 -> -294728 | D8: ='P&L'!D6 -> -357141.25 | H8: =INDEX(Monthly!$C$45:$AL$45,($R$2-1)*12+1) -> -7071.9457 | I8: =INDEX(Monthly!$C$45:$AL$45,($R$2-1)*12+2) -> -8031.4488 | J8: =INDEX(Monthly!$C$45:$AL$45,($R$2-1)*12+3) -> -11076.835 | K8: =INDEX(Monthly!$C$45:$AL$45,($R$2-1)*12+4) -> -12361.697 | L8: =INDEX(Monthly!$C$45:$AL$45,($R$2-1)*12+5) -> -13678.718 | M8: =INDEX(Monthly!$C$45:$AL$45,($R$2-1)*12+6) -> -15026.614 | N8: =INDEX(Monthly!$C$45:$AL$45,($R$2-1)*12+7) -> -16404.147 | O8: =INDEX(Monthly!$C$45:$AL$45,($R$2-1)*12+8) -> -17810.134 | P8: =INDEX(Monthly!$C$45:$AL$45,($R$2-1)*12+9) -> -19243.436 | Q8: =INDEX(Monthly!$C$45:$AL$45,($R$2-1)*12+10) -> -20702.96 | R8: =INDEX(Monthly!$C$45:$AL$45,($R$2-1)*12+11) -> -21242.097 | S8: =INDEX(Monthly!$C$45:$AL$45,($R$2-1)*12+12) -> -17771.565
A9: Gross profit | B9: ='P&L'!B7 -> 999760.79 | C9: ='P&L'!C7 -> 1551921 | D9: ='P&L'!D7 -> 1813150.4 | H9: =INDEX(Monthly!$C$46:$AL$46,($R$2-1)*12+1) -> 40871.412 | I9: =INDEX(Monthly!$C$46:$AL$46,($R$2-1)*12+2) -> 46417.487 | J9: =INDEX(Monthly!$C$46:$AL$46,($R$2-1)*12+3) -> 61696.567 | K9: =INDEX(Monthly!$C$46:$AL$46,($R$2-1)*12+4) -> 68690.202 | L9: =INDEX(Monthly!$C$46:$AL$46,($R$2-1)*12+5) -> 75811.558 | M9: =INDEX(Monthly!$C$46:$AL$46,($R$2-1)*12+6) -> 83055.526 | N9: =INDEX(Monthly!$C$46:$AL$46,($R$2-1)*12+7) -> 90417.201 | O9: =INDEX(Monthly!$C$46:$AL$46,($R$2-1)*12+8) -> 97891.875 | P9: =INDEX(Monthly!$C$46:$AL$46,($R$2-1)*12+9) -> 105475.03 | Q9: =INDEX(Monthly!$C$46:$AL$46,($R$2-1)*12+10) -> 113162.32 | R9: =INDEX(Monthly!$C$46:$AL$46,($R$2-1)*12+11) -> 115303.45 | S9: =INDEX(Monthly!$C$46:$AL$46,($R$2-1)*12+12) -> 100968.16
A10: Gross margin | B10: ='P&L'!B8 -> 0.84712397 | C10: ='P&L'!C8 -> 0.84039848 | D10: ='P&L'!D8 -> 0.83544089 | H10: =IF(H7=0,0,H9/H7) -> 0.85249373 | I10: =IF(I7=0,0,I9/I7) -> 0.85249576 | J10: =IF(J7=0,0,J9/J7) -> 0.84779006 | K10: =IF(K7=0,0,K9/K7) -> 0.84748418 | L10: =IF(L7=0,0,L9/L7) -> 0.84714855 | M10: =IF(M7=0,0,M9/M7) -> 0.84679562 | N10: =IF(N7=0,0,N9/N7) -> 0.84643381 | O10: =IF(O7=0,0,O9/O7) -> 0.84606893 | ... S10: =IF(S7=0,0,S9/S7) -> 0.85033177
A11: Total operating expenses | B11: ='P&L'!B14 -> -1123040 | C11: ='P&L'!C14 -> -1123611.2 | D11: ='P&L'!D14 -> -1130823.5 | H11: =INDEX(Monthly!$C$54:$AL$54,($R$2-1)*12+1) -> -93586.667 | I11: =INDEX(Monthly!$C$54:$AL$54,($R$2-1)*12+2) -> -93586.667 | J11: =INDEX(Monthly!$C$54:$AL$54,($R$2-1)*12+3) -> -93586.667 | K11: =INDEX(Monthly!$C$54:$AL$54,($R$2-1)*12+4) -> -93586.667 | L11: =INDEX(Monthly!$C$54:$AL$54,($R$2-1)*12+5) -> -93586.667 | M11: =INDEX(Monthly!$C$54:$AL$54,($R$2-1)*12+6) -> -93586.667 | N11: =INDEX(Monthly!$C$54:$AL$54,($R$2-1)*12+7) -> -93586.667 | O11: =INDEX(Monthly!$C$54:$AL$54,($R$2-1)*12+8) -> -93586.667 | P11: =INDEX(Monthly!$C$54:$AL$54,($R$2-1)*12+9) -> -93586.667 | Q11: =INDEX(Monthly!$C$54:$AL$54,($R$2-1)*12+10) -> -93586.667 | R11: =INDEX(Monthly!$C$54:$AL$54,($R$2-1)*12+11) -> -93586.667 | S11: =INDEX(Monthly!$C$54:$AL$54,($R$2-1)*12+12) -> -93586.667
A12: EBITDA | B12: ='P&L'!B15 -> -123279.21 | C12: ='P&L'!C15 -> 428309.82 | D12: ='P&L'!D15 -> 682326.82 | H12: =INDEX(Monthly!$C$55:$AL$55,($R$2-1)*12+1) -> -52715.254 | I12: =INDEX(Monthly!$C$55:$AL$55,($R$2-1)*12+2) -> -47169.18 | J12: =INDEX(Monthly!$C$55:$AL$55,($R$2-1)*12+3) -> -31890.1 | K12: =INDEX(Monthly!$C$55:$AL$55,($R$2-1)*12+4) -> -24896.465 | L12: =INDEX(Monthly!$C$55:$AL$55,($R$2-1)*12+5) -> -17775.109 | M12: =INDEX(Monthly!$C$55:$AL$55,($R$2-1)*12+6) -> -10531.141 | N12: =INDEX(Monthly!$C$55:$AL$55,($R$2-1)*12+7) -> -3169.4659 | O12: =INDEX(Monthly!$C$55:$AL$55,($R$2-1)*12+8) -> 4305.2082 | P12: =INDEX(Monthly!$C$55:$AL$55,($R$2-1)*12+9) -> 11888.361 | Q12: =INDEX(Monthly!$C$55:$AL$55,($R$2-1)*12+10) -> 19575.654 | R12: =INDEX(Monthly!$C$55:$AL$55,($R$2-1)*12+11) -> 21716.787 | S12: =INDEX(Monthly!$C$55:$AL$55,($R$2-1)*12+12) -> 7381.4964
A13: EBITDA margin | B13: ='P&L'!B16 -> -0.10445776 | C13: ='P&L'!C16 -> 0.23193894 | D13: ='P&L'!D16 -> 0.31439407 | H13: =IF(H7=0,0,H12/H7) -> -1.099532 | I13: =IF(I7=0,0,I12/I7) -> -0.86630122 | J13: =IF(J7=0,0,J12/J7) -> -0.43821093 | K13: =IF(K7=0,0,K12/K7) -> -0.30716695 | L13: =IF(L7=0,0,L12/L7) -> -0.19862615 | M13: =IF(M7=0,0,M12/M7) -> -0.10737063 | N13: =IF(N7=0,0,N12/N7) -> -0.029670716 | O13: =IF(O7=0,0,O12/O7) -> 0.03720945 | ... S13: =IF(S7=0,0,S12/S7) -> 0.062165347
A14: Depreciation | B14: ='P&L'!B17 -> -341666.67 | C14: ='P&L'!C17 -> -345000 | D14: ='P&L'!D17 -> -348333.33 | H14: =INDEX(Monthly!$C$75:$AL$75,($R$2-1)*12+1) -> -28472.222 | I14: =INDEX(Monthly!$C$75:$AL$75,($R$2-1)*12+2) -> -28472.222 | J14: =INDEX(Monthly!$C$75:$AL$75,($R$2-1)*12+3) -> -28472.222 | K14: =INDEX(Monthly!$C$75:$AL$75,($R$2-1)*12+4) -> -28472.222 | L14: =INDEX(Monthly!$C$75:$AL$75,($R$2-1)*12+5) -> -28472.222 | M14: =INDEX(Monthly!$C$75:$AL$75,($R$2-1)*12+6) -> -28472.222 | N14: =INDEX(Monthly!$C$75:$AL$75,($R$2-1)*12+7) -> -28472.222 | O14: =INDEX(Monthly!$C$75:$AL$75,($R$2-1)*12+8) -> -28472.222 | P14: =INDEX(Monthly!$C$75:$AL$75,($R$2-1)*12+9) -> -28472.222 | Q14: =INDEX(Monthly!$C$75:$AL$75,($R$2-1)*12+10) -> -28472.222 | R14: =INDEX(Monthly!$C$75:$AL$75,($R$2-1)*12+11) -> -28472.222 | S14: =INDEX(Monthly!$C$75:$AL$75,($R$2-1)*12+12) -> -28472.222
A15: EBIT | B15: ='P&L'!B18 -> -464945.87 | C15: ='P&L'!C18 -> 83309.822 | D15: ='P&L'!D18 -> 333993.48 | H15: =INDEX(Monthly!$C$58:$AL$58,($R$2-1)*12+1) -> -81187.477 | I15: =INDEX(Monthly!$C$58:$AL$58,($R$2-1)*12+2) -> -75641.402 | J15: =INDEX(Monthly!$C$58:$AL$58,($R$2-1)*12+3) -> -60362.322 | K15: =INDEX(Monthly!$C$58:$AL$58,($R$2-1)*12+4) -> -53368.687 | L15: =INDEX(Monthly!$C$58:$AL$58,($R$2-1)*12+5) -> -46247.331 | M15: =INDEX(Monthly!$C$58:$AL$58,($R$2-1)*12+6) -> -39003.363 | N15: =INDEX(Monthly!$C$58:$AL$58,($R$2-1)*12+7) -> -31641.688 | O15: =INDEX(Monthly!$C$58:$AL$58,($R$2-1)*12+8) -> -24167.014 | P15: =INDEX(Monthly!$C$58:$AL$58,($R$2-1)*12+9) -> -16583.861 | Q15: =INDEX(Monthly!$C$58:$AL$58,($R$2-1)*12+10) -> -8896.568 | R15: =INDEX(Monthly!$C$58:$AL$58,($R$2-1)*12+11) -> -6755.4353 | S15: =INDEX(Monthly!$C$58:$AL$58,($R$2-1)*12+12) -> -21090.726
A16: Interest | B16: ='P&L'!B19 -> -244286.46 | C16: ='P&L'!C19 -> -218875 | D16: ='P&L'!D19 -> -193375 | H16: =INDEX(Monthly!$C$59:$AL$59,($R$2-1)*12+1) -> -21250 | I16: =INDEX(Monthly!$C$59:$AL$59,($R$2-1)*12+2) -> -21161.458 | J16: =INDEX(Monthly!$C$59:$AL$59,($R$2-1)*12+3) -> -20984.375 | K16: =INDEX(Monthly!$C$59:$AL$59,($R$2-1)*12+4) -> -20807.292 | L16: =INDEX(Monthly!$C$59:$AL$59,($R$2-1)*12+5) -> -20630.208 | M16: =INDEX(Monthly!$C$59:$AL$59,($R$2-1)*12+6) -> -20453.125 | N16: =INDEX(Monthly!$C$59:$AL$59,($R$2-1)*12+7) -> -20276.042 | O16: =INDEX(Monthly!$C$59:$AL$59,($R$2-1)*12+8) -> -20098.958 | P16: =INDEX(Monthly!$C$59:$AL$59,($R$2-1)*12+9) -> -19921.875 | Q16: =INDEX(Monthly!$C$59:$AL$59,($R$2-1)*12+10) -> -19744.792 | R16: =INDEX(Monthly!$C$59:$AL$59,($R$2-1)*12+11) -> -19567.708 | S16: =INDEX(Monthly!$C$59:$AL$59,($R$2-1)*12+12) -> -19390.625
A17: Pre-tax income | B17: ='P&L'!B20 -> -709232.33 | C17: ='P&L'!C20 -> -135565.18 | D17: ='P&L'!D20 -> 140618.48 | H17: =INDEX(Monthly!$C$60:$AL$60,($R$2-1)*12+1) -> -102437.48 | I17: =INDEX(Monthly!$C$60:$AL$60,($R$2-1)*12+2) -> -96802.86 | J17: =INDEX(Monthly!$C$60:$AL$60,($R$2-1)*12+3) -> -81346.697 | K17: =INDEX(Monthly!$C$60:$AL$60,($R$2-1)*12+4) -> -74175.979 | L17: =INDEX(Monthly!$C$60:$AL$60,($R$2-1)*12+5) -> -66877.539 | M17: =INDEX(Monthly!$C$60:$AL$60,($R$2-1)*12+6) -> -59456.488 | N17: =INDEX(Monthly!$C$60:$AL$60,($R$2-1)*12+7) -> -51917.73 | O17: =INDEX(Monthly!$C$60:$AL$60,($R$2-1)*12+8) -> -44265.972 | P17: =INDEX(Monthly!$C$60:$AL$60,($R$2-1)*12+9) -> -36505.736 | Q17: =INDEX(Monthly!$C$60:$AL$60,($R$2-1)*12+10) -> -28641.36 | R17: =INDEX(Monthly!$C$60:$AL$60,($R$2-1)*12+11) -> -26323.144 | S17: =INDEX(Monthly!$C$60:$AL$60,($R$2-1)*12+12) -> -40481.351
A18: Income tax | B18: ='P&L'!B21 -> 0 | C18: ='P&L'!C21 -> 0 | D18: ='P&L'!D21 -> 0 | H18: =INDEX(Monthly!$C$63:$AL$63,($R$2-1)*12+1) -> 0 | I18: =INDEX(Monthly!$C$63:$AL$63,($R$2-1)*12+2) -> 0 | J18: =INDEX(Monthly!$C$63:$AL$63,($R$2-1)*12+3) -> 0 | K18: =INDEX(Monthly!$C$63:$AL$63,($R$2-1)*12+4) -> 0 | L18: =INDEX(Monthly!$C$63:$AL$63,($R$2-1)*12+5) -> 0 | M18: =INDEX(Monthly!$C$63:$AL$63,($R$2-1)*12+6) -> 0 | N18: =INDEX(Monthly!$C$63:$AL$63,($R$2-1)*12+7) -> 0 | O18: =INDEX(Monthly!$C$63:$AL$63,($R$2-1)*12+8) -> 0 | P18: =INDEX(Monthly!$C$63:$AL$63,($R$2-1)*12+9) -> 0 | Q18: =INDEX(Monthly!$C$63:$AL$63,($R$2-1)*12+10) -> 0 | R18: =INDEX(Monthly!$C$63:$AL$63,($R$2-1)*12+11) -> 0 | S18: =INDEX(Monthly!$C$63:$AL$63,($R$2-1)*12+12) -> 0
A19: Net income | B19: ='P&L'!B22 -> -709232.33 | C19: ='P&L'!C22 -> -135565.18 | D19: ='P&L'!D22 -> 140618.48 | H19: =INDEX(Monthly!$C$64:$AL$64,($R$2-1)*12+1) -> -102437.48 | I19: =INDEX(Monthly!$C$64:$AL$64,($R$2-1)*12+2) -> -96802.86 | J19: =INDEX(Monthly!$C$64:$AL$64,($R$2-1)*12+3) -> -81346.697 | K19: =INDEX(Monthly!$C$64:$AL$64,($R$2-1)*12+4) -> -74175.979 | L19: =INDEX(Monthly!$C$64:$AL$64,($R$2-1)*12+5) -> -66877.539 | M19: =INDEX(Monthly!$C$64:$AL$64,($R$2-1)*12+6) -> -59456.488 | N19: =INDEX(Monthly!$C$64:$AL$64,($R$2-1)*12+7) -> -51917.73 | O19: =INDEX(Monthly!$C$64:$AL$64,($R$2-1)*12+8) -> -44265.972 | P19: =INDEX(Monthly!$C$64:$AL$64,($R$2-1)*12+9) -> -36505.736 | Q19: =INDEX(Monthly!$C$64:$AL$64,($R$2-1)*12+10) -> -28641.36 | R19: =INDEX(Monthly!$C$64:$AL$64,($R$2-1)*12+11) -> -26323.144 | S19: =INDEX(Monthly!$C$64:$AL$64,($R$2-1)*12+12) -> -40481.351
A20: Net margin | B20: ='P&L'!B23 -> -0.60095146 | C20: ='P&L'!C23 -> -0.073411448 | D20: ='P&L'!D23 -> 0.064792437 | H20: =IF(H7=0,0,H19/H7) -> -2.1366354 | I20: =IF(I7=0,0,I19/I7) -> -1.777865 | J20: =IF(J7=0,0,J19/J7) -> -1.1178081 | K20: =IF(K7=0,0,K19/K7) -> -0.91516645 | L20: =IF(L7=0,0,L19/L7) -> -0.74731627 | M20: =IF(M7=0,0,M19/M7) -> -0.60619078 | N20: =IF(N7=0,0,N19/N7) -> -0.48602391 | O20: =IF(O7=0,0,O19/O7) -> -0.38258603 | ... S20: =IF(S7=0,0,S19/S7) -> -0.34092508
A22: Cash flow ($'000) — by year | H22: ="Cash flow ($'000) — Year "&$R$2&", by month" -> Cash flow ($'000) — Year 1, by month
B23: 1 | C23: 2 | D23: 3 | H23: =INDEX(Monthly!$C$4:$AL$4,($R$2-1)*12+1) -> 1 | I23: =INDEX(Monthly!$C$4:$AL$4,($R$2-1)*12+2) -> 2 | J23: =INDEX(Monthly!$C$4:$AL$4,($R$2-1)*12+3) -> 3 | K23: =INDEX(Monthly!$C$4:$AL$4,($R$2-1)*12+4) -> 4 | L23: =INDEX(Monthly!$C$4:$AL$4,($R$2-1)*12+5) -> 5 | M23: =INDEX(Monthly!$C$4:$AL$4,($R$2-1)*12+6) -> 6 | N23: =INDEX(Monthly!$C$4:$AL$4,($R$2-1)*12+7) -> 7 | O23: =INDEX(Monthly!$C$4:$AL$4,($R$2-1)*12+8) -> 8 | P23: =INDEX(Monthly!$C$4:$AL$4,($R$2-1)*12+9) -> 9 | Q23: =INDEX(Monthly!$C$4:$AL$4,($R$2-1)*12+10) -> 10 | R23: =INDEX(Monthly!$C$4:$AL$4,($R$2-1)*12+11) -> 11 | S23: =INDEX(Monthly!$C$4:$AL$4,($R$2-1)*12+12) -> 12
A24: Operating cash flow | B24: ='Cash Flow'!B10 -> -367780.64 | C24: ='Cash Flow'!C10 -> 209654.47 | D24: ='Cash Flow'!D10 -> 489150.48 | H24: =INDEX(Monthly!$C$94:$AL$94,($R$2-1)*12+1) -> -74096.968 | I24: =INDEX(Monthly!$C$94:$AL$94,($R$2-1)*12+2) -> -68348.558 | J24: =INDEX(Monthly!$C$94:$AL$94,($R$2-1)*12+3) -> -52776.439 | K24: =INDEX(Monthly!$C$94:$AL$94,($R$2-1)*12+4) -> -45698.883 | L24: =INDEX(Monthly!$C$94:$AL$94,($R$2-1)*12+5) -> -38397.166 | M24: =INDEX(Monthly!$C$94:$AL$94,($R$2-1)*12+6) -> -30972.969 | N24: =INDEX(Monthly!$C$94:$AL$94,($R$2-1)*12+7) -> -23431.19 | O24: =INDEX(Monthly!$C$94:$AL$94,($R$2-1)*12+8) -> -15776.533 | P24: =INDEX(Monthly!$C$94:$AL$94,($R$2-1)*12+9) -> -8013.5132 | Q24: =INDEX(Monthly!$C$94:$AL$94,($R$2-1)*12+10) -> -146.46471 | R24: =INDEX(Monthly!$C$94:$AL$94,($R$2-1)*12+11) -> 2204.0197 | S24: =INDEX(Monthly!$C$94:$AL$94,($R$2-1)*12+12) -> -12325.971
A25: Capital spending | B25: ='Cash Flow'!B11 -> -4100000 | C25: ='Cash Flow'!C11 -> -40000 | D25: ='Cash Flow'!D11 -> -40000 | H25: =INDEX(Monthly!$C$95:$AL$95,($R$2-1)*12+1) -> -4100000 | I25: =INDEX(Monthly!$C$95:$AL$95,($R$2-1)*12+2) -> 0 | J25: =INDEX(Monthly!$C$95:$AL$95,($R$2-1)*12+3) -> 0 | K25: =INDEX(Monthly!$C$95:$AL$95,($R$2-1)*12+4) -> 0 | L25: =INDEX(Monthly!$C$95:$AL$95,($R$2-1)*12+5) -> 0 | M25: =INDEX(Monthly!$C$95:$AL$95,($R$2-1)*12+6) -> 0 | N25: =INDEX(Monthly!$C$95:$AL$95,($R$2-1)*12+7) -> 0 | O25: =INDEX(Monthly!$C$95:$AL$95,($R$2-1)*12+8) -> 0 | P25: =INDEX(Monthly!$C$95:$AL$95,($R$2-1)*12+9) -> 0 | Q25: =INDEX(Monthly!$C$95:$AL$95,($R$2-1)*12+10) -> 0 | R25: =INDEX(Monthly!$C$95:$AL$95,($R$2-1)*12+11) -> 0 | S25: =INDEX(Monthly!$C$95:$AL$95,($R$2-1)*12+12) -> 0
A26: Equity raised | B26: ='Cash Flow'!B12 -> 2100000 | C26: ='Cash Flow'!C12 -> 0 | D26: ='Cash Flow'!D12 -> 0 | H26: =INDEX(Monthly!$C$96:$AL$96,($R$2-1)*12+1) -> 2100000 | I26: =INDEX(Monthly!$C$96:$AL$96,($R$2-1)*12+2) -> 0 | J26: =INDEX(Monthly!$C$96:$AL$96,($R$2-1)*12+3) -> 0 | K26: =INDEX(Monthly!$C$96:$AL$96,($R$2-1)*12+4) -> 0 | L26: =INDEX(Monthly!$C$96:$AL$96,($R$2-1)*12+5) -> 0 | M26: =INDEX(Monthly!$C$96:$AL$96,($R$2-1)*12+6) -> 0 | N26: =INDEX(Monthly!$C$96:$AL$96,($R$2-1)*12+7) -> 0 | O26: =INDEX(Monthly!$C$96:$AL$96,($R$2-1)*12+8) -> 0 | P26: =INDEX(Monthly!$C$96:$AL$96,($R$2-1)*12+9) -> 0 | Q26: =INDEX(Monthly!$C$96:$AL$96,($R$2-1)*12+10) -> 0 | R26: =INDEX(Monthly!$C$96:$AL$96,($R$2-1)*12+11) -> 0 | S26: =INDEX(Monthly!$C$96:$AL$96,($R$2-1)*12+12) -> 0
A27: Loan drawdown | B27: ='Cash Flow'!B13 -> 3000000 | C27: ='Cash Flow'!C13 -> 0 | D27: ='Cash Flow'!D13 -> 0 | H27: =INDEX(Monthly!$C$81:$AL$81,($R$2-1)*12+1) -> 3000000 | I27: =INDEX(Monthly!$C$81:$AL$81,($R$2-1)*12+2) -> 0 | J27: =INDEX(Monthly!$C$81:$AL$81,($R$2-1)*12+3) -> 0 | K27: =INDEX(Monthly!$C$81:$AL$81,($R$2-1)*12+4) -> 0 | L27: =INDEX(Monthly!$C$81:$AL$81,($R$2-1)*12+5) -> 0 | M27: =INDEX(Monthly!$C$81:$AL$81,($R$2-1)*12+6) -> 0 | N27: =INDEX(Monthly!$C$81:$AL$81,($R$2-1)*12+7) -> 0 | O27: =INDEX(Monthly!$C$81:$AL$81,($R$2-1)*12+8) -> 0 | P27: =INDEX(Monthly!$C$81:$AL$81,($R$2-1)*12+9) -> 0 | Q27: =INDEX(Monthly!$C$81:$AL$81,($R$2-1)*12+10) -> 0 | R27: =INDEX(Monthly!$C$81:$AL$81,($R$2-1)*12+11) -> 0 | S27: =INDEX(Monthly!$C$81:$AL$81,($R$2-1)*12+12) -> 0
A28: Loan repayment | B28: ='Cash Flow'!B14 -> -275000 | C28: ='Cash Flow'!C14 -> -300000 | D28: ='Cash Flow'!D14 -> -300000 | H28: =INDEX(Monthly!$C$82:$AL$82,($R$2-1)*12+1) -> 0 | I28: =INDEX(Monthly!$C$82:$AL$82,($R$2-1)*12+2) -> -25000 | J28: =INDEX(Monthly!$C$82:$AL$82,($R$2-1)*12+3) -> -25000 | K28: =INDEX(Monthly!$C$82:$AL$82,($R$2-1)*12+4) -> -25000 | L28: =INDEX(Monthly!$C$82:$AL$82,($R$2-1)*12+5) -> -25000 | M28: =INDEX(Monthly!$C$82:$AL$82,($R$2-1)*12+6) -> -25000 | N28: =INDEX(Monthly!$C$82:$AL$82,($R$2-1)*12+7) -> -25000 | O28: =INDEX(Monthly!$C$82:$AL$82,($R$2-1)*12+8) -> -25000 | P28: =INDEX(Monthly!$C$82:$AL$82,($R$2-1)*12+9) -> -25000 | Q28: =INDEX(Monthly!$C$82:$AL$82,($R$2-1)*12+10) -> -25000 | R28: =INDEX(Monthly!$C$82:$AL$82,($R$2-1)*12+11) -> -25000 | S28: =INDEX(Monthly!$C$82:$AL$82,($R$2-1)*12+12) -> -25000
A29: Financing cash flow | B29: ='Cash Flow'!B15 -> 4825000 | C29: ='Cash Flow'!C15 -> -300000 | D29: ='Cash Flow'!D15 -> -300000 | H29: =INDEX(Monthly!$C$97:$AL$97,($R$2-1)*12+1) -> 5100000 | I29: =INDEX(Monthly!$C$97:$AL$97,($R$2-1)*12+2) -> -25000 | J29: =INDEX(Monthly!$C$97:$AL$97,($R$2-1)*12+3) -> -25000 | K29: =INDEX(Monthly!$C$97:$AL$97,($R$2-1)*12+4) -> -25000 | L29: =INDEX(Monthly!$C$97:$AL$97,($R$2-1)*12+5) -> -25000 | M29: =INDEX(Monthly!$C$97:$AL$97,($R$2-1)*12+6) -> -25000 | N29: =INDEX(Monthly!$C$97:$AL$97,($R$2-1)*12+7) -> -25000 | O29: =INDEX(Monthly!$C$97:$AL$97,($R$2-1)*12+8) -> -25000 | P29: =INDEX(Monthly!$C$97:$AL$97,($R$2-1)*12+9) -> -25000 | Q29: =INDEX(Monthly!$C$97:$AL$97,($R$2-1)*12+10) -> -25000 | R29: =INDEX(Monthly!$C$97:$AL$97,($R$2-1)*12+11) -> -25000 | S29: =INDEX(Monthly!$C$97:$AL$97,($R$2-1)*12+12) -> -25000
A30: Net change in cash | B30: ='Cash Flow'!B16 -> 357219.36 | C30: ='Cash Flow'!C16 -> -130345.53 | D30: ='Cash Flow'!D16 -> 149150.48 | H30: =INDEX(Monthly!$C$98:$AL$98,($R$2-1)*12+1) -> 925903.03 | I30: =INDEX(Monthly!$C$98:$AL$98,($R$2-1)*12+2) -> -93348.558 | J30: =INDEX(Monthly!$C$98:$AL$98,($R$2-1)*12+3) -> -77776.439 | K30: =INDEX(Monthly!$C$98:$AL$98,($R$2-1)*12+4) -> -70698.883 | L30: =INDEX(Monthly!$C$98:$AL$98,($R$2-1)*12+5) -> -63397.166 | M30: =INDEX(Monthly!$C$98:$AL$98,($R$2-1)*12+6) -> -55972.969 | N30: =INDEX(Monthly!$C$98:$AL$98,($R$2-1)*12+7) -> -48431.19 | O30: =INDEX(Monthly!$C$98:$AL$98,($R$2-1)*12+8) -> -40776.533 | P30: =INDEX(Monthly!$C$98:$AL$98,($R$2-1)*12+9) -> -33013.513 | Q30: =INDEX(Monthly!$C$98:$AL$98,($R$2-1)*12+10) -> -25146.465 | R30: =INDEX(Monthly!$C$98:$AL$98,($R$2-1)*12+11) -> -22795.98 | S30: =INDEX(Monthly!$C$98:$AL$98,($R$2-1)*12+12) -> -37325.971
A31: Closing cash | B31: ='Cash Flow'!B18 -> 357219.36 | C31: ='Cash Flow'!C18 -> 226873.84 | D31: ='Cash Flow'!D18 -> 376024.31 | H31: =INDEX(Monthly!$C$100:$AL$100,($R$2-1)*12+1) -> 925903.03 | I31: =INDEX(Monthly!$C$100:$AL$100,($R$2-1)*12+2) -> 832554.47 | J31: =INDEX(Monthly!$C$100:$AL$100,($R$2-1)*12+3) -> 754778.03 | K31: =INDEX(Monthly!$C$100:$AL$100,($R$2-1)*12+4) -> 684079.15 | L31: =INDEX(Monthly!$C$100:$AL$100,($R$2-1)*12+5) -> 620681.99 | M31: =INDEX(Monthly!$C$100:$AL$100,($R$2-1)*12+6) -> 564709.02 | N31: =INDEX(Monthly!$C$100:$AL$100,($R$2-1)*12+7) -> 516277.83 | O31: =INDEX(Monthly!$C$100:$AL$100,($R$2-1)*12+8) -> 475501.29 | P31: =INDEX(Monthly!$C$100:$AL$100,($R$2-1)*12+9) -> 442487.78 | Q31: =INDEX(Monthly!$C$100:$AL$100,($R$2-1)*12+10) -> 417341.32 | R31: =INDEX(Monthly!$C$100:$AL$100,($R$2-1)*12+11) -> 394545.33 | S31: =INDEX(Monthly!$C$100:$AL$100,($R$2-1)*12+12) -> 357219.36
A39: Balance sheet at year end ($'000) | H39: ="Balance sheet at month end ($'000) — Year "&$R$2 -> Balance sheet at month end ($'000) — Year 1
B40: 1 | C40: 2 | D40: 3 | H40: =INDEX(Monthly!$C$4:$AL$4,($R$2-1)*12+1) -> 1 | I40: =INDEX(Monthly!$C$4:$AL$4,($R$2-1)*12+2) -> 2 | J40: =INDEX(Monthly!$C$4:$AL$4,($R$2-1)*12+3) -> 3 | K40: =INDEX(Monthly!$C$4:$AL$4,($R$2-1)*12+4) -> 4 | L40: =INDEX(Monthly!$C$4:$AL$4,($R$2-1)*12+5) -> 5 | M40: =INDEX(Monthly!$C$4:$AL$4,($R$2-1)*12+6) -> 6 | N40: =INDEX(Monthly!$C$4:$AL$4,($R$2-1)*12+7) -> 7 | O40: =INDEX(Monthly!$C$4:$AL$4,($R$2-1)*12+8) -> 8 | P40: =INDEX(Monthly!$C$4:$AL$4,($R$2-1)*12+9) -> 9 | Q40: =INDEX(Monthly!$C$4:$AL$4,($R$2-1)*12+10) -> 10 | R40: =INDEX(Monthly!$C$4:$AL$4,($R$2-1)*12+11) -> 11 | S40: =INDEX(Monthly!$C$4:$AL$4,($R$2-1)*12+12) -> 12
A41: Cash | B41: ='Balance Sheet'!B5 -> 357219.36 | C41: ='Balance Sheet'!C5 -> 226873.84 | D41: ='Balance Sheet'!D5 -> 376024.31 | H41: =INDEX(Monthly!$C$100:$AL$100,($R$2-1)*12+1) -> 925903.03 | I41: =INDEX(Monthly!$C$100:$AL$100,($R$2-1)*12+2) -> 832554.47 | J41: =INDEX(Monthly!$C$100:$AL$100,($R$2-1)*12+3) -> 754778.03 | K41: =INDEX(Monthly!$C$100:$AL$100,($R$2-1)*12+4) -> 684079.15 | L41: =INDEX(Monthly!$C$100:$AL$100,($R$2-1)*12+5) -> 620681.99 | M41: =INDEX(Monthly!$C$100:$AL$100,($R$2-1)*12+6) -> 564709.02 | N41: =INDEX(Monthly!$C$100:$AL$100,($R$2-1)*12+7) -> 516277.83 | O41: =INDEX(Monthly!$C$100:$AL$100,($R$2-1)*12+8) -> 475501.29 | P41: =INDEX(Monthly!$C$100:$AL$100,($R$2-1)*12+9) -> 442487.78 | Q41: =INDEX(Monthly!$C$100:$AL$100,($R$2-1)*12+10) -> 417341.32 | R41: =INDEX(Monthly!$C$100:$AL$100,($R$2-1)*12+11) -> 394545.33 | S41: =INDEX(Monthly!$C$100:$AL$100,($R$2-1)*12+12) -> 357219.36
A42: Accounts receivable | B42: ='Balance Sheet'!B6 -> 7915.9819 | C42: ='Balance Sheet'!C6 -> 9917.125 | D42: ='Balance Sheet'!D6 -> 11443.887 | H42: =INDEX(Monthly!$C$86:$AL$86,($R$2-1)*12+1) -> 3196.2239 | I42: =INDEX(Monthly!$C$86:$AL$86,($R$2-1)*12+2) -> 3629.9291 | J42: =INDEX(Monthly!$C$86:$AL$86,($R$2-1)*12+3) -> 4851.5601 | K42: =INDEX(Monthly!$C$86:$AL$86,($R$2-1)*12+4) -> 5403.4599 | L42: =INDEX(Monthly!$C$86:$AL$86,($R$2-1)*12+5) -> 5966.0184 | M42: =INDEX(Monthly!$C$86:$AL$86,($R$2-1)*12+6) -> 6538.8093 | N42: =INDEX(Monthly!$C$86:$AL$86,($R$2-1)*12+7) -> 7121.4232 | O42: =INDEX(Monthly!$C$86:$AL$86,($R$2-1)*12+8) -> 7713.4673 | P42: =INDEX(Monthly!$C$86:$AL$86,($R$2-1)*12+9) -> 8314.5643 | Q42: =INDEX(Monthly!$C$86:$AL$86,($R$2-1)*12+10) -> 8924.3521 | R42: =INDEX(Monthly!$C$86:$AL$86,($R$2-1)*12+11) -> 9103.0367 | S42: =INDEX(Monthly!$C$86:$AL$86,($R$2-1)*12+12) -> 7915.9819
A43: Inventory | B43: ='Balance Sheet'!B7 -> 4146.6985 | C43: ='Balance Sheet'!C7 -> 5342.5115 | D43: ='Balance Sheet'!D7 -> 6271.585 | H43: =INDEX(Monthly!$C$87:$AL$87,($R$2-1)*12+1) -> 1650.1207 | I43: =INDEX(Monthly!$C$87:$AL$87,($R$2-1)*12+2) -> 1874.0047 | J43: =INDEX(Monthly!$C$87:$AL$87,($R$2-1)*12+3) -> 2584.5949 | K43: =INDEX(Monthly!$C$87:$AL$87,($R$2-1)*12+4) -> 2884.3959 | L43: =INDEX(Monthly!$C$87:$AL$87,($R$2-1)*12+5) -> 3191.701 | M43: =INDEX(Monthly!$C$87:$AL$87,($R$2-1)*12+6) -> 3506.2099 | N43: =INDEX(Monthly!$C$87:$AL$87,($R$2-1)*12+7) -> 3827.6344 | O43: =INDEX(Monthly!$C$87:$AL$87,($R$2-1)*12+8) -> 4155.698 | P43: =INDEX(Monthly!$C$87:$AL$87,($R$2-1)*12+9) -> 4490.1351 | Q43: =INDEX(Monthly!$C$87:$AL$87,($R$2-1)*12+10) -> 4830.6908 | R43: =INDEX(Monthly!$C$87:$AL$87,($R$2-1)*12+11) -> 4956.4892 | S43: =INDEX(Monthly!$C$87:$AL$87,($R$2-1)*12+12) -> 4146.6985
A44: Net fixed assets | B44: ='Balance Sheet'!B8 -> 3758333.3 | C44: ='Balance Sheet'!C8 -> 3453333.3 | D44: ='Balance Sheet'!D8 -> 3145000 | H44: =INDEX(Monthly!$C$77:$AL$77,($R$2-1)*12+1) -> 4071527.8 | I44: =INDEX(Monthly!$C$77:$AL$77,($R$2-1)*12+2) -> 4043055.6 | J44: =INDEX(Monthly!$C$77:$AL$77,($R$2-1)*12+3) -> 4014583.3 | K44: =INDEX(Monthly!$C$77:$AL$77,($R$2-1)*12+4) -> 3986111.1 | L44: =INDEX(Monthly!$C$77:$AL$77,($R$2-1)*12+5) -> 3957638.9 | M44: =INDEX(Monthly!$C$77:$AL$77,($R$2-1)*12+6) -> 3929166.7 | N44: =INDEX(Monthly!$C$77:$AL$77,($R$2-1)*12+7) -> 3900694.4 | O44: =INDEX(Monthly!$C$77:$AL$77,($R$2-1)*12+8) -> 3872222.2 | P44: =INDEX(Monthly!$C$77:$AL$77,($R$2-1)*12+9) -> 3843750 | Q44: =INDEX(Monthly!$C$77:$AL$77,($R$2-1)*12+10) -> 3815277.8 | R44: =INDEX(Monthly!$C$77:$AL$77,($R$2-1)*12+11) -> 3786805.6 | S44: =INDEX(Monthly!$C$77:$AL$77,($R$2-1)*12+12) -> 3758333.3
A45: Total assets | B45: ='Balance Sheet'!B9 -> 4127615.4 | C45: ='Balance Sheet'!C9 -> 3695466.8 | D45: ='Balance Sheet'!D9 -> 3538739.8 | H45: =INDEX(Monthly!$C$114:$AL$114,($R$2-1)*12+1) -> 5002277.2 | I45: =INDEX(Monthly!$C$114:$AL$114,($R$2-1)*12+2) -> 4881114 | J45: =INDEX(Monthly!$C$114:$AL$114,($R$2-1)*12+3) -> 4776797.5 | K45: =INDEX(Monthly!$C$114:$AL$114,($R$2-1)*12+4) -> 4678478.1 | L45: =INDEX(Monthly!$C$114:$AL$114,($R$2-1)*12+5) -> 4587478.6 | M45: =INDEX(Monthly!$C$114:$AL$114,($R$2-1)*12+6) -> 4503920.7 | N45: =INDEX(Monthly!$C$114:$AL$114,($R$2-1)*12+7) -> 4427921.3 | O45: =INDEX(Monthly!$C$114:$AL$114,($R$2-1)*12+8) -> 4359592.7 | P45: =INDEX(Monthly!$C$114:$AL$114,($R$2-1)*12+9) -> 4299042.5 | Q45: =INDEX(Monthly!$C$114:$AL$114,($R$2-1)*12+10) -> 4246374.1 | R45: =INDEX(Monthly!$C$114:$AL$114,($R$2-1)*12+11) -> 4195410.4 | S45: =INDEX(Monthly!$C$114:$AL$114,($R$2-1)*12+12) -> 4127615.4
A46: Accounts payable | B46: ='Balance Sheet'!B10 -> 11847.71 | C46: ='Balance Sheet'!C10 -> 15264.319 | D46: ='Balance Sheet'!D10 -> 17918.814 | H46: =INDEX(Monthly!$C$88:$AL$88,($R$2-1)*12+1) -> 4714.6305 | I46: =INDEX(Monthly!$C$88:$AL$88,($R$2-1)*12+2) -> 5354.2992 | J46: =INDEX(Monthly!$C$88:$AL$88,($R$2-1)*12+3) -> 7384.5568 | K46: =INDEX(Monthly!$C$88:$AL$88,($R$2-1)*12+4) -> 8241.1313 | L46: =INDEX(Monthly!$C$88:$AL$88,($R$2-1)*12+5) -> 9119.1457 | M46: =INDEX(Monthly!$C$88:$AL$88,($R$2-1)*12+6) -> 10017.742 | N46: =INDEX(Monthly!$C$88:$AL$88,($R$2-1)*12+7) -> 10936.098 | O46: =INDEX(Monthly!$C$88:$AL$88,($R$2-1)*12+8) -> 11873.423 | P46: =INDEX(Monthly!$C$88:$AL$88,($R$2-1)*12+9) -> 12828.957 | Q46: =INDEX(Monthly!$C$88:$AL$88,($R$2-1)*12+10) -> 13801.974 | R46: =INDEX(Monthly!$C$88:$AL$88,($R$2-1)*12+11) -> 14161.398 | S46: =INDEX(Monthly!$C$88:$AL$88,($R$2-1)*12+12) -> 11847.71
A47: Loan | B47: ='Balance Sheet'!B11 -> 2725000 | C47: ='Balance Sheet'!C11 -> 2425000 | D47: ='Balance Sheet'!D11 -> 2125000 | H47: =INDEX(Monthly!$C$83:$AL$83,($R$2-1)*12+1) -> 3000000 | I47: =INDEX(Monthly!$C$83:$AL$83,($R$2-1)*12+2) -> 2975000 | J47: =INDEX(Monthly!$C$83:$AL$83,($R$2-1)*12+3) -> 2950000 | K47: =INDEX(Monthly!$C$83:$AL$83,($R$2-1)*12+4) -> 2925000 | L47: =INDEX(Monthly!$C$83:$AL$83,($R$2-1)*12+5) -> 2900000 | M47: =INDEX(Monthly!$C$83:$AL$83,($R$2-1)*12+6) -> 2875000 | N47: =INDEX(Monthly!$C$83:$AL$83,($R$2-1)*12+7) -> 2850000 | O47: =INDEX(Monthly!$C$83:$AL$83,($R$2-1)*12+8) -> 2825000 | P47: =INDEX(Monthly!$C$83:$AL$83,($R$2-1)*12+9) -> 2800000 | Q47: =INDEX(Monthly!$C$83:$AL$83,($R$2-1)*12+10) -> 2775000 | R47: =INDEX(Monthly!$C$83:$AL$83,($R$2-1)*12+11) -> 2750000 | S47: =INDEX(Monthly!$C$83:$AL$83,($R$2-1)*12+12) -> 2725000
A48: Total liabilities | B48: ='Balance Sheet'!B12 -> 2736847.7 | C48: ='Balance Sheet'!C12 -> 2440264.3 | D48: ='Balance Sheet'!D12 -> 2142918.8 | H48: =INDEX(Monthly!$C$115:$AL$115,($R$2-1)*12+1) -> 3004714.6 | I48: =INDEX(Monthly!$C$115:$AL$115,($R$2-1)*12+2) -> 2980354.3 | J48: =INDEX(Monthly!$C$115:$AL$115,($R$2-1)*12+3) -> 2957384.6 | K48: =INDEX(Monthly!$C$115:$AL$115,($R$2-1)*12+4) -> 2933241.1 | L48: =INDEX(Monthly!$C$115:$AL$115,($R$2-1)*12+5) -> 2909119.1 | M48: =INDEX(Monthly!$C$115:$AL$115,($R$2-1)*12+6) -> 2885017.7 | N48: =INDEX(Monthly!$C$115:$AL$115,($R$2-1)*12+7) -> 2860936.1 | O48: =INDEX(Monthly!$C$115:$AL$115,($R$2-1)*12+8) -> 2836873.4 | P48: =INDEX(Monthly!$C$115:$AL$115,($R$2-1)*12+9) -> 2812829 | Q48: =INDEX(Monthly!$C$115:$AL$115,($R$2-1)*12+10) -> 2788802 | R48: =INDEX(Monthly!$C$115:$AL$115,($R$2-1)*12+11) -> 2764161.4 | S48: =INDEX(Monthly!$C$115:$AL$115,($R$2-1)*12+12) -> 2736847.7
A49: Paid-in capital | B49: ='Balance Sheet'!B13 -> 2100000 | C49: ='Balance Sheet'!C13 -> 2100000 | D49: ='Balance Sheet'!D13 -> 2100000 | H49: =INDEX(Monthly!$C$112:$AL$112,($R$2-1)*12+1) -> 2100000 | I49: =INDEX(Monthly!$C$112:$AL$112,($R$2-1)*12+2) -> 2100000 | J49: =INDEX(Monthly!$C$112:$AL$112,($R$2-1)*12+3) -> 2100000 | K49: =INDEX(Monthly!$C$112:$AL$112,($R$2-1)*12+4) -> 2100000 | L49: =INDEX(Monthly!$C$112:$AL$112,($R$2-1)*12+5) -> 2100000 | M49: =INDEX(Monthly!$C$112:$AL$112,($R$2-1)*12+6) -> 2100000 | N49: =INDEX(Monthly!$C$112:$AL$112,($R$2-1)*12+7) -> 2100000 | O49: =INDEX(Monthly!$C$112:$AL$112,($R$2-1)*12+8) -> 2100000 | P49: =INDEX(Monthly!$C$112:$AL$112,($R$2-1)*12+9) -> 2100000 | Q49: =INDEX(Monthly!$C$112:$AL$112,($R$2-1)*12+10) -> 2100000 | R49: =INDEX(Monthly!$C$112:$AL$112,($R$2-1)*12+11) -> 2100000 | S49: =INDEX(Monthly!$C$112:$AL$112,($R$2-1)*12+12) -> 2100000
A50: Retained earnings | B50: ='Balance Sheet'!B14 -> -709232.33 | C50: ='Balance Sheet'!C14 -> -844797.51 | D50: ='Balance Sheet'!D14 -> -704179.03 | H50: =INDEX(Monthly!$C$113:$AL$113,($R$2-1)*12+1) -> -102437.48 | I50: =INDEX(Monthly!$C$113:$AL$113,($R$2-1)*12+2) -> -199240.34 | J50: =INDEX(Monthly!$C$113:$AL$113,($R$2-1)*12+3) -> -280587.03 | K50: =INDEX(Monthly!$C$113:$AL$113,($R$2-1)*12+4) -> -354763.01 | L50: =INDEX(Monthly!$C$113:$AL$113,($R$2-1)*12+5) -> -421640.55 | M50: =INDEX(Monthly!$C$113:$AL$113,($R$2-1)*12+6) -> -481097.04 | N50: =INDEX(Monthly!$C$113:$AL$113,($R$2-1)*12+7) -> -533014.77 | O50: =INDEX(Monthly!$C$113:$AL$113,($R$2-1)*12+8) -> -577280.74 | P50: =INDEX(Monthly!$C$113:$AL$113,($R$2-1)*12+9) -> -613786.48 | Q50: =INDEX(Monthly!$C$113:$AL$113,($R$2-1)*12+10) -> -642427.84 | R50: =INDEX(Monthly!$C$113:$AL$113,($R$2-1)*12+11) -> -668750.98 | S50: =INDEX(Monthly!$C$113:$AL$113,($R$2-1)*12+12) -> -709232.33
...

Sheet Scenarios
A1: Scenarios — Low / Base / High | H1: =HYPERLINK("#'Cover'!A1","◂ Contents") -> ◂ Contents
A2: All three scenarios calculated side by side, live: change any input and every column updates. Active = the scenario chosen on the Dashboard.
A5: Key drivers
A6: Driver | B6: Low | C6: Base | D6: High | E6: Active
A7: Retail cars per operating day at maturity (year 1) (cars) | B7: =Inputs!$B$7 -> 200 | C7: =Inputs!$C$7 -> 240 | D7: =Inputs!$D$7 -> 280 | E7: =Inputs!$E$7 -> 240
A8: Average price per retail wash (year 1) ($) | B8: =Inputs!$B$28 -> 12 | C8: =Inputs!$C$28 -> 13 | D8: =Inputs!$D$28 -> 14 | E8: =Inputs!$E$28 -> 13
A9: Unlimited members at start (presale or current base) (#) | B9: =Inputs!$B$20 -> 150 | C9: =Inputs!$C$20 -> 250 | D9: =Inputs!$D$20 -> 350 | E9: =Inputs!$E$20 -> 250
A10: Unlimited plan fee per member per month (year 1) ($) | B10: =Inputs!$B$30 -> 32 | C10: =Inputs!$C$30 -> 35 | D10: =Inputs!$D$30 -> 38 | E10: =Inputs!$E$30 -> 35
A11: Members who cancel per month (%) | B11: =Inputs!$B$24 -> 0.05 | C11: =Inputs!$C$24 -> 0.04 | D11: =Inputs!$D$24 -> 0.032 | E11: =Inputs!$E$24 -> 0.04
A12: Site lease or land cost per month ($) | B12: =Inputs!$B$42 -> 30000 | C12: =Inputs!$C$42 -> 30000 | D12: =Inputs!$D$42 -> 30000 | E12: =Inputs!$E$42 -> 30000
A13: Tunnel equipment (month 1) ($) | B13: =Inputs!$B$50 -> 1650000 | C13: =Inputs!$C$50 -> 1650000 | D13: =Inputs!$D$50 -> 1650000 | E13: =Inputs!$E$50 -> 1650000
A14: Equity raised at start ($) | B14: =Inputs!$B$69 -> 2100000 | C14: =Inputs!$C$69 -> 2100000 | D14: =Inputs!$D$69 -> 2100000 | E14: =Inputs!$E$69 -> 2100000
A16: Results by scenario ($'000)
A17: Output | B17: Low | C17: Base | D17: High | E17: Active
A18: Revenue — final year | B18: =D31 -> 1373352.6 | C18: =D32 -> 2170291.6 | D18: =D33 -> 3275560.9 | E18: ='P&L'!D5 -> 2170291.6
A19: Revenue — whole plan | B19: =SUM(B31:D31) -> 3330663.1 | C19: =SUM(B32:D32) -> 5197123 | D19: =SUM(B33:D33) -> 7627129.2 | E19: =SUM('P&L'!$B$5:$D$5) -> 5197123
A20: EBITDA — final year | B20: =D37 -> -24636.3 | C20: =D38 -> 682326.82 | D20: =D39 -> 1692015.6 | E20: ='P&L'!D15 -> 682326.82
A21: EBITDA margin — final year | B21: =IF(B18=0,0,B20/B18) -> -0.017938802 | C21: =IF(C18=0,0,C20/C18) -> 0.31439407 | D21: =IF(D18=0,0,D20/D18) -> 0.51655752 | E21: =IF(E18=0,0,E20/E18) -> 0.31439407
A22: Net income — final year | B22: =D43 -> -566344.63 | C22: =D44 -> 140618.48 | D22: =D45 -> 908742.73 | E22: ='P&L'!D22 -> 140618.48
A23: Net income — whole plan | B23: =SUM(B43:D43) -> -2370448 | C23: =SUM(B44:D44) -> -704179.03 | D23: =SUM(B45:D45) -> 1211876 | E23: =SUM('P&L'!$B$22:$D$22) -> -704179.03
A24: Cash at the end of the plan | B24: =D49 -> -1288612.1 | C24: =D50 -> 376024.31 | D24: =D51 -> 2288697.8 | E24: ='Balance Sheet'!D5 -> 376024.31
A25: Lowest cash balance | B25: =MIN('Scenario calc'!$C$102:$AL$102) -> -1288612.1 | C25: =MIN('Scenario calc'!$C$231:$AL$231) -> 179017.17 | D25: =MIN('Scenario calc'!$C$360:$AL$360) -> 777911.47 | E25: ='Break-even'!B18 -> 179017.17
A26: Lowest cash point (month #) | B26: =MATCH(MIN('Scenario calc'!$C$102:$AL$102),'Scenario calc'!$C$102:$AL$102,0) -> 36 | C26: =MATCH(MIN('Scenario calc'!$C$231:$AL$231),'Scenario calc'!$C$231:$AL$231,0) -> 26 | D26: =MATCH(MIN('Scenario calc'!$C$360:$AL$360),'Scenario calc'!$C$360:$AL$360,0) -> 7 | E26: ='Break-even'!B6 -> 26
A27: Funding required (incl. cash buffer) | B27: =SUMPRODUCT(--('Scenario calc'!$C$6:$AL$6<=B26),'Scenario calc'!$C$74:$AL$74)-SUMPRODUCT(--('Scenario calc'!$C$6:$AL$6<=B26),'Scenario calc'!$C$96:$AL$96)-SUMPRODUCT(--('Scenario calc'!$C$6:$AL$6<=B26),'Scenario calc'!$C$84:$AL$84)+Inputs!$B$84 -> 6669612.1 | C27: =SUMPRODUCT(--('Scenario calc'!$C$135:$AL$135<=C26),'Scenario calc'!$C$203:$AL$203)-SUMPRODUCT(--('Scenario calc'!$C$135:$AL$135<=C26),'Scenario calc'!$C$225:$AL$225)-SUMPRODUCT(--('Scenario calc'!$C$135:$AL$135<=C26),'Scenario calc'!$C$213:$AL$213)+Inputs!$C$84 -> 5201982.8 | D27: =SUMPRODUCT(--('Scenario calc'!$C$264:$AL$264<=D26),'Scenario calc'!$C$332:$AL$332)-SUMPRODUCT(--('Scenario calc'!$C$264:$AL$264<=D26),'Scenario calc'!$C$354:$AL$354)-SUMPRODUCT(--('Scenario calc'!$C$264:$AL$264<=D26),'Scenario calc'!$C$342:$AL$342)+Inputs!$D$84 -> 4603088.5 | E27: ='Break-even'!B12 -> 5201982.8
A29: Revenue by year ($'000)
A30: Scenario | B30: 1 | C30: 2 | D30: 3
A31: Low | B31: =SUMIF('Scenario calc'!$C$7:$AL$7,B$30,'Scenario calc'!$C$39:$AL$39) -> 723753.78 | C31: =SUMIF('Scenario calc'!$C$7:$AL$7,C$30,'Scenario calc'!$C$39:$AL$39) -> 1233556.7 | D31: =SUMIF('Scenario calc'!$C$7:$AL$7,D$30,'Scenario calc'!$C$39:$AL$39) -> 1373352.6
A32: Base | B32: =SUMIF('Scenario calc'!$C$136:$AL$136,B$30,'Scenario calc'!$C$168:$AL$168) -> 1180182.4 | C32: =SUMIF('Scenario calc'!$C$136:$AL$136,C$30,'Scenario calc'!$C$168:$AL$168) -> 1846649 | D32: =SUMIF('Scenario calc'!$C$136:$AL$136,D$30,'Scenario calc'!$C$168:$AL$168) -> 2170291.6
A33: High | B33: =SUMIF('Scenario calc'!$C$265:$AL$265,B$30,'Scenario calc'!$C$297:$AL$297) -> 1713972.3 | C33: =SUMIF('Scenario calc'!$C$265:$AL$265,C$30,'Scenario calc'!$C$297:$AL$297) -> 2637596 | D33: =SUMIF('Scenario calc'!$C$265:$AL$265,D$30,'Scenario calc'!$C$297:$AL$297) -> 3275560.9
A35: EBITDA by year ($'000)
A36: Scenario | B36: 1 | C36: 2 | D36: 3
A37: Low | B37: =SUMIF('Scenario calc'!$C$7:$AL$7,B$36,'Scenario calc'!$C$57:$AL$57) -> -533892.68 | C37: =SUMIF('Scenario calc'!$C$7:$AL$7,C$36,'Scenario calc'!$C$57:$AL$57) -> -120382.6 | D37: =SUMIF('Scenario calc'!$C$7:$AL$7,D$36,'Scenario calc'!$C$57:$AL$57) -> -24636.3
A38: Base | B38: =SUMIF('Scenario calc'!$C$136:$AL$136,B$36,'Scenario calc'!$C$186:$AL$186) -> -123279.21 | C38: =SUMIF('Scenario calc'!$C$136:$AL$136,C$36,'Scenario calc'!$C$186:$AL$186) -> 428309.82 | D38: =SUMIF('Scenario calc'!$C$136:$AL$136,D$36,'Scenario calc'!$C$186:$AL$186) -> 682326.82
A39: High | B39: =SUMIF('Scenario calc'!$C$265:$AL$265,B$36,'Scenario calc'!$C$315:$AL$315) -> 374729.35 | C39: =SUMIF('Scenario calc'!$C$265:$AL$265,C$36,'Scenario calc'!$C$315:$AL$315) -> 1158811.7 | D39: =SUMIF('Scenario calc'!$C$265:$AL$265,D$36,'Scenario calc'!$C$315:$AL$315) -> 1692015.6
A41: Net income by year ($'000)
A42: Scenario | B42: 1 | C42: 2 | D42: 3
A43: Low | B43: =SUMIF('Scenario calc'!$C$7:$AL$7,B$42,'Scenario calc'!$C$66:$AL$66) -> -1119845.8 | C43: =SUMIF('Scenario calc'!$C$7:$AL$7,C$42,'Scenario calc'!$C$66:$AL$66) -> -684257.6 | D43: =SUMIF('Scenario calc'!$C$7:$AL$7,D$42,'Scenario calc'!$C$66:$AL$66) -> -566344.63
A44: Base | B44: =SUMIF('Scenario calc'!$C$136:$AL$136,B$42,'Scenario calc'!$C$195:$AL$195) -> -709232.33 | C44: =SUMIF('Scenario calc'!$C$136:$AL$136,C$42,'Scenario calc'!$C$195:$AL$195) -> -135565.18 | D44: =SUMIF('Scenario calc'!$C$136:$AL$136,D$42,'Scenario calc'!$C$195:$AL$195) -> 140618.48
A45: High | B45: =SUMIF('Scenario calc'!$C$265:$AL$265,B$42,'Scenario calc'!$C$324:$AL$324) -> -211223.77 | C45: =SUMIF('Scenario calc'!$C$265:$AL$265,C$42,'Scenario calc'!$C$324:$AL$324) -> 514357.01 | D45: =SUMIF('Scenario calc'!$C$265:$AL$265,D$42,'Scenario calc'!$C$324:$AL$324) -> 908742.73
A47: Cash at year end by year ($'000)
...

Sheet Break-even
A1: Startup costs, funding need and break-even | F1: =HYPERLINK("#'Cover'!A1","◂ Contents") -> ◂ Contents
A2: Live for the selected scenario. Periods are counted in months from the start of the plan.
A3: Scenario shown | B3: =CHOOSE(Dashboard!$B$4,"Low","Base","High") -> Base
A5: Startup costs & funding need (up to the lowest cash point)
A6: Lowest cash point (month #) | B6: =MATCH(MIN(Monthly!$C$100:$AL$100),Monthly!$C$100:$AL$100,0) -> 26
A7: Capital spending up to the lowest cash point | B7: =SUMPRODUCT(--(Monthly!$C$4:$AL$4<=$B$6),Monthly!$C$72:$AL$72) -> 4180000
A8: Operating cash burn up to the lowest cash point | B8: =-SUMPRODUCT(--(Monthly!$C$4:$AL$4<=$B$6),Monthly!$C$94:$AL$94) -> 115982.83 | D8: Losses and working capital before the business funds itself
A9: Loan repayments up to the lowest cash point | B9: =-SUMPRODUCT(--(Monthly!$C$4:$AL$4<=$B$6),Monthly!$C$82:$AL$82) -> 625000
A10: Total uses of funds | B10: =B7+B8+B9 -> 4920982.8
A11: Minimum cash buffer to keep | B11: =Inputs!$E$84 -> 281000 | D11: Input on the Inputs sheet
A12: Funding required (uses + buffer) | B12: =B10+B11 -> 5201982.8
A14: Equity raised | B14: =Inputs!$E$69 -> 2100000
A15: Loan drawn | B15: =Inputs!$E$70 -> 3000000
A16: Total sources of funds | B16: =B14+B15 -> 5100000
A17: Funding surplus / (shortfall) | B17: =B16-B12 -> -101982.83 | D17: Negative = raise at least this much more
A18: Lowest cash balance in the plan | B18: =MIN(Monthly!$C$100:$AL$100) -> 179017.17 | D18: Equals sources minus uses
A20: Break-even timing
A21: First month with positive EBITDA (month #) | B21: =IFERROR(MATCH(1,Monthly!$C$101:$AL$101,0),"Not within horizon") -> 8
A22: First month with positive net income (month #) | B22: =IFERROR(MATCH(1,Monthly!$C$104:$AL$104,0),"Not within horizon") -> 23
A23: Cash invested paid back (month #) | B23: =IF(MIN(Monthly!$C$106:$AL$106)>=0,"No investment to pay back",IFERROR(MATCH(1,Monthly!$C$108:$AL$108,0),"Not within horizon")) -> Not within horizon | D23: Cumulative operating + investing cash flow back to zero
A25: Annual break-even revenue
A26: Year # | B26: 1 | C26: 2 | D26: 3
B27: Year 1 | C27: Year 2 | D27: Year 3
A28: Revenue | B28: =SUMIF(Monthly!$C$5:$AL$5,B$26,Monthly!$C$37:$AL$37) -> 1180182.4 | C28: =SUMIF(Monthly!$C$5:$AL$5,C$26,Monthly!$C$37:$AL$37) -> 1846649 | D28: =SUMIF(Monthly!$C$5:$AL$5,D$26,Monthly!$C$37:$AL$37) -> 2170291.6
A29: Gross profit | B29: =SUMIF(Monthly!$C$5:$AL$5,B$26,Monthly!$C$46:$AL$46) -> 999760.79 | C29: =SUMIF(Monthly!$C$5:$AL$5,C$26,Monthly!$C$46:$AL$46) -> 1551921 | D29: =SUMIF(Monthly!$C$5:$AL$5,D$26,Monthly!$C$46:$AL$46) -> 1813150.4
A30: Gross margin (contribution) | B30: =IF(B28=0,0,B29/B28) -> 0.84712397 | C30: =IF(C28=0,0,C29/C28) -> 0.84039848 | D30: =IF(D28=0,0,D29/D28) -> 0.83544089
A31: Operating expenses (treated as fixed) | B31: =-SUMIF(Monthly!$C$5:$AL$5,B$26,Monthly!$C$54:$AL$54) -> 1123040 | C31: =-SUMIF(Monthly!$C$5:$AL$5,C$26,Monthly!$C$54:$AL$54) -> 1123611.2 | D31: =-SUMIF(Monthly!$C$5:$AL$5,D$26,Monthly!$C$54:$AL$54) -> 1130823.5
A32: Break-even revenue (EBITDA = 0) | B32: =IF(B30>0,B31/B30,"n/a") -> 1325709.2 | C32: =IF(C30>0,C31/C30,"n/a") -> 1336998.1 | D32: =IF(D30>0,D31/D30,"n/a") -> 1353565
A33: Margin of safety (revenue above break-even) | B33: =IF(AND(ISNUMBER(B32),B28>0),(B28-B32)/B28,"n/a") -> -0.1233087 | C33: =IF(AND(ISNUMBER(C32),C28>0),(C28-C32)/C28,"n/a") -> 0.27598687 | D33: =IF(AND(ISNUMBER(D32),D28>0),(D28-D32)/D28,"n/a") -> 0.37632114
A35: Simplification: cost of sales is treated as variable and operating expenses as fixed, so break-even revenue = operating expenses ÷ gross margin.

Sheet Valuation
A1: Discounted cash flow valuation | H1: =HYPERLINK("#'Cover'!A1","◂ Contents") -> ◂ Contents
A2: Enterprise value at the start of the plan, before the funding raised in period 1. Year-end discounting.
A3: Scenario shown | B3: =CHOOSE(Dashboard!$B$4,"Low","Base","High") -> Base
A5: Assumptions (active scenario, from the Inputs sheet)
A6: Discount rate (WACC) | B6: =Inputs!$E$87 -> 0.25
A7: Terminal growth rate | B7: =Inputs!$E$88 -> 0.02
A8: Exit multiple (EV ÷ final-year EBITDA) | B8: =Inputs!$E$89 -> 4
A9: Tax rate (for the interest tax shield) | B9: =Inputs!$E$81 -> 0.21
A10: Sensitivity step: WACC | B10: =Inputs!$E$90 -> 0.01
A11: Sensitivity step: terminal growth | B11: =Inputs!$E$91 -> 0.005
A13: Free cash flow by year
A14: Year # | B14: 1 | C14: 2 | D14: 3
B15: Year 1 | C15: Year 2 | D15: Year 3
A16: EBITDA | B16: =SUMIF(Monthly!$C$5:$AL$5,B$14,Monthly!$C$55:$AL$55) -> -123279.21 | C16: =SUMIF(Monthly!$C$5:$AL$5,C$14,Monthly!$C$55:$AL$55) -> 428309.82 | D16: =SUMIF(Monthly!$C$5:$AL$5,D$14,Monthly!$C$55:$AL$55) -> 682326.82
A17: Unlevered free cash flow | B17: =SUMIF(Monthly!$C$5:$AL$5,B$14,Monthly!$C$109:$AL$109) -> -4274794.3 | C17: =SUMIF(Monthly!$C$5:$AL$5,C$14,Monthly!$C$109:$AL$109) -> 342565.72 | D17: =SUMIF(Monthly!$C$5:$AL$5,D$14,Monthly!$C$109:$AL$109) -> 601916.73
A18: Discount factor | B18: =1/(1+Inputs!$E$87)^B$14 -> 0.8 | C18: =1/(1+Inputs!$E$87)^C$14 -> 0.64 | D18: =1/(1+Inputs!$E$87)^D$14 -> 0.512
A19: Present value of free cash flow | B19: =B17*B18 -> -3419835.5 | C19: =C17*C18 -> 219242.06 | D19: =D17*D18 -> 308181.36
A21: Enterprise value
B22: Perpetual growth | C22: Exit multiple
A23: Present value of the plan's free cash flows | B23: =SUM($B$19:$D$19) -> -2892412 | C23: =B23 -> -2892412
A24: Final-year free cash flow | final-year EBITDA | B24: =$D$17 -> 601916.73 | C24: =$D$16 -> 682326.82
A25: Terminal value at the end of year 3 | B25: =IF($B$6>$B$7,B24*(1+$B$7)/($B$6-$B$7),0) -> 2669369.8 | C25: =C24*$B$8 -> 2729307.3
A26: Present value of the terminal value | B26: =B25/(1+$B$6)^$D$14 -> 1366717.4 | C26: =C25/(1+$B$6)^$D$14 -> 1397405.3
A27: Enterprise value | B27: =B23+B26 -> -1525694.7 | C27: =C23+C26 -> -1495006.7
A28: Terminal value share of enterprise value | B28: =IF(B27<>0,B26/B27,0) -> -0.89580003 | C28: =IF(C27<>0,C26/C27,0) -> -0.93471507
A29: Cross-check: implied exit multiple | implied perpetual growth | B29: =IF(C24>0,B25/C24,"n/a") -> 3.9121573 | C29: =IF(C25+B24<>0,(C25*$B$6-B24)/(C25+B24),"n/a") -> 0.024138302
A30: Enterprise value — average of the two methods | B30: =AVERAGE(B27,C27) -> -1510350.7
A32: Sensitivity: enterprise value (perpetual growth) by WACC and terminal growth
A33: WACC ↓ · terminal growth → | B33: =$B$7+(-2)*$B$11 -> 0.01 | C33: =$B$7+(-1)*$B$11 -> 0.015 | D33: =$B$7+(0)*$B$11 -> 0.02 | E33: =$B$7+(1)*$B$11 -> 0.025 | F33: =$B$7+(2)*$B$11 -> 0.03
A34: =$B$6+(-2)*$B$10 -> 0.23 | B34: =IF($A34>B$33,SUMPRODUCT($B$17:$D$17/(1+$A34)^$B$14:$D$14)+$D$17*(1+B$33)/($A34-B$33)/(1+$A34)^$D$14,"n/a") -> -1440575.2 | C34: =IF($A34>C$33,SUMPRODUCT($B$17:$D$17/(1+$A34)^$B$14:$D$14)+$D$17*(1+C$33)/($A34-C$33)/(1+$A34)^$D$14,"n/a") -> -1398518.5 | D34: =IF($A34>D$33,SUMPRODUCT($B$17:$D$17/(1+$A34)^$B$14:$D$14)+$D$17*(1+D$33)/($A34-D$33)/(1+$A34)^$D$14,"n/a") -> -1354459.1 | E34: =IF($A34>E$33,SUMPRODUCT($B$17:$D$17/(1+$A34)^$B$14:$D$14)+$D$17*(1+E$33)/($A34-E$33)/(1+$A34)^$D$14,"n/a") -> -1308250.5 | F34: =IF($A34>F$33,SUMPRODUCT($B$17:$D$17/(1+$A34)^$B$14:$D$14)+$D$17*(1+F$33)/($A34-F$33)/(1+$A34)^$D$14,"n/a") -> -1259731.4
A35: =$B$6+(-1)*$B$10 -> 0.24 | B35: =IF($A35>B$33,SUMPRODUCT($B$17:$D$17/(1+$A35)^$B$14:$D$14)+$D$17*(1+B$33)/($A35-B$33)/(1+$A35)^$D$14,"n/a") -> -1522600.2 | C35: =IF($A35>C$33,SUMPRODUCT($B$17:$D$17/(1+$A35)^$B$14:$D$14)+$D$17*(1+C$33)/($A35-C$33)/(1+$A35)^$D$14,"n/a") -> -1484777.4 | D35: =IF($A35>D$33,SUMPRODUCT($B$17:$D$17/(1+$A35)^$B$14:$D$14)+$D$17*(1+D$33)/($A35-D$33)/(1+$A35)^$D$14,"n/a") -> -1445235.5 | E35: =IF($A35>E$33,SUMPRODUCT($B$17:$D$17/(1+$A35)^$B$14:$D$14)+$D$17*(1+E$33)/($A35-E$33)/(1+$A35)^$D$14,"n/a") -> -1403854.4 | F35: =IF($A35>F$33,SUMPRODUCT($B$17:$D$17/(1+$A35)^$B$14:$D$14)+$D$17*(1+F$33)/($A35-F$33)/(1+$A35)^$D$14,"n/a") -> -1360502.8
A36: =$B$6+(0)*$B$10 -> 0.25 | B36: =IF($A36>B$33,SUMPRODUCT($B$17:$D$17/(1+$A36)^$B$14:$D$14)+$D$17*(1+B$33)/($A36-B$33)/(1+$A36)^$D$14,"n/a") -> -1595482.1 | C36: =IF($A36>C$33,SUMPRODUCT($B$17:$D$17/(1+$A36)^$B$14:$D$14)+$D$17*(1+C$33)/($A36-C$33)/(1+$A36)^$D$14,"n/a") -> -1561330.8 | D36: =IF($A36>D$33,SUMPRODUCT($B$17:$D$17/(1+$A36)^$B$14:$D$14)+$D$17*(1+D$33)/($A36-D$33)/(1+$A36)^$D$14,"n/a") -> -1525694.7 | E36: =IF($A36>E$33,SUMPRODUCT($B$17:$D$17/(1+$A36)^$B$14:$D$14)+$D$17*(1+E$33)/($A36-E$33)/(1+$A36)^$D$14,"n/a") -> -1488474.7 | F36: =IF($A36>F$33,SUMPRODUCT($B$17:$D$17/(1+$A36)^$B$14:$D$14)+$D$17*(1+F$33)/($A36-F$33)/(1+$A36)^$D$14,"n/a") -> -1449562.9
A37: =$B$6+(1)*$B$10 -> 0.26 | B37: =IF($A37>B$33,SUMPRODUCT($B$17:$D$17/(1+$A37)^$B$14:$D$14)+$D$17*(1+B$33)/($A37-B$33)/(1+$A37)^$D$14,"n/a") -> -1660373 | C37: =IF($A37>C$33,SUMPRODUCT($B$17:$D$17/(1+$A37)^$B$14:$D$14)+$D$17*(1+C$33)/($A37-C$33)/(1+$A37)^$D$14,"n/a") -> -1629423.1 | D37: =IF($A37>D$33,SUMPRODUCT($B$17:$D$17/(1+$A37)^$B$14:$D$14)+$D$17*(1+D$33)/($A37-D$33)/(1+$A37)^$D$14,"n/a") -> -1597183.7 | E37: =IF($A37>E$33,SUMPRODUCT($B$17:$D$17/(1+$A37)^$B$14:$D$14)+$D$17*(1+E$33)/($A37-E$33)/(1+$A37)^$D$14,"n/a") -> -1563572.3 | F37: =IF($A37>F$33,SUMPRODUCT($B$17:$D$17/(1+$A37)^$B$14:$D$14)+$D$17*(1+F$33)/($A37-F$33)/(1+$A37)^$D$14,"n/a") -> -1528499.6
A38: =$B$6+(2)*$B$10 -> 0.27 | B38: =IF($A38>B$33,SUMPRODUCT($B$17:$D$17/(1+$A38)^$B$14:$D$14)+$D$17*(1+B$33)/($A38-B$33)/(1+$A38)^$D$14,"n/a") -> -1718245.9 | C38: =IF($A38>C$33,SUMPRODUCT($B$17:$D$17/(1+$A38)^$B$14:$D$14)+$D$17*(1+C$33)/($A38-C$33)/(1+$A38)^$D$14,"n/a") -> -1690101.9 | D38: =IF($A38>D$33,SUMPRODUCT($B$17:$D$17/(1+$A38)^$B$14:$D$14)+$D$17*(1+D$33)/($A38-D$33)/(1+$A38)^$D$14,"n/a") -> -1660832.2 | E38: =IF($A38>E$33,SUMPRODUCT($B$17:$D$17/(1+$A38)^$B$14:$D$14)+$D$17*(1+E$33)/($A38-E$33)/(1+$A38)^$D$14,"n/a") -> -1630367.7 | F38: =IF($A38>F$33,SUMPRODUCT($B$17:$D$17/(1+$A38)^$B$14:$D$14)+$D$17*(1+F$33)/($A38-F$33)/(1+$A38)^$D$14,"n/a") -> -1598634
A40: Free cash flow = operating cash flow + interest × (1 − tax rate) − capital spending. Cells marked n/a: WACC not above growth.

Sheet Sources & Uses
A1: Sources and uses of funds | E1: =HYPERLINK("#'Cover'!A1","◂ Contents") -> ◂ Contents
A2: Live for the selected scenario. Where the money comes from and where it goes in the period set below.
A3: Scenario shown | B3: =CHOOSE(Dashboard!$B$4,"Low","Base","High") -> Base
A5: Funding structure ($'000) — raised at the start of the plan
B6: Amount | C6: Share
A7: Equity | B7: =Inputs!$E$69 -> 2100000 | C7: =IF($B$9=0,0,B7/$B$9) -> 0.41176471
A8: Debt (loan) | B8: =Inputs!$E$70 -> 3000000 | C8: =IF($B$9=0,0,B8/$B$9) -> 0.58823529
A9: Total funding | B9: =B7+B8 -> 5100000 | C9: =IF(B9=0,0,1) -> 1
A10: Gearing (debt ÷ equity) | B10: =IF(B7<=0,IF(B8>0,"n/a",0),B8/B7) -> 1.4285714 | D10: n/a: debt without positive equity
A11: Funding required by the plan (Break-even sheet) | B11: ='Break-even'!B12 -> 5201982.8
A12: Funding surplus / (shortfall) | B12: ='Break-even'!B17 -> -101982.83
A14: ="Sources and uses of cash in the first "&$B$16&IF($B$16=1," month"," months")&" ($'000)" -> Sources and uses of cash in the first 12 months ($'000)
A15: Period covered (months from the start) | B15: 12 | D15: 1 to 36 (capped)
A16: Months used | B16: =MIN(36,MAX(1,ROUND(B15,0))) -> 12
A17: Sources | B17: Amount | C17: Share
A18: Equity raised | B18: =SUMPRODUCT(--(Monthly!$C$4:$AL$4<=$B$16),Monthly!$C$96:$AL$96) -> 2100000 | C18: =IF($B$21=0,0,B18/$B$21) -> 0.41176471
A19: Loan drawdowns | B19: =SUMPRODUCT(--(Monthly!$C$4:$AL$4<=$B$16),Monthly!$C$81:$AL$81) -> 3000000 | C19: =IF($B$21=0,0,B19/$B$21) -> 0.58823529
A20: Cash generated by operations | B20: =MAX(0,SUMPRODUCT(--(Monthly!$C$4:$AL$4<=$B$16),Monthly!$C$94:$AL$94)) -> 0 | C20: =IF($B$21=0,0,B20/$B$21) -> 0
A21: Total sources | B21: =SUM(B18:B20) -> 5100000 | C21: =IF(B21=0,0,1) -> 1
A23: Uses | B23: Amount | C23: Share
A24: Cash used by operations | B24: =MAX(0,-SUMPRODUCT(--(Monthly!$C$4:$AL$4<=$B$16),Monthly!$C$94:$AL$94)) -> 367780.64 | C24: =IF($B$28=0,0,B24/$B$28) -> 0.07211385
A25: Capital spending | B25: =-SUMPRODUCT(--(Monthly!$C$4:$AL$4<=$B$16),Monthly!$C$95:$AL$95) -> 4100000 | C25: =IF($B$28=0,0,B25/$B$28) -> 0.80392157
A26: Loan repayments | B26: =-SUMPRODUCT(--(Monthly!$C$4:$AL$4<=$B$16),Monthly!$C$82:$AL$82) -> 275000 | C26: =IF($B$28=0,0,B26/$B$28) -> 0.053921569
A27: Cash at the end of the period | B27: =INDEX(Monthly!$C$100:$AL$100,$B$16) -> 357219.36 | C27: =IF($B$28=0,0,B27/$B$28) -> 0.070043013
A28: Total uses | B28: =SUM(B24:B27) -> 5100000 | C28: =IF(B28=0,0,1) -> 1
A29: Sources − uses (must be 0; opening cash is 0) | B29: =B21-B28 -> 0

Sheet KPIs
A1: KPIs & ratios | G1: =HYPERLINK("#'Cover'!A1","◂ Contents") -> ◂ Contents
A2: Car wash financial model (planning) — industry metrics and financial ratios for the active scenario
A4: Financial ratios
B5: 1 | C5: 2 | D5: 3 | E5: Target
A6: Revenue growth | B6: =IF(N('P&L'!A5)<=0,"n/a",'P&L'!B5/'P&L'!A5-1) -> n/a | C6: =IF(N('P&L'!B5)<=0,"n/a",'P&L'!C5/'P&L'!B5-1) -> 0.56471494 | D6: =IF(N('P&L'!C5)<=0,"n/a",'P&L'!D5/'P&L'!C5-1) -> 0.17525939
A7: Gross margin | B7: =IF('P&L'!B5<=0,"n/a",'P&L'!B7/'P&L'!B5) -> 0.84712397 | C7: =IF('P&L'!C5<=0,"n/a",'P&L'!C7/'P&L'!C5) -> 0.84039848 | D7: =IF('P&L'!D5<=0,"n/a",'P&L'!D7/'P&L'!D5) -> 0.83544089
A8: EBITDA margin | B8: =IF('P&L'!B5<=0,"n/a",'P&L'!B15/'P&L'!B5) -> -0.10445776 | C8: =IF('P&L'!C5<=0,"n/a",'P&L'!C15/'P&L'!C5) -> 0.23193894 | D8: =IF('P&L'!D5<=0,"n/a",'P&L'!D15/'P&L'!D5) -> 0.31439407
A9: Net margin | B9: =IF('P&L'!B5<=0,"n/a",'P&L'!B22/'P&L'!B5) -> -0.60095146 | C9: =IF('P&L'!C5<=0,"n/a",'P&L'!C22/'P&L'!C5) -> -0.073411448 | D9: =IF('P&L'!D5<=0,"n/a",'P&L'!D22/'P&L'!D5) -> 0.064792437
A10: Payroll, % of revenue | B10: =IF('P&L'!B5<=0,"n/a",-SUMIF(Headcount!$C$5:$AL$5,B$5,Headcount!$C$15:$AL$15)/'P&L'!B5) -> 0.3720103 | C10: =IF('P&L'!C5<=0,"n/a",-SUMIF(Headcount!$C$5:$AL$5,C$5,Headcount!$C$15:$AL$15)/'P&L'!C5) -> 0.24488205 | D10: =IF('P&L'!D5<=0,"n/a",-SUMIF(Headcount!$C$5:$AL$5,D$5,Headcount!$C$15:$AL$15)/'P&L'!D5) -> 0.21461519
A11: Marketing, % of revenue | B11: =IF('P&L'!B5<=0,"n/a",-'P&L'!B13/'P&L'!B5) -> 0.12201504 | C11: =IF('P&L'!C5<=0,"n/a",-'P&L'!C13/'P&L'!C5) -> 0.062383268 | D11: =IF('P&L'!D5<=0,"n/a",-'P&L'!D13/'P&L'!D5) -> 0.04246434
A12: Operating expenses, % of revenue | B12: =IF('P&L'!B5<=0,"n/a",-'P&L'!B14/'P&L'!B5) -> 0.95158173 | C12: =IF('P&L'!C5<=0,"n/a",-'P&L'!C14/'P&L'!C5) -> 0.60845953 | D12: =IF('P&L'!D5<=0,"n/a",-'P&L'!D14/'P&L'!D5) -> 0.52104682
A13: Current ratio (current assets ÷ current liabilities) | B13: =IF(('Balance Sheet'!B12-'Balance Sheet'!B11)<=0,"n/a",('Balance Sheet'!B5+'Balance Sheet'!B6+'Balance Sheet'!B7)/('Balance Sheet'!B12-'Balance Sheet'!B11)) -> 31.169065 | C13: =IF(('Balance Sheet'!C12-'Balance Sheet'!C11)<=0,"n/a",('Balance Sheet'!C5+'Balance Sheet'!C6+'Balance Sheet'!C7)/('Balance Sheet'!C12-'Balance Sheet'!C11)) -> 15.862711 | D13: =IF(('Balance Sheet'!D12-'Balance Sheet'!D11)<=0,"n/a",('Balance Sheet'!D5+'Balance Sheet'!D6+'Balance Sheet'!D7)/('Balance Sheet'!D12-'Balance Sheet'!D11)) -> 21.97354
A14: Debt ÷ equity (loan ÷ total equity) | B14: =IF('Balance Sheet'!B15<=0,"n/a",'Balance Sheet'!B11/'Balance Sheet'!B15) -> 1.9593495 | C14: =IF('Balance Sheet'!C15<=0,"n/a",'Balance Sheet'!C11/'Balance Sheet'!C15) -> 1.9319592 | D14: =IF('Balance Sheet'!D15<=0,"n/a",'Balance Sheet'!D11/'Balance Sheet'!D15) -> 1.5224015
A15: Return on assets (net income ÷ year-end assets) | B15: =IF('Balance Sheet'!B9<=0,"n/a",'P&L'!B22/'Balance Sheet'!B9) -> -0.17182617 | C15: =IF('Balance Sheet'!C9<=0,"n/a",'P&L'!C22/'Balance Sheet'!C9) -> -0.036684182 | D15: =IF('Balance Sheet'!D9<=0,"n/a",'P&L'!D22/'Balance Sheet'!D9) -> 0.039736881
