Workbook

Sheet Cover
B2: Car wash financial model (planning)
B3: 5-year financial model · monthly detail · Low / Base / High scenarios · US dollars · Full plan
B5: Purpose | D5: Revenue and profit plan
B6: Active scenario | D6: =Dashboard!C4&" (change it on the Dashboard, cell B4)" -> Base (change it on the Dashboard, cell B4)
B7: Model checks | D7: =Checks!B25 -> PASS
B8: Prepared | D8: 21 October 2026
B10: Contents
C11: PRESENTATION
B12: 1 | C12: =HYPERLINK("#Dashboard!A1","Dashboard") -> Dashboard | D12: Scenario switch, key numbers, core financials
B13: 2 | C13: =HYPERLINK("#Summary!A1","Summary") -> Summary | D13: Income statement, cash flow and balance sheet — every year and any year by month
B14: 3 | C14: =HYPERLINK("#Scenarios!A1","Scenarios") -> Scenarios | D14: Low / Base / High side by side: drivers, outputs, charts
B15: 4 | C15: =HYPERLINK("#'Break-even'!A1","Break-even") -> Break-even | D15: Startup costs, funding need, break-even timing and revenue
B16: 5 | C16: =HYPERLINK("#Valuation!A1","Valuation") -> Valuation | D16: Free cash flow, DCF (perpetual growth and exit multiple), WACC × growth sensitivity
B17: 6 | C17: =HYPERLINK("#'Sources & Uses'!A1","Sources & Uses") -> Sources & Uses | D17: Funding structure, sources and uses of cash for the first months
B18: 7 | C18: =HYPERLINK("#KPIs!A1","KPIs") -> KPIs | D18: Financial ratios, DuPont analysis, industry metrics
C19: INPUTS
B20: 8 | C20: =HYPERLINK("#Inputs!A1","Inputs") -> Inputs | D20: Every assumption, Low / Base / High, with units and comments
C21: STATEMENTS
B22: 9 | C22: =HYPERLINK("#'P&L'!A1","P&L") -> P&L | D22: Annual profit & loss
B23: 10 | C23: =HYPERLINK("#'Cash Flow'!A1","Cash Flow") -> Cash Flow | D23: Annual cash flow statement
B24: 11 | C24: =HYPERLINK("#'Balance Sheet'!A1","Balance Sheet") -> Balance Sheet | D24: Balance sheet at year end
C25: CALCULATIONS
B26: 12 | C26: =HYPERLINK("#Monthly!A1","Monthly") -> Monthly | D26: Month-by-month engine of the model
B27: 13 | C27: =HYPERLINK("#Headcount!A1","Headcount") -> Headcount | D27: Team and payroll
B28: 14 | C28: =HYPERLINK("#'Scenario calc'!A1","Scenario calc") -> Scenario calc | D28: Low, Base and High calculated side by side for the Scenarios sheet
C29: CONTROL
B30: 15 | C30: =HYPERLINK("#Checks!A1","Checks") -> Checks | D30: Live integrity checks and the overall verdict
B32: How to read this file
C33: 1000 | D33: Input you can change — yellow cell with a blue figure (Inputs sheet and the view switches)
C34: 1000 | D34: Formula — calculated, do not overwrite
C35: 1000 | D35: Link to another sheet
C36: 1000 | D36: Active value the model uses (follows the scenario)

Sheet Dashboard
A1: Dashboard | W1: =HYPERLINK("#'Cover'!A1","◂ Contents") -> ◂ Contents
A2: Car wash financial model (planning)
A4: Active scenario | B4: 2 | C4: =CHOOSE(B4,"Low","Base","High") -> Base | D4: 1 = Low · 2 = Base · 3 = High — every sheet follows this cell | S4: Model checks | T4: =Checks!B25 -> PASS
A6: REVENUE · YEAR 5 | C6: EBITDA MARGIN · YEAR 5 | H6: NET INCOME · YEAR 5 | L6: LOWEST CASH BALANCE | P6: FUNDING REQUIRED | T6: ENTERPRISE VALUE (DCF)
A7: =F12 -> 2440877.2 | C7: =F17 -> 0.35310317 | H7: =F18 -> 364506.48 | L7: =F39 -> 131554.54 | P7: =F37 -> 5249445.5 | T7: =F44 -> -1277795.6
A8: =IF(AND(B12>0,F12>=0),(F12/B12)^(1/4)-1,"CAGR n/a") -> 0.19922093 | C8: =F16 -> 861881.48 | H8: =F19 -> 0.14933422 | L8: ='Break-even'!B6 -> 26 | P8: =IF(F38>=0,"Covered by funding raised",-F38) -> 149445.46 | T8: Average of 2 methods
A10: Core financials ($'000) — active scenario
B11: 1 | C11: 2 | D11: 3 | E11: 4 | F11: 5
A12: Revenue | B12: =SUMIF(Monthly!$C$5:$BJ$5,B$11,Monthly!$C$37:$BJ$37) -> 1180182.4 | C12: =SUMIF(Monthly!$C$5:$BJ$5,C$11,Monthly!$C$37:$BJ$37) -> 1805881.5 | D12: =SUMIF(Monthly!$C$5:$BJ$5,D$11,Monthly!$C$37:$BJ$37) -> 2080276.6 | E12: =SUMIF(Monthly!$C$5:$BJ$5,E$11,Monthly!$C$37:$BJ$37) -> 2282431.1 | F12: =SUMIF(Monthly!$C$5:$BJ$5,F$11,Monthly!$C$37:$BJ$37) -> 2440877.2
A13: Gross profit | B13: =SUMIF(Monthly!$C$5:$BJ$5,B$11,Monthly!$C$46:$BJ$46) -> 999760.79 | C13: =SUMIF(Monthly!$C$5:$BJ$5,C$11,Monthly!$C$46:$BJ$46) -> 1517202.4 | D13: =SUMIF(Monthly!$C$5:$BJ$5,D$11,Monthly!$C$46:$BJ$46) -> 1736853.9 | E13: =SUMIF(Monthly!$C$5:$BJ$5,E$11,Monthly!$C$46:$BJ$46) -> 1897646.6 | F13: =SUMIF(Monthly!$C$5:$BJ$5,F$11,Monthly!$C$46:$BJ$46) -> 2022782
A14: Gross margin | B14: =IF(B12=0,0,B13/B12) -> 0.84712397 | C14: =IF(C12=0,0,C13/C12) -> 0.84014507 | D14: =IF(D12=0,0,D13/D12) -> 0.83491491 | E14: =IF(E12=0,0,E13/E12) -> 0.83141464 | F14: =IF(F12=0,0,F13/F12) -> 0.82871109
A15: Operating expenses | B15: =SUMIF(Monthly!$C$5:$BJ$5,B$11,Monthly!$C$54:$BJ$54) -> -1123040 | C15: =SUMIF(Monthly!$C$5:$BJ$5,C$11,Monthly!$C$54:$BJ$54) -> -1123611.2 | D15: =SUMIF(Monthly!$C$5:$BJ$5,D$11,Monthly!$C$54:$BJ$54) -> -1130823.5 | E15: =SUMIF(Monthly!$C$5:$BJ$5,E$11,Monthly!$C$54:$BJ$54) -> -1143551.4 | F15: =SUMIF(Monthly!$C$5:$BJ$5,F$11,Monthly!$C$54:$BJ$54) -> -1160900.5
A16: EBITDA | B16: =SUMIF(Monthly!$C$5:$BJ$5,B$11,Monthly!$C$55:$BJ$55) -> -123279.21 | C16: =SUMIF(Monthly!$C$5:$BJ$5,C$11,Monthly!$C$55:$BJ$55) -> 393591.21 | D16: =SUMIF(Monthly!$C$5:$BJ$5,D$11,Monthly!$C$55:$BJ$55) -> 606030.41 | E16: =SUMIF(Monthly!$C$5:$BJ$5,E$11,Monthly!$C$55:$BJ$55) -> 754095.19 | F16: =SUMIF(Monthly!$C$5:$BJ$5,F$11,Monthly!$C$55:$BJ$55) -> 861881.48
A17: EBITDA margin | B17: =IF(B12=0,0,B16/B12) -> -0.10445776 | C17: =IF(C12=0,0,C16/C12) -> 0.21794964 | D17: =IF(D12=0,0,D16/D12) -> 0.29132204 | E17: =IF(E12=0,0,E16/E12) -> 0.33039122 | F17: =IF(F12=0,0,F16/F12) -> 0.35310317
A18: Net income | B18: =SUMIF(Monthly!$C$5:$BJ$5,B$11,Monthly!$C$64:$BJ$64) -> -709232.33 | C18: =SUMIF(Monthly!$C$5:$BJ$5,C$11,Monthly!$C$64:$BJ$64) -> -170283.79 | D18: =SUMIF(Monthly!$C$5:$BJ$5,D$11,Monthly!$C$64:$BJ$64) -> 64322.078 | E18: =SUMIF(Monthly!$C$5:$BJ$5,E$11,Monthly!$C$64:$BJ$64) -> 234553.52 | F18: =SUMIF(Monthly!$C$5:$BJ$5,F$11,Monthly!$C$64:$BJ$64) -> 364506.48
A19: Net margin | B19: =IF(B12=0,0,B18/B12) -> -0.60095146 | C19: =IF(C12=0,0,C18/C12) -> -0.094294003 | D19: =IF(D12=0,0,D18/D12) -> 0.030919964 | E19: =IF(E12=0,0,E18/E12) -> 0.10276478 | F19: =IF(F12=0,0,F18/F12) -> 0.14933422
A20: Operating cash flow | B20: =SUMIF(Monthly!$C$5:$BJ$5,B$11,Monthly!$C$92:$BJ$92) -> -369557.79 | C20: =SUMIF(Monthly!$C$5:$BJ$5,C$11,Monthly!$C$92:$BJ$92) -> 174478.45 | D20: =SUMIF(Monthly!$C$5:$BJ$5,D$11,Monthly!$C$92:$BJ$92) -> 412515.86 | E20: =SUMIF(Monthly!$C$5:$BJ$5,E$11,Monthly!$C$92:$BJ$92) -> 586141.12 | F20: =SUMIF(Monthly!$C$5:$BJ$5,F$11,Monthly!$C$92:$BJ$92) -> 719465.28
A21: Investing cash flow | B21: =SUMIF(Monthly!$C$5:$BJ$5,B$11,Monthly!$C$93:$BJ$93) -> -4100000 | C21: =SUMIF(Monthly!$C$5:$BJ$5,C$11,Monthly!$C$93:$BJ$93) -> -40000 | D21: =SUMIF(Monthly!$C$5:$BJ$5,D$11,Monthly!$C$93:$BJ$93) -> -40000 | E21: =SUMIF(Monthly!$C$5:$BJ$5,E$11,Monthly!$C$93:$BJ$93) -> -40000 | F21: =SUMIF(Monthly!$C$5:$BJ$5,F$11,Monthly!$C$93:$BJ$93) -> -40000
A22: Financing cash flow | B22: =SUMIF(Monthly!$C$5:$BJ$5,B$11,Monthly!$C$95:$BJ$95) -> 4825000 | C22: =SUMIF(Monthly!$C$5:$BJ$5,C$11,Monthly!$C$95:$BJ$95) -> -300000 | D22: =SUMIF(Monthly!$C$5:$BJ$5,D$11,Monthly!$C$95:$BJ$95) -> -300000 | E22: =SUMIF(Monthly!$C$5:$BJ$5,E$11,Monthly!$C$95:$BJ$95) -> -300000 | F22: =SUMIF(Monthly!$C$5:$BJ$5,F$11,Monthly!$C$95:$BJ$95) -> -300000
A23: Net change in cash | B23: =SUMIF(Monthly!$C$5:$BJ$5,B$11,Monthly!$C$96:$BJ$96) -> 355442.21 | C23: =SUMIF(Monthly!$C$5:$BJ$5,C$11,Monthly!$C$96:$BJ$96) -> -165521.55 | D23: =SUMIF(Monthly!$C$5:$BJ$5,D$11,Monthly!$C$96:$BJ$96) -> 72515.855 | E23: =SUMIF(Monthly!$C$5:$BJ$5,E$11,Monthly!$C$96:$BJ$96) -> 246141.12 | F23: =SUMIF(Monthly!$C$5:$BJ$5,F$11,Monthly!$C$96:$BJ$96) -> 379465.28
A24: Year-end cash | B24: =INDEX(Monthly!$C$98:$BJ$98,B$11*12) -> 355442.21 | C24: =INDEX(Monthly!$C$98:$BJ$98,C$11*12) -> 189920.66 | D24: =INDEX(Monthly!$C$98:$BJ$98,D$11*12) -> 262436.52 | E24: =INDEX(Monthly!$C$98:$BJ$98,E$11*12) -> 508577.64 | F24: =INDEX(Monthly!$C$98:$BJ$98,F$11*12) -> 888042.92
A26: Car wash metrics
B27: 1 | C27: 2 | D27: 3 | E27: 4 | F27: 5
A28: Unlimited members (year end) | B28: =KPIs!B29 -> 972.08918 | C28: =KPIs!C29 -> 1644.3434 | D28: =KPIs!D29 -> 2081.656 | E28: =KPIs!E29 -> 2376.2884 | F28: =KPIs!F29 -> 2584.8337
A29: Washes per operating day | B29: =KPIs!B37 -> 255.65215 | C29: =KPIs!C37 -> 401.36881 | D29: =KPIs!D37 -> 466.96809 | E29: =KPIs!E37 -> 510.31287 | F29: =KPIs!F37 -> 540.17969
A30: Tunnel capacity used | B30: =KPIs!B39 -> 0.30183253 | C30: =KPIs!C39 -> 0.47387108 | D30: =KPIs!D39 -> 0.55132006 | E30: =KPIs!E39 -> 0.60249454 | F30: =KPIs!F39 -> 0.63775642
A31: Revenue per wash | B31: =KPIs!B45 -> 13.265403 | C31: =KPIs!C45 -> 12.929043 | D31: =KPIs!D45 -> 12.801317 | E31: =KPIs!E45 -> 12.852331 | F31: =KPIs!F45 -> 12.984596
A32: Team (FTE, year end) | B32: =INDEX(Headcount!$C$10:$BJ$10,B$27*12) -> 11 | C32: =INDEX(Headcount!$C$10:$BJ$10,C$27*12) -> 11 | D32: =INDEX(Headcount!$C$10:$BJ$10,D$27*12) -> 11 | E32: =INDEX(Headcount!$C$10:$BJ$10,E$27*12) -> 11 | F32: =INDEX(Headcount!$C$10:$BJ$10,F$27*12) -> 11
A34: Funding & valuation ($'000) — active scenario
A35: Equity raised | F35: =Inputs!$E$67 -> 2100000
A36: Loan drawn | F36: =Inputs!$E$68 -> 3000000
A37: Funding required (incl. cash buffer) | F37: ='Break-even'!B12 -> 5249445.5
A38: Funding surplus / (shortfall) | F38: ='Break-even'!B17 -> -149445.46
A39: ="Lowest cash balance (month "&'Break-even'!B6&")" -> Lowest cash balance (month 26) | F39: ='Break-even'!B18 -> 131554.54
A40: First month with positive EBITDA | F40: ='Break-even'!B21 -> 8
A41: Cash invested paid back | F41: ='Break-even'!B23 -> Not within horizon
A42: Enterprise value — perpetual growth | F42: =Valuation!B27 -> -1267217.7
A43: Enterprise value — exit multiple | F43: =Valuation!C27 -> -1288373.6
A44: Enterprise value — average | F44: =Valuation!B30 -> -1277795.6

Sheet Summary
A1: Financial statements summary | U1: =HYPERLINK("#'Cover'!A1","◂ Contents") -> ◂ Contents
A2: Car wash financial model (planning) | P2: Select detailed year: | R2: 1
A5: Income statement ($'000) — by year | H5: ="Income statement ($'000) — Year "&$R$2&", by month" -> Income statement ($'000) — Year 1, by month
B6: 1 | C6: 2 | D6: 3 | E6: 4 | F6: 5 | H6: =INDEX(Monthly!$C$4:$BJ$4,($R$2-1)*12+1) -> 1 | I6: =INDEX(Monthly!$C$4:$BJ$4,($R$2-1)*12+2) -> 2 | J6: =INDEX(Monthly!$C$4:$BJ$4,($R$2-1)*12+3) -> 3 | K6: =INDEX(Monthly!$C$4:$BJ$4,($R$2-1)*12+4) -> 4 | L6: =INDEX(Monthly!$C$4:$BJ$4,($R$2-1)*12+5) -> 5 | M6: =INDEX(Monthly!$C$4:$BJ$4,($R$2-1)*12+6) -> 6 | N6: =INDEX(Monthly!$C$4:$BJ$4,($R$2-1)*12+7) -> 7 | O6: =INDEX(Monthly!$C$4:$BJ$4,($R$2-1)*12+8) -> 8 | P6: =INDEX(Monthly!$C$4:$BJ$4,($R$2-1)*12+9) -> 9 | Q6: =INDEX(Monthly!$C$4:$BJ$4,($R$2-1)*12+10) -> 10 | R6: =INDEX(Monthly!$C$4:$BJ$4,($R$2-1)*12+11) -> 11 | S6: =INDEX(Monthly!$C$4:$BJ$4,($R$2-1)*12+12) -> 12
A7: Revenue | B7: ='P&L'!B5 -> 1180182.4 | C7: ='P&L'!C5 -> 1805881.5 | D7: ='P&L'!D5 -> 2080276.6 | E7: ='P&L'!E5 -> 2282431.1 | F7: ='P&L'!F5 -> 2440877.2 | H7: =INDEX(Monthly!$C$37:$BJ$37,($R$2-1)*12+1) -> 47943.358 | I7: =INDEX(Monthly!$C$37:$BJ$37,($R$2-1)*12+2) -> 54448.936 | J7: =INDEX(Monthly!$C$37:$BJ$37,($R$2-1)*12+3) -> 72773.402 | K7: =INDEX(Monthly!$C$37:$BJ$37,($R$2-1)*12+4) -> 81051.899 | L7: =INDEX(Monthly!$C$37:$BJ$37,($R$2-1)*12+5) -> 89490.276 | M7: =INDEX(Monthly!$C$37:$BJ$37,($R$2-1)*12+6) -> 98082.139 | N7: =INDEX(Monthly!$C$37:$BJ$37,($R$2-1)*12+7) -> 106821.35 | O7: =INDEX(Monthly!$C$37:$BJ$37,($R$2-1)*12+8) -> 115702.01 | P7: =INDEX(Monthly!$C$37:$BJ$37,($R$2-1)*12+9) -> 124718.46 | Q7: =INDEX(Monthly!$C$37:$BJ$37,($R$2-1)*12+10) -> 133865.28 | R7: =INDEX(Monthly!$C$37:$BJ$37,($R$2-1)*12+11) -> 136545.55 | S7: =INDEX(Monthly!$C$37:$BJ$37,($R$2-1)*12+12) -> 118739.73
A8: Cost of sales | B8: ='P&L'!B6 -> -180421.6 | C8: ='P&L'!C6 -> -288679.06 | D8: ='P&L'!D6 -> -343422.65 | E8: ='P&L'!E6 -> -384784.48 | F8: ='P&L'!F6 -> -418095.19 | H8: =INDEX(Monthly!$C$45:$BJ$45,($R$2-1)*12+1) -> -7071.9457 | I8: =INDEX(Monthly!$C$45:$BJ$45,($R$2-1)*12+2) -> -8031.4488 | J8: =INDEX(Monthly!$C$45:$BJ$45,($R$2-1)*12+3) -> -11076.835 | K8: =INDEX(Monthly!$C$45:$BJ$45,($R$2-1)*12+4) -> -12361.697 | L8: =INDEX(Monthly!$C$45:$BJ$45,($R$2-1)*12+5) -> -13678.718 | M8: =INDEX(Monthly!$C$45:$BJ$45,($R$2-1)*12+6) -> -15026.614 | N8: =INDEX(Monthly!$C$45:$BJ$45,($R$2-1)*12+7) -> -16404.147 | O8: =INDEX(Monthly!$C$45:$BJ$45,($R$2-1)*12+8) -> -17810.134 | P8: =INDEX(Monthly!$C$45:$BJ$45,($R$2-1)*12+9) -> -19243.436 | Q8: =INDEX(Monthly!$C$45:$BJ$45,($R$2-1)*12+10) -> -20702.96 | R8: =INDEX(Monthly!$C$45:$BJ$45,($R$2-1)*12+11) -> -21242.097 | S8: =INDEX(Monthly!$C$45:$BJ$45,($R$2-1)*12+12) -> -17771.565
A9: Gross profit | B9: ='P&L'!B7 -> 999760.79 | C9: ='P&L'!C7 -> 1517202.4 | D9: ='P&L'!D7 -> 1736853.9 | E9: ='P&L'!E7 -> 1897646.6 | F9: ='P&L'!F7 -> 2022782 | H9: =INDEX(Monthly!$C$46:$BJ$46,($R$2-1)*12+1) -> 40871.412 | I9: =INDEX(Monthly!$C$46:$BJ$46,($R$2-1)*12+2) -> 46417.487 | J9: =INDEX(Monthly!$C$46:$BJ$46,($R$2-1)*12+3) -> 61696.567 | K9: =INDEX(Monthly!$C$46:$BJ$46,($R$2-1)*12+4) -> 68690.202 | L9: =INDEX(Monthly!$C$46:$BJ$46,($R$2-1)*12+5) -> 75811.558 | M9: =INDEX(Monthly!$C$46:$BJ$46,($R$2-1)*12+6) -> 83055.526 | N9: =INDEX(Monthly!$C$46:$BJ$46,($R$2-1)*12+7) -> 90417.201 | O9: =INDEX(Monthly!$C$46:$BJ$46,($R$2-1)*12+8) -> 97891.875 | P9: =INDEX(Monthly!$C$46:$BJ$46,($R$2-1)*12+9) -> 105475.03 | Q9: =INDEX(Monthly!$C$46:$BJ$46,($R$2-1)*12+10) -> 113162.32 | R9: =INDEX(Monthly!$C$46:$BJ$46,($R$2-1)*12+11) -> 115303.45 | S9: =INDEX(Monthly!$C$46:$BJ$46,($R$2-1)*12+12) -> 100968.16
A10: Gross margin | B10: ='P&L'!B8 -> 0.84712397 | C10: ='P&L'!C8 -> 0.84014507 | D10: ='P&L'!D8 -> 0.83491491 | E10: ='P&L'!E8 -> 0.83141464 | F10: ='P&L'!F8 -> 0.82871109 | H10: =IF(H7=0,0,H9/H7) -> 0.85249373 | I10: =IF(I7=0,0,I9/I7) -> 0.85249576 | J10: =IF(J7=0,0,J9/J7) -> 0.84779006 | K10: =IF(K7=0,0,K9/K7) -> 0.84748418 | L10: =IF(L7=0,0,L9/L7) -> 0.84714855 | M10: =IF(M7=0,0,M9/M7) -> 0.84679562 | N10: =IF(N7=0,0,N9/N7) -> 0.84643381 | O10: =IF(O7=0,0,O9/O7) -> 0.84606893 | ... S10: =IF(S7=0,0,S9/S7) -> 0.85033177
A11: Total operating expenses | B11: ='P&L'!B14 -> -1123040 | C11: ='P&L'!C14 -> -1123611.2 | D11: ='P&L'!D14 -> -1130823.5 | E11: ='P&L'!E14 -> -1143551.4 | F11: ='P&L'!F14 -> -1160900.5 | H11: =INDEX(Monthly!$C$54:$BJ$54,($R$2-1)*12+1) -> -93586.667 | I11: =INDEX(Monthly!$C$54:$BJ$54,($R$2-1)*12+2) -> -93586.667 | J11: =INDEX(Monthly!$C$54:$BJ$54,($R$2-1)*12+3) -> -93586.667 | K11: =INDEX(Monthly!$C$54:$BJ$54,($R$2-1)*12+4) -> -93586.667 | L11: =INDEX(Monthly!$C$54:$BJ$54,($R$2-1)*12+5) -> -93586.667 | M11: =INDEX(Monthly!$C$54:$BJ$54,($R$2-1)*12+6) -> -93586.667 | N11: =INDEX(Monthly!$C$54:$BJ$54,($R$2-1)*12+7) -> -93586.667 | O11: =INDEX(Monthly!$C$54:$BJ$54,($R$2-1)*12+8) -> -93586.667 | P11: =INDEX(Monthly!$C$54:$BJ$54,($R$2-1)*12+9) -> -93586.667 | Q11: =INDEX(Monthly!$C$54:$BJ$54,($R$2-1)*12+10) -> -93586.667 | R11: =INDEX(Monthly!$C$54:$BJ$54,($R$2-1)*12+11) -> -93586.667 | S11: =INDEX(Monthly!$C$54:$BJ$54,($R$2-1)*12+12) -> -93586.667
A12: EBITDA | B12: ='P&L'!B15 -> -123279.21 | C12: ='P&L'!C15 -> 393591.21 | D12: ='P&L'!D15 -> 606030.41 | E12: ='P&L'!E15 -> 754095.19 | F12: ='P&L'!F15 -> 861881.48 | H12: =INDEX(Monthly!$C$55:$BJ$55,($R$2-1)*12+1) -> -52715.254 | I12: =INDEX(Monthly!$C$55:$BJ$55,($R$2-1)*12+2) -> -47169.18 | J12: =INDEX(Monthly!$C$55:$BJ$55,($R$2-1)*12+3) -> -31890.1 | K12: =INDEX(Monthly!$C$55:$BJ$55,($R$2-1)*12+4) -> -24896.465 | L12: =INDEX(Monthly!$C$55:$BJ$55,($R$2-1)*12+5) -> -17775.109 | M12: =INDEX(Monthly!$C$55:$BJ$55,($R$2-1)*12+6) -> -10531.141 | N12: =INDEX(Monthly!$C$55:$BJ$55,($R$2-1)*12+7) -> -3169.4659 | O12: =INDEX(Monthly!$C$55:$BJ$55,($R$2-1)*12+8) -> 4305.2082 | P12: =INDEX(Monthly!$C$55:$BJ$55,($R$2-1)*12+9) -> 11888.361 | Q12: =INDEX(Monthly!$C$55:$BJ$55,($R$2-1)*12+10) -> 19575.654 | R12: =INDEX(Monthly!$C$55:$BJ$55,($R$2-1)*12+11) -> 21716.787 | S12: =INDEX(Monthly!$C$55:$BJ$55,($R$2-1)*12+12) -> 7381.4964
A13: EBITDA margin | B13: ='P&L'!B16 -> -0.10445776 | C13: ='P&L'!C16 -> 0.21794964 | D13: ='P&L'!D16 -> 0.29132204 | E13: ='P&L'!E16 -> 0.33039122 | F13: ='P&L'!F16 -> 0.35310317 | H13: =IF(H7=0,0,H12/H7) -> -1.099532 | I13: =IF(I7=0,0,I12/I7) -> -0.86630122 | J13: =IF(J7=0,0,J12/J7) -> -0.43821093 | K13: =IF(K7=0,0,K12/K7) -> -0.30716695 | L13: =IF(L7=0,0,L12/L7) -> -0.19862615 | M13: =IF(M7=0,0,M12/M7) -> -0.10737063 | N13: =IF(N7=0,0,N12/N7) -> -0.029670716 | O13: =IF(O7=0,0,O12/O7) -> 0.03720945 | ... S13: =IF(S7=0,0,S12/S7) -> 0.062165347
A14: Depreciation | B14: ='P&L'!B17 -> -341666.67 | C14: ='P&L'!C17 -> -345000 | D14: ='P&L'!D17 -> -348333.33 | E14: ='P&L'!E17 -> -351666.67 | F14: ='P&L'!F17 -> -355000 | H14: =INDEX(Monthly!$C$73:$BJ$73,($R$2-1)*12+1) -> -28472.222 | I14: =INDEX(Monthly!$C$73:$BJ$73,($R$2-1)*12+2) -> -28472.222 | J14: =INDEX(Monthly!$C$73:$BJ$73,($R$2-1)*12+3) -> -28472.222 | K14: =INDEX(Monthly!$C$73:$BJ$73,($R$2-1)*12+4) -> -28472.222 | L14: =INDEX(Monthly!$C$73:$BJ$73,($R$2-1)*12+5) -> -28472.222 | M14: =INDEX(Monthly!$C$73:$BJ$73,($R$2-1)*12+6) -> -28472.222 | N14: =INDEX(Monthly!$C$73:$BJ$73,($R$2-1)*12+7) -> -28472.222 | O14: =INDEX(Monthly!$C$73:$BJ$73,($R$2-1)*12+8) -> -28472.222 | P14: =INDEX(Monthly!$C$73:$BJ$73,($R$2-1)*12+9) -> -28472.222 | Q14: =INDEX(Monthly!$C$73:$BJ$73,($R$2-1)*12+10) -> -28472.222 | R14: =INDEX(Monthly!$C$73:$BJ$73,($R$2-1)*12+11) -> -28472.222 | S14: =INDEX(Monthly!$C$73:$BJ$73,($R$2-1)*12+12) -> -28472.222
A15: EBIT | B15: ='P&L'!B18 -> -464945.87 | C15: ='P&L'!C18 -> 48591.208 | D15: ='P&L'!D18 -> 257697.08 | E15: ='P&L'!E18 -> 402428.52 | F15: ='P&L'!F18 -> 506881.48 | H15: =INDEX(Monthly!$C$58:$BJ$58,($R$2-1)*12+1) -> -81187.477 | I15: =INDEX(Monthly!$C$58:$BJ$58,($R$2-1)*12+2) -> -75641.402 | J15: =INDEX(Monthly!$C$58:$BJ$58,($R$2-1)*12+3) -> -60362.322 | K15: =INDEX(Monthly!$C$58:$BJ$58,($R$2-1)*12+4) -> -53368.687 | L15: =INDEX(Monthly!$C$58:$BJ$58,($R$2-1)*12+5) -> -46247.331 | M15: =INDEX(Monthly!$C$58:$BJ$58,($R$2-1)*12+6) -> -39003.363 | N15: =INDEX(Monthly!$C$58:$BJ$58,($R$2-1)*12+7) -> -31641.688 | O15: =INDEX(Monthly!$C$58:$BJ$58,($R$2-1)*12+8) -> -24167.014 | P15: =INDEX(Monthly!$C$58:$BJ$58,($R$2-1)*12+9) -> -16583.861 | Q15: =INDEX(Monthly!$C$58:$BJ$58,($R$2-1)*12+10) -> -8896.568 | R15: =INDEX(Monthly!$C$58:$BJ$58,($R$2-1)*12+11) -> -6755.4353 | S15: =INDEX(Monthly!$C$58:$BJ$58,($R$2-1)*12+12) -> -21090.726
A16: Interest | B16: ='P&L'!B19 -> -244286.46 | C16: ='P&L'!C19 -> -218875 | D16: ='P&L'!D19 -> -193375 | E16: ='P&L'!E19 -> -167875 | F16: ='P&L'!F19 -> -142375 | H16: =INDEX(Monthly!$C$59:$BJ$59,($R$2-1)*12+1) -> -21250 | I16: =INDEX(Monthly!$C$59:$BJ$59,($R$2-1)*12+2) -> -21161.458 | J16: =INDEX(Monthly!$C$59:$BJ$59,($R$2-1)*12+3) -> -20984.375 | K16: =INDEX(Monthly!$C$59:$BJ$59,($R$2-1)*12+4) -> -20807.292 | L16: =INDEX(Monthly!$C$59:$BJ$59,($R$2-1)*12+5) -> -20630.208 | M16: =INDEX(Monthly!$C$59:$BJ$59,($R$2-1)*12+6) -> -20453.125 | N16: =INDEX(Monthly!$C$59:$BJ$59,($R$2-1)*12+7) -> -20276.042 | O16: =INDEX(Monthly!$C$59:$BJ$59,($R$2-1)*12+8) -> -20098.958 | P16: =INDEX(Monthly!$C$59:$BJ$59,($R$2-1)*12+9) -> -19921.875 | Q16: =INDEX(Monthly!$C$59:$BJ$59,($R$2-1)*12+10) -> -19744.792 | R16: =INDEX(Monthly!$C$59:$BJ$59,($R$2-1)*12+11) -> -19567.708 | S16: =INDEX(Monthly!$C$59:$BJ$59,($R$2-1)*12+12) -> -19390.625
A17: Pre-tax income | B17: ='P&L'!B20 -> -709232.33 | C17: ='P&L'!C20 -> -170283.79 | D17: ='P&L'!D20 -> 64322.078 | E17: ='P&L'!E20 -> 234553.52 | F17: ='P&L'!F20 -> 364506.48 | H17: =INDEX(Monthly!$C$60:$BJ$60,($R$2-1)*12+1) -> -102437.48 | I17: =INDEX(Monthly!$C$60:$BJ$60,($R$2-1)*12+2) -> -96802.86 | J17: =INDEX(Monthly!$C$60:$BJ$60,($R$2-1)*12+3) -> -81346.697 | K17: =INDEX(Monthly!$C$60:$BJ$60,($R$2-1)*12+4) -> -74175.979 | L17: =INDEX(Monthly!$C$60:$BJ$60,($R$2-1)*12+5) -> -66877.539 | M17: =INDEX(Monthly!$C$60:$BJ$60,($R$2-1)*12+6) -> -59456.488 | N17: =INDEX(Monthly!$C$60:$BJ$60,($R$2-1)*12+7) -> -51917.73 | O17: =INDEX(Monthly!$C$60:$BJ$60,($R$2-1)*12+8) -> -44265.972 | P17: =INDEX(Monthly!$C$60:$BJ$60,($R$2-1)*12+9) -> -36505.736 | Q17: =INDEX(Monthly!$C$60:$BJ$60,($R$2-1)*12+10) -> -28641.36 | R17: =INDEX(Monthly!$C$60:$BJ$60,($R$2-1)*12+11) -> -26323.144 | S17: =INDEX(Monthly!$C$60:$BJ$60,($R$2-1)*12+12) -> -40481.351
A18: Income tax | B18: ='P&L'!B21 -> 0 | C18: ='P&L'!C21 -> 0 | D18: ='P&L'!D21 -> 0 | E18: ='P&L'!E21 -> 0 | F18: ='P&L'!F21 -> 0 | H18: =INDEX(Monthly!$C$63:$BJ$63,($R$2-1)*12+1) -> 0 | I18: =INDEX(Monthly!$C$63:$BJ$63,($R$2-1)*12+2) -> 0 | J18: =INDEX(Monthly!$C$63:$BJ$63,($R$2-1)*12+3) -> 0 | K18: =INDEX(Monthly!$C$63:$BJ$63,($R$2-1)*12+4) -> 0 | L18: =INDEX(Monthly!$C$63:$BJ$63,($R$2-1)*12+5) -> 0 | M18: =INDEX(Monthly!$C$63:$BJ$63,($R$2-1)*12+6) -> 0 | N18: =INDEX(Monthly!$C$63:$BJ$63,($R$2-1)*12+7) -> 0 | O18: =INDEX(Monthly!$C$63:$BJ$63,($R$2-1)*12+8) -> 0 | P18: =INDEX(Monthly!$C$63:$BJ$63,($R$2-1)*12+9) -> 0 | Q18: =INDEX(Monthly!$C$63:$BJ$63,($R$2-1)*12+10) -> 0 | R18: =INDEX(Monthly!$C$63:$BJ$63,($R$2-1)*12+11) -> 0 | S18: =INDEX(Monthly!$C$63:$BJ$63,($R$2-1)*12+12) -> 0
A19: Net income | B19: ='P&L'!B22 -> -709232.33 | C19: ='P&L'!C22 -> -170283.79 | D19: ='P&L'!D22 -> 64322.078 | E19: ='P&L'!E22 -> 234553.52 | F19: ='P&L'!F22 -> 364506.48 | H19: =INDEX(Monthly!$C$64:$BJ$64,($R$2-1)*12+1) -> -102437.48 | I19: =INDEX(Monthly!$C$64:$BJ$64,($R$2-1)*12+2) -> -96802.86 | J19: =INDEX(Monthly!$C$64:$BJ$64,($R$2-1)*12+3) -> -81346.697 | K19: =INDEX(Monthly!$C$64:$BJ$64,($R$2-1)*12+4) -> -74175.979 | L19: =INDEX(Monthly!$C$64:$BJ$64,($R$2-1)*12+5) -> -66877.539 | M19: =INDEX(Monthly!$C$64:$BJ$64,($R$2-1)*12+6) -> -59456.488 | N19: =INDEX(Monthly!$C$64:$BJ$64,($R$2-1)*12+7) -> -51917.73 | O19: =INDEX(Monthly!$C$64:$BJ$64,($R$2-1)*12+8) -> -44265.972 | P19: =INDEX(Monthly!$C$64:$BJ$64,($R$2-1)*12+9) -> -36505.736 | Q19: =INDEX(Monthly!$C$64:$BJ$64,($R$2-1)*12+10) -> -28641.36 | R19: =INDEX(Monthly!$C$64:$BJ$64,($R$2-1)*12+11) -> -26323.144 | S19: =INDEX(Monthly!$C$64:$BJ$64,($R$2-1)*12+12) -> -40481.351
A20: Net margin | B20: ='P&L'!B23 -> -0.60095146 | C20: ='P&L'!C23 -> -0.094294003 | D20: ='P&L'!D23 -> 0.030919964 | E20: ='P&L'!E23 -> 0.10276478 | F20: ='P&L'!F23 -> 0.14933422 | H20: =IF(H7=0,0,H19/H7) -> -2.1366354 | I20: =IF(I7=0,0,I19/I7) -> -1.777865 | J20: =IF(J7=0,0,J19/J7) -> -1.1178081 | K20: =IF(K7=0,0,K19/K7) -> -0.91516645 | L20: =IF(L7=0,0,L19/L7) -> -0.74731627 | M20: =IF(M7=0,0,M19/M7) -> -0.60619078 | N20: =IF(N7=0,0,N19/N7) -> -0.48602391 | O20: =IF(O7=0,0,O19/O7) -> -0.38258603 | ... S20: =IF(S7=0,0,S19/S7) -> -0.34092508
A22: Cash flow ($'000) — by year | H22: ="Cash flow ($'000) — Year "&$R$2&", by month" -> Cash flow ($'000) — Year 1, by month
B23: 1 | C23: 2 | D23: 3 | E23: 4 | F23: 5 | H23: =INDEX(Monthly!$C$4:$BJ$4,($R$2-1)*12+1) -> 1 | I23: =INDEX(Monthly!$C$4:$BJ$4,($R$2-1)*12+2) -> 2 | J23: =INDEX(Monthly!$C$4:$BJ$4,($R$2-1)*12+3) -> 3 | K23: =INDEX(Monthly!$C$4:$BJ$4,($R$2-1)*12+4) -> 4 | L23: =INDEX(Monthly!$C$4:$BJ$4,($R$2-1)*12+5) -> 5 | M23: =INDEX(Monthly!$C$4:$BJ$4,($R$2-1)*12+6) -> 6 | N23: =INDEX(Monthly!$C$4:$BJ$4,($R$2-1)*12+7) -> 7 | O23: =INDEX(Monthly!$C$4:$BJ$4,($R$2-1)*12+8) -> 8 | P23: =INDEX(Monthly!$C$4:$BJ$4,($R$2-1)*12+9) -> 9 | Q23: =INDEX(Monthly!$C$4:$BJ$4,($R$2-1)*12+10) -> 10 | R23: =INDEX(Monthly!$C$4:$BJ$4,($R$2-1)*12+11) -> 11 | S23: =INDEX(Monthly!$C$4:$BJ$4,($R$2-1)*12+12) -> 12
A24: Operating cash flow | B24: ='Cash Flow'!B10 -> -369557.79 | C24: ='Cash Flow'!C10 -> 174478.45 | D24: ='Cash Flow'!D10 -> 412515.86 | E24: ='Cash Flow'!E10 -> 586141.12 | F24: ='Cash Flow'!F10 -> 719465.28 | H24: =INDEX(Monthly!$C$92:$BJ$92,($R$2-1)*12+1) -> -74804.163 | I24: =INDEX(Monthly!$C$92:$BJ$92,($R$2-1)*12+2) -> -68444.509 | J24: =INDEX(Monthly!$C$92:$BJ$92,($R$2-1)*12+3) -> -53080.977 | K24: =INDEX(Monthly!$C$92:$BJ$92,($R$2-1)*12+4) -> -45827.369 | L24: =INDEX(Monthly!$C$92:$BJ$92,($R$2-1)*12+5) -> -38528.868 | M24: =INDEX(Monthly!$C$92:$BJ$92,($R$2-1)*12+6) -> -31107.758 | N24: =INDEX(Monthly!$C$92:$BJ$92,($R$2-1)*12+7) -> -23568.944 | O24: =INDEX(Monthly!$C$92:$BJ$92,($R$2-1)*12+8) -> -15917.132 | P24: =INDEX(Monthly!$C$92:$BJ$92,($R$2-1)*12+9) -> -8156.8434 | Q24: =INDEX(Monthly!$C$92:$BJ$92,($R$2-1)*12+10) -> -292.41714 | R24: =INDEX(Monthly!$C$92:$BJ$92,($R$2-1)*12+11) -> 2150.1061 | S24: =INDEX(Monthly!$C$92:$BJ$92,($R$2-1)*12+12) -> -11978.918
A25: Capital spending | B25: ='Cash Flow'!B11 -> -4100000 | C25: ='Cash Flow'!C11 -> -40000 | D25: ='Cash Flow'!D11 -> -40000 | E25: ='Cash Flow'!E11 -> -40000 | F25: ='Cash Flow'!F11 -> -40000 | H25: =INDEX(Monthly!$C$93:$BJ$93,($R$2-1)*12+1) -> -4100000 | I25: =INDEX(Monthly!$C$93:$BJ$93,($R$2-1)*12+2) -> 0 | J25: =INDEX(Monthly!$C$93:$BJ$93,($R$2-1)*12+3) -> 0 | K25: =INDEX(Monthly!$C$93:$BJ$93,($R$2-1)*12+4) -> 0 | L25: =INDEX(Monthly!$C$93:$BJ$93,($R$2-1)*12+5) -> 0 | M25: =INDEX(Monthly!$C$93:$BJ$93,($R$2-1)*12+6) -> 0 | N25: =INDEX(Monthly!$C$93:$BJ$93,($R$2-1)*12+7) -> 0 | O25: =INDEX(Monthly!$C$93:$BJ$93,($R$2-1)*12+8) -> 0 | P25: =INDEX(Monthly!$C$93:$BJ$93,($R$2-1)*12+9) -> 0 | Q25: =INDEX(Monthly!$C$93:$BJ$93,($R$2-1)*12+10) -> 0 | R25: =INDEX(Monthly!$C$93:$BJ$93,($R$2-1)*12+11) -> 0 | S25: =INDEX(Monthly!$C$93:$BJ$93,($R$2-1)*12+12) -> 0
A26: Equity raised | B26: ='Cash Flow'!B12 -> 2100000 | C26: ='Cash Flow'!C12 -> 0 | D26: ='Cash Flow'!D12 -> 0 | E26: ='Cash Flow'!E12 -> 0 | F26: ='Cash Flow'!F12 -> 0 | H26: =INDEX(Monthly!$C$94:$BJ$94,($R$2-1)*12+1) -> 2100000 | I26: =INDEX(Monthly!$C$94:$BJ$94,($R$2-1)*12+2) -> 0 | J26: =INDEX(Monthly!$C$94:$BJ$94,($R$2-1)*12+3) -> 0 | K26: =INDEX(Monthly!$C$94:$BJ$94,($R$2-1)*12+4) -> 0 | L26: =INDEX(Monthly!$C$94:$BJ$94,($R$2-1)*12+5) -> 0 | M26: =INDEX(Monthly!$C$94:$BJ$94,($R$2-1)*12+6) -> 0 | N26: =INDEX(Monthly!$C$94:$BJ$94,($R$2-1)*12+7) -> 0 | O26: =INDEX(Monthly!$C$94:$BJ$94,($R$2-1)*12+8) -> 0 | P26: =INDEX(Monthly!$C$94:$BJ$94,($R$2-1)*12+9) -> 0 | Q26: =INDEX(Monthly!$C$94:$BJ$94,($R$2-1)*12+10) -> 0 | R26: =INDEX(Monthly!$C$94:$BJ$94,($R$2-1)*12+11) -> 0 | S26: =INDEX(Monthly!$C$94:$BJ$94,($R$2-1)*12+12) -> 0
A27: Loan drawdown | B27: ='Cash Flow'!B13 -> 3000000 | C27: ='Cash Flow'!C13 -> 0 | D27: ='Cash Flow'!D13 -> 0 | E27: ='Cash Flow'!E13 -> 0 | F27: ='Cash Flow'!F13 -> 0 | H27: =INDEX(Monthly!$C$79:$BJ$79,($R$2-1)*12+1) -> 3000000 | I27: =INDEX(Monthly!$C$79:$BJ$79,($R$2-1)*12+2) -> 0 | J27: =INDEX(Monthly!$C$79:$BJ$79,($R$2-1)*12+3) -> 0 | K27: =INDEX(Monthly!$C$79:$BJ$79,($R$2-1)*12+4) -> 0 | L27: =INDEX(Monthly!$C$79:$BJ$79,($R$2-1)*12+5) -> 0 | M27: =INDEX(Monthly!$C$79:$BJ$79,($R$2-1)*12+6) -> 0 | N27: =INDEX(Monthly!$C$79:$BJ$79,($R$2-1)*12+7) -> 0 | O27: =INDEX(Monthly!$C$79:$BJ$79,($R$2-1)*12+8) -> 0 | P27: =INDEX(Monthly!$C$79:$BJ$79,($R$2-1)*12+9) -> 0 | Q27: =INDEX(Monthly!$C$79:$BJ$79,($R$2-1)*12+10) -> 0 | R27: =INDEX(Monthly!$C$79:$BJ$79,($R$2-1)*12+11) -> 0 | S27: =INDEX(Monthly!$C$79:$BJ$79,($R$2-1)*12+12) -> 0
A28: Loan repayment | B28: ='Cash Flow'!B14 -> -275000 | C28: ='Cash Flow'!C14 -> -300000 | D28: ='Cash Flow'!D14 -> -300000 | E28: ='Cash Flow'!E14 -> -300000 | F28: ='Cash Flow'!F14 -> -300000 | H28: =INDEX(Monthly!$C$80:$BJ$80,($R$2-1)*12+1) -> 0 | I28: =INDEX(Monthly!$C$80:$BJ$80,($R$2-1)*12+2) -> -25000 | J28: =INDEX(Monthly!$C$80:$BJ$80,($R$2-1)*12+3) -> -25000 | K28: =INDEX(Monthly!$C$80:$BJ$80,($R$2-1)*12+4) -> -25000 | L28: =INDEX(Monthly!$C$80:$BJ$80,($R$2-1)*12+5) -> -25000 | M28: =INDEX(Monthly!$C$80:$BJ$80,($R$2-1)*12+6) -> -25000 | N28: =INDEX(Monthly!$C$80:$BJ$80,($R$2-1)*12+7) -> -25000 | O28: =INDEX(Monthly!$C$80:$BJ$80,($R$2-1)*12+8) -> -25000 | P28: =INDEX(Monthly!$C$80:$BJ$80,($R$2-1)*12+9) -> -25000 | Q28: =INDEX(Monthly!$C$80:$BJ$80,($R$2-1)*12+10) -> -25000 | R28: =INDEX(Monthly!$C$80:$BJ$80,($R$2-1)*12+11) -> -25000 | S28: =INDEX(Monthly!$C$80:$BJ$80,($R$2-1)*12+12) -> -25000
A29: Financing cash flow | B29: ='Cash Flow'!B15 -> 4825000 | C29: ='Cash Flow'!C15 -> -300000 | D29: ='Cash Flow'!D15 -> -300000 | E29: ='Cash Flow'!E15 -> -300000 | F29: ='Cash Flow'!F15 -> -300000 | H29: =INDEX(Monthly!$C$95:$BJ$95,($R$2-1)*12+1) -> 5100000 | I29: =INDEX(Monthly!$C$95:$BJ$95,($R$2-1)*12+2) -> -25000 | J29: =INDEX(Monthly!$C$95:$BJ$95,($R$2-1)*12+3) -> -25000 | K29: =INDEX(Monthly!$C$95:$BJ$95,($R$2-1)*12+4) -> -25000 | L29: =INDEX(Monthly!$C$95:$BJ$95,($R$2-1)*12+5) -> -25000 | M29: =INDEX(Monthly!$C$95:$BJ$95,($R$2-1)*12+6) -> -25000 | N29: =INDEX(Monthly!$C$95:$BJ$95,($R$2-1)*12+7) -> -25000 | O29: =INDEX(Monthly!$C$95:$BJ$95,($R$2-1)*12+8) -> -25000 | P29: =INDEX(Monthly!$C$95:$BJ$95,($R$2-1)*12+9) -> -25000 | Q29: =INDEX(Monthly!$C$95:$BJ$95,($R$2-1)*12+10) -> -25000 | R29: =INDEX(Monthly!$C$95:$BJ$95,($R$2-1)*12+11) -> -25000 | S29: =INDEX(Monthly!$C$95:$BJ$95,($R$2-1)*12+12) -> -25000
A30: Net change in cash | B30: ='Cash Flow'!B16 -> 355442.21 | C30: ='Cash Flow'!C16 -> -165521.55 | D30: ='Cash Flow'!D16 -> 72515.855 | E30: ='Cash Flow'!E16 -> 246141.12 | F30: ='Cash Flow'!F16 -> 379465.28 | H30: =INDEX(Monthly!$C$96:$BJ$96,($R$2-1)*12+1) -> 925195.84 | I30: =INDEX(Monthly!$C$96:$BJ$96,($R$2-1)*12+2) -> -93444.509 | J30: =INDEX(Monthly!$C$96:$BJ$96,($R$2-1)*12+3) -> -78080.977 | K30: =INDEX(Monthly!$C$96:$BJ$96,($R$2-1)*12+4) -> -70827.369 | L30: =INDEX(Monthly!$C$96:$BJ$96,($R$2-1)*12+5) -> -63528.868 | M30: =INDEX(Monthly!$C$96:$BJ$96,($R$2-1)*12+6) -> -56107.758 | N30: =INDEX(Monthly!$C$96:$BJ$96,($R$2-1)*12+7) -> -48568.944 | O30: =INDEX(Monthly!$C$96:$BJ$96,($R$2-1)*12+8) -> -40917.132 | P30: =INDEX(Monthly!$C$96:$BJ$96,($R$2-1)*12+9) -> -33156.843 | Q30: =INDEX(Monthly!$C$96:$BJ$96,($R$2-1)*12+10) -> -25292.417 | R30: =INDEX(Monthly!$C$96:$BJ$96,($R$2-1)*12+11) -> -22849.894 | S30: =INDEX(Monthly!$C$96:$BJ$96,($R$2-1)*12+12) -> -36978.918
A31: Closing cash | B31: ='Cash Flow'!B18 -> 355442.21 | C31: ='Cash Flow'!C18 -> 189920.66 | D31: ='Cash Flow'!D18 -> 262436.52 | E31: ='Cash Flow'!E18 -> 508577.64 | F31: ='Cash Flow'!F18 -> 888042.92 | H31: =INDEX(Monthly!$C$98:$BJ$98,($R$2-1)*12+1) -> 925195.84 | I31: =INDEX(Monthly!$C$98:$BJ$98,($R$2-1)*12+2) -> 831751.33 | J31: =INDEX(Monthly!$C$98:$BJ$98,($R$2-1)*12+3) -> 753670.35 | K31: =INDEX(Monthly!$C$98:$BJ$98,($R$2-1)*12+4) -> 682842.98 | L31: =INDEX(Monthly!$C$98:$BJ$98,($R$2-1)*12+5) -> 619314.11 | M31: =INDEX(Monthly!$C$98:$BJ$98,($R$2-1)*12+6) -> 563206.36 | N31: =INDEX(Monthly!$C$98:$BJ$98,($R$2-1)*12+7) -> 514637.41 | O31: =INDEX(Monthly!$C$98:$BJ$98,($R$2-1)*12+8) -> 473720.28 | P31: =INDEX(Monthly!$C$98:$BJ$98,($R$2-1)*12+9) -> 440563.44 | Q31: =INDEX(Monthly!$C$98:$BJ$98,($R$2-1)*12+10) -> 415271.02 | R31: =INDEX(Monthly!$C$98:$BJ$98,($R$2-1)*12+11) -> 392421.13 | S31: =INDEX(Monthly!$C$98:$BJ$98,($R$2-1)*12+12) -> 355442.21
A39: Balance sheet at year end ($'000) | H39: ="Balance sheet at month end ($'000) — Year "&$R$2 -> Balance sheet at month end ($'000) — Year 1
B40: 1 | C40: 2 | D40: 3 | E40: 4 | F40: 5 | H40: =INDEX(Monthly!$C$4:$BJ$4,($R$2-1)*12+1) -> 1 | I40: =INDEX(Monthly!$C$4:$BJ$4,($R$2-1)*12+2) -> 2 | J40: =INDEX(Monthly!$C$4:$BJ$4,($R$2-1)*12+3) -> 3 | K40: =INDEX(Monthly!$C$4:$BJ$4,($R$2-1)*12+4) -> 4 | L40: =INDEX(Monthly!$C$4:$BJ$4,($R$2-1)*12+5) -> 5 | M40: =INDEX(Monthly!$C$4:$BJ$4,($R$2-1)*12+6) -> 6 | N40: =INDEX(Monthly!$C$4:$BJ$4,($R$2-1)*12+7) -> 7 | O40: =INDEX(Monthly!$C$4:$BJ$4,($R$2-1)*12+8) -> 8 | P40: =INDEX(Monthly!$C$4:$BJ$4,($R$2-1)*12+9) -> 9 | Q40: =INDEX(Monthly!$C$4:$BJ$4,($R$2-1)*12+10) -> 10 | R40: =INDEX(Monthly!$C$4:$BJ$4,($R$2-1)*12+11) -> 11 | S40: =INDEX(Monthly!$C$4:$BJ$4,($R$2-1)*12+12) -> 12
A41: Cash | B41: ='Balance Sheet'!B5 -> 355442.21 | C41: ='Balance Sheet'!C5 -> 189920.66 | D41: ='Balance Sheet'!D5 -> 262436.52 | E41: ='Balance Sheet'!E5 -> 508577.64 | F41: ='Balance Sheet'!F5 -> 888042.92 | H41: =INDEX(Monthly!$C$98:$BJ$98,($R$2-1)*12+1) -> 925195.84 | I41: =INDEX(Monthly!$C$98:$BJ$98,($R$2-1)*12+2) -> 831751.33 | J41: =INDEX(Monthly!$C$98:$BJ$98,($R$2-1)*12+3) -> 753670.35 | K41: =INDEX(Monthly!$C$98:$BJ$98,($R$2-1)*12+4) -> 682842.98 | L41: =INDEX(Monthly!$C$98:$BJ$98,($R$2-1)*12+5) -> 619314.11 | M41: =INDEX(Monthly!$C$98:$BJ$98,($R$2-1)*12+6) -> 563206.36 | N41: =INDEX(Monthly!$C$98:$BJ$98,($R$2-1)*12+7) -> 514637.41 | O41: =INDEX(Monthly!$C$98:$BJ$98,($R$2-1)*12+8) -> 473720.28 | P41: =INDEX(Monthly!$C$98:$BJ$98,($R$2-1)*12+9) -> 440563.44 | Q41: =INDEX(Monthly!$C$98:$BJ$98,($R$2-1)*12+10) -> 415271.02 | R41: =INDEX(Monthly!$C$98:$BJ$98,($R$2-1)*12+11) -> 392421.13 | S41: =INDEX(Monthly!$C$98:$BJ$98,($R$2-1)*12+12) -> 355442.21
A42: Accounts receivable | B42: ='Balance Sheet'!B6 -> 7915.9819 | C42: ='Balance Sheet'!C6 -> 9704.5001 | D42: ='Balance Sheet'!D6 -> 10979.008 | E42: ='Balance Sheet'!E6 -> 11939.788 | F42: ='Balance Sheet'!F6 -> 12712.467 | H42: =INDEX(Monthly!$C$84:$BJ$84,($R$2-1)*12+1) -> 3196.2239 | I42: =INDEX(Monthly!$C$84:$BJ$84,($R$2-1)*12+2) -> 3629.9291 | J42: =INDEX(Monthly!$C$84:$BJ$84,($R$2-1)*12+3) -> 4851.5601 | K42: =INDEX(Monthly!$C$84:$BJ$84,($R$2-1)*12+4) -> 5403.4599 | L42: =INDEX(Monthly!$C$84:$BJ$84,($R$2-1)*12+5) -> 5966.0184 | M42: =INDEX(Monthly!$C$84:$BJ$84,($R$2-1)*12+6) -> 6538.8093 | N42: =INDEX(Monthly!$C$84:$BJ$84,($R$2-1)*12+7) -> 7121.4232 | O42: =INDEX(Monthly!$C$84:$BJ$84,($R$2-1)*12+8) -> 7713.4673 | P42: =INDEX(Monthly!$C$84:$BJ$84,($R$2-1)*12+9) -> 8314.5643 | Q42: =INDEX(Monthly!$C$84:$BJ$84,($R$2-1)*12+10) -> 8924.3521 | R42: =INDEX(Monthly!$C$84:$BJ$84,($R$2-1)*12+11) -> 9103.0367 | S42: =INDEX(Monthly!$C$84:$BJ$84,($R$2-1)*12+12) -> 7915.9819
A43: Inventory | B43: ='Balance Sheet'!B7 -> 8885.7825 | C43: ='Balance Sheet'!C7 -> 11211.928 | D43: ='Balance Sheet'!D7 -> 12914.355 | E43: ='Balance Sheet'!E7 -> 14236.927 | F43: ='Balance Sheet'!F7 -> 15334.144 | H43: =INDEX(Monthly!$C$85:$BJ$85,($R$2-1)*12+1) -> 3535.9729 | I43: =INDEX(Monthly!$C$85:$BJ$85,($R$2-1)*12+2) -> 4015.7244 | J43: =INDEX(Monthly!$C$85:$BJ$85,($R$2-1)*12+3) -> 5538.4176 | K43: =INDEX(Monthly!$C$85:$BJ$85,($R$2-1)*12+4) -> 6180.8484 | L43: =INDEX(Monthly!$C$85:$BJ$85,($R$2-1)*12+5) -> 6839.3592 | M43: =INDEX(Monthly!$C$85:$BJ$85,($R$2-1)*12+6) -> 7513.3068 | N43: =INDEX(Monthly!$C$85:$BJ$85,($R$2-1)*12+7) -> 8202.0737 | O43: =INDEX(Monthly!$C$85:$BJ$85,($R$2-1)*12+8) -> 8905.0672 | P43: =INDEX(Monthly!$C$85:$BJ$85,($R$2-1)*12+9) -> 9621.7181 | Q43: =INDEX(Monthly!$C$85:$BJ$85,($R$2-1)*12+10) -> 10351.48 | R43: =INDEX(Monthly!$C$85:$BJ$85,($R$2-1)*12+11) -> 10621.048 | S43: =INDEX(Monthly!$C$85:$BJ$85,($R$2-1)*12+12) -> 8885.7825
A44: Net fixed assets | B44: ='Balance Sheet'!B8 -> 3758333.3 | C44: ='Balance Sheet'!C8 -> 3453333.3 | D44: ='Balance Sheet'!D8 -> 3145000 | E44: ='Balance Sheet'!E8 -> 2833333.3 | F44: ='Balance Sheet'!F8 -> 2518333.3 | H44: =INDEX(Monthly!$C$75:$BJ$75,($R$2-1)*12+1) -> 4071527.8 | I44: =INDEX(Monthly!$C$75:$BJ$75,($R$2-1)*12+2) -> 4043055.6 | J44: =INDEX(Monthly!$C$75:$BJ$75,($R$2-1)*12+3) -> 4014583.3 | K44: =INDEX(Monthly!$C$75:$BJ$75,($R$2-1)*12+4) -> 3986111.1 | L44: =INDEX(Monthly!$C$75:$BJ$75,($R$2-1)*12+5) -> 3957638.9 | M44: =INDEX(Monthly!$C$75:$BJ$75,($R$2-1)*12+6) -> 3929166.7 | N44: =INDEX(Monthly!$C$75:$BJ$75,($R$2-1)*12+7) -> 3900694.4 | O44: =INDEX(Monthly!$C$75:$BJ$75,($R$2-1)*12+8) -> 3872222.2 | P44: =INDEX(Monthly!$C$75:$BJ$75,($R$2-1)*12+9) -> 3843750 | Q44: =INDEX(Monthly!$C$75:$BJ$75,($R$2-1)*12+10) -> 3815277.8 | R44: =INDEX(Monthly!$C$75:$BJ$75,($R$2-1)*12+11) -> 3786805.6 | S44: =INDEX(Monthly!$C$75:$BJ$75,($R$2-1)*12+12) -> 3758333.3
A45: Total assets | B45: ='Balance Sheet'!B9 -> 4130577.3 | C45: ='Balance Sheet'!C9 -> 3664170.4 | D45: ='Balance Sheet'!D9 -> 3431329.9 | E45: ='Balance Sheet'!E9 -> 3368087.7 | F45: ='Balance Sheet'!F9 -> 3434422.9 | H45: =INDEX(Monthly!$C$112:$BJ$112,($R$2-1)*12+1) -> 5003455.8 | I45: =INDEX(Monthly!$C$112:$BJ$112,($R$2-1)*12+2) -> 4882452.5 | J45: =INDEX(Monthly!$C$112:$BJ$112,($R$2-1)*12+3) -> 4778643.7 | K45: =INDEX(Monthly!$C$112:$BJ$112,($R$2-1)*12+4) -> 4680538.4 | L45: =INDEX(Monthly!$C$112:$BJ$112,($R$2-1)*12+5) -> 4589758.4 | M45: =INDEX(Monthly!$C$112:$BJ$112,($R$2-1)*12+6) -> 4506425.1 | N45: =INDEX(Monthly!$C$112:$BJ$112,($R$2-1)*12+7) -> 4430655.4 | O45: =INDEX(Monthly!$C$112:$BJ$112,($R$2-1)*12+8) -> 4362561 | P45: =INDEX(Monthly!$C$112:$BJ$112,($R$2-1)*12+9) -> 4302249.7 | Q45: =INDEX(Monthly!$C$112:$BJ$112,($R$2-1)*12+10) -> 4249824.6 | R45: =INDEX(Monthly!$C$112:$BJ$112,($R$2-1)*12+11) -> 4198950.8 | S45: =INDEX(Monthly!$C$112:$BJ$112,($R$2-1)*12+12) -> 4130577.3
A46: Accounts payable | B46: ='Balance Sheet'!B10 -> 14809.638 | C46: ='Balance Sheet'!C10 -> 18686.546 | D46: ='Balance Sheet'!D10 -> 21523.926 | E46: ='Balance Sheet'!E10 -> 23728.212 | F46: ='Balance Sheet'!F10 -> 25556.907 | H46: =INDEX(Monthly!$C$86:$BJ$86,($R$2-1)*12+1) -> 5893.2881 | I46: =INDEX(Monthly!$C$86:$BJ$86,($R$2-1)*12+2) -> 6692.874 | J46: =INDEX(Monthly!$C$86:$BJ$86,($R$2-1)*12+3) -> 9230.696 | K46: =INDEX(Monthly!$C$86:$BJ$86,($R$2-1)*12+4) -> 10301.414 | L46: =INDEX(Monthly!$C$86:$BJ$86,($R$2-1)*12+5) -> 11398.932 | M46: =INDEX(Monthly!$C$86:$BJ$86,($R$2-1)*12+6) -> 12522.178 | N46: =INDEX(Monthly!$C$86:$BJ$86,($R$2-1)*12+7) -> 13670.123 | O46: =INDEX(Monthly!$C$86:$BJ$86,($R$2-1)*12+8) -> 14841.779 | P46: =INDEX(Monthly!$C$86:$BJ$86,($R$2-1)*12+9) -> 16036.197 | Q46: =INDEX(Monthly!$C$86:$BJ$86,($R$2-1)*12+10) -> 17252.467 | R46: =INDEX(Monthly!$C$86:$BJ$86,($R$2-1)*12+11) -> 17701.747 | S46: =INDEX(Monthly!$C$86:$BJ$86,($R$2-1)*12+12) -> 14809.638
A47: Loan | B47: ='Balance Sheet'!B11 -> 2725000 | C47: ='Balance Sheet'!C11 -> 2425000 | D47: ='Balance Sheet'!D11 -> 2125000 | E47: ='Balance Sheet'!E11 -> 1825000 | F47: ='Balance Sheet'!F11 -> 1525000 | H47: =INDEX(Monthly!$C$81:$BJ$81,($R$2-1)*12+1) -> 3000000 | I47: =INDEX(Monthly!$C$81:$BJ$81,($R$2-1)*12+2) -> 2975000 | J47: =INDEX(Monthly!$C$81:$BJ$81,($R$2-1)*12+3) -> 2950000 | K47: =INDEX(Monthly!$C$81:$BJ$81,($R$2-1)*12+4) -> 2925000 | L47: =INDEX(Monthly!$C$81:$BJ$81,($R$2-1)*12+5) -> 2900000 | M47: =INDEX(Monthly!$C$81:$BJ$81,($R$2-1)*12+6) -> 2875000 | N47: =INDEX(Monthly!$C$81:$BJ$81,($R$2-1)*12+7) -> 2850000 | O47: =INDEX(Monthly!$C$81:$BJ$81,($R$2-1)*12+8) -> 2825000 | P47: =INDEX(Monthly!$C$81:$BJ$81,($R$2-1)*12+9) -> 2800000 | Q47: =INDEX(Monthly!$C$81:$BJ$81,($R$2-1)*12+10) -> 2775000 | R47: =INDEX(Monthly!$C$81:$BJ$81,($R$2-1)*12+11) -> 2750000 | S47: =INDEX(Monthly!$C$81:$BJ$81,($R$2-1)*12+12) -> 2725000
A48: Total liabilities | B48: ='Balance Sheet'!B12 -> 2739809.6 | C48: ='Balance Sheet'!C12 -> 2443686.5 | D48: ='Balance Sheet'!D12 -> 2146523.9 | E48: ='Balance Sheet'!E12 -> 1848728.2 | F48: ='Balance Sheet'!F12 -> 1550556.9 | H48: =INDEX(Monthly!$C$113:$BJ$113,($R$2-1)*12+1) -> 3005893.3 | I48: =INDEX(Monthly!$C$113:$BJ$113,($R$2-1)*12+2) -> 2981692.9 | J48: =INDEX(Monthly!$C$113:$BJ$113,($R$2-1)*12+3) -> 2959230.7 | K48: =INDEX(Monthly!$C$113:$BJ$113,($R$2-1)*12+4) -> 2935301.4 | L48: =INDEX(Monthly!$C$113:$BJ$113,($R$2-1)*12+5) -> 2911398.9 | M48: =INDEX(Monthly!$C$113:$BJ$113,($R$2-1)*12+6) -> 2887522.2 | N48: =INDEX(Monthly!$C$113:$BJ$113,($R$2-1)*12+7) -> 2863670.1 | O48: =INDEX(Monthly!$C$113:$BJ$113,($R$2-1)*12+8) -> 2839841.8 | P48: =INDEX(Monthly!$C$113:$BJ$113,($R$2-1)*12+9) -> 2816036.2 | Q48: =INDEX(Monthly!$C$113:$BJ$113,($R$2-1)*12+10) -> 2792252.5 | R48: =INDEX(Monthly!$C$113:$BJ$113,($R$2-1)*12+11) -> 2767701.7 | S48: =INDEX(Monthly!$C$113:$BJ$113,($R$2-1)*12+12) -> 2739809.6
A49: Paid-in capital | B49: ='Balance Sheet'!B13 -> 2100000 | C49: ='Balance Sheet'!C13 -> 2100000 | D49: ='Balance Sheet'!D13 -> 2100000 | E49: ='Balance Sheet'!E13 -> 2100000 | F49: ='Balance Sheet'!F13 -> 2100000 | H49: =INDEX(Monthly!$C$110:$BJ$110,($R$2-1)*12+1) -> 2100000 | I49: =INDEX(Monthly!$C$110:$BJ$110,($R$2-1)*12+2) -> 2100000 | J49: =INDEX(Monthly!$C$110:$BJ$110,($R$2-1)*12+3) -> 2100000 | K49: =INDEX(Monthly!$C$110:$BJ$110,($R$2-1)*12+4) -> 2100000 | L49: =INDEX(Monthly!$C$110:$BJ$110,($R$2-1)*12+5) -> 2100000 | M49: =INDEX(Monthly!$C$110:$BJ$110,($R$2-1)*12+6) -> 2100000 | N49: =INDEX(Monthly!$C$110:$BJ$110,($R$2-1)*12+7) -> 2100000 | O49: =INDEX(Monthly!$C$110:$BJ$110,($R$2-1)*12+8) -> 2100000 | P49: =INDEX(Monthly!$C$110:$BJ$110,($R$2-1)*12+9) -> 2100000 | Q49: =INDEX(Monthly!$C$110:$BJ$110,($R$2-1)*12+10) -> 2100000 | R49: =INDEX(Monthly!$C$110:$BJ$110,($R$2-1)*12+11) -> 2100000 | S49: =INDEX(Monthly!$C$110:$BJ$110,($R$2-1)*12+12) -> 2100000
A50: Retained earnings | B50: ='Balance Sheet'!B14 -> -709232.33 | C50: ='Balance Sheet'!C14 -> -879516.12 | D50: ='Balance Sheet'!D14 -> -815194.05 | E50: ='Balance Sheet'!E14 -> -580640.52 | F50: ='Balance Sheet'!F14 -> -216134.04 | H50: =INDEX(Monthly!$C$111:$BJ$111,($R$2-1)*12+1) -> -102437.48 | I50: =INDEX(Monthly!$C$111:$BJ$111,($R$2-1)*12+2) -> -199240.34 | J50: =INDEX(Monthly!$C$111:$BJ$111,($R$2-1)*12+3) -> -280587.03 | K50: =INDEX(Monthly!$C$111:$BJ$111,($R$2-1)*12+4) -> -354763.01 | L50: =INDEX(Monthly!$C$111:$BJ$111,($R$2-1)*12+5) -> -421640.55 | M50: =INDEX(Monthly!$C$111:$BJ$111,($R$2-1)*12+6) -> -481097.04 | N50: =INDEX(Monthly!$C$111:$BJ$111,($R$2-1)*12+7) -> -533014.77 | O50: =INDEX(Monthly!$C$111:$BJ$111,($R$2-1)*12+8) -> -577280.74 | P50: =INDEX(Monthly!$C$111:$BJ$111,($R$2-1)*12+9) -> -613786.48 | Q50: =INDEX(Monthly!$C$111:$BJ$111,($R$2-1)*12+10) -> -642427.84 | R50: =INDEX(Monthly!$C$111:$BJ$111,($R$2-1)*12+11) -> -668750.98 | S50: =INDEX(Monthly!$C$111:$BJ$111,($R$2-1)*12+12) -> -709232.33
...

Sheet Scenarios
A1: Scenarios — Low / Base / High | H1: =HYPERLINK("#'Cover'!A1","◂ Contents") -> ◂ Contents
A2: All three scenarios calculated side by side, live: change any input and every column updates. Active = the scenario chosen on the Dashboard.
A5: Key drivers
A6: Driver | B6: Low | C6: Base | D6: High | E6: Active
A7: Retail cars per operating day at maturity (year 1) (cars) | B7: =Inputs!$B$7 -> 200 | C7: =Inputs!$C$7 -> 240 | D7: =Inputs!$D$7 -> 280 | E7: =Inputs!$E$7 -> 240
A8: Average price per retail wash (year 1) ($) | B8: =Inputs!$B$27 -> 12 | C8: =Inputs!$C$27 -> 13 | D8: =Inputs!$D$27 -> 14 | E8: =Inputs!$E$27 -> 13
A9: Unlimited members at start (presale or current base) (#) | B9: =Inputs!$B$19 -> 150 | C9: =Inputs!$C$19 -> 250 | D9: =Inputs!$D$19 -> 350 | E9: =Inputs!$E$19 -> 250
A10: Unlimited plan fee per member per month (year 1) ($) | B10: =Inputs!$B$29 -> 32 | C10: =Inputs!$C$29 -> 35 | D10: =Inputs!$D$29 -> 38 | E10: =Inputs!$E$29 -> 35
A11: Members who cancel per month (%) | B11: =Inputs!$B$23 -> 0.05 | C11: =Inputs!$C$23 -> 0.04 | D11: =Inputs!$D$23 -> 0.032 | E11: =Inputs!$E$23 -> 0.04
A12: Site lease or land cost per month ($) | B12: =Inputs!$B$41 -> 30000 | C12: =Inputs!$C$41 -> 30000 | D12: =Inputs!$D$41 -> 30000 | E12: =Inputs!$E$41 -> 30000
A13: Tunnel equipment (month 1) ($) | B13: =Inputs!$B$49 -> 1650000 | C13: =Inputs!$C$49 -> 1650000 | D13: =Inputs!$D$49 -> 1650000 | E13: =Inputs!$E$49 -> 1650000
A14: Equity raised at start ($) | B14: =Inputs!$B$67 -> 2100000 | C14: =Inputs!$C$67 -> 2100000 | D14: =Inputs!$D$67 -> 2100000 | E14: =Inputs!$E$67 -> 2100000
A16: Results by scenario ($'000)
A17: Output | B17: Low | C17: Base | D17: High | E17: Active
A18: Revenue — final year | B18: =F31 -> 1509180.9 | C18: =F32 -> 2440877.2 | D18: =F33 -> 3820481.8 | E18: ='P&L'!F5 -> 2440877.2
A19: Revenue — whole plan | B19: =SUM(B31:F31) -> 6296493.3 | C19: =SUM(B32:F32) -> 9789648.8 | D19: =SUM(B33:F33) -> 14540688 | E19: =SUM('P&L'!$B$5:$F$5) -> 9789648.8
A20: EBITDA — final year | B20: =F37 -> 29088.848 | C20: =F38 -> 861881.48 | D20: =F39 -> 2118274.9 | E20: ='P&L'!F15 -> 861881.48
A21: EBITDA margin — final year | B21: =IF(B18=0,0,B20/B18) -> 0.019274593 | C21: =IF(C18=0,0,C20/C18) -> 0.35310317 | D21: =IF(D18=0,0,D20/D18) -> 0.5544523 | E21: =IF(E18=0,0,E20/E18) -> 0.35310317
A22: Net income — final year | B22: =F43 -> -468286.15 | C22: =F44 -> 364506.48 | D22: =F45 -> 1280510.9 | E22: ='P&L'!F22 -> 364506.48
A23: Net income — whole plan | B23: =SUM(B43:F43) -> -3340553.2 | C23: =SUM(B44:F44) -> -216134.04 | D23: =SUM(B45:F45) -> 3272119.7 | E23: =SUM('P&L'!$B$22:$F$22) -> -216134.04
A24: Cash at the end of the plan | B24: =F49 -> -2233642.3 | C24: =F50 -> 888042.92 | D24: =F51 -> 4371228 | E24: ='Balance Sheet'!F5 -> 888042.92
A25: Lowest cash balance | B25: =MIN('Scenario calc'!$C$100:$BJ$100) -> -2233642.3 | C25: =MIN('Scenario calc'!$C$227:$BJ$227) -> 131554.54 | D25: =MIN('Scenario calc'!$C$354:$BJ$354) -> 775910.09 | E25: ='Break-even'!B18 -> 131554.54
A26: Lowest cash point (month #) | B26: =MATCH(MIN('Scenario calc'!$C$100:$BJ$100),'Scenario calc'!$C$100:$BJ$100,0) -> 60 | C26: =MATCH(MIN('Scenario calc'!$C$227:$BJ$227),'Scenario calc'!$C$227:$BJ$227,0) -> 26 | D26: =MATCH(MIN('Scenario calc'!$C$354:$BJ$354),'Scenario calc'!$C$354:$BJ$354,0) -> 7 | E26: ='Break-even'!B6 -> 26
A27: Funding required (incl. cash buffer) | B27: =SUMPRODUCT(--('Scenario calc'!$C$6:$BJ$6<=B26),'Scenario calc'!$C$73:$BJ$73)-SUMPRODUCT(--('Scenario calc'!$C$6:$BJ$6<=B26),'Scenario calc'!$C$94:$BJ$94)-SUMPRODUCT(--('Scenario calc'!$C$6:$BJ$6<=B26),'Scenario calc'!$C$82:$BJ$82)+Inputs!$B$82 -> 7614642.3 | C27: =SUMPRODUCT(--('Scenario calc'!$C$133:$BJ$133<=C26),'Scenario calc'!$C$200:$BJ$200)-SUMPRODUCT(--('Scenario calc'!$C$133:$BJ$133<=C26),'Scenario calc'!$C$221:$BJ$221)-SUMPRODUCT(--('Scenario calc'!$C$133:$BJ$133<=C26),'Scenario calc'!$C$209:$BJ$209)+Inputs!$C$82 -> 5249445.5 | D27: =SUMPRODUCT(--('Scenario calc'!$C$260:$BJ$260<=D26),'Scenario calc'!$C$327:$BJ$327)-SUMPRODUCT(--('Scenario calc'!$C$260:$BJ$260<=D26),'Scenario calc'!$C$348:$BJ$348)-SUMPRODUCT(--('Scenario calc'!$C$260:$BJ$260<=D26),'Scenario calc'!$C$336:$BJ$336)+Inputs!$D$82 -> 4605089.9 | E27: ='Break-even'!B12 -> 5249445.5
A29: Revenue by year ($'000)
A30: Scenario | B30: 1 | C30: 2 | D30: 3 | E30: 4 | F30: 5
A31: Low | B31: =SUMIF('Scenario calc'!$C$7:$BJ$7,B$30,'Scenario calc'!$C$39:$BJ$39) -> 723753.78 | C31: =SUMIF('Scenario calc'!$C$7:$BJ$7,C$30,'Scenario calc'!$C$39:$BJ$39) -> 1233556.7 | D31: =SUMIF('Scenario calc'!$C$7:$BJ$7,D$30,'Scenario calc'!$C$39:$BJ$39) -> 1373352.6 | E31: =SUMIF('Scenario calc'!$C$7:$BJ$7,E$30,'Scenario calc'!$C$39:$BJ$39) -> 1456649.3 | F31: =SUMIF('Scenario calc'!$C$7:$BJ$7,F$30,'Scenario calc'!$C$39:$BJ$39) -> 1509180.9
A32: Base | B32: =SUMIF('Scenario calc'!$C$134:$BJ$134,B$30,'Scenario calc'!$C$166:$BJ$166) -> 1180182.4 | C32: =SUMIF('Scenario calc'!$C$134:$BJ$134,C$30,'Scenario calc'!$C$166:$BJ$166) -> 1805881.5 | D32: =SUMIF('Scenario calc'!$C$134:$BJ$134,D$30,'Scenario calc'!$C$166:$BJ$166) -> 2080276.6 | E32: =SUMIF('Scenario calc'!$C$134:$BJ$134,E$30,'Scenario calc'!$C$166:$BJ$166) -> 2282431.1 | F32: =SUMIF('Scenario calc'!$C$134:$BJ$134,F$30,'Scenario calc'!$C$166:$BJ$166) -> 2440877.2
A33: High | B33: =SUMIF('Scenario calc'!$C$261:$BJ$261,B$30,'Scenario calc'!$C$293:$BJ$293) -> 1713972.3 | C33: =SUMIF('Scenario calc'!$C$261:$BJ$261,C$30,'Scenario calc'!$C$293:$BJ$293) -> 2530234.4 | D33: =SUMIF('Scenario calc'!$C$261:$BJ$261,D$30,'Scenario calc'!$C$293:$BJ$293) -> 3028027.2 | E33: =SUMIF('Scenario calc'!$C$261:$BJ$261,E$30,'Scenario calc'!$C$293:$BJ$293) -> 3447972 | F33: =SUMIF('Scenario calc'!$C$261:$BJ$261,F$30,'Scenario calc'!$C$293:$BJ$293) -> 3820481.8
A35: EBITDA by year ($'000)
A36: Scenario | B36: 1 | C36: 2 | D36: 3 | E36: 4 | F36: 5
A37: Low | B37: =SUMIF('Scenario calc'!$C$7:$BJ$7,B$36,'Scenario calc'!$C$57:$BJ$57) -> -533892.68 | C37: =SUMIF('Scenario calc'!$C$7:$BJ$7,C$36,'Scenario calc'!$C$57:$BJ$57) -> -120382.6 | D37: =SUMIF('Scenario calc'!$C$7:$BJ$7,D$36,'Scenario calc'!$C$57:$BJ$57) -> -24636.3 | E37: =SUMIF('Scenario calc'!$C$7:$BJ$7,E$36,'Scenario calc'!$C$57:$BJ$57) -> 17722.667 | F37: =SUMIF('Scenario calc'!$C$7:$BJ$7,F$36,'Scenario calc'!$C$57:$BJ$57) -> 29088.848
A38: Base | B38: =SUMIF('Scenario calc'!$C$134:$BJ$134,B$36,'Scenario calc'!$C$184:$BJ$184) -> -123279.21 | C38: =SUMIF('Scenario calc'!$C$134:$BJ$134,C$36,'Scenario calc'!$C$184:$BJ$184) -> 393591.21 | D38: =SUMIF('Scenario calc'!$C$134:$BJ$134,D$36,'Scenario calc'!$C$184:$BJ$184) -> 606030.41 | E38: =SUMIF('Scenario calc'!$C$134:$BJ$134,E$36,'Scenario calc'!$C$184:$BJ$184) -> 754095.19 | F38: =SUMIF('Scenario calc'!$C$134:$BJ$134,F$36,'Scenario calc'!$C$184:$BJ$184) -> 861881.48
A39: High | B39: =SUMIF('Scenario calc'!$C$261:$BJ$261,B$36,'Scenario calc'!$C$311:$BJ$311) -> 374729.35 | C39: =SUMIF('Scenario calc'!$C$261:$BJ$261,C$36,'Scenario calc'!$C$311:$BJ$311) -> 1064559.3 | D39: =SUMIF('Scenario calc'!$C$261:$BJ$261,D$36,'Scenario calc'!$C$311:$BJ$311) -> 1475107.6 | E39: =SUMIF('Scenario calc'!$C$261:$BJ$261,E$36,'Scenario calc'!$C$311:$BJ$311) -> 1817705.5 | F39: =SUMIF('Scenario calc'!$C$261:$BJ$261,F$36,'Scenario calc'!$C$311:$BJ$311) -> 2118274.9
A41: Net income by year ($'000)
A42: Scenario | B42: 1 | C42: 2 | D42: 3 | E42: 4 | F42: 5
A43: Low | B43: =SUMIF('Scenario calc'!$C$7:$BJ$7,B$42,'Scenario calc'!$C$66:$BJ$66) -> -1119845.8 | C43: =SUMIF('Scenario calc'!$C$7:$BJ$7,C$42,'Scenario calc'!$C$66:$BJ$66) -> -684257.6 | D43: =SUMIF('Scenario calc'!$C$7:$BJ$7,D$42,'Scenario calc'!$C$66:$BJ$66) -> -566344.63 | E43: =SUMIF('Scenario calc'!$C$7:$BJ$7,E$42,'Scenario calc'!$C$66:$BJ$66) -> -501819 | F43: =SUMIF('Scenario calc'!$C$7:$BJ$7,F$42,'Scenario calc'!$C$66:$BJ$66) -> -468286.15
A44: Base | B44: =SUMIF('Scenario calc'!$C$134:$BJ$134,B$42,'Scenario calc'!$C$193:$BJ$193) -> -709232.33 | C44: =SUMIF('Scenario calc'!$C$134:$BJ$134,C$42,'Scenario calc'!$C$193:$BJ$193) -> -170283.79 | D44: =SUMIF('Scenario calc'!$C$134:$BJ$134,D$42,'Scenario calc'!$C$193:$BJ$193) -> 64322.078 | E44: =SUMIF('Scenario calc'!$C$134:$BJ$134,E$42,'Scenario calc'!$C$193:$BJ$193) -> 234553.52 | F44: =SUMIF('Scenario calc'!$C$134:$BJ$134,F$42,'Scenario calc'!$C$193:$BJ$193) -> 364506.48
A45: High | B45: =SUMIF('Scenario calc'!$C$261:$BJ$261,B$42,'Scenario calc'!$C$320:$BJ$320) -> -211223.77 | C45: =SUMIF('Scenario calc'!$C$261:$BJ$261,C$42,'Scenario calc'!$C$320:$BJ$320) -> 439897.6 | D45: =SUMIF('Scenario calc'!$C$261:$BJ$261,D$42,'Scenario calc'!$C$320:$BJ$320) -> 737385.45 | E45: =SUMIF('Scenario calc'!$C$261:$BJ$261,E$42,'Scenario calc'!$C$320:$BJ$320) -> 1025549.4 | F45: =SUMIF('Scenario calc'!$C$261:$BJ$261,F$42,'Scenario calc'!$C$320:$BJ$320) -> 1280510.9
A47: Cash at year end by year ($'000)
...

Sheet Break-even
A1: Startup costs, funding need and break-even | H1: =HYPERLINK("#'Cover'!A1","◂ Contents") -> ◂ Contents
A2: Live for the selected scenario. Periods are counted in months from the start of the plan.
A3: Scenario shown | B3: =CHOOSE(Dashboard!$B$4,"Low","Base","High") -> Base
A5: Startup costs & funding need (up to the lowest cash point)
A6: Lowest cash point (month #) | B6: =MATCH(MIN(Monthly!$C$98:$BJ$98),Monthly!$C$98:$BJ$98,0) -> 26
A7: Capital spending up to the lowest cash point | B7: =SUMPRODUCT(--(Monthly!$C$4:$BJ$4<=$B$6),Monthly!$C$71:$BJ$71) -> 4180000
A8: Operating cash burn up to the lowest cash point | B8: =-SUMPRODUCT(--(Monthly!$C$4:$BJ$4<=$B$6),Monthly!$C$92:$BJ$92) -> 163445.46 | D8: Losses and working capital before the business funds itself
A9: Loan repayments up to the lowest cash point | B9: =-SUMPRODUCT(--(Monthly!$C$4:$BJ$4<=$B$6),Monthly!$C$80:$BJ$80) -> 625000
A10: Total uses of funds | B10: =B7+B8+B9 -> 4968445.5
A11: Minimum cash buffer to keep | B11: =Inputs!$E$82 -> 281000 | D11: Input on the Inputs sheet
A12: Funding required (uses + buffer) | B12: =B10+B11 -> 5249445.5
A14: Equity raised | B14: =Inputs!$E$67 -> 2100000
A15: Loan drawn | B15: =Inputs!$E$68 -> 3000000
A16: Total sources of funds | B16: =B14+B15 -> 5100000
A17: Funding surplus / (shortfall) | B17: =B16-B12 -> -149445.46 | D17: Negative = raise at least this much more
A18: Lowest cash balance in the plan | B18: =MIN(Monthly!$C$98:$BJ$98) -> 131554.54 | D18: Equals sources minus uses
A20: Break-even timing
A21: First month with positive EBITDA (month #) | B21: =IFERROR(MATCH(1,Monthly!$C$99:$BJ$99,0),"Not within horizon") -> 8
A22: First month with positive net income (month #) | B22: =IFERROR(MATCH(1,Monthly!$C$102:$BJ$102,0),"Not within horizon") -> 27
A23: Cash invested paid back (month #) | B23: =IF(MIN(Monthly!$C$104:$BJ$104)>=0,"No investment to pay back",IFERROR(MATCH(1,Monthly!$C$106:$BJ$106,0),"Not within horizon")) -> Not within horizon | D23: Cumulative operating + investing cash flow back to zero
A25: Annual break-even revenue
A26: Year # | B26: 1 | C26: 2 | D26: 3 | E26: 4 | F26: 5
B27: Year 1 | C27: Year 2 | D27: Year 3 | E27: Year 4 | F27: Year 5
A28: Revenue | B28: =SUMIF(Monthly!$C$5:$BJ$5,B$26,Monthly!$C$37:$BJ$37) -> 1180182.4 | C28: =SUMIF(Monthly!$C$5:$BJ$5,C$26,Monthly!$C$37:$BJ$37) -> 1805881.5 | D28: =SUMIF(Monthly!$C$5:$BJ$5,D$26,Monthly!$C$37:$BJ$37) -> 2080276.6 | E28: =SUMIF(Monthly!$C$5:$BJ$5,E$26,Monthly!$C$37:$BJ$37) -> 2282431.1 | F28: =SUMIF(Monthly!$C$5:$BJ$5,F$26,Monthly!$C$37:$BJ$37) -> 2440877.2
A29: Gross profit | B29: =SUMIF(Monthly!$C$5:$BJ$5,B$26,Monthly!$C$46:$BJ$46) -> 999760.79 | C29: =SUMIF(Monthly!$C$5:$BJ$5,C$26,Monthly!$C$46:$BJ$46) -> 1517202.4 | D29: =SUMIF(Monthly!$C$5:$BJ$5,D$26,Monthly!$C$46:$BJ$46) -> 1736853.9 | E29: =SUMIF(Monthly!$C$5:$BJ$5,E$26,Monthly!$C$46:$BJ$46) -> 1897646.6 | F29: =SUMIF(Monthly!$C$5:$BJ$5,F$26,Monthly!$C$46:$BJ$46) -> 2022782
A30: Gross margin (contribution) | B30: =IF(B28=0,0,B29/B28) -> 0.84712397 | C30: =IF(C28=0,0,C29/C28) -> 0.84014507 | D30: =IF(D28=0,0,D29/D28) -> 0.83491491 | E30: =IF(E28=0,0,E29/E28) -> 0.83141464 | F30: =IF(F28=0,0,F29/F28) -> 0.82871109
A31: Operating expenses (treated as fixed) | B31: =-SUMIF(Monthly!$C$5:$BJ$5,B$26,Monthly!$C$54:$BJ$54) -> 1123040 | C31: =-SUMIF(Monthly!$C$5:$BJ$5,C$26,Monthly!$C$54:$BJ$54) -> 1123611.2 | D31: =-SUMIF(Monthly!$C$5:$BJ$5,D$26,Monthly!$C$54:$BJ$54) -> 1130823.5 | E31: =-SUMIF(Monthly!$C$5:$BJ$5,E$26,Monthly!$C$54:$BJ$54) -> 1143551.4 | F31: =-SUMIF(Monthly!$C$5:$BJ$5,F$26,Monthly!$C$54:$BJ$54) -> 1160900.5
A32: Break-even revenue (EBITDA = 0) | B32: =IF(B30>0,B31/B30,"n/a") -> 1325709.2 | C32: =IF(C30>0,C31/C30,"n/a") -> 1337401.4 | D32: =IF(D30>0,D31/D30,"n/a") -> 1354417.7 | E32: =IF(E30>0,E31/E30,"n/a") -> 1375428.6 | F32: =IF(F30>0,F31/F30,"n/a") -> 1400850.7
A33: Margin of safety (revenue above break-even) | B33: =IF(AND(ISNUMBER(B32),B28>0),(B28-B32)/B28,"n/a") -> -0.1233087 | C33: =IF(AND(ISNUMBER(C32),C28>0),(C28-C32)/C28,"n/a") -> 0.25941905 | D33: =IF(AND(ISNUMBER(D32),D28>0),(D28-D32)/D28,"n/a") -> 0.34892422 | E33: =IF(AND(ISNUMBER(E32),E28>0),(E28-E32)/E28,"n/a") -> 0.39738441 | F33: =IF(AND(ISNUMBER(F32),F28>0),(F28-F32)/F28,"n/a") -> 0.42608718
A35: Simplification: cost of sales is treated as variable and operating expenses as fixed, so break-even revenue = operating expenses ÷ gross margin.

Sheet Valuation
A1: Discounted cash flow valuation | H1: =HYPERLINK("#'Cover'!A1","◂ Contents") -> ◂ Contents
A2: Enterprise value at the start of the plan, before the funding raised in period 1. Year-end discounting.
A3: Scenario shown | B3: =CHOOSE(Dashboard!$B$4,"Low","Base","High") -> Base
A5: Assumptions (active scenario, from the Inputs sheet)
A6: Discount rate (WACC) | B6: =Inputs!$E$85 -> 0.25
A7: Terminal growth rate | B7: =Inputs!$E$86 -> 0.02
A8: Exit multiple (EV ÷ final-year EBITDA) | B8: =Inputs!$E$87 -> 4
A9: Tax rate (for the interest tax shield) | B9: =Inputs!$E$79 -> 0.21
A10: Sensitivity step: WACC | B10: =Inputs!$E$88 -> 0.01
A11: Sensitivity step: terminal growth | B11: =Inputs!$E$89 -> 0.005
A13: Free cash flow by year
A14: Year # | B14: 1 | C14: 2 | D14: 3 | E14: 4 | F14: 5
B15: Year 1 | C15: Year 2 | D15: Year 3 | E15: Year 4 | F15: Year 5
A16: EBITDA | B16: =SUMIF(Monthly!$C$5:$BJ$5,B$14,Monthly!$C$55:$BJ$55) -> -123279.21 | C16: =SUMIF(Monthly!$C$5:$BJ$5,C$14,Monthly!$C$55:$BJ$55) -> 393591.21 | D16: =SUMIF(Monthly!$C$5:$BJ$5,D$14,Monthly!$C$55:$BJ$55) -> 606030.41 | E16: =SUMIF(Monthly!$C$5:$BJ$5,E$14,Monthly!$C$55:$BJ$55) -> 754095.19 | F16: =SUMIF(Monthly!$C$5:$BJ$5,F$14,Monthly!$C$55:$BJ$55) -> 861881.48
A17: Unlevered free cash flow | B17: =SUMIF(Monthly!$C$5:$BJ$5,B$14,Monthly!$C$107:$BJ$107) -> -4276571.5 | C17: =SUMIF(Monthly!$C$5:$BJ$5,C$14,Monthly!$C$107:$BJ$107) -> 307389.7 | D17: =SUMIF(Monthly!$C$5:$BJ$5,D$14,Monthly!$C$107:$BJ$107) -> 525282.11 | E17: =SUMIF(Monthly!$C$5:$BJ$5,E$14,Monthly!$C$107:$BJ$107) -> 678762.37 | F17: =SUMIF(Monthly!$C$5:$BJ$5,F$14,Monthly!$C$107:$BJ$107) -> 791941.53
A18: Discount factor | B18: =1/(1+Inputs!$E$85)^B$14 -> 0.8 | C18: =1/(1+Inputs!$E$85)^C$14 -> 0.64 | D18: =1/(1+Inputs!$E$85)^D$14 -> 0.512 | E18: =1/(1+Inputs!$E$85)^E$14 -> 0.4096 | F18: =1/(1+Inputs!$E$85)^F$14 -> 0.32768
A19: Present value of free cash flow | B19: =B17*B18 -> -3421257.2 | C19: =C17*C18 -> 196729.41 | D19: =D17*D18 -> 268944.44 | E19: =E17*E18 -> 278021.07 | F19: =F17*F18 -> 259503.4
A21: Enterprise value
B22: Perpetual growth | C22: Exit multiple
A23: Present value of the plan's free cash flows | B23: =SUM($B$19:$F$19) -> -2418058.9 | C23: =B23 -> -2418058.9
A24: Final-year free cash flow | final-year EBITDA | B24: =$F$17 -> 791941.53 | C24: =$F$16 -> 861881.48
A25: Terminal value at the end of year 5 | B25: =IF($B$6>$B$7,B24*(1+$B$7)/($B$6-$B$7),0) -> 3512088.5 | C25: =C24*$B$8 -> 3447525.9
A26: Present value of the terminal value | B26: =B25/(1+$B$6)^$F$14 -> 1150841.2 | C26: =C25/(1+$B$6)^$F$14 -> 1129685.3
A27: Enterprise value | B27: =B23+B26 -> -1267217.7 | C27: =C23+C26 -> -1288373.6
A28: Terminal value share of enterprise value | B28: =IF(B27<>0,B26/B27,0) -> -0.90816374 | C28: =IF(C27<>0,C26/C27,0) -> -0.87683054
A29: Cross-check: implied exit multiple | implied perpetual growth | B29: =IF(C24>0,B25/C24,"n/a") -> 4.0749089 | C29: =IF(C25+B24<>0,(C25*$B$6-B24)/(C25+B24),"n/a") -> 0.016497344
A30: Enterprise value — average of the two methods | B30: =AVERAGE(B27,C27) -> -1277795.6
A32: Sensitivity: enterprise value (perpetual growth) by WACC and terminal growth
A33: WACC ↓ · terminal growth → | B33: =$B$7+(-2)*$B$11 -> 0.01 | C33: =$B$7+(-1)*$B$11 -> 0.015 | D33: =$B$7+(0)*$B$11 -> 0.02 | E33: =$B$7+(1)*$B$11 -> 0.025 | F33: =$B$7+(2)*$B$11 -> 0.03
A34: =$B$6+(-2)*$B$10 -> 0.23 | B34: =IF($A34>B$33,SUMPRODUCT($B$17:$F$17/(1+$A34)^$B$14:$F$14)+$F$17*(1+B$33)/($A34-B$33)/(1+$A34)^$F$14,"n/a") -> -1122165.7 | C34: =IF($A34>C$33,SUMPRODUCT($B$17:$F$17/(1+$A34)^$B$14:$F$14)+$F$17*(1+C$33)/($A34-C$33)/(1+$A34)^$F$14,"n/a") -> -1085590.9 | D34: =IF($A34>D$33,SUMPRODUCT($B$17:$F$17/(1+$A34)^$B$14:$F$14)+$F$17*(1+D$33)/($A34-D$33)/(1+$A34)^$F$14,"n/a") -> -1047274.5 | E34: =IF($A34>E$33,SUMPRODUCT($B$17:$F$17/(1+$A34)^$B$14:$F$14)+$F$17*(1+E$33)/($A34-E$33)/(1+$A34)^$F$14,"n/a") -> -1007089 | F34: =IF($A34>F$33,SUMPRODUCT($B$17:$F$17/(1+$A34)^$B$14:$F$14)+$F$17*(1+F$33)/($A34-F$33)/(1+$A34)^$F$14,"n/a") -> -964894.17
A35: =$B$6+(-1)*$B$10 -> 0.24 | B35: =IF($A35>B$33,SUMPRODUCT($B$17:$F$17/(1+$A35)^$B$14:$F$14)+$F$17*(1+B$33)/($A35-B$33)/(1+$A35)^$F$14,"n/a") -> -1229937.5 | C35: =IF($A35>C$33,SUMPRODUCT($B$17:$F$17/(1+$A35)^$B$14:$F$14)+$F$17*(1+C$33)/($A35-C$33)/(1+$A35)^$F$14,"n/a") -> -1197573.2 | D35: =IF($A35>D$33,SUMPRODUCT($B$17:$F$17/(1+$A35)^$B$14:$F$14)+$F$17*(1+D$33)/($A35-D$33)/(1+$A35)^$F$14,"n/a") -> -1163737.8 | E35: =IF($A35>E$33,SUMPRODUCT($B$17:$F$17/(1+$A35)^$B$14:$F$14)+$F$17*(1+E$33)/($A35-E$33)/(1+$A35)^$F$14,"n/a") -> -1128328.7 | F35: =IF($A35>F$33,SUMPRODUCT($B$17:$F$17/(1+$A35)^$B$14:$F$14)+$F$17*(1+F$33)/($A35-F$33)/(1+$A35)^$F$14,"n/a") -> -1091233.4
