Workbook

Sheet Cover
B2: Childcare centre financial model (planning)
B3: 5-year financial model · monthly detail · Low / Base / High scenarios · US dollars · Full plan
B5: Purpose | D5: Revenue and profit plan
B6: Active scenario | D6: =Dashboard!C4&" (change it on the Dashboard, cell B4)" -> Base (change it on the Dashboard, cell B4)
B7: Model checks | D7: =Checks!B25 -> PASS
B8: Prepared | D8: 22 October 2026
B10: Contents
C11: PRESENTATION
B12: 1 | C12: =HYPERLINK("#Dashboard!A1","Dashboard") -> Dashboard | D12: Scenario switch, key numbers, core financials
B13: 2 | C13: =HYPERLINK("#Summary!A1","Summary") -> Summary | D13: Income statement, cash flow and balance sheet — every year and any year by month
B14: 3 | C14: =HYPERLINK("#Scenarios!A1","Scenarios") -> Scenarios | D14: Low / Base / High side by side: drivers, outputs, charts
B15: 4 | C15: =HYPERLINK("#'Break-even'!A1","Break-even") -> Break-even | D15: Startup costs, funding need, break-even timing and revenue
B16: 5 | C16: =HYPERLINK("#Valuation!A1","Valuation") -> Valuation | D16: Free cash flow, DCF (perpetual growth and exit multiple), WACC × growth sensitivity
B17: 6 | C17: =HYPERLINK("#'Sources & Uses'!A1","Sources & Uses") -> Sources & Uses | D17: Funding structure, sources and uses of cash for the first months
B18: 7 | C18: =HYPERLINK("#KPIs!A1","KPIs") -> KPIs | D18: Financial ratios, DuPont analysis, industry metrics
C19: INPUTS
B20: 8 | C20: =HYPERLINK("#Inputs!A1","Inputs") -> Inputs | D20: Every assumption, Low / Base / High, with units and comments
C21: STATEMENTS
B22: 9 | C22: =HYPERLINK("#'P&L'!A1","P&L") -> P&L | D22: Annual profit & loss
B23: 10 | C23: =HYPERLINK("#'Cash Flow'!A1","Cash Flow") -> Cash Flow | D23: Annual cash flow statement
B24: 11 | C24: =HYPERLINK("#'Balance Sheet'!A1","Balance Sheet") -> Balance Sheet | D24: Balance sheet at year end
C25: CALCULATIONS
B26: 12 | C26: =HYPERLINK("#Monthly!A1","Monthly") -> Monthly | D26: Month-by-month engine of the model
B27: 13 | C27: =HYPERLINK("#Headcount!A1","Headcount") -> Headcount | D27: Team and payroll
B28: 14 | C28: =HYPERLINK("#'Scenario calc'!A1","Scenario calc") -> Scenario calc | D28: Low, Base and High calculated side by side for the Scenarios sheet
C29: CONTROL
B30: 15 | C30: =HYPERLINK("#Checks!A1","Checks") -> Checks | D30: Live integrity checks and the overall verdict
B32: How to read this file
C33: 1000 | D33: Input you can change — yellow cell with a blue figure (Inputs sheet and the view switches)
C34: 1000 | D34: Formula — calculated, do not overwrite
C35: 1000 | D35: Link to another sheet
C36: 1000 | D36: Active value the model uses (follows the scenario)

Sheet Dashboard
A1: Dashboard | W1: =HYPERLINK("#'Cover'!A1","◂ Contents") -> ◂ Contents
A2: Childcare centre financial model (planning)
A4: Active scenario | B4: 2 | C4: =CHOOSE(B4,"Low","Base","High") -> Base | D4: 1 = Low · 2 = Base · 3 = High — every sheet follows this cell | S4: Model checks | T4: =Checks!B25 -> PASS
A6: REVENUE · YEAR 5 | C6: EBITDA MARGIN · YEAR 5 | H6: NET INCOME · YEAR 5 | L6: LOWEST CASH BALANCE | P6: FUNDING REQUIRED | T6: ENTERPRISE VALUE (DCF)
A7: =F12 -> 792649.71 | C7: =F17 -> 0.08295451 | H7: =F18 -> 6787.2016 | L7: =F38 -> 64092.356 | P7: =F36 -> 709907.64 | T7: =F43 -> -302247.25
A8: =IF(AND(B12>0,F12>=0),(F12/B12)^(1/4)-1,"CAGR n/a") -> 0.17228696 | C8: =F16 -> 65753.868 | H8: =F19 -> 0.0085626746 | L8: ='Break-even'!B6 -> 13 | P8: =IF(F37>=0,"Covered by funding raised",-F37) -> 9907.6437 | T8: Average of 2 methods
A10: Core financials ($'000) — active scenario
B11: 1 | C11: 2 | D11: 3 | E11: 4 | F11: 5
A12: Revenue | B12: =SUMIF(Monthly!$C$5:$BJ$5,B$11,Monthly!$C$32:$BJ$32) -> 419706.38 | C12: =SUMIF(Monthly!$C$5:$BJ$5,C$11,Monthly!$C$32:$BJ$32) -> 725888.9 | D12: =SUMIF(Monthly!$C$5:$BJ$5,D$11,Monthly!$C$32:$BJ$32) -> 747148.37 | E12: =SUMIF(Monthly!$C$5:$BJ$5,E$11,Monthly!$C$32:$BJ$32) -> 769562.82 | F12: =SUMIF(Monthly!$C$5:$BJ$5,F$11,Monthly!$C$32:$BJ$32) -> 792649.71
A13: Gross profit | B13: =SUMIF(Monthly!$C$5:$BJ$5,B$11,Monthly!$C$39:$BJ$39) -> 171077.38 | C13: =SUMIF(Monthly!$C$5:$BJ$5,C$11,Monthly!$C$39:$BJ$39) -> 363320.66 | D13: =SUMIF(Monthly!$C$5:$BJ$5,D$11,Monthly!$C$39:$BJ$39) -> 373703.09 | E13: =SUMIF(Monthly!$C$5:$BJ$5,E$11,Monthly!$C$39:$BJ$39) -> 384914.18 | F13: =SUMIF(Monthly!$C$5:$BJ$5,F$11,Monthly!$C$39:$BJ$39) -> 396461.6
A14: Gross margin | B14: =IF(B12=0,0,B13/B12) -> 0.40761205 | C14: =IF(C12=0,0,C13/C12) -> 0.50051827 | D14: =IF(D12=0,0,D13/D12) -> 0.50017252 | E14: =IF(E12=0,0,E13/E12) -> 0.50017252 | F14: =IF(F12=0,0,F13/F12) -> 0.50017252
A15: Operating expenses | B15: =SUMIF(Monthly!$C$5:$BJ$5,B$11,Monthly!$C$51:$BJ$51) -> -296928.37 | C15: =SUMIF(Monthly!$C$5:$BJ$5,C$11,Monthly!$C$51:$BJ$51) -> -309263.38 | D15: =SUMIF(Monthly!$C$5:$BJ$5,D$11,Monthly!$C$51:$BJ$51) -> -316201.28 | E15: =SUMIF(Monthly!$C$5:$BJ$5,E$11,Monthly!$C$51:$BJ$51) -> -323347.32 | F15: =SUMIF(Monthly!$C$5:$BJ$5,F$11,Monthly!$C$51:$BJ$51) -> -330707.74
A16: EBITDA | B16: =SUMIF(Monthly!$C$5:$BJ$5,B$11,Monthly!$C$52:$BJ$52) -> -125850.99 | C16: =SUMIF(Monthly!$C$5:$BJ$5,C$11,Monthly!$C$52:$BJ$52) -> 54057.278 | D16: =SUMIF(Monthly!$C$5:$BJ$5,D$11,Monthly!$C$52:$BJ$52) -> 57501.808 | E16: =SUMIF(Monthly!$C$5:$BJ$5,E$11,Monthly!$C$52:$BJ$52) -> 61566.862 | F16: =SUMIF(Monthly!$C$5:$BJ$5,F$11,Monthly!$C$52:$BJ$52) -> 65753.868
A17: EBITDA margin | B17: =IF(B12=0,0,B16/B12) -> -0.29985485 | C17: =IF(C12=0,0,C16/C12) -> 0.074470458 | D17: =IF(D12=0,0,D16/D12) -> 0.076961699 | E17: =IF(E12=0,0,E16/E12) -> 0.080002386 | F17: =IF(F12=0,0,F16/F12) -> 0.08295451
A18: Net income | B18: =SUMIF(Monthly!$C$5:$BJ$5,B$11,Monthly!$C$61:$BJ$61) -> -189210.72 | C18: =SUMIF(Monthly!$C$5:$BJ$5,C$11,Monthly!$C$61:$BJ$61) -> -8209.3882 | D18: =SUMIF(Monthly!$C$5:$BJ$5,D$11,Monthly!$C$61:$BJ$61) -> -3664.8586 | E18: =SUMIF(Monthly!$C$5:$BJ$5,E$11,Monthly!$C$61:$BJ$61) -> 1500.1957 | F18: =SUMIF(Monthly!$C$5:$BJ$5,F$11,Monthly!$C$61:$BJ$61) -> 6787.2016
A19: Net margin | B19: =IF(B12=0,0,B18/B12) -> -0.45081687 | C19: =IF(C12=0,0,C18/C12) -> -0.011309428 | D19: =IF(D12=0,0,D18/D12) -> -0.0049051282 | E19: =IF(E12=0,0,E18/E12) -> 0.0019494129 | F19: =IF(F12=0,0,F18/F12) -> 0.0085626746
A20: Operating cash flow | B20: =SUMIF(Monthly!$C$5:$BJ$5,B$11,Monthly!$C$89:$BJ$89) -> -161309.3 | C20: =SUMIF(Monthly!$C$5:$BJ$5,C$11,Monthly!$C$89:$BJ$89) -> 35051.747 | D20: =SUMIF(Monthly!$C$5:$BJ$5,D$11,Monthly!$C$89:$BJ$89) -> 41791.018 | E20: =SUMIF(Monthly!$C$5:$BJ$5,E$11,Monthly!$C$89:$BJ$89) -> 47839.748 | F20: =SUMIF(Monthly!$C$5:$BJ$5,F$11,Monthly!$C$89:$BJ$89) -> 54009.941
A21: Investing cash flow | B21: =SUMIF(Monthly!$C$5:$BJ$5,B$11,Monthly!$C$90:$BJ$90) -> -442000 | C21: =SUMIF(Monthly!$C$5:$BJ$5,C$11,Monthly!$C$90:$BJ$90) -> -9000 | D21: =SUMIF(Monthly!$C$5:$BJ$5,D$11,Monthly!$C$90:$BJ$90) -> -9000 | E21: =SUMIF(Monthly!$C$5:$BJ$5,E$11,Monthly!$C$90:$BJ$90) -> -9000 | F21: =SUMIF(Monthly!$C$5:$BJ$5,F$11,Monthly!$C$90:$BJ$90) -> -9000
A22: Financing cash flow | B22: =SUMIF(Monthly!$C$5:$BJ$5,B$11,Monthly!$C$92:$BJ$92) -> 677083.33 | C22: =SUMIF(Monthly!$C$5:$BJ$5,C$11,Monthly!$C$92:$BJ$92) -> -25000 | D22: =SUMIF(Monthly!$C$5:$BJ$5,D$11,Monthly!$C$92:$BJ$92) -> -25000 | E22: =SUMIF(Monthly!$C$5:$BJ$5,E$11,Monthly!$C$92:$BJ$92) -> -25000 | F22: =SUMIF(Monthly!$C$5:$BJ$5,F$11,Monthly!$C$92:$BJ$92) -> -25000
A23: Net change in cash | B23: =SUMIF(Monthly!$C$5:$BJ$5,B$11,Monthly!$C$93:$BJ$93) -> 73774.032 | C23: =SUMIF(Monthly!$C$5:$BJ$5,C$11,Monthly!$C$93:$BJ$93) -> 1051.747 | D23: =SUMIF(Monthly!$C$5:$BJ$5,D$11,Monthly!$C$93:$BJ$93) -> 7791.0179 | E23: =SUMIF(Monthly!$C$5:$BJ$5,E$11,Monthly!$C$93:$BJ$93) -> 13839.748 | F23: =SUMIF(Monthly!$C$5:$BJ$5,F$11,Monthly!$C$93:$BJ$93) -> 20009.941
A24: Year-end cash | B24: =INDEX(Monthly!$C$95:$BJ$95,B$11*12) -> 73774.032 | C24: =INDEX(Monthly!$C$95:$BJ$95,C$11*12) -> 74825.779 | D24: =INDEX(Monthly!$C$95:$BJ$95,D$11*12) -> 82616.797 | E24: =INDEX(Monthly!$C$95:$BJ$95,E$11*12) -> 96456.545 | F24: =INDEX(Monthly!$C$95:$BJ$95,F$11*12) -> 116466.49
A26: Childcare metrics
B27: 1 | C27: 2 | D27: 3 | E27: 4 | F27: 5
A28: Children enrolled (year end) | B28: =KPIs!B30 -> 47.75 | C28: =KPIs!C30 -> 51 | D28: =KPIs!D30 -> 51 | E28: =KPIs!E30 -> 51 | F28: =KPIs!F30 -> 51
A29: Occupancy (child-months ÷ place-months) | B29: =KPIs!B33 -> 0.49791667 | C29: =KPIs!C33 -> 0.85 | D29: =KPIs!D33 -> 0.85 | E29: =KPIs!E33 -> 0.85 | F29: =KPIs!F33 -> 0.85
A30: Teacher payroll, % of revenue | B30: =KPIs!B43 -> 0.49501273 | C30: =KPIs!C43 -> 0.40048443 | D30: =KPIs!D43 -> 0.40076165 | E30: =KPIs!E43 -> 0.40076165 | F30: =KPIs!F43 -> 0.40076165
A31: Team (FTE, year end) | B31: =INDEX(Headcount!$C$11:$BJ$11,B$27*12) -> 2 | C31: =INDEX(Headcount!$C$11:$BJ$11,C$27*12) -> 2 | D31: =INDEX(Headcount!$C$11:$BJ$11,D$27*12) -> 2 | E31: =INDEX(Headcount!$C$11:$BJ$11,E$27*12) -> 2 | F31: =INDEX(Headcount!$C$11:$BJ$11,F$27*12) -> 2
A33: Funding & valuation ($'000) — active scenario
A34: Equity raised | F34: =Inputs!$E$73 -> 450000
A35: Loan drawn | F35: =Inputs!$E$74 -> 250000
A36: Funding required (incl. cash buffer) | F36: ='Break-even'!B12 -> 709907.64
A37: Funding surplus / (shortfall) | F37: ='Break-even'!B17 -> -9907.6437
A38: ="Lowest cash balance (month "&'Break-even'!B6&")" -> Lowest cash balance (month 13) | F38: ='Break-even'!B18 -> 64092.356
A39: First month with positive EBITDA | F39: ='Break-even'!B21 -> 12
A40: Cash invested paid back | F40: ='Break-even'!B23 -> Not within horizon
A41: Enterprise value — perpetual growth | F41: =Valuation!B27 -> -306225.94
A42: Enterprise value — exit multiple | F42: =Valuation!C27 -> -298268.56
A43: Enterprise value — average | F43: =Valuation!B30 -> -302247.25

Sheet Summary
A1: Financial statements summary | U1: =HYPERLINK("#'Cover'!A1","◂ Contents") -> ◂ Contents
A2: Childcare centre financial model (planning) | P2: Select detailed year: | R2: 1
A5: Income statement ($'000) — by year | H5: ="Income statement ($'000) — Year "&$R$2&", by month" -> Income statement ($'000) — Year 1, by month
B6: 1 | C6: 2 | D6: 3 | E6: 4 | F6: 5 | H6: =INDEX(Monthly!$C$4:$BJ$4,($R$2-1)*12+1) -> 1 | I6: =INDEX(Monthly!$C$4:$BJ$4,($R$2-1)*12+2) -> 2 | J6: =INDEX(Monthly!$C$4:$BJ$4,($R$2-1)*12+3) -> 3 | K6: =INDEX(Monthly!$C$4:$BJ$4,($R$2-1)*12+4) -> 4 | L6: =INDEX(Monthly!$C$4:$BJ$4,($R$2-1)*12+5) -> 5 | M6: =INDEX(Monthly!$C$4:$BJ$4,($R$2-1)*12+6) -> 6 | N6: =INDEX(Monthly!$C$4:$BJ$4,($R$2-1)*12+7) -> 7 | O6: =INDEX(Monthly!$C$4:$BJ$4,($R$2-1)*12+8) -> 8 | P6: =INDEX(Monthly!$C$4:$BJ$4,($R$2-1)*12+9) -> 9 | Q6: =INDEX(Monthly!$C$4:$BJ$4,($R$2-1)*12+10) -> 10 | R6: =INDEX(Monthly!$C$4:$BJ$4,($R$2-1)*12+11) -> 11 | S6: =INDEX(Monthly!$C$4:$BJ$4,($R$2-1)*12+12) -> 12
A7: Revenue | B7: ='P&L'!B5 -> 419706.38 | C7: ='P&L'!C5 -> 725888.9 | D7: ='P&L'!D5 -> 747148.37 | E7: ='P&L'!E5 -> 769562.82 | F7: ='P&L'!F5 -> 792649.71 | H7: =INDEX(Monthly!$C$32:$BJ$32,($R$2-1)*12+1) -> 15609 | I7: =INDEX(Monthly!$C$32:$BJ$32,($R$2-1)*12+2) -> 18036.438 | J7: =INDEX(Monthly!$C$32:$BJ$32,($R$2-1)*12+3) -> 21776.375 | K7: =INDEX(Monthly!$C$32:$BJ$32,($R$2-1)*12+4) -> 25516.312 | L7: =INDEX(Monthly!$C$32:$BJ$32,($R$2-1)*12+5) -> 29256.25 | M7: =INDEX(Monthly!$C$32:$BJ$32,($R$2-1)*12+6) -> 32996.188 | N7: =INDEX(Monthly!$C$32:$BJ$32,($R$2-1)*12+7) -> 36736.125 | O7: =INDEX(Monthly!$C$32:$BJ$32,($R$2-1)*12+8) -> 40476.062 | P7: =INDEX(Monthly!$C$32:$BJ$32,($R$2-1)*12+9) -> 44216 | Q7: =INDEX(Monthly!$C$32:$BJ$32,($R$2-1)*12+10) -> 47955.938 | R7: =INDEX(Monthly!$C$32:$BJ$32,($R$2-1)*12+11) -> 51695.875 | S7: =INDEX(Monthly!$C$32:$BJ$32,($R$2-1)*12+12) -> 55435.812
A8: Cost of sales | B8: ='P&L'!B6 -> -248629 | C8: ='P&L'!C6 -> -362568.24 | D8: ='P&L'!D6 -> -373445.29 | E8: ='P&L'!E6 -> -384648.65 | F8: ='P&L'!F6 -> -396188.11 | H8: =INDEX(Monthly!$C$38:$BJ$38,($R$2-1)*12+1) -> -9208 | I8: =INDEX(Monthly!$C$38:$BJ$38,($R$2-1)*12+2) -> -9578.5 | J8: =INDEX(Monthly!$C$38:$BJ$38,($R$2-1)*12+3) -> -17789 | K8: =INDEX(Monthly!$C$38:$BJ$38,($R$2-1)*12+4) -> -18159.5 | L8: =INDEX(Monthly!$C$38:$BJ$38,($R$2-1)*12+5) -> -18530 | M8: =INDEX(Monthly!$C$38:$BJ$38,($R$2-1)*12+6) -> -18900.5 | N8: =INDEX(Monthly!$C$38:$BJ$38,($R$2-1)*12+7) -> -19271 | O8: =INDEX(Monthly!$C$38:$BJ$38,($R$2-1)*12+8) -> -23561.5 | P8: =INDEX(Monthly!$C$38:$BJ$38,($R$2-1)*12+9) -> -27852 | Q8: =INDEX(Monthly!$C$38:$BJ$38,($R$2-1)*12+10) -> -28222.5 | R8: =INDEX(Monthly!$C$38:$BJ$38,($R$2-1)*12+11) -> -28593 | S8: =INDEX(Monthly!$C$38:$BJ$38,($R$2-1)*12+12) -> -28963.5
A9: Gross profit | B9: ='P&L'!B7 -> 171077.38 | C9: ='P&L'!C7 -> 363320.66 | D9: ='P&L'!D7 -> 373703.09 | E9: ='P&L'!E7 -> 384914.18 | F9: ='P&L'!F7 -> 396461.6 | H9: =INDEX(Monthly!$C$39:$BJ$39,($R$2-1)*12+1) -> 6401 | I9: =INDEX(Monthly!$C$39:$BJ$39,($R$2-1)*12+2) -> 8457.9375 | J9: =INDEX(Monthly!$C$39:$BJ$39,($R$2-1)*12+3) -> 3987.375 | K9: =INDEX(Monthly!$C$39:$BJ$39,($R$2-1)*12+4) -> 7356.8125 | L9: =INDEX(Monthly!$C$39:$BJ$39,($R$2-1)*12+5) -> 10726.25 | M9: =INDEX(Monthly!$C$39:$BJ$39,($R$2-1)*12+6) -> 14095.688 | N9: =INDEX(Monthly!$C$39:$BJ$39,($R$2-1)*12+7) -> 17465.125 | O9: =INDEX(Monthly!$C$39:$BJ$39,($R$2-1)*12+8) -> 16914.562 | P9: =INDEX(Monthly!$C$39:$BJ$39,($R$2-1)*12+9) -> 16364 | Q9: =INDEX(Monthly!$C$39:$BJ$39,($R$2-1)*12+10) -> 19733.438 | R9: =INDEX(Monthly!$C$39:$BJ$39,($R$2-1)*12+11) -> 23102.875 | S9: =INDEX(Monthly!$C$39:$BJ$39,($R$2-1)*12+12) -> 26472.312
A10: Gross margin | B10: ='P&L'!B8 -> 0.40761205 | C10: ='P&L'!C8 -> 0.50051827 | D10: ='P&L'!D8 -> 0.50017252 | E10: ='P&L'!E8 -> 0.50017252 | F10: ='P&L'!F8 -> 0.50017252 | H10: =IF(H7=0,0,H9/H7) -> 0.41008393 | I10: =IF(I7=0,0,I9/I7) -> 0.46893615 | J10: =IF(J7=0,0,J9/J7) -> 0.18310554 | K10: =IF(K7=0,0,K9/K7) -> 0.28831801 | L10: =IF(L7=0,0,L9/L7) -> 0.36663106 | M10: =IF(M7=0,0,M9/M7) -> 0.4271914 | N10: =IF(N7=0,0,N9/N7) -> 0.47542099 | O10: =IF(O7=0,0,O9/O7) -> 0.41789051 | ... S10: =IF(S7=0,0,S9/S7) -> 0.47753088
A11: Total operating expenses | B11: ='P&L'!B18 -> -296928.37 | C11: ='P&L'!C18 -> -309263.38 | D11: ='P&L'!D18 -> -316201.28 | E11: ='P&L'!E18 -> -323347.32 | F11: ='P&L'!F18 -> -330707.74 | H11: =INDEX(Monthly!$C$51:$BJ$51,($R$2-1)*12+1) -> -24349.217 | I11: =INDEX(Monthly!$C$51:$BJ$51,($R$2-1)*12+2) -> -24421.001 | J11: =INDEX(Monthly!$C$51:$BJ$51,($R$2-1)*12+3) -> -24492.785 | K11: =INDEX(Monthly!$C$51:$BJ$51,($R$2-1)*12+4) -> -24564.57 | L11: =INDEX(Monthly!$C$51:$BJ$51,($R$2-1)*12+5) -> -24636.354 | M11: =INDEX(Monthly!$C$51:$BJ$51,($R$2-1)*12+6) -> -24708.139 | N11: =INDEX(Monthly!$C$51:$BJ$51,($R$2-1)*12+7) -> -24779.923 | O11: =INDEX(Monthly!$C$51:$BJ$51,($R$2-1)*12+8) -> -24851.707 | P11: =INDEX(Monthly!$C$51:$BJ$51,($R$2-1)*12+9) -> -24923.492 | Q11: =INDEX(Monthly!$C$51:$BJ$51,($R$2-1)*12+10) -> -24995.276 | R11: =INDEX(Monthly!$C$51:$BJ$51,($R$2-1)*12+11) -> -25067.06 | S11: =INDEX(Monthly!$C$51:$BJ$51,($R$2-1)*12+12) -> -25138.845
A12: EBITDA | B12: ='P&L'!B19 -> -125850.99 | C12: ='P&L'!C19 -> 54057.278 | D12: ='P&L'!D19 -> 57501.808 | E12: ='P&L'!E19 -> 61566.862 | F12: ='P&L'!F19 -> 65753.868 | H12: =INDEX(Monthly!$C$52:$BJ$52,($R$2-1)*12+1) -> -17948.217 | I12: =INDEX(Monthly!$C$52:$BJ$52,($R$2-1)*12+2) -> -15963.064 | J12: =INDEX(Monthly!$C$52:$BJ$52,($R$2-1)*12+3) -> -20505.41 | K12: =INDEX(Monthly!$C$52:$BJ$52,($R$2-1)*12+4) -> -17207.757 | L12: =INDEX(Monthly!$C$52:$BJ$52,($R$2-1)*12+5) -> -13910.104 | M12: =INDEX(Monthly!$C$52:$BJ$52,($R$2-1)*12+6) -> -10612.451 | N12: =INDEX(Monthly!$C$52:$BJ$52,($R$2-1)*12+7) -> -7314.7979 | O12: =INDEX(Monthly!$C$52:$BJ$52,($R$2-1)*12+8) -> -7937.1448 | P12: =INDEX(Monthly!$C$52:$BJ$52,($R$2-1)*12+9) -> -8559.4917 | Q12: =INDEX(Monthly!$C$52:$BJ$52,($R$2-1)*12+10) -> -5261.8385 | R12: =INDEX(Monthly!$C$52:$BJ$52,($R$2-1)*12+11) -> -1964.1854 | S12: =INDEX(Monthly!$C$52:$BJ$52,($R$2-1)*12+12) -> 1333.4677
A13: EBITDA margin | B13: ='P&L'!B20 -> -0.29985485 | C13: ='P&L'!C20 -> 0.074470458 | D13: ='P&L'!D20 -> 0.076961699 | E13: ='P&L'!E20 -> 0.080002386 | F13: ='P&L'!F20 -> 0.08295451 | H13: =IF(H7=0,0,H12/H7) -> -1.1498633 | I13: =IF(I7=0,0,I12/I7) -> -0.88504526 | J13: =IF(J7=0,0,J12/J7) -> -0.94163562 | K13: =IF(K7=0,0,K12/K7) -> -0.6743826 | L13: =IF(L7=0,0,L12/L7) -> -0.47545752 | M13: =IF(M7=0,0,M12/M7) -> -0.32162658 | N13: =IF(N7=0,0,N12/N7) -> -0.1991173 | O13: =IF(O7=0,0,O12/O7) -> -0.19609479 | ... S13: =IF(S7=0,0,S12/S7) -> 0.024054265
A14: Depreciation | B14: ='P&L'!B21 -> -44200 | C14: ='P&L'!C21 -> -45100 | D14: ='P&L'!D21 -> -46000 | E14: ='P&L'!E21 -> -46900 | F14: ='P&L'!F21 -> -47800 | H14: =INDEX(Monthly!$C$70:$BJ$70,($R$2-1)*12+1) -> -3683.3333 | I14: =INDEX(Monthly!$C$70:$BJ$70,($R$2-1)*12+2) -> -3683.3333 | J14: =INDEX(Monthly!$C$70:$BJ$70,($R$2-1)*12+3) -> -3683.3333 | K14: =INDEX(Monthly!$C$70:$BJ$70,($R$2-1)*12+4) -> -3683.3333 | L14: =INDEX(Monthly!$C$70:$BJ$70,($R$2-1)*12+5) -> -3683.3333 | M14: =INDEX(Monthly!$C$70:$BJ$70,($R$2-1)*12+6) -> -3683.3333 | N14: =INDEX(Monthly!$C$70:$BJ$70,($R$2-1)*12+7) -> -3683.3333 | O14: =INDEX(Monthly!$C$70:$BJ$70,($R$2-1)*12+8) -> -3683.3333 | P14: =INDEX(Monthly!$C$70:$BJ$70,($R$2-1)*12+9) -> -3683.3333 | Q14: =INDEX(Monthly!$C$70:$BJ$70,($R$2-1)*12+10) -> -3683.3333 | R14: =INDEX(Monthly!$C$70:$BJ$70,($R$2-1)*12+11) -> -3683.3333 | S14: =INDEX(Monthly!$C$70:$BJ$70,($R$2-1)*12+12) -> -3683.3333
A15: EBIT | B15: ='P&L'!B22 -> -170050.99 | C15: ='P&L'!C22 -> 8957.2785 | D15: ='P&L'!D22 -> 11501.808 | E15: ='P&L'!E22 -> 14666.862 | F15: ='P&L'!F22 -> 17953.868 | H15: =INDEX(Monthly!$C$55:$BJ$55,($R$2-1)*12+1) -> -21631.55 | I15: =INDEX(Monthly!$C$55:$BJ$55,($R$2-1)*12+2) -> -19646.397 | J15: =INDEX(Monthly!$C$55:$BJ$55,($R$2-1)*12+3) -> -24188.744 | K15: =INDEX(Monthly!$C$55:$BJ$55,($R$2-1)*12+4) -> -20891.091 | L15: =INDEX(Monthly!$C$55:$BJ$55,($R$2-1)*12+5) -> -17593.438 | M15: =INDEX(Monthly!$C$55:$BJ$55,($R$2-1)*12+6) -> -14295.784 | N15: =INDEX(Monthly!$C$55:$BJ$55,($R$2-1)*12+7) -> -10998.131 | O15: =INDEX(Monthly!$C$55:$BJ$55,($R$2-1)*12+8) -> -11620.478 | P15: =INDEX(Monthly!$C$55:$BJ$55,($R$2-1)*12+9) -> -12242.825 | Q15: =INDEX(Monthly!$C$55:$BJ$55,($R$2-1)*12+10) -> -8945.1719 | R15: =INDEX(Monthly!$C$55:$BJ$55,($R$2-1)*12+11) -> -5647.5188 | S15: =INDEX(Monthly!$C$55:$BJ$55,($R$2-1)*12+12) -> -2349.8656
A16: Interest | B16: ='P&L'!B23 -> -19159.722 | C16: ='P&L'!C23 -> -17166.667 | D16: ='P&L'!D23 -> -15166.667 | E16: ='P&L'!E23 -> -13166.667 | F16: ='P&L'!F23 -> -11166.667 | H16: =INDEX(Monthly!$C$56:$BJ$56,($R$2-1)*12+1) -> -1666.6667 | I16: =INDEX(Monthly!$C$56:$BJ$56,($R$2-1)*12+2) -> -1659.7222 | J16: =INDEX(Monthly!$C$56:$BJ$56,($R$2-1)*12+3) -> -1645.8333 | K16: =INDEX(Monthly!$C$56:$BJ$56,($R$2-1)*12+4) -> -1631.9444 | L16: =INDEX(Monthly!$C$56:$BJ$56,($R$2-1)*12+5) -> -1618.0556 | M16: =INDEX(Monthly!$C$56:$BJ$56,($R$2-1)*12+6) -> -1604.1667 | N16: =INDEX(Monthly!$C$56:$BJ$56,($R$2-1)*12+7) -> -1590.2778 | O16: =INDEX(Monthly!$C$56:$BJ$56,($R$2-1)*12+8) -> -1576.3889 | P16: =INDEX(Monthly!$C$56:$BJ$56,($R$2-1)*12+9) -> -1562.5 | Q16: =INDEX(Monthly!$C$56:$BJ$56,($R$2-1)*12+10) -> -1548.6111 | R16: =INDEX(Monthly!$C$56:$BJ$56,($R$2-1)*12+11) -> -1534.7222 | S16: =INDEX(Monthly!$C$56:$BJ$56,($R$2-1)*12+12) -> -1520.8333
A17: Pre-tax income | B17: ='P&L'!B24 -> -189210.72 | C17: ='P&L'!C24 -> -8209.3882 | D17: ='P&L'!D24 -> -3664.8586 | E17: ='P&L'!E24 -> 1500.1957 | F17: ='P&L'!F24 -> 6787.2016 | H17: =INDEX(Monthly!$C$57:$BJ$57,($R$2-1)*12+1) -> -23298.217 | I17: =INDEX(Monthly!$C$57:$BJ$57,($R$2-1)*12+2) -> -21306.119 | J17: =INDEX(Monthly!$C$57:$BJ$57,($R$2-1)*12+3) -> -25834.577 | K17: =INDEX(Monthly!$C$57:$BJ$57,($R$2-1)*12+4) -> -22523.035 | L17: =INDEX(Monthly!$C$57:$BJ$57,($R$2-1)*12+5) -> -19211.493 | M17: =INDEX(Monthly!$C$57:$BJ$57,($R$2-1)*12+6) -> -15899.951 | N17: =INDEX(Monthly!$C$57:$BJ$57,($R$2-1)*12+7) -> -12588.409 | O17: =INDEX(Monthly!$C$57:$BJ$57,($R$2-1)*12+8) -> -13196.867 | P17: =INDEX(Monthly!$C$57:$BJ$57,($R$2-1)*12+9) -> -13805.325 | Q17: =INDEX(Monthly!$C$57:$BJ$57,($R$2-1)*12+10) -> -10493.783 | R17: =INDEX(Monthly!$C$57:$BJ$57,($R$2-1)*12+11) -> -7182.241 | S17: =INDEX(Monthly!$C$57:$BJ$57,($R$2-1)*12+12) -> -3870.699
A18: Income tax | B18: ='P&L'!B25 -> 0 | C18: ='P&L'!C25 -> 0 | D18: ='P&L'!D25 -> 0 | E18: ='P&L'!E25 -> 0 | F18: ='P&L'!F25 -> 0 | H18: =INDEX(Monthly!$C$60:$BJ$60,($R$2-1)*12+1) -> 0 | I18: =INDEX(Monthly!$C$60:$BJ$60,($R$2-1)*12+2) -> 0 | J18: =INDEX(Monthly!$C$60:$BJ$60,($R$2-1)*12+3) -> 0 | K18: =INDEX(Monthly!$C$60:$BJ$60,($R$2-1)*12+4) -> 0 | L18: =INDEX(Monthly!$C$60:$BJ$60,($R$2-1)*12+5) -> 0 | M18: =INDEX(Monthly!$C$60:$BJ$60,($R$2-1)*12+6) -> 0 | N18: =INDEX(Monthly!$C$60:$BJ$60,($R$2-1)*12+7) -> 0 | O18: =INDEX(Monthly!$C$60:$BJ$60,($R$2-1)*12+8) -> 0 | P18: =INDEX(Monthly!$C$60:$BJ$60,($R$2-1)*12+9) -> 0 | Q18: =INDEX(Monthly!$C$60:$BJ$60,($R$2-1)*12+10) -> 0 | R18: =INDEX(Monthly!$C$60:$BJ$60,($R$2-1)*12+11) -> 0 | S18: =INDEX(Monthly!$C$60:$BJ$60,($R$2-1)*12+12) -> 0
A19: Net income | B19: ='P&L'!B26 -> -189210.72 | C19: ='P&L'!C26 -> -8209.3882 | D19: ='P&L'!D26 -> -3664.8586 | E19: ='P&L'!E26 -> 1500.1957 | F19: ='P&L'!F26 -> 6787.2016 | H19: =INDEX(Monthly!$C$61:$BJ$61,($R$2-1)*12+1) -> -23298.217 | I19: =INDEX(Monthly!$C$61:$BJ$61,($R$2-1)*12+2) -> -21306.119 | J19: =INDEX(Monthly!$C$61:$BJ$61,($R$2-1)*12+3) -> -25834.577 | K19: =INDEX(Monthly!$C$61:$BJ$61,($R$2-1)*12+4) -> -22523.035 | L19: =INDEX(Monthly!$C$61:$BJ$61,($R$2-1)*12+5) -> -19211.493 | M19: =INDEX(Monthly!$C$61:$BJ$61,($R$2-1)*12+6) -> -15899.951 | N19: =INDEX(Monthly!$C$61:$BJ$61,($R$2-1)*12+7) -> -12588.409 | O19: =INDEX(Monthly!$C$61:$BJ$61,($R$2-1)*12+8) -> -13196.867 | P19: =INDEX(Monthly!$C$61:$BJ$61,($R$2-1)*12+9) -> -13805.325 | Q19: =INDEX(Monthly!$C$61:$BJ$61,($R$2-1)*12+10) -> -10493.783 | R19: =INDEX(Monthly!$C$61:$BJ$61,($R$2-1)*12+11) -> -7182.241 | S19: =INDEX(Monthly!$C$61:$BJ$61,($R$2-1)*12+12) -> -3870.699
A20: Net margin | B20: ='P&L'!B27 -> -0.45081687 | C20: ='P&L'!C27 -> -0.011309428 | D20: ='P&L'!D27 -> -0.0049051282 | E20: ='P&L'!E27 -> 0.0019494129 | F20: ='P&L'!F27 -> 0.0085626746 | H20: =IF(H7=0,0,H19/H7) -> -1.4926143 | I20: =IF(I7=0,0,I19/I7) -> -1.181282 | J20: =IF(J7=0,0,J19/J7) -> -1.186358 | K20: =IF(K7=0,0,K19/K7) -> -0.88269161 | L20: =IF(L7=0,0,L19/L7) -> -0.65666287 | M20: =IF(M7=0,0,M19/M7) -> -0.48187237 | N20: =IF(N7=0,0,N19/N7) -> -0.34267112 | O20: =IF(O7=0,0,O19/O7) -> -0.32604127 | ... S20: =IF(S7=0,0,S19/S7) -> -0.069823076
A22: Cash flow ($'000) — by year | H22: ="Cash flow ($'000) — Year "&$R$2&", by month" -> Cash flow ($'000) — Year 1, by month
B23: 1 | C23: 2 | D23: 3 | E23: 4 | F23: 5 | H23: =INDEX(Monthly!$C$4:$BJ$4,($R$2-1)*12+1) -> 1 | I23: =INDEX(Monthly!$C$4:$BJ$4,($R$2-1)*12+2) -> 2 | J23: =INDEX(Monthly!$C$4:$BJ$4,($R$2-1)*12+3) -> 3 | K23: =INDEX(Monthly!$C$4:$BJ$4,($R$2-1)*12+4) -> 4 | L23: =INDEX(Monthly!$C$4:$BJ$4,($R$2-1)*12+5) -> 5 | M23: =INDEX(Monthly!$C$4:$BJ$4,($R$2-1)*12+6) -> 6 | N23: =INDEX(Monthly!$C$4:$BJ$4,($R$2-1)*12+7) -> 7 | O23: =INDEX(Monthly!$C$4:$BJ$4,($R$2-1)*12+8) -> 8 | P23: =INDEX(Monthly!$C$4:$BJ$4,($R$2-1)*12+9) -> 9 | Q23: =INDEX(Monthly!$C$4:$BJ$4,($R$2-1)*12+10) -> 10 | R23: =INDEX(Monthly!$C$4:$BJ$4,($R$2-1)*12+11) -> 11 | S23: =INDEX(Monthly!$C$4:$BJ$4,($R$2-1)*12+12) -> 12
A24: Operating cash flow | B24: ='Cash Flow'!B10 -> -161309.3 | C24: ='Cash Flow'!C10 -> 35051.747 | D24: ='Cash Flow'!D10 -> 41791.018 | E24: ='Cash Flow'!E10 -> 47839.748 | F24: ='Cash Flow'!F10 -> 54009.941 | H24: =INDEX(Monthly!$C$89:$BJ$89,($R$2-1)*12+1) -> -23923.317 | I24: =INDEX(Monthly!$C$89:$BJ$89,($R$2-1)*12+2) -> -18575.875 | J24: =INDEX(Monthly!$C$89:$BJ$89,($R$2-1)*12+3) -> -21582.417 | K24: =INDEX(Monthly!$C$89:$BJ$89,($R$2-1)*12+4) -> -20361.541 | L24: =INDEX(Monthly!$C$89:$BJ$89,($R$2-1)*12+5) -> -17049.999 | M24: =INDEX(Monthly!$C$89:$BJ$89,($R$2-1)*12+6) -> -13738.457 | N24: =INDEX(Monthly!$C$89:$BJ$89,($R$2-1)*12+7) -> -10426.915 | O24: =INDEX(Monthly!$C$89:$BJ$89,($R$2-1)*12+8) -> -9990.0399 | P24: =INDEX(Monthly!$C$89:$BJ$89,($R$2-1)*12+9) -> -10598.498 | Q24: =INDEX(Monthly!$C$89:$BJ$89,($R$2-1)*12+10) -> -8332.2892 | R24: =INDEX(Monthly!$C$89:$BJ$89,($R$2-1)*12+11) -> -5020.7472 | S24: =INDEX(Monthly!$C$89:$BJ$89,($R$2-1)*12+12) -> -1709.2052
A25: Capital spending | B25: ='Cash Flow'!B11 -> -442000 | C25: ='Cash Flow'!C11 -> -9000 | D25: ='Cash Flow'!D11 -> -9000 | E25: ='Cash Flow'!E11 -> -9000 | F25: ='Cash Flow'!F11 -> -9000 | H25: =INDEX(Monthly!$C$90:$BJ$90,($R$2-1)*12+1) -> -442000 | I25: =INDEX(Monthly!$C$90:$BJ$90,($R$2-1)*12+2) -> 0 | J25: =INDEX(Monthly!$C$90:$BJ$90,($R$2-1)*12+3) -> 0 | K25: =INDEX(Monthly!$C$90:$BJ$90,($R$2-1)*12+4) -> 0 | L25: =INDEX(Monthly!$C$90:$BJ$90,($R$2-1)*12+5) -> 0 | M25: =INDEX(Monthly!$C$90:$BJ$90,($R$2-1)*12+6) -> 0 | N25: =INDEX(Monthly!$C$90:$BJ$90,($R$2-1)*12+7) -> 0 | O25: =INDEX(Monthly!$C$90:$BJ$90,($R$2-1)*12+8) -> 0 | P25: =INDEX(Monthly!$C$90:$BJ$90,($R$2-1)*12+9) -> 0 | Q25: =INDEX(Monthly!$C$90:$BJ$90,($R$2-1)*12+10) -> 0 | R25: =INDEX(Monthly!$C$90:$BJ$90,($R$2-1)*12+11) -> 0 | S25: =INDEX(Monthly!$C$90:$BJ$90,($R$2-1)*12+12) -> 0
A26: Equity raised | B26: ='Cash Flow'!B12 -> 450000 | C26: ='Cash Flow'!C12 -> 0 | D26: ='Cash Flow'!D12 -> 0 | E26: ='Cash Flow'!E12 -> 0 | F26: ='Cash Flow'!F12 -> 0 | H26: =INDEX(Monthly!$C$91:$BJ$91,($R$2-1)*12+1) -> 450000 | I26: =INDEX(Monthly!$C$91:$BJ$91,($R$2-1)*12+2) -> 0 | J26: =INDEX(Monthly!$C$91:$BJ$91,($R$2-1)*12+3) -> 0 | K26: =INDEX(Monthly!$C$91:$BJ$91,($R$2-1)*12+4) -> 0 | L26: =INDEX(Monthly!$C$91:$BJ$91,($R$2-1)*12+5) -> 0 | M26: =INDEX(Monthly!$C$91:$BJ$91,($R$2-1)*12+6) -> 0 | N26: =INDEX(Monthly!$C$91:$BJ$91,($R$2-1)*12+7) -> 0 | O26: =INDEX(Monthly!$C$91:$BJ$91,($R$2-1)*12+8) -> 0 | P26: =INDEX(Monthly!$C$91:$BJ$91,($R$2-1)*12+9) -> 0 | Q26: =INDEX(Monthly!$C$91:$BJ$91,($R$2-1)*12+10) -> 0 | R26: =INDEX(Monthly!$C$91:$BJ$91,($R$2-1)*12+11) -> 0 | S26: =INDEX(Monthly!$C$91:$BJ$91,($R$2-1)*12+12) -> 0
A27: Loan drawdown | B27: ='Cash Flow'!B13 -> 250000 | C27: ='Cash Flow'!C13 -> 0 | D27: ='Cash Flow'!D13 -> 0 | E27: ='Cash Flow'!E13 -> 0 | F27: ='Cash Flow'!F13 -> 0 | H27: =INDEX(Monthly!$C$76:$BJ$76,($R$2-1)*12+1) -> 250000 | I27: =INDEX(Monthly!$C$76:$BJ$76,($R$2-1)*12+2) -> 0 | J27: =INDEX(Monthly!$C$76:$BJ$76,($R$2-1)*12+3) -> 0 | K27: =INDEX(Monthly!$C$76:$BJ$76,($R$2-1)*12+4) -> 0 | L27: =INDEX(Monthly!$C$76:$BJ$76,($R$2-1)*12+5) -> 0 | M27: =INDEX(Monthly!$C$76:$BJ$76,($R$2-1)*12+6) -> 0 | N27: =INDEX(Monthly!$C$76:$BJ$76,($R$2-1)*12+7) -> 0 | O27: =INDEX(Monthly!$C$76:$BJ$76,($R$2-1)*12+8) -> 0 | P27: =INDEX(Monthly!$C$76:$BJ$76,($R$2-1)*12+9) -> 0 | Q27: =INDEX(Monthly!$C$76:$BJ$76,($R$2-1)*12+10) -> 0 | R27: =INDEX(Monthly!$C$76:$BJ$76,($R$2-1)*12+11) -> 0 | S27: =INDEX(Monthly!$C$76:$BJ$76,($R$2-1)*12+12) -> 0
A28: Loan repayment | B28: ='Cash Flow'!B14 -> -22916.667 | C28: ='Cash Flow'!C14 -> -25000 | D28: ='Cash Flow'!D14 -> -25000 | E28: ='Cash Flow'!E14 -> -25000 | F28: ='Cash Flow'!F14 -> -25000 | H28: =INDEX(Monthly!$C$77:$BJ$77,($R$2-1)*12+1) -> 0 | I28: =INDEX(Monthly!$C$77:$BJ$77,($R$2-1)*12+2) -> -2083.3333 | J28: =INDEX(Monthly!$C$77:$BJ$77,($R$2-1)*12+3) -> -2083.3333 | K28: =INDEX(Monthly!$C$77:$BJ$77,($R$2-1)*12+4) -> -2083.3333 | L28: =INDEX(Monthly!$C$77:$BJ$77,($R$2-1)*12+5) -> -2083.3333 | M28: =INDEX(Monthly!$C$77:$BJ$77,($R$2-1)*12+6) -> -2083.3333 | N28: =INDEX(Monthly!$C$77:$BJ$77,($R$2-1)*12+7) -> -2083.3333 | O28: =INDEX(Monthly!$C$77:$BJ$77,($R$2-1)*12+8) -> -2083.3333 | P28: =INDEX(Monthly!$C$77:$BJ$77,($R$2-1)*12+9) -> -2083.3333 | Q28: =INDEX(Monthly!$C$77:$BJ$77,($R$2-1)*12+10) -> -2083.3333 | R28: =INDEX(Monthly!$C$77:$BJ$77,($R$2-1)*12+11) -> -2083.3333 | S28: =INDEX(Monthly!$C$77:$BJ$77,($R$2-1)*12+12) -> -2083.3333
A29: Financing cash flow | B29: ='Cash Flow'!B15 -> 677083.33 | C29: ='Cash Flow'!C15 -> -25000 | D29: ='Cash Flow'!D15 -> -25000 | E29: ='Cash Flow'!E15 -> -25000 | F29: ='Cash Flow'!F15 -> -25000 | H29: =INDEX(Monthly!$C$92:$BJ$92,($R$2-1)*12+1) -> 700000 | I29: =INDEX(Monthly!$C$92:$BJ$92,($R$2-1)*12+2) -> -2083.3333 | J29: =INDEX(Monthly!$C$92:$BJ$92,($R$2-1)*12+3) -> -2083.3333 | K29: =INDEX(Monthly!$C$92:$BJ$92,($R$2-1)*12+4) -> -2083.3333 | L29: =INDEX(Monthly!$C$92:$BJ$92,($R$2-1)*12+5) -> -2083.3333 | M29: =INDEX(Monthly!$C$92:$BJ$92,($R$2-1)*12+6) -> -2083.3333 | N29: =INDEX(Monthly!$C$92:$BJ$92,($R$2-1)*12+7) -> -2083.3333 | O29: =INDEX(Monthly!$C$92:$BJ$92,($R$2-1)*12+8) -> -2083.3333 | P29: =INDEX(Monthly!$C$92:$BJ$92,($R$2-1)*12+9) -> -2083.3333 | Q29: =INDEX(Monthly!$C$92:$BJ$92,($R$2-1)*12+10) -> -2083.3333 | R29: =INDEX(Monthly!$C$92:$BJ$92,($R$2-1)*12+11) -> -2083.3333 | S29: =INDEX(Monthly!$C$92:$BJ$92,($R$2-1)*12+12) -> -2083.3333
A30: Net change in cash | B30: ='Cash Flow'!B16 -> 73774.032 | C30: ='Cash Flow'!C16 -> 1051.747 | D30: ='Cash Flow'!D16 -> 7791.0179 | E30: ='Cash Flow'!E16 -> 13839.748 | F30: ='Cash Flow'!F16 -> 20009.941 | H30: =INDEX(Monthly!$C$93:$BJ$93,($R$2-1)*12+1) -> 234076.68 | I30: =INDEX(Monthly!$C$93:$BJ$93,($R$2-1)*12+2) -> -20659.209 | J30: =INDEX(Monthly!$C$93:$BJ$93,($R$2-1)*12+3) -> -23665.75 | K30: =INDEX(Monthly!$C$93:$BJ$93,($R$2-1)*12+4) -> -22444.875 | L30: =INDEX(Monthly!$C$93:$BJ$93,($R$2-1)*12+5) -> -19133.333 | M30: =INDEX(Monthly!$C$93:$BJ$93,($R$2-1)*12+6) -> -15821.791 | N30: =INDEX(Monthly!$C$93:$BJ$93,($R$2-1)*12+7) -> -12510.249 | O30: =INDEX(Monthly!$C$93:$BJ$93,($R$2-1)*12+8) -> -12073.373 | P30: =INDEX(Monthly!$C$93:$BJ$93,($R$2-1)*12+9) -> -12681.831 | Q30: =INDEX(Monthly!$C$93:$BJ$93,($R$2-1)*12+10) -> -10415.623 | R30: =INDEX(Monthly!$C$93:$BJ$93,($R$2-1)*12+11) -> -7104.0806 | S30: =INDEX(Monthly!$C$93:$BJ$93,($R$2-1)*12+12) -> -3792.5385
A31: Closing cash | B31: ='Cash Flow'!B18 -> 73774.032 | C31: ='Cash Flow'!C18 -> 74825.779 | D31: ='Cash Flow'!D18 -> 82616.797 | E31: ='Cash Flow'!E18 -> 96456.545 | F31: ='Cash Flow'!F18 -> 116466.49 | H31: =INDEX(Monthly!$C$95:$BJ$95,($R$2-1)*12+1) -> 234076.68 | I31: =INDEX(Monthly!$C$95:$BJ$95,($R$2-1)*12+2) -> 213417.47 | J31: =INDEX(Monthly!$C$95:$BJ$95,($R$2-1)*12+3) -> 189751.72 | K31: =INDEX(Monthly!$C$95:$BJ$95,($R$2-1)*12+4) -> 167306.85 | L31: =INDEX(Monthly!$C$95:$BJ$95,($R$2-1)*12+5) -> 148173.52 | M31: =INDEX(Monthly!$C$95:$BJ$95,($R$2-1)*12+6) -> 132351.73 | N31: =INDEX(Monthly!$C$95:$BJ$95,($R$2-1)*12+7) -> 119841.48 | O31: =INDEX(Monthly!$C$95:$BJ$95,($R$2-1)*12+8) -> 107768.1 | P31: =INDEX(Monthly!$C$95:$BJ$95,($R$2-1)*12+9) -> 95086.274 | Q31: =INDEX(Monthly!$C$95:$BJ$95,($R$2-1)*12+10) -> 84670.651 | R31: =INDEX(Monthly!$C$95:$BJ$95,($R$2-1)*12+11) -> 77566.57 | S31: =INDEX(Monthly!$C$95:$BJ$95,($R$2-1)*12+12) -> 73774.032
A39: Balance sheet at year end ($'000) | H39: ="Balance sheet at month end ($'000) — Year "&$R$2 -> Balance sheet at month end ($'000) — Year 1
B40: 1 | C40: 2 | D40: 3 | E40: 4 | F40: 5 | H40: =INDEX(Monthly!$C$4:$BJ$4,($R$2-1)*12+1) -> 1 | I40: =INDEX(Monthly!$C$4:$BJ$4,($R$2-1)*12+2) -> 2 | J40: =INDEX(Monthly!$C$4:$BJ$4,($R$2-1)*12+3) -> 3 | K40: =INDEX(Monthly!$C$4:$BJ$4,($R$2-1)*12+4) -> 4 | L40: =INDEX(Monthly!$C$4:$BJ$4,($R$2-1)*12+5) -> 5 | M40: =INDEX(Monthly!$C$4:$BJ$4,($R$2-1)*12+6) -> 6 | N40: =INDEX(Monthly!$C$4:$BJ$4,($R$2-1)*12+7) -> 7 | O40: =INDEX(Monthly!$C$4:$BJ$4,($R$2-1)*12+8) -> 8 | P40: =INDEX(Monthly!$C$4:$BJ$4,($R$2-1)*12+9) -> 9 | Q40: =INDEX(Monthly!$C$4:$BJ$4,($R$2-1)*12+10) -> 10 | R40: =INDEX(Monthly!$C$4:$BJ$4,($R$2-1)*12+11) -> 11 | S40: =INDEX(Monthly!$C$4:$BJ$4,($R$2-1)*12+12) -> 12
A41: Cash | B41: ='Balance Sheet'!B5 -> 73774.032 | C41: ='Balance Sheet'!C5 -> 74825.779 | D41: ='Balance Sheet'!D5 -> 82616.797 | E41: ='Balance Sheet'!E5 -> 96456.545 | F41: ='Balance Sheet'!F5 -> 116466.49 | H41: =INDEX(Monthly!$C$95:$BJ$95,($R$2-1)*12+1) -> 234076.68 | I41: =INDEX(Monthly!$C$95:$BJ$95,($R$2-1)*12+2) -> 213417.47 | J41: =INDEX(Monthly!$C$95:$BJ$95,($R$2-1)*12+3) -> 189751.72 | K41: =INDEX(Monthly!$C$95:$BJ$95,($R$2-1)*12+4) -> 167306.85 | L41: =INDEX(Monthly!$C$95:$BJ$95,($R$2-1)*12+5) -> 148173.52 | M41: =INDEX(Monthly!$C$95:$BJ$95,($R$2-1)*12+6) -> 132351.73 | N41: =INDEX(Monthly!$C$95:$BJ$95,($R$2-1)*12+7) -> 119841.48 | O41: =INDEX(Monthly!$C$95:$BJ$95,($R$2-1)*12+8) -> 107768.1 | P41: =INDEX(Monthly!$C$95:$BJ$95,($R$2-1)*12+9) -> 95086.274 | Q41: =INDEX(Monthly!$C$95:$BJ$95,($R$2-1)*12+10) -> 84670.651 | R41: =INDEX(Monthly!$C$95:$BJ$95,($R$2-1)*12+11) -> 77566.57 | S41: =INDEX(Monthly!$C$95:$BJ$95,($R$2-1)*12+12) -> 73774.032
A42: Accounts receivable | B42: ='Balance Sheet'!B6 -> 24022.185 | C42: ='Balance Sheet'!C6 -> 26194.522 | D42: ='Balance Sheet'!D6 -> 26980.358 | E42: ='Balance Sheet'!E6 -> 27789.769 | F42: ='Balance Sheet'!F6 -> 28623.462 | H42: =INDEX(Monthly!$C$81:$BJ$81,($R$2-1)*12+1) -> 6763.9 | I42: =INDEX(Monthly!$C$81:$BJ$81,($R$2-1)*12+2) -> 7815.7896 | J42: =INDEX(Monthly!$C$81:$BJ$81,($R$2-1)*12+3) -> 9436.4292 | K42: =INDEX(Monthly!$C$81:$BJ$81,($R$2-1)*12+4) -> 11057.069 | L42: =INDEX(Monthly!$C$81:$BJ$81,($R$2-1)*12+5) -> 12677.708 | M42: =INDEX(Monthly!$C$81:$BJ$81,($R$2-1)*12+6) -> 14298.348 | N42: =INDEX(Monthly!$C$81:$BJ$81,($R$2-1)*12+7) -> 15918.987 | O42: =INDEX(Monthly!$C$81:$BJ$81,($R$2-1)*12+8) -> 17539.627 | P42: =INDEX(Monthly!$C$81:$BJ$81,($R$2-1)*12+9) -> 19160.267 | Q42: =INDEX(Monthly!$C$81:$BJ$81,($R$2-1)*12+10) -> 20780.906 | R42: =INDEX(Monthly!$C$81:$BJ$81,($R$2-1)*12+11) -> 22401.546 | S42: =INDEX(Monthly!$C$81:$BJ$81,($R$2-1)*12+12) -> 24022.185
A43: Inventory | B43: ='Balance Sheet'!B7 -> 2896.35 | C43: ='Balance Sheet'!C7 -> 3021.402 | D43: ='Balance Sheet'!D7 -> 3112.0441 | E43: ='Balance Sheet'!E7 -> 3205.4054 | F43: ='Balance Sheet'!F7 -> 3301.5675 | H43: =INDEX(Monthly!$C$82:$BJ$82,($R$2-1)*12+1) -> 920.8 | I43: =INDEX(Monthly!$C$82:$BJ$82,($R$2-1)*12+2) -> 957.85 | J43: =INDEX(Monthly!$C$82:$BJ$82,($R$2-1)*12+3) -> 1778.9 | K43: =INDEX(Monthly!$C$82:$BJ$82,($R$2-1)*12+4) -> 1815.95 | L43: =INDEX(Monthly!$C$82:$BJ$82,($R$2-1)*12+5) -> 1853 | M43: =INDEX(Monthly!$C$82:$BJ$82,($R$2-1)*12+6) -> 1890.05 | N43: =INDEX(Monthly!$C$82:$BJ$82,($R$2-1)*12+7) -> 1927.1 | O43: =INDEX(Monthly!$C$82:$BJ$82,($R$2-1)*12+8) -> 2356.15 | P43: =INDEX(Monthly!$C$82:$BJ$82,($R$2-1)*12+9) -> 2785.2 | Q43: =INDEX(Monthly!$C$82:$BJ$82,($R$2-1)*12+10) -> 2822.25 | R43: =INDEX(Monthly!$C$82:$BJ$82,($R$2-1)*12+11) -> 2859.3 | S43: =INDEX(Monthly!$C$82:$BJ$82,($R$2-1)*12+12) -> 2896.35
A44: Net fixed assets | B44: ='Balance Sheet'!B8 -> 397800 | C44: ='Balance Sheet'!C8 -> 361700 | D44: ='Balance Sheet'!D8 -> 324700 | E44: ='Balance Sheet'!E8 -> 286800 | F44: ='Balance Sheet'!F8 -> 248000 | H44: =INDEX(Monthly!$C$72:$BJ$72,($R$2-1)*12+1) -> 438316.67 | I44: =INDEX(Monthly!$C$72:$BJ$72,($R$2-1)*12+2) -> 434633.33 | J44: =INDEX(Monthly!$C$72:$BJ$72,($R$2-1)*12+3) -> 430950 | K44: =INDEX(Monthly!$C$72:$BJ$72,($R$2-1)*12+4) -> 427266.67 | L44: =INDEX(Monthly!$C$72:$BJ$72,($R$2-1)*12+5) -> 423583.33 | M44: =INDEX(Monthly!$C$72:$BJ$72,($R$2-1)*12+6) -> 419900 | N44: =INDEX(Monthly!$C$72:$BJ$72,($R$2-1)*12+7) -> 416216.67 | O44: =INDEX(Monthly!$C$72:$BJ$72,($R$2-1)*12+8) -> 412533.33 | P44: =INDEX(Monthly!$C$72:$BJ$72,($R$2-1)*12+9) -> 408850 | Q44: =INDEX(Monthly!$C$72:$BJ$72,($R$2-1)*12+10) -> 405166.67 | R44: =INDEX(Monthly!$C$72:$BJ$72,($R$2-1)*12+11) -> 401483.33 | S44: =INDEX(Monthly!$C$72:$BJ$72,($R$2-1)*12+12) -> 397800
A45: Total assets | B45: ='Balance Sheet'!B9 -> 498492.57 | C45: ='Balance Sheet'!C9 -> 465741.7 | D45: ='Balance Sheet'!D9 -> 437409.2 | E45: ='Balance Sheet'!E9 -> 414251.72 | F45: ='Balance Sheet'!F9 -> 396391.52 | H45: =INDEX(Monthly!$C$109:$BJ$109,($R$2-1)*12+1) -> 680078.05 | I45: =INDEX(Monthly!$C$109:$BJ$109,($R$2-1)*12+2) -> 656824.45 | J45: =INDEX(Monthly!$C$109:$BJ$109,($R$2-1)*12+3) -> 631917.05 | K45: =INDEX(Monthly!$C$109:$BJ$109,($R$2-1)*12+4) -> 607446.54 | L45: =INDEX(Monthly!$C$109:$BJ$109,($R$2-1)*12+5) -> 586287.56 | M45: =INDEX(Monthly!$C$109:$BJ$109,($R$2-1)*12+6) -> 568440.12 | N45: =INDEX(Monthly!$C$109:$BJ$109,($R$2-1)*12+7) -> 553904.23 | O45: =INDEX(Monthly!$C$109:$BJ$109,($R$2-1)*12+8) -> 540197.22 | P45: =INDEX(Monthly!$C$109:$BJ$109,($R$2-1)*12+9) -> 525881.74 | Q45: =INDEX(Monthly!$C$109:$BJ$109,($R$2-1)*12+10) -> 513440.47 | R45: =INDEX(Monthly!$C$109:$BJ$109,($R$2-1)*12+11) -> 504310.75 | S45: =INDEX(Monthly!$C$109:$BJ$109,($R$2-1)*12+12) -> 498492.57
A46: Accounts payable | B46: ='Balance Sheet'!B10 -> 10619.95 | C46: ='Balance Sheet'!C10 -> 11078.474 | D46: ='Balance Sheet'!D10 -> 11410.828 | E46: ='Balance Sheet'!E10 -> 11753.153 | F46: ='Balance Sheet'!F10 -> 12105.748 | H46: =INDEX(Monthly!$C$83:$BJ$83,($R$2-1)*12+1) -> 3376.2667 | I46: =INDEX(Monthly!$C$83:$BJ$83,($R$2-1)*12+2) -> 3512.1167 | J46: =INDEX(Monthly!$C$83:$BJ$83,($R$2-1)*12+3) -> 6522.6333 | K46: =INDEX(Monthly!$C$83:$BJ$83,($R$2-1)*12+4) -> 6658.4833 | L46: =INDEX(Monthly!$C$83:$BJ$83,($R$2-1)*12+5) -> 6794.3333 | M46: =INDEX(Monthly!$C$83:$BJ$83,($R$2-1)*12+6) -> 6930.1833 | N46: =INDEX(Monthly!$C$83:$BJ$83,($R$2-1)*12+7) -> 7066.0333 | O46: =INDEX(Monthly!$C$83:$BJ$83,($R$2-1)*12+8) -> 8639.2167 | P46: =INDEX(Monthly!$C$83:$BJ$83,($R$2-1)*12+9) -> 10212.4 | Q46: =INDEX(Monthly!$C$83:$BJ$83,($R$2-1)*12+10) -> 10348.25 | R46: =INDEX(Monthly!$C$83:$BJ$83,($R$2-1)*12+11) -> 10484.1 | S46: =INDEX(Monthly!$C$83:$BJ$83,($R$2-1)*12+12) -> 10619.95
A47: Loan | B47: ='Balance Sheet'!B11 -> 227083.33 | C47: ='Balance Sheet'!C11 -> 202083.33 | D47: ='Balance Sheet'!D11 -> 177083.33 | E47: ='Balance Sheet'!E11 -> 152083.33 | F47: ='Balance Sheet'!F11 -> 127083.33 | H47: =INDEX(Monthly!$C$78:$BJ$78,($R$2-1)*12+1) -> 250000 | I47: =INDEX(Monthly!$C$78:$BJ$78,($R$2-1)*12+2) -> 247916.67 | J47: =INDEX(Monthly!$C$78:$BJ$78,($R$2-1)*12+3) -> 245833.33 | K47: =INDEX(Monthly!$C$78:$BJ$78,($R$2-1)*12+4) -> 243750 | L47: =INDEX(Monthly!$C$78:$BJ$78,($R$2-1)*12+5) -> 241666.67 | M47: =INDEX(Monthly!$C$78:$BJ$78,($R$2-1)*12+6) -> 239583.33 | N47: =INDEX(Monthly!$C$78:$BJ$78,($R$2-1)*12+7) -> 237500 | O47: =INDEX(Monthly!$C$78:$BJ$78,($R$2-1)*12+8) -> 235416.67 | P47: =INDEX(Monthly!$C$78:$BJ$78,($R$2-1)*12+9) -> 233333.33 | Q47: =INDEX(Monthly!$C$78:$BJ$78,($R$2-1)*12+10) -> 231250 | R47: =INDEX(Monthly!$C$78:$BJ$78,($R$2-1)*12+11) -> 229166.67 | S47: =INDEX(Monthly!$C$78:$BJ$78,($R$2-1)*12+12) -> 227083.33
A48: Total liabilities | B48: ='Balance Sheet'!B12 -> 237703.28 | C48: ='Balance Sheet'!C12 -> 213161.81 | D48: ='Balance Sheet'!D12 -> 188494.16 | E48: ='Balance Sheet'!E12 -> 163836.49 | F48: ='Balance Sheet'!F12 -> 139189.08 | H48: =INDEX(Monthly!$C$110:$BJ$110,($R$2-1)*12+1) -> 253376.27 | I48: =INDEX(Monthly!$C$110:$BJ$110,($R$2-1)*12+2) -> 251428.78 | J48: =INDEX(Monthly!$C$110:$BJ$110,($R$2-1)*12+3) -> 252355.97 | K48: =INDEX(Monthly!$C$110:$BJ$110,($R$2-1)*12+4) -> 250408.48 | L48: =INDEX(Monthly!$C$110:$BJ$110,($R$2-1)*12+5) -> 248461 | M48: =INDEX(Monthly!$C$110:$BJ$110,($R$2-1)*12+6) -> 246513.52 | N48: =INDEX(Monthly!$C$110:$BJ$110,($R$2-1)*12+7) -> 244566.03 | O48: =INDEX(Monthly!$C$110:$BJ$110,($R$2-1)*12+8) -> 244055.88 | P48: =INDEX(Monthly!$C$110:$BJ$110,($R$2-1)*12+9) -> 243545.73 | Q48: =INDEX(Monthly!$C$110:$BJ$110,($R$2-1)*12+10) -> 241598.25 | R48: =INDEX(Monthly!$C$110:$BJ$110,($R$2-1)*12+11) -> 239650.77 | S48: =INDEX(Monthly!$C$110:$BJ$110,($R$2-1)*12+12) -> 237703.28
A49: Paid-in capital | B49: ='Balance Sheet'!B13 -> 450000 | C49: ='Balance Sheet'!C13 -> 450000 | D49: ='Balance Sheet'!D13 -> 450000 | E49: ='Balance Sheet'!E13 -> 450000 | F49: ='Balance Sheet'!F13 -> 450000 | H49: =INDEX(Monthly!$C$107:$BJ$107,($R$2-1)*12+1) -> 450000 | I49: =INDEX(Monthly!$C$107:$BJ$107,($R$2-1)*12+2) -> 450000 | J49: =INDEX(Monthly!$C$107:$BJ$107,($R$2-1)*12+3) -> 450000 | K49: =INDEX(Monthly!$C$107:$BJ$107,($R$2-1)*12+4) -> 450000 | L49: =INDEX(Monthly!$C$107:$BJ$107,($R$2-1)*12+5) -> 450000 | M49: =INDEX(Monthly!$C$107:$BJ$107,($R$2-1)*12+6) -> 450000 | N49: =INDEX(Monthly!$C$107:$BJ$107,($R$2-1)*12+7) -> 450000 | O49: =INDEX(Monthly!$C$107:$BJ$107,($R$2-1)*12+8) -> 450000 | P49: =INDEX(Monthly!$C$107:$BJ$107,($R$2-1)*12+9) -> 450000 | Q49: =INDEX(Monthly!$C$107:$BJ$107,($R$2-1)*12+10) -> 450000 | R49: =INDEX(Monthly!$C$107:$BJ$107,($R$2-1)*12+11) -> 450000 | S49: =INDEX(Monthly!$C$107:$BJ$107,($R$2-1)*12+12) -> 450000
A50: Retained earnings | B50: ='Balance Sheet'!B14 -> -189210.72 | C50: ='Balance Sheet'!C14 -> -197420.1 | D50: ='Balance Sheet'!D14 -> -201084.96 | E50: ='Balance Sheet'!E14 -> -199584.77 | F50: ='Balance Sheet'!F14 -> -192797.57 | H50: =INDEX(Monthly!$C$108:$BJ$108,($R$2-1)*12+1) -> -23298.217 | I50: =INDEX(Monthly!$C$108:$BJ$108,($R$2-1)*12+2) -> -44604.336 | J50: =INDEX(Monthly!$C$108:$BJ$108,($R$2-1)*12+3) -> -70438.913 | K50: =INDEX(Monthly!$C$108:$BJ$108,($R$2-1)*12+4) -> -92961.948 | L50: =INDEX(Monthly!$C$108:$BJ$108,($R$2-1)*12+5) -> -112173.44 | M50: =INDEX(Monthly!$C$108:$BJ$108,($R$2-1)*12+6) -> -128073.39 | N50: =INDEX(Monthly!$C$108:$BJ$108,($R$2-1)*12+7) -> -140661.8 | O50: =INDEX(Monthly!$C$108:$BJ$108,($R$2-1)*12+8) -> -153858.67 | P50: =INDEX(Monthly!$C$108:$BJ$108,($R$2-1)*12+9) -> -167663.99 | Q50: =INDEX(Monthly!$C$108:$BJ$108,($R$2-1)*12+10) -> -178157.78 | R50: =INDEX(Monthly!$C$108:$BJ$108,($R$2-1)*12+11) -> -185340.02 | S50: =INDEX(Monthly!$C$108:$BJ$108,($R$2-1)*12+12) -> -189210.72
...

Sheet Scenarios
A1: Scenarios — Low / Base / High | H1: =HYPERLINK("#'Cover'!A1","◂ Contents") -> ◂ Contents
A2: All three scenarios calculated side by side, live: change any input and every column updates. Active = the scenario chosen on the Dashboard.
A5: Key drivers
A6: Driver | B6: Low | C6: Base | D6: High | E6: Active
A7: Licensed places (children) at start (#) | B7: =Inputs!$B$7 -> 60 | C7: =Inputs!$C$7 -> 60 | D7: =Inputs!$D$7 -> 60 | E7: =Inputs!$E$7 -> 60
A8: Enrolment once full, % of licensed places (%) | B8: =Inputs!$B$10 -> 0.78 | C8: =Inputs!$C$10 -> 0.85 | D8: =Inputs!$D$10 -> 0.9 | E8: =Inputs!$E$10 -> 0.85
A9: Tuition per infant / toddler per month (year 1) ($) | B9: =Inputs!$B$17 -> 1430 | C9: =Inputs!$C$17 -> 1500 | D9: =Inputs!$D$17 -> 1570 | E9: =Inputs!$E$17 -> 1500
A10: Tuition per preschooler per month (year 1) ($) | B10: =Inputs!$B$18 -> 1040 | C10: =Inputs!$C$18 -> 1100 | D10: =Inputs!$D$18 -> 1160 | E10: =Inputs!$E$18 -> 1100
A11: Children paid by subsidy / vouchers, % of enrolled (%) | B11: =Inputs!$B$22 -> 0.25 | C11: =Inputs!$C$22 -> 0.25 | D11: =Inputs!$D$22 -> 0.25 | E11: =Inputs!$E$22 -> 0.25
A12: Rent per square foot per year (year 1) ($) | B12: =Inputs!$B$38 -> 17 | C12: =Inputs!$C$38 -> 16 | D12: =Inputs!$D$38 -> 15 | E12: =Inputs!$E$38 -> 16
A13: Equity raised at start ($) | B13: =Inputs!$B$73 -> 450000 | C13: =Inputs!$C$73 -> 450000 | D13: =Inputs!$D$73 -> 450000 | E13: =Inputs!$E$73 -> 450000
A15: Results by scenario ($'000)
A16: Output | B16: Low | C16: Base | D16: High | E16: Active
A17: Revenue — final year | B17: =F30 -> 665483.7 | C17: =F31 -> 792649.71 | D17: =F32 -> 932012.18 | E17: ='P&L'!F5 -> 792649.71
A18: Revenue — whole plan | B18: =SUM(B30:F30) -> 2787044.2 | C18: =SUM(B31:F31) -> 3454956.2 | D18: =SUM(B32:F32) -> 4086174.7 | E18: =SUM('P&L'!$B$5:$F$5) -> 3454956.2
A19: EBITDA — final year | B19: =F36 -> -92680.594 | C19: =F37 -> 65753.868 | D19: =F38 -> 189614.03 | E19: ='P&L'!F19 -> 65753.868
A20: EBITDA margin — final year | B20: =IF(B17=0,0,B19/B17) -> -0.13926802 | C20: =IF(C17=0,0,C19/C17) -> 0.08295451 | D20: =IF(D17=0,0,D19/D17) -> 0.20344587 | E20: =IF(E17=0,0,E19/E17) -> 0.08295451
A21: Net income — final year | B21: =F42 -> -151647.26 | C21: =F43 -> 6787.2016 | D21: =F44 -> 103211.42 | E21: ='P&L'!F26 -> 6787.2016
A22: Net income — whole plan | B22: =SUM(B42:F42) -> -912098.28 | C22: =SUM(B43:F43) -> -192797.57 | D22: =SUM(B44:F44) -> 285694.57 | E22: =SUM('P&L'!$B$26:$F$26) -> -192797.57
A23: Cash at the end of the plan | B23: =F48 -> -597675.42 | C23: =F49 -> 116466.49 | D23: =F50 -> 590407.17 | E23: ='Balance Sheet'!F5 -> 116466.49
A24: Lowest cash balance | B24: =MIN('Scenario calc'!$C$97:$BJ$97) -> -597675.42 | C24: =MIN('Scenario calc'!$C$223:$BJ$223) -> 64092.356 | D24: =MIN('Scenario calc'!$C$349:$BJ$349) -> 173336.78 | E24: ='Break-even'!B18 -> 64092.356
A25: Lowest cash point (month #) | B25: =MATCH(MIN('Scenario calc'!$C$97:$BJ$97),'Scenario calc'!$C$97:$BJ$97,0) -> 60 | C25: =MATCH(MIN('Scenario calc'!$C$223:$BJ$223),'Scenario calc'!$C$223:$BJ$223,0) -> 13 | D25: =MATCH(MIN('Scenario calc'!$C$349:$BJ$349),'Scenario calc'!$C$349:$BJ$349,0) -> 8 | E25: ='Break-even'!B6 -> 13
A26: Funding required (incl. cash buffer) | B26: =SUMPRODUCT(--('Scenario calc'!$C$6:$BJ$6<=B25),'Scenario calc'!$C$70:$BJ$70)-SUMPRODUCT(--('Scenario calc'!$C$6:$BJ$6<=B25),'Scenario calc'!$C$91:$BJ$91)-SUMPRODUCT(--('Scenario calc'!$C$6:$BJ$6<=B25),'Scenario calc'!$C$79:$BJ$79)+Inputs!$B$88 -> 1371675.4 | C26: =SUMPRODUCT(--('Scenario calc'!$C$132:$BJ$132<=C25),'Scenario calc'!$C$196:$BJ$196)-SUMPRODUCT(--('Scenario calc'!$C$132:$BJ$132<=C25),'Scenario calc'!$C$217:$BJ$217)-SUMPRODUCT(--('Scenario calc'!$C$132:$BJ$132<=C25),'Scenario calc'!$C$205:$BJ$205)+Inputs!$C$88 -> 709907.64 | D26: =SUMPRODUCT(--('Scenario calc'!$C$258:$BJ$258<=D25),'Scenario calc'!$C$322:$BJ$322)-SUMPRODUCT(--('Scenario calc'!$C$258:$BJ$258<=D25),'Scenario calc'!$C$343:$BJ$343)-SUMPRODUCT(--('Scenario calc'!$C$258:$BJ$258<=D25),'Scenario calc'!$C$331:$BJ$331)+Inputs!$D$88 -> 600663.22 | E26: ='Break-even'!B12 -> 709907.64
A28: Revenue by year ($'000)
A29: Scenario | B29: 1 | C29: 2 | D29: 3 | E29: 4 | F29: 5
A30: Low | B30: =SUMIF('Scenario calc'!$C$7:$BJ$7,B$29,'Scenario calc'!$C$34:$BJ$34) -> 267942.91 | C30: =SUMIF('Scenario calc'!$C$7:$BJ$7,C$29,'Scenario calc'!$C$34:$BJ$34) -> 570948.2 | D30: =SUMIF('Scenario calc'!$C$7:$BJ$7,D$29,'Scenario calc'!$C$34:$BJ$34) -> 633416.96 | E30: =SUMIF('Scenario calc'!$C$7:$BJ$7,E$29,'Scenario calc'!$C$34:$BJ$34) -> 649252.39 | F30: =SUMIF('Scenario calc'!$C$7:$BJ$7,F$29,'Scenario calc'!$C$34:$BJ$34) -> 665483.7
A31: Base | B31: =SUMIF('Scenario calc'!$C$133:$BJ$133,B$29,'Scenario calc'!$C$160:$BJ$160) -> 419706.38 | C31: =SUMIF('Scenario calc'!$C$133:$BJ$133,C$29,'Scenario calc'!$C$160:$BJ$160) -> 725888.9 | D31: =SUMIF('Scenario calc'!$C$133:$BJ$133,D$29,'Scenario calc'!$C$160:$BJ$160) -> 747148.37 | E31: =SUMIF('Scenario calc'!$C$133:$BJ$133,E$29,'Scenario calc'!$C$160:$BJ$160) -> 769562.82 | F31: =SUMIF('Scenario calc'!$C$133:$BJ$133,F$29,'Scenario calc'!$C$160:$BJ$160) -> 792649.71
A32: High | B32: =SUMIF('Scenario calc'!$C$259:$BJ$259,B$29,'Scenario calc'!$C$286:$BJ$286) -> 567743.87 | C32: =SUMIF('Scenario calc'!$C$259:$BJ$259,C$29,'Scenario calc'!$C$286:$BJ$286) -> 828555.44 | D32: =SUMIF('Scenario calc'!$C$259:$BJ$259,D$29,'Scenario calc'!$C$286:$BJ$286) -> 861697.65 | E32: =SUMIF('Scenario calc'!$C$259:$BJ$259,E$29,'Scenario calc'!$C$286:$BJ$286) -> 896165.56 | F32: =SUMIF('Scenario calc'!$C$259:$BJ$259,F$29,'Scenario calc'!$C$286:$BJ$286) -> 932012.18
A34: EBITDA by year ($'000)
A35: Scenario | B35: 1 | C35: 2 | D35: 3 | E35: 4 | F35: 5
A36: Low | B36: =SUMIF('Scenario calc'!$C$7:$BJ$7,B$35,'Scenario calc'!$C$54:$BJ$54) -> -228607.08 | C36: =SUMIF('Scenario calc'!$C$7:$BJ$7,C$35,'Scenario calc'!$C$54:$BJ$54) -> -109978.92 | D36: =SUMIF('Scenario calc'!$C$7:$BJ$7,D$35,'Scenario calc'!$C$54:$BJ$54) -> -85835.831 | E36: =SUMIF('Scenario calc'!$C$7:$BJ$7,E$35,'Scenario calc'!$C$54:$BJ$54) -> -89169.476 | F36: =SUMIF('Scenario calc'!$C$7:$BJ$7,F$35,'Scenario calc'!$C$54:$BJ$54) -> -92680.594
A37: Base | B37: =SUMIF('Scenario calc'!$C$133:$BJ$133,B$35,'Scenario calc'!$C$180:$BJ$180) -> -125850.99 | C37: =SUMIF('Scenario calc'!$C$133:$BJ$133,C$35,'Scenario calc'!$C$180:$BJ$180) -> 54057.278 | D37: =SUMIF('Scenario calc'!$C$133:$BJ$133,D$35,'Scenario calc'!$C$180:$BJ$180) -> 57501.808 | E37: =SUMIF('Scenario calc'!$C$133:$BJ$133,E$35,'Scenario calc'!$C$180:$BJ$180) -> 61566.862 | F37: =SUMIF('Scenario calc'!$C$133:$BJ$133,F$35,'Scenario calc'!$C$180:$BJ$180) -> 65753.868
A38: High | B38: =SUMIF('Scenario calc'!$C$259:$BJ$259,B$35,'Scenario calc'!$C$306:$BJ$306) -> 3918.8463 | C38: =SUMIF('Scenario calc'!$C$259:$BJ$259,C$35,'Scenario calc'!$C$306:$BJ$306) -> 142946.24 | D38: =SUMIF('Scenario calc'!$C$259:$BJ$259,D$35,'Scenario calc'!$C$306:$BJ$306) -> 157721.04 | E38: =SUMIF('Scenario calc'!$C$259:$BJ$259,E$35,'Scenario calc'!$C$306:$BJ$306) -> 173264.93 | F38: =SUMIF('Scenario calc'!$C$259:$BJ$259,F$35,'Scenario calc'!$C$306:$BJ$306) -> 189614.03
A40: Net income by year ($'000)
A41: Scenario | B41: 1 | C41: 2 | D41: 3 | E41: 4 | F41: 5
A42: Low | B42: =SUMIF('Scenario calc'!$C$7:$BJ$7,B$41,'Scenario calc'!$C$63:$BJ$63) -> -291966.8 | C42: =SUMIF('Scenario calc'!$C$7:$BJ$7,C$41,'Scenario calc'!$C$63:$BJ$63) -> -172245.58 | D42: =SUMIF('Scenario calc'!$C$7:$BJ$7,D$41,'Scenario calc'!$C$63:$BJ$63) -> -147002.5 | E42: =SUMIF('Scenario calc'!$C$7:$BJ$7,E$41,'Scenario calc'!$C$63:$BJ$63) -> -149236.14 | F42: =SUMIF('Scenario calc'!$C$7:$BJ$7,F$41,'Scenario calc'!$C$63:$BJ$63) -> -151647.26
A43: Base | B43: =SUMIF('Scenario calc'!$C$133:$BJ$133,B$41,'Scenario calc'!$C$189:$BJ$189) -> -189210.72 | C43: =SUMIF('Scenario calc'!$C$133:$BJ$133,C$41,'Scenario calc'!$C$189:$BJ$189) -> -8209.3882 | D43: =SUMIF('Scenario calc'!$C$133:$BJ$133,D$41,'Scenario calc'!$C$189:$BJ$189) -> -3664.8586 | E43: =SUMIF('Scenario calc'!$C$133:$BJ$133,E$41,'Scenario calc'!$C$189:$BJ$189) -> 1500.1957 | F43: =SUMIF('Scenario calc'!$C$133:$BJ$133,F$41,'Scenario calc'!$C$189:$BJ$189) -> 6787.2016
A44: High | B44: =SUMIF('Scenario calc'!$C$259:$BJ$259,B$41,'Scenario calc'!$C$315:$BJ$315) -> -59440.876 | C44: =SUMIF('Scenario calc'!$C$259:$BJ$259,C$41,'Scenario calc'!$C$315:$BJ$315) -> 76219.448 | D44: =SUMIF('Scenario calc'!$C$259:$BJ$259,D$41,'Scenario calc'!$C$315:$BJ$315) -> 76277.952 | E44: =SUMIF('Scenario calc'!$C$259:$BJ$259,E$41,'Scenario calc'!$C$315:$BJ$315) -> 89426.629 | F44: =SUMIF('Scenario calc'!$C$259:$BJ$259,F$41,'Scenario calc'!$C$315:$BJ$315) -> 103211.42
A46: Cash at year end by year ($'000)
A47: Scenario | B47: 1 | C47: 2 | D47: 3 | E47: 4 | F47: 5
...

Sheet Break-even
A1: Startup costs, funding need and break-even | H1: =HYPERLINK("#'Cover'!A1","◂ Contents") -> ◂ Contents
A2: Live for the selected scenario. Periods are counted in months from the start of the plan.
A3: Scenario shown | B3: =CHOOSE(Dashboard!$B$4,"Low","Base","High") -> Base
A5: Startup costs & funding need (up to the lowest cash point)
A6: Lowest cash point (month #) | B6: =MATCH(MIN(Monthly!$C$95:$BJ$95),Monthly!$C$95:$BJ$95,0) -> 13
A7: Capital spending up to the lowest cash point | B7: =SUMPRODUCT(--(Monthly!$C$4:$BJ$4<=$B$6),Monthly!$C$68:$BJ$68) -> 451000
A8: Operating cash burn up to the lowest cash point | B8: =-SUMPRODUCT(--(Monthly!$C$4:$BJ$4<=$B$6),Monthly!$C$89:$BJ$89) -> 159907.64 | D8: Losses and working capital before the business funds itself
A9: Loan repayments up to the lowest cash point | B9: =-SUMPRODUCT(--(Monthly!$C$4:$BJ$4<=$B$6),Monthly!$C$77:$BJ$77) -> 25000
A10: Total uses of funds | B10: =B7+B8+B9 -> 635907.64
A11: Minimum cash buffer to keep | B11: =Inputs!$E$88 -> 74000 | D11: Input on the Inputs sheet
A12: Funding required (uses + buffer) | B12: =B10+B11 -> 709907.64
A14: Equity raised | B14: =Inputs!$E$73 -> 450000
A15: Loan drawn | B15: =Inputs!$E$74 -> 250000
A16: Total sources of funds | B16: =B14+B15 -> 700000
A17: Funding surplus / (shortfall) | B17: =B16-B12 -> -9907.6437 | D17: Negative = raise at least this much more
A18: Lowest cash balance in the plan | B18: =MIN(Monthly!$C$95:$BJ$95) -> 64092.356 | D18: Equals sources minus uses
A20: Break-even timing
A21: First month with positive EBITDA (month #) | B21: =IFERROR(MATCH(1,Monthly!$C$96:$BJ$96,0),"Not within horizon") -> 12
A22: First month with positive net income (month #) | B22: =IFERROR(MATCH(1,Monthly!$C$99:$BJ$99,0),"Not within horizon") -> 37
A23: Cash invested paid back (month #) | B23: =IF(MIN(Monthly!$C$101:$BJ$101)>=0,"No investment to pay back",IFERROR(MATCH(1,Monthly!$C$103:$BJ$103,0),"Not within horizon")) -> Not within horizon | D23: Cumulative operating + investing cash flow back to zero
A25: Annual break-even revenue
A26: Year # | B26: 1 | C26: 2 | D26: 3 | E26: 4 | F26: 5
B27: Year 1 | C27: Year 2 | D27: Year 3 | E27: Year 4 | F27: Year 5
A28: Revenue | B28: =SUMIF(Monthly!$C$5:$BJ$5,B$26,Monthly!$C$32:$BJ$32) -> 419706.38 | C28: =SUMIF(Monthly!$C$5:$BJ$5,C$26,Monthly!$C$32:$BJ$32) -> 725888.9 | D28: =SUMIF(Monthly!$C$5:$BJ$5,D$26,Monthly!$C$32:$BJ$32) -> 747148.37 | E28: =SUMIF(Monthly!$C$5:$BJ$5,E$26,Monthly!$C$32:$BJ$32) -> 769562.82 | F28: =SUMIF(Monthly!$C$5:$BJ$5,F$26,Monthly!$C$32:$BJ$32) -> 792649.71
A29: Gross profit | B29: =SUMIF(Monthly!$C$5:$BJ$5,B$26,Monthly!$C$39:$BJ$39) -> 171077.38 | C29: =SUMIF(Monthly!$C$5:$BJ$5,C$26,Monthly!$C$39:$BJ$39) -> 363320.66 | D29: =SUMIF(Monthly!$C$5:$BJ$5,D$26,Monthly!$C$39:$BJ$39) -> 373703.09 | E29: =SUMIF(Monthly!$C$5:$BJ$5,E$26,Monthly!$C$39:$BJ$39) -> 384914.18 | F29: =SUMIF(Monthly!$C$5:$BJ$5,F$26,Monthly!$C$39:$BJ$39) -> 396461.6
A30: Gross margin (contribution) | B30: =IF(B28=0,0,B29/B28) -> 0.40761205 | C30: =IF(C28=0,0,C29/C28) -> 0.50051827 | D30: =IF(D28=0,0,D29/D28) -> 0.50017252 | E30: =IF(E28=0,0,E29/E28) -> 0.50017252 | F30: =IF(F28=0,0,F29/F28) -> 0.50017252
A31: Operating expenses (treated as fixed) | B31: =-SUMIF(Monthly!$C$5:$BJ$5,B$26,Monthly!$C$51:$BJ$51) -> 296928.37 | C31: =-SUMIF(Monthly!$C$5:$BJ$5,C$26,Monthly!$C$51:$BJ$51) -> 309263.38 | D31: =-SUMIF(Monthly!$C$5:$BJ$5,D$26,Monthly!$C$51:$BJ$51) -> 316201.28 | E31: =-SUMIF(Monthly!$C$5:$BJ$5,E$26,Monthly!$C$51:$BJ$51) -> 323347.32 | F31: =-SUMIF(Monthly!$C$5:$BJ$5,F$26,Monthly!$C$51:$BJ$51) -> 330707.74
A32: Break-even revenue (EBITDA = 0) | B32: =IF(B30>0,B31/B30,"n/a") -> 728458.27 | C32: =IF(C30>0,C31/C30,"n/a") -> 617886.29 | D32: =IF(D30>0,D31/D30,"n/a") -> 632184.42 | E32: =IF(E30>0,E31/E30,"n/a") -> 646471.57 | F32: =IF(F30>0,F31/F30,"n/a") -> 661187.33
A33: Margin of safety (revenue above break-even) | B33: =IF(AND(ISNUMBER(B32),B28>0),(B28-B32)/B28,"n/a") -> -0.73563786 | C33: =IF(AND(ISNUMBER(C32),C28>0),(C28-C32)/C28,"n/a") -> 0.14878669 | D33: =IF(AND(ISNUMBER(D32),D28>0),(D28-D32)/D28,"n/a") -> 0.15387031 | E33: =IF(AND(ISNUMBER(E32),E28>0),(E28-E32)/E28,"n/a") -> 0.15994958 | F33: =IF(AND(ISNUMBER(F32),F28>0),(F28-F32)/F28,"n/a") -> 0.16585179
A35: Simplification: cost of sales is treated as variable and operating expenses as fixed, so break-even revenue = operating expenses ÷ gross margin.

Sheet Valuation
A1: Discounted cash flow valuation | H1: =HYPERLINK("#'Cover'!A1","◂ Contents") -> ◂ Contents
A2: Enterprise value at the start of the plan, before the funding raised in period 1. Year-end discounting.
A3: Scenario shown | B3: =CHOOSE(Dashboard!$B$4,"Low","Base","High") -> Base
A5: Assumptions (active scenario, from the Inputs sheet)
A6: Discount rate (WACC) | B6: =Inputs!$E$91 -> 0.25
A7: Terminal growth rate | B7: =Inputs!$E$92 -> 0.02
A8: Exit multiple (EV ÷ final-year EBITDA) | B8: =Inputs!$E$93 -> 4
A9: Tax rate (for the interest tax shield) | B9: =Inputs!$E$85 -> 0.21
A10: Sensitivity step: WACC | B10: =Inputs!$E$94 -> 0.01
A11: Sensitivity step: terminal growth | B11: =Inputs!$E$95 -> 0.005
A13: Free cash flow by year
A14: Year # | B14: 1 | C14: 2 | D14: 3 | E14: 4 | F14: 5
B15: Year 1 | C15: Year 2 | D15: Year 3 | E15: Year 4 | F15: Year 5
A16: EBITDA | B16: =SUMIF(Monthly!$C$5:$BJ$5,B$14,Monthly!$C$52:$BJ$52) -> -125850.99 | C16: =SUMIF(Monthly!$C$5:$BJ$5,C$14,Monthly!$C$52:$BJ$52) -> 54057.278 | D16: =SUMIF(Monthly!$C$5:$BJ$5,D$14,Monthly!$C$52:$BJ$52) -> 57501.808 | E16: =SUMIF(Monthly!$C$5:$BJ$5,E$14,Monthly!$C$52:$BJ$52) -> 61566.862 | F16: =SUMIF(Monthly!$C$5:$BJ$5,F$14,Monthly!$C$52:$BJ$52) -> 65753.868
A17: Unlevered free cash flow | B17: =SUMIF(Monthly!$C$5:$BJ$5,B$14,Monthly!$C$104:$BJ$104) -> -588173.12 | C17: =SUMIF(Monthly!$C$5:$BJ$5,C$14,Monthly!$C$104:$BJ$104) -> 39613.414 | D17: =SUMIF(Monthly!$C$5:$BJ$5,D$14,Monthly!$C$104:$BJ$104) -> 44772.685 | E17: =SUMIF(Monthly!$C$5:$BJ$5,E$14,Monthly!$C$104:$BJ$104) -> 49241.415 | F17: =SUMIF(Monthly!$C$5:$BJ$5,F$14,Monthly!$C$104:$BJ$104) -> 53831.608
A18: Discount factor | B18: =1/(1+Inputs!$E$91)^B$14 -> 0.8 | C18: =1/(1+Inputs!$E$91)^C$14 -> 0.64 | D18: =1/(1+Inputs!$E$91)^D$14 -> 0.512 | E18: =1/(1+Inputs!$E$91)^E$14 -> 0.4096 | F18: =1/(1+Inputs!$E$91)^F$14 -> 0.32768
A19: Present value of free cash flow | B19: =B17*B18 -> -470538.5 | C19: =C17*C18 -> 25352.585 | D19: =D17*D18 -> 22923.615 | E19: =E17*E18 -> 20169.284 | F19: =F17*F18 -> 17639.541
A21: Enterprise value
B22: Perpetual growth | C22: Exit multiple
A23: Present value of the plan's free cash flows | B23: =SUM($B$19:$F$19) -> -384453.47 | C23: =B23 -> -384453.47
A24: Final-year free cash flow | final-year EBITDA | B24: =$F$17 -> 53831.608 | C24: =$F$16 -> 65753.868
A25: Terminal value at the end of year 5 | B25: =IF($B$6>$B$7,B24*(1+$B$7)/($B$6-$B$7),0) -> 238731.48 | C25: =C24*$B$8 -> 263015.47
A26: Present value of the terminal value | B26: =B25/(1+$B$6)^$F$14 -> 78227.53 | C26: =C25/(1+$B$6)^$F$14 -> 86184.91
A27: Enterprise value | B27: =B23+B26 -> -306225.94 | C27: =C23+C26 -> -298268.56
A28: Terminal value share of enterprise value | B28: =IF(B27<>0,B26/B27,0) -> -0.2554569 | C28: =IF(C27<>0,C26/C27,0) -> -0.2889507
A29: Cross-check: implied exit multiple | implied perpetual growth | B29: =IF(C24>0,B25/C24,"n/a") -> 3.6306834 | C29: =IF(C25+B24<>0,(C25*$B$6-B24)/(C25+B24),"n/a") -> 0.037627806
A30: Enterprise value — average of the two methods | B30: =AVERAGE(B27,C27) -> -302247.25
A32: Sensitivity: enterprise value (perpetual growth) by WACC and terminal growth
A33: WACC ↓ · terminal growth → | B33: =$B$7+(-2)*$B$11 -> 0.01 | C33: =$B$7+(-1)*$B$11 -> 0.015 | D33: =$B$7+(0)*$B$11 -> 0.02 | E33: =$B$7+(1)*$B$11 -> 0.025 | F33: =$B$7+(2)*$B$11 -> 0.03
A34: =$B$6+(-2)*$B$10 -> 0.23 | B34: =IF($A34>B$33,SUMPRODUCT($B$17:$F$17/(1+$A34)^$B$14:$F$14)+$F$17*(1+B$33)/($A34-B$33)/(1+$A34)^$F$14,"n/a") -> -299528.13 | C34: =IF($A34>C$33,SUMPRODUCT($B$17:$F$17/(1+$A34)^$B$14:$F$14)+$F$17*(1+C$33)/($A34-C$33)/(1+$A34)^$F$14,"n/a") -> -297041.99 | D34: =IF($A34>D$33,SUMPRODUCT($B$17:$F$17/(1+$A34)^$B$14:$F$14)+$F$17*(1+D$33)/($A34-D$33)/(1+$A34)^$F$14,"n/a") -> -294437.46 | E34: =IF($A34>E$33,SUMPRODUCT($B$17:$F$17/(1+$A34)^$B$14:$F$14)+$F$17*(1+E$33)/($A34-E$33)/(1+$A34)^$F$14,"n/a") -> -291705.88 | F34: =IF($A34>F$33,SUMPRODUCT($B$17:$F$17/(1+$A34)^$B$14:$F$14)+$F$17*(1+F$33)/($A34-F$33)/(1+$A34)^$F$14,"n/a") -> -288837.72
A35: =$B$6+(-1)*$B$10 -> 0.24 | B35: =IF($A35>B$33,SUMPRODUCT($B$17:$F$17/(1+$A35)^$B$14:$F$14)+$F$17*(1+B$33)/($A35-B$33)/(1+$A35)^$F$14,"n/a") -> -305262.33 | C35: =IF($A35>C$33,SUMPRODUCT($B$17:$F$17/(1+$A35)^$B$14:$F$14)+$F$17*(1+C$33)/($A35-C$33)/(1+$A35)^$F$14,"n/a") -> -303062.39 | D35: =IF($A35>D$33,SUMPRODUCT($B$17:$F$17/(1+$A35)^$B$14:$F$14)+$F$17*(1+D$33)/($A35-D$33)/(1+$A35)^$F$14,"n/a") -> -300762.45 | E35: =IF($A35>E$33,SUMPRODUCT($B$17:$F$17/(1+$A35)^$B$14:$F$14)+$F$17*(1+E$33)/($A35-E$33)/(1+$A35)^$F$14,"n/a") -> -298355.55 | F35: =IF($A35>F$33,SUMPRODUCT($B$17:$F$17/(1+$A35)^$B$14:$F$14)+$F$17*(1+F$33)/($A35-F$33)/(1+$A35)^$F$14,"n/a") -> -295834.02
A36: =$B$6+(0)*$B$10 -> 0.25 | B36: =IF($A36>B$33,SUMPRODUCT($B$17:$F$17/(1+$A36)^$B$14:$F$14)+$F$17*(1+B$33)/($A36-B$33)/(1+$A36)^$F$14,"n/a") -> -310220.4 | C36: =IF($A36>C$33,SUMPRODUCT($B$17:$F$17/(1+$A36)^$B$14:$F$14)+$F$17*(1+C$33)/($A36-C$33)/(1+$A36)^$F$14,"n/a") -> -308265.67 | D36: =IF($A36>D$33,SUMPRODUCT($B$17:$F$17/(1+$A36)^$B$14:$F$14)+$F$17*(1+D$33)/($A36-D$33)/(1+$A36)^$F$14,"n/a") -> -306225.94 | E36: =IF($A36>E$33,SUMPRODUCT($B$17:$F$17/(1+$A36)^$B$14:$F$14)+$F$17*(1+E$33)/($A36-E$33)/(1+$A36)^$F$14,"n/a") -> -304095.56 | F36: =IF($A36>F$33,SUMPRODUCT($B$17:$F$17/(1+$A36)^$B$14:$F$14)+$F$17*(1+F$33)/($A36-F$33)/(1+$A36)^$F$14,"n/a") -> -301868.35
