Workbook

Sheet Cover
B2: Dental practice financial model (growing)
B3: 3-year financial model · monthly detail · Low / Base / High scenarios · US dollars · Full plan
B5: Purpose | D5: Revenue and profit plan
B6: Active scenario | D6: =Dashboard!C4&" (change it on the Dashboard, cell B4)" -> Base (change it on the Dashboard, cell B4)
B7: Model checks | D7: =Checks!B25 -> PASS
B8: Prepared | D8: 22 October 2026
B10: Contents
C11: PRESENTATION
B12: 1 | C12: =HYPERLINK("#Dashboard!A1","Dashboard") -> Dashboard | D12: Scenario switch, key numbers, core financials
B13: 2 | C13: =HYPERLINK("#Summary!A1","Summary") -> Summary | D13: Income statement, cash flow and balance sheet — every year and any year by month
B14: 3 | C14: =HYPERLINK("#Scenarios!A1","Scenarios") -> Scenarios | D14: Low / Base / High side by side: drivers, outputs, charts
B15: 4 | C15: =HYPERLINK("#'Break-even'!A1","Break-even") -> Break-even | D15: Startup costs, funding need, break-even timing and revenue
B16: 5 | C16: =HYPERLINK("#Valuation!A1","Valuation") -> Valuation | D16: Free cash flow, DCF (perpetual growth and exit multiple), WACC × growth sensitivity
B17: 6 | C17: =HYPERLINK("#'Sources & Uses'!A1","Sources & Uses") -> Sources & Uses | D17: Funding structure, sources and uses of cash for the first months
B18: 7 | C18: =HYPERLINK("#KPIs!A1","KPIs") -> KPIs | D18: Financial ratios, DuPont analysis, industry metrics
C19: INPUTS
B20: 8 | C20: =HYPERLINK("#Inputs!A1","Inputs") -> Inputs | D20: Every assumption, Low / Base / High, with units and comments
C21: STATEMENTS
B22: 9 | C22: =HYPERLINK("#'P&L'!A1","P&L") -> P&L | D22: Annual profit & loss
B23: 10 | C23: =HYPERLINK("#'Cash Flow'!A1","Cash Flow") -> Cash Flow | D23: Annual cash flow statement
B24: 11 | C24: =HYPERLINK("#'Balance Sheet'!A1","Balance Sheet") -> Balance Sheet | D24: Balance sheet at year end
C25: CALCULATIONS
B26: 12 | C26: =HYPERLINK("#Monthly!A1","Monthly") -> Monthly | D26: Month-by-month engine of the model
B27: 13 | C27: =HYPERLINK("#Headcount!A1","Headcount") -> Headcount | D27: Team and payroll
B28: 14 | C28: =HYPERLINK("#'Scenario calc'!A1","Scenario calc") -> Scenario calc | D28: Low, Base and High calculated side by side for the Scenarios sheet
C29: CONTROL
B30: 15 | C30: =HYPERLINK("#Checks!A1","Checks") -> Checks | D30: Live integrity checks and the overall verdict
B32: How to read this file
C33: 1000 | D33: Input you can change — yellow cell with a blue figure (Inputs sheet and the view switches)
C34: 1000 | D34: Formula — calculated, do not overwrite
C35: 1000 | D35: Link to another sheet
C36: 1000 | D36: Active value the model uses (follows the scenario)

Sheet Dashboard
A1: Dashboard | W1: =HYPERLINK("#'Cover'!A1","◂ Contents") -> ◂ Contents
A2: Dental practice financial model (growing)
A4: Active scenario | B4: 2 | C4: =CHOOSE(B4,"Low","Base","High") -> Base | D4: 1 = Low · 2 = Base · 3 = High — every sheet follows this cell | S4: Model checks | T4: =Checks!B25 -> PASS
A6: REVENUE · YEAR 3 | C6: EBITDA MARGIN · YEAR 3 | H6: NET INCOME · YEAR 3 | L6: LOWEST CASH BALANCE | P6: FUNDING REQUIRED | T6: ENTERPRISE VALUE (DCF)
A7: =D12 -> 2337329.1 | C7: =D17 -> 0.19248584 | H7: =D18 -> 332947.38 | L7: =F38 -> 123032.22 | P7: =F36 -> 475967.78 | T7: =F43 -> 1983726.8
A8: =IF(AND(B12>0,D12>=0),(D12/B12)^(1/2)-1,"CAGR n/a") -> 0.087785827 | C8: =D16 -> 449902.76 | H8: =D19 -> 0.1424478 | L8: ='Break-even'!B6 -> 1 | P8: =IF(F37>=0,"Covered by funding raised",-F37) -> 225967.78 | T8: Average of 2 methods
A10: Core financials ($'000) — active scenario
B11: 1 | C11: 2 | D11: 3
A12: Revenue | B12: =SUMIF(Monthly!$C$5:$AL$5,B$11,Monthly!$C$31:$AL$31) -> 1975300.1 | C12: =SUMIF(Monthly!$C$5:$AL$5,C$11,Monthly!$C$31:$AL$31) -> 2149133.3 | D12: =SUMIF(Monthly!$C$5:$AL$5,D$11,Monthly!$C$31:$AL$31) -> 2337329.1
A13: Gross profit | B13: =SUMIF(Monthly!$C$5:$AL$5,B$11,Monthly!$C$38:$AL$38) -> 1700585.9 | C13: =SUMIF(Monthly!$C$5:$AL$5,C$11,Monthly!$C$38:$AL$38) -> 1850264.9 | D13: =SUMIF(Monthly!$C$5:$AL$5,D$11,Monthly!$C$38:$AL$38) -> 2012307.8
A14: Gross margin | B14: =IF(B12=0,0,B13/B12) -> 0.86092536 | C14: =IF(C12=0,0,C13/C12) -> 0.86093538 | D14: =IF(D12=0,0,D13/D12) -> 0.86094328
A15: Operating expenses | B15: =SUMIF(Monthly!$C$5:$AL$5,B$11,Monthly!$C$50:$AL$50) -> -1397453.4 | C15: =SUMIF(Monthly!$C$5:$AL$5,C$11,Monthly!$C$50:$AL$50) -> -1476940 | D15: =SUMIF(Monthly!$C$5:$AL$5,D$11,Monthly!$C$50:$AL$50) -> -1562405.1
A16: EBITDA | B16: =SUMIF(Monthly!$C$5:$AL$5,B$11,Monthly!$C$51:$AL$51) -> 303132.53 | C16: =SUMIF(Monthly!$C$5:$AL$5,C$11,Monthly!$C$51:$AL$51) -> 373324.91 | D16: =SUMIF(Monthly!$C$5:$AL$5,D$11,Monthly!$C$51:$AL$51) -> 449902.76
A17: EBITDA margin | B17: =IF(B12=0,0,B16/B12) -> 0.15346151 | C17: =IF(C12=0,0,C16/C12) -> 0.17370952 | D17: =IF(D12=0,0,D16/D12) -> 0.19248584
A18: Net income | B18: =SUMIF(Monthly!$C$5:$AL$5,B$11,Monthly!$C$60:$AL$60) -> 221437.82 | C18: =SUMIF(Monthly!$C$5:$AL$5,C$11,Monthly!$C$60:$AL$60) -> 274821.52 | D18: =SUMIF(Monthly!$C$5:$AL$5,D$11,Monthly!$C$60:$AL$60) -> 332947.38
A19: Net margin | B19: =IF(B12=0,0,B18/B12) -> 0.11210338 | C19: =IF(C12=0,0,C18/C12) -> 0.12787551 | D19: =IF(D12=0,0,D18/D12) -> 0.1424478
A20: Operating cash flow | B20: =SUMIF(Monthly!$C$5:$AL$5,B$11,Monthly!$C$84:$AL$84) -> 147060.42 | C20: =SUMIF(Monthly!$C$5:$AL$5,C$11,Monthly!$C$84:$AL$84) -> 282618.64 | D20: =SUMIF(Monthly!$C$5:$AL$5,D$11,Monthly!$C$84:$AL$84) -> 344946.13
A21: Investing cash flow | B21: =SUMIF(Monthly!$C$5:$AL$5,B$11,Monthly!$C$85:$AL$85) -> -89629.501 | C21: =SUMIF(Monthly!$C$5:$AL$5,C$11,Monthly!$C$85:$AL$85) -> -32237 | D21: =SUMIF(Monthly!$C$5:$AL$5,D$11,Monthly!$C$85:$AL$85) -> -35059.937
A22: Financing cash flow | B22: =SUMIF(Monthly!$C$5:$AL$5,B$11,Monthly!$C$87:$AL$87) -> 230357.14 | C22: =SUMIF(Monthly!$C$5:$AL$5,C$11,Monthly!$C$87:$AL$87) -> -21428.571 | D22: =SUMIF(Monthly!$C$5:$AL$5,D$11,Monthly!$C$87:$AL$87) -> -21428.571
A23: Net change in cash | B23: =SUMIF(Monthly!$C$5:$AL$5,B$11,Monthly!$C$88:$AL$88) -> 287788.06 | C23: =SUMIF(Monthly!$C$5:$AL$5,C$11,Monthly!$C$88:$AL$88) -> 228953.06 | D23: =SUMIF(Monthly!$C$5:$AL$5,D$11,Monthly!$C$88:$AL$88) -> 288457.62
A24: Year-end cash | B24: =INDEX(Monthly!$C$90:$AL$90,B$11*12) -> 287788.06 | C24: =INDEX(Monthly!$C$90:$AL$90,C$11*12) -> 516741.13 | D24: =INDEX(Monthly!$C$90:$AL$90,D$11*12) -> 805198.75
A26: Dental practice metrics
B27: 1 | C27: 2 | D27: 3
A28: Active patients (year end) | B28: =KPIs!B29 -> 3170.4728 | C28: =KPIs!C29 -> 3348.9509 | D28: =KPIs!D29 -> 3536.0755
A29: Doctor chair utilisation | B29: =KPIs!B37 -> 0.81766307 | C29: =KPIs!C37 -> 0.86358429 | D29: =KPIs!D37 -> 0.91174739
A30: Production per visit | B30: =KPIs!B44 -> 262.12257 | C30: =KPIs!C44 -> 269.97414 | D30: =KPIs!D44 -> 278.06352
A31: Team (FTE, year end) | B31: =INDEX(Headcount!$C$13:$AL$13,B$27*12) -> 12.5 | C31: =INDEX(Headcount!$C$13:$AL$13,C$27*12) -> 12.98 | D31: =INDEX(Headcount!$C$13:$AL$13,D$27*12) -> 13.4828
A33: Funding & valuation ($'000) — active scenario
A34: Equity raised | F34: =Inputs!$E$83 -> 100000
A35: Loan drawn | F35: =Inputs!$E$84 -> 150000
A36: Funding required (incl. cash buffer) | F36: ='Break-even'!B12 -> 475967.78
A37: Funding surplus / (shortfall) | F37: ='Break-even'!B17 -> -225967.78
A38: ="Lowest cash balance (month "&'Break-even'!B6&")" -> Lowest cash balance (month 1) | F38: ='Break-even'!B18 -> 123032.22
A39: First month with positive EBITDA | F39: ='Break-even'!B21 -> 1
A40: Cash invested paid back | F40: ='Break-even'!B23 -> 9
A41: Enterprise value — perpetual growth | F41: =Valuation!B27 -> 1929696
A42: Enterprise value — exit multiple | F42: =Valuation!C27 -> 2037757.6
A43: Enterprise value — average | F43: =Valuation!B30 -> 1983726.8

Sheet Summary
A1: Financial statements summary | U1: =HYPERLINK("#'Cover'!A1","◂ Contents") -> ◂ Contents
A2: Dental practice financial model (growing) | P2: Select detailed year: | R2: 1
A5: Income statement ($'000) — by year | H5: ="Income statement ($'000) — Year "&$R$2&", by month" -> Income statement ($'000) — Year 1, by month
B6: 1 | C6: 2 | D6: 3 | H6: =INDEX(Monthly!$C$4:$AL$4,($R$2-1)*12+1) -> 1 | I6: =INDEX(Monthly!$C$4:$AL$4,($R$2-1)*12+2) -> 2 | J6: =INDEX(Monthly!$C$4:$AL$4,($R$2-1)*12+3) -> 3 | K6: =INDEX(Monthly!$C$4:$AL$4,($R$2-1)*12+4) -> 4 | L6: =INDEX(Monthly!$C$4:$AL$4,($R$2-1)*12+5) -> 5 | M6: =INDEX(Monthly!$C$4:$AL$4,($R$2-1)*12+6) -> 6 | N6: =INDEX(Monthly!$C$4:$AL$4,($R$2-1)*12+7) -> 7 | O6: =INDEX(Monthly!$C$4:$AL$4,($R$2-1)*12+8) -> 8 | P6: =INDEX(Monthly!$C$4:$AL$4,($R$2-1)*12+9) -> 9 | Q6: =INDEX(Monthly!$C$4:$AL$4,($R$2-1)*12+10) -> 10 | R6: =INDEX(Monthly!$C$4:$AL$4,($R$2-1)*12+11) -> 11 | S6: =INDEX(Monthly!$C$4:$AL$4,($R$2-1)*12+12) -> 12
A7: Revenue | B7: ='P&L'!B5 -> 1975300.1 | C7: ='P&L'!C5 -> 2149133.3 | D7: ='P&L'!D5 -> 2337329.1 | H7: =INDEX(Monthly!$C$31:$AL$31,($R$2-1)*12+1) -> 160761.97 | I7: =INDEX(Monthly!$C$31:$AL$31,($R$2-1)*12+2) -> 161494.44 | J7: =INDEX(Monthly!$C$31:$AL$31,($R$2-1)*12+3) -> 162216.65 | K7: =INDEX(Monthly!$C$31:$AL$31,($R$2-1)*12+4) -> 162928.76 | L7: =INDEX(Monthly!$C$31:$AL$31,($R$2-1)*12+5) -> 163630.89 | M7: =INDEX(Monthly!$C$31:$AL$31,($R$2-1)*12+6) -> 164323.19 | N7: =INDEX(Monthly!$C$31:$AL$31,($R$2-1)*12+7) -> 165005.81 | O7: =INDEX(Monthly!$C$31:$AL$31,($R$2-1)*12+8) -> 165678.86 | P7: =INDEX(Monthly!$C$31:$AL$31,($R$2-1)*12+9) -> 166342.49 | Q7: =INDEX(Monthly!$C$31:$AL$31,($R$2-1)*12+10) -> 166996.84 | R7: =INDEX(Monthly!$C$31:$AL$31,($R$2-1)*12+11) -> 167642.02 | S7: =INDEX(Monthly!$C$31:$AL$31,($R$2-1)*12+12) -> 168278.17
A8: Cost of sales | B8: ='P&L'!B6 -> -274714.15 | C8: ='P&L'!C6 -> -298868.42 | D8: ='P&L'!D6 -> -325021.31 | H8: =INDEX(Monthly!$C$37:$AL$37,($R$2-1)*12+1) -> -22377.042 | I8: =INDEX(Monthly!$C$37:$AL$37,($R$2-1)*12+2) -> -22475.267 | J8: =INDEX(Monthly!$C$37:$AL$37,($R$2-1)*12+3) -> -22572.117 | K8: =INDEX(Monthly!$C$37:$AL$37,($R$2-1)*12+4) -> -22667.611 | L8: =INDEX(Monthly!$C$37:$AL$37,($R$2-1)*12+5) -> -22761.768 | M8: =INDEX(Monthly!$C$37:$AL$37,($R$2-1)*12+6) -> -22854.608 | N8: =INDEX(Monthly!$C$37:$AL$37,($R$2-1)*12+7) -> -22946.147 | O8: =INDEX(Monthly!$C$37:$AL$37,($R$2-1)*12+8) -> -23036.405 | P8: =INDEX(Monthly!$C$37:$AL$37,($R$2-1)*12+9) -> -23125.399 | Q8: =INDEX(Monthly!$C$37:$AL$37,($R$2-1)*12+10) -> -23213.147 | R8: =INDEX(Monthly!$C$37:$AL$37,($R$2-1)*12+11) -> -23299.667 | S8: =INDEX(Monthly!$C$37:$AL$37,($R$2-1)*12+12) -> -23384.975
A9: Gross profit | B9: ='P&L'!B7 -> 1700585.9 | C9: ='P&L'!C7 -> 1850264.9 | D9: ='P&L'!D7 -> 2012307.8 | H9: =INDEX(Monthly!$C$38:$AL$38,($R$2-1)*12+1) -> 138384.93 | I9: =INDEX(Monthly!$C$38:$AL$38,($R$2-1)*12+2) -> 139019.17 | J9: =INDEX(Monthly!$C$38:$AL$38,($R$2-1)*12+3) -> 139644.54 | K9: =INDEX(Monthly!$C$38:$AL$38,($R$2-1)*12+4) -> 140261.14 | L9: =INDEX(Monthly!$C$38:$AL$38,($R$2-1)*12+5) -> 140869.12 | M9: =INDEX(Monthly!$C$38:$AL$38,($R$2-1)*12+6) -> 141468.59 | N9: =INDEX(Monthly!$C$38:$AL$38,($R$2-1)*12+7) -> 142059.66 | O9: =INDEX(Monthly!$C$38:$AL$38,($R$2-1)*12+8) -> 142642.46 | P9: =INDEX(Monthly!$C$38:$AL$38,($R$2-1)*12+9) -> 143217.1 | Q9: =INDEX(Monthly!$C$38:$AL$38,($R$2-1)*12+10) -> 143783.69 | R9: =INDEX(Monthly!$C$38:$AL$38,($R$2-1)*12+11) -> 144342.35 | S9: =INDEX(Monthly!$C$38:$AL$38,($R$2-1)*12+12) -> 144893.19
A10: Gross margin | B10: ='P&L'!B8 -> 0.86092536 | C10: ='P&L'!C8 -> 0.86093538 | D10: ='P&L'!D8 -> 0.86094328 | H10: =IF(H7=0,0,H9/H7) -> 0.86080637 | I10: =IF(I7=0,0,I9/I7) -> 0.86082947 | J10: =IF(J7=0,0,J9/J7) -> 0.86085204 | K10: =IF(K7=0,0,K9/K7) -> 0.86087409 | L10: =IF(L7=0,0,L9/L7) -> 0.86089565 | M10: =IF(M7=0,0,M9/M7) -> 0.86091673 | N10: =IF(N7=0,0,N9/N7) -> 0.86093734 | O10: =IF(O7=0,0,O9/O7) -> 0.86095749 | ... S10: =IF(S7=0,0,S9/S7) -> 0.86103381
A11: Total operating expenses | B11: ='P&L'!B18 -> -1397453.4 | C11: ='P&L'!C18 -> -1476940 | D11: ='P&L'!D18 -> -1562405.1 | H11: =INDEX(Monthly!$C$50:$AL$50,($R$2-1)*12+1) -> -116196.67 | I11: =INDEX(Monthly!$C$50:$AL$50,($R$2-1)*12+2) -> -116245.76 | J11: =INDEX(Monthly!$C$50:$AL$50,($R$2-1)*12+3) -> -116294.16 | K11: =INDEX(Monthly!$C$50:$AL$50,($R$2-1)*12+4) -> -116341.88 | L11: =INDEX(Monthly!$C$50:$AL$50,($R$2-1)*12+5) -> -116388.94 | M11: =INDEX(Monthly!$C$50:$AL$50,($R$2-1)*12+6) -> -116435.34 | N11: =INDEX(Monthly!$C$50:$AL$50,($R$2-1)*12+7) -> -116481.09 | O11: =INDEX(Monthly!$C$50:$AL$50,($R$2-1)*12+8) -> -116526.2 | P11: =INDEX(Monthly!$C$50:$AL$50,($R$2-1)*12+9) -> -116570.67 | Q11: =INDEX(Monthly!$C$50:$AL$50,($R$2-1)*12+10) -> -116614.53 | R11: =INDEX(Monthly!$C$50:$AL$50,($R$2-1)*12+11) -> -116657.77 | S11: =INDEX(Monthly!$C$50:$AL$50,($R$2-1)*12+12) -> -116700.4
A12: EBITDA | B12: ='P&L'!B19 -> 303132.53 | C12: ='P&L'!C19 -> 373324.91 | D12: ='P&L'!D19 -> 449902.76 | H12: =INDEX(Monthly!$C$51:$AL$51,($R$2-1)*12+1) -> 22188.26 | I12: =INDEX(Monthly!$C$51:$AL$51,($R$2-1)*12+2) -> 22773.414 | J12: =INDEX(Monthly!$C$51:$AL$51,($R$2-1)*12+3) -> 23350.376 | K12: =INDEX(Monthly!$C$51:$AL$51,($R$2-1)*12+4) -> 23919.26 | L12: =INDEX(Monthly!$C$51:$AL$51,($R$2-1)*12+5) -> 24480.18 | M12: =INDEX(Monthly!$C$51:$AL$51,($R$2-1)*12+6) -> 25033.247 | N12: =INDEX(Monthly!$C$51:$AL$51,($R$2-1)*12+7) -> 25578.571 | O12: =INDEX(Monthly!$C$51:$AL$51,($R$2-1)*12+8) -> 26116.261 | P12: =INDEX(Monthly!$C$51:$AL$51,($R$2-1)*12+9) -> 26646.423 | Q12: =INDEX(Monthly!$C$51:$AL$51,($R$2-1)*12+10) -> 27169.162 | R12: =INDEX(Monthly!$C$51:$AL$51,($R$2-1)*12+11) -> 27684.584 | S12: =INDEX(Monthly!$C$51:$AL$51,($R$2-1)*12+12) -> 28192.789
A13: EBITDA margin | B13: ='P&L'!B20 -> 0.15346151 | C13: ='P&L'!C20 -> 0.17370952 | D13: ='P&L'!D20 -> 0.19248584 | H13: =IF(H7=0,0,H12/H7) -> 0.13801933 | I13: =IF(I7=0,0,I12/I7) -> 0.14101671 | J13: =IF(J7=0,0,J12/J7) -> 0.14394561 | K13: =IF(K7=0,0,K12/K7) -> 0.14680809 | L13: =IF(L7=0,0,L12/L7) -> 0.1496061 | M13: =IF(M7=0,0,M12/M7) -> 0.15234153 | N13: =IF(N7=0,0,N12/N7) -> 0.15501619 | O13: =IF(O7=0,0,O12/O7) -> 0.15763182 | ... S13: =IF(S7=0,0,S12/S7) -> 0.16753682
A14: Depreciation | B14: ='P&L'!B21 -> -10846.744 | C14: ='P&L'!C21 -> -15279.934 | D14: ='P&L'!D21 -> -20102.158 | H14: =INDEX(Monthly!$C$65:$AL$65,($R$2-1)*12+1) -> -742.99321 | I14: =INDEX(Monthly!$C$65:$AL$65,($R$2-1)*12+2) -> -771.8315 | J14: =INDEX(Monthly!$C$65:$AL$65,($R$2-1)*12+3) -> -800.79876 | K14: =INDEX(Monthly!$C$65:$AL$65,($R$2-1)*12+4) -> -829.89318 | L14: =INDEX(Monthly!$C$65:$AL$65,($R$2-1)*12+5) -> -859.11298 | M14: =INDEX(Monthly!$C$65:$AL$65,($R$2-1)*12+6) -> -888.45641 | N14: =INDEX(Monthly!$C$65:$AL$65,($R$2-1)*12+7) -> -917.92173 | O14: =INDEX(Monthly!$C$65:$AL$65,($R$2-1)*12+8) -> -947.50724 | P14: =INDEX(Monthly!$C$65:$AL$65,($R$2-1)*12+9) -> -977.21126 | Q14: =INDEX(Monthly!$C$65:$AL$65,($R$2-1)*12+10) -> -1007.0321 | R14: =INDEX(Monthly!$C$65:$AL$65,($R$2-1)*12+11) -> -1036.9682 | S14: =INDEX(Monthly!$C$65:$AL$65,($R$2-1)*12+12) -> -1067.0179
A15: EBIT | B15: ='P&L'!B22 -> 292285.78 | C15: ='P&L'!C22 -> 358044.98 | D15: ='P&L'!D22 -> 429800.6 | H15: =INDEX(Monthly!$C$54:$AL$54,($R$2-1)*12+1) -> 21445.267 | I15: =INDEX(Monthly!$C$54:$AL$54,($R$2-1)*12+2) -> 22001.582 | J15: =INDEX(Monthly!$C$54:$AL$54,($R$2-1)*12+3) -> 22549.577 | K15: =INDEX(Monthly!$C$54:$AL$54,($R$2-1)*12+4) -> 23089.367 | L15: =INDEX(Monthly!$C$54:$AL$54,($R$2-1)*12+5) -> 23621.067 | M15: =INDEX(Monthly!$C$54:$AL$54,($R$2-1)*12+6) -> 24144.791 | N15: =INDEX(Monthly!$C$54:$AL$54,($R$2-1)*12+7) -> 24660.649 | O15: =INDEX(Monthly!$C$54:$AL$54,($R$2-1)*12+8) -> 25168.753 | P15: =INDEX(Monthly!$C$54:$AL$54,($R$2-1)*12+9) -> 25669.211 | Q15: =INDEX(Monthly!$C$54:$AL$54,($R$2-1)*12+10) -> 26162.13 | R15: =INDEX(Monthly!$C$54:$AL$54,($R$2-1)*12+11) -> 26647.615 | S15: =INDEX(Monthly!$C$54:$AL$54,($R$2-1)*12+12) -> 27125.771
A16: Interest | B16: ='P&L'!B23 -> -11984.747 | C16: ='P&L'!C23 -> -10169.643 | D16: ='P&L'!D23 -> -8348.2143 | H16: =INDEX(Monthly!$C$55:$AL$55,($R$2-1)*12+1) -> -1062.5 | I16: =INDEX(Monthly!$C$55:$AL$55,($R$2-1)*12+2) -> -1056.1756 | J16: =INDEX(Monthly!$C$55:$AL$55,($R$2-1)*12+3) -> -1043.5268 | K16: =INDEX(Monthly!$C$55:$AL$55,($R$2-1)*12+4) -> -1030.878 | L16: =INDEX(Monthly!$C$55:$AL$55,($R$2-1)*12+5) -> -1018.2292 | M16: =INDEX(Monthly!$C$55:$AL$55,($R$2-1)*12+6) -> -1005.5804 | N16: =INDEX(Monthly!$C$55:$AL$55,($R$2-1)*12+7) -> -992.93155 | O16: =INDEX(Monthly!$C$55:$AL$55,($R$2-1)*12+8) -> -980.28274 | P16: =INDEX(Monthly!$C$55:$AL$55,($R$2-1)*12+9) -> -967.63393 | Q16: =INDEX(Monthly!$C$55:$AL$55,($R$2-1)*12+10) -> -954.98512 | R16: =INDEX(Monthly!$C$55:$AL$55,($R$2-1)*12+11) -> -942.33631 | S16: =INDEX(Monthly!$C$55:$AL$55,($R$2-1)*12+12) -> -929.6875
A17: Pre-tax income | B17: ='P&L'!B24 -> 280301.03 | C17: ='P&L'!C24 -> 347875.34 | D17: ='P&L'!D24 -> 421452.39 | H17: =INDEX(Monthly!$C$56:$AL$56,($R$2-1)*12+1) -> 20382.767 | I17: =INDEX(Monthly!$C$56:$AL$56,($R$2-1)*12+2) -> 20945.407 | J17: =INDEX(Monthly!$C$56:$AL$56,($R$2-1)*12+3) -> 21506.05 | K17: =INDEX(Monthly!$C$56:$AL$56,($R$2-1)*12+4) -> 22058.489 | L17: =INDEX(Monthly!$C$56:$AL$56,($R$2-1)*12+5) -> 22602.838 | M17: =INDEX(Monthly!$C$56:$AL$56,($R$2-1)*12+6) -> 23139.21 | N17: =INDEX(Monthly!$C$56:$AL$56,($R$2-1)*12+7) -> 23667.718 | O17: =INDEX(Monthly!$C$56:$AL$56,($R$2-1)*12+8) -> 24188.471 | P17: =INDEX(Monthly!$C$56:$AL$56,($R$2-1)*12+9) -> 24701.577 | Q17: =INDEX(Monthly!$C$56:$AL$56,($R$2-1)*12+10) -> 25207.145 | R17: =INDEX(Monthly!$C$56:$AL$56,($R$2-1)*12+11) -> 25705.279 | S17: =INDEX(Monthly!$C$56:$AL$56,($R$2-1)*12+12) -> 26196.084
A18: Income tax | B18: ='P&L'!B25 -> -58863.217 | C18: ='P&L'!C25 -> -73053.821 | D18: ='P&L'!D25 -> -88505.001 | H18: =INDEX(Monthly!$C$59:$AL$59,($R$2-1)*12+1) -> -4280.381 | I18: =INDEX(Monthly!$C$59:$AL$59,($R$2-1)*12+2) -> -4398.5354 | J18: =INDEX(Monthly!$C$59:$AL$59,($R$2-1)*12+3) -> -4516.2705 | K18: =INDEX(Monthly!$C$59:$AL$59,($R$2-1)*12+4) -> -4632.2826 | L18: =INDEX(Monthly!$C$59:$AL$59,($R$2-1)*12+5) -> -4746.5959 | M18: =INDEX(Monthly!$C$59:$AL$59,($R$2-1)*12+6) -> -4859.2341 | N18: =INDEX(Monthly!$C$59:$AL$59,($R$2-1)*12+7) -> -4970.2207 | O18: =INDEX(Monthly!$C$59:$AL$59,($R$2-1)*12+8) -> -5079.5788 | P18: =INDEX(Monthly!$C$59:$AL$59,($R$2-1)*12+9) -> -5187.3313 | Q18: =INDEX(Monthly!$C$59:$AL$59,($R$2-1)*12+10) -> -5293.5005 | R18: =INDEX(Monthly!$C$59:$AL$59,($R$2-1)*12+11) -> -5398.1086 | S18: =INDEX(Monthly!$C$59:$AL$59,($R$2-1)*12+12) -> -5501.1776
A19: Net income | B19: ='P&L'!B26 -> 221437.82 | C19: ='P&L'!C26 -> 274821.52 | D19: ='P&L'!D26 -> 332947.38 | H19: =INDEX(Monthly!$C$60:$AL$60,($R$2-1)*12+1) -> 16102.386 | I19: =INDEX(Monthly!$C$60:$AL$60,($R$2-1)*12+2) -> 16546.871 | J19: =INDEX(Monthly!$C$60:$AL$60,($R$2-1)*12+3) -> 16989.779 | K19: =INDEX(Monthly!$C$60:$AL$60,($R$2-1)*12+4) -> 17426.206 | L19: =INDEX(Monthly!$C$60:$AL$60,($R$2-1)*12+5) -> 17856.242 | M19: =INDEX(Monthly!$C$60:$AL$60,($R$2-1)*12+6) -> 18279.976 | N19: =INDEX(Monthly!$C$60:$AL$60,($R$2-1)*12+7) -> 18697.497 | O19: =INDEX(Monthly!$C$60:$AL$60,($R$2-1)*12+8) -> 19108.892 | P19: =INDEX(Monthly!$C$60:$AL$60,($R$2-1)*12+9) -> 19514.246 | Q19: =INDEX(Monthly!$C$60:$AL$60,($R$2-1)*12+10) -> 19913.645 | R19: =INDEX(Monthly!$C$60:$AL$60,($R$2-1)*12+11) -> 20307.171 | S19: =INDEX(Monthly!$C$60:$AL$60,($R$2-1)*12+12) -> 20694.906
A20: Net margin | B20: ='P&L'!B27 -> 0.11210338 | C20: ='P&L'!C27 -> 0.12787551 | D20: ='P&L'!D27 -> 0.1424478 | H20: =IF(H7=0,0,H19/H7) -> 0.1001629 | I20: =IF(I7=0,0,I19/I7) -> 0.10246094 | J20: =IF(J7=0,0,J19/J7) -> 0.10473511 | K20: =IF(K7=0,0,K19/K7) -> 0.10695599 | L20: =IF(L7=0,0,L19/L7) -> 0.10912513 | M20: =IF(M7=0,0,M19/M7) -> 0.11124404 | N20: =IF(N7=0,0,N19/N7) -> 0.11331418 | O20: =IF(O7=0,0,O19/O7) -> 0.11533693 | ... S20: =IF(S7=0,0,S19/S7) -> 0.12298034
A22: Cash flow ($'000) — by year | H22: ="Cash flow ($'000) — Year "&$R$2&", by month" -> Cash flow ($'000) — Year 1, by month
B23: 1 | C23: 2 | D23: 3 | H23: =INDEX(Monthly!$C$4:$AL$4,($R$2-1)*12+1) -> 1 | I23: =INDEX(Monthly!$C$4:$AL$4,($R$2-1)*12+2) -> 2 | J23: =INDEX(Monthly!$C$4:$AL$4,($R$2-1)*12+3) -> 3 | K23: =INDEX(Monthly!$C$4:$AL$4,($R$2-1)*12+4) -> 4 | L23: =INDEX(Monthly!$C$4:$AL$4,($R$2-1)*12+5) -> 5 | M23: =INDEX(Monthly!$C$4:$AL$4,($R$2-1)*12+6) -> 6 | N23: =INDEX(Monthly!$C$4:$AL$4,($R$2-1)*12+7) -> 7 | O23: =INDEX(Monthly!$C$4:$AL$4,($R$2-1)*12+8) -> 8 | P23: =INDEX(Monthly!$C$4:$AL$4,($R$2-1)*12+9) -> 9 | Q23: =INDEX(Monthly!$C$4:$AL$4,($R$2-1)*12+10) -> 10 | R23: =INDEX(Monthly!$C$4:$AL$4,($R$2-1)*12+11) -> 11 | S23: =INDEX(Monthly!$C$4:$AL$4,($R$2-1)*12+12) -> 12
A24: Operating cash flow | B24: ='Cash Flow'!B10 -> 147060.42 | C24: ='Cash Flow'!C10 -> 282618.64 | D24: ='Cash Flow'!D10 -> 344946.13 | H24: =INDEX(Monthly!$C$84:$AL$84,($R$2-1)*12+1) -> -64556.352 | I24: =INDEX(Monthly!$C$84:$AL$84,($R$2-1)*12+2) -> 16946.201 | J24: =INDEX(Monthly!$C$84:$AL$84,($R$2-1)*12+3) -> 17423.292 | K24: =INDEX(Monthly!$C$84:$AL$84,($R$2-1)*12+4) -> 17893.955 | L24: =INDEX(Monthly!$C$84:$AL$84,($R$2-1)*12+5) -> 18358.28 | M24: =INDEX(Monthly!$C$84:$AL$84,($R$2-1)*12+6) -> 18816.357 | N24: =INDEX(Monthly!$C$84:$AL$84,($R$2-1)*12+7) -> 19268.272 | O24: =INDEX(Monthly!$C$84:$AL$84,($R$2-1)*12+8) -> 19714.113 | P24: =INDEX(Monthly!$C$84:$AL$84,($R$2-1)*12+9) -> 20153.963 | Q24: =INDEX(Monthly!$C$84:$AL$84,($R$2-1)*12+10) -> 20587.907 | R24: =INDEX(Monthly!$C$84:$AL$84,($R$2-1)*12+11) -> 21016.028 | S24: =INDEX(Monthly!$C$84:$AL$84,($R$2-1)*12+12) -> 21438.407
A25: Capital spending | B25: ='Cash Flow'!B11 -> -89629.501 | C25: ='Cash Flow'!C11 -> -32237 | D25: ='Cash Flow'!D11 -> -35059.937 | H25: =INDEX(Monthly!$C$85:$AL$85,($R$2-1)*12+1) -> -62411.43 | I25: =INDEX(Monthly!$C$85:$AL$85,($R$2-1)*12+2) -> -2422.4166 | J25: =INDEX(Monthly!$C$85:$AL$85,($R$2-1)*12+3) -> -2433.2498 | K25: =INDEX(Monthly!$C$85:$AL$85,($R$2-1)*12+4) -> -2443.9313 | L25: =INDEX(Monthly!$C$85:$AL$85,($R$2-1)*12+5) -> -2454.4634 | M25: =INDEX(Monthly!$C$85:$AL$85,($R$2-1)*12+6) -> -2464.8479 | N25: =INDEX(Monthly!$C$85:$AL$85,($R$2-1)*12+7) -> -2475.0871 | O25: =INDEX(Monthly!$C$85:$AL$85,($R$2-1)*12+8) -> -2485.1829 | P25: =INDEX(Monthly!$C$85:$AL$85,($R$2-1)*12+9) -> -2495.1374 | Q25: =INDEX(Monthly!$C$85:$AL$85,($R$2-1)*12+10) -> -2504.9525 | R25: =INDEX(Monthly!$C$85:$AL$85,($R$2-1)*12+11) -> -2514.6303 | S25: =INDEX(Monthly!$C$85:$AL$85,($R$2-1)*12+12) -> -2524.1725
A26: Equity raised | B26: ='Cash Flow'!B12 -> 100000 | C26: ='Cash Flow'!C12 -> 0 | D26: ='Cash Flow'!D12 -> 0 | H26: =INDEX(Monthly!$C$86:$AL$86,($R$2-1)*12+1) -> 100000 | I26: =INDEX(Monthly!$C$86:$AL$86,($R$2-1)*12+2) -> 0 | J26: =INDEX(Monthly!$C$86:$AL$86,($R$2-1)*12+3) -> 0 | K26: =INDEX(Monthly!$C$86:$AL$86,($R$2-1)*12+4) -> 0 | L26: =INDEX(Monthly!$C$86:$AL$86,($R$2-1)*12+5) -> 0 | M26: =INDEX(Monthly!$C$86:$AL$86,($R$2-1)*12+6) -> 0 | N26: =INDEX(Monthly!$C$86:$AL$86,($R$2-1)*12+7) -> 0 | O26: =INDEX(Monthly!$C$86:$AL$86,($R$2-1)*12+8) -> 0 | P26: =INDEX(Monthly!$C$86:$AL$86,($R$2-1)*12+9) -> 0 | Q26: =INDEX(Monthly!$C$86:$AL$86,($R$2-1)*12+10) -> 0 | R26: =INDEX(Monthly!$C$86:$AL$86,($R$2-1)*12+11) -> 0 | S26: =INDEX(Monthly!$C$86:$AL$86,($R$2-1)*12+12) -> 0
A27: Loan drawdown | B27: ='Cash Flow'!B13 -> 150000 | C27: ='Cash Flow'!C13 -> 0 | D27: ='Cash Flow'!D13 -> 0 | H27: =INDEX(Monthly!$C$71:$AL$71,($R$2-1)*12+1) -> 150000 | I27: =INDEX(Monthly!$C$71:$AL$71,($R$2-1)*12+2) -> 0 | J27: =INDEX(Monthly!$C$71:$AL$71,($R$2-1)*12+3) -> 0 | K27: =INDEX(Monthly!$C$71:$AL$71,($R$2-1)*12+4) -> 0 | L27: =INDEX(Monthly!$C$71:$AL$71,($R$2-1)*12+5) -> 0 | M27: =INDEX(Monthly!$C$71:$AL$71,($R$2-1)*12+6) -> 0 | N27: =INDEX(Monthly!$C$71:$AL$71,($R$2-1)*12+7) -> 0 | O27: =INDEX(Monthly!$C$71:$AL$71,($R$2-1)*12+8) -> 0 | P27: =INDEX(Monthly!$C$71:$AL$71,($R$2-1)*12+9) -> 0 | Q27: =INDEX(Monthly!$C$71:$AL$71,($R$2-1)*12+10) -> 0 | R27: =INDEX(Monthly!$C$71:$AL$71,($R$2-1)*12+11) -> 0 | S27: =INDEX(Monthly!$C$71:$AL$71,($R$2-1)*12+12) -> 0
A28: Loan repayment | B28: ='Cash Flow'!B14 -> -19642.857 | C28: ='Cash Flow'!C14 -> -21428.571 | D28: ='Cash Flow'!D14 -> -21428.571 | H28: =INDEX(Monthly!$C$72:$AL$72,($R$2-1)*12+1) -> 0 | I28: =INDEX(Monthly!$C$72:$AL$72,($R$2-1)*12+2) -> -1785.7143 | J28: =INDEX(Monthly!$C$72:$AL$72,($R$2-1)*12+3) -> -1785.7143 | K28: =INDEX(Monthly!$C$72:$AL$72,($R$2-1)*12+4) -> -1785.7143 | L28: =INDEX(Monthly!$C$72:$AL$72,($R$2-1)*12+5) -> -1785.7143 | M28: =INDEX(Monthly!$C$72:$AL$72,($R$2-1)*12+6) -> -1785.7143 | N28: =INDEX(Monthly!$C$72:$AL$72,($R$2-1)*12+7) -> -1785.7143 | O28: =INDEX(Monthly!$C$72:$AL$72,($R$2-1)*12+8) -> -1785.7143 | P28: =INDEX(Monthly!$C$72:$AL$72,($R$2-1)*12+9) -> -1785.7143 | Q28: =INDEX(Monthly!$C$72:$AL$72,($R$2-1)*12+10) -> -1785.7143 | R28: =INDEX(Monthly!$C$72:$AL$72,($R$2-1)*12+11) -> -1785.7143 | S28: =INDEX(Monthly!$C$72:$AL$72,($R$2-1)*12+12) -> -1785.7143
A29: Financing cash flow | B29: ='Cash Flow'!B15 -> 230357.14 | C29: ='Cash Flow'!C15 -> -21428.571 | D29: ='Cash Flow'!D15 -> -21428.571 | H29: =INDEX(Monthly!$C$87:$AL$87,($R$2-1)*12+1) -> 250000 | I29: =INDEX(Monthly!$C$87:$AL$87,($R$2-1)*12+2) -> -1785.7143 | J29: =INDEX(Monthly!$C$87:$AL$87,($R$2-1)*12+3) -> -1785.7143 | K29: =INDEX(Monthly!$C$87:$AL$87,($R$2-1)*12+4) -> -1785.7143 | L29: =INDEX(Monthly!$C$87:$AL$87,($R$2-1)*12+5) -> -1785.7143 | M29: =INDEX(Monthly!$C$87:$AL$87,($R$2-1)*12+6) -> -1785.7143 | N29: =INDEX(Monthly!$C$87:$AL$87,($R$2-1)*12+7) -> -1785.7143 | O29: =INDEX(Monthly!$C$87:$AL$87,($R$2-1)*12+8) -> -1785.7143 | P29: =INDEX(Monthly!$C$87:$AL$87,($R$2-1)*12+9) -> -1785.7143 | Q29: =INDEX(Monthly!$C$87:$AL$87,($R$2-1)*12+10) -> -1785.7143 | R29: =INDEX(Monthly!$C$87:$AL$87,($R$2-1)*12+11) -> -1785.7143 | S29: =INDEX(Monthly!$C$87:$AL$87,($R$2-1)*12+12) -> -1785.7143
A30: Net change in cash | B30: ='Cash Flow'!B16 -> 287788.06 | C30: ='Cash Flow'!C16 -> 228953.06 | D30: ='Cash Flow'!D16 -> 288457.62 | H30: =INDEX(Monthly!$C$88:$AL$88,($R$2-1)*12+1) -> 123032.22 | I30: =INDEX(Monthly!$C$88:$AL$88,($R$2-1)*12+2) -> 12738.07 | J30: =INDEX(Monthly!$C$88:$AL$88,($R$2-1)*12+3) -> 13204.328 | K30: =INDEX(Monthly!$C$88:$AL$88,($R$2-1)*12+4) -> 13664.309 | L30: =INDEX(Monthly!$C$88:$AL$88,($R$2-1)*12+5) -> 14118.103 | M30: =INDEX(Monthly!$C$88:$AL$88,($R$2-1)*12+6) -> 14565.795 | N30: =INDEX(Monthly!$C$88:$AL$88,($R$2-1)*12+7) -> 15007.471 | O30: =INDEX(Monthly!$C$88:$AL$88,($R$2-1)*12+8) -> 15443.215 | P30: =INDEX(Monthly!$C$88:$AL$88,($R$2-1)*12+9) -> 15873.111 | Q30: =INDEX(Monthly!$C$88:$AL$88,($R$2-1)*12+10) -> 16297.24 | R30: =INDEX(Monthly!$C$88:$AL$88,($R$2-1)*12+11) -> 16715.683 | S30: =INDEX(Monthly!$C$88:$AL$88,($R$2-1)*12+12) -> 17128.52
A31: Closing cash | B31: ='Cash Flow'!B18 -> 287788.06 | C31: ='Cash Flow'!C18 -> 516741.13 | D31: ='Cash Flow'!D18 -> 805198.75 | H31: =INDEX(Monthly!$C$90:$AL$90,($R$2-1)*12+1) -> 123032.22 | I31: =INDEX(Monthly!$C$90:$AL$90,($R$2-1)*12+2) -> 135770.29 | J31: =INDEX(Monthly!$C$90:$AL$90,($R$2-1)*12+3) -> 148974.62 | K31: =INDEX(Monthly!$C$90:$AL$90,($R$2-1)*12+4) -> 162638.93 | L31: =INDEX(Monthly!$C$90:$AL$90,($R$2-1)*12+5) -> 176757.03 | M31: =INDEX(Monthly!$C$90:$AL$90,($R$2-1)*12+6) -> 191322.82 | N31: =INDEX(Monthly!$C$90:$AL$90,($R$2-1)*12+7) -> 206330.29 | O31: =INDEX(Monthly!$C$90:$AL$90,($R$2-1)*12+8) -> 221773.51 | P31: =INDEX(Monthly!$C$90:$AL$90,($R$2-1)*12+9) -> 237646.62 | Q31: =INDEX(Monthly!$C$90:$AL$90,($R$2-1)*12+10) -> 253943.86 | R31: =INDEX(Monthly!$C$90:$AL$90,($R$2-1)*12+11) -> 270659.54 | S31: =INDEX(Monthly!$C$90:$AL$90,($R$2-1)*12+12) -> 287788.06
A39: Balance sheet at year end ($'000) | H39: ="Balance sheet at month end ($'000) — Year "&$R$2 -> Balance sheet at month end ($'000) — Year 1
B40: 1 | C40: 2 | D40: 3 | H40: =INDEX(Monthly!$C$4:$AL$4,($R$2-1)*12+1) -> 1 | I40: =INDEX(Monthly!$C$4:$AL$4,($R$2-1)*12+2) -> 2 | J40: =INDEX(Monthly!$C$4:$AL$4,($R$2-1)*12+3) -> 3 | K40: =INDEX(Monthly!$C$4:$AL$4,($R$2-1)*12+4) -> 4 | L40: =INDEX(Monthly!$C$4:$AL$4,($R$2-1)*12+5) -> 5 | M40: =INDEX(Monthly!$C$4:$AL$4,($R$2-1)*12+6) -> 6 | N40: =INDEX(Monthly!$C$4:$AL$4,($R$2-1)*12+7) -> 7 | O40: =INDEX(Monthly!$C$4:$AL$4,($R$2-1)*12+8) -> 8 | P40: =INDEX(Monthly!$C$4:$AL$4,($R$2-1)*12+9) -> 9 | Q40: =INDEX(Monthly!$C$4:$AL$4,($R$2-1)*12+10) -> 10 | R40: =INDEX(Monthly!$C$4:$AL$4,($R$2-1)*12+11) -> 11 | S40: =INDEX(Monthly!$C$4:$AL$4,($R$2-1)*12+12) -> 12
A41: Cash | B41: ='Balance Sheet'!B5 -> 287788.06 | C41: ='Balance Sheet'!C5 -> 516741.13 | D41: ='Balance Sheet'!D5 -> 805198.75 | H41: =INDEX(Monthly!$C$90:$AL$90,($R$2-1)*12+1) -> 123032.22 | I41: =INDEX(Monthly!$C$90:$AL$90,($R$2-1)*12+2) -> 135770.29 | J41: =INDEX(Monthly!$C$90:$AL$90,($R$2-1)*12+3) -> 148974.62 | K41: =INDEX(Monthly!$C$90:$AL$90,($R$2-1)*12+4) -> 162638.93 | L41: =INDEX(Monthly!$C$90:$AL$90,($R$2-1)*12+5) -> 176757.03 | M41: =INDEX(Monthly!$C$90:$AL$90,($R$2-1)*12+6) -> 191322.82 | N41: =INDEX(Monthly!$C$90:$AL$90,($R$2-1)*12+7) -> 206330.29 | O41: =INDEX(Monthly!$C$90:$AL$90,($R$2-1)*12+8) -> 221773.51 | P41: =INDEX(Monthly!$C$90:$AL$90,($R$2-1)*12+9) -> 237646.62 | Q41: =INDEX(Monthly!$C$90:$AL$90,($R$2-1)*12+10) -> 253943.86 | R41: =INDEX(Monthly!$C$90:$AL$90,($R$2-1)*12+11) -> 270659.54 | S41: =INDEX(Monthly!$C$90:$AL$90,($R$2-1)*12+12) -> 287788.06
A42: Accounts receivable | B42: ='Balance Sheet'!B6 -> 95357.627 | C42: ='Balance Sheet'!C6 -> 103729.39 | D42: ='Balance Sheet'!D6 -> 112795.59 | H42: =INDEX(Monthly!$C$76:$AL$76,($R$2-1)*12+1) -> 91098.449 | I42: =INDEX(Monthly!$C$76:$AL$76,($R$2-1)*12+2) -> 91513.515 | J42: =INDEX(Monthly!$C$76:$AL$76,($R$2-1)*12+3) -> 91922.77 | K42: =INDEX(Monthly!$C$76:$AL$76,($R$2-1)*12+4) -> 92326.295 | L42: =INDEX(Monthly!$C$76:$AL$76,($R$2-1)*12+5) -> 92724.171 | M42: =INDEX(Monthly!$C$76:$AL$76,($R$2-1)*12+6) -> 93116.477 | N42: =INDEX(Monthly!$C$76:$AL$76,($R$2-1)*12+7) -> 93503.29 | O42: =INDEX(Monthly!$C$76:$AL$76,($R$2-1)*12+8) -> 93884.688 | P42: =INDEX(Monthly!$C$76:$AL$76,($R$2-1)*12+9) -> 94260.747 | Q42: =INDEX(Monthly!$C$76:$AL$76,($R$2-1)*12+10) -> 94631.541 | R42: =INDEX(Monthly!$C$76:$AL$76,($R$2-1)*12+11) -> 94997.143 | S42: =INDEX(Monthly!$C$76:$AL$76,($R$2-1)*12+12) -> 95357.627
A43: Inventory | B43: ='Balance Sheet'!B7 -> 9353.9901 | C43: ='Balance Sheet'!C7 -> 10174.559 | D43: ='Balance Sheet'!D7 -> 11063.283 | H43: =INDEX(Monthly!$C$77:$AL$77,($R$2-1)*12+1) -> 8950.8167 | I43: =INDEX(Monthly!$C$77:$AL$77,($R$2-1)*12+2) -> 8990.1068 | J43: =INDEX(Monthly!$C$77:$AL$77,($R$2-1)*12+3) -> 9028.8468 | K43: =INDEX(Monthly!$C$77:$AL$77,($R$2-1)*12+4) -> 9067.0445 | L43: =INDEX(Monthly!$C$77:$AL$77,($R$2-1)*12+5) -> 9104.7074 | M43: =INDEX(Monthly!$C$77:$AL$77,($R$2-1)*12+6) -> 9141.843 | N43: =INDEX(Monthly!$C$77:$AL$77,($R$2-1)*12+7) -> 9178.4588 | O43: =INDEX(Monthly!$C$77:$AL$77,($R$2-1)*12+8) -> 9214.5619 | P43: =INDEX(Monthly!$C$77:$AL$77,($R$2-1)*12+9) -> 9250.1595 | Q43: =INDEX(Monthly!$C$77:$AL$77,($R$2-1)*12+10) -> 9285.2588 | R43: =INDEX(Monthly!$C$77:$AL$77,($R$2-1)*12+11) -> 9319.8667 | S43: =INDEX(Monthly!$C$77:$AL$77,($R$2-1)*12+12) -> 9353.9901
A44: Net fixed assets | B44: ='Balance Sheet'!B8 -> 78782.757 | C44: ='Balance Sheet'!C8 -> 95739.823 | D44: ='Balance Sheet'!D8 -> 110697.6 | H44: =INDEX(Monthly!$C$67:$AL$67,($R$2-1)*12+1) -> 61668.436 | I44: =INDEX(Monthly!$C$67:$AL$67,($R$2-1)*12+2) -> 63319.021 | J44: =INDEX(Monthly!$C$67:$AL$67,($R$2-1)*12+3) -> 64951.472 | K44: =INDEX(Monthly!$C$67:$AL$67,($R$2-1)*12+4) -> 66565.511 | L44: =INDEX(Monthly!$C$67:$AL$67,($R$2-1)*12+5) -> 68160.861 | M44: =INDEX(Monthly!$C$67:$AL$67,($R$2-1)*12+6) -> 69737.252 | N44: =INDEX(Monthly!$C$67:$AL$67,($R$2-1)*12+7) -> 71294.418 | O44: =INDEX(Monthly!$C$67:$AL$67,($R$2-1)*12+8) -> 72832.093 | P44: =INDEX(Monthly!$C$67:$AL$67,($R$2-1)*12+9) -> 74350.02 | Q44: =INDEX(Monthly!$C$67:$AL$67,($R$2-1)*12+10) -> 75847.94 | R44: =INDEX(Monthly!$C$67:$AL$67,($R$2-1)*12+11) -> 77325.602 | S44: =INDEX(Monthly!$C$67:$AL$67,($R$2-1)*12+12) -> 78782.757
A45: Total assets | B45: ='Balance Sheet'!B9 -> 471282.44 | C45: ='Balance Sheet'!C9 -> 726384.9 | D45: ='Balance Sheet'!D9 -> 1039755.2 | H45: =INDEX(Monthly!$C$104:$AL$104,($R$2-1)*12+1) -> 284749.92 | I45: =INDEX(Monthly!$C$104:$AL$104,($R$2-1)*12+2) -> 299592.93 | J45: =INDEX(Monthly!$C$104:$AL$104,($R$2-1)*12+3) -> 314877.71 | K45: =INDEX(Monthly!$C$104:$AL$104,($R$2-1)*12+4) -> 330597.78 | L45: =INDEX(Monthly!$C$104:$AL$104,($R$2-1)*12+5) -> 346746.77 | M45: =INDEX(Monthly!$C$104:$AL$104,($R$2-1)*12+6) -> 363318.39 | N45: =INDEX(Monthly!$C$104:$AL$104,($R$2-1)*12+7) -> 380306.46 | O45: =INDEX(Monthly!$C$104:$AL$104,($R$2-1)*12+8) -> 397704.85 | P45: =INDEX(Monthly!$C$104:$AL$104,($R$2-1)*12+9) -> 415507.55 | Q45: =INDEX(Monthly!$C$104:$AL$104,($R$2-1)*12+10) -> 433708.6 | R45: =INDEX(Monthly!$C$104:$AL$104,($R$2-1)*12+11) -> 452302.16 | S45: =INDEX(Monthly!$C$104:$AL$104,($R$2-1)*12+12) -> 471282.44
A46: Accounts payable | B46: ='Balance Sheet'!B10 -> 19487.479 | C46: ='Balance Sheet'!C10 -> 21196.999 | D46: ='Balance Sheet'!D10 -> 23048.507 | H46: =INDEX(Monthly!$C$78:$AL$78,($R$2-1)*12+1) -> 18647.535 | I46: =INDEX(Monthly!$C$78:$AL$78,($R$2-1)*12+2) -> 18729.389 | J46: =INDEX(Monthly!$C$78:$AL$78,($R$2-1)*12+3) -> 18810.098 | K46: =INDEX(Monthly!$C$78:$AL$78,($R$2-1)*12+4) -> 18889.676 | L46: =INDEX(Monthly!$C$78:$AL$78,($R$2-1)*12+5) -> 18968.14 | M46: =INDEX(Monthly!$C$78:$AL$78,($R$2-1)*12+6) -> 19045.506 | N46: =INDEX(Monthly!$C$78:$AL$78,($R$2-1)*12+7) -> 19121.789 | O46: =INDEX(Monthly!$C$78:$AL$78,($R$2-1)*12+8) -> 19197.004 | P46: =INDEX(Monthly!$C$78:$AL$78,($R$2-1)*12+9) -> 19271.166 | Q46: =INDEX(Monthly!$C$78:$AL$78,($R$2-1)*12+10) -> 19344.289 | R46: =INDEX(Monthly!$C$78:$AL$78,($R$2-1)*12+11) -> 19416.389 | S46: =INDEX(Monthly!$C$78:$AL$78,($R$2-1)*12+12) -> 19487.479
A47: Loan | B47: ='Balance Sheet'!B11 -> 130357.14 | C47: ='Balance Sheet'!C11 -> 108928.57 | D47: ='Balance Sheet'!D11 -> 87500 | H47: =INDEX(Monthly!$C$73:$AL$73,($R$2-1)*12+1) -> 150000 | I47: =INDEX(Monthly!$C$73:$AL$73,($R$2-1)*12+2) -> 148214.29 | J47: =INDEX(Monthly!$C$73:$AL$73,($R$2-1)*12+3) -> 146428.57 | K47: =INDEX(Monthly!$C$73:$AL$73,($R$2-1)*12+4) -> 144642.86 | L47: =INDEX(Monthly!$C$73:$AL$73,($R$2-1)*12+5) -> 142857.14 | M47: =INDEX(Monthly!$C$73:$AL$73,($R$2-1)*12+6) -> 141071.43 | N47: =INDEX(Monthly!$C$73:$AL$73,($R$2-1)*12+7) -> 139285.71 | O47: =INDEX(Monthly!$C$73:$AL$73,($R$2-1)*12+8) -> 137500 | P47: =INDEX(Monthly!$C$73:$AL$73,($R$2-1)*12+9) -> 135714.29 | Q47: =INDEX(Monthly!$C$73:$AL$73,($R$2-1)*12+10) -> 133928.57 | R47: =INDEX(Monthly!$C$73:$AL$73,($R$2-1)*12+11) -> 132142.86 | S47: =INDEX(Monthly!$C$73:$AL$73,($R$2-1)*12+12) -> 130357.14
A48: Total liabilities | B48: ='Balance Sheet'!B12 -> 149844.62 | C48: ='Balance Sheet'!C12 -> 130125.57 | D48: ='Balance Sheet'!D12 -> 110548.51 | H48: =INDEX(Monthly!$C$105:$AL$105,($R$2-1)*12+1) -> 168647.53 | I48: =INDEX(Monthly!$C$105:$AL$105,($R$2-1)*12+2) -> 166943.67 | J48: =INDEX(Monthly!$C$105:$AL$105,($R$2-1)*12+3) -> 165238.67 | K48: =INDEX(Monthly!$C$105:$AL$105,($R$2-1)*12+4) -> 163532.53 | L48: =INDEX(Monthly!$C$105:$AL$105,($R$2-1)*12+5) -> 161825.28 | M48: =INDEX(Monthly!$C$105:$AL$105,($R$2-1)*12+6) -> 160116.93 | N48: =INDEX(Monthly!$C$105:$AL$105,($R$2-1)*12+7) -> 158407.5 | O48: =INDEX(Monthly!$C$105:$AL$105,($R$2-1)*12+8) -> 156697 | P48: =INDEX(Monthly!$C$105:$AL$105,($R$2-1)*12+9) -> 154985.45 | Q48: =INDEX(Monthly!$C$105:$AL$105,($R$2-1)*12+10) -> 153272.86 | R48: =INDEX(Monthly!$C$105:$AL$105,($R$2-1)*12+11) -> 151559.25 | S48: =INDEX(Monthly!$C$105:$AL$105,($R$2-1)*12+12) -> 149844.62
A49: Paid-in capital | B49: ='Balance Sheet'!B13 -> 100000 | C49: ='Balance Sheet'!C13 -> 100000 | D49: ='Balance Sheet'!D13 -> 100000 | H49: =INDEX(Monthly!$C$102:$AL$102,($R$2-1)*12+1) -> 100000 | I49: =INDEX(Monthly!$C$102:$AL$102,($R$2-1)*12+2) -> 100000 | J49: =INDEX(Monthly!$C$102:$AL$102,($R$2-1)*12+3) -> 100000 | K49: =INDEX(Monthly!$C$102:$AL$102,($R$2-1)*12+4) -> 100000 | L49: =INDEX(Monthly!$C$102:$AL$102,($R$2-1)*12+5) -> 100000 | M49: =INDEX(Monthly!$C$102:$AL$102,($R$2-1)*12+6) -> 100000 | N49: =INDEX(Monthly!$C$102:$AL$102,($R$2-1)*12+7) -> 100000 | O49: =INDEX(Monthly!$C$102:$AL$102,($R$2-1)*12+8) -> 100000 | P49: =INDEX(Monthly!$C$102:$AL$102,($R$2-1)*12+9) -> 100000 | Q49: =INDEX(Monthly!$C$102:$AL$102,($R$2-1)*12+10) -> 100000 | R49: =INDEX(Monthly!$C$102:$AL$102,($R$2-1)*12+11) -> 100000 | S49: =INDEX(Monthly!$C$102:$AL$102,($R$2-1)*12+12) -> 100000
A50: Retained earnings | B50: ='Balance Sheet'!B14 -> 221437.82 | C50: ='Balance Sheet'!C14 -> 496259.33 | D50: ='Balance Sheet'!D14 -> 829206.72 | H50: =INDEX(Monthly!$C$103:$AL$103,($R$2-1)*12+1) -> 16102.386 | I50: =INDEX(Monthly!$C$103:$AL$103,($R$2-1)*12+2) -> 32649.257 | J50: =INDEX(Monthly!$C$103:$AL$103,($R$2-1)*12+3) -> 49639.036 | K50: =INDEX(Monthly!$C$103:$AL$103,($R$2-1)*12+4) -> 67065.242 | L50: =INDEX(Monthly!$C$103:$AL$103,($R$2-1)*12+5) -> 84921.484 | M50: =INDEX(Monthly!$C$103:$AL$103,($R$2-1)*12+6) -> 103201.46 | N50: =INDEX(Monthly!$C$103:$AL$103,($R$2-1)*12+7) -> 121898.96 | O50: =INDEX(Monthly!$C$103:$AL$103,($R$2-1)*12+8) -> 141007.85 | P50: =INDEX(Monthly!$C$103:$AL$103,($R$2-1)*12+9) -> 160522.1 | Q50: =INDEX(Monthly!$C$103:$AL$103,($R$2-1)*12+10) -> 180435.74 | R50: =INDEX(Monthly!$C$103:$AL$103,($R$2-1)*12+11) -> 200742.91 | S50: =INDEX(Monthly!$C$103:$AL$103,($R$2-1)*12+12) -> 221437.82
...

Sheet Scenarios
A1: Scenarios — Low / Base / High | H1: =HYPERLINK("#'Cover'!A1","◂ Contents") -> ◂ Contents
A2: All three scenarios calculated side by side, live: change any input and every column updates. Active = the scenario chosen on the Dashboard.
A5: Key drivers
A6: Driver | B6: Low | C6: Base | D6: High | E6: Active
A7: Active patients at start (#) | B7: =Inputs!$B$14 -> 2700 | C7: =Inputs!$C$14 -> 3000 | D7: =Inputs!$D$14 -> 3300 | E7: =Inputs!$E$14 -> 3000
A8: Doctor operatories (restorative chairs) (#) | B8: =Inputs!$B$7 -> 6 | C8: =Inputs!$C$7 -> 6 | D8: =Inputs!$D$7 -> 6 | E8: =Inputs!$E$7 -> 6
A9: Production per doctor visit, office fees (year 1) ($) | B9: =Inputs!$B$26 -> 320 | C9: =Inputs!$C$26 -> 330 | D9: =Inputs!$D$26 -> 340 | E9: =Inputs!$E$26 -> 330
A10: Hygiene recall visits per active patient per year (visits) | B10: =Inputs!$B$22 -> 1.4 | C10: =Inputs!$C$22 -> 1.5 | D10: =Inputs!$D$22 -> 1.6 | E10: =Inputs!$E$22 -> 1.5
A11: Marketing cost per new patient ($) | B11: =Inputs!$B$19 -> 230 | C11: =Inputs!$C$19 -> 210 | D11: =Inputs!$D$19 -> 190 | E11: =Inputs!$E$19 -> 210
A12: Rent per sq ft per year (incl. CAM) ($) | B12: =Inputs!$B$49 -> 32 | C12: =Inputs!$C$49 -> 30 | D12: =Inputs!$D$49 -> 28 | E12: =Inputs!$E$49 -> 30
A13: Equity raised at start ($) | B13: =Inputs!$B$83 -> 100000 | C13: =Inputs!$C$83 -> 100000 | D13: =Inputs!$D$83 -> 100000 | E13: =Inputs!$E$83 -> 100000
A15: Results by scenario ($'000)
A16: Output | B16: Low | C16: Base | D16: High | E16: Active
A17: Revenue — final year | B17: =D30 -> 1710590.8 | C17: =D31 -> 2337329.1 | D17: =D32 -> 2956070.4 | E17: ='P&L'!D5 -> 2337329.1
A18: Revenue — whole plan | B18: =SUM(B30:D30) -> 4915431.1 | C18: =SUM(B31:D31) -> 6461762.6 | D18: =SUM(B32:D32) -> 8140720.3 | E18: =SUM('P&L'!$B$5:$D$5) -> 6461762.6
A19: EBITDA — final year | B19: =D36 -> -88156.988 | C19: =D37 -> 449902.76 | D19: =D38 -> 1003994.9 | E19: ='P&L'!D19 -> 449902.76
A20: EBITDA margin — final year | B20: =IF(B17=0,0,B19/B17) -> -0.051535988 | C20: =IF(C17=0,0,C19/C17) -> 0.19248584 | D20: =IF(D17=0,0,D19/D17) -> 0.33963835 | E20: =IF(E17=0,0,E19/E17) -> 0.19248584
A21: Net income — final year | B21: =D42 -> -113923.38 | C21: =D43 -> 332947.38 | D21: =D44 -> 768301.97 | E21: ='P&L'!D26 -> 332947.38
A22: Net income — whole plan | B22: =SUM(B42:D42) -> -304541.71 | C22: =SUM(B43:D43) -> 829206.72 | D22: =SUM(B44:D44) -> 2019017.3 | E22: =SUM('P&L'!$B$26:$D$26) -> 829206.72
A23: Cash at the end of the plan | B23: =D48 -> -304710.09 | C23: =D49 -> 805198.75 | D23: =D50 -> 1973944.5 | E23: ='Balance Sheet'!D5 -> 805198.75
A24: Lowest cash balance | B24: =MIN('Scenario calc'!$C$92:$AL$92) -> -304710.09 | C24: =MIN('Scenario calc'!$C$217:$AL$217) -> 123032.22 | D24: =MIN('Scenario calc'!$C$342:$AL$342) -> 149009.98 | E24: ='Break-even'!B18 -> 123032.22
A25: Lowest cash point (month #) | B25: =MATCH(MIN('Scenario calc'!$C$92:$AL$92),'Scenario calc'!$C$92:$AL$92,0) -> 36 | C25: =MATCH(MIN('Scenario calc'!$C$217:$AL$217),'Scenario calc'!$C$217:$AL$217,0) -> 1 | D25: =MATCH(MIN('Scenario calc'!$C$342:$AL$342),'Scenario calc'!$C$342:$AL$342,0) -> 1 | E25: ='Break-even'!B6 -> 1
A26: Funding required (incl. cash buffer) | B26: =SUMPRODUCT(--('Scenario calc'!$C$6:$AL$6<=B25),'Scenario calc'!$C$65:$AL$65)-SUMPRODUCT(--('Scenario calc'!$C$6:$AL$6<=B25),'Scenario calc'!$C$86:$AL$86)-SUMPRODUCT(--('Scenario calc'!$C$6:$AL$6<=B25),'Scenario calc'!$C$74:$AL$74)+Inputs!$B$98 -> 903710.09 | C26: =SUMPRODUCT(--('Scenario calc'!$C$131:$AL$131<=C25),'Scenario calc'!$C$190:$AL$190)-SUMPRODUCT(--('Scenario calc'!$C$131:$AL$131<=C25),'Scenario calc'!$C$211:$AL$211)-SUMPRODUCT(--('Scenario calc'!$C$131:$AL$131<=C25),'Scenario calc'!$C$199:$AL$199)+Inputs!$C$98 -> 475967.78 | D26: =SUMPRODUCT(--('Scenario calc'!$C$256:$AL$256<=D25),'Scenario calc'!$C$315:$AL$315)-SUMPRODUCT(--('Scenario calc'!$C$256:$AL$256<=D25),'Scenario calc'!$C$336:$AL$336)-SUMPRODUCT(--('Scenario calc'!$C$256:$AL$256<=D25),'Scenario calc'!$C$324:$AL$324)+Inputs!$D$98 -> 449990.02 | E26: ='Break-even'!B12 -> 475967.78
A28: Revenue by year ($'000)
A29: Scenario | B29: 1 | C29: 2 | D29: 3
A30: Low | B30: =SUMIF('Scenario calc'!$C$7:$AL$7,B$29,'Scenario calc'!$C$33:$AL$33) -> 1565966.3 | C30: =SUMIF('Scenario calc'!$C$7:$AL$7,C$29,'Scenario calc'!$C$33:$AL$33) -> 1638874 | D30: =SUMIF('Scenario calc'!$C$7:$AL$7,D$29,'Scenario calc'!$C$33:$AL$33) -> 1710590.8
A31: Base | B31: =SUMIF('Scenario calc'!$C$132:$AL$132,B$29,'Scenario calc'!$C$158:$AL$158) -> 1975300.1 | C31: =SUMIF('Scenario calc'!$C$132:$AL$132,C$29,'Scenario calc'!$C$158:$AL$158) -> 2149133.3 | D31: =SUMIF('Scenario calc'!$C$132:$AL$132,D$29,'Scenario calc'!$C$158:$AL$158) -> 2337329.1
A32: High | B32: =SUMIF('Scenario calc'!$C$257:$AL$257,B$29,'Scenario calc'!$C$283:$AL$283) -> 2442863.9 | C32: =SUMIF('Scenario calc'!$C$257:$AL$257,C$29,'Scenario calc'!$C$283:$AL$283) -> 2741786 | D32: =SUMIF('Scenario calc'!$C$257:$AL$257,D$29,'Scenario calc'!$C$283:$AL$283) -> 2956070.4
A34: EBITDA by year ($'000)
A35: Scenario | B35: 1 | C35: 2 | D35: 3
A36: Low | B36: =SUMIF('Scenario calc'!$C$7:$AL$7,B$35,'Scenario calc'!$C$53:$AL$53) -> -68678.961 | C36: =SUMIF('Scenario calc'!$C$7:$AL$7,C$35,'Scenario calc'!$C$53:$AL$53) -> -75580.509 | D36: =SUMIF('Scenario calc'!$C$7:$AL$7,D$35,'Scenario calc'!$C$53:$AL$53) -> -88156.988
A37: Base | B37: =SUMIF('Scenario calc'!$C$132:$AL$132,B$35,'Scenario calc'!$C$178:$AL$178) -> 303132.53 | C37: =SUMIF('Scenario calc'!$C$132:$AL$132,C$35,'Scenario calc'!$C$178:$AL$178) -> 373324.91 | D37: =SUMIF('Scenario calc'!$C$132:$AL$132,D$35,'Scenario calc'!$C$178:$AL$178) -> 449902.76
A38: High | B38: =SUMIF('Scenario calc'!$C$257:$AL$257,B$35,'Scenario calc'!$C$303:$AL$303) -> 732453.68 | C38: =SUMIF('Scenario calc'!$C$257:$AL$257,C$35,'Scenario calc'!$C$303:$AL$303) -> 901235.53 | D38: =SUMIF('Scenario calc'!$C$257:$AL$257,D$35,'Scenario calc'!$C$303:$AL$303) -> 1003994.9
A40: Net income by year ($'000)
A41: Scenario | B41: 1 | C41: 2 | D41: 3
A42: Low | B42: =SUMIF('Scenario calc'!$C$7:$AL$7,B$41,'Scenario calc'!$C$62:$AL$62) -> -91045.538 | C42: =SUMIF('Scenario calc'!$C$7:$AL$7,C$41,'Scenario calc'!$C$62:$AL$62) -> -99572.791 | D42: =SUMIF('Scenario calc'!$C$7:$AL$7,D$41,'Scenario calc'!$C$62:$AL$62) -> -113923.38
A43: Base | B43: =SUMIF('Scenario calc'!$C$132:$AL$132,B$41,'Scenario calc'!$C$187:$AL$187) -> 221437.82 | C43: =SUMIF('Scenario calc'!$C$132:$AL$132,C$41,'Scenario calc'!$C$187:$AL$187) -> 274821.52 | D43: =SUMIF('Scenario calc'!$C$132:$AL$132,D$41,'Scenario calc'!$C$187:$AL$187) -> 332947.38
A44: High | B44: =SUMIF('Scenario calc'!$C$257:$AL$257,B$41,'Scenario calc'!$C$312:$AL$312) -> 560178.81 | C44: =SUMIF('Scenario calc'!$C$257:$AL$257,C$41,'Scenario calc'!$C$312:$AL$312) -> 690536.5 | D44: =SUMIF('Scenario calc'!$C$257:$AL$257,D$41,'Scenario calc'!$C$312:$AL$312) -> 768301.97
A46: Cash at year end by year ($'000)
A47: Scenario | B47: 1 | C47: 2 | D47: 3
...

Sheet Break-even
A1: Startup costs, funding need and break-even | F1: =HYPERLINK("#'Cover'!A1","◂ Contents") -> ◂ Contents
A2: Live for the selected scenario. Periods are counted in months from the start of the plan.
A3: Scenario shown | B3: =CHOOSE(Dashboard!$B$4,"Low","Base","High") -> Base
A5: Startup costs & funding need (up to the lowest cash point)
A6: Lowest cash point (month #) | B6: =MATCH(MIN(Monthly!$C$90:$AL$90),Monthly!$C$90:$AL$90,0) -> 1
A7: Capital spending up to the lowest cash point | B7: =SUMPRODUCT(--(Monthly!$C$4:$AL$4<=$B$6),Monthly!$C$63:$AL$63) -> 62411.43
A8: Operating cash burn up to the lowest cash point | B8: =-SUMPRODUCT(--(Monthly!$C$4:$AL$4<=$B$6),Monthly!$C$84:$AL$84) -> 64556.352 | D8: Losses and working capital before the business funds itself
A9: Loan repayments up to the lowest cash point | B9: =-SUMPRODUCT(--(Monthly!$C$4:$AL$4<=$B$6),Monthly!$C$72:$AL$72) -> 0
A10: Total uses of funds | B10: =B7+B8+B9 -> 126967.78
A11: Minimum cash buffer to keep | B11: =Inputs!$E$98 -> 349000 | D11: Input on the Inputs sheet
A12: Funding required (uses + buffer) | B12: =B10+B11 -> 475967.78
A14: Equity raised | B14: =Inputs!$E$83 -> 100000
A15: Loan drawn | B15: =Inputs!$E$84 -> 150000
A16: Total sources of funds | B16: =B14+B15 -> 250000
A17: Funding surplus / (shortfall) | B17: =B16-B12 -> -225967.78 | D17: Negative = raise at least this much more
A18: Lowest cash balance in the plan | B18: =MIN(Monthly!$C$90:$AL$90) -> 123032.22 | D18: Equals sources minus uses
A20: Break-even timing
A21: First month with positive EBITDA (month #) | B21: =IFERROR(MATCH(1,Monthly!$C$91:$AL$91,0),"Not within horizon") -> 1
A22: First month with positive net income (month #) | B22: =IFERROR(MATCH(1,Monthly!$C$94:$AL$94,0),"Not within horizon") -> 1
A23: Cash invested paid back (month #) | B23: =IF(MIN(Monthly!$C$96:$AL$96)>=0,"No investment to pay back",IFERROR(MATCH(1,Monthly!$C$98:$AL$98,0),"Not within horizon")) -> 9 | D23: Cumulative operating + investing cash flow back to zero
A25: Annual break-even revenue
A26: Year # | B26: 1 | C26: 2 | D26: 3
B27: Year 1 | C27: Year 2 | D27: Year 3
A28: Revenue | B28: =SUMIF(Monthly!$C$5:$AL$5,B$26,Monthly!$C$31:$AL$31) -> 1975300.1 | C28: =SUMIF(Monthly!$C$5:$AL$5,C$26,Monthly!$C$31:$AL$31) -> 2149133.3 | D28: =SUMIF(Monthly!$C$5:$AL$5,D$26,Monthly!$C$31:$AL$31) -> 2337329.1
A29: Gross profit | B29: =SUMIF(Monthly!$C$5:$AL$5,B$26,Monthly!$C$38:$AL$38) -> 1700585.9 | C29: =SUMIF(Monthly!$C$5:$AL$5,C$26,Monthly!$C$38:$AL$38) -> 1850264.9 | D29: =SUMIF(Monthly!$C$5:$AL$5,D$26,Monthly!$C$38:$AL$38) -> 2012307.8
A30: Gross margin (contribution) | B30: =IF(B28=0,0,B29/B28) -> 0.86092536 | C30: =IF(C28=0,0,C29/C28) -> 0.86093538 | D30: =IF(D28=0,0,D29/D28) -> 0.86094328
A31: Operating expenses (treated as fixed) | B31: =-SUMIF(Monthly!$C$5:$AL$5,B$26,Monthly!$C$50:$AL$50) -> 1397453.4 | C31: =-SUMIF(Monthly!$C$5:$AL$5,C$26,Monthly!$C$50:$AL$50) -> 1476940 | D31: =-SUMIF(Monthly!$C$5:$AL$5,D$26,Monthly!$C$50:$AL$50) -> 1562405.1
A32: Break-even revenue (EBITDA = 0) | B32: =IF(B30>0,B31/B30,"n/a") -> 1623199.3 | C32: =IF(C30>0,C31/C30,"n/a") -> 1715506.2 | D32: =IF(D30>0,D31/D30,"n/a") -> 1814759.6
A33: Margin of safety (revenue above break-even) | B33: =IF(AND(ISNUMBER(B32),B28>0),(B28-B32)/B28,"n/a") -> 0.17825181 | C33: =IF(AND(ISNUMBER(C32),C28>0),(C28-C32)/C28,"n/a") -> 0.20176836 | D33: =IF(AND(ISNUMBER(D32),D28>0),(D28-D32)/D28,"n/a") -> 0.22357551
A35: Simplification: cost of sales is treated as variable and operating expenses as fixed, so break-even revenue = operating expenses ÷ gross margin.

Sheet Valuation
A1: Discounted cash flow valuation | H1: =HYPERLINK("#'Cover'!A1","◂ Contents") -> ◂ Contents
A2: Enterprise value at the start of the plan, before the funding raised in period 1. Year-end discounting.
A3: Scenario shown | B3: =CHOOSE(Dashboard!$B$4,"Low","Base","High") -> Base
A5: Assumptions (active scenario, from the Inputs sheet)
A6: Discount rate (WACC) | B6: =Inputs!$E$101 -> 0.16
A7: Terminal growth rate | B7: =Inputs!$E$102 -> 0.02
A8: Exit multiple (EV ÷ final-year EBITDA) | B8: =Inputs!$E$103 -> 5.5
A9: Tax rate (for the interest tax shield) | B9: =Inputs!$E$95 -> 0.21
A10: Sensitivity step: WACC | B10: =Inputs!$E$104 -> 0.01
A11: Sensitivity step: terminal growth | B11: =Inputs!$E$105 -> 0.005
A13: Free cash flow by year
A14: Year # | B14: 1 | C14: 2 | D14: 3
B15: Year 1 | C15: Year 2 | D15: Year 3
A16: EBITDA | B16: =SUMIF(Monthly!$C$5:$AL$5,B$14,Monthly!$C$51:$AL$51) -> 303132.53 | C16: =SUMIF(Monthly!$C$5:$AL$5,C$14,Monthly!$C$51:$AL$51) -> 373324.91 | D16: =SUMIF(Monthly!$C$5:$AL$5,D$14,Monthly!$C$51:$AL$51) -> 449902.76
A17: Unlevered free cash flow | B17: =SUMIF(Monthly!$C$5:$AL$5,B$14,Monthly!$C$99:$AL$99) -> 66898.872 | C17: =SUMIF(Monthly!$C$5:$AL$5,C$14,Monthly!$C$99:$AL$99) -> 258415.65 | D17: =SUMIF(Monthly!$C$5:$AL$5,D$14,Monthly!$C$99:$AL$99) -> 316481.28
A18: Discount factor | B18: =1/(1+Inputs!$E$101)^B$14 -> 0.86206897 | C18: =1/(1+Inputs!$E$101)^C$14 -> 0.7431629 | D18: =1/(1+Inputs!$E$101)^D$14 -> 0.64065767
A19: Present value of free cash flow | B19: =B17*B18 -> 57671.441 | C19: =C17*C18 -> 192044.93 | D19: =D17*D18 -> 202756.16
A21: Enterprise value
B22: Perpetual growth | C22: Exit multiple
A23: Present value of the plan's free cash flows | B23: =SUM($B$19:$D$19) -> 452472.53 | C23: =B23 -> 452472.53
A24: Final-year free cash flow | final-year EBITDA | B24: =$D$17 -> 316481.28 | C24: =$D$16 -> 449902.76
A25: Terminal value at the end of year 3 | B25: =IF($B$6>$B$7,B24*(1+$B$7)/($B$6-$B$7),0) -> 2305792.2 | C25: =C24*$B$8 -> 2474465.2
A26: Present value of the terminal value | B26: =B25/(1+$B$6)^$D$14 -> 1477223.5 | C26: =C25/(1+$B$6)^$D$14 -> 1585285.1
A27: Enterprise value | B27: =B23+B26 -> 1929696 | C27: =C23+C26 -> 2037757.6
A28: Terminal value share of enterprise value | B28: =IF(B27<>0,B26/B27,0) -> 0.76552134 | C28: =IF(C27<>0,C26/C27,0) -> 0.77795567
A29: Cross-check: implied exit multiple | implied perpetual growth | B29: =IF(C24>0,B25/C24,"n/a") -> 5.1250901 | C29: =IF(C25+B24<>0,(C25*$B$6-B24)/(C25+B24),"n/a") -> 0.028461007
A30: Enterprise value — average of the two methods | B30: =AVERAGE(B27,C27) -> 1983726.8
A32: Sensitivity: enterprise value (perpetual growth) by WACC and terminal growth
A33: WACC ↓ · terminal growth → | B33: =$B$7+(-2)*$B$11 -> 0.01 | C33: =$B$7+(-1)*$B$11 -> 0.015 | D33: =$B$7+(0)*$B$11 -> 0.02 | E33: =$B$7+(1)*$B$11 -> 0.025 | F33: =$B$7+(2)*$B$11 -> 0.03
A34: =$B$6+(-2)*$B$10 -> 0.14 | B34: =IF($A34>B$33,SUMPRODUCT($B$17:$D$17/(1+$A34)^$B$14:$D$14)+$D$17*(1+B$33)/($A34-B$33)/(1+$A34)^$D$14,"n/a") -> 2130772.4 | C34: =IF($A34>C$33,SUMPRODUCT($B$17:$D$17/(1+$A34)^$B$14:$D$14)+$D$17*(1+C$33)/($A34-C$33)/(1+$A34)^$D$14,"n/a") -> 2205702.2 | D34: =IF($A34>D$33,SUMPRODUCT($B$17:$D$17/(1+$A34)^$B$14:$D$14)+$D$17*(1+D$33)/($A34-D$33)/(1+$A34)^$D$14,"n/a") -> 2286876.2 | E34: =IF($A34>E$33,SUMPRODUCT($B$17:$D$17/(1+$A34)^$B$14:$D$14)+$D$17*(1+E$33)/($A34-E$33)/(1+$A34)^$D$14,"n/a") -> 2375108.9 | F34: =IF($A34>F$33,SUMPRODUCT($B$17:$D$17/(1+$A34)^$B$14:$D$14)+$D$17*(1+F$33)/($A34-F$33)/(1+$A34)^$D$14,"n/a") -> 2471362.7
A35: =$B$6+(-1)*$B$10 -> 0.15 | B35: =IF($A35>B$33,SUMPRODUCT($B$17:$D$17/(1+$A35)^$B$14:$D$14)+$D$17*(1+B$33)/($A35-B$33)/(1+$A35)^$D$14,"n/a") -> 1962896 | C35: =IF($A35>C$33,SUMPRODUCT($B$17:$D$17/(1+$A35)^$B$14:$D$14)+$D$17*(1+C$33)/($A35-C$33)/(1+$A35)^$D$14,"n/a") -> 2026204.3 | D35: =IF($A35>D$33,SUMPRODUCT($B$17:$D$17/(1+$A35)^$B$14:$D$14)+$D$17*(1+D$33)/($A35-D$33)/(1+$A35)^$D$14,"n/a") -> 2094382.4 | E35: =IF($A35>E$33,SUMPRODUCT($B$17:$D$17/(1+$A35)^$B$14:$D$14)+$D$17*(1+E$33)/($A35-E$33)/(1+$A35)^$D$14,"n/a") -> 2168014.8 | F35: =IF($A35>F$33,SUMPRODUCT($B$17:$D$17/(1+$A35)^$B$14:$D$14)+$D$17*(1+F$33)/($A35-F$33)/(1+$A35)^$D$14,"n/a") -> 2247783.3
A36: =$B$6+(0)*$B$10 -> 0.16 | B36: =IF($A36>B$33,SUMPRODUCT($B$17:$D$17/(1+$A36)^$B$14:$D$14)+$D$17*(1+B$33)/($A36-B$33)/(1+$A36)^$D$14,"n/a") -> 1817697.3 | C36: =IF($A36>C$33,SUMPRODUCT($B$17:$D$17/(1+$A36)^$B$14:$D$14)+$D$17*(1+C$33)/($A36-C$33)/(1+$A36)^$D$14,"n/a") -> 1871765.7 | D36: =IF($A36>D$33,SUMPRODUCT($B$17:$D$17/(1+$A36)^$B$14:$D$14)+$D$17*(1+D$33)/($A36-D$33)/(1+$A36)^$D$14,"n/a") -> 1929696 | E36: =IF($A36>E$33,SUMPRODUCT($B$17:$D$17/(1+$A36)^$B$14:$D$14)+$D$17*(1+E$33)/($A36-E$33)/(1+$A36)^$D$14,"n/a") -> 1991917.4 | F36: =IF($A36>F$33,SUMPRODUCT($B$17:$D$17/(1+$A36)^$B$14:$D$14)+$D$17*(1+F$33)/($A36-F$33)/(1+$A36)^$D$14,"n/a") -> 2058925.2
A37: =$B$6+(1)*$B$10 -> 0.17 | B37: =IF($A37>B$33,SUMPRODUCT($B$17:$D$17/(1+$A37)^$B$14:$D$14)+$D$17*(1+B$33)/($A37-B$33)/(1+$A37)^$D$14,"n/a") -> 1690916.3 | C37: =IF($A37>C$33,SUMPRODUCT($B$17:$D$17/(1+$A37)^$B$14:$D$14)+$D$17*(1+C$33)/($A37-C$33)/(1+$A37)^$D$14,"n/a") -> 1737528 | D37: =IF($A37>D$33,SUMPRODUCT($B$17:$D$17/(1+$A37)^$B$14:$D$14)+$D$17*(1+D$33)/($A37-D$33)/(1+$A37)^$D$14,"n/a") -> 1787247.1 | E37: =IF($A37>E$33,SUMPRODUCT($B$17:$D$17/(1+$A37)^$B$14:$D$14)+$D$17*(1+E$33)/($A37-E$33)/(1+$A37)^$D$14,"n/a") -> 1840395.1 | F37: =IF($A37>F$33,SUMPRODUCT($B$17:$D$17/(1+$A37)^$B$14:$D$14)+$D$17*(1+F$33)/($A37-F$33)/(1+$A37)^$D$14,"n/a") -> 1897339.4
A38: =$B$6+(2)*$B$10 -> 0.18 | B38: =IF($A38>B$33,SUMPRODUCT($B$17:$D$17/(1+$A38)^$B$14:$D$14)+$D$17*(1+B$33)/($A38-B$33)/(1+$A38)^$D$14,"n/a") -> 1579295.4 | C38: =IF($A38>C$33,SUMPRODUCT($B$17:$D$17/(1+$A38)^$B$14:$D$14)+$D$17*(1+C$33)/($A38-C$33)/(1+$A38)^$D$14,"n/a") -> 1619810.9 | D38: =IF($A38>D$33,SUMPRODUCT($B$17:$D$17/(1+$A38)^$B$14:$D$14)+$D$17*(1+D$33)/($A38-D$33)/(1+$A38)^$D$14,"n/a") -> 1662858.6 | E38: =IF($A38>E$33,SUMPRODUCT($B$17:$D$17/(1+$A38)^$B$14:$D$14)+$D$17*(1+E$33)/($A38-E$33)/(1+$A38)^$D$14,"n/a") -> 1708683.6 | F38: =IF($A38>F$33,SUMPRODUCT($B$17:$D$17/(1+$A38)^$B$14:$D$14)+$D$17*(1+F$33)/($A38-F$33)/(1+$A38)^$D$14,"n/a") -> 1757563.6
A40: Free cash flow = operating cash flow + interest × (1 − tax rate) − capital spending. Cells marked n/a: WACC not above growth.

Sheet Sources & Uses
A1: Sources and uses of funds | E1: =HYPERLINK("#'Cover'!A1","◂ Contents") -> ◂ Contents
A2: Live for the selected scenario. Where the money comes from and where it goes in the period set below.
A3: Scenario shown | B3: =CHOOSE(Dashboard!$B$4,"Low","Base","High") -> Base
A5: Funding structure ($'000) — raised at the start of the plan
B6: Amount | C6: Share
A7: Equity | B7: =Inputs!$E$83 -> 100000 | C7: =IF($B$9=0,0,B7/$B$9) -> 0.4
A8: Debt (loan) | B8: =Inputs!$E$84 -> 150000 | C8: =IF($B$9=0,0,B8/$B$9) -> 0.6
A9: Total funding | B9: =B7+B8 -> 250000 | C9: =IF(B9=0,0,1) -> 1
A10: Gearing (debt ÷ equity) | B10: =IF(B7<=0,IF(B8>0,"n/a",0),B8/B7) -> 1.5 | D10: n/a: debt without positive equity
A11: Funding required by the plan (Break-even sheet) | B11: ='Break-even'!B12 -> 475967.78
A12: Funding surplus / (shortfall) | B12: ='Break-even'!B17 -> -225967.78
A14: ="Sources and uses of cash in the first "&$B$16&IF($B$16=1," month"," months")&" ($'000)" -> Sources and uses of cash in the first 12 months ($'000)
A15: Period covered (months from the start) | B15: 12 | D15: 1 to 36 (capped)
A16: Months used | B16: =MIN(36,MAX(1,ROUND(B15,0))) -> 12
A17: Sources | B17: Amount | C17: Share
A18: Equity raised | B18: =SUMPRODUCT(--(Monthly!$C$4:$AL$4<=$B$16),Monthly!$C$86:$AL$86) -> 100000 | C18: =IF($B$21=0,0,B18/$B$21) -> 0.25185084
A19: Loan drawdowns | B19: =SUMPRODUCT(--(Monthly!$C$4:$AL$4<=$B$16),Monthly!$C$71:$AL$71) -> 150000 | C19: =IF($B$21=0,0,B19/$B$21) -> 0.37777626
A20: Cash generated by operations | B20: =MAX(0,SUMPRODUCT(--(Monthly!$C$4:$AL$4<=$B$16),Monthly!$C$84:$AL$84)) -> 147060.42 | C20: =IF($B$21=0,0,B20/$B$21) -> 0.37037291
A21: Total sources | B21: =SUM(B18:B20) -> 397060.42 | C21: =IF(B21=0,0,1) -> 1
A23: Uses | B23: Amount | C23: Share
A24: Cash used by operations | B24: =MAX(0,-SUMPRODUCT(--(Monthly!$C$4:$AL$4<=$B$16),Monthly!$C$84:$AL$84)) -> 0 | C24: =IF($B$28=0,0,B24/$B$28) -> 0
A25: Capital spending | B25: =-SUMPRODUCT(--(Monthly!$C$4:$AL$4<=$B$16),Monthly!$C$85:$AL$85) -> 89629.501 | C25: =IF($B$28=0,0,B25/$B$28) -> 0.22573265
A26: Loan repayments | B26: =-SUMPRODUCT(--(Monthly!$C$4:$AL$4<=$B$16),Monthly!$C$72:$AL$72) -> 19642.857 | C26: =IF($B$28=0,0,B26/$B$28) -> 0.0494707
A27: Cash at the end of the period | B27: =INDEX(Monthly!$C$90:$AL$90,$B$16) -> 287788.06 | C27: =IF($B$28=0,0,B27/$B$28) -> 0.72479665
A28: Total uses | B28: =SUM(B24:B27) -> 397060.42 | C28: =IF(B28=0,0,1) -> 1
A29: Sources − uses (must be 0; opening cash is 0) | B29: =B21-B28 -> 0

Sheet KPIs
A1: KPIs & ratios | G1: =HYPERLINK("#'Cover'!A1","◂ Contents") -> ◂ Contents
A2: Dental practice financial model (growing) — industry metrics and financial ratios for the active scenario
A4: Financial ratios
B5: 1 | C5: 2 | D5: 3 | E5: Target
A6: Revenue growth | B6: =IF(N('P&L'!A5)<=0,"n/a",'P&L'!B5/'P&L'!A5-1) -> n/a | C6: =IF(N('P&L'!B5)<=0,"n/a",'P&L'!C5/'P&L'!B5-1) -> 0.088003464 | D6: =IF(N('P&L'!C5)<=0,"n/a",'P&L'!D5/'P&L'!C5-1) -> 0.087568233
A7: Gross margin | B7: =IF('P&L'!B5<=0,"n/a",'P&L'!B7/'P&L'!B5) -> 0.86092536 | C7: =IF('P&L'!C5<=0,"n/a",'P&L'!C7/'P&L'!C5) -> 0.86093538 | D7: =IF('P&L'!D5<=0,"n/a",'P&L'!D7/'P&L'!D5) -> 0.86094328
A8: EBITDA margin | B8: =IF('P&L'!B5<=0,"n/a",'P&L'!B19/'P&L'!B5) -> 0.15346151 | C8: =IF('P&L'!C5<=0,"n/a",'P&L'!C19/'P&L'!C5) -> 0.17370952 | D8: =IF('P&L'!D5<=0,"n/a",'P&L'!D19/'P&L'!D5) -> 0.19248584
A9: Net margin | B9: =IF('P&L'!B5<=0,"n/a",'P&L'!B26/'P&L'!B5) -> 0.11210338 | C9: =IF('P&L'!C5<=0,"n/a",'P&L'!C26/'P&L'!C5) -> 0.12787551 | D9: =IF('P&L'!D5<=0,"n/a",'P&L'!D26/'P&L'!D5) -> 0.1424478
A10: Payroll, % of revenue | B10: =IF('P&L'!B5<=0,"n/a",-SUMIF(Headcount!$C$5:$AL$5,B$5,Headcount!$C$21:$AL$21)/'P&L'!B5) -> 0.47974989 | C10: =IF('P&L'!C5<=0,"n/a",-SUMIF(Headcount!$C$5:$AL$5,C$5,Headcount!$C$21:$AL$21)/'P&L'!C5) -> 0.47014738 | D10: =IF('P&L'!D5<=0,"n/a",-SUMIF(Headcount!$C$5:$AL$5,D$5,Headcount!$C$21:$AL$21)/'P&L'!D5) -> 0.46116705
A11: Marketing, % of revenue | B11: =IF('P&L'!B5<=0,"n/a",-'P&L'!B11/'P&L'!B5) -> 0.042525184 | C11: =IF('P&L'!C5<=0,"n/a",-'P&L'!C11/'P&L'!C5) -> 0.041039799 | D11: =IF('P&L'!D5<=0,"n/a",-'P&L'!D11/'P&L'!D5) -> 0.039622148
A12: Operating expenses, % of revenue | B12: =IF('P&L'!B5<=0,"n/a",-'P&L'!B18/'P&L'!B5) -> 0.70746385 | C12: =IF('P&L'!C5<=0,"n/a",-'P&L'!C18/'P&L'!C5) -> 0.68722586 | D12: =IF('P&L'!D5<=0,"n/a",-'P&L'!D18/'P&L'!D5) -> 0.66845745
A13: Current ratio (current assets ÷ current liabilities) | B13: =IF(('Balance Sheet'!B12-'Balance Sheet'!B11)<=0,"n/a",('Balance Sheet'!B5+'Balance Sheet'!B6+'Balance Sheet'!B7)/('Balance Sheet'!B12-'Balance Sheet'!B11)) -> 20.141121 | C13: =IF(('Balance Sheet'!C12-'Balance Sheet'!C11)<=0,"n/a",('Balance Sheet'!C5+'Balance Sheet'!C6+'Balance Sheet'!C7)/('Balance Sheet'!C12-'Balance Sheet'!C11)) -> 29.751622 | D13: =IF(('Balance Sheet'!D12-'Balance Sheet'!D11)<=0,"n/a",('Balance Sheet'!D5+'Balance Sheet'!D6+'Balance Sheet'!D7)/('Balance Sheet'!D12-'Balance Sheet'!D11)) -> 40.308799
A14: Debt ÷ equity (loan ÷ total equity) | B14: =IF('Balance Sheet'!B15<=0,"n/a",'Balance Sheet'!B11/'Balance Sheet'!B15) -> 0.40554389 | C14: =IF('Balance Sheet'!C15<=0,"n/a",'Balance Sheet'!C11/'Balance Sheet'!C15) -> 0.18268657 | D14: =IF('Balance Sheet'!D15<=0,"n/a",'Balance Sheet'!D11/'Balance Sheet'!D15) -> 0.094166345
A15: Return on assets (net income ÷ year-end assets) | B15: =IF('Balance Sheet'!B9<=0,"n/a",'P&L'!B26/'Balance Sheet'!B9) -> 0.46986223 | C15: =IF('Balance Sheet'!C9<=0,"n/a",'P&L'!C26/'Balance Sheet'!C9) -> 0.37834145 | D15: =IF('Balance Sheet'!D9<=0,"n/a",'P&L'!D26/'Balance Sheet'!D9) -> 0.32021708
