Workbook

Sheet Cover
B2: Fitness studio financial model (planning)
B3: 3-year financial model · monthly detail · Low / Base / High scenarios · US dollars · Full plan
B5: Purpose | D5: Revenue and profit plan
B6: Active scenario | D6: =Dashboard!C4&" (change it on the Dashboard, cell B4)" -> Base (change it on the Dashboard, cell B4)
B7: Model checks | D7: =Checks!B25 -> PASS
B8: Prepared | D8: 22 October 2026
B10: Contents
C11: PRESENTATION
B12: 1 | C12: =HYPERLINK("#Dashboard!A1","Dashboard") -> Dashboard | D12: Scenario switch, key numbers, core financials
B13: 2 | C13: =HYPERLINK("#Summary!A1","Summary") -> Summary | D13: Income statement, cash flow and balance sheet — every year and any year by month
B14: 3 | C14: =HYPERLINK("#Scenarios!A1","Scenarios") -> Scenarios | D14: Low / Base / High side by side: drivers, outputs, charts
B15: 4 | C15: =HYPERLINK("#'Break-even'!A1","Break-even") -> Break-even | D15: Startup costs, funding need, break-even timing and revenue
B16: 5 | C16: =HYPERLINK("#Valuation!A1","Valuation") -> Valuation | D16: Free cash flow, DCF (perpetual growth and exit multiple), WACC × growth sensitivity
B17: 6 | C17: =HYPERLINK("#'Sources & Uses'!A1","Sources & Uses") -> Sources & Uses | D17: Funding structure, sources and uses of cash for the first months
B18: 7 | C18: =HYPERLINK("#KPIs!A1","KPIs") -> KPIs | D18: Financial ratios, DuPont analysis, industry metrics
C19: INPUTS
B20: 8 | C20: =HYPERLINK("#Inputs!A1","Inputs") -> Inputs | D20: Every assumption, Low / Base / High, with units and comments
C21: STATEMENTS
B22: 9 | C22: =HYPERLINK("#'P&L'!A1","P&L") -> P&L | D22: Annual profit & loss
B23: 10 | C23: =HYPERLINK("#'Cash Flow'!A1","Cash Flow") -> Cash Flow | D23: Annual cash flow statement
B24: 11 | C24: =HYPERLINK("#'Balance Sheet'!A1","Balance Sheet") -> Balance Sheet | D24: Balance sheet at year end
C25: CALCULATIONS
B26: 12 | C26: =HYPERLINK("#Monthly!A1","Monthly") -> Monthly | D26: Month-by-month engine of the model
B27: 13 | C27: =HYPERLINK("#Headcount!A1","Headcount") -> Headcount | D27: Team and payroll
B28: 14 | C28: =HYPERLINK("#'Scenario calc'!A1","Scenario calc") -> Scenario calc | D28: Low, Base and High calculated side by side for the Scenarios sheet
C29: CONTROL
B30: 15 | C30: =HYPERLINK("#Checks!A1","Checks") -> Checks | D30: Live integrity checks and the overall verdict
B32: How to read this file
C33: 1000 | D33: Input you can change — yellow cell with a blue figure (Inputs sheet and the view switches)
C34: 1000 | D34: Formula — calculated, do not overwrite
C35: 1000 | D35: Link to another sheet
C36: 1000 | D36: Active value the model uses (follows the scenario)

Sheet Dashboard
A1: Dashboard | W1: =HYPERLINK("#'Cover'!A1","◂ Contents") -> ◂ Contents
A2: Fitness studio financial model (planning)
A4: Active scenario | B4: 2 | C4: =CHOOSE(B4,"Low","Base","High") -> Base | D4: 1 = Low · 2 = Base · 3 = High — every sheet follows this cell | S4: Model checks | T4: =Checks!B25 -> PASS
A6: REVENUE · YEAR 3 | C6: EBITDA MARGIN · YEAR 3 | H6: NET INCOME · YEAR 3 | L6: LOWEST CASH BALANCE | P6: FUNDING REQUIRED | T6: ENTERPRISE VALUE (DCF)
A7: =D12 -> 722638.4 | C7: =D17 -> 0.11067489 | H7: =D18 -> 36406.5 | L7: =F38 -> 7440.3636 | P7: =F36 -> 583559.64 | T7: =F43 -> -109106.8
A8: =IF(AND(B12>0,D12>=0),(D12/B12)^(1/2)-1,"CAGR n/a") -> 0.35588405 | C8: =D16 -> 79977.928 | H8: =D19 -> 0.050379968 | L8: ='Break-even'!B6 -> 16 | P8: =IF(F37>=0,"Covered by funding raised",-F37) -> 103559.64 | T8: Average of 2 methods
A10: Core financials ($'000) — active scenario
B11: 1 | C11: 2 | D11: 3
A12: Revenue | B12: =SUMIF(Monthly!$C$5:$AL$5,B$11,Monthly!$C$24:$AL$24) -> 393075.46 | C12: =SUMIF(Monthly!$C$5:$AL$5,C$11,Monthly!$C$24:$AL$24) -> 663933.88 | D12: =SUMIF(Monthly!$C$5:$AL$5,D$11,Monthly!$C$24:$AL$24) -> 722638.4
A13: Gross profit | B13: =SUMIF(Monthly!$C$5:$AL$5,B$11,Monthly!$C$31:$AL$31) -> 262844.88 | C13: =SUMIF(Monthly!$C$5:$AL$5,C$11,Monthly!$C$31:$AL$31) -> 504280.12 | D13: =SUMIF(Monthly!$C$5:$AL$5,D$11,Monthly!$C$31:$AL$31) -> 554018.95
A14: Gross margin | B14: =IF(B12=0,0,B13/B12) -> 0.6686881 | C14: =IF(C12=0,0,C13/C12) -> 0.75953364 | D14: =IF(D12=0,0,D13/D12) -> 0.76666138
A15: Operating expenses | B15: =SUMIF(Monthly!$C$5:$AL$5,B$11,Monthly!$C$41:$AL$41) -> -445823.02 | C15: =SUMIF(Monthly!$C$5:$AL$5,C$11,Monthly!$C$41:$AL$41) -> -464040.36 | D15: =SUMIF(Monthly!$C$5:$AL$5,D$11,Monthly!$C$41:$AL$41) -> -474041.03
A16: EBITDA | B16: =SUMIF(Monthly!$C$5:$AL$5,B$11,Monthly!$C$42:$AL$42) -> -182978.13 | C16: =SUMIF(Monthly!$C$5:$AL$5,C$11,Monthly!$C$42:$AL$42) -> 40239.768 | D16: =SUMIF(Monthly!$C$5:$AL$5,D$11,Monthly!$C$42:$AL$42) -> 79977.928
A17: EBITDA margin | B17: =IF(B12=0,0,B16/B12) -> -0.46550384 | C17: =IF(C12=0,0,C16/C12) -> 0.060608094 | D17: =IF(D12=0,0,D16/D12) -> 0.11067489
A18: Net income | B18: =SUMIF(Monthly!$C$5:$AL$5,B$11,Monthly!$C$51:$AL$51) -> -229972.18 | C18: =SUMIF(Monthly!$C$5:$AL$5,C$11,Monthly!$C$51:$AL$51) -> -5045.9468 | D18: =SUMIF(Monthly!$C$5:$AL$5,D$11,Monthly!$C$51:$AL$51) -> 36406.5
A19: Net margin | B19: =IF(B12=0,0,B18/B12) -> -0.58505861 | C19: =IF(C12=0,0,C18/C12) -> -0.0076000742 | D19: =IF(D12=0,0,D18/D12) -> 0.050379968
A20: Operating cash flow | B20: =SUMIF(Monthly!$C$5:$AL$5,B$11,Monthly!$C$75:$AL$75) -> -190250.26 | C20: =SUMIF(Monthly!$C$5:$AL$5,C$11,Monthly!$C$75:$AL$75) -> 31208.152 | D20: =SUMIF(Monthly!$C$5:$AL$5,D$11,Monthly!$C$75:$AL$75) -> 72257.209
A21: Investing cash flow | B21: =SUMIF(Monthly!$C$5:$AL$5,B$11,Monthly!$C$76:$AL$76) -> -250000 | C21: =SUMIF(Monthly!$C$5:$AL$5,C$11,Monthly!$C$76:$AL$76) -> 0 | D21: =SUMIF(Monthly!$C$5:$AL$5,D$11,Monthly!$C$76:$AL$76) -> 0
A22: Financing cash flow | B22: =SUMIF(Monthly!$C$5:$AL$5,B$11,Monthly!$C$78:$AL$78) -> 460357.14 | C22: =SUMIF(Monthly!$C$5:$AL$5,C$11,Monthly!$C$78:$AL$78) -> -21428.571 | D22: =SUMIF(Monthly!$C$5:$AL$5,D$11,Monthly!$C$78:$AL$78) -> -21428.571
A23: Net change in cash | B23: =SUMIF(Monthly!$C$5:$AL$5,B$11,Monthly!$C$79:$AL$79) -> 20106.884 | C23: =SUMIF(Monthly!$C$5:$AL$5,C$11,Monthly!$C$79:$AL$79) -> 9779.5808 | D23: =SUMIF(Monthly!$C$5:$AL$5,D$11,Monthly!$C$79:$AL$79) -> 50828.638
A24: Year-end cash | B24: =INDEX(Monthly!$C$81:$AL$81,B$11*12) -> 20106.884 | C24: =INDEX(Monthly!$C$81:$AL$81,C$11*12) -> 29886.464 | D24: =INDEX(Monthly!$C$81:$AL$81,D$11*12) -> 80715.102
A26: Membership metrics
B27: 1 | C27: 2 | D27: 3
A28: Members (year end) | B28: =KPIs!B29 -> 355.83586 | C28: =KPIs!C29 -> 450 | D28: =KPIs!D29 -> 450
A29: Capacity used (year end) | B29: =KPIs!B33 -> 0.79074635 | C29: =KPIs!C33 -> 1 | D29: =KPIs!D33 -> 1
A30: Membership fees per month (year end) | B30: =KPIs!B34 -> 35227.75 | C30: =KPIs!C34 -> 45886.5 | D30: =KPIs!D34 -> 47263.095
A31: Team (FTE, year end) | B31: =INDEX(Headcount!$C$10:$AL$10,B$27*12) -> 4 | C31: =INDEX(Headcount!$C$10:$AL$10,C$27*12) -> 4 | D31: =INDEX(Headcount!$C$10:$AL$10,D$27*12) -> 4
A33: Funding & valuation ($'000) — active scenario
A34: Equity raised | F34: =Inputs!$E$54 -> 330000
A35: Loan drawn | F35: =Inputs!$E$55 -> 150000
A36: Funding required (incl. cash buffer) | F36: ='Break-even'!B12 -> 583559.64
A37: Funding surplus / (shortfall) | F37: ='Break-even'!B17 -> -103559.64
A38: ="Lowest cash balance (month "&'Break-even'!B6&")" -> Lowest cash balance (month 16) | F38: ='Break-even'!B18 -> 7440.3636
A39: First month with positive EBITDA | F39: ='Break-even'!B21 -> 15
A40: Cash invested paid back | F40: ='Break-even'!B23 -> Not within horizon
A41: Enterprise value — perpetual growth | F41: =Valuation!B27 -> -101923.28
A42: Enterprise value — exit multiple | F42: =Valuation!C27 -> -116290.32
A43: Enterprise value — average | F43: =Valuation!B30 -> -109106.8

Sheet Summary
A1: Financial statements summary | U1: =HYPERLINK("#'Cover'!A1","◂ Contents") -> ◂ Contents
A2: Fitness studio financial model (planning) | P2: Select detailed year: | R2: 1
A5: Income statement ($'000) — by year | H5: ="Income statement ($'000) — Year "&$R$2&", by month" -> Income statement ($'000) — Year 1, by month
B6: 1 | C6: 2 | D6: 3 | H6: =INDEX(Monthly!$C$4:$AL$4,($R$2-1)*12+1) -> 1 | I6: =INDEX(Monthly!$C$4:$AL$4,($R$2-1)*12+2) -> 2 | J6: =INDEX(Monthly!$C$4:$AL$4,($R$2-1)*12+3) -> 3 | K6: =INDEX(Monthly!$C$4:$AL$4,($R$2-1)*12+4) -> 4 | L6: =INDEX(Monthly!$C$4:$AL$4,($R$2-1)*12+5) -> 5 | M6: =INDEX(Monthly!$C$4:$AL$4,($R$2-1)*12+6) -> 6 | N6: =INDEX(Monthly!$C$4:$AL$4,($R$2-1)*12+7) -> 7 | O6: =INDEX(Monthly!$C$4:$AL$4,($R$2-1)*12+8) -> 8 | P6: =INDEX(Monthly!$C$4:$AL$4,($R$2-1)*12+9) -> 9 | Q6: =INDEX(Monthly!$C$4:$AL$4,($R$2-1)*12+10) -> 10 | R6: =INDEX(Monthly!$C$4:$AL$4,($R$2-1)*12+11) -> 11 | S6: =INDEX(Monthly!$C$4:$AL$4,($R$2-1)*12+12) -> 12
A7: Revenue | B7: ='P&L'!B5 -> 393075.46 | C7: ='P&L'!C5 -> 663933.88 | D7: ='P&L'!D5 -> 722638.4 | H7: =INDEX(Monthly!$C$24:$AL$24,($R$2-1)*12+1) -> 18123 | I7: =INDEX(Monthly!$C$24:$AL$24,($R$2-1)*12+2) -> 21349.608 | J7: =INDEX(Monthly!$C$24:$AL$24,($R$2-1)*12+3) -> 24382.62 | K7: =INDEX(Monthly!$C$24:$AL$24,($R$2-1)*12+4) -> 27233.65 | L7: =INDEX(Monthly!$C$24:$AL$24,($R$2-1)*12+5) -> 29913.619 | M7: =INDEX(Monthly!$C$24:$AL$24,($R$2-1)*12+6) -> 32432.79 | N7: =INDEX(Monthly!$C$24:$AL$24,($R$2-1)*12+7) -> 34800.811 | O7: =INDEX(Monthly!$C$24:$AL$24,($R$2-1)*12+8) -> 37026.75 | P7: =INDEX(Monthly!$C$24:$AL$24,($R$2-1)*12+9) -> 39119.133 | Q7: =INDEX(Monthly!$C$24:$AL$24,($R$2-1)*12+10) -> 41085.973 | R7: =INDEX(Monthly!$C$24:$AL$24,($R$2-1)*12+11) -> 42934.803 | S7: =INDEX(Monthly!$C$24:$AL$24,($R$2-1)*12+12) -> 44672.703
A8: Cost of sales | B8: ='P&L'!B6 -> -130230.58 | C8: ='P&L'!C6 -> -159653.76 | D8: ='P&L'!D6 -> -168619.45 | H8: =INDEX(Monthly!$C$30:$AL$30,($R$2-1)*12+1) -> -9415.35 | I8: =INDEX(Monthly!$C$30:$AL$30,($R$2-1)*12+2) -> -9732.249 | J8: =INDEX(Monthly!$C$30:$AL$30,($R$2-1)*12+3) -> -10030.134 | K8: =INDEX(Monthly!$C$30:$AL$30,($R$2-1)*12+4) -> -10310.146 | L8: =INDEX(Monthly!$C$30:$AL$30,($R$2-1)*12+5) -> -10573.357 | M8: =INDEX(Monthly!$C$30:$AL$30,($R$2-1)*12+6) -> -10820.776 | N8: =INDEX(Monthly!$C$30:$AL$30,($R$2-1)*12+7) -> -11053.349 | O8: =INDEX(Monthly!$C$30:$AL$30,($R$2-1)*12+8) -> -11271.968 | P8: =INDEX(Monthly!$C$30:$AL$30,($R$2-1)*12+9) -> -11477.47 | Q8: =INDEX(Monthly!$C$30:$AL$30,($R$2-1)*12+10) -> -11670.642 | R8: =INDEX(Monthly!$C$30:$AL$30,($R$2-1)*12+11) -> -11852.223 | S8: =INDEX(Monthly!$C$30:$AL$30,($R$2-1)*12+12) -> -12022.91
A9: Gross profit | B9: ='P&L'!B7 -> 262844.88 | C9: ='P&L'!C7 -> 504280.12 | D9: ='P&L'!D7 -> 554018.95 | H9: =INDEX(Monthly!$C$31:$AL$31,($R$2-1)*12+1) -> 8707.65 | I9: =INDEX(Monthly!$C$31:$AL$31,($R$2-1)*12+2) -> 11617.359 | J9: =INDEX(Monthly!$C$31:$AL$31,($R$2-1)*12+3) -> 14352.485 | K9: =INDEX(Monthly!$C$31:$AL$31,($R$2-1)*12+4) -> 16923.504 | L9: =INDEX(Monthly!$C$31:$AL$31,($R$2-1)*12+5) -> 19340.262 | M9: =INDEX(Monthly!$C$31:$AL$31,($R$2-1)*12+6) -> 21612.014 | N9: =INDEX(Monthly!$C$31:$AL$31,($R$2-1)*12+7) -> 23747.461 | O9: =INDEX(Monthly!$C$31:$AL$31,($R$2-1)*12+8) -> 25754.782 | P9: =INDEX(Monthly!$C$31:$AL$31,($R$2-1)*12+9) -> 27641.663 | Q9: =INDEX(Monthly!$C$31:$AL$31,($R$2-1)*12+10) -> 29415.331 | R9: =INDEX(Monthly!$C$31:$AL$31,($R$2-1)*12+11) -> 31082.579 | S9: =INDEX(Monthly!$C$31:$AL$31,($R$2-1)*12+12) -> 32649.792
A10: Gross margin | B10: ='P&L'!B8 -> 0.6686881 | C10: ='P&L'!C8 -> 0.75953364 | D10: ='P&L'!D8 -> 0.76666138 | H10: =IF(H7=0,0,H9/H7) -> 0.48047509 | I10: =IF(I7=0,0,I9/I7) -> 0.54414859 | J10: =IF(J7=0,0,J9/J7) -> 0.58863591 | K10: =IF(K7=0,0,K9/K7) -> 0.62141887 | L10: =IF(L7=0,0,L9/L7) -> 0.64653701 | M10: =IF(M7=0,0,M9/M7) -> 0.66636309 | N10: =IF(N7=0,0,N9/N7) -> 0.68238242 | O10: =IF(O7=0,0,O9/O7) -> 0.6955723 | ... S10: =IF(S7=0,0,S9/S7) -> 0.73086674
A11: Total operating expenses | B11: ='P&L'!B16 -> -445823.02 | C11: ='P&L'!C16 -> -464040.36 | D11: ='P&L'!D16 -> -474041.03 | H11: =INDEX(Monthly!$C$41:$AL$41,($R$2-1)*12+1) -> -36566.587 | I11: =INDEX(Monthly!$C$41:$AL$41,($R$2-1)*12+2) -> -36695.651 | J11: =INDEX(Monthly!$C$41:$AL$41,($R$2-1)*12+3) -> -36816.971 | K11: =INDEX(Monthly!$C$41:$AL$41,($R$2-1)*12+4) -> -36931.013 | L11: =INDEX(Monthly!$C$41:$AL$41,($R$2-1)*12+5) -> -37038.211 | M11: =INDEX(Monthly!$C$41:$AL$41,($R$2-1)*12+6) -> -37138.978 | N11: =INDEX(Monthly!$C$41:$AL$41,($R$2-1)*12+7) -> -37233.699 | O11: =INDEX(Monthly!$C$41:$AL$41,($R$2-1)*12+8) -> -37322.737 | P11: =INDEX(Monthly!$C$41:$AL$41,($R$2-1)*12+9) -> -37406.432 | Q11: =INDEX(Monthly!$C$41:$AL$41,($R$2-1)*12+10) -> -37485.106 | R11: =INDEX(Monthly!$C$41:$AL$41,($R$2-1)*12+11) -> -37559.059 | S11: =INDEX(Monthly!$C$41:$AL$41,($R$2-1)*12+12) -> -37628.575
A12: EBITDA | B12: ='P&L'!B17 -> -182978.13 | C12: ='P&L'!C17 -> 40239.768 | D12: ='P&L'!D17 -> 79977.928 | H12: =INDEX(Monthly!$C$42:$AL$42,($R$2-1)*12+1) -> -27858.937 | I12: =INDEX(Monthly!$C$42:$AL$42,($R$2-1)*12+2) -> -25078.292 | J12: =INDEX(Monthly!$C$42:$AL$42,($R$2-1)*12+3) -> -22464.486 | K12: =INDEX(Monthly!$C$42:$AL$42,($R$2-1)*12+4) -> -20007.508 | L12: =INDEX(Monthly!$C$42:$AL$42,($R$2-1)*12+5) -> -17697.949 | M12: =INDEX(Monthly!$C$42:$AL$42,($R$2-1)*12+6) -> -15526.964 | N12: =INDEX(Monthly!$C$42:$AL$42,($R$2-1)*12+7) -> -13486.238 | O12: =INDEX(Monthly!$C$42:$AL$42,($R$2-1)*12+8) -> -11567.955 | P12: =INDEX(Monthly!$C$42:$AL$42,($R$2-1)*12+9) -> -9764.7691 | Q12: =INDEX(Monthly!$C$42:$AL$42,($R$2-1)*12+10) -> -8069.7745 | R12: =INDEX(Monthly!$C$42:$AL$42,($R$2-1)*12+11) -> -6476.4795 | S12: =INDEX(Monthly!$C$42:$AL$42,($R$2-1)*12+12) -> -4978.7823
A13: EBITDA margin | B13: ='P&L'!B18 -> -0.46550384 | C13: ='P&L'!C18 -> 0.060608094 | D13: ='P&L'!D18 -> 0.11067489 | H13: =IF(H7=0,0,H12/H7) -> -1.5372144 | I13: =IF(I7=0,0,I12/I7) -> -1.1746488 | J13: =IF(J7=0,0,J12/J7) -> -0.92133193 | K13: =IF(K7=0,0,K12/K7) -> -0.73466128 | L13: =IF(L7=0,0,L12/L7) -> -0.59163517 | M13: =IF(M7=0,0,M12/M7) -> -0.47874277 | N13: =IF(N7=0,0,N12/N7) -> -0.38752654 | O13: =IF(O7=0,0,O12/O7) -> -0.31242156 | ... S13: =IF(S7=0,0,S12/S7) -> -0.11145021
A14: Depreciation | B14: ='P&L'!B19 -> -35714.286 | C14: ='P&L'!C19 -> -35714.286 | D14: ='P&L'!D19 -> -35714.286 | H14: =INDEX(Monthly!$C$56:$AL$56,($R$2-1)*12+1) -> -2976.1905 | I14: =INDEX(Monthly!$C$56:$AL$56,($R$2-1)*12+2) -> -2976.1905 | J14: =INDEX(Monthly!$C$56:$AL$56,($R$2-1)*12+3) -> -2976.1905 | K14: =INDEX(Monthly!$C$56:$AL$56,($R$2-1)*12+4) -> -2976.1905 | L14: =INDEX(Monthly!$C$56:$AL$56,($R$2-1)*12+5) -> -2976.1905 | M14: =INDEX(Monthly!$C$56:$AL$56,($R$2-1)*12+6) -> -2976.1905 | N14: =INDEX(Monthly!$C$56:$AL$56,($R$2-1)*12+7) -> -2976.1905 | O14: =INDEX(Monthly!$C$56:$AL$56,($R$2-1)*12+8) -> -2976.1905 | P14: =INDEX(Monthly!$C$56:$AL$56,($R$2-1)*12+9) -> -2976.1905 | Q14: =INDEX(Monthly!$C$56:$AL$56,($R$2-1)*12+10) -> -2976.1905 | R14: =INDEX(Monthly!$C$56:$AL$56,($R$2-1)*12+11) -> -2976.1905 | S14: =INDEX(Monthly!$C$56:$AL$56,($R$2-1)*12+12) -> -2976.1905
A15: EBIT | B15: ='P&L'!B20 -> -218692.42 | C15: ='P&L'!C20 -> 4525.4818 | D15: ='P&L'!D20 -> 44263.643 | H15: =INDEX(Monthly!$C$45:$AL$45,($R$2-1)*12+1) -> -30835.127 | I15: =INDEX(Monthly!$C$45:$AL$45,($R$2-1)*12+2) -> -28054.482 | J15: =INDEX(Monthly!$C$45:$AL$45,($R$2-1)*12+3) -> -25440.676 | K15: =INDEX(Monthly!$C$45:$AL$45,($R$2-1)*12+4) -> -22983.699 | L15: =INDEX(Monthly!$C$45:$AL$45,($R$2-1)*12+5) -> -20674.14 | M15: =INDEX(Monthly!$C$45:$AL$45,($R$2-1)*12+6) -> -18503.154 | N15: =INDEX(Monthly!$C$45:$AL$45,($R$2-1)*12+7) -> -16462.428 | O15: =INDEX(Monthly!$C$45:$AL$45,($R$2-1)*12+8) -> -14544.145 | P15: =INDEX(Monthly!$C$45:$AL$45,($R$2-1)*12+9) -> -12740.96 | Q15: =INDEX(Monthly!$C$45:$AL$45,($R$2-1)*12+10) -> -11045.965 | R15: =INDEX(Monthly!$C$45:$AL$45,($R$2-1)*12+11) -> -9452.67 | S15: =INDEX(Monthly!$C$45:$AL$45,($R$2-1)*12+12) -> -7954.9728
A16: Interest | B16: ='P&L'!B21 -> -11279.762 | C16: ='P&L'!C21 -> -9571.4286 | D16: ='P&L'!D21 -> -7857.1429 | H16: =INDEX(Monthly!$C$46:$AL$46,($R$2-1)*12+1) -> -1000 | I16: =INDEX(Monthly!$C$46:$AL$46,($R$2-1)*12+2) -> -994.04762 | J16: =INDEX(Monthly!$C$46:$AL$46,($R$2-1)*12+3) -> -982.14286 | K16: =INDEX(Monthly!$C$46:$AL$46,($R$2-1)*12+4) -> -970.2381 | L16: =INDEX(Monthly!$C$46:$AL$46,($R$2-1)*12+5) -> -958.33333 | M16: =INDEX(Monthly!$C$46:$AL$46,($R$2-1)*12+6) -> -946.42857 | N16: =INDEX(Monthly!$C$46:$AL$46,($R$2-1)*12+7) -> -934.52381 | O16: =INDEX(Monthly!$C$46:$AL$46,($R$2-1)*12+8) -> -922.61905 | P16: =INDEX(Monthly!$C$46:$AL$46,($R$2-1)*12+9) -> -910.71429 | Q16: =INDEX(Monthly!$C$46:$AL$46,($R$2-1)*12+10) -> -898.80952 | R16: =INDEX(Monthly!$C$46:$AL$46,($R$2-1)*12+11) -> -886.90476 | S16: =INDEX(Monthly!$C$46:$AL$46,($R$2-1)*12+12) -> -875
A17: Pre-tax income | B17: ='P&L'!B22 -> -229972.18 | C17: ='P&L'!C22 -> -5045.9468 | D17: ='P&L'!D22 -> 36406.5 | H17: =INDEX(Monthly!$C$47:$AL$47,($R$2-1)*12+1) -> -31835.127 | I17: =INDEX(Monthly!$C$47:$AL$47,($R$2-1)*12+2) -> -29048.53 | J17: =INDEX(Monthly!$C$47:$AL$47,($R$2-1)*12+3) -> -26422.819 | K17: =INDEX(Monthly!$C$47:$AL$47,($R$2-1)*12+4) -> -23953.937 | L17: =INDEX(Monthly!$C$47:$AL$47,($R$2-1)*12+5) -> -21632.473 | M17: =INDEX(Monthly!$C$47:$AL$47,($R$2-1)*12+6) -> -19449.583 | N17: =INDEX(Monthly!$C$47:$AL$47,($R$2-1)*12+7) -> -17396.952 | O17: =INDEX(Monthly!$C$47:$AL$47,($R$2-1)*12+8) -> -15466.764 | P17: =INDEX(Monthly!$C$47:$AL$47,($R$2-1)*12+9) -> -13651.674 | Q17: =INDEX(Monthly!$C$47:$AL$47,($R$2-1)*12+10) -> -11944.774 | R17: =INDEX(Monthly!$C$47:$AL$47,($R$2-1)*12+11) -> -10339.575 | S17: =INDEX(Monthly!$C$47:$AL$47,($R$2-1)*12+12) -> -8829.9728
A18: Income tax | B18: ='P&L'!B23 -> 0 | C18: ='P&L'!C23 -> 0 | D18: ='P&L'!D23 -> 0 | H18: =INDEX(Monthly!$C$50:$AL$50,($R$2-1)*12+1) -> 0 | I18: =INDEX(Monthly!$C$50:$AL$50,($R$2-1)*12+2) -> 0 | J18: =INDEX(Monthly!$C$50:$AL$50,($R$2-1)*12+3) -> 0 | K18: =INDEX(Monthly!$C$50:$AL$50,($R$2-1)*12+4) -> 0 | L18: =INDEX(Monthly!$C$50:$AL$50,($R$2-1)*12+5) -> 0 | M18: =INDEX(Monthly!$C$50:$AL$50,($R$2-1)*12+6) -> 0 | N18: =INDEX(Monthly!$C$50:$AL$50,($R$2-1)*12+7) -> 0 | O18: =INDEX(Monthly!$C$50:$AL$50,($R$2-1)*12+8) -> 0 | P18: =INDEX(Monthly!$C$50:$AL$50,($R$2-1)*12+9) -> 0 | Q18: =INDEX(Monthly!$C$50:$AL$50,($R$2-1)*12+10) -> 0 | R18: =INDEX(Monthly!$C$50:$AL$50,($R$2-1)*12+11) -> 0 | S18: =INDEX(Monthly!$C$50:$AL$50,($R$2-1)*12+12) -> 0
A19: Net income | B19: ='P&L'!B24 -> -229972.18 | C19: ='P&L'!C24 -> -5045.9468 | D19: ='P&L'!D24 -> 36406.5 | H19: =INDEX(Monthly!$C$51:$AL$51,($R$2-1)*12+1) -> -31835.127 | I19: =INDEX(Monthly!$C$51:$AL$51,($R$2-1)*12+2) -> -29048.53 | J19: =INDEX(Monthly!$C$51:$AL$51,($R$2-1)*12+3) -> -26422.819 | K19: =INDEX(Monthly!$C$51:$AL$51,($R$2-1)*12+4) -> -23953.937 | L19: =INDEX(Monthly!$C$51:$AL$51,($R$2-1)*12+5) -> -21632.473 | M19: =INDEX(Monthly!$C$51:$AL$51,($R$2-1)*12+6) -> -19449.583 | N19: =INDEX(Monthly!$C$51:$AL$51,($R$2-1)*12+7) -> -17396.952 | O19: =INDEX(Monthly!$C$51:$AL$51,($R$2-1)*12+8) -> -15466.764 | P19: =INDEX(Monthly!$C$51:$AL$51,($R$2-1)*12+9) -> -13651.674 | Q19: =INDEX(Monthly!$C$51:$AL$51,($R$2-1)*12+10) -> -11944.774 | R19: =INDEX(Monthly!$C$51:$AL$51,($R$2-1)*12+11) -> -10339.575 | S19: =INDEX(Monthly!$C$51:$AL$51,($R$2-1)*12+12) -> -8829.9728
A20: Net margin | B20: ='P&L'!B25 -> -0.58505861 | C20: ='P&L'!C25 -> -0.0076000742 | D20: ='P&L'!D25 -> 0.050379968 | H20: =IF(H7=0,0,H19/H7) -> -1.7566146 | I20: =IF(I7=0,0,I19/I7) -> -1.3606119 | J20: =IF(J7=0,0,J19/J7) -> -1.0836743 | K20: =IF(K7=0,0,K19/K7) -> -0.87957129 | L20: =IF(L7=0,0,L19/L7) -> -0.72316469 | M20: =IF(M7=0,0,M19/M7) -> -0.59968886 | N20: =IF(N7=0,0,N19/N7) -> -0.49990076 | O20: =IF(O7=0,0,O19/O7) -> -0.41771866 | ... S20: =IF(S7=0,0,S19/S7) -> -0.19765925
A22: Cash flow ($'000) — by year | H22: ="Cash flow ($'000) — Year "&$R$2&", by month" -> Cash flow ($'000) — Year 1, by month
B23: 1 | C23: 2 | D23: 3 | H23: =INDEX(Monthly!$C$4:$AL$4,($R$2-1)*12+1) -> 1 | I23: =INDEX(Monthly!$C$4:$AL$4,($R$2-1)*12+2) -> 2 | J23: =INDEX(Monthly!$C$4:$AL$4,($R$2-1)*12+3) -> 3 | K23: =INDEX(Monthly!$C$4:$AL$4,($R$2-1)*12+4) -> 4 | L23: =INDEX(Monthly!$C$4:$AL$4,($R$2-1)*12+5) -> 5 | M23: =INDEX(Monthly!$C$4:$AL$4,($R$2-1)*12+6) -> 6 | N23: =INDEX(Monthly!$C$4:$AL$4,($R$2-1)*12+7) -> 7 | O23: =INDEX(Monthly!$C$4:$AL$4,($R$2-1)*12+8) -> 8 | P23: =INDEX(Monthly!$C$4:$AL$4,($R$2-1)*12+9) -> 9 | Q23: =INDEX(Monthly!$C$4:$AL$4,($R$2-1)*12+10) -> 10 | R23: =INDEX(Monthly!$C$4:$AL$4,($R$2-1)*12+11) -> 11 | S23: =INDEX(Monthly!$C$4:$AL$4,($R$2-1)*12+12) -> 12
A24: Operating cash flow | B24: ='Cash Flow'!B10 -> -190250.26 | C24: ='Cash Flow'!C10 -> 31208.152 | D24: ='Cash Flow'!D10 -> 72257.209 | H24: =INDEX(Monthly!$C$75:$AL$75,($R$2-1)*12+1) -> -25720.487 | I24: =INDEX(Monthly!$C$75:$AL$75,($R$2-1)*12+2) -> -25966.707 | J24: =INDEX(Monthly!$C$75:$AL$75,($R$2-1)*12+3) -> -23347.334 | K24: =INDEX(Monthly!$C$75:$AL$75,($R$2-1)*12+4) -> -20884.409 | L24: =INDEX(Monthly!$C$75:$AL$75,($R$2-1)*12+5) -> -18568.546 | M24: =INDEX(Monthly!$C$75:$AL$75,($R$2-1)*12+6) -> -16390.92 | N24: =INDEX(Monthly!$C$75:$AL$75,($R$2-1)*12+7) -> -14343.237 | O24: =INDEX(Monthly!$C$75:$AL$75,($R$2-1)*12+8) -> -12417.701 | P24: =INDEX(Monthly!$C$75:$AL$75,($R$2-1)*12+9) -> -10606.983 | Q24: =INDEX(Monthly!$C$75:$AL$75,($R$2-1)*12+10) -> -8904.1934 | R24: =INDEX(Monthly!$C$75:$AL$75,($R$2-1)*12+11) -> -7302.8571 | S24: =INDEX(Monthly!$C$75:$AL$75,($R$2-1)*12+12) -> -5796.8867
A25: Capital spending | B25: ='Cash Flow'!B11 -> -250000 | C25: ='Cash Flow'!C11 -> 0 | D25: ='Cash Flow'!D11 -> 0 | H25: =INDEX(Monthly!$C$76:$AL$76,($R$2-1)*12+1) -> -250000 | I25: =INDEX(Monthly!$C$76:$AL$76,($R$2-1)*12+2) -> 0 | J25: =INDEX(Monthly!$C$76:$AL$76,($R$2-1)*12+3) -> 0 | K25: =INDEX(Monthly!$C$76:$AL$76,($R$2-1)*12+4) -> 0 | L25: =INDEX(Monthly!$C$76:$AL$76,($R$2-1)*12+5) -> 0 | M25: =INDEX(Monthly!$C$76:$AL$76,($R$2-1)*12+6) -> 0 | N25: =INDEX(Monthly!$C$76:$AL$76,($R$2-1)*12+7) -> 0 | O25: =INDEX(Monthly!$C$76:$AL$76,($R$2-1)*12+8) -> 0 | P25: =INDEX(Monthly!$C$76:$AL$76,($R$2-1)*12+9) -> 0 | Q25: =INDEX(Monthly!$C$76:$AL$76,($R$2-1)*12+10) -> 0 | R25: =INDEX(Monthly!$C$76:$AL$76,($R$2-1)*12+11) -> 0 | S25: =INDEX(Monthly!$C$76:$AL$76,($R$2-1)*12+12) -> 0
A26: Equity raised | B26: ='Cash Flow'!B12 -> 330000 | C26: ='Cash Flow'!C12 -> 0 | D26: ='Cash Flow'!D12 -> 0 | H26: =INDEX(Monthly!$C$77:$AL$77,($R$2-1)*12+1) -> 330000 | I26: =INDEX(Monthly!$C$77:$AL$77,($R$2-1)*12+2) -> 0 | J26: =INDEX(Monthly!$C$77:$AL$77,($R$2-1)*12+3) -> 0 | K26: =INDEX(Monthly!$C$77:$AL$77,($R$2-1)*12+4) -> 0 | L26: =INDEX(Monthly!$C$77:$AL$77,($R$2-1)*12+5) -> 0 | M26: =INDEX(Monthly!$C$77:$AL$77,($R$2-1)*12+6) -> 0 | N26: =INDEX(Monthly!$C$77:$AL$77,($R$2-1)*12+7) -> 0 | O26: =INDEX(Monthly!$C$77:$AL$77,($R$2-1)*12+8) -> 0 | P26: =INDEX(Monthly!$C$77:$AL$77,($R$2-1)*12+9) -> 0 | Q26: =INDEX(Monthly!$C$77:$AL$77,($R$2-1)*12+10) -> 0 | R26: =INDEX(Monthly!$C$77:$AL$77,($R$2-1)*12+11) -> 0 | S26: =INDEX(Monthly!$C$77:$AL$77,($R$2-1)*12+12) -> 0
A27: Loan drawdown | B27: ='Cash Flow'!B13 -> 150000 | C27: ='Cash Flow'!C13 -> 0 | D27: ='Cash Flow'!D13 -> 0 | H27: =INDEX(Monthly!$C$62:$AL$62,($R$2-1)*12+1) -> 150000 | I27: =INDEX(Monthly!$C$62:$AL$62,($R$2-1)*12+2) -> 0 | J27: =INDEX(Monthly!$C$62:$AL$62,($R$2-1)*12+3) -> 0 | K27: =INDEX(Monthly!$C$62:$AL$62,($R$2-1)*12+4) -> 0 | L27: =INDEX(Monthly!$C$62:$AL$62,($R$2-1)*12+5) -> 0 | M27: =INDEX(Monthly!$C$62:$AL$62,($R$2-1)*12+6) -> 0 | N27: =INDEX(Monthly!$C$62:$AL$62,($R$2-1)*12+7) -> 0 | O27: =INDEX(Monthly!$C$62:$AL$62,($R$2-1)*12+8) -> 0 | P27: =INDEX(Monthly!$C$62:$AL$62,($R$2-1)*12+9) -> 0 | Q27: =INDEX(Monthly!$C$62:$AL$62,($R$2-1)*12+10) -> 0 | R27: =INDEX(Monthly!$C$62:$AL$62,($R$2-1)*12+11) -> 0 | S27: =INDEX(Monthly!$C$62:$AL$62,($R$2-1)*12+12) -> 0
A28: Loan repayment | B28: ='Cash Flow'!B14 -> -19642.857 | C28: ='Cash Flow'!C14 -> -21428.571 | D28: ='Cash Flow'!D14 -> -21428.571 | H28: =INDEX(Monthly!$C$63:$AL$63,($R$2-1)*12+1) -> 0 | I28: =INDEX(Monthly!$C$63:$AL$63,($R$2-1)*12+2) -> -1785.7143 | J28: =INDEX(Monthly!$C$63:$AL$63,($R$2-1)*12+3) -> -1785.7143 | K28: =INDEX(Monthly!$C$63:$AL$63,($R$2-1)*12+4) -> -1785.7143 | L28: =INDEX(Monthly!$C$63:$AL$63,($R$2-1)*12+5) -> -1785.7143 | M28: =INDEX(Monthly!$C$63:$AL$63,($R$2-1)*12+6) -> -1785.7143 | N28: =INDEX(Monthly!$C$63:$AL$63,($R$2-1)*12+7) -> -1785.7143 | O28: =INDEX(Monthly!$C$63:$AL$63,($R$2-1)*12+8) -> -1785.7143 | P28: =INDEX(Monthly!$C$63:$AL$63,($R$2-1)*12+9) -> -1785.7143 | Q28: =INDEX(Monthly!$C$63:$AL$63,($R$2-1)*12+10) -> -1785.7143 | R28: =INDEX(Monthly!$C$63:$AL$63,($R$2-1)*12+11) -> -1785.7143 | S28: =INDEX(Monthly!$C$63:$AL$63,($R$2-1)*12+12) -> -1785.7143
A29: Financing cash flow | B29: ='Cash Flow'!B15 -> 460357.14 | C29: ='Cash Flow'!C15 -> -21428.571 | D29: ='Cash Flow'!D15 -> -21428.571 | H29: =INDEX(Monthly!$C$78:$AL$78,($R$2-1)*12+1) -> 480000 | I29: =INDEX(Monthly!$C$78:$AL$78,($R$2-1)*12+2) -> -1785.7143 | J29: =INDEX(Monthly!$C$78:$AL$78,($R$2-1)*12+3) -> -1785.7143 | K29: =INDEX(Monthly!$C$78:$AL$78,($R$2-1)*12+4) -> -1785.7143 | L29: =INDEX(Monthly!$C$78:$AL$78,($R$2-1)*12+5) -> -1785.7143 | M29: =INDEX(Monthly!$C$78:$AL$78,($R$2-1)*12+6) -> -1785.7143 | N29: =INDEX(Monthly!$C$78:$AL$78,($R$2-1)*12+7) -> -1785.7143 | O29: =INDEX(Monthly!$C$78:$AL$78,($R$2-1)*12+8) -> -1785.7143 | P29: =INDEX(Monthly!$C$78:$AL$78,($R$2-1)*12+9) -> -1785.7143 | Q29: =INDEX(Monthly!$C$78:$AL$78,($R$2-1)*12+10) -> -1785.7143 | R29: =INDEX(Monthly!$C$78:$AL$78,($R$2-1)*12+11) -> -1785.7143 | S29: =INDEX(Monthly!$C$78:$AL$78,($R$2-1)*12+12) -> -1785.7143
A30: Net change in cash | B30: ='Cash Flow'!B16 -> 20106.884 | C30: ='Cash Flow'!C16 -> 9779.5808 | D30: ='Cash Flow'!D16 -> 50828.638 | H30: =INDEX(Monthly!$C$79:$AL$79,($R$2-1)*12+1) -> 204279.51 | I30: =INDEX(Monthly!$C$79:$AL$79,($R$2-1)*12+2) -> -27752.421 | J30: =INDEX(Monthly!$C$79:$AL$79,($R$2-1)*12+3) -> -25133.048 | K30: =INDEX(Monthly!$C$79:$AL$79,($R$2-1)*12+4) -> -22670.123 | L30: =INDEX(Monthly!$C$79:$AL$79,($R$2-1)*12+5) -> -20354.26 | M30: =INDEX(Monthly!$C$79:$AL$79,($R$2-1)*12+6) -> -18176.634 | N30: =INDEX(Monthly!$C$79:$AL$79,($R$2-1)*12+7) -> -16128.951 | O30: =INDEX(Monthly!$C$79:$AL$79,($R$2-1)*12+8) -> -14203.415 | P30: =INDEX(Monthly!$C$79:$AL$79,($R$2-1)*12+9) -> -12392.697 | Q30: =INDEX(Monthly!$C$79:$AL$79,($R$2-1)*12+10) -> -10689.908 | R30: =INDEX(Monthly!$C$79:$AL$79,($R$2-1)*12+11) -> -9088.5714 | S30: =INDEX(Monthly!$C$79:$AL$79,($R$2-1)*12+12) -> -7582.601
A31: Closing cash | B31: ='Cash Flow'!B18 -> 20106.884 | C31: ='Cash Flow'!C18 -> 29886.464 | D31: ='Cash Flow'!D18 -> 80715.102 | H31: =INDEX(Monthly!$C$81:$AL$81,($R$2-1)*12+1) -> 204279.51 | I31: =INDEX(Monthly!$C$81:$AL$81,($R$2-1)*12+2) -> 176527.09 | J31: =INDEX(Monthly!$C$81:$AL$81,($R$2-1)*12+3) -> 151394.04 | K31: =INDEX(Monthly!$C$81:$AL$81,($R$2-1)*12+4) -> 128723.92 | L31: =INDEX(Monthly!$C$81:$AL$81,($R$2-1)*12+5) -> 108369.66 | M31: =INDEX(Monthly!$C$81:$AL$81,($R$2-1)*12+6) -> 90193.027 | N31: =INDEX(Monthly!$C$81:$AL$81,($R$2-1)*12+7) -> 74064.076 | O31: =INDEX(Monthly!$C$81:$AL$81,($R$2-1)*12+8) -> 59860.661 | P31: =INDEX(Monthly!$C$81:$AL$81,($R$2-1)*12+9) -> 47467.964 | Q31: =INDEX(Monthly!$C$81:$AL$81,($R$2-1)*12+10) -> 36778.056 | R31: =INDEX(Monthly!$C$81:$AL$81,($R$2-1)*12+11) -> 27689.485 | S31: =INDEX(Monthly!$C$81:$AL$81,($R$2-1)*12+12) -> 20106.884
A39: Balance sheet at year end ($'000) | H39: ="Balance sheet at month end ($'000) — Year "&$R$2 -> Balance sheet at month end ($'000) — Year 1
B40: 1 | C40: 2 | D40: 3 | H40: =INDEX(Monthly!$C$4:$AL$4,($R$2-1)*12+1) -> 1 | I40: =INDEX(Monthly!$C$4:$AL$4,($R$2-1)*12+2) -> 2 | J40: =INDEX(Monthly!$C$4:$AL$4,($R$2-1)*12+3) -> 3 | K40: =INDEX(Monthly!$C$4:$AL$4,($R$2-1)*12+4) -> 4 | L40: =INDEX(Monthly!$C$4:$AL$4,($R$2-1)*12+5) -> 5 | M40: =INDEX(Monthly!$C$4:$AL$4,($R$2-1)*12+6) -> 6 | N40: =INDEX(Monthly!$C$4:$AL$4,($R$2-1)*12+7) -> 7 | O40: =INDEX(Monthly!$C$4:$AL$4,($R$2-1)*12+8) -> 8 | P40: =INDEX(Monthly!$C$4:$AL$4,($R$2-1)*12+9) -> 9 | Q40: =INDEX(Monthly!$C$4:$AL$4,($R$2-1)*12+10) -> 10 | R40: =INDEX(Monthly!$C$4:$AL$4,($R$2-1)*12+11) -> 11 | S40: =INDEX(Monthly!$C$4:$AL$4,($R$2-1)*12+12) -> 12
A41: Cash | B41: ='Balance Sheet'!B5 -> 20106.884 | C41: ='Balance Sheet'!C5 -> 29886.464 | D41: ='Balance Sheet'!D5 -> 80715.102 | H41: =INDEX(Monthly!$C$81:$AL$81,($R$2-1)*12+1) -> 204279.51 | I41: =INDEX(Monthly!$C$81:$AL$81,($R$2-1)*12+2) -> 176527.09 | J41: =INDEX(Monthly!$C$81:$AL$81,($R$2-1)*12+3) -> 151394.04 | K41: =INDEX(Monthly!$C$81:$AL$81,($R$2-1)*12+4) -> 128723.92 | L41: =INDEX(Monthly!$C$81:$AL$81,($R$2-1)*12+5) -> 108369.66 | M41: =INDEX(Monthly!$C$81:$AL$81,($R$2-1)*12+6) -> 90193.027 | N41: =INDEX(Monthly!$C$81:$AL$81,($R$2-1)*12+7) -> 74064.076 | O41: =INDEX(Monthly!$C$81:$AL$81,($R$2-1)*12+8) -> 59860.661 | P41: =INDEX(Monthly!$C$81:$AL$81,($R$2-1)*12+9) -> 47467.964 | Q41: =INDEX(Monthly!$C$81:$AL$81,($R$2-1)*12+10) -> 36778.056 | R41: =INDEX(Monthly!$C$81:$AL$81,($R$2-1)*12+11) -> 27689.485 | S41: =INDEX(Monthly!$C$81:$AL$81,($R$2-1)*12+12) -> 20106.884
A42: Accounts receivable | B42: ='Balance Sheet'!B6 -> 0 | C42: ='Balance Sheet'!C6 -> 0 | D42: ='Balance Sheet'!D6 -> 0 | H42: =INDEX(Monthly!$C$67:$AL$67,($R$2-1)*12+1) -> 0 | I42: =INDEX(Monthly!$C$67:$AL$67,($R$2-1)*12+2) -> 0 | J42: =INDEX(Monthly!$C$67:$AL$67,($R$2-1)*12+3) -> 0 | K42: =INDEX(Monthly!$C$67:$AL$67,($R$2-1)*12+4) -> 0 | L42: =INDEX(Monthly!$C$67:$AL$67,($R$2-1)*12+5) -> 0 | M42: =INDEX(Monthly!$C$67:$AL$67,($R$2-1)*12+6) -> 0 | N42: =INDEX(Monthly!$C$67:$AL$67,($R$2-1)*12+7) -> 0 | O42: =INDEX(Monthly!$C$67:$AL$67,($R$2-1)*12+8) -> 0 | P42: =INDEX(Monthly!$C$67:$AL$67,($R$2-1)*12+9) -> 0 | Q42: =INDEX(Monthly!$C$67:$AL$67,($R$2-1)*12+10) -> 0 | R42: =INDEX(Monthly!$C$67:$AL$67,($R$2-1)*12+11) -> 0 | S42: =INDEX(Monthly!$C$67:$AL$67,($R$2-1)*12+12) -> 0
A43: Inventory | B43: ='Balance Sheet'!B7 -> 4007.6367 | C43: ='Balance Sheet'!C7 -> 4547.45 | D43: ='Balance Sheet'!D7 -> 4683.8735 | H43: =INDEX(Monthly!$C$68:$AL$68,($R$2-1)*12+1) -> 3138.45 | I43: =INDEX(Monthly!$C$68:$AL$68,($R$2-1)*12+2) -> 3244.083 | J43: =INDEX(Monthly!$C$68:$AL$68,($R$2-1)*12+3) -> 3343.378 | K43: =INDEX(Monthly!$C$68:$AL$68,($R$2-1)*12+4) -> 3436.7153 | L43: =INDEX(Monthly!$C$68:$AL$68,($R$2-1)*12+5) -> 3524.4524 | M43: =INDEX(Monthly!$C$68:$AL$68,($R$2-1)*12+6) -> 3606.9253 | N43: =INDEX(Monthly!$C$68:$AL$68,($R$2-1)*12+7) -> 3684.4498 | O43: =INDEX(Monthly!$C$68:$AL$68,($R$2-1)*12+8) -> 3757.3228 | P43: =INDEX(Monthly!$C$68:$AL$68,($R$2-1)*12+9) -> 3825.8234 | Q43: =INDEX(Monthly!$C$68:$AL$68,($R$2-1)*12+10) -> 3890.214 | R43: =INDEX(Monthly!$C$68:$AL$68,($R$2-1)*12+11) -> 3950.7412 | S43: =INDEX(Monthly!$C$68:$AL$68,($R$2-1)*12+12) -> 4007.6367
A44: Net fixed assets | B44: ='Balance Sheet'!B8 -> 214285.71 | C44: ='Balance Sheet'!C8 -> 178571.43 | D44: ='Balance Sheet'!D8 -> 142857.14 | H44: =INDEX(Monthly!$C$58:$AL$58,($R$2-1)*12+1) -> 247023.81 | I44: =INDEX(Monthly!$C$58:$AL$58,($R$2-1)*12+2) -> 244047.62 | J44: =INDEX(Monthly!$C$58:$AL$58,($R$2-1)*12+3) -> 241071.43 | K44: =INDEX(Monthly!$C$58:$AL$58,($R$2-1)*12+4) -> 238095.24 | L44: =INDEX(Monthly!$C$58:$AL$58,($R$2-1)*12+5) -> 235119.05 | M44: =INDEX(Monthly!$C$58:$AL$58,($R$2-1)*12+6) -> 232142.86 | N44: =INDEX(Monthly!$C$58:$AL$58,($R$2-1)*12+7) -> 229166.67 | O44: =INDEX(Monthly!$C$58:$AL$58,($R$2-1)*12+8) -> 226190.48 | P44: =INDEX(Monthly!$C$58:$AL$58,($R$2-1)*12+9) -> 223214.29 | Q44: =INDEX(Monthly!$C$58:$AL$58,($R$2-1)*12+10) -> 220238.1 | R44: =INDEX(Monthly!$C$58:$AL$58,($R$2-1)*12+11) -> 217261.9 | S44: =INDEX(Monthly!$C$58:$AL$58,($R$2-1)*12+12) -> 214285.71
A45: Total assets | B45: ='Balance Sheet'!B9 -> 238400.23 | C45: ='Balance Sheet'!C9 -> 213005.34 | D45: ='Balance Sheet'!D9 -> 228256.12 | H45: =INDEX(Monthly!$C$95:$AL$95,($R$2-1)*12+1) -> 454441.77 | I45: =INDEX(Monthly!$C$95:$AL$95,($R$2-1)*12+2) -> 423818.79 | J45: =INDEX(Monthly!$C$95:$AL$95,($R$2-1)*12+3) -> 395808.85 | K45: =INDEX(Monthly!$C$95:$AL$95,($R$2-1)*12+4) -> 370255.87 | L45: =INDEX(Monthly!$C$95:$AL$95,($R$2-1)*12+5) -> 347013.16 | M45: =INDEX(Monthly!$C$95:$AL$95,($R$2-1)*12+6) -> 325942.81 | N45: =INDEX(Monthly!$C$95:$AL$95,($R$2-1)*12+7) -> 306915.19 | O45: =INDEX(Monthly!$C$95:$AL$95,($R$2-1)*12+8) -> 289808.46 | P45: =INDEX(Monthly!$C$95:$AL$95,($R$2-1)*12+9) -> 274508.07 | Q45: =INDEX(Monthly!$C$95:$AL$95,($R$2-1)*12+10) -> 260906.37 | R45: =INDEX(Monthly!$C$95:$AL$95,($R$2-1)*12+11) -> 248902.13 | S45: =INDEX(Monthly!$C$95:$AL$95,($R$2-1)*12+12) -> 238400.23
A46: Accounts payable | B46: ='Balance Sheet'!B10 -> 8015.2734 | C46: ='Balance Sheet'!C10 -> 9094.9 | D46: ='Balance Sheet'!D10 -> 9367.747 | H46: =INDEX(Monthly!$C$69:$AL$69,($R$2-1)*12+1) -> 6276.9 | I46: =INDEX(Monthly!$C$69:$AL$69,($R$2-1)*12+2) -> 6488.166 | J46: =INDEX(Monthly!$C$69:$AL$69,($R$2-1)*12+3) -> 6686.756 | K46: =INDEX(Monthly!$C$69:$AL$69,($R$2-1)*12+4) -> 6873.4307 | L46: =INDEX(Monthly!$C$69:$AL$69,($R$2-1)*12+5) -> 7048.9048 | M46: =INDEX(Monthly!$C$69:$AL$69,($R$2-1)*12+6) -> 7213.8505 | N46: =INDEX(Monthly!$C$69:$AL$69,($R$2-1)*12+7) -> 7368.8995 | O46: =INDEX(Monthly!$C$69:$AL$69,($R$2-1)*12+8) -> 7514.6455 | P46: =INDEX(Monthly!$C$69:$AL$69,($R$2-1)*12+9) -> 7651.6468 | Q46: =INDEX(Monthly!$C$69:$AL$69,($R$2-1)*12+10) -> 7780.428 | R46: =INDEX(Monthly!$C$69:$AL$69,($R$2-1)*12+11) -> 7901.4823 | S46: =INDEX(Monthly!$C$69:$AL$69,($R$2-1)*12+12) -> 8015.2734
A47: Loan | B47: ='Balance Sheet'!B11 -> 130357.14 | C47: ='Balance Sheet'!C11 -> 108928.57 | D47: ='Balance Sheet'!D11 -> 87500 | H47: =INDEX(Monthly!$C$64:$AL$64,($R$2-1)*12+1) -> 150000 | I47: =INDEX(Monthly!$C$64:$AL$64,($R$2-1)*12+2) -> 148214.29 | J47: =INDEX(Monthly!$C$64:$AL$64,($R$2-1)*12+3) -> 146428.57 | K47: =INDEX(Monthly!$C$64:$AL$64,($R$2-1)*12+4) -> 144642.86 | L47: =INDEX(Monthly!$C$64:$AL$64,($R$2-1)*12+5) -> 142857.14 | M47: =INDEX(Monthly!$C$64:$AL$64,($R$2-1)*12+6) -> 141071.43 | N47: =INDEX(Monthly!$C$64:$AL$64,($R$2-1)*12+7) -> 139285.71 | O47: =INDEX(Monthly!$C$64:$AL$64,($R$2-1)*12+8) -> 137500 | P47: =INDEX(Monthly!$C$64:$AL$64,($R$2-1)*12+9) -> 135714.29 | Q47: =INDEX(Monthly!$C$64:$AL$64,($R$2-1)*12+10) -> 133928.57 | R47: =INDEX(Monthly!$C$64:$AL$64,($R$2-1)*12+11) -> 132142.86 | S47: =INDEX(Monthly!$C$64:$AL$64,($R$2-1)*12+12) -> 130357.14
A48: Total liabilities | B48: ='Balance Sheet'!B12 -> 138372.42 | C48: ='Balance Sheet'!C12 -> 118023.47 | D48: ='Balance Sheet'!D12 -> 96867.747 | H48: =INDEX(Monthly!$C$96:$AL$96,($R$2-1)*12+1) -> 156276.9 | I48: =INDEX(Monthly!$C$96:$AL$96,($R$2-1)*12+2) -> 154702.45 | J48: =INDEX(Monthly!$C$96:$AL$96,($R$2-1)*12+3) -> 153115.33 | K48: =INDEX(Monthly!$C$96:$AL$96,($R$2-1)*12+4) -> 151516.29 | L48: =INDEX(Monthly!$C$96:$AL$96,($R$2-1)*12+5) -> 149906.05 | M48: =INDEX(Monthly!$C$96:$AL$96,($R$2-1)*12+6) -> 148285.28 | N48: =INDEX(Monthly!$C$96:$AL$96,($R$2-1)*12+7) -> 146654.61 | O48: =INDEX(Monthly!$C$96:$AL$96,($R$2-1)*12+8) -> 145014.65 | P48: =INDEX(Monthly!$C$96:$AL$96,($R$2-1)*12+9) -> 143365.93 | Q48: =INDEX(Monthly!$C$96:$AL$96,($R$2-1)*12+10) -> 141709 | R48: =INDEX(Monthly!$C$96:$AL$96,($R$2-1)*12+11) -> 140044.34 | S48: =INDEX(Monthly!$C$96:$AL$96,($R$2-1)*12+12) -> 138372.42
A49: Paid-in capital | B49: ='Balance Sheet'!B13 -> 330000 | C49: ='Balance Sheet'!C13 -> 330000 | D49: ='Balance Sheet'!D13 -> 330000 | H49: =INDEX(Monthly!$C$93:$AL$93,($R$2-1)*12+1) -> 330000 | I49: =INDEX(Monthly!$C$93:$AL$93,($R$2-1)*12+2) -> 330000 | J49: =INDEX(Monthly!$C$93:$AL$93,($R$2-1)*12+3) -> 330000 | K49: =INDEX(Monthly!$C$93:$AL$93,($R$2-1)*12+4) -> 330000 | L49: =INDEX(Monthly!$C$93:$AL$93,($R$2-1)*12+5) -> 330000 | M49: =INDEX(Monthly!$C$93:$AL$93,($R$2-1)*12+6) -> 330000 | N49: =INDEX(Monthly!$C$93:$AL$93,($R$2-1)*12+7) -> 330000 | O49: =INDEX(Monthly!$C$93:$AL$93,($R$2-1)*12+8) -> 330000 | P49: =INDEX(Monthly!$C$93:$AL$93,($R$2-1)*12+9) -> 330000 | Q49: =INDEX(Monthly!$C$93:$AL$93,($R$2-1)*12+10) -> 330000 | R49: =INDEX(Monthly!$C$93:$AL$93,($R$2-1)*12+11) -> 330000 | S49: =INDEX(Monthly!$C$93:$AL$93,($R$2-1)*12+12) -> 330000
A50: Retained earnings | B50: ='Balance Sheet'!B14 -> -229972.18 | C50: ='Balance Sheet'!C14 -> -235018.13 | D50: ='Balance Sheet'!D14 -> -198611.63 | H50: =INDEX(Monthly!$C$94:$AL$94,($R$2-1)*12+1) -> -31835.127 | I50: =INDEX(Monthly!$C$94:$AL$94,($R$2-1)*12+2) -> -60883.657 | J50: =INDEX(Monthly!$C$94:$AL$94,($R$2-1)*12+3) -> -87306.477 | K50: =INDEX(Monthly!$C$94:$AL$94,($R$2-1)*12+4) -> -111260.41 | L50: =INDEX(Monthly!$C$94:$AL$94,($R$2-1)*12+5) -> -132892.89 | M50: =INDEX(Monthly!$C$94:$AL$94,($R$2-1)*12+6) -> -152342.47 | N50: =INDEX(Monthly!$C$94:$AL$94,($R$2-1)*12+7) -> -169739.42 | O50: =INDEX(Monthly!$C$94:$AL$94,($R$2-1)*12+8) -> -185206.19 | P50: =INDEX(Monthly!$C$94:$AL$94,($R$2-1)*12+9) -> -198857.86 | Q50: =INDEX(Monthly!$C$94:$AL$94,($R$2-1)*12+10) -> -210802.63 | R50: =INDEX(Monthly!$C$94:$AL$94,($R$2-1)*12+11) -> -221142.21 | S50: =INDEX(Monthly!$C$94:$AL$94,($R$2-1)*12+12) -> -229972.18
...

Sheet Scenarios
A1: Scenarios — Low / Base / High | H1: =HYPERLINK("#'Cover'!A1","◂ Contents") -> ◂ Contents
A2: All three scenarios calculated side by side, live: change any input and every column updates. Active = the scenario chosen on the Dashboard.
A5: Key drivers
A6: Driver | B6: Low | C6: Base | D6: High | E6: Active
A7: Members at start (presale or current base) (#) | B7: =Inputs!$B$7 -> 80 | C7: =Inputs!$C$7 -> 120 | D7: =Inputs!$D$7 -> 160 | E7: =Inputs!$E$7 -> 120
A8: Membership fee per month (year 1) ($) | B8: =Inputs!$B$18 -> 89 | C8: =Inputs!$C$18 -> 99 | D8: =Inputs!$D$18 -> 109 | E8: =Inputs!$E$18 -> 99
A9: Members who cancel per month (%) | B9: =Inputs!$B$15 -> 0.07 | C9: =Inputs!$C$15 -> 0.06 | D9: =Inputs!$D$15 -> 0.05 | E9: =Inputs!$E$15 -> 0.06
A10: Marketing budget per month (year 1) ($) | B10: =Inputs!$B$11 -> 4000 | C10: =Inputs!$C$11 -> 4000 | D10: =Inputs!$D$11 -> 4000 | E10: =Inputs!$E$11 -> 4000
A11: Capacity: most members the studio can hold (#) | B11: =Inputs!$B$8 -> 450 | C11: =Inputs!$C$8 -> 450 | D11: =Inputs!$D$8 -> 450 | E11: =Inputs!$E$8 -> 450
A12: Rent per month ($) | B12: =Inputs!$B$33 -> 12000 | C12: =Inputs!$C$33 -> 12000 | D12: =Inputs!$D$33 -> 12000 | E12: =Inputs!$E$33 -> 12000
A13: Equity raised at start ($) | B13: =Inputs!$B$54 -> 330000 | C13: =Inputs!$C$54 -> 330000 | D13: =Inputs!$D$54 -> 330000 | E13: =Inputs!$E$54 -> 330000
A15: Results by scenario ($'000)
A16: Output | B16: Low | C16: Base | D16: High | E16: Active
A17: Revenue — final year | B17: =D30 -> 515887.22 | C17: =D31 -> 722638.4 | D17: =D32 -> 822654.14 | E17: ='P&L'!D5 -> 722638.4
A18: Revenue — whole plan | B18: =SUM(B30:D30) -> 1201588.4 | C18: =SUM(B31:D31) -> 1779647.7 | D18: =SUM(B32:D32) -> 2184359.1 | E18: =SUM('P&L'!$B$5:$D$5) -> 1779647.7
A19: EBITDA — final year | B19: =D36 -> -106913.55 | C19: =D37 -> 79977.928 | D19: =D38 -> 178027.21 | E19: ='P&L'!D17 -> 79977.928
A20: EBITDA margin — final year | B20: =IF(B17=0,0,B19/B17) -> -0.2072421 | C20: =IF(C17=0,0,C19/C17) -> 0.11067489 | D20: =IF(D17=0,0,D19/D17) -> 0.2164059 | E20: =IF(E17=0,0,E19/E17) -> 0.11067489
A21: Net income — final year | B21: =D42 -> -150484.98 | C21: =D43 -> 36406.5 | D21: =D44 -> 106220.07 | E21: ='P&L'!D24 -> 36406.5
A22: Net income — whole plan | B22: =SUM(B42:D42) -> -728442.32 | C22: =SUM(B43:D43) -> -198611.63 | D22: =SUM(B44:D44) -> 150683.88 | E22: =SUM('P&L'!$B$24:$D$24) -> -198611.63
A23: Cash at the end of the plan | B23: =D48 -> -449313.79 | C23: =D49 -> 80715.102 | D23: =D50 -> 429925.03 | E23: ='Balance Sheet'!D5 -> 80715.102
A24: Lowest cash balance | B24: =MIN('Scenario calc'!$C$83:$AL$83) -> -449313.79 | C24: =MIN('Scenario calc'!$C$193:$AL$193) -> 7440.3636 | D24: =MIN('Scenario calc'!$C$303:$AL$303) -> 155942.75 | E24: ='Break-even'!B18 -> 7440.3636
A25: Lowest cash point (month #) | B25: =MATCH(MIN('Scenario calc'!$C$83:$AL$83),'Scenario calc'!$C$83:$AL$83,0) -> 36 | C25: =MATCH(MIN('Scenario calc'!$C$193:$AL$193),'Scenario calc'!$C$193:$AL$193,0) -> 16 | D25: =MATCH(MIN('Scenario calc'!$C$303:$AL$303),'Scenario calc'!$C$303:$AL$303,0) -> 7 | E25: ='Break-even'!B6 -> 16
A26: Funding required (incl. cash buffer) | B26: =SUMPRODUCT(--('Scenario calc'!$C$6:$AL$6<=B25),'Scenario calc'!$C$56:$AL$56)-SUMPRODUCT(--('Scenario calc'!$C$6:$AL$6<=B25),'Scenario calc'!$C$77:$AL$77)-SUMPRODUCT(--('Scenario calc'!$C$6:$AL$6<=B25),'Scenario calc'!$C$65:$AL$65)+Inputs!$B$69 -> 1040313.8 | C26: =SUMPRODUCT(--('Scenario calc'!$C$116:$AL$116<=C25),'Scenario calc'!$C$166:$AL$166)-SUMPRODUCT(--('Scenario calc'!$C$116:$AL$116<=C25),'Scenario calc'!$C$187:$AL$187)-SUMPRODUCT(--('Scenario calc'!$C$116:$AL$116<=C25),'Scenario calc'!$C$175:$AL$175)+Inputs!$C$69 -> 583559.64 | D26: =SUMPRODUCT(--('Scenario calc'!$C$226:$AL$226<=D25),'Scenario calc'!$C$276:$AL$276)-SUMPRODUCT(--('Scenario calc'!$C$226:$AL$226<=D25),'Scenario calc'!$C$297:$AL$297)-SUMPRODUCT(--('Scenario calc'!$C$226:$AL$226<=D25),'Scenario calc'!$C$285:$AL$285)+Inputs!$D$69 -> 435057.25 | E26: ='Break-even'!B12 -> 583559.64
A28: Revenue by year ($'000)
A29: Scenario | B29: 1 | C29: 2 | D29: 3
A30: Low | B30: =SUMIF('Scenario calc'!$C$7:$AL$7,B$29,'Scenario calc'!$C$26:$AL$26) -> 256826.28 | C30: =SUMIF('Scenario calc'!$C$7:$AL$7,C$29,'Scenario calc'!$C$26:$AL$26) -> 428874.85 | D30: =SUMIF('Scenario calc'!$C$7:$AL$7,D$29,'Scenario calc'!$C$26:$AL$26) -> 515887.22
A31: Base | B31: =SUMIF('Scenario calc'!$C$117:$AL$117,B$29,'Scenario calc'!$C$136:$AL$136) -> 393075.46 | C31: =SUMIF('Scenario calc'!$C$117:$AL$117,C$29,'Scenario calc'!$C$136:$AL$136) -> 663933.88 | D31: =SUMIF('Scenario calc'!$C$117:$AL$117,D$29,'Scenario calc'!$C$136:$AL$136) -> 722638.4
A32: High | B32: =SUMIF('Scenario calc'!$C$227:$AL$227,B$29,'Scenario calc'!$C$246:$AL$246) -> 570691.31 | C32: =SUMIF('Scenario calc'!$C$227:$AL$227,C$29,'Scenario calc'!$C$246:$AL$246) -> 791013.6 | D32: =SUMIF('Scenario calc'!$C$227:$AL$227,D$29,'Scenario calc'!$C$246:$AL$246) -> 822654.14
A34: EBITDA by year ($'000)
A35: Scenario | B35: 1 | C35: 2 | D35: 3
A36: Low | B36: =SUMIF('Scenario calc'!$C$7:$AL$7,B$35,'Scenario calc'!$C$44:$AL$44) -> -312506.71 | C36: =SUMIF('Scenario calc'!$C$7:$AL$7,C$35,'Scenario calc'!$C$44:$AL$44) -> -173170.87 | D36: =SUMIF('Scenario calc'!$C$7:$AL$7,D$35,'Scenario calc'!$C$44:$AL$44) -> -106913.55
A37: Base | B37: =SUMIF('Scenario calc'!$C$117:$AL$117,B$35,'Scenario calc'!$C$154:$AL$154) -> -182978.13 | C37: =SUMIF('Scenario calc'!$C$117:$AL$117,C$35,'Scenario calc'!$C$154:$AL$154) -> 40239.768 | D37: =SUMIF('Scenario calc'!$C$117:$AL$117,D$35,'Scenario calc'!$C$154:$AL$154) -> 79977.928
A38: High | B38: =SUMIF('Scenario calc'!$C$227:$AL$227,B$35,'Scenario calc'!$C$264:$AL$264) -> -14886.38 | C38: =SUMIF('Scenario calc'!$C$227:$AL$227,C$35,'Scenario calc'!$C$264:$AL$264) -> 163449.44 | D38: =SUMIF('Scenario calc'!$C$227:$AL$227,D$35,'Scenario calc'!$C$264:$AL$264) -> 178027.21
A40: Net income by year ($'000)
A41: Scenario | B41: 1 | C41: 2 | D41: 3
A42: Low | B42: =SUMIF('Scenario calc'!$C$7:$AL$7,B$41,'Scenario calc'!$C$53:$AL$53) -> -359500.76 | C42: =SUMIF('Scenario calc'!$C$7:$AL$7,C$41,'Scenario calc'!$C$53:$AL$53) -> -218456.58 | D42: =SUMIF('Scenario calc'!$C$7:$AL$7,D$41,'Scenario calc'!$C$53:$AL$53) -> -150484.98
A43: Base | B43: =SUMIF('Scenario calc'!$C$117:$AL$117,B$41,'Scenario calc'!$C$163:$AL$163) -> -229972.18 | C43: =SUMIF('Scenario calc'!$C$117:$AL$117,C$41,'Scenario calc'!$C$163:$AL$163) -> -5045.9468 | D43: =SUMIF('Scenario calc'!$C$117:$AL$117,D$41,'Scenario calc'!$C$163:$AL$163) -> 36406.5
A44: High | B44: =SUMIF('Scenario calc'!$C$227:$AL$227,B$41,'Scenario calc'!$C$273:$AL$273) -> -61880.427 | C44: =SUMIF('Scenario calc'!$C$227:$AL$227,C$41,'Scenario calc'!$C$273:$AL$273) -> 106344.24 | D44: =SUMIF('Scenario calc'!$C$227:$AL$227,D$41,'Scenario calc'!$C$273:$AL$273) -> 106220.07
A46: Cash at year end by year ($'000)
A47: Scenario | B47: 1 | C47: 2 | D47: 3
...

Sheet Break-even
A1: Startup costs, funding need and break-even | F1: =HYPERLINK("#'Cover'!A1","◂ Contents") -> ◂ Contents
A2: Live for the selected scenario. Periods are counted in months from the start of the plan.
A3: Scenario shown | B3: =CHOOSE(Dashboard!$B$4,"Low","Base","High") -> Base
A5: Startup costs & funding need (up to the lowest cash point)
A6: Lowest cash point (month #) | B6: =MATCH(MIN(Monthly!$C$81:$AL$81),Monthly!$C$81:$AL$81,0) -> 16
A7: Capital spending up to the lowest cash point | B7: =SUMPRODUCT(--(Monthly!$C$4:$AL$4<=$B$6),Monthly!$C$54:$AL$54) -> 250000
A8: Operating cash burn up to the lowest cash point | B8: =-SUMPRODUCT(--(Monthly!$C$4:$AL$4<=$B$6),Monthly!$C$75:$AL$75) -> 195773.92 | D8: Losses and working capital before the business funds itself
A9: Loan repayments up to the lowest cash point | B9: =-SUMPRODUCT(--(Monthly!$C$4:$AL$4<=$B$6),Monthly!$C$63:$AL$63) -> 26785.714
A10: Total uses of funds | B10: =B7+B8+B9 -> 472559.64
A11: Minimum cash buffer to keep | B11: =Inputs!$E$69 -> 111000 | D11: Input on the Inputs sheet
A12: Funding required (uses + buffer) | B12: =B10+B11 -> 583559.64
A14: Equity raised | B14: =Inputs!$E$54 -> 330000
A15: Loan drawn | B15: =Inputs!$E$55 -> 150000
A16: Total sources of funds | B16: =B14+B15 -> 480000
A17: Funding surplus / (shortfall) | B17: =B16-B12 -> -103559.64 | D17: Negative = raise at least this much more
A18: Lowest cash balance in the plan | B18: =MIN(Monthly!$C$81:$AL$81) -> 7440.3636 | D18: Equals sources minus uses
A20: Break-even timing
A21: First month with positive EBITDA (month #) | B21: =IFERROR(MATCH(1,Monthly!$C$82:$AL$82,0),"Not within horizon") -> 15
A22: First month with positive net income (month #) | B22: =IFERROR(MATCH(1,Monthly!$C$85:$AL$85,0),"Not within horizon") -> 18
A23: Cash invested paid back (month #) | B23: =IF(MIN(Monthly!$C$87:$AL$87)>=0,"No investment to pay back",IFERROR(MATCH(1,Monthly!$C$89:$AL$89,0),"Not within horizon")) -> Not within horizon | D23: Cumulative operating + investing cash flow back to zero
A25: Annual break-even revenue
A26: Year # | B26: 1 | C26: 2 | D26: 3
B27: Year 1 | C27: Year 2 | D27: Year 3
A28: Revenue | B28: =SUMIF(Monthly!$C$5:$AL$5,B$26,Monthly!$C$24:$AL$24) -> 393075.46 | C28: =SUMIF(Monthly!$C$5:$AL$5,C$26,Monthly!$C$24:$AL$24) -> 663933.88 | D28: =SUMIF(Monthly!$C$5:$AL$5,D$26,Monthly!$C$24:$AL$24) -> 722638.4
A29: Gross profit | B29: =SUMIF(Monthly!$C$5:$AL$5,B$26,Monthly!$C$31:$AL$31) -> 262844.88 | C29: =SUMIF(Monthly!$C$5:$AL$5,C$26,Monthly!$C$31:$AL$31) -> 504280.12 | D29: =SUMIF(Monthly!$C$5:$AL$5,D$26,Monthly!$C$31:$AL$31) -> 554018.95
A30: Gross margin (contribution) | B30: =IF(B28=0,0,B29/B28) -> 0.6686881 | C30: =IF(C28=0,0,C29/C28) -> 0.75953364 | D30: =IF(D28=0,0,D29/D28) -> 0.76666138
A31: Operating expenses (treated as fixed) | B31: =-SUMIF(Monthly!$C$5:$AL$5,B$26,Monthly!$C$41:$AL$41) -> 445823.02 | C31: =-SUMIF(Monthly!$C$5:$AL$5,C$26,Monthly!$C$41:$AL$41) -> 464040.36 | D31: =-SUMIF(Monthly!$C$5:$AL$5,D$26,Monthly!$C$41:$AL$41) -> 474041.03
A32: Break-even revenue (EBITDA = 0) | B32: =IF(B30>0,B31/B30,"n/a") -> 666712.95 | C32: =IF(C30>0,C31/C30,"n/a") -> 610954.31 | D32: =IF(D30>0,D31/D30,"n/a") -> 618318.64
A33: Margin of safety (revenue above break-even) | B33: =IF(AND(ISNUMBER(B32),B28>0),(B28-B32)/B28,"n/a") -> -0.69614493 | C33: =IF(AND(ISNUMBER(C32),C28>0),(C28-C32)/C28,"n/a") -> 0.079796458 | D33: =IF(AND(ISNUMBER(D32),D28>0),(D28-D32)/D28,"n/a") -> 0.14435955
A35: Simplification: cost of sales is treated as variable and operating expenses as fixed, so break-even revenue = operating expenses ÷ gross margin. In a year with zero or negative gross margin there is no break-even revenue (n/a); the chart line shows 0 there.

Sheet Valuation
A1: Discounted cash flow valuation | H1: =HYPERLINK("#'Cover'!A1","◂ Contents") -> ◂ Contents
A2: Enterprise value at the start of the plan, before the funding raised in period 1. Year-end discounting.
A3: Scenario shown | B3: =CHOOSE(Dashboard!$B$4,"Low","Base","High") -> Base
A5: Assumptions (active scenario, from the Inputs sheet)
A6: Discount rate (WACC) | B6: =Inputs!$E$72 -> 0.25
A7: Terminal growth rate | B7: =Inputs!$E$73 -> 0.02
A8: Exit multiple (EV ÷ final-year EBITDA) | B8: =Inputs!$E$74 -> 4
A9: Tax rate (for the interest tax shield) | B9: =Inputs!$E$66 -> 0.21
A10: Sensitivity step: WACC | B10: =Inputs!$E$75 -> 0.01
A11: Sensitivity step: terminal growth | B11: =Inputs!$E$76 -> 0.005
A13: Free cash flow by year
A14: Year # | B14: 1 | C14: 2 | D14: 3
B15: Year 1 | C15: Year 2 | D15: Year 3
A16: EBITDA | B16: =SUMIF(Monthly!$C$5:$AL$5,B$14,Monthly!$C$42:$AL$42) -> -182978.13 | C16: =SUMIF(Monthly!$C$5:$AL$5,C$14,Monthly!$C$42:$AL$42) -> 40239.768 | D16: =SUMIF(Monthly!$C$5:$AL$5,D$14,Monthly!$C$42:$AL$42) -> 79977.928
A17: Unlevered free cash flow | B17: =SUMIF(Monthly!$C$5:$AL$5,B$14,Monthly!$C$90:$AL$90) -> -431339.25 | C17: =SUMIF(Monthly!$C$5:$AL$5,C$14,Monthly!$C$90:$AL$90) -> 38769.581 | D17: =SUMIF(Monthly!$C$5:$AL$5,D$14,Monthly!$C$90:$AL$90) -> 78464.352
A18: Discount factor | B18: =1/(1+Inputs!$E$72)^B$14 -> 0.8 | C18: =1/(1+Inputs!$E$72)^C$14 -> 0.64 | D18: =1/(1+Inputs!$E$72)^D$14 -> 0.512
A19: Present value of free cash flow | B19: =B17*B18 -> -345071.4 | C19: =C17*C18 -> 24812.532 | D19: =D17*D18 -> 40173.748
A21: Enterprise value
B22: Perpetual growth | C22: Exit multiple
A23: Present value of the plan's free cash flows | B23: =SUM($B$19:$D$19) -> -280085.12 | C23: =B23 -> -280085.12
A24: Final-year free cash flow | final-year EBITDA | B24: =$D$17 -> 78464.352 | C24: =$D$16 -> 79977.928
A25: Terminal value at the end of year 3 | B25: =IF($B$6>$B$7,B24*(1+$B$7)/($B$6-$B$7),0) -> 347972.34 | C25: =C24*$B$8 -> 319911.71
A26: Present value of the terminal value | B26: =B25/(1+$B$6)^$D$14 -> 178161.84 | C26: =C25/(1+$B$6)^$D$14 -> 163794.8
A27: Enterprise value | B27: =B23+B26 -> -101923.28 | C27: =C23+C26 -> -116290.32
A28: Terminal value share of enterprise value | B28: =IF(B27<>0,B26/B27,0) -> -1.7479995 | C28: =IF(C27<>0,C26/C27,0) -> -1.408499
A29: Cross-check: implied exit multiple | implied perpetual growth | B29: =IF(C24>0,B25/C24,"n/a") -> 4.3508547 | C29: =IF(C25+B24<>0,(C25*$B$6-B24)/(C25+B24),"n/a") -> 0.0037993661
A30: Enterprise value — average of the two methods | B30: =AVERAGE(B27,C27) -> -109106.8
A32: Sensitivity: enterprise value (perpetual growth) by WACC and terminal growth
A33: WACC ↓ · terminal growth → | B33: =$B$7+(-2)*$B$11 -> 0.01 | C33: =$B$7+(-1)*$B$11 -> 0.015 | D33: =$B$7+(0)*$B$11 -> 0.02 | E33: =$B$7+(1)*$B$11 -> 0.025 | F33: =$B$7+(2)*$B$11 -> 0.03
A34: =$B$6+(-2)*$B$10 -> 0.23 | B34: =IF($A34>B$33,SUMPRODUCT($B$17:$D$17/(1+$A34)^$B$14:$D$14)+$D$17*(1+B$33)/($A34-B$33)/(1+$A34)^$D$14,"n/a") -> -89312.941 | C34: =IF($A34>C$33,SUMPRODUCT($B$17:$D$17/(1+$A34)^$B$14:$D$14)+$D$17*(1+C$33)/($A34-C$33)/(1+$A34)^$D$14,"n/a") -> -83830.537 | D34: =IF($A34>D$33,SUMPRODUCT($B$17:$D$17/(1+$A34)^$B$14:$D$14)+$D$17*(1+D$33)/($A34-D$33)/(1+$A34)^$D$14,"n/a") -> -78087.066 | E34: =IF($A34>E$33,SUMPRODUCT($B$17:$D$17/(1+$A34)^$B$14:$D$14)+$D$17*(1+E$33)/($A34-E$33)/(1+$A34)^$D$14,"n/a") -> -72063.426 | F34: =IF($A34>F$33,SUMPRODUCT($B$17:$D$17/(1+$A34)^$B$14:$D$14)+$D$17*(1+F$33)/($A34-F$33)/(1+$A34)^$D$14,"n/a") -> -65738.604
A35: =$B$6+(-1)*$B$10 -> 0.24 | B35: =IF($A35>B$33,SUMPRODUCT($B$17:$D$17/(1+$A35)^$B$14:$D$14)+$D$17*(1+B$33)/($A35-B$33)/(1+$A35)^$D$14,"n/a") -> -100768.55 | C35: =IF($A35>C$33,SUMPRODUCT($B$17:$D$17/(1+$A35)^$B$14:$D$14)+$D$17*(1+C$33)/($A35-C$33)/(1+$A35)^$D$14,"n/a") -> -95838.081 | D35: =IF($A35>D$33,SUMPRODUCT($B$17:$D$17/(1+$A35)^$B$14:$D$14)+$D$17*(1+D$33)/($A35-D$33)/(1+$A35)^$D$14,"n/a") -> -90683.494 | E35: =IF($A35>E$33,SUMPRODUCT($B$17:$D$17/(1+$A35)^$B$14:$D$14)+$D$17*(1+E$33)/($A35-E$33)/(1+$A35)^$D$14,"n/a") -> -85289.16 | F35: =IF($A35>F$33,SUMPRODUCT($B$17:$D$17/(1+$A35)^$B$14:$D$14)+$D$17*(1+F$33)/($A35-F$33)/(1+$A35)^$D$14,"n/a") -> -79637.952
A36: =$B$6+(0)*$B$10 -> 0.25 | B36: =IF($A36>B$33,SUMPRODUCT($B$17:$D$17/(1+$A36)^$B$14:$D$14)+$D$17*(1+B$33)/($A36-B$33)/(1+$A36)^$D$14,"n/a") -> -111020.59 | C36: =IF($A36>C$33,SUMPRODUCT($B$17:$D$17/(1+$A36)^$B$14:$D$14)+$D$17*(1+C$33)/($A36-C$33)/(1+$A36)^$D$14,"n/a") -> -106568.72 | D36: =IF($A36>D$33,SUMPRODUCT($B$17:$D$17/(1+$A36)^$B$14:$D$14)+$D$17*(1+D$33)/($A36-D$33)/(1+$A36)^$D$14,"n/a") -> -101923.28 | E36: =IF($A36>E$33,SUMPRODUCT($B$17:$D$17/(1+$A36)^$B$14:$D$14)+$D$17*(1+E$33)/($A36-E$33)/(1+$A36)^$D$14,"n/a") -> -97071.376 | F36: =IF($A36>F$33,SUMPRODUCT($B$17:$D$17/(1+$A36)^$B$14:$D$14)+$D$17*(1+F$33)/($A36-F$33)/(1+$A36)^$D$14,"n/a") -> -91998.933
A37: =$B$6+(1)*$B$10 -> 0.26 | B37: =IF($A37>B$33,SUMPRODUCT($B$17:$D$17/(1+$A37)^$B$14:$D$14)+$D$17*(1+B$33)/($A37-B$33)/(1+$A37)^$D$14,"n/a") -> -120219.49 | C37: =IF($A37>C$33,SUMPRODUCT($B$17:$D$17/(1+$A37)^$B$14:$D$14)+$D$17*(1+C$33)/($A37-C$33)/(1+$A37)^$D$14,"n/a") -> -116184.94 | D37: =IF($A37>D$33,SUMPRODUCT($B$17:$D$17/(1+$A37)^$B$14:$D$14)+$D$17*(1+D$33)/($A37-D$33)/(1+$A37)^$D$14,"n/a") -> -111982.28 | E37: =IF($A37>E$33,SUMPRODUCT($B$17:$D$17/(1+$A37)^$B$14:$D$14)+$D$17*(1+E$33)/($A37-E$33)/(1+$A37)^$D$14,"n/a") -> -107600.79 | F37: =IF($A37>F$33,SUMPRODUCT($B$17:$D$17/(1+$A37)^$B$14:$D$14)+$D$17*(1+F$33)/($A37-F$33)/(1+$A37)^$D$14,"n/a") -> -103028.79
A38: =$B$6+(2)*$B$10 -> 0.27 | B38: =IF($A38>B$33,SUMPRODUCT($B$17:$D$17/(1+$A38)^$B$14:$D$14)+$D$17*(1+B$33)/($A38-B$33)/(1+$A38)^$D$14,"n/a") -> -128492.34 | C38: =IF($A38>C$33,SUMPRODUCT($B$17:$D$17/(1+$A38)^$B$14:$D$14)+$D$17*(1+C$33)/($A38-C$33)/(1+$A38)^$D$14,"n/a") -> -124823.56 | D38: =IF($A38>D$33,SUMPRODUCT($B$17:$D$17/(1+$A38)^$B$14:$D$14)+$D$17*(1+D$33)/($A38-D$33)/(1+$A38)^$D$14,"n/a") -> -121008.03 | E38: =IF($A38>E$33,SUMPRODUCT($B$17:$D$17/(1+$A38)^$B$14:$D$14)+$D$17*(1+E$33)/($A38-E$33)/(1+$A38)^$D$14,"n/a") -> -117036.77 | F38: =IF($A38>F$33,SUMPRODUCT($B$17:$D$17/(1+$A38)^$B$14:$D$14)+$D$17*(1+F$33)/($A38-F$33)/(1+$A38)^$D$14,"n/a") -> -112900.03
A40: Free cash flow = operating cash flow + interest × (1 − tax rate) − capital spending. Cells marked n/a: WACC not above growth.

Sheet Sources & Uses
A1: Sources and uses of funds | E1: =HYPERLINK("#'Cover'!A1","◂ Contents") -> ◂ Contents
A2: Live for the selected scenario. Where the money comes from and where it goes in the period set below.
A3: Scenario shown | B3: =CHOOSE(Dashboard!$B$4,"Low","Base","High") -> Base
A5: Funding structure ($'000) — raised at the start of the plan
B6: Amount | C6: Share
A7: Equity | B7: =Inputs!$E$54 -> 330000 | C7: =IF($B$9=0,0,B7/$B$9) -> 0.6875
A8: Debt (loan) | B8: =Inputs!$E$55 -> 150000 | C8: =IF($B$9=0,0,B8/$B$9) -> 0.3125
A9: Total funding | B9: =B7+B8 -> 480000 | C9: =IF(B9=0,0,1) -> 1
A10: Gearing (debt ÷ equity) | B10: =IF(B7<=0,IF(B8>0,"n/a",0),B8/B7) -> 0.45454545 | D10: n/a: debt without positive equity
A11: Funding required by the plan (Break-even sheet) | B11: ='Break-even'!B12 -> 583559.64
A12: Funding surplus / (shortfall) | B12: ='Break-even'!B17 -> -103559.64
A14: ="Sources and uses of cash in the first "&$B$16&IF($B$16=1," month"," months")&" ($'000)" -> Sources and uses of cash in the first 12 months ($'000)
A15: Period covered (months from the start) | B15: 12 | D15: 1 to 36 (capped)
A16: Months used | B16: =MIN(36,MAX(1,ROUND(B15,0))) -> 12
A17: Sources | B17: Amount | C17: Share
A18: Equity raised | B18: =SUMPRODUCT(--(Monthly!$C$4:$AL$4<=$B$16),Monthly!$C$77:$AL$77) -> 330000 | C18: =IF($B$21=0,0,B18/$B$21) -> 0.6875
A19: Loan drawdowns | B19: =SUMPRODUCT(--(Monthly!$C$4:$AL$4<=$B$16),Monthly!$C$62:$AL$62) -> 150000 | C19: =IF($B$21=0,0,B19/$B$21) -> 0.3125
A20: Cash generated by operations | B20: =MAX(0,SUMPRODUCT(--(Monthly!$C$4:$AL$4<=$B$16),Monthly!$C$75:$AL$75)) -> 0 | C20: =IF($B$21=0,0,B20/$B$21) -> 0
A21: Total sources | B21: =SUM(B18:B20) -> 480000 | C21: =IF(B21=0,0,1) -> 1
A23: Uses | B23: Amount | C23: Share
A24: Cash used by operations | B24: =MAX(0,-SUMPRODUCT(--(Monthly!$C$4:$AL$4<=$B$16),Monthly!$C$75:$AL$75)) -> 190250.26 | C24: =IF($B$28=0,0,B24/$B$28) -> 0.39635471
A25: Capital spending | B25: =-SUMPRODUCT(--(Monthly!$C$4:$AL$4<=$B$16),Monthly!$C$76:$AL$76) -> 250000 | C25: =IF($B$28=0,0,B25/$B$28) -> 0.52083333
A26: Loan repayments | B26: =-SUMPRODUCT(--(Monthly!$C$4:$AL$4<=$B$16),Monthly!$C$63:$AL$63) -> 19642.857 | C26: =IF($B$28=0,0,B26/$B$28) -> 0.040922619
A27: Cash at the end of the period | B27: =INDEX(Monthly!$C$81:$AL$81,$B$16) -> 20106.884 | C27: =IF($B$28=0,0,B27/$B$28) -> 0.041889341
A28: Total uses | B28: =SUM(B24:B27) -> 480000 | C28: =IF(B28=0,0,1) -> 1
A29: Sources − uses (must be 0; opening cash is 0) | B29: =B21-B28 -> 0

Sheet KPIs
A1: KPIs & ratios | G1: =HYPERLINK("#'Cover'!A1","◂ Contents") -> ◂ Contents
A2: Fitness studio financial model (planning) — industry metrics and financial ratios for the active scenario
A4: Financial ratios
B5: 1 | C5: 2 | D5: 3 | E5: Target
A6: Revenue growth | B6: =IF(N('P&L'!A5)<=0,"n/a",'P&L'!B5/'P&L'!A5-1) -> n/a | C6: =IF(N('P&L'!B5)<=0,"n/a",'P&L'!C5/'P&L'!B5-1) -> 0.68907488 | D6: =IF(N('P&L'!C5)<=0,"n/a",'P&L'!D5/'P&L'!C5-1) -> 0.08841922
A7: Gross margin | B7: =IF('P&L'!B5<=0,"n/a",'P&L'!B7/'P&L'!B5) -> 0.6686881 | C7: =IF('P&L'!C5<=0,"n/a",'P&L'!C7/'P&L'!C5) -> 0.75953364 | D7: =IF('P&L'!D5<=0,"n/a",'P&L'!D7/'P&L'!D5) -> 0.76666138
A8: EBITDA margin | B8: =IF('P&L'!B5<=0,"n/a",'P&L'!B17/'P&L'!B5) -> -0.46550384 | C8: =IF('P&L'!C5<=0,"n/a",'P&L'!C17/'P&L'!C5) -> 0.060608094 | D8: =IF('P&L'!D5<=0,"n/a",'P&L'!D17/'P&L'!D5) -> 0.11067489
A9: Net margin | B9: =IF('P&L'!B5<=0,"n/a",'P&L'!B24/'P&L'!B5) -> -0.58505861 | C9: =IF('P&L'!C5<=0,"n/a",'P&L'!C24/'P&L'!C5) -> -0.0076000742 | D9: =IF('P&L'!D5<=0,"n/a",'P&L'!D24/'P&L'!D5) -> 0.050379968
A10: Payroll, % of revenue | B10: =IF('P&L'!B5<=0,"n/a",-SUMIF(Headcount!$C$5:$AL$5,B$5,Headcount!$C$15:$AL$15)/'P&L'!B5) -> 0.42256517 | C10: =IF('P&L'!C5<=0,"n/a",-SUMIF(Headcount!$C$5:$AL$5,C$5,Headcount!$C$15:$AL$15)/'P&L'!C5) -> 0.25768078 | D10: =IF('P&L'!D5<=0,"n/a",-SUMIF(Headcount!$C$5:$AL$5,D$5,Headcount!$C$15:$AL$15)/'P&L'!D5) -> 0.24385016
A11: Marketing, % of revenue | B11: =IF('P&L'!B5<=0,"n/a",-'P&L'!B10/'P&L'!B5) -> 0.12211396 | C11: =IF('P&L'!C5<=0,"n/a",-'P&L'!C10/'P&L'!C5) -> 0.075911173 | D11: =IF('P&L'!D5<=0,"n/a",-'P&L'!D10/'P&L'!D5) -> 0.073231647
A12: Operating expenses, % of revenue | B12: =IF('P&L'!B5<=0,"n/a",-'P&L'!B16/'P&L'!B5) -> 1.1341919 | C12: =IF('P&L'!C5<=0,"n/a",-'P&L'!C16/'P&L'!C5) -> 0.69892555 | D12: =IF('P&L'!D5<=0,"n/a",-'P&L'!D16/'P&L'!D5) -> 0.65598649
A13: Current ratio (current assets ÷ current liabilities) | B13: =IF(('Balance Sheet'!B12-'Balance Sheet'!B11)<=0,"n/a",('Balance Sheet'!B5+'Balance Sheet'!B6+'Balance Sheet'!B7)/('Balance Sheet'!B12-'Balance Sheet'!B11)) -> 3.0085711 | C13: =IF(('Balance Sheet'!C12-'Balance Sheet'!C11)<=0,"n/a",('Balance Sheet'!C5+'Balance Sheet'!C6+'Balance Sheet'!C7)/('Balance Sheet'!C12-'Balance Sheet'!C11)) -> 3.7860685 | D13: =IF(('Balance Sheet'!D12-'Balance Sheet'!D11)<=0,"n/a",('Balance Sheet'!D5+'Balance Sheet'!D6+'Balance Sheet'!D7)/('Balance Sheet'!D12-'Balance Sheet'!D11)) -> 9.1162769
A14: Debt ÷ equity (loan ÷ total equity) | B14: =IF('Balance Sheet'!B15<=0,"n/a",'Balance Sheet'!B11/'Balance Sheet'!B15) -> 1.3032089 | C14: =IF('Balance Sheet'!C15<=0,"n/a",'Balance Sheet'!C11/'Balance Sheet'!C15) -> 1.1468354 | D14: =IF('Balance Sheet'!D15<=0,"n/a",'Balance Sheet'!D11/'Balance Sheet'!D15) -> 0.66596457
A15: Return on assets (net income ÷ year-end assets) | B15: =IF('Balance Sheet'!B9<=0,"n/a",'P&L'!B24/'Balance Sheet'!B9) -> -0.96464746 | C15: =IF('Balance Sheet'!C9<=0,"n/a",'P&L'!C24/'Balance Sheet'!C9) -> -0.023689297 | D15: =IF('Balance Sheet'!D9<=0,"n/a",'P&L'!D24/'Balance Sheet'!D9) -> 0.15949846
A16: Return on equity (net income ÷ year-end equity) | B16: =IF('Balance Sheet'!B15<=0,"n/a",'P&L'!B24/'Balance Sheet'!B15) -> -2.2990823 | C16: =IF('Balance Sheet'!C15<=0,"n/a",'P&L'!C24/'Balance Sheet'!C15) -> -0.053125367 | D16: =IF('Balance Sheet'!D15<=0,"n/a",'P&L'!D24/'Balance Sheet'!D15) -> 0.27709073
A18: DuPont analysis — return on equity = net margin × asset turnover × equity multiplier
B19: 1 | C19: 2 | D19: 3
