Workbook

Sheet Cover
B2: Fitness studio financial model (planning)
B3: 5-year financial model · monthly detail · Low / Base / High scenarios · US dollars · Full plan
B5: Purpose | D5: Revenue and profit plan
B6: Active scenario | D6: =Dashboard!C4&" (change it on the Dashboard, cell B4)" -> Base (change it on the Dashboard, cell B4)
B7: Model checks | D7: =Checks!B22 -> PASS
B8: Prepared | D8: 20 October 2026
B10: Contents
C11: PRESENTATION
B12: 1 | C12: =HYPERLINK("#Dashboard!A1","Dashboard") -> Dashboard | D12: Scenario switch, key numbers, core financials
B13: 2 | C13: =HYPERLINK("#Summary!A1","Summary") -> Summary | D13: Income statement, cash flow and balance sheet — every year and any year by month
B14: 3 | C14: =HYPERLINK("#'Break-even'!A1","Break-even") -> Break-even | D14: Startup costs, funding need, break-even timing and revenue
B15: 4 | C15: =HYPERLINK("#Valuation!A1","Valuation") -> Valuation | D15: Free cash flow, DCF (perpetual growth and exit multiple), WACC × growth sensitivity
C16: INPUTS
B17: 5 | C17: =HYPERLINK("#Inputs!A1","Inputs") -> Inputs | D17: Every assumption, Low / Base / High, with units and comments
C18: STATEMENTS
B19: 6 | C19: =HYPERLINK("#'P&L'!A1","P&L") -> P&L | D19: Annual profit & loss
B20: 7 | C20: =HYPERLINK("#'Cash Flow'!A1","Cash Flow") -> Cash Flow | D20: Annual cash flow statement
B21: 8 | C21: =HYPERLINK("#'Balance Sheet'!A1","Balance Sheet") -> Balance Sheet | D21: Balance sheet at year end
C22: CALCULATIONS
B23: 9 | C23: =HYPERLINK("#Monthly!A1","Monthly") -> Monthly | D23: Month-by-month engine of the model
B24: 10 | C24: =HYPERLINK("#Headcount!A1","Headcount") -> Headcount | D24: Team and payroll
C25: CONTROL
B26: 11 | C26: =HYPERLINK("#Checks!A1","Checks") -> Checks | D26: Live integrity checks and the overall verdict
B28: How to read this file
C29: 1000 | D29: Input you can change — yellow cell with a blue figure (Inputs sheet and the view switches)
C30: 1000 | D30: Formula — calculated, do not overwrite
C31: 1000 | D31: Link to another sheet
C32: 1000 | D32: Active value the model uses (follows the scenario)

Sheet Dashboard
A1: Dashboard | W1: =HYPERLINK("#'Cover'!A1","◂ Contents") -> ◂ Contents
A2: Fitness studio financial model (planning)
A4: Active scenario | B4: 2 | C4: =CHOOSE(B4,"Low","Base","High") -> Base | D4: 1 = Low · 2 = Base · 3 = High — every sheet follows this cell | S4: Model checks | T4: =Checks!B22 -> PASS
A6: REVENUE · YEAR 5 | C6: EBITDA MARGIN · YEAR 5 | H6: NET INCOME · YEAR 5 | L6: LOWEST CASH BALANCE | P6: FUNDING REQUIRED | T6: ENTERPRISE VALUE (DCF)
A7: =F12 -> 766647.08 | C7: =F17 -> 0.12496169 | H7: =F18 -> 55658.655 | L7: =F38 -> 7440.3636 | P7: =F36 -> 583559.64 | T7: =F43 -> -81635.822
A8: =IF(AND(B12>0,F12>=0),(F12/B12)^(1/4)-1,"CAGR n/a") -> 0.18176164 | C8: =F16 -> 95801.512 | H8: =F19 -> 0.072600101 | L8: ='Break-even'!B6 -> 16 | P8: =IF(F37>=0,"Covered by funding raised","Shortfall $"&TEXT(-F37/1000000,"0.0")&"M") -> Shortfall $0.1M | T8: Average of 2 methods
A10: Core financials ($'000) — active scenario
B11: 1 | C11: 2 | D11: 3 | E11: 4 | F11: 5
A12: Revenue | B12: =SUMIF(Monthly!$C$5:$BJ$5,B$11,Monthly!$C$24:$BJ$24) -> 393075.46 | C12: =SUMIF(Monthly!$C$5:$BJ$5,C$11,Monthly!$C$24:$BJ$24) -> 663933.88 | D12: =SUMIF(Monthly!$C$5:$BJ$5,D$11,Monthly!$C$24:$BJ$24) -> 722638.4 | E12: =SUMIF(Monthly!$C$5:$BJ$5,E$11,Monthly!$C$24:$BJ$24) -> 744317.55 | F12: =SUMIF(Monthly!$C$5:$BJ$5,F$11,Monthly!$C$24:$BJ$24) -> 766647.08
A13: Gross profit | B13: =SUMIF(Monthly!$C$5:$BJ$5,B$11,Monthly!$C$31:$BJ$31) -> 262844.88 | C13: =SUMIF(Monthly!$C$5:$BJ$5,C$11,Monthly!$C$31:$BJ$31) -> 504280.12 | D13: =SUMIF(Monthly!$C$5:$BJ$5,D$11,Monthly!$C$31:$BJ$31) -> 554018.95 | E13: =SUMIF(Monthly!$C$5:$BJ$5,E$11,Monthly!$C$31:$BJ$31) -> 570639.52 | F13: =SUMIF(Monthly!$C$5:$BJ$5,F$11,Monthly!$C$31:$BJ$31) -> 587758.71
A14: Gross margin | B14: =IF(B12=0,0,B13/B12) -> 0.6686881 | C14: =IF(C12=0,0,C13/C12) -> 0.75953364 | D14: =IF(D12=0,0,D13/D12) -> 0.76666138 | E14: =IF(E12=0,0,E13/E12) -> 0.76666138 | F14: =IF(F12=0,0,F13/F12) -> 0.76666138
A15: Operating expenses | B15: =SUMIF(Monthly!$C$5:$BJ$5,B$11,Monthly!$C$41:$BJ$41) -> -445823.02 | C15: =SUMIF(Monthly!$C$5:$BJ$5,C$11,Monthly!$C$41:$BJ$41) -> -464040.36 | D15: =SUMIF(Monthly!$C$5:$BJ$5,D$11,Monthly!$C$41:$BJ$41) -> -474041.03 | E15: =SUMIF(Monthly!$C$5:$BJ$5,E$11,Monthly!$C$41:$BJ$41) -> -482840.66 | F15: =SUMIF(Monthly!$C$5:$BJ$5,F$11,Monthly!$C$41:$BJ$41) -> -491957.2
A16: EBITDA | B16: =SUMIF(Monthly!$C$5:$BJ$5,B$11,Monthly!$C$42:$BJ$42) -> -182978.13 | C16: =SUMIF(Monthly!$C$5:$BJ$5,C$11,Monthly!$C$42:$BJ$42) -> 40239.768 | D16: =SUMIF(Monthly!$C$5:$BJ$5,D$11,Monthly!$C$42:$BJ$42) -> 79977.928 | E16: =SUMIF(Monthly!$C$5:$BJ$5,E$11,Monthly!$C$42:$BJ$42) -> 87798.866 | F16: =SUMIF(Monthly!$C$5:$BJ$5,F$11,Monthly!$C$42:$BJ$42) -> 95801.512
A17: EBITDA margin | B17: =IF(B12=0,0,B16/B12) -> -0.46550384 | C17: =IF(C12=0,0,C16/C12) -> 0.060608094 | D17: =IF(D12=0,0,D16/D12) -> 0.11067489 | E17: =IF(E12=0,0,E16/E12) -> 0.11795888 | F17: =IF(F12=0,0,F16/F12) -> 0.12496169
A18: Net income | B18: =SUMIF(Monthly!$C$5:$BJ$5,B$11,Monthly!$C$51:$BJ$51) -> -229972.18 | C18: =SUMIF(Monthly!$C$5:$BJ$5,C$11,Monthly!$C$51:$BJ$51) -> -5045.9468 | D18: =SUMIF(Monthly!$C$5:$BJ$5,D$11,Monthly!$C$51:$BJ$51) -> 36406.5 | E18: =SUMIF(Monthly!$C$5:$BJ$5,E$11,Monthly!$C$51:$BJ$51) -> 45941.723 | F18: =SUMIF(Monthly!$C$5:$BJ$5,F$11,Monthly!$C$51:$BJ$51) -> 55658.655
A19: Net margin | B19: =IF(B12=0,0,B18/B12) -> -0.58505861 | C19: =IF(C12=0,0,C18/C12) -> -0.0076000742 | D19: =IF(D12=0,0,D18/D12) -> 0.050379968 | E19: =IF(E12=0,0,E18/E12) -> 0.061723284 | F19: =IF(F12=0,0,F18/F12) -> 0.072600101
A20: Operating cash flow | B20: =SUMIF(Monthly!$C$5:$BJ$5,B$11,Monthly!$C$75:$BJ$75) -> -190250.26 | C20: =SUMIF(Monthly!$C$5:$BJ$5,C$11,Monthly!$C$75:$BJ$75) -> 31208.152 | D20: =SUMIF(Monthly!$C$5:$BJ$5,D$11,Monthly!$C$75:$BJ$75) -> 72257.209 | E20: =SUMIF(Monthly!$C$5:$BJ$5,E$11,Monthly!$C$75:$BJ$75) -> 81796.525 | F20: =SUMIF(Monthly!$C$5:$BJ$5,F$11,Monthly!$C$75:$BJ$75) -> 91517.672
A21: Investing cash flow | B21: =SUMIF(Monthly!$C$5:$BJ$5,B$11,Monthly!$C$76:$BJ$76) -> -250000 | C21: =SUMIF(Monthly!$C$5:$BJ$5,C$11,Monthly!$C$76:$BJ$76) -> 0 | D21: =SUMIF(Monthly!$C$5:$BJ$5,D$11,Monthly!$C$76:$BJ$76) -> 0 | E21: =SUMIF(Monthly!$C$5:$BJ$5,E$11,Monthly!$C$76:$BJ$76) -> 0 | F21: =SUMIF(Monthly!$C$5:$BJ$5,F$11,Monthly!$C$76:$BJ$76) -> 0
A22: Financing cash flow | B22: =SUMIF(Monthly!$C$5:$BJ$5,B$11,Monthly!$C$78:$BJ$78) -> 460357.14 | C22: =SUMIF(Monthly!$C$5:$BJ$5,C$11,Monthly!$C$78:$BJ$78) -> -21428.571 | D22: =SUMIF(Monthly!$C$5:$BJ$5,D$11,Monthly!$C$78:$BJ$78) -> -21428.571 | E22: =SUMIF(Monthly!$C$5:$BJ$5,E$11,Monthly!$C$78:$BJ$78) -> -21428.571 | F22: =SUMIF(Monthly!$C$5:$BJ$5,F$11,Monthly!$C$78:$BJ$78) -> -21428.571
A23: Net change in cash | B23: =SUMIF(Monthly!$C$5:$BJ$5,B$11,Monthly!$C$79:$BJ$79) -> 20106.884 | C23: =SUMIF(Monthly!$C$5:$BJ$5,C$11,Monthly!$C$79:$BJ$79) -> 9779.5808 | D23: =SUMIF(Monthly!$C$5:$BJ$5,D$11,Monthly!$C$79:$BJ$79) -> 50828.638 | E23: =SUMIF(Monthly!$C$5:$BJ$5,E$11,Monthly!$C$79:$BJ$79) -> 60367.954 | F23: =SUMIF(Monthly!$C$5:$BJ$5,F$11,Monthly!$C$79:$BJ$79) -> 70089.101
A24: Year-end cash | B24: =INDEX(Monthly!$C$81:$BJ$81,B$11*12) -> 20106.884 | C24: =INDEX(Monthly!$C$81:$BJ$81,C$11*12) -> 29886.464 | D24: =INDEX(Monthly!$C$81:$BJ$81,D$11*12) -> 80715.102 | E24: =INDEX(Monthly!$C$81:$BJ$81,E$11*12) -> 141083.06 | F24: =INDEX(Monthly!$C$81:$BJ$81,F$11*12) -> 211172.16
A26: Membership metrics
B27: 1 | C27: 2 | D27: 3 | E27: 4 | F27: 5
A28: Members (year end) | B28: =B49 -> 355.83586 | C28: =C49 -> 450 | D28: =D49 -> 450 | E28: =E49 -> 450 | F28: =F49 -> 450
A29: Capacity used (year end) | B29: =B53 -> 0.79074635 | C29: =C53 -> 1 | D29: =D53 -> 1 | E29: =E53 -> 1 | F29: =F53 -> 1
A30: Membership fees per month (year end) | B30: =B54 -> 35227.75 | C30: =C54 -> 45886.5 | D30: =D54 -> 47263.095 | E30: =E54 -> 48680.988 | F30: =F54 -> 50141.417
A31: Team (FTE, year end) | B31: =INDEX(Headcount!$C$10:$BJ$10,B$27*12) -> 4 | C31: =INDEX(Headcount!$C$10:$BJ$10,C$27*12) -> 4 | D31: =INDEX(Headcount!$C$10:$BJ$10,D$27*12) -> 4 | E31: =INDEX(Headcount!$C$10:$BJ$10,E$27*12) -> 4 | F31: =INDEX(Headcount!$C$10:$BJ$10,F$27*12) -> 4
A33: Funding & valuation ($'000) — active scenario
A34: Equity raised | F34: =Inputs!$E$54 -> 330000
A35: Loan drawn | F35: =Inputs!$E$55 -> 150000
A36: Funding required (incl. cash buffer) | F36: ='Break-even'!B12 -> 583559.64
A37: Funding surplus / (shortfall) | F37: ='Break-even'!B17 -> -103559.64
A38: ="Lowest cash balance (month "&'Break-even'!B6&")" -> Lowest cash balance (month 16) | F38: ='Break-even'!B18 -> 7440.3636
A39: First month with positive EBITDA | F39: ='Break-even'!B21 -> 15
A40: Cash invested paid back | F40: ='Break-even'!B23 -> Not within horizon
A41: Enterprise value — perpetual growth | F41: =Valuation!B27 -> -75381.994
A42: Enterprise value — exit multiple | F42: =Valuation!C27 -> -87889.65
A43: Enterprise value — average | F43: =Valuation!B30 -> -81635.822
A46: Membership metrics — detail
A47: Year # | B47: 1 | C47: 2 | D47: 3 | E47: 4 | F47: 5
...

Sheet Summary
A1: Financial statements summary | U1: =HYPERLINK("#'Cover'!A1","◂ Contents") -> ◂ Contents
A2: Fitness studio financial model (planning) | P2: Select detailed year: | R2: 1
A5: Income statement ($'000) — by year | H5: ="Income statement ($'000) — Year "&$R$2&", by month" -> Income statement ($'000) — Year 1, by month
B6: 1 | C6: 2 | D6: 3 | E6: 4 | F6: 5 | H6: =INDEX(Monthly!$C$4:$BJ$4,($R$2-1)*12+1) -> 1 | I6: =INDEX(Monthly!$C$4:$BJ$4,($R$2-1)*12+2) -> 2 | J6: =INDEX(Monthly!$C$4:$BJ$4,($R$2-1)*12+3) -> 3 | K6: =INDEX(Monthly!$C$4:$BJ$4,($R$2-1)*12+4) -> 4 | L6: =INDEX(Monthly!$C$4:$BJ$4,($R$2-1)*12+5) -> 5 | M6: =INDEX(Monthly!$C$4:$BJ$4,($R$2-1)*12+6) -> 6 | N6: =INDEX(Monthly!$C$4:$BJ$4,($R$2-1)*12+7) -> 7 | O6: =INDEX(Monthly!$C$4:$BJ$4,($R$2-1)*12+8) -> 8 | P6: =INDEX(Monthly!$C$4:$BJ$4,($R$2-1)*12+9) -> 9 | Q6: =INDEX(Monthly!$C$4:$BJ$4,($R$2-1)*12+10) -> 10 | R6: =INDEX(Monthly!$C$4:$BJ$4,($R$2-1)*12+11) -> 11 | S6: =INDEX(Monthly!$C$4:$BJ$4,($R$2-1)*12+12) -> 12
A7: Revenue | B7: ='P&L'!B5 -> 393075.46 | C7: ='P&L'!C5 -> 663933.88 | D7: ='P&L'!D5 -> 722638.4 | E7: ='P&L'!E5 -> 744317.55 | F7: ='P&L'!F5 -> 766647.08 | H7: =INDEX(Monthly!$C$24:$BJ$24,($R$2-1)*12+1) -> 18123 | I7: =INDEX(Monthly!$C$24:$BJ$24,($R$2-1)*12+2) -> 21349.608 | J7: =INDEX(Monthly!$C$24:$BJ$24,($R$2-1)*12+3) -> 24382.62 | K7: =INDEX(Monthly!$C$24:$BJ$24,($R$2-1)*12+4) -> 27233.65 | L7: =INDEX(Monthly!$C$24:$BJ$24,($R$2-1)*12+5) -> 29913.619 | M7: =INDEX(Monthly!$C$24:$BJ$24,($R$2-1)*12+6) -> 32432.79 | N7: =INDEX(Monthly!$C$24:$BJ$24,($R$2-1)*12+7) -> 34800.811 | O7: =INDEX(Monthly!$C$24:$BJ$24,($R$2-1)*12+8) -> 37026.75 | P7: =INDEX(Monthly!$C$24:$BJ$24,($R$2-1)*12+9) -> 39119.133 | Q7: =INDEX(Monthly!$C$24:$BJ$24,($R$2-1)*12+10) -> 41085.973 | R7: =INDEX(Monthly!$C$24:$BJ$24,($R$2-1)*12+11) -> 42934.803 | S7: =INDEX(Monthly!$C$24:$BJ$24,($R$2-1)*12+12) -> 44672.703
A8: Cost of sales | B8: ='P&L'!B6 -> -130230.58 | C8: ='P&L'!C6 -> -159653.76 | D8: ='P&L'!D6 -> -168619.45 | E8: ='P&L'!E6 -> -173678.03 | F8: ='P&L'!F6 -> -178888.37 | H8: =INDEX(Monthly!$C$30:$BJ$30,($R$2-1)*12+1) -> -9415.35 | I8: =INDEX(Monthly!$C$30:$BJ$30,($R$2-1)*12+2) -> -9732.249 | J8: =INDEX(Monthly!$C$30:$BJ$30,($R$2-1)*12+3) -> -10030.134 | K8: =INDEX(Monthly!$C$30:$BJ$30,($R$2-1)*12+4) -> -10310.146 | L8: =INDEX(Monthly!$C$30:$BJ$30,($R$2-1)*12+5) -> -10573.357 | M8: =INDEX(Monthly!$C$30:$BJ$30,($R$2-1)*12+6) -> -10820.776 | N8: =INDEX(Monthly!$C$30:$BJ$30,($R$2-1)*12+7) -> -11053.349 | O8: =INDEX(Monthly!$C$30:$BJ$30,($R$2-1)*12+8) -> -11271.968 | P8: =INDEX(Monthly!$C$30:$BJ$30,($R$2-1)*12+9) -> -11477.47 | Q8: =INDEX(Monthly!$C$30:$BJ$30,($R$2-1)*12+10) -> -11670.642 | R8: =INDEX(Monthly!$C$30:$BJ$30,($R$2-1)*12+11) -> -11852.223 | S8: =INDEX(Monthly!$C$30:$BJ$30,($R$2-1)*12+12) -> -12022.91
A9: Gross profit | B9: ='P&L'!B7 -> 262844.88 | C9: ='P&L'!C7 -> 504280.12 | D9: ='P&L'!D7 -> 554018.95 | E9: ='P&L'!E7 -> 570639.52 | F9: ='P&L'!F7 -> 587758.71 | H9: =INDEX(Monthly!$C$31:$BJ$31,($R$2-1)*12+1) -> 8707.65 | I9: =INDEX(Monthly!$C$31:$BJ$31,($R$2-1)*12+2) -> 11617.359 | J9: =INDEX(Monthly!$C$31:$BJ$31,($R$2-1)*12+3) -> 14352.485 | K9: =INDEX(Monthly!$C$31:$BJ$31,($R$2-1)*12+4) -> 16923.504 | L9: =INDEX(Monthly!$C$31:$BJ$31,($R$2-1)*12+5) -> 19340.262 | M9: =INDEX(Monthly!$C$31:$BJ$31,($R$2-1)*12+6) -> 21612.014 | N9: =INDEX(Monthly!$C$31:$BJ$31,($R$2-1)*12+7) -> 23747.461 | O9: =INDEX(Monthly!$C$31:$BJ$31,($R$2-1)*12+8) -> 25754.782 | P9: =INDEX(Monthly!$C$31:$BJ$31,($R$2-1)*12+9) -> 27641.663 | Q9: =INDEX(Monthly!$C$31:$BJ$31,($R$2-1)*12+10) -> 29415.331 | R9: =INDEX(Monthly!$C$31:$BJ$31,($R$2-1)*12+11) -> 31082.579 | S9: =INDEX(Monthly!$C$31:$BJ$31,($R$2-1)*12+12) -> 32649.792
A10: Gross margin | B10: ='P&L'!B8 -> 0.6686881 | C10: ='P&L'!C8 -> 0.75953364 | D10: ='P&L'!D8 -> 0.76666138 | E10: ='P&L'!E8 -> 0.76666138 | F10: ='P&L'!F8 -> 0.76666138 | H10: =IF(H7=0,0,H9/H7) -> 0.48047509 | I10: =IF(I7=0,0,I9/I7) -> 0.54414859 | J10: =IF(J7=0,0,J9/J7) -> 0.58863591 | K10: =IF(K7=0,0,K9/K7) -> 0.62141887 | L10: =IF(L7=0,0,L9/L7) -> 0.64653701 | M10: =IF(M7=0,0,M9/M7) -> 0.66636309 | N10: =IF(N7=0,0,N9/N7) -> 0.68238242 | O10: =IF(O7=0,0,O9/O7) -> 0.6955723 | ... S10: =IF(S7=0,0,S9/S7) -> 0.73086674
A11: Total operating expenses | B11: ='P&L'!B16 -> -445823.02 | C11: ='P&L'!C16 -> -464040.36 | D11: ='P&L'!D16 -> -474041.03 | E11: ='P&L'!E16 -> -482840.66 | F11: ='P&L'!F16 -> -491957.2 | H11: =INDEX(Monthly!$C$41:$BJ$41,($R$2-1)*12+1) -> -36566.587 | I11: =INDEX(Monthly!$C$41:$BJ$41,($R$2-1)*12+2) -> -36695.651 | J11: =INDEX(Monthly!$C$41:$BJ$41,($R$2-1)*12+3) -> -36816.971 | K11: =INDEX(Monthly!$C$41:$BJ$41,($R$2-1)*12+4) -> -36931.013 | L11: =INDEX(Monthly!$C$41:$BJ$41,($R$2-1)*12+5) -> -37038.211 | M11: =INDEX(Monthly!$C$41:$BJ$41,($R$2-1)*12+6) -> -37138.978 | N11: =INDEX(Monthly!$C$41:$BJ$41,($R$2-1)*12+7) -> -37233.699 | O11: =INDEX(Monthly!$C$41:$BJ$41,($R$2-1)*12+8) -> -37322.737 | P11: =INDEX(Monthly!$C$41:$BJ$41,($R$2-1)*12+9) -> -37406.432 | Q11: =INDEX(Monthly!$C$41:$BJ$41,($R$2-1)*12+10) -> -37485.106 | R11: =INDEX(Monthly!$C$41:$BJ$41,($R$2-1)*12+11) -> -37559.059 | S11: =INDEX(Monthly!$C$41:$BJ$41,($R$2-1)*12+12) -> -37628.575
A12: EBITDA | B12: ='P&L'!B17 -> -182978.13 | C12: ='P&L'!C17 -> 40239.768 | D12: ='P&L'!D17 -> 79977.928 | E12: ='P&L'!E17 -> 87798.866 | F12: ='P&L'!F17 -> 95801.512 | H12: =INDEX(Monthly!$C$42:$BJ$42,($R$2-1)*12+1) -> -27858.937 | I12: =INDEX(Monthly!$C$42:$BJ$42,($R$2-1)*12+2) -> -25078.292 | J12: =INDEX(Monthly!$C$42:$BJ$42,($R$2-1)*12+3) -> -22464.486 | K12: =INDEX(Monthly!$C$42:$BJ$42,($R$2-1)*12+4) -> -20007.508 | L12: =INDEX(Monthly!$C$42:$BJ$42,($R$2-1)*12+5) -> -17697.949 | M12: =INDEX(Monthly!$C$42:$BJ$42,($R$2-1)*12+6) -> -15526.964 | N12: =INDEX(Monthly!$C$42:$BJ$42,($R$2-1)*12+7) -> -13486.238 | O12: =INDEX(Monthly!$C$42:$BJ$42,($R$2-1)*12+8) -> -11567.955 | P12: =INDEX(Monthly!$C$42:$BJ$42,($R$2-1)*12+9) -> -9764.7691 | Q12: =INDEX(Monthly!$C$42:$BJ$42,($R$2-1)*12+10) -> -8069.7745 | R12: =INDEX(Monthly!$C$42:$BJ$42,($R$2-1)*12+11) -> -6476.4795 | S12: =INDEX(Monthly!$C$42:$BJ$42,($R$2-1)*12+12) -> -4978.7823
A13: EBITDA margin | B13: ='P&L'!B18 -> -0.46550384 | C13: ='P&L'!C18 -> 0.060608094 | D13: ='P&L'!D18 -> 0.11067489 | E13: ='P&L'!E18 -> 0.11795888 | F13: ='P&L'!F18 -> 0.12496169 | H13: =IF(H7=0,0,H12/H7) -> -1.5372144 | I13: =IF(I7=0,0,I12/I7) -> -1.1746488 | J13: =IF(J7=0,0,J12/J7) -> -0.92133193 | K13: =IF(K7=0,0,K12/K7) -> -0.73466128 | L13: =IF(L7=0,0,L12/L7) -> -0.59163517 | M13: =IF(M7=0,0,M12/M7) -> -0.47874277 | N13: =IF(N7=0,0,N12/N7) -> -0.38752654 | O13: =IF(O7=0,0,O12/O7) -> -0.31242156 | ... S13: =IF(S7=0,0,S12/S7) -> -0.11145021
A14: Depreciation | B14: ='P&L'!B19 -> -35714.286 | C14: ='P&L'!C19 -> -35714.286 | D14: ='P&L'!D19 -> -35714.286 | E14: ='P&L'!E19 -> -35714.286 | F14: ='P&L'!F19 -> -35714.286 | H14: =INDEX(Monthly!$C$56:$BJ$56,($R$2-1)*12+1) -> -2976.1905 | I14: =INDEX(Monthly!$C$56:$BJ$56,($R$2-1)*12+2) -> -2976.1905 | J14: =INDEX(Monthly!$C$56:$BJ$56,($R$2-1)*12+3) -> -2976.1905 | K14: =INDEX(Monthly!$C$56:$BJ$56,($R$2-1)*12+4) -> -2976.1905 | L14: =INDEX(Monthly!$C$56:$BJ$56,($R$2-1)*12+5) -> -2976.1905 | M14: =INDEX(Monthly!$C$56:$BJ$56,($R$2-1)*12+6) -> -2976.1905 | N14: =INDEX(Monthly!$C$56:$BJ$56,($R$2-1)*12+7) -> -2976.1905 | O14: =INDEX(Monthly!$C$56:$BJ$56,($R$2-1)*12+8) -> -2976.1905 | P14: =INDEX(Monthly!$C$56:$BJ$56,($R$2-1)*12+9) -> -2976.1905 | Q14: =INDEX(Monthly!$C$56:$BJ$56,($R$2-1)*12+10) -> -2976.1905 | R14: =INDEX(Monthly!$C$56:$BJ$56,($R$2-1)*12+11) -> -2976.1905 | S14: =INDEX(Monthly!$C$56:$BJ$56,($R$2-1)*12+12) -> -2976.1905
A15: EBIT | B15: ='P&L'!B20 -> -218692.42 | C15: ='P&L'!C20 -> 4525.4818 | D15: ='P&L'!D20 -> 44263.643 | E15: ='P&L'!E20 -> 52084.581 | F15: ='P&L'!F20 -> 60087.227 | H15: =INDEX(Monthly!$C$45:$BJ$45,($R$2-1)*12+1) -> -30835.127 | I15: =INDEX(Monthly!$C$45:$BJ$45,($R$2-1)*12+2) -> -28054.482 | J15: =INDEX(Monthly!$C$45:$BJ$45,($R$2-1)*12+3) -> -25440.676 | K15: =INDEX(Monthly!$C$45:$BJ$45,($R$2-1)*12+4) -> -22983.699 | L15: =INDEX(Monthly!$C$45:$BJ$45,($R$2-1)*12+5) -> -20674.14 | M15: =INDEX(Monthly!$C$45:$BJ$45,($R$2-1)*12+6) -> -18503.154 | N15: =INDEX(Monthly!$C$45:$BJ$45,($R$2-1)*12+7) -> -16462.428 | O15: =INDEX(Monthly!$C$45:$BJ$45,($R$2-1)*12+8) -> -14544.145 | P15: =INDEX(Monthly!$C$45:$BJ$45,($R$2-1)*12+9) -> -12740.96 | Q15: =INDEX(Monthly!$C$45:$BJ$45,($R$2-1)*12+10) -> -11045.965 | R15: =INDEX(Monthly!$C$45:$BJ$45,($R$2-1)*12+11) -> -9452.67 | S15: =INDEX(Monthly!$C$45:$BJ$45,($R$2-1)*12+12) -> -7954.9728
A16: Interest | B16: ='P&L'!B21 -> -11279.762 | C16: ='P&L'!C21 -> -9571.4286 | D16: ='P&L'!D21 -> -7857.1429 | E16: ='P&L'!E21 -> -6142.8571 | F16: ='P&L'!F21 -> -4428.5714 | H16: =INDEX(Monthly!$C$46:$BJ$46,($R$2-1)*12+1) -> -1000 | I16: =INDEX(Monthly!$C$46:$BJ$46,($R$2-1)*12+2) -> -994.04762 | J16: =INDEX(Monthly!$C$46:$BJ$46,($R$2-1)*12+3) -> -982.14286 | K16: =INDEX(Monthly!$C$46:$BJ$46,($R$2-1)*12+4) -> -970.2381 | L16: =INDEX(Monthly!$C$46:$BJ$46,($R$2-1)*12+5) -> -958.33333 | M16: =INDEX(Monthly!$C$46:$BJ$46,($R$2-1)*12+6) -> -946.42857 | N16: =INDEX(Monthly!$C$46:$BJ$46,($R$2-1)*12+7) -> -934.52381 | O16: =INDEX(Monthly!$C$46:$BJ$46,($R$2-1)*12+8) -> -922.61905 | P16: =INDEX(Monthly!$C$46:$BJ$46,($R$2-1)*12+9) -> -910.71429 | Q16: =INDEX(Monthly!$C$46:$BJ$46,($R$2-1)*12+10) -> -898.80952 | R16: =INDEX(Monthly!$C$46:$BJ$46,($R$2-1)*12+11) -> -886.90476 | S16: =INDEX(Monthly!$C$46:$BJ$46,($R$2-1)*12+12) -> -875
A17: Pre-tax income | B17: ='P&L'!B22 -> -229972.18 | C17: ='P&L'!C22 -> -5045.9468 | D17: ='P&L'!D22 -> 36406.5 | E17: ='P&L'!E22 -> 45941.723 | F17: ='P&L'!F22 -> 55658.655 | H17: =INDEX(Monthly!$C$47:$BJ$47,($R$2-1)*12+1) -> -31835.127 | I17: =INDEX(Monthly!$C$47:$BJ$47,($R$2-1)*12+2) -> -29048.53 | J17: =INDEX(Monthly!$C$47:$BJ$47,($R$2-1)*12+3) -> -26422.819 | K17: =INDEX(Monthly!$C$47:$BJ$47,($R$2-1)*12+4) -> -23953.937 | L17: =INDEX(Monthly!$C$47:$BJ$47,($R$2-1)*12+5) -> -21632.473 | M17: =INDEX(Monthly!$C$47:$BJ$47,($R$2-1)*12+6) -> -19449.583 | N17: =INDEX(Monthly!$C$47:$BJ$47,($R$2-1)*12+7) -> -17396.952 | O17: =INDEX(Monthly!$C$47:$BJ$47,($R$2-1)*12+8) -> -15466.764 | P17: =INDEX(Monthly!$C$47:$BJ$47,($R$2-1)*12+9) -> -13651.674 | Q17: =INDEX(Monthly!$C$47:$BJ$47,($R$2-1)*12+10) -> -11944.774 | R17: =INDEX(Monthly!$C$47:$BJ$47,($R$2-1)*12+11) -> -10339.575 | S17: =INDEX(Monthly!$C$47:$BJ$47,($R$2-1)*12+12) -> -8829.9728
A18: Income tax | B18: ='P&L'!B23 -> 0 | C18: ='P&L'!C23 -> 0 | D18: ='P&L'!D23 -> 0 | E18: ='P&L'!E23 -> 0 | F18: ='P&L'!F23 -> 0 | H18: =INDEX(Monthly!$C$50:$BJ$50,($R$2-1)*12+1) -> 0 | I18: =INDEX(Monthly!$C$50:$BJ$50,($R$2-1)*12+2) -> 0 | J18: =INDEX(Monthly!$C$50:$BJ$50,($R$2-1)*12+3) -> 0 | K18: =INDEX(Monthly!$C$50:$BJ$50,($R$2-1)*12+4) -> 0 | L18: =INDEX(Monthly!$C$50:$BJ$50,($R$2-1)*12+5) -> 0 | M18: =INDEX(Monthly!$C$50:$BJ$50,($R$2-1)*12+6) -> 0 | N18: =INDEX(Monthly!$C$50:$BJ$50,($R$2-1)*12+7) -> 0 | O18: =INDEX(Monthly!$C$50:$BJ$50,($R$2-1)*12+8) -> 0 | P18: =INDEX(Monthly!$C$50:$BJ$50,($R$2-1)*12+9) -> 0 | Q18: =INDEX(Monthly!$C$50:$BJ$50,($R$2-1)*12+10) -> 0 | R18: =INDEX(Monthly!$C$50:$BJ$50,($R$2-1)*12+11) -> 0 | S18: =INDEX(Monthly!$C$50:$BJ$50,($R$2-1)*12+12) -> 0
A19: Net income | B19: ='P&L'!B24 -> -229972.18 | C19: ='P&L'!C24 -> -5045.9468 | D19: ='P&L'!D24 -> 36406.5 | E19: ='P&L'!E24 -> 45941.723 | F19: ='P&L'!F24 -> 55658.655 | H19: =INDEX(Monthly!$C$51:$BJ$51,($R$2-1)*12+1) -> -31835.127 | I19: =INDEX(Monthly!$C$51:$BJ$51,($R$2-1)*12+2) -> -29048.53 | J19: =INDEX(Monthly!$C$51:$BJ$51,($R$2-1)*12+3) -> -26422.819 | K19: =INDEX(Monthly!$C$51:$BJ$51,($R$2-1)*12+4) -> -23953.937 | L19: =INDEX(Monthly!$C$51:$BJ$51,($R$2-1)*12+5) -> -21632.473 | M19: =INDEX(Monthly!$C$51:$BJ$51,($R$2-1)*12+6) -> -19449.583 | N19: =INDEX(Monthly!$C$51:$BJ$51,($R$2-1)*12+7) -> -17396.952 | O19: =INDEX(Monthly!$C$51:$BJ$51,($R$2-1)*12+8) -> -15466.764 | P19: =INDEX(Monthly!$C$51:$BJ$51,($R$2-1)*12+9) -> -13651.674 | Q19: =INDEX(Monthly!$C$51:$BJ$51,($R$2-1)*12+10) -> -11944.774 | R19: =INDEX(Monthly!$C$51:$BJ$51,($R$2-1)*12+11) -> -10339.575 | S19: =INDEX(Monthly!$C$51:$BJ$51,($R$2-1)*12+12) -> -8829.9728
A20: Net margin | B20: ='P&L'!B25 -> -0.58505861 | C20: ='P&L'!C25 -> -0.0076000742 | D20: ='P&L'!D25 -> 0.050379968 | E20: ='P&L'!E25 -> 0.061723284 | F20: ='P&L'!F25 -> 0.072600101 | H20: =IF(H7=0,0,H19/H7) -> -1.7566146 | I20: =IF(I7=0,0,I19/I7) -> -1.3606119 | J20: =IF(J7=0,0,J19/J7) -> -1.0836743 | K20: =IF(K7=0,0,K19/K7) -> -0.87957129 | L20: =IF(L7=0,0,L19/L7) -> -0.72316469 | M20: =IF(M7=0,0,M19/M7) -> -0.59968886 | N20: =IF(N7=0,0,N19/N7) -> -0.49990076 | O20: =IF(O7=0,0,O19/O7) -> -0.41771866 | ... S20: =IF(S7=0,0,S19/S7) -> -0.19765925
A22: Cash flow ($'000) — by year | H22: ="Cash flow ($'000) — Year "&$R$2&", by month" -> Cash flow ($'000) — Year 1, by month
B23: 1 | C23: 2 | D23: 3 | E23: 4 | F23: 5 | H23: =INDEX(Monthly!$C$4:$BJ$4,($R$2-1)*12+1) -> 1 | I23: =INDEX(Monthly!$C$4:$BJ$4,($R$2-1)*12+2) -> 2 | J23: =INDEX(Monthly!$C$4:$BJ$4,($R$2-1)*12+3) -> 3 | K23: =INDEX(Monthly!$C$4:$BJ$4,($R$2-1)*12+4) -> 4 | L23: =INDEX(Monthly!$C$4:$BJ$4,($R$2-1)*12+5) -> 5 | M23: =INDEX(Monthly!$C$4:$BJ$4,($R$2-1)*12+6) -> 6 | N23: =INDEX(Monthly!$C$4:$BJ$4,($R$2-1)*12+7) -> 7 | O23: =INDEX(Monthly!$C$4:$BJ$4,($R$2-1)*12+8) -> 8 | P23: =INDEX(Monthly!$C$4:$BJ$4,($R$2-1)*12+9) -> 9 | Q23: =INDEX(Monthly!$C$4:$BJ$4,($R$2-1)*12+10) -> 10 | R23: =INDEX(Monthly!$C$4:$BJ$4,($R$2-1)*12+11) -> 11 | S23: =INDEX(Monthly!$C$4:$BJ$4,($R$2-1)*12+12) -> 12
A24: Operating cash flow | B24: ='Cash Flow'!B10 -> -190250.26 | C24: ='Cash Flow'!C10 -> 31208.152 | D24: ='Cash Flow'!D10 -> 72257.209 | E24: ='Cash Flow'!E10 -> 81796.525 | F24: ='Cash Flow'!F10 -> 91517.672 | H24: =INDEX(Monthly!$C$75:$BJ$75,($R$2-1)*12+1) -> -25720.487 | I24: =INDEX(Monthly!$C$75:$BJ$75,($R$2-1)*12+2) -> -25966.707 | J24: =INDEX(Monthly!$C$75:$BJ$75,($R$2-1)*12+3) -> -23347.334 | K24: =INDEX(Monthly!$C$75:$BJ$75,($R$2-1)*12+4) -> -20884.409 | L24: =INDEX(Monthly!$C$75:$BJ$75,($R$2-1)*12+5) -> -18568.546 | M24: =INDEX(Monthly!$C$75:$BJ$75,($R$2-1)*12+6) -> -16390.92 | N24: =INDEX(Monthly!$C$75:$BJ$75,($R$2-1)*12+7) -> -14343.237 | O24: =INDEX(Monthly!$C$75:$BJ$75,($R$2-1)*12+8) -> -12417.701 | P24: =INDEX(Monthly!$C$75:$BJ$75,($R$2-1)*12+9) -> -10606.983 | Q24: =INDEX(Monthly!$C$75:$BJ$75,($R$2-1)*12+10) -> -8904.1934 | R24: =INDEX(Monthly!$C$75:$BJ$75,($R$2-1)*12+11) -> -7302.8571 | S24: =INDEX(Monthly!$C$75:$BJ$75,($R$2-1)*12+12) -> -5796.8867
A25: Capital spending | B25: ='Cash Flow'!B11 -> -250000 | C25: ='Cash Flow'!C11 -> 0 | D25: ='Cash Flow'!D11 -> 0 | E25: ='Cash Flow'!E11 -> 0 | F25: ='Cash Flow'!F11 -> 0 | H25: =INDEX(Monthly!$C$76:$BJ$76,($R$2-1)*12+1) -> -250000 | I25: =INDEX(Monthly!$C$76:$BJ$76,($R$2-1)*12+2) -> 0 | J25: =INDEX(Monthly!$C$76:$BJ$76,($R$2-1)*12+3) -> 0 | K25: =INDEX(Monthly!$C$76:$BJ$76,($R$2-1)*12+4) -> 0 | L25: =INDEX(Monthly!$C$76:$BJ$76,($R$2-1)*12+5) -> 0 | M25: =INDEX(Monthly!$C$76:$BJ$76,($R$2-1)*12+6) -> 0 | N25: =INDEX(Monthly!$C$76:$BJ$76,($R$2-1)*12+7) -> 0 | O25: =INDEX(Monthly!$C$76:$BJ$76,($R$2-1)*12+8) -> 0 | P25: =INDEX(Monthly!$C$76:$BJ$76,($R$2-1)*12+9) -> 0 | Q25: =INDEX(Monthly!$C$76:$BJ$76,($R$2-1)*12+10) -> 0 | R25: =INDEX(Monthly!$C$76:$BJ$76,($R$2-1)*12+11) -> 0 | S25: =INDEX(Monthly!$C$76:$BJ$76,($R$2-1)*12+12) -> 0
A26: Equity raised | B26: ='Cash Flow'!B12 -> 330000 | C26: ='Cash Flow'!C12 -> 0 | D26: ='Cash Flow'!D12 -> 0 | E26: ='Cash Flow'!E12 -> 0 | F26: ='Cash Flow'!F12 -> 0 | H26: =INDEX(Monthly!$C$77:$BJ$77,($R$2-1)*12+1) -> 330000 | I26: =INDEX(Monthly!$C$77:$BJ$77,($R$2-1)*12+2) -> 0 | J26: =INDEX(Monthly!$C$77:$BJ$77,($R$2-1)*12+3) -> 0 | K26: =INDEX(Monthly!$C$77:$BJ$77,($R$2-1)*12+4) -> 0 | L26: =INDEX(Monthly!$C$77:$BJ$77,($R$2-1)*12+5) -> 0 | M26: =INDEX(Monthly!$C$77:$BJ$77,($R$2-1)*12+6) -> 0 | N26: =INDEX(Monthly!$C$77:$BJ$77,($R$2-1)*12+7) -> 0 | O26: =INDEX(Monthly!$C$77:$BJ$77,($R$2-1)*12+8) -> 0 | P26: =INDEX(Monthly!$C$77:$BJ$77,($R$2-1)*12+9) -> 0 | Q26: =INDEX(Monthly!$C$77:$BJ$77,($R$2-1)*12+10) -> 0 | R26: =INDEX(Monthly!$C$77:$BJ$77,($R$2-1)*12+11) -> 0 | S26: =INDEX(Monthly!$C$77:$BJ$77,($R$2-1)*12+12) -> 0
A27: Loan drawdown | B27: ='Cash Flow'!B13 -> 150000 | C27: ='Cash Flow'!C13 -> 0 | D27: ='Cash Flow'!D13 -> 0 | E27: ='Cash Flow'!E13 -> 0 | F27: ='Cash Flow'!F13 -> 0 | H27: =INDEX(Monthly!$C$62:$BJ$62,($R$2-1)*12+1) -> 150000 | I27: =INDEX(Monthly!$C$62:$BJ$62,($R$2-1)*12+2) -> 0 | J27: =INDEX(Monthly!$C$62:$BJ$62,($R$2-1)*12+3) -> 0 | K27: =INDEX(Monthly!$C$62:$BJ$62,($R$2-1)*12+4) -> 0 | L27: =INDEX(Monthly!$C$62:$BJ$62,($R$2-1)*12+5) -> 0 | M27: =INDEX(Monthly!$C$62:$BJ$62,($R$2-1)*12+6) -> 0 | N27: =INDEX(Monthly!$C$62:$BJ$62,($R$2-1)*12+7) -> 0 | O27: =INDEX(Monthly!$C$62:$BJ$62,($R$2-1)*12+8) -> 0 | P27: =INDEX(Monthly!$C$62:$BJ$62,($R$2-1)*12+9) -> 0 | Q27: =INDEX(Monthly!$C$62:$BJ$62,($R$2-1)*12+10) -> 0 | R27: =INDEX(Monthly!$C$62:$BJ$62,($R$2-1)*12+11) -> 0 | S27: =INDEX(Monthly!$C$62:$BJ$62,($R$2-1)*12+12) -> 0
A28: Loan repayment | B28: ='Cash Flow'!B14 -> -19642.857 | C28: ='Cash Flow'!C14 -> -21428.571 | D28: ='Cash Flow'!D14 -> -21428.571 | E28: ='Cash Flow'!E14 -> -21428.571 | F28: ='Cash Flow'!F14 -> -21428.571 | H28: =INDEX(Monthly!$C$63:$BJ$63,($R$2-1)*12+1) -> 0 | I28: =INDEX(Monthly!$C$63:$BJ$63,($R$2-1)*12+2) -> -1785.7143 | J28: =INDEX(Monthly!$C$63:$BJ$63,($R$2-1)*12+3) -> -1785.7143 | K28: =INDEX(Monthly!$C$63:$BJ$63,($R$2-1)*12+4) -> -1785.7143 | L28: =INDEX(Monthly!$C$63:$BJ$63,($R$2-1)*12+5) -> -1785.7143 | M28: =INDEX(Monthly!$C$63:$BJ$63,($R$2-1)*12+6) -> -1785.7143 | N28: =INDEX(Monthly!$C$63:$BJ$63,($R$2-1)*12+7) -> -1785.7143 | O28: =INDEX(Monthly!$C$63:$BJ$63,($R$2-1)*12+8) -> -1785.7143 | P28: =INDEX(Monthly!$C$63:$BJ$63,($R$2-1)*12+9) -> -1785.7143 | Q28: =INDEX(Monthly!$C$63:$BJ$63,($R$2-1)*12+10) -> -1785.7143 | R28: =INDEX(Monthly!$C$63:$BJ$63,($R$2-1)*12+11) -> -1785.7143 | S28: =INDEX(Monthly!$C$63:$BJ$63,($R$2-1)*12+12) -> -1785.7143
A29: Financing cash flow | B29: ='Cash Flow'!B15 -> 460357.14 | C29: ='Cash Flow'!C15 -> -21428.571 | D29: ='Cash Flow'!D15 -> -21428.571 | E29: ='Cash Flow'!E15 -> -21428.571 | F29: ='Cash Flow'!F15 -> -21428.571 | H29: =INDEX(Monthly!$C$78:$BJ$78,($R$2-1)*12+1) -> 480000 | I29: =INDEX(Monthly!$C$78:$BJ$78,($R$2-1)*12+2) -> -1785.7143 | J29: =INDEX(Monthly!$C$78:$BJ$78,($R$2-1)*12+3) -> -1785.7143 | K29: =INDEX(Monthly!$C$78:$BJ$78,($R$2-1)*12+4) -> -1785.7143 | L29: =INDEX(Monthly!$C$78:$BJ$78,($R$2-1)*12+5) -> -1785.7143 | M29: =INDEX(Monthly!$C$78:$BJ$78,($R$2-1)*12+6) -> -1785.7143 | N29: =INDEX(Monthly!$C$78:$BJ$78,($R$2-1)*12+7) -> -1785.7143 | O29: =INDEX(Monthly!$C$78:$BJ$78,($R$2-1)*12+8) -> -1785.7143 | P29: =INDEX(Monthly!$C$78:$BJ$78,($R$2-1)*12+9) -> -1785.7143 | Q29: =INDEX(Monthly!$C$78:$BJ$78,($R$2-1)*12+10) -> -1785.7143 | R29: =INDEX(Monthly!$C$78:$BJ$78,($R$2-1)*12+11) -> -1785.7143 | S29: =INDEX(Monthly!$C$78:$BJ$78,($R$2-1)*12+12) -> -1785.7143
A30: Net change in cash | B30: ='Cash Flow'!B16 -> 20106.884 | C30: ='Cash Flow'!C16 -> 9779.5808 | D30: ='Cash Flow'!D16 -> 50828.638 | E30: ='Cash Flow'!E16 -> 60367.954 | F30: ='Cash Flow'!F16 -> 70089.101 | H30: =INDEX(Monthly!$C$79:$BJ$79,($R$2-1)*12+1) -> 204279.51 | I30: =INDEX(Monthly!$C$79:$BJ$79,($R$2-1)*12+2) -> -27752.421 | J30: =INDEX(Monthly!$C$79:$BJ$79,($R$2-1)*12+3) -> -25133.048 | K30: =INDEX(Monthly!$C$79:$BJ$79,($R$2-1)*12+4) -> -22670.123 | L30: =INDEX(Monthly!$C$79:$BJ$79,($R$2-1)*12+5) -> -20354.26 | M30: =INDEX(Monthly!$C$79:$BJ$79,($R$2-1)*12+6) -> -18176.634 | N30: =INDEX(Monthly!$C$79:$BJ$79,($R$2-1)*12+7) -> -16128.951 | O30: =INDEX(Monthly!$C$79:$BJ$79,($R$2-1)*12+8) -> -14203.415 | P30: =INDEX(Monthly!$C$79:$BJ$79,($R$2-1)*12+9) -> -12392.697 | Q30: =INDEX(Monthly!$C$79:$BJ$79,($R$2-1)*12+10) -> -10689.908 | R30: =INDEX(Monthly!$C$79:$BJ$79,($R$2-1)*12+11) -> -9088.5714 | S30: =INDEX(Monthly!$C$79:$BJ$79,($R$2-1)*12+12) -> -7582.601
A31: Closing cash | B31: ='Cash Flow'!B18 -> 20106.884 | C31: ='Cash Flow'!C18 -> 29886.464 | D31: ='Cash Flow'!D18 -> 80715.102 | E31: ='Cash Flow'!E18 -> 141083.06 | F31: ='Cash Flow'!F18 -> 211172.16 | H31: =INDEX(Monthly!$C$81:$BJ$81,($R$2-1)*12+1) -> 204279.51 | I31: =INDEX(Monthly!$C$81:$BJ$81,($R$2-1)*12+2) -> 176527.09 | J31: =INDEX(Monthly!$C$81:$BJ$81,($R$2-1)*12+3) -> 151394.04 | K31: =INDEX(Monthly!$C$81:$BJ$81,($R$2-1)*12+4) -> 128723.92 | L31: =INDEX(Monthly!$C$81:$BJ$81,($R$2-1)*12+5) -> 108369.66 | M31: =INDEX(Monthly!$C$81:$BJ$81,($R$2-1)*12+6) -> 90193.027 | N31: =INDEX(Monthly!$C$81:$BJ$81,($R$2-1)*12+7) -> 74064.076 | O31: =INDEX(Monthly!$C$81:$BJ$81,($R$2-1)*12+8) -> 59860.661 | P31: =INDEX(Monthly!$C$81:$BJ$81,($R$2-1)*12+9) -> 47467.964 | Q31: =INDEX(Monthly!$C$81:$BJ$81,($R$2-1)*12+10) -> 36778.056 | R31: =INDEX(Monthly!$C$81:$BJ$81,($R$2-1)*12+11) -> 27689.485 | S31: =INDEX(Monthly!$C$81:$BJ$81,($R$2-1)*12+12) -> 20106.884
A39: Balance sheet at year end ($'000) | H39: ="Balance sheet at month end ($'000) — Year "&$R$2 -> Balance sheet at month end ($'000) — Year 1
B40: 1 | C40: 2 | D40: 3 | E40: 4 | F40: 5 | H40: =INDEX(Monthly!$C$4:$BJ$4,($R$2-1)*12+1) -> 1 | I40: =INDEX(Monthly!$C$4:$BJ$4,($R$2-1)*12+2) -> 2 | J40: =INDEX(Monthly!$C$4:$BJ$4,($R$2-1)*12+3) -> 3 | K40: =INDEX(Monthly!$C$4:$BJ$4,($R$2-1)*12+4) -> 4 | L40: =INDEX(Monthly!$C$4:$BJ$4,($R$2-1)*12+5) -> 5 | M40: =INDEX(Monthly!$C$4:$BJ$4,($R$2-1)*12+6) -> 6 | N40: =INDEX(Monthly!$C$4:$BJ$4,($R$2-1)*12+7) -> 7 | O40: =INDEX(Monthly!$C$4:$BJ$4,($R$2-1)*12+8) -> 8 | P40: =INDEX(Monthly!$C$4:$BJ$4,($R$2-1)*12+9) -> 9 | Q40: =INDEX(Monthly!$C$4:$BJ$4,($R$2-1)*12+10) -> 10 | R40: =INDEX(Monthly!$C$4:$BJ$4,($R$2-1)*12+11) -> 11 | S40: =INDEX(Monthly!$C$4:$BJ$4,($R$2-1)*12+12) -> 12
A41: Cash | B41: ='Balance Sheet'!B5 -> 20106.884 | C41: ='Balance Sheet'!C5 -> 29886.464 | D41: ='Balance Sheet'!D5 -> 80715.102 | E41: ='Balance Sheet'!E5 -> 141083.06 | F41: ='Balance Sheet'!F5 -> 211172.16 | H41: =INDEX(Monthly!$C$81:$BJ$81,($R$2-1)*12+1) -> 204279.51 | I41: =INDEX(Monthly!$C$81:$BJ$81,($R$2-1)*12+2) -> 176527.09 | J41: =INDEX(Monthly!$C$81:$BJ$81,($R$2-1)*12+3) -> 151394.04 | K41: =INDEX(Monthly!$C$81:$BJ$81,($R$2-1)*12+4) -> 128723.92 | L41: =INDEX(Monthly!$C$81:$BJ$81,($R$2-1)*12+5) -> 108369.66 | M41: =INDEX(Monthly!$C$81:$BJ$81,($R$2-1)*12+6) -> 90193.027 | N41: =INDEX(Monthly!$C$81:$BJ$81,($R$2-1)*12+7) -> 74064.076 | O41: =INDEX(Monthly!$C$81:$BJ$81,($R$2-1)*12+8) -> 59860.661 | P41: =INDEX(Monthly!$C$81:$BJ$81,($R$2-1)*12+9) -> 47467.964 | Q41: =INDEX(Monthly!$C$81:$BJ$81,($R$2-1)*12+10) -> 36778.056 | R41: =INDEX(Monthly!$C$81:$BJ$81,($R$2-1)*12+11) -> 27689.485 | S41: =INDEX(Monthly!$C$81:$BJ$81,($R$2-1)*12+12) -> 20106.884
A42: Accounts receivable | B42: ='Balance Sheet'!B6 -> 0 | C42: ='Balance Sheet'!C6 -> 0 | D42: ='Balance Sheet'!D6 -> 0 | E42: ='Balance Sheet'!E6 -> 0 | F42: ='Balance Sheet'!F6 -> 0 | H42: =INDEX(Monthly!$C$67:$BJ$67,($R$2-1)*12+1) -> 0 | I42: =INDEX(Monthly!$C$67:$BJ$67,($R$2-1)*12+2) -> 0 | J42: =INDEX(Monthly!$C$67:$BJ$67,($R$2-1)*12+3) -> 0 | K42: =INDEX(Monthly!$C$67:$BJ$67,($R$2-1)*12+4) -> 0 | L42: =INDEX(Monthly!$C$67:$BJ$67,($R$2-1)*12+5) -> 0 | M42: =INDEX(Monthly!$C$67:$BJ$67,($R$2-1)*12+6) -> 0 | N42: =INDEX(Monthly!$C$67:$BJ$67,($R$2-1)*12+7) -> 0 | O42: =INDEX(Monthly!$C$67:$BJ$67,($R$2-1)*12+8) -> 0 | P42: =INDEX(Monthly!$C$67:$BJ$67,($R$2-1)*12+9) -> 0 | Q42: =INDEX(Monthly!$C$67:$BJ$67,($R$2-1)*12+10) -> 0 | R42: =INDEX(Monthly!$C$67:$BJ$67,($R$2-1)*12+11) -> 0 | S42: =INDEX(Monthly!$C$67:$BJ$67,($R$2-1)*12+12) -> 0
A43: Inventory | B43: ='Balance Sheet'!B7 -> 4007.6367 | C43: ='Balance Sheet'!C7 -> 4547.45 | D43: ='Balance Sheet'!D7 -> 4683.8735 | E43: ='Balance Sheet'!E7 -> 4824.3897 | F43: ='Balance Sheet'!F7 -> 4969.1214 | H43: =INDEX(Monthly!$C$68:$BJ$68,($R$2-1)*12+1) -> 3138.45 | I43: =INDEX(Monthly!$C$68:$BJ$68,($R$2-1)*12+2) -> 3244.083 | J43: =INDEX(Monthly!$C$68:$BJ$68,($R$2-1)*12+3) -> 3343.378 | K43: =INDEX(Monthly!$C$68:$BJ$68,($R$2-1)*12+4) -> 3436.7153 | L43: =INDEX(Monthly!$C$68:$BJ$68,($R$2-1)*12+5) -> 3524.4524 | M43: =INDEX(Monthly!$C$68:$BJ$68,($R$2-1)*12+6) -> 3606.9253 | N43: =INDEX(Monthly!$C$68:$BJ$68,($R$2-1)*12+7) -> 3684.4498 | O43: =INDEX(Monthly!$C$68:$BJ$68,($R$2-1)*12+8) -> 3757.3228 | P43: =INDEX(Monthly!$C$68:$BJ$68,($R$2-1)*12+9) -> 3825.8234 | Q43: =INDEX(Monthly!$C$68:$BJ$68,($R$2-1)*12+10) -> 3890.214 | R43: =INDEX(Monthly!$C$68:$BJ$68,($R$2-1)*12+11) -> 3950.7412 | S43: =INDEX(Monthly!$C$68:$BJ$68,($R$2-1)*12+12) -> 4007.6367
A44: Net fixed assets | B44: ='Balance Sheet'!B8 -> 214285.71 | C44: ='Balance Sheet'!C8 -> 178571.43 | D44: ='Balance Sheet'!D8 -> 142857.14 | E44: ='Balance Sheet'!E8 -> 107142.86 | F44: ='Balance Sheet'!F8 -> 71428.571 | H44: =INDEX(Monthly!$C$58:$BJ$58,($R$2-1)*12+1) -> 247023.81 | I44: =INDEX(Monthly!$C$58:$BJ$58,($R$2-1)*12+2) -> 244047.62 | J44: =INDEX(Monthly!$C$58:$BJ$58,($R$2-1)*12+3) -> 241071.43 | K44: =INDEX(Monthly!$C$58:$BJ$58,($R$2-1)*12+4) -> 238095.24 | L44: =INDEX(Monthly!$C$58:$BJ$58,($R$2-1)*12+5) -> 235119.05 | M44: =INDEX(Monthly!$C$58:$BJ$58,($R$2-1)*12+6) -> 232142.86 | N44: =INDEX(Monthly!$C$58:$BJ$58,($R$2-1)*12+7) -> 229166.67 | O44: =INDEX(Monthly!$C$58:$BJ$58,($R$2-1)*12+8) -> 226190.48 | P44: =INDEX(Monthly!$C$58:$BJ$58,($R$2-1)*12+9) -> 223214.29 | Q44: =INDEX(Monthly!$C$58:$BJ$58,($R$2-1)*12+10) -> 220238.1 | R44: =INDEX(Monthly!$C$58:$BJ$58,($R$2-1)*12+11) -> 217261.9 | S44: =INDEX(Monthly!$C$58:$BJ$58,($R$2-1)*12+12) -> 214285.71
A45: Total assets | B45: ='Balance Sheet'!B9 -> 238400.23 | C45: ='Balance Sheet'!C9 -> 213005.34 | D45: ='Balance Sheet'!D9 -> 228256.12 | E45: ='Balance Sheet'!E9 -> 253050.3 | F45: ='Balance Sheet'!F9 -> 287569.85 | H45: =INDEX(Monthly!$C$95:$BJ$95,($R$2-1)*12+1) -> 454441.77 | I45: =INDEX(Monthly!$C$95:$BJ$95,($R$2-1)*12+2) -> 423818.79 | J45: =INDEX(Monthly!$C$95:$BJ$95,($R$2-1)*12+3) -> 395808.85 | K45: =INDEX(Monthly!$C$95:$BJ$95,($R$2-1)*12+4) -> 370255.87 | L45: =INDEX(Monthly!$C$95:$BJ$95,($R$2-1)*12+5) -> 347013.16 | M45: =INDEX(Monthly!$C$95:$BJ$95,($R$2-1)*12+6) -> 325942.81 | N45: =INDEX(Monthly!$C$95:$BJ$95,($R$2-1)*12+7) -> 306915.19 | O45: =INDEX(Monthly!$C$95:$BJ$95,($R$2-1)*12+8) -> 289808.46 | P45: =INDEX(Monthly!$C$95:$BJ$95,($R$2-1)*12+9) -> 274508.07 | Q45: =INDEX(Monthly!$C$95:$BJ$95,($R$2-1)*12+10) -> 260906.37 | R45: =INDEX(Monthly!$C$95:$BJ$95,($R$2-1)*12+11) -> 248902.13 | S45: =INDEX(Monthly!$C$95:$BJ$95,($R$2-1)*12+12) -> 238400.23
A46: Accounts payable | B46: ='Balance Sheet'!B10 -> 8015.2734 | C46: ='Balance Sheet'!C10 -> 9094.9 | D46: ='Balance Sheet'!D10 -> 9367.747 | E46: ='Balance Sheet'!E10 -> 9648.7794 | F46: ='Balance Sheet'!F10 -> 9938.2428 | H46: =INDEX(Monthly!$C$69:$BJ$69,($R$2-1)*12+1) -> 6276.9 | I46: =INDEX(Monthly!$C$69:$BJ$69,($R$2-1)*12+2) -> 6488.166 | J46: =INDEX(Monthly!$C$69:$BJ$69,($R$2-1)*12+3) -> 6686.756 | K46: =INDEX(Monthly!$C$69:$BJ$69,($R$2-1)*12+4) -> 6873.4307 | L46: =INDEX(Monthly!$C$69:$BJ$69,($R$2-1)*12+5) -> 7048.9048 | M46: =INDEX(Monthly!$C$69:$BJ$69,($R$2-1)*12+6) -> 7213.8505 | N46: =INDEX(Monthly!$C$69:$BJ$69,($R$2-1)*12+7) -> 7368.8995 | O46: =INDEX(Monthly!$C$69:$BJ$69,($R$2-1)*12+8) -> 7514.6455 | P46: =INDEX(Monthly!$C$69:$BJ$69,($R$2-1)*12+9) -> 7651.6468 | Q46: =INDEX(Monthly!$C$69:$BJ$69,($R$2-1)*12+10) -> 7780.428 | R46: =INDEX(Monthly!$C$69:$BJ$69,($R$2-1)*12+11) -> 7901.4823 | S46: =INDEX(Monthly!$C$69:$BJ$69,($R$2-1)*12+12) -> 8015.2734
A47: Loan | B47: ='Balance Sheet'!B11 -> 130357.14 | C47: ='Balance Sheet'!C11 -> 108928.57 | D47: ='Balance Sheet'!D11 -> 87500 | E47: ='Balance Sheet'!E11 -> 66071.429 | F47: ='Balance Sheet'!F11 -> 44642.857 | H47: =INDEX(Monthly!$C$64:$BJ$64,($R$2-1)*12+1) -> 150000 | I47: =INDEX(Monthly!$C$64:$BJ$64,($R$2-1)*12+2) -> 148214.29 | J47: =INDEX(Monthly!$C$64:$BJ$64,($R$2-1)*12+3) -> 146428.57 | K47: =INDEX(Monthly!$C$64:$BJ$64,($R$2-1)*12+4) -> 144642.86 | L47: =INDEX(Monthly!$C$64:$BJ$64,($R$2-1)*12+5) -> 142857.14 | M47: =INDEX(Monthly!$C$64:$BJ$64,($R$2-1)*12+6) -> 141071.43 | N47: =INDEX(Monthly!$C$64:$BJ$64,($R$2-1)*12+7) -> 139285.71 | O47: =INDEX(Monthly!$C$64:$BJ$64,($R$2-1)*12+8) -> 137500 | P47: =INDEX(Monthly!$C$64:$BJ$64,($R$2-1)*12+9) -> 135714.29 | Q47: =INDEX(Monthly!$C$64:$BJ$64,($R$2-1)*12+10) -> 133928.57 | R47: =INDEX(Monthly!$C$64:$BJ$64,($R$2-1)*12+11) -> 132142.86 | S47: =INDEX(Monthly!$C$64:$BJ$64,($R$2-1)*12+12) -> 130357.14
A48: Total liabilities | B48: ='Balance Sheet'!B12 -> 138372.42 | C48: ='Balance Sheet'!C12 -> 118023.47 | D48: ='Balance Sheet'!D12 -> 96867.747 | E48: ='Balance Sheet'!E12 -> 75720.208 | F48: ='Balance Sheet'!F12 -> 54581.1 | H48: =INDEX(Monthly!$C$96:$BJ$96,($R$2-1)*12+1) -> 156276.9 | I48: =INDEX(Monthly!$C$96:$BJ$96,($R$2-1)*12+2) -> 154702.45 | J48: =INDEX(Monthly!$C$96:$BJ$96,($R$2-1)*12+3) -> 153115.33 | K48: =INDEX(Monthly!$C$96:$BJ$96,($R$2-1)*12+4) -> 151516.29 | L48: =INDEX(Monthly!$C$96:$BJ$96,($R$2-1)*12+5) -> 149906.05 | M48: =INDEX(Monthly!$C$96:$BJ$96,($R$2-1)*12+6) -> 148285.28 | N48: =INDEX(Monthly!$C$96:$BJ$96,($R$2-1)*12+7) -> 146654.61 | O48: =INDEX(Monthly!$C$96:$BJ$96,($R$2-1)*12+8) -> 145014.65 | P48: =INDEX(Monthly!$C$96:$BJ$96,($R$2-1)*12+9) -> 143365.93 | Q48: =INDEX(Monthly!$C$96:$BJ$96,($R$2-1)*12+10) -> 141709 | R48: =INDEX(Monthly!$C$96:$BJ$96,($R$2-1)*12+11) -> 140044.34 | S48: =INDEX(Monthly!$C$96:$BJ$96,($R$2-1)*12+12) -> 138372.42
A49: Paid-in capital | B49: ='Balance Sheet'!B13 -> 330000 | C49: ='Balance Sheet'!C13 -> 330000 | D49: ='Balance Sheet'!D13 -> 330000 | E49: ='Balance Sheet'!E13 -> 330000 | F49: ='Balance Sheet'!F13 -> 330000 | H49: =INDEX(Monthly!$C$93:$BJ$93,($R$2-1)*12+1) -> 330000 | I49: =INDEX(Monthly!$C$93:$BJ$93,($R$2-1)*12+2) -> 330000 | J49: =INDEX(Monthly!$C$93:$BJ$93,($R$2-1)*12+3) -> 330000 | K49: =INDEX(Monthly!$C$93:$BJ$93,($R$2-1)*12+4) -> 330000 | L49: =INDEX(Monthly!$C$93:$BJ$93,($R$2-1)*12+5) -> 330000 | M49: =INDEX(Monthly!$C$93:$BJ$93,($R$2-1)*12+6) -> 330000 | N49: =INDEX(Monthly!$C$93:$BJ$93,($R$2-1)*12+7) -> 330000 | O49: =INDEX(Monthly!$C$93:$BJ$93,($R$2-1)*12+8) -> 330000 | P49: =INDEX(Monthly!$C$93:$BJ$93,($R$2-1)*12+9) -> 330000 | Q49: =INDEX(Monthly!$C$93:$BJ$93,($R$2-1)*12+10) -> 330000 | R49: =INDEX(Monthly!$C$93:$BJ$93,($R$2-1)*12+11) -> 330000 | S49: =INDEX(Monthly!$C$93:$BJ$93,($R$2-1)*12+12) -> 330000
A50: Retained earnings | B50: ='Balance Sheet'!B14 -> -229972.18 | C50: ='Balance Sheet'!C14 -> -235018.13 | D50: ='Balance Sheet'!D14 -> -198611.63 | E50: ='Balance Sheet'!E14 -> -152669.91 | F50: ='Balance Sheet'!F14 -> -97011.25 | H50: =INDEX(Monthly!$C$94:$BJ$94,($R$2-1)*12+1) -> -31835.127 | I50: =INDEX(Monthly!$C$94:$BJ$94,($R$2-1)*12+2) -> -60883.657 | J50: =INDEX(Monthly!$C$94:$BJ$94,($R$2-1)*12+3) -> -87306.477 | K50: =INDEX(Monthly!$C$94:$BJ$94,($R$2-1)*12+4) -> -111260.41 | L50: =INDEX(Monthly!$C$94:$BJ$94,($R$2-1)*12+5) -> -132892.89 | M50: =INDEX(Monthly!$C$94:$BJ$94,($R$2-1)*12+6) -> -152342.47 | N50: =INDEX(Monthly!$C$94:$BJ$94,($R$2-1)*12+7) -> -169739.42 | O50: =INDEX(Monthly!$C$94:$BJ$94,($R$2-1)*12+8) -> -185206.19 | P50: =INDEX(Monthly!$C$94:$BJ$94,($R$2-1)*12+9) -> -198857.86 | Q50: =INDEX(Monthly!$C$94:$BJ$94,($R$2-1)*12+10) -> -210802.63 | R50: =INDEX(Monthly!$C$94:$BJ$94,($R$2-1)*12+11) -> -221142.21 | S50: =INDEX(Monthly!$C$94:$BJ$94,($R$2-1)*12+12) -> -229972.18
...

Sheet Break-even
A1: Startup costs, funding need and break-even | H1: =HYPERLINK("#'Cover'!A1","◂ Contents") -> ◂ Contents
A2: Live for the selected scenario. Periods are counted in months from the start of the plan.
A3: Scenario shown | B3: =CHOOSE(Dashboard!$B$4,"Low","Base","High") -> Base
A5: Startup costs & funding need (up to the lowest cash point)
A6: Lowest cash point (month #) | B6: =MATCH(MIN(Monthly!$C$81:$BJ$81),Monthly!$C$81:$BJ$81,0) -> 16
A7: Capital spending up to the lowest cash point | B7: =SUMPRODUCT(--(Monthly!$C$4:$BJ$4<=$B$6),Monthly!$C$54:$BJ$54) -> 250000
A8: Operating cash burn up to the lowest cash point | B8: =-SUMPRODUCT(--(Monthly!$C$4:$BJ$4<=$B$6),Monthly!$C$75:$BJ$75) -> 195773.92 | D8: Losses and working capital before the business funds itself
A9: Loan repayments up to the lowest cash point | B9: =-SUMPRODUCT(--(Monthly!$C$4:$BJ$4<=$B$6),Monthly!$C$63:$BJ$63) -> 26785.714
A10: Total uses of funds | B10: =B7+B8+B9 -> 472559.64
A11: Minimum cash buffer to keep | B11: =Inputs!$E$69 -> 111000 | D11: Input on the Inputs sheet
A12: Funding required (uses + buffer) | B12: =B10+B11 -> 583559.64
A14: Equity raised | B14: =Inputs!$E$54 -> 330000
A15: Loan drawn | B15: =Inputs!$E$55 -> 150000
A16: Total sources of funds | B16: =B14+B15 -> 480000
A17: Funding surplus / (shortfall) | B17: =B16-B12 -> -103559.64 | D17: Negative = raise at least this much more
A18: Lowest cash balance in the plan | B18: =MIN(Monthly!$C$81:$BJ$81) -> 7440.3636 | D18: Equals sources minus uses
A20: Break-even timing
A21: First month with positive EBITDA (month #) | B21: =IFERROR(MATCH(1,Monthly!$C$82:$BJ$82,0),"Not within horizon") -> 15
A22: First month with positive net income (month #) | B22: =IFERROR(MATCH(1,Monthly!$C$85:$BJ$85,0),"Not within horizon") -> 18
A23: Cash invested paid back (month #) | B23: =IF(MIN(Monthly!$C$87:$BJ$87)>=0,"No investment to pay back",IFERROR(MATCH(1,Monthly!$C$89:$BJ$89,0),"Not within horizon")) -> Not within horizon | D23: Cumulative operating + investing cash flow back to zero
A25: Annual break-even revenue
A26: Year # | B26: 1 | C26: 2 | D26: 3 | E26: 4 | F26: 5
B27: Year 1 | C27: Year 2 | D27: Year 3 | E27: Year 4 | F27: Year 5
A28: Revenue | B28: =SUMIF(Monthly!$C$5:$BJ$5,B$26,Monthly!$C$24:$BJ$24) -> 393075.46 | C28: =SUMIF(Monthly!$C$5:$BJ$5,C$26,Monthly!$C$24:$BJ$24) -> 663933.88 | D28: =SUMIF(Monthly!$C$5:$BJ$5,D$26,Monthly!$C$24:$BJ$24) -> 722638.4 | E28: =SUMIF(Monthly!$C$5:$BJ$5,E$26,Monthly!$C$24:$BJ$24) -> 744317.55 | F28: =SUMIF(Monthly!$C$5:$BJ$5,F$26,Monthly!$C$24:$BJ$24) -> 766647.08
A29: Gross profit | B29: =SUMIF(Monthly!$C$5:$BJ$5,B$26,Monthly!$C$31:$BJ$31) -> 262844.88 | C29: =SUMIF(Monthly!$C$5:$BJ$5,C$26,Monthly!$C$31:$BJ$31) -> 504280.12 | D29: =SUMIF(Monthly!$C$5:$BJ$5,D$26,Monthly!$C$31:$BJ$31) -> 554018.95 | E29: =SUMIF(Monthly!$C$5:$BJ$5,E$26,Monthly!$C$31:$BJ$31) -> 570639.52 | F29: =SUMIF(Monthly!$C$5:$BJ$5,F$26,Monthly!$C$31:$BJ$31) -> 587758.71
A30: Gross margin (contribution) | B30: =IF(B28=0,0,B29/B28) -> 0.6686881 | C30: =IF(C28=0,0,C29/C28) -> 0.75953364 | D30: =IF(D28=0,0,D29/D28) -> 0.76666138 | E30: =IF(E28=0,0,E29/E28) -> 0.76666138 | F30: =IF(F28=0,0,F29/F28) -> 0.76666138
A31: Operating expenses (treated as fixed) | B31: =-SUMIF(Monthly!$C$5:$BJ$5,B$26,Monthly!$C$41:$BJ$41) -> 445823.02 | C31: =-SUMIF(Monthly!$C$5:$BJ$5,C$26,Monthly!$C$41:$BJ$41) -> 464040.36 | D31: =-SUMIF(Monthly!$C$5:$BJ$5,D$26,Monthly!$C$41:$BJ$41) -> 474041.03 | E31: =-SUMIF(Monthly!$C$5:$BJ$5,E$26,Monthly!$C$41:$BJ$41) -> 482840.66 | F31: =-SUMIF(Monthly!$C$5:$BJ$5,F$26,Monthly!$C$41:$BJ$41) -> 491957.2
A32: Break-even revenue (EBITDA = 0) | B32: =IF(B30>0,B31/B30,"n/a") -> 666712.95 | C32: =IF(C30>0,C31/C30,"n/a") -> 610954.31 | D32: =IF(D30>0,D31/D30,"n/a") -> 618318.64 | E32: =IF(E30>0,E31/E30,"n/a") -> 629796.5 | F32: =IF(F30>0,F31/F30,"n/a") -> 641687.72
A33: Margin of safety (revenue above break-even) | B33: =IF(AND(ISNUMBER(B32),B28>0),(B28-B32)/B28,"n/a") -> -0.69614493 | C33: =IF(AND(ISNUMBER(C32),C28>0),(C28-C32)/C28,"n/a") -> 0.079796458 | D33: =IF(AND(ISNUMBER(D32),D28>0),(D28-D32)/D28,"n/a") -> 0.14435955 | E33: =IF(AND(ISNUMBER(E32),E28>0),(E28-E32)/E28,"n/a") -> 0.15386047 | F33: =IF(AND(ISNUMBER(F32),F28>0),(F28-F32)/F28,"n/a") -> 0.16299463
A35: Simplification: cost of sales is treated as variable and operating expenses as fixed, so break-even revenue = operating expenses ÷ gross margin.

Sheet Valuation
A1: Discounted cash flow valuation | H1: =HYPERLINK("#'Cover'!A1","◂ Contents") -> ◂ Contents
A2: Enterprise value at the start of the plan, before the funding raised in period 1. Year-end discounting.
A3: Scenario shown | B3: =CHOOSE(Dashboard!$B$4,"Low","Base","High") -> Base
A5: Assumptions (active scenario, from the Inputs sheet)
A6: Discount rate (WACC) | B6: =Inputs!$E$72 -> 0.25
A7: Terminal growth rate | B7: =Inputs!$E$73 -> 0.02
A8: Exit multiple (EV ÷ final-year EBITDA) | B8: =Inputs!$E$74 -> 4
A9: Tax rate (for the interest tax shield) | B9: =Inputs!$E$66 -> 0.21
A10: Sensitivity step: WACC | B10: =Inputs!$E$75 -> 0.01
A11: Sensitivity step: terminal growth | B11: =Inputs!$E$76 -> 0.005
A13: Free cash flow by year
A14: Year # | B14: 1 | C14: 2 | D14: 3 | E14: 4 | F14: 5
B15: Year 1 | C15: Year 2 | D15: Year 3 | E15: Year 4 | F15: Year 5
A16: EBITDA | B16: =SUMIF(Monthly!$C$5:$BJ$5,B$14,Monthly!$C$42:$BJ$42) -> -182978.13 | C16: =SUMIF(Monthly!$C$5:$BJ$5,C$14,Monthly!$C$42:$BJ$42) -> 40239.768 | D16: =SUMIF(Monthly!$C$5:$BJ$5,D$14,Monthly!$C$42:$BJ$42) -> 79977.928 | E16: =SUMIF(Monthly!$C$5:$BJ$5,E$14,Monthly!$C$42:$BJ$42) -> 87798.866 | F16: =SUMIF(Monthly!$C$5:$BJ$5,F$14,Monthly!$C$42:$BJ$42) -> 95801.512
A17: Unlevered free cash flow | B17: =SUMIF(Monthly!$C$5:$BJ$5,B$14,Monthly!$C$90:$BJ$90) -> -431339.25 | C17: =SUMIF(Monthly!$C$5:$BJ$5,C$14,Monthly!$C$90:$BJ$90) -> 38769.581 | D17: =SUMIF(Monthly!$C$5:$BJ$5,D$14,Monthly!$C$90:$BJ$90) -> 78464.352 | E17: =SUMIF(Monthly!$C$5:$BJ$5,E$14,Monthly!$C$90:$BJ$90) -> 86649.382 | F17: =SUMIF(Monthly!$C$5:$BJ$5,F$14,Monthly!$C$90:$BJ$90) -> 95016.244
A18: Discount factor | B18: =1/(1+Inputs!$E$72)^B$14 -> 0.8 | C18: =1/(1+Inputs!$E$72)^C$14 -> 0.64 | D18: =1/(1+Inputs!$E$72)^D$14 -> 0.512 | E18: =1/(1+Inputs!$E$72)^E$14 -> 0.4096 | F18: =1/(1+Inputs!$E$72)^F$14 -> 0.32768
A19: Present value of free cash flow | B19: =B17*B18 -> -345071.4 | C19: =C17*C18 -> 24812.532 | D19: =D17*D18 -> 40173.748 | E19: =E17*E18 -> 35491.587 | F19: =F17*F18 -> 31134.923
A21: Enterprise value
B22: Perpetual growth | C22: Exit multiple
A23: Present value of the plan's free cash flows | B23: =SUM($B$19:$F$19) -> -213458.61 | C23: =B23 -> -213458.61
A24: Final-year free cash flow | final-year EBITDA | B24: =$F$17 -> 95016.244 | C24: =$F$16 -> 95801.512
A25: Terminal value at the end of year 5 | B25: =IF($B$6>$B$7,B24*(1+$B$7)/($B$6-$B$7),0) -> 421376.39 | C25: =C24*$B$8 -> 383206.05
A26: Present value of the terminal value | B26: =B25/(1+$B$6)^$F$14 -> 138076.61 | C26: =C25/(1+$B$6)^$F$14 -> 125568.96
A27: Enterprise value | B27: =B23+B26 -> -75381.994 | C27: =C23+C26 -> -87889.65
A28: Terminal value share of enterprise value | B28: =IF(B27<>0,B26/B27,0) -> -1.8316922 | C28: =IF(C27<>0,C26/C27,0) -> -1.4287115
A29: Cross-check: implied exit multiple | implied perpetual growth | B29: =IF(C24>0,B25/C24,"n/a") -> 4.3984315 | C29: =IF(C25+B24<>0,(C25*$B$6-B24)/(C25+B24),"n/a") -> 0.0016420571
A30: Enterprise value — average of the two methods | B30: =AVERAGE(B27,C27) -> -81635.822
A32: Sensitivity: enterprise value (perpetual growth) by WACC and terminal growth
A33: WACC ↓ · terminal growth → | B33: =$B$7+(-2)*$B$11 -> 0.01 | C33: =$B$7+(-1)*$B$11 -> 0.015 | D33: =$B$7+(0)*$B$11 -> 0.02 | E33: =$B$7+(1)*$B$11 -> 0.025 | F33: =$B$7+(2)*$B$11 -> 0.03
A34: =$B$6+(-2)*$B$10 -> 0.23 | B34: =IF($A34>B$33,SUMPRODUCT($B$17:$F$17/(1+$A34)^$B$14:$F$14)+$F$17*(1+B$33)/($A34-B$33)/(1+$A34)^$F$14,"n/a") -> -56341.392 | C34: =IF($A34>C$33,SUMPRODUCT($B$17:$F$17/(1+$A34)^$B$14:$F$14)+$F$17*(1+C$33)/($A34-C$33)/(1+$A34)^$F$14,"n/a") -> -51953.193 | D34: =IF($A34>D$33,SUMPRODUCT($B$17:$F$17/(1+$A34)^$B$14:$F$14)+$F$17*(1+D$33)/($A34-D$33)/(1+$A34)^$F$14,"n/a") -> -47356.033 | E34: =IF($A34>E$33,SUMPRODUCT($B$17:$F$17/(1+$A34)^$B$14:$F$14)+$F$17*(1+E$33)/($A34-E$33)/(1+$A34)^$F$14,"n/a") -> -42534.621 | F34: =IF($A34>F$33,SUMPRODUCT($B$17:$F$17/(1+$A34)^$B$14:$F$14)+$F$17*(1+F$33)/($A34-F$33)/(1+$A34)^$F$14,"n/a") -> -37472.138
A35: =$B$6+(-1)*$B$10 -> 0.24 | B35: =IF($A35>B$33,SUMPRODUCT($B$17:$F$17/(1+$A35)^$B$14:$F$14)+$F$17*(1+B$33)/($A35-B$33)/(1+$A35)^$F$14,"n/a") -> -70099.571 | C35: =IF($A35>C$33,SUMPRODUCT($B$17:$F$17/(1+$A35)^$B$14:$F$14)+$F$17*(1+C$33)/($A35-C$33)/(1+$A35)^$F$14,"n/a") -> -66216.541 | D35: =IF($A35>D$33,SUMPRODUCT($B$17:$F$17/(1+$A35)^$B$14:$F$14)+$F$17*(1+D$33)/($A35-D$33)/(1+$A35)^$F$14,"n/a") -> -62157.01 | E35: =IF($A35>E$33,SUMPRODUCT($B$17:$F$17/(1+$A35)^$B$14:$F$14)+$F$17*(1+E$33)/($A35-E$33)/(1+$A35)^$F$14,"n/a") -> -57908.663 | F35: =IF($A35>F$33,SUMPRODUCT($B$17:$F$17/(1+$A35)^$B$14:$F$14)+$F$17*(1+F$33)/($A35-F$33)/(1+$A35)^$F$14,"n/a") -> -53458.013
A36: =$B$6+(0)*$B$10 -> 0.25 | B36: =IF($A36>B$33,SUMPRODUCT($B$17:$F$17/(1+$A36)^$B$14:$F$14)+$F$17*(1+B$33)/($A36-B$33)/(1+$A36)^$F$14,"n/a") -> -82432.475 | C36: =IF($A36>C$33,SUMPRODUCT($B$17:$F$17/(1+$A36)^$B$14:$F$14)+$F$17*(1+C$33)/($A36-C$33)/(1+$A36)^$F$14,"n/a") -> -78982.239 | D36: =IF($A36>D$33,SUMPRODUCT($B$17:$F$17/(1+$A36)^$B$14:$F$14)+$F$17*(1+D$33)/($A36-D$33)/(1+$A36)^$F$14,"n/a") -> -75381.994 | E36: =IF($A36>E$33,SUMPRODUCT($B$17:$F$17/(1+$A36)^$B$14:$F$14)+$F$17*(1+E$33)/($A36-E$33)/(1+$A36)^$F$14,"n/a") -> -71621.738 | F36: =IF($A36>F$33,SUMPRODUCT($B$17:$F$17/(1+$A36)^$B$14:$F$14)+$F$17*(1+F$33)/($A36-F$33)/(1+$A36)^$F$14,"n/a") -> -67690.561
A37: =$B$6+(1)*$B$10 -> 0.26 | B37: =IF($A37>B$33,SUMPRODUCT($B$17:$F$17/(1+$A37)^$B$14:$F$14)+$F$17*(1+B$33)/($A37-B$33)/(1+$A37)^$F$14,"n/a") -> -93518.391 | C37: =IF($A37>C$33,SUMPRODUCT($B$17:$F$17/(1+$A37)^$B$14:$F$14)+$F$17*(1+C$33)/($A37-C$33)/(1+$A37)^$F$14,"n/a") -> -90441.022 | D37: =IF($A37>D$33,SUMPRODUCT($B$17:$F$17/(1+$A37)^$B$14:$F$14)+$F$17*(1+D$33)/($A37-D$33)/(1+$A37)^$F$14,"n/a") -> -87235.429 | E37: =IF($A37>E$33,SUMPRODUCT($B$17:$F$17/(1+$A37)^$B$14:$F$14)+$F$17*(1+E$33)/($A37-E$33)/(1+$A37)^$F$14,"n/a") -> -83893.428 | F37: =IF($A37>F$33,SUMPRODUCT($B$17:$F$17/(1+$A37)^$B$14:$F$14)+$F$17*(1+F$33)/($A37-F$33)/(1+$A37)^$F$14,"n/a") -> -80406.123
A38: =$B$6+(2)*$B$10 -> 0.27 | B38: =IF($A38>B$33,SUMPRODUCT($B$17:$F$17/(1+$A38)^$B$14:$F$14)+$F$17*(1+B$33)/($A38-B$33)/(1+$A38)^$F$14,"n/a") -> -103507.93 | C38: =IF($A38>C$33,SUMPRODUCT($B$17:$F$17/(1+$A38)^$B$14:$F$14)+$F$17*(1+C$33)/($A38-C$33)/(1+$A38)^$F$14,"n/a") -> -100753.45 | D38: =IF($A38>D$33,SUMPRODUCT($B$17:$F$17/(1+$A38)^$B$14:$F$14)+$F$17*(1+D$33)/($A38-D$33)/(1+$A38)^$F$14,"n/a") -> -97888.789 | E38: =IF($A38>E$33,SUMPRODUCT($B$17:$F$17/(1+$A38)^$B$14:$F$14)+$F$17*(1+E$33)/($A38-E$33)/(1+$A38)^$F$14,"n/a") -> -94907.207 | F38: =IF($A38>F$33,SUMPRODUCT($B$17:$F$17/(1+$A38)^$B$14:$F$14)+$F$17*(1+F$33)/($A38-F$33)/(1+$A38)^$F$14,"n/a") -> -91801.391
A40: Free cash flow = operating cash flow + interest × (1 − tax rate) − capital spending. Cells marked n/a: WACC not above growth.

Sheet Inputs
A1: Inputs — Low / Base / High | I1: =HYPERLINK("#'Cover'!A1","◂ Contents") -> ◂ Contents
A2: Illustrative assumptions — replace them with your own numbers.
A5: Driver | B5: Low | C5: Base | D5: High | E5: Active | F5: Unit | G5: Source / comment
A6: Members
A7: Members at start (presale or current base) | B7: 80 | C7: 120 | D7: 160 | E7: =CHOOSE(Dashboard!$B$4,B7,C7,D7) -> 120 | F7: # | G7: Low ≤ Base ≤ High
A8: Capacity: most members the studio can hold | B8: 450 | C8: 450 | D8: 450 | E8: =CHOOSE(Dashboard!$B$4,B8,C8,D8) -> 450 | F8: #
A9: Referral & walk-in joins per month (year 1) | B9: 12 | C9: 15 | D9: 18 | E9: =CHOOSE(Dashboard!$B$4,B9,C9,D9) -> 15 | F9: # | G9: Low ≤ Base ≤ High
A10: Referral & walk-in joins growth per year | B10: 0.05 | C10: 0.1 | D10: 0.15 | E10: =CHOOSE(Dashboard!$B$4,B10,C10,D10) -> 0.1 | F10: % | G10: Low ≤ Base ≤ High
A11: Marketing budget per month (year 1) | B11: 4000 | C11: 4000 | D11: 4000 | E11: =CHOOSE(Dashboard!$B$4,B11,C11,D11) -> 4000 | F11: $
A12: Marketing budget growth per year | B12: 0 | C12: 0.05 | D12: 0.1 | E12: =CHOOSE(Dashboard!$B$4,B12,C12,D12) -> 0.05 | F12: % | G12: Low ≤ Base ≤ High
A13: Cost per lead | B13: 28 | C13: 25 | D13: 22 | E13: =CHOOSE(Dashboard!$B$4,B13,C13,D13) -> 25 | F13: $ | G13: Low ≥ Base ≥ High (lower is better)
A14: Leads that join | B14: 0.11 | C14: 0.12 | D14: 0.13 | E14: =CHOOSE(Dashboard!$B$4,B14,C14,D14) -> 0.12 | F14: % | G14: Low ≤ Base ≤ High
A15: Members who cancel per month | B15: 0.07 | C15: 0.06 | D15: 0.05 | E15: =CHOOSE(Dashboard!$B$4,B15,C15,D15) -> 0.06 | F15: % | G15: Low ≥ Base ≥ High (lower is better)
A17: Prices
A18: Membership fee per month (year 1) | B18: 89 | C18: 99 | D18: 109 | E18: =CHOOSE(Dashboard!$B$4,B18,C18,D18) -> 99 | F18: $ | G18: Low ≤ Base ≤ High
A19: Price increase per year | B19: 0.02 | C19: 0.03 | D19: 0.04 | E19: =CHOOSE(Dashboard!$B$4,B19,C19,D19) -> 0.03 | F19: % | G19: Low ≤ Base ≤ High
A20: Joining fee per new member | B20: 49 | C20: 49 | D20: 49 | E20: =CHOOSE(Dashboard!$B$4,B20,C20,D20) -> 49 | F20: $ | G20: Low ≤ Base ≤ High
A22: Personal training & retail
A23: Members buying personal training | B23: 0.07 | C23: 0.08 | D23: 0.09 | E23: =CHOOSE(Dashboard!$B$4,B23,C23,D23) -> 0.08 | F23: % | G23: Low ≤ Base ≤ High
A24: Sessions per personal-training client per month | B24: 4 | C24: 4 | D24: 4 | E24: =CHOOSE(Dashboard!$B$4,B24,C24,D24) -> 4 | F24: # | G24: Low ≤ Base ≤ High
A25: Price per personal-training session | B25: 55 | C25: 60 | D25: 65 | E25: =CHOOSE(Dashboard!$B$4,B25,C25,D25) -> 60 | F25: $ | G25: Low ≤ Base ≤ High
A26: Trainer payout, % of personal-training revenue | B26: 0.55 | C26: 0.5 | D26: 0.45 | E26: =CHOOSE(Dashboard!$B$4,B26,C26,D26) -> 0.5 | F26: % | G26: Low ≥ Base ≥ High (lower is better)
A27: Retail & drinks sales per member per month | B27: 4 | C27: 5 | D27: 6 | E27: =CHOOSE(Dashboard!$B$4,B27,C27,D27) -> 5 | F27: $ | G27: Low ≤ Base ≤ High
A28: Retail & drinks cost, % of sales | B28: 0.55 | C28: 0.5 | D28: 0.45 | E28: =CHOOSE(Dashboard!$B$4,B28,C28,D28) -> 0.5 | F28: % | G28: Low ≥ Base ≥ High (lower is better)
A30: Costs
A31: Group classes per week | B31: 40 | C31: 40 | D31: 40 | E31: =CHOOSE(Dashboard!$B$4,B31,C31,D31) -> 40 | F31: #
A32: Instructor cost per class (year 1) | B32: 50 | C32: 45 | D32: 40 | E32: =CHOOSE(Dashboard!$B$4,B32,C32,D32) -> 45 | F32: $ | G32: Low ≥ Base ≥ High (lower is better)
A33: Rent per month | B33: 12000 | C33: 12000 | D33: 12000 | E33: =CHOOSE(Dashboard!$B$4,B33,C33,D33) -> 12000 | F33: $
A34: Utilities per month | B34: 2200 | C34: 2200 | D34: 2200 | E34: =CHOOSE(Dashboard!$B$4,B34,C34,D34) -> 2200 | F34: $
A35: Equipment maintenance & cleaning per month | B35: 1800 | C35: 1800 | D35: 1800 | E35: =CHOOSE(Dashboard!$B$4,B35,C35,D35) -> 1800 | F35: $
A36: Booking software & payment fees, % of revenue | B36: 0.045 | C36: 0.04 | D36: 0.035 | E36: =CHOOSE(Dashboard!$B$4,B36,C36,D36) -> 0.04 | F36: % | G36: Low ≥ Base ≥ High (lower is better)
A37: Insurance & other G&A per month | B37: 2000 | C37: 2000 | D37: 2000 | E37: =CHOOSE(Dashboard!$B$4,B37,C37,D37) -> 2000 | F37: $
A38: Studio size | B38: 4000 | C38: 4000 | D38: 4000 | E38: =CHOOSE(Dashboard!$B$4,B38,C38,D38) -> 4000 | F38: sq ft
A39: Fit-out & equipment (month 1) | B39: 250000 | C39: 250000 | D39: 250000 | E39: =CHOOSE(Dashboard!$B$4,B39,C39,D39) -> 250000 | F39: $
A41: Headcount
A42: Studio manager: headcount (FTE) | B42: 1 | C42: 1 | D42: 1 | E42: =CHOOSE(Dashboard!$B$4,B42,C42,D42) -> 1 | F42: FTE | G42: Low ≤ Base ≤ High
A43: Studio manager: salary per FTE per year | B43: 55000 | C43: 55000 | D43: 55000 | E43: =CHOOSE(Dashboard!$B$4,B43,C43,D43) -> 55000 | F43: $
A44: Studio manager: headcount growth per year | B44: 0 | C44: 0 | D44: 0 | E44: =CHOOSE(Dashboard!$B$4,B44,C44,D44) -> 0 | F44: % | G44: Low ≤ Base ≤ High
A45: Studio manager: first month on payroll | B45: 1 | C45: 1 | D45: 1 | E45: =CHOOSE(Dashboard!$B$4,B45,C45,D45) -> 1 | F45: month #
A46: Front desk & sales: headcount (FTE) | B46: 3 | C46: 3 | D46: 3 | E46: =CHOOSE(Dashboard!$B$4,B46,C46,D46) -> 3 | F46: FTE | G46: Low ≤ Base ≤ High
...

Sheet P&L
A1: Annual profit & loss | H1: =HYPERLINK("#'Cover'!A1","◂ Contents") -> ◂ Contents
A2: Rolled up from the period detail (SUMIF on the year row; balances at year end).
A3: Year # | B3: 1 | C3: 2 | D3: 3 | E3: 4 | F3: 5
B4: Year 1 | C4: Year 2 | D4: Year 3 | E4: Year 4 | F4: Year 5
A5: Revenue | B5: =SUMIF(Monthly!$C$5:$BJ$5,B$3,Monthly!$C$24:$BJ$24) -> 393075.46 | C5: =SUMIF(Monthly!$C$5:$BJ$5,C$3,Monthly!$C$24:$BJ$24) -> 663933.88 | D5: =SUMIF(Monthly!$C$5:$BJ$5,D$3,Monthly!$C$24:$BJ$24) -> 722638.4 | E5: =SUMIF(Monthly!$C$5:$BJ$5,E$3,Monthly!$C$24:$BJ$24) -> 744317.55 | F5: =SUMIF(Monthly!$C$5:$BJ$5,F$3,Monthly!$C$24:$BJ$24) -> 766647.08
A6: Cost of sales | B6: =SUMIF(Monthly!$C$5:$BJ$5,B$3,Monthly!$C$30:$BJ$30) -> -130230.58 | C6: =SUMIF(Monthly!$C$5:$BJ$5,C$3,Monthly!$C$30:$BJ$30) -> -159653.76 | D6: =SUMIF(Monthly!$C$5:$BJ$5,D$3,Monthly!$C$30:$BJ$30) -> -168619.45 | E6: =SUMIF(Monthly!$C$5:$BJ$5,E$3,Monthly!$C$30:$BJ$30) -> -173678.03 | F6: =SUMIF(Monthly!$C$5:$BJ$5,F$3,Monthly!$C$30:$BJ$30) -> -178888.37
A7: Gross profit | B7: =SUMIF(Monthly!$C$5:$BJ$5,B$3,Monthly!$C$31:$BJ$31) -> 262844.88 | C7: =SUMIF(Monthly!$C$5:$BJ$5,C$3,Monthly!$C$31:$BJ$31) -> 504280.12 | D7: =SUMIF(Monthly!$C$5:$BJ$5,D$3,Monthly!$C$31:$BJ$31) -> 554018.95 | E7: =SUMIF(Monthly!$C$5:$BJ$5,E$3,Monthly!$C$31:$BJ$31) -> 570639.52 | F7: =SUMIF(Monthly!$C$5:$BJ$5,F$3,Monthly!$C$31:$BJ$31) -> 587758.71
A8: Gross margin | B8: =IF(B5=0,0,B7/B5) -> 0.6686881 | C8: =IF(C5=0,0,C7/C5) -> 0.75953364 | D8: =IF(D5=0,0,D7/D5) -> 0.76666138 | E8: =IF(E5=0,0,E7/E5) -> 0.76666138 | F8: =IF(F5=0,0,F7/F5) -> 0.76666138
A9: Staff payroll | B9: =SUMIF(Monthly!$C$5:$BJ$5,B$3,Monthly!$C$34:$BJ$34) -> -166100 | C9: =SUMIF(Monthly!$C$5:$BJ$5,C$3,Monthly!$C$34:$BJ$34) -> -171083 | D9: =SUMIF(Monthly!$C$5:$BJ$5,D$3,Monthly!$C$34:$BJ$34) -> -176215.49 | E9: =SUMIF(Monthly!$C$5:$BJ$5,E$3,Monthly!$C$34:$BJ$34) -> -181501.95 | F9: =SUMIF(Monthly!$C$5:$BJ$5,F$3,Monthly!$C$34:$BJ$34) -> -186947.01
A10: Marketing | B10: =SUMIF(Monthly!$C$5:$BJ$5,B$3,Monthly!$C$35:$BJ$35) -> -48000 | C10: =SUMIF(Monthly!$C$5:$BJ$5,C$3,Monthly!$C$35:$BJ$35) -> -50400 | D10: =SUMIF(Monthly!$C$5:$BJ$5,D$3,Monthly!$C$35:$BJ$35) -> -52920 | E10: =SUMIF(Monthly!$C$5:$BJ$5,E$3,Monthly!$C$35:$BJ$35) -> -55566 | F10: =SUMIF(Monthly!$C$5:$BJ$5,F$3,Monthly!$C$35:$BJ$35) -> -58344.3
A11: Rent | B11: =SUMIF(Monthly!$C$5:$BJ$5,B$3,Monthly!$C$36:$BJ$36) -> -144000 | C11: =SUMIF(Monthly!$C$5:$BJ$5,C$3,Monthly!$C$36:$BJ$36) -> -144000 | D11: =SUMIF(Monthly!$C$5:$BJ$5,D$3,Monthly!$C$36:$BJ$36) -> -144000 | E11: =SUMIF(Monthly!$C$5:$BJ$5,E$3,Monthly!$C$36:$BJ$36) -> -144000 | F11: =SUMIF(Monthly!$C$5:$BJ$5,F$3,Monthly!$C$36:$BJ$36) -> -144000
