Workbook

Sheet Cover
B2: Food truck financial model (planning)
B3: 5-year financial model · monthly detail · Low / Base / High scenarios · US dollars · Full plan
B5: Purpose | D5: Revenue and profit plan
B6: Active scenario | D6: =Dashboard!C4&" (change it on the Dashboard, cell B4)" -> Base (change it on the Dashboard, cell B4)
B7: Model checks | D7: =Checks!B25 -> PASS
B8: Prepared | D8: 22 October 2026
B10: Contents
C11: PRESENTATION
B12: 1 | C12: =HYPERLINK("#Dashboard!A1","Dashboard") -> Dashboard | D12: Scenario switch, key numbers, core financials
B13: 2 | C13: =HYPERLINK("#Summary!A1","Summary") -> Summary | D13: Income statement, cash flow and balance sheet — every year and any year by month
B14: 3 | C14: =HYPERLINK("#Scenarios!A1","Scenarios") -> Scenarios | D14: Low / Base / High side by side: drivers, outputs, charts
B15: 4 | C15: =HYPERLINK("#'Break-even'!A1","Break-even") -> Break-even | D15: Startup costs, funding need, break-even timing and revenue
B16: 5 | C16: =HYPERLINK("#Valuation!A1","Valuation") -> Valuation | D16: Free cash flow, DCF (perpetual growth and exit multiple), WACC × growth sensitivity
B17: 6 | C17: =HYPERLINK("#'Sources & Uses'!A1","Sources & Uses") -> Sources & Uses | D17: Funding structure, sources and uses of cash for the first months
B18: 7 | C18: =HYPERLINK("#KPIs!A1","KPIs") -> KPIs | D18: Financial ratios, DuPont analysis, industry metrics
C19: INPUTS
B20: 8 | C20: =HYPERLINK("#Inputs!A1","Inputs") -> Inputs | D20: Every assumption, Low / Base / High, with units and comments
C21: STATEMENTS
B22: 9 | C22: =HYPERLINK("#'P&L'!A1","P&L") -> P&L | D22: Annual profit & loss
B23: 10 | C23: =HYPERLINK("#'Cash Flow'!A1","Cash Flow") -> Cash Flow | D23: Annual cash flow statement
B24: 11 | C24: =HYPERLINK("#'Balance Sheet'!A1","Balance Sheet") -> Balance Sheet | D24: Balance sheet at year end
C25: CALCULATIONS
B26: 12 | C26: =HYPERLINK("#Monthly!A1","Monthly") -> Monthly | D26: Month-by-month engine of the model
B27: 13 | C27: =HYPERLINK("#Headcount!A1","Headcount") -> Headcount | D27: Team and payroll
B28: 14 | C28: =HYPERLINK("#'Scenario calc'!A1","Scenario calc") -> Scenario calc | D28: Low, Base and High calculated side by side for the Scenarios sheet
C29: CONTROL
B30: 15 | C30: =HYPERLINK("#Checks!A1","Checks") -> Checks | D30: Live integrity checks and the overall verdict
B32: How to read this file
C33: 1000 | D33: Input you can change — yellow cell with a blue figure (Inputs sheet and the view switches)
C34: 1000 | D34: Formula — calculated, do not overwrite
C35: 1000 | D35: Link to another sheet
C36: 1000 | D36: Active value the model uses (follows the scenario)

Sheet Dashboard
A1: Dashboard | W1: =HYPERLINK("#'Cover'!A1","◂ Contents") -> ◂ Contents
A2: Food truck financial model (planning)
A4: Active scenario | B4: 2 | C4: =CHOOSE(B4,"Low","Base","High") -> Base | D4: 1 = Low · 2 = Base · 3 = High — every sheet follows this cell | S4: Model checks | T4: =Checks!B25 -> PASS
A6: REVENUE · YEAR 5 | C6: EBITDA MARGIN · YEAR 5 | H6: NET INCOME · YEAR 5 | L6: LOWEST CASH BALANCE | P6: FUNDING REQUIRED | T6: ENTERPRISE VALUE (DCF)
A7: =F12 -> 406053.09 | C7: =F17 -> 0.12196808 | H7: =F18 -> 23592.293 | L7: =F39 -> 9872.4151 | P7: =F37 -> 222127.58 | T7: =F44 -> 2883.7108
A8: =IF(AND(B12>0,F12>=0),(F12/B12)^(1/4)-1,"CAGR n/a") -> 0.10344142 | C8: =F16 -> 49525.516 | H8: =F19 -> 0.058101498 | L8: ='Break-even'!B6 -> 26 | P8: =IF(F38>=0,"Covered by funding raised",-F38) -> 32127.585 | T8: Average of 2 methods
A10: Core financials ($'000) — active scenario
B11: 1 | C11: 2 | D11: 3 | E11: 4 | F11: 5
A12: Revenue | B12: =SUMIF(Monthly!$C$5:$BJ$5,B$11,Monthly!$C$24:$BJ$24) -> 273896 | C12: =SUMIF(Monthly!$C$5:$BJ$5,C$11,Monthly!$C$24:$BJ$24) -> 336825.82 | D12: =SUMIF(Monthly!$C$5:$BJ$5,D$11,Monthly!$C$24:$BJ$24) -> 358461.37 | E12: =SUMIF(Monthly!$C$5:$BJ$5,E$11,Monthly!$C$24:$BJ$24) -> 381506.04 | F12: =SUMIF(Monthly!$C$5:$BJ$5,F$11,Monthly!$C$24:$BJ$24) -> 406053.09
A13: Gross profit | B13: =SUMIF(Monthly!$C$5:$BJ$5,B$11,Monthly!$C$33:$BJ$33) -> 161966.54 | C13: =SUMIF(Monthly!$C$5:$BJ$5,C$11,Monthly!$C$33:$BJ$33) -> 199005.1 | D13: =SUMIF(Monthly!$C$5:$BJ$5,D$11,Monthly!$C$33:$BJ$33) -> 211683.05 | E13: =SUMIF(Monthly!$C$5:$BJ$5,E$11,Monthly!$C$33:$BJ$33) -> 225178.61 | F13: =SUMIF(Monthly!$C$5:$BJ$5,F$11,Monthly!$C$33:$BJ$33) -> 239545.29
A14: Gross margin | B14: =IF(B12=0,0,B13/B12) -> 0.5913432 | C14: =IF(C12=0,0,C13/C12) -> 0.59082496 | D14: =IF(D12=0,0,D13/D12) -> 0.5905324 | E14: =IF(E12=0,0,E13/E12) -> 0.59023605 | F14: =IF(F12=0,0,F13/F12) -> 0.58993587
A15: Operating expenses | B15: =SUMIF(Monthly!$C$5:$BJ$5,B$11,Monthly!$C$45:$BJ$45) -> -169272.5 | C15: =SUMIF(Monthly!$C$5:$BJ$5,C$11,Monthly!$C$45:$BJ$45) -> -174374.61 | D15: =SUMIF(Monthly!$C$5:$BJ$5,D$11,Monthly!$C$45:$BJ$45) -> -179430.04 | E15: =SUMIF(Monthly!$C$5:$BJ$5,E$11,Monthly!$C$45:$BJ$45) -> -184643.35 | F15: =SUMIF(Monthly!$C$5:$BJ$5,F$11,Monthly!$C$45:$BJ$45) -> -190019.77
A16: EBITDA | B16: =SUMIF(Monthly!$C$5:$BJ$5,B$11,Monthly!$C$46:$BJ$46) -> -7305.964 | C16: =SUMIF(Monthly!$C$5:$BJ$5,C$11,Monthly!$C$46:$BJ$46) -> 24630.491 | D16: =SUMIF(Monthly!$C$5:$BJ$5,D$11,Monthly!$C$46:$BJ$46) -> 32253.01 | E16: =SUMIF(Monthly!$C$5:$BJ$5,E$11,Monthly!$C$46:$BJ$46) -> 40535.265 | F16: =SUMIF(Monthly!$C$5:$BJ$5,F$11,Monthly!$C$46:$BJ$46) -> 49525.516
A17: EBITDA margin | B17: =IF(B12=0,0,B16/B12) -> -0.026674227 | C17: =IF(C12=0,0,C16/C12) -> 0.073125305 | D17: =IF(D12=0,0,D16/D12) -> 0.089976252 | E17: =IF(E12=0,0,E16/E12) -> 0.10625065 | F17: =IF(F12=0,0,F16/F12) -> 0.12196808
A18: Net income | B18: =SUMIF(Monthly!$C$5:$BJ$5,B$11,Monthly!$C$55:$BJ$55) -> -34439.625 | C18: =SUMIF(Monthly!$C$5:$BJ$5,C$11,Monthly!$C$55:$BJ$55) -> -1245.9377 | D18: =SUMIF(Monthly!$C$5:$BJ$5,D$11,Monthly!$C$55:$BJ$55) -> 7639.439 | E18: =SUMIF(Monthly!$C$5:$BJ$5,E$11,Monthly!$C$55:$BJ$55) -> 17184.551 | F18: =SUMIF(Monthly!$C$5:$BJ$5,F$11,Monthly!$C$55:$BJ$55) -> 23592.293
A19: Net margin | B19: =IF(B12=0,0,B18/B12) -> -0.12573979 | C19: =IF(C12=0,0,C18/C12) -> -0.0036990563 | D19: =IF(D12=0,0,D18/D12) -> 0.02131175 | E19: =IF(E12=0,0,E18/E12) -> 0.045043982 | F19: =IF(F12=0,0,F18/F12) -> 0.058101498
A20: Operating cash flow | B20: =SUMIF(Monthly!$C$5:$BJ$5,B$11,Monthly!$C$83:$BJ$83) -> -15659.701 | C20: =SUMIF(Monthly!$C$5:$BJ$5,C$11,Monthly!$C$83:$BJ$83) -> 18765.734 | D20: =SUMIF(Monthly!$C$5:$BJ$5,D$11,Monthly!$C$83:$BJ$83) -> 28004.382 | E20: =SUMIF(Monthly!$C$5:$BJ$5,E$11,Monthly!$C$83:$BJ$83) -> 37902.51 | F20: =SUMIF(Monthly!$C$5:$BJ$5,F$11,Monthly!$C$83:$BJ$83) -> 44662.997
A21: Investing cash flow | B21: =SUMIF(Monthly!$C$5:$BJ$5,B$11,Monthly!$C$84:$BJ$84) -> -138000 | C21: =SUMIF(Monthly!$C$5:$BJ$5,C$11,Monthly!$C$84:$BJ$84) -> -2500 | D21: =SUMIF(Monthly!$C$5:$BJ$5,D$11,Monthly!$C$84:$BJ$84) -> -2500 | E21: =SUMIF(Monthly!$C$5:$BJ$5,E$11,Monthly!$C$84:$BJ$84) -> -2500 | F21: =SUMIF(Monthly!$C$5:$BJ$5,F$11,Monthly!$C$84:$BJ$84) -> -2500
A22: Financing cash flow | B22: =SUMIF(Monthly!$C$5:$BJ$5,B$11,Monthly!$C$86:$BJ$86) -> 173500 | C22: =SUMIF(Monthly!$C$5:$BJ$5,C$11,Monthly!$C$86:$BJ$86) -> -18000 | D22: =SUMIF(Monthly!$C$5:$BJ$5,D$11,Monthly!$C$86:$BJ$86) -> -18000 | E22: =SUMIF(Monthly!$C$5:$BJ$5,E$11,Monthly!$C$86:$BJ$86) -> -18000 | F22: =SUMIF(Monthly!$C$5:$BJ$5,F$11,Monthly!$C$86:$BJ$86) -> -18000
A23: Net change in cash | B23: =SUMIF(Monthly!$C$5:$BJ$5,B$11,Monthly!$C$87:$BJ$87) -> 19840.299 | C23: =SUMIF(Monthly!$C$5:$BJ$5,C$11,Monthly!$C$87:$BJ$87) -> -1734.2661 | D23: =SUMIF(Monthly!$C$5:$BJ$5,D$11,Monthly!$C$87:$BJ$87) -> 7504.3816 | E23: =SUMIF(Monthly!$C$5:$BJ$5,E$11,Monthly!$C$87:$BJ$87) -> 17402.51 | F23: =SUMIF(Monthly!$C$5:$BJ$5,F$11,Monthly!$C$87:$BJ$87) -> 24162.997
A24: Year-end cash | B24: =INDEX(Monthly!$C$89:$BJ$89,B$11*12) -> 19840.299 | C24: =INDEX(Monthly!$C$89:$BJ$89,C$11*12) -> 18106.033 | D24: =INDEX(Monthly!$C$89:$BJ$89,D$11*12) -> 25610.415 | E24: =INDEX(Monthly!$C$89:$BJ$89,E$11*12) -> 43012.925 | F24: =INDEX(Monthly!$C$89:$BJ$89,F$11*12) -> 67175.922
A26: Food truck metrics
B27: 1 | C27: 2 | D27: 3 | E27: 4 | F27: 5
A28: Meals served | B28: =KPIs!B31 -> 19564 | C28: =KPIs!C31 -> 23358.24 | D28: =KPIs!D31 -> 24134.587 | E28: =KPIs!E31 -> 24938.005 | F28: =KPIs!F31 -> 25769.494
A29: Revenue per service day | B29: =KPIs!B38 -> 1110.0142 | C29: =KPIs!C38 -> 1327.1309 | D29: =KPIs!D38 -> 1401.9374 | E29: =KPIs!E38 -> 1480.5735 | F29: =KPIs!F38 -> 1563.1963
A30: Events & catering, % of revenue | B30: =KPIs!B36 -> 0.15717645 | C30: =KPIs!C36 -> 0.16182726 | D30: =KPIs!D36 -> 0.16445278 | E30: =KPIs!E36 -> 0.16711241 | F30: =KPIs!F36 -> 0.1698063
A31: Prime cost (food, packaging, payroll), % of revenue | B31: =KPIs!B43 -> 0.79477422 | C31: =KPIs!C43 -> 0.72449893 | D31: =KPIs!D43 -> 0.71284287 | E31: =KPIs!E43 -> 0.70154451 | F31: =KPIs!F43 -> 0.69059323
A32: Team (FTE, year end) | B32: =INDEX(Headcount!$C$11:$BJ$11,B$27*12) -> 3.2 | C32: =INDEX(Headcount!$C$11:$BJ$11,C$27*12) -> 3.2 | D32: =INDEX(Headcount!$C$11:$BJ$11,D$27*12) -> 3.2 | E32: =INDEX(Headcount!$C$11:$BJ$11,E$27*12) -> 3.2 | F32: =INDEX(Headcount!$C$11:$BJ$11,F$27*12) -> 3.2
A34: Funding & valuation ($'000) — active scenario
A35: Equity raised | F35: =Inputs!$E$71 -> 100000
A36: Loan drawn | F36: =Inputs!$E$72 -> 90000
A37: Funding required (incl. cash buffer) | F37: ='Break-even'!B12 -> 222127.58
A38: Funding surplus / (shortfall) | F38: ='Break-even'!B17 -> -32127.585
A39: ="Lowest cash balance (month "&'Break-even'!B6&")" -> Lowest cash balance (month 26) | F39: ='Break-even'!B18 -> 9872.4151
A40: First month with positive EBITDA | F40: ='Break-even'!B21 -> 6
A41: Cash invested paid back | F41: ='Break-even'!B23 -> Not within horizon
A42: Enterprise value — perpetual growth | F42: =Valuation!B27 -> 1604.5212
A43: Enterprise value — exit multiple | F43: =Valuation!C27 -> 4162.9003
A44: Enterprise value — average | F44: =Valuation!B30 -> 2883.7108

Sheet Summary
A1: Financial statements summary | U1: =HYPERLINK("#'Cover'!A1","◂ Contents") -> ◂ Contents
A2: Food truck financial model (planning) | P2: Select detailed year: | R2: 1
A5: Income statement ($'000) — by year | H5: ="Income statement ($'000) — Year "&$R$2&", by month" -> Income statement ($'000) — Year 1, by month
B6: 1 | C6: 2 | D6: 3 | E6: 4 | F6: 5 | H6: =INDEX(Monthly!$C$4:$BJ$4,($R$2-1)*12+1) -> 1 | I6: =INDEX(Monthly!$C$4:$BJ$4,($R$2-1)*12+2) -> 2 | J6: =INDEX(Monthly!$C$4:$BJ$4,($R$2-1)*12+3) -> 3 | K6: =INDEX(Monthly!$C$4:$BJ$4,($R$2-1)*12+4) -> 4 | L6: =INDEX(Monthly!$C$4:$BJ$4,($R$2-1)*12+5) -> 5 | M6: =INDEX(Monthly!$C$4:$BJ$4,($R$2-1)*12+6) -> 6 | N6: =INDEX(Monthly!$C$4:$BJ$4,($R$2-1)*12+7) -> 7 | O6: =INDEX(Monthly!$C$4:$BJ$4,($R$2-1)*12+8) -> 8 | P6: =INDEX(Monthly!$C$4:$BJ$4,($R$2-1)*12+9) -> 9 | Q6: =INDEX(Monthly!$C$4:$BJ$4,($R$2-1)*12+10) -> 10 | R6: =INDEX(Monthly!$C$4:$BJ$4,($R$2-1)*12+11) -> 11 | S6: =INDEX(Monthly!$C$4:$BJ$4,($R$2-1)*12+12) -> 12
A7: Revenue | B7: ='P&L'!B5 -> 273896 | C7: ='P&L'!C5 -> 336825.82 | D7: ='P&L'!D5 -> 358461.37 | E7: ='P&L'!E5 -> 381506.04 | F7: ='P&L'!F5 -> 406053.09 | H7: =INDEX(Monthly!$C$24:$BJ$24,($R$2-1)*12+1) -> 10416 | I7: =INDEX(Monthly!$C$24:$BJ$24,($R$2-1)*12+2) -> 12152 | J7: =INDEX(Monthly!$C$24:$BJ$24,($R$2-1)*12+3) -> 18816 | K7: =INDEX(Monthly!$C$24:$BJ$24,($R$2-1)*12+4) -> 21168 | L7: =INDEX(Monthly!$C$24:$BJ$24,($R$2-1)*12+5) -> 23520 | M7: =INDEX(Monthly!$C$24:$BJ$24,($R$2-1)*12+6) -> 25872 | N7: =INDEX(Monthly!$C$24:$BJ$24,($R$2-1)*12+7) -> 28224 | O7: =INDEX(Monthly!$C$24:$BJ$24,($R$2-1)*12+8) -> 28224 | P7: =INDEX(Monthly!$C$24:$BJ$24,($R$2-1)*12+9) -> 28224 | Q7: =INDEX(Monthly!$C$24:$BJ$24,($R$2-1)*12+10) -> 28224 | R7: =INDEX(Monthly!$C$24:$BJ$24,($R$2-1)*12+11) -> 28224 | S7: =INDEX(Monthly!$C$24:$BJ$24,($R$2-1)*12+12) -> 20832
A8: Cost of sales | B8: ='P&L'!B6 -> -111929.46 | C8: ='P&L'!C6 -> -137820.72 | D8: ='P&L'!D6 -> -146778.32 | E8: ='P&L'!E6 -> -156327.42 | F8: ='P&L'!F6 -> -166507.81 | H8: =INDEX(Monthly!$C$32:$BJ$32,($R$2-1)*12+1) -> -4308.144 | I8: =INDEX(Monthly!$C$32:$BJ$32,($R$2-1)*12+2) -> -5026.168 | J8: =INDEX(Monthly!$C$32:$BJ$32,($R$2-1)*12+3) -> -7671.744 | K8: =INDEX(Monthly!$C$32:$BJ$32,($R$2-1)*12+4) -> -8630.712 | L8: =INDEX(Monthly!$C$32:$BJ$32,($R$2-1)*12+5) -> -9589.68 | M8: =INDEX(Monthly!$C$32:$BJ$32,($R$2-1)*12+6) -> -10548.648 | N8: =INDEX(Monthly!$C$32:$BJ$32,($R$2-1)*12+7) -> -11507.616 | O8: =INDEX(Monthly!$C$32:$BJ$32,($R$2-1)*12+8) -> -11507.616 | P8: =INDEX(Monthly!$C$32:$BJ$32,($R$2-1)*12+9) -> -11507.616 | Q8: =INDEX(Monthly!$C$32:$BJ$32,($R$2-1)*12+10) -> -11507.616 | R8: =INDEX(Monthly!$C$32:$BJ$32,($R$2-1)*12+11) -> -11507.616 | S8: =INDEX(Monthly!$C$32:$BJ$32,($R$2-1)*12+12) -> -8616.288
A9: Gross profit | B9: ='P&L'!B7 -> 161966.54 | C9: ='P&L'!C7 -> 199005.1 | D9: ='P&L'!D7 -> 211683.05 | E9: ='P&L'!E7 -> 225178.61 | F9: ='P&L'!F7 -> 239545.29 | H9: =INDEX(Monthly!$C$33:$BJ$33,($R$2-1)*12+1) -> 6107.856 | I9: =INDEX(Monthly!$C$33:$BJ$33,($R$2-1)*12+2) -> 7125.832 | J9: =INDEX(Monthly!$C$33:$BJ$33,($R$2-1)*12+3) -> 11144.256 | K9: =INDEX(Monthly!$C$33:$BJ$33,($R$2-1)*12+4) -> 12537.288 | L9: =INDEX(Monthly!$C$33:$BJ$33,($R$2-1)*12+5) -> 13930.32 | M9: =INDEX(Monthly!$C$33:$BJ$33,($R$2-1)*12+6) -> 15323.352 | N9: =INDEX(Monthly!$C$33:$BJ$33,($R$2-1)*12+7) -> 16716.384 | O9: =INDEX(Monthly!$C$33:$BJ$33,($R$2-1)*12+8) -> 16716.384 | P9: =INDEX(Monthly!$C$33:$BJ$33,($R$2-1)*12+9) -> 16716.384 | Q9: =INDEX(Monthly!$C$33:$BJ$33,($R$2-1)*12+10) -> 16716.384 | R9: =INDEX(Monthly!$C$33:$BJ$33,($R$2-1)*12+11) -> 16716.384 | S9: =INDEX(Monthly!$C$33:$BJ$33,($R$2-1)*12+12) -> 12215.712
A10: Gross margin | B10: ='P&L'!B8 -> 0.5913432 | C10: ='P&L'!C8 -> 0.59082496 | D10: ='P&L'!D8 -> 0.5905324 | E10: ='P&L'!E8 -> 0.59023605 | F10: ='P&L'!F8 -> 0.58993587 | H10: =IF(H7=0,0,H9/H7) -> 0.58639171 | I10: =IF(I7=0,0,I9/I7) -> 0.58639171 | J10: =IF(J7=0,0,J9/J7) -> 0.59227551 | K10: =IF(K7=0,0,K9/K7) -> 0.59227551 | L10: =IF(L7=0,0,L9/L7) -> 0.59227551 | M10: =IF(M7=0,0,M9/M7) -> 0.59227551 | N10: =IF(N7=0,0,N9/N7) -> 0.59227551 | O10: =IF(O7=0,0,O9/O7) -> 0.59227551 | ... S10: =IF(S7=0,0,S9/S7) -> 0.58639171
A11: Total operating expenses | B11: ='P&L'!B18 -> -169272.5 | C11: ='P&L'!C18 -> -174374.61 | D11: ='P&L'!D18 -> -179430.04 | E11: ='P&L'!E18 -> -184643.35 | F11: ='P&L'!F18 -> -190019.77 | H11: =INDEX(Monthly!$C$45:$BJ$45,($R$2-1)*12+1) -> -13894.667 | I11: =INDEX(Monthly!$C$45:$BJ$45,($R$2-1)*12+2) -> -13904.167 | J11: =INDEX(Monthly!$C$45:$BJ$45,($R$2-1)*12+3) -> -14141.667 | K11: =INDEX(Monthly!$C$45:$BJ$45,($R$2-1)*12+4) -> -14151.167 | L11: =INDEX(Monthly!$C$45:$BJ$45,($R$2-1)*12+5) -> -14160.667 | M11: =INDEX(Monthly!$C$45:$BJ$45,($R$2-1)*12+6) -> -14170.167 | N11: =INDEX(Monthly!$C$45:$BJ$45,($R$2-1)*12+7) -> -14179.667 | O11: =INDEX(Monthly!$C$45:$BJ$45,($R$2-1)*12+8) -> -14179.667 | P11: =INDEX(Monthly!$C$45:$BJ$45,($R$2-1)*12+9) -> -14179.667 | Q11: =INDEX(Monthly!$C$45:$BJ$45,($R$2-1)*12+10) -> -14179.667 | R11: =INDEX(Monthly!$C$45:$BJ$45,($R$2-1)*12+11) -> -14179.667 | S11: =INDEX(Monthly!$C$45:$BJ$45,($R$2-1)*12+12) -> -13951.667
A12: EBITDA | B12: ='P&L'!B19 -> -7305.964 | C12: ='P&L'!C19 -> 24630.491 | D12: ='P&L'!D19 -> 32253.01 | E12: ='P&L'!E19 -> 40535.265 | F12: ='P&L'!F19 -> 49525.516 | H12: =INDEX(Monthly!$C$46:$BJ$46,($R$2-1)*12+1) -> -7786.8107 | I12: =INDEX(Monthly!$C$46:$BJ$46,($R$2-1)*12+2) -> -6778.3347 | J12: =INDEX(Monthly!$C$46:$BJ$46,($R$2-1)*12+3) -> -2997.4107 | K12: =INDEX(Monthly!$C$46:$BJ$46,($R$2-1)*12+4) -> -1613.8787 | L12: =INDEX(Monthly!$C$46:$BJ$46,($R$2-1)*12+5) -> -230.34667 | M12: =INDEX(Monthly!$C$46:$BJ$46,($R$2-1)*12+6) -> 1153.1853 | N12: =INDEX(Monthly!$C$46:$BJ$46,($R$2-1)*12+7) -> 2536.7173 | O12: =INDEX(Monthly!$C$46:$BJ$46,($R$2-1)*12+8) -> 2536.7173 | P12: =INDEX(Monthly!$C$46:$BJ$46,($R$2-1)*12+9) -> 2536.7173 | Q12: =INDEX(Monthly!$C$46:$BJ$46,($R$2-1)*12+10) -> 2536.7173 | R12: =INDEX(Monthly!$C$46:$BJ$46,($R$2-1)*12+11) -> 2536.7173 | S12: =INDEX(Monthly!$C$46:$BJ$46,($R$2-1)*12+12) -> -1735.9547
A13: EBITDA margin | B13: ='P&L'!B20 -> -0.026674227 | C13: ='P&L'!C20 -> 0.073125305 | D13: ='P&L'!D20 -> 0.089976252 | E13: ='P&L'!E20 -> 0.10625065 | F13: ='P&L'!F20 -> 0.12196808 | H13: =IF(H7=0,0,H12/H7) -> -0.74758167 | I13: =IF(I7=0,0,I12/I7) -> -0.55779581 | J13: =IF(J7=0,0,J12/J7) -> -0.15930116 | K13: =IF(K7=0,0,K12/K7) -> -0.076241434 | L13: =IF(L7=0,0,L12/L7) -> -0.0097936508 | M13: =IF(M7=0,0,M12/M7) -> 0.044572717 | N13: =IF(N7=0,0,N12/N7) -> 0.089878023 | O13: =IF(O7=0,0,O12/O7) -> 0.089878023 | ... S13: =IF(S7=0,0,S12/S7) -> -0.083331157
A14: Depreciation | B14: ='P&L'!B21 -> -19714.286 | C14: ='P&L'!C21 -> -20071.429 | D14: ='P&L'!D21 -> -20428.571 | E14: ='P&L'!E21 -> -20785.714 | F14: ='P&L'!F21 -> -21142.857 | H14: =INDEX(Monthly!$C$64:$BJ$64,($R$2-1)*12+1) -> -1642.8571 | I14: =INDEX(Monthly!$C$64:$BJ$64,($R$2-1)*12+2) -> -1642.8571 | J14: =INDEX(Monthly!$C$64:$BJ$64,($R$2-1)*12+3) -> -1642.8571 | K14: =INDEX(Monthly!$C$64:$BJ$64,($R$2-1)*12+4) -> -1642.8571 | L14: =INDEX(Monthly!$C$64:$BJ$64,($R$2-1)*12+5) -> -1642.8571 | M14: =INDEX(Monthly!$C$64:$BJ$64,($R$2-1)*12+6) -> -1642.8571 | N14: =INDEX(Monthly!$C$64:$BJ$64,($R$2-1)*12+7) -> -1642.8571 | O14: =INDEX(Monthly!$C$64:$BJ$64,($R$2-1)*12+8) -> -1642.8571 | P14: =INDEX(Monthly!$C$64:$BJ$64,($R$2-1)*12+9) -> -1642.8571 | Q14: =INDEX(Monthly!$C$64:$BJ$64,($R$2-1)*12+10) -> -1642.8571 | R14: =INDEX(Monthly!$C$64:$BJ$64,($R$2-1)*12+11) -> -1642.8571 | S14: =INDEX(Monthly!$C$64:$BJ$64,($R$2-1)*12+12) -> -1642.8571
A15: EBIT | B15: ='P&L'!B22 -> -27020.25 | C15: ='P&L'!C22 -> 4559.0623 | D15: ='P&L'!D22 -> 11824.439 | E15: ='P&L'!E22 -> 19749.551 | F15: ='P&L'!F22 -> 28382.659 | H15: =INDEX(Monthly!$C$49:$BJ$49,($R$2-1)*12+1) -> -9429.6678 | I15: =INDEX(Monthly!$C$49:$BJ$49,($R$2-1)*12+2) -> -8421.1918 | J15: =INDEX(Monthly!$C$49:$BJ$49,($R$2-1)*12+3) -> -4640.2678 | K15: =INDEX(Monthly!$C$49:$BJ$49,($R$2-1)*12+4) -> -3256.7358 | L15: =INDEX(Monthly!$C$49:$BJ$49,($R$2-1)*12+5) -> -1873.2038 | M15: =INDEX(Monthly!$C$49:$BJ$49,($R$2-1)*12+6) -> -489.67181 | N15: =INDEX(Monthly!$C$49:$BJ$49,($R$2-1)*12+7) -> 893.86019 | O15: =INDEX(Monthly!$C$49:$BJ$49,($R$2-1)*12+8) -> 893.86019 | P15: =INDEX(Monthly!$C$49:$BJ$49,($R$2-1)*12+9) -> 893.86019 | Q15: =INDEX(Monthly!$C$49:$BJ$49,($R$2-1)*12+10) -> 893.86019 | R15: =INDEX(Monthly!$C$49:$BJ$49,($R$2-1)*12+11) -> 893.86019 | S15: =INDEX(Monthly!$C$49:$BJ$49,($R$2-1)*12+12) -> -3378.8118
A16: Interest | B16: ='P&L'!B23 -> -7419.375 | C16: ='P&L'!C23 -> -5805 | D16: ='P&L'!D23 -> -4185 | E16: ='P&L'!E23 -> -2565 | F16: ='P&L'!F23 -> -945 | H16: =INDEX(Monthly!$C$50:$BJ$50,($R$2-1)*12+1) -> -675 | I16: =INDEX(Monthly!$C$50:$BJ$50,($R$2-1)*12+2) -> -669.375 | J16: =INDEX(Monthly!$C$50:$BJ$50,($R$2-1)*12+3) -> -658.125 | K16: =INDEX(Monthly!$C$50:$BJ$50,($R$2-1)*12+4) -> -646.875 | L16: =INDEX(Monthly!$C$50:$BJ$50,($R$2-1)*12+5) -> -635.625 | M16: =INDEX(Monthly!$C$50:$BJ$50,($R$2-1)*12+6) -> -624.375 | N16: =INDEX(Monthly!$C$50:$BJ$50,($R$2-1)*12+7) -> -613.125 | O16: =INDEX(Monthly!$C$50:$BJ$50,($R$2-1)*12+8) -> -601.875 | P16: =INDEX(Monthly!$C$50:$BJ$50,($R$2-1)*12+9) -> -590.625 | Q16: =INDEX(Monthly!$C$50:$BJ$50,($R$2-1)*12+10) -> -579.375 | R16: =INDEX(Monthly!$C$50:$BJ$50,($R$2-1)*12+11) -> -568.125 | S16: =INDEX(Monthly!$C$50:$BJ$50,($R$2-1)*12+12) -> -556.875
A17: Pre-tax income | B17: ='P&L'!B24 -> -34439.625 | C17: ='P&L'!C24 -> -1245.9377 | D17: ='P&L'!D24 -> 7639.439 | E17: ='P&L'!E24 -> 17184.551 | F17: ='P&L'!F24 -> 27437.659 | H17: =INDEX(Monthly!$C$51:$BJ$51,($R$2-1)*12+1) -> -10104.668 | I17: =INDEX(Monthly!$C$51:$BJ$51,($R$2-1)*12+2) -> -9090.5668 | J17: =INDEX(Monthly!$C$51:$BJ$51,($R$2-1)*12+3) -> -5298.3928 | K17: =INDEX(Monthly!$C$51:$BJ$51,($R$2-1)*12+4) -> -3903.6108 | L17: =INDEX(Monthly!$C$51:$BJ$51,($R$2-1)*12+5) -> -2508.8288 | M17: =INDEX(Monthly!$C$51:$BJ$51,($R$2-1)*12+6) -> -1114.0468 | N17: =INDEX(Monthly!$C$51:$BJ$51,($R$2-1)*12+7) -> 280.73519 | O17: =INDEX(Monthly!$C$51:$BJ$51,($R$2-1)*12+8) -> 291.98519 | P17: =INDEX(Monthly!$C$51:$BJ$51,($R$2-1)*12+9) -> 303.23519 | Q17: =INDEX(Monthly!$C$51:$BJ$51,($R$2-1)*12+10) -> 314.48519 | R17: =INDEX(Monthly!$C$51:$BJ$51,($R$2-1)*12+11) -> 325.73519 | S17: =INDEX(Monthly!$C$51:$BJ$51,($R$2-1)*12+12) -> -3935.6868
A18: Income tax | B18: ='P&L'!B25 -> 0 | C18: ='P&L'!C25 -> 0 | D18: ='P&L'!D25 -> 0 | E18: ='P&L'!E25 -> 0 | F18: ='P&L'!F25 -> -3845.3658 | H18: =INDEX(Monthly!$C$54:$BJ$54,($R$2-1)*12+1) -> 0 | I18: =INDEX(Monthly!$C$54:$BJ$54,($R$2-1)*12+2) -> 0 | J18: =INDEX(Monthly!$C$54:$BJ$54,($R$2-1)*12+3) -> 0 | K18: =INDEX(Monthly!$C$54:$BJ$54,($R$2-1)*12+4) -> 0 | L18: =INDEX(Monthly!$C$54:$BJ$54,($R$2-1)*12+5) -> 0 | M18: =INDEX(Monthly!$C$54:$BJ$54,($R$2-1)*12+6) -> 0 | N18: =INDEX(Monthly!$C$54:$BJ$54,($R$2-1)*12+7) -> 0 | O18: =INDEX(Monthly!$C$54:$BJ$54,($R$2-1)*12+8) -> 0 | P18: =INDEX(Monthly!$C$54:$BJ$54,($R$2-1)*12+9) -> 0 | Q18: =INDEX(Monthly!$C$54:$BJ$54,($R$2-1)*12+10) -> 0 | R18: =INDEX(Monthly!$C$54:$BJ$54,($R$2-1)*12+11) -> 0 | S18: =INDEX(Monthly!$C$54:$BJ$54,($R$2-1)*12+12) -> 0
A19: Net income | B19: ='P&L'!B26 -> -34439.625 | C19: ='P&L'!C26 -> -1245.9377 | D19: ='P&L'!D26 -> 7639.439 | E19: ='P&L'!E26 -> 17184.551 | F19: ='P&L'!F26 -> 23592.293 | H19: =INDEX(Monthly!$C$55:$BJ$55,($R$2-1)*12+1) -> -10104.668 | I19: =INDEX(Monthly!$C$55:$BJ$55,($R$2-1)*12+2) -> -9090.5668 | J19: =INDEX(Monthly!$C$55:$BJ$55,($R$2-1)*12+3) -> -5298.3928 | K19: =INDEX(Monthly!$C$55:$BJ$55,($R$2-1)*12+4) -> -3903.6108 | L19: =INDEX(Monthly!$C$55:$BJ$55,($R$2-1)*12+5) -> -2508.8288 | M19: =INDEX(Monthly!$C$55:$BJ$55,($R$2-1)*12+6) -> -1114.0468 | N19: =INDEX(Monthly!$C$55:$BJ$55,($R$2-1)*12+7) -> 280.73519 | O19: =INDEX(Monthly!$C$55:$BJ$55,($R$2-1)*12+8) -> 291.98519 | P19: =INDEX(Monthly!$C$55:$BJ$55,($R$2-1)*12+9) -> 303.23519 | Q19: =INDEX(Monthly!$C$55:$BJ$55,($R$2-1)*12+10) -> 314.48519 | R19: =INDEX(Monthly!$C$55:$BJ$55,($R$2-1)*12+11) -> 325.73519 | S19: =INDEX(Monthly!$C$55:$BJ$55,($R$2-1)*12+12) -> -3935.6868
A20: Net margin | B20: ='P&L'!B27 -> -0.12573979 | C20: ='P&L'!C27 -> -0.0036990563 | D20: ='P&L'!D27 -> 0.02131175 | E20: ='P&L'!E27 -> 0.045043982 | F20: ='P&L'!F27 -> 0.058101498 | H20: =IF(H7=0,0,H19/H7) -> -0.9701102 | I20: =IF(I7=0,0,I19/I7) -> -0.74807166 | J20: =IF(J7=0,0,J19/J7) -> -0.28158975 | K20: =IF(K7=0,0,K19/K7) -> -0.18441094 | L20: =IF(L7=0,0,L19/L7) -> -0.10666789 | M20: =IF(M7=0,0,M19/M7) -> -0.043059942 | N20: =IF(N7=0,0,N19/N7) -> 0.0099466833 | O20: =IF(O7=0,0,O19/O7) -> 0.01034528 | ... S20: =IF(S7=0,0,S19/S7) -> -0.18892506
A22: Cash flow ($'000) — by year | H22: ="Cash flow ($'000) — Year "&$R$2&", by month" -> Cash flow ($'000) — Year 1, by month
B23: 1 | C23: 2 | D23: 3 | E23: 4 | F23: 5 | H23: =INDEX(Monthly!$C$4:$BJ$4,($R$2-1)*12+1) -> 1 | I23: =INDEX(Monthly!$C$4:$BJ$4,($R$2-1)*12+2) -> 2 | J23: =INDEX(Monthly!$C$4:$BJ$4,($R$2-1)*12+3) -> 3 | K23: =INDEX(Monthly!$C$4:$BJ$4,($R$2-1)*12+4) -> 4 | L23: =INDEX(Monthly!$C$4:$BJ$4,($R$2-1)*12+5) -> 5 | M23: =INDEX(Monthly!$C$4:$BJ$4,($R$2-1)*12+6) -> 6 | N23: =INDEX(Monthly!$C$4:$BJ$4,($R$2-1)*12+7) -> 7 | O23: =INDEX(Monthly!$C$4:$BJ$4,($R$2-1)*12+8) -> 8 | P23: =INDEX(Monthly!$C$4:$BJ$4,($R$2-1)*12+9) -> 9 | Q23: =INDEX(Monthly!$C$4:$BJ$4,($R$2-1)*12+10) -> 10 | R23: =INDEX(Monthly!$C$4:$BJ$4,($R$2-1)*12+11) -> 11 | S23: =INDEX(Monthly!$C$4:$BJ$4,($R$2-1)*12+12) -> 12
A24: Operating cash flow | B24: ='Cash Flow'!B10 -> -15659.701 | C24: ='Cash Flow'!C10 -> 18765.734 | D24: ='Cash Flow'!D10 -> 28004.382 | E24: ='Cash Flow'!E10 -> 37902.51 | F24: ='Cash Flow'!F10 -> 44662.997 | H24: =INDEX(Monthly!$C$83:$BJ$83,($R$2-1)*12+1) -> -8928.9915 | I24: =INDEX(Monthly!$C$83:$BJ$83,($R$2-1)*12+2) -> -7525.5731 | J24: =INDEX(Monthly!$C$83:$BJ$83,($R$2-1)*12+3) -> -3969.1922 | K24: =INDEX(Monthly!$C$83:$BJ$83,($R$2-1)*12+4) -> -2368.0913 | L24: =INDEX(Monthly!$C$83:$BJ$83,($R$2-1)*12+5) -> -973.30927 | M24: =INDEX(Monthly!$C$83:$BJ$83,($R$2-1)*12+6) -> 421.47273 | N24: =INDEX(Monthly!$C$83:$BJ$83,($R$2-1)*12+7) -> 1816.2547 | O24: =INDEX(Monthly!$C$83:$BJ$83,($R$2-1)*12+8) -> 1934.8423 | P24: =INDEX(Monthly!$C$83:$BJ$83,($R$2-1)*12+9) -> 1946.0923 | Q24: =INDEX(Monthly!$C$83:$BJ$83,($R$2-1)*12+10) -> 1957.3423 | R24: =INDEX(Monthly!$C$83:$BJ$83,($R$2-1)*12+11) -> 1968.5923 | S24: =INDEX(Monthly!$C$83:$BJ$83,($R$2-1)*12+12) -> -1939.1401
A25: Capital spending | B25: ='Cash Flow'!B11 -> -138000 | C25: ='Cash Flow'!C11 -> -2500 | D25: ='Cash Flow'!D11 -> -2500 | E25: ='Cash Flow'!E11 -> -2500 | F25: ='Cash Flow'!F11 -> -2500 | H25: =INDEX(Monthly!$C$84:$BJ$84,($R$2-1)*12+1) -> -138000 | I25: =INDEX(Monthly!$C$84:$BJ$84,($R$2-1)*12+2) -> 0 | J25: =INDEX(Monthly!$C$84:$BJ$84,($R$2-1)*12+3) -> 0 | K25: =INDEX(Monthly!$C$84:$BJ$84,($R$2-1)*12+4) -> 0 | L25: =INDEX(Monthly!$C$84:$BJ$84,($R$2-1)*12+5) -> 0 | M25: =INDEX(Monthly!$C$84:$BJ$84,($R$2-1)*12+6) -> 0 | N25: =INDEX(Monthly!$C$84:$BJ$84,($R$2-1)*12+7) -> 0 | O25: =INDEX(Monthly!$C$84:$BJ$84,($R$2-1)*12+8) -> 0 | P25: =INDEX(Monthly!$C$84:$BJ$84,($R$2-1)*12+9) -> 0 | Q25: =INDEX(Monthly!$C$84:$BJ$84,($R$2-1)*12+10) -> 0 | R25: =INDEX(Monthly!$C$84:$BJ$84,($R$2-1)*12+11) -> 0 | S25: =INDEX(Monthly!$C$84:$BJ$84,($R$2-1)*12+12) -> 0
A26: Equity raised | B26: ='Cash Flow'!B12 -> 100000 | C26: ='Cash Flow'!C12 -> 0 | D26: ='Cash Flow'!D12 -> 0 | E26: ='Cash Flow'!E12 -> 0 | F26: ='Cash Flow'!F12 -> 0 | H26: =INDEX(Monthly!$C$85:$BJ$85,($R$2-1)*12+1) -> 100000 | I26: =INDEX(Monthly!$C$85:$BJ$85,($R$2-1)*12+2) -> 0 | J26: =INDEX(Monthly!$C$85:$BJ$85,($R$2-1)*12+3) -> 0 | K26: =INDEX(Monthly!$C$85:$BJ$85,($R$2-1)*12+4) -> 0 | L26: =INDEX(Monthly!$C$85:$BJ$85,($R$2-1)*12+5) -> 0 | M26: =INDEX(Monthly!$C$85:$BJ$85,($R$2-1)*12+6) -> 0 | N26: =INDEX(Monthly!$C$85:$BJ$85,($R$2-1)*12+7) -> 0 | O26: =INDEX(Monthly!$C$85:$BJ$85,($R$2-1)*12+8) -> 0 | P26: =INDEX(Monthly!$C$85:$BJ$85,($R$2-1)*12+9) -> 0 | Q26: =INDEX(Monthly!$C$85:$BJ$85,($R$2-1)*12+10) -> 0 | R26: =INDEX(Monthly!$C$85:$BJ$85,($R$2-1)*12+11) -> 0 | S26: =INDEX(Monthly!$C$85:$BJ$85,($R$2-1)*12+12) -> 0
A27: Loan drawdown | B27: ='Cash Flow'!B13 -> 90000 | C27: ='Cash Flow'!C13 -> 0 | D27: ='Cash Flow'!D13 -> 0 | E27: ='Cash Flow'!E13 -> 0 | F27: ='Cash Flow'!F13 -> 0 | H27: =INDEX(Monthly!$C$70:$BJ$70,($R$2-1)*12+1) -> 90000 | I27: =INDEX(Monthly!$C$70:$BJ$70,($R$2-1)*12+2) -> 0 | J27: =INDEX(Monthly!$C$70:$BJ$70,($R$2-1)*12+3) -> 0 | K27: =INDEX(Monthly!$C$70:$BJ$70,($R$2-1)*12+4) -> 0 | L27: =INDEX(Monthly!$C$70:$BJ$70,($R$2-1)*12+5) -> 0 | M27: =INDEX(Monthly!$C$70:$BJ$70,($R$2-1)*12+6) -> 0 | N27: =INDEX(Monthly!$C$70:$BJ$70,($R$2-1)*12+7) -> 0 | O27: =INDEX(Monthly!$C$70:$BJ$70,($R$2-1)*12+8) -> 0 | P27: =INDEX(Monthly!$C$70:$BJ$70,($R$2-1)*12+9) -> 0 | Q27: =INDEX(Monthly!$C$70:$BJ$70,($R$2-1)*12+10) -> 0 | R27: =INDEX(Monthly!$C$70:$BJ$70,($R$2-1)*12+11) -> 0 | S27: =INDEX(Monthly!$C$70:$BJ$70,($R$2-1)*12+12) -> 0
A28: Loan repayment | B28: ='Cash Flow'!B14 -> -16500 | C28: ='Cash Flow'!C14 -> -18000 | D28: ='Cash Flow'!D14 -> -18000 | E28: ='Cash Flow'!E14 -> -18000 | F28: ='Cash Flow'!F14 -> -18000 | H28: =INDEX(Monthly!$C$71:$BJ$71,($R$2-1)*12+1) -> 0 | I28: =INDEX(Monthly!$C$71:$BJ$71,($R$2-1)*12+2) -> -1500 | J28: =INDEX(Monthly!$C$71:$BJ$71,($R$2-1)*12+3) -> -1500 | K28: =INDEX(Monthly!$C$71:$BJ$71,($R$2-1)*12+4) -> -1500 | L28: =INDEX(Monthly!$C$71:$BJ$71,($R$2-1)*12+5) -> -1500 | M28: =INDEX(Monthly!$C$71:$BJ$71,($R$2-1)*12+6) -> -1500 | N28: =INDEX(Monthly!$C$71:$BJ$71,($R$2-1)*12+7) -> -1500 | O28: =INDEX(Monthly!$C$71:$BJ$71,($R$2-1)*12+8) -> -1500 | P28: =INDEX(Monthly!$C$71:$BJ$71,($R$2-1)*12+9) -> -1500 | Q28: =INDEX(Monthly!$C$71:$BJ$71,($R$2-1)*12+10) -> -1500 | R28: =INDEX(Monthly!$C$71:$BJ$71,($R$2-1)*12+11) -> -1500 | S28: =INDEX(Monthly!$C$71:$BJ$71,($R$2-1)*12+12) -> -1500
A29: Financing cash flow | B29: ='Cash Flow'!B15 -> 173500 | C29: ='Cash Flow'!C15 -> -18000 | D29: ='Cash Flow'!D15 -> -18000 | E29: ='Cash Flow'!E15 -> -18000 | F29: ='Cash Flow'!F15 -> -18000 | H29: =INDEX(Monthly!$C$86:$BJ$86,($R$2-1)*12+1) -> 190000 | I29: =INDEX(Monthly!$C$86:$BJ$86,($R$2-1)*12+2) -> -1500 | J29: =INDEX(Monthly!$C$86:$BJ$86,($R$2-1)*12+3) -> -1500 | K29: =INDEX(Monthly!$C$86:$BJ$86,($R$2-1)*12+4) -> -1500 | L29: =INDEX(Monthly!$C$86:$BJ$86,($R$2-1)*12+5) -> -1500 | M29: =INDEX(Monthly!$C$86:$BJ$86,($R$2-1)*12+6) -> -1500 | N29: =INDEX(Monthly!$C$86:$BJ$86,($R$2-1)*12+7) -> -1500 | O29: =INDEX(Monthly!$C$86:$BJ$86,($R$2-1)*12+8) -> -1500 | P29: =INDEX(Monthly!$C$86:$BJ$86,($R$2-1)*12+9) -> -1500 | Q29: =INDEX(Monthly!$C$86:$BJ$86,($R$2-1)*12+10) -> -1500 | R29: =INDEX(Monthly!$C$86:$BJ$86,($R$2-1)*12+11) -> -1500 | S29: =INDEX(Monthly!$C$86:$BJ$86,($R$2-1)*12+12) -> -1500
A30: Net change in cash | B30: ='Cash Flow'!B16 -> 19840.299 | C30: ='Cash Flow'!C16 -> -1734.2661 | D30: ='Cash Flow'!D16 -> 7504.3816 | E30: ='Cash Flow'!E16 -> 17402.51 | F30: ='Cash Flow'!F16 -> 24162.997 | H30: =INDEX(Monthly!$C$87:$BJ$87,($R$2-1)*12+1) -> 43071.009 | I30: =INDEX(Monthly!$C$87:$BJ$87,($R$2-1)*12+2) -> -9025.5731 | J30: =INDEX(Monthly!$C$87:$BJ$87,($R$2-1)*12+3) -> -5469.1922 | K30: =INDEX(Monthly!$C$87:$BJ$87,($R$2-1)*12+4) -> -3868.0913 | L30: =INDEX(Monthly!$C$87:$BJ$87,($R$2-1)*12+5) -> -2473.3093 | M30: =INDEX(Monthly!$C$87:$BJ$87,($R$2-1)*12+6) -> -1078.5273 | N30: =INDEX(Monthly!$C$87:$BJ$87,($R$2-1)*12+7) -> 316.25473 | O30: =INDEX(Monthly!$C$87:$BJ$87,($R$2-1)*12+8) -> 434.84233 | P30: =INDEX(Monthly!$C$87:$BJ$87,($R$2-1)*12+9) -> 446.09233 | Q30: =INDEX(Monthly!$C$87:$BJ$87,($R$2-1)*12+10) -> 457.34233 | R30: =INDEX(Monthly!$C$87:$BJ$87,($R$2-1)*12+11) -> 468.59233 | S30: =INDEX(Monthly!$C$87:$BJ$87,($R$2-1)*12+12) -> -3439.1401
A31: Closing cash | B31: ='Cash Flow'!B18 -> 19840.299 | C31: ='Cash Flow'!C18 -> 18106.033 | D31: ='Cash Flow'!D18 -> 25610.415 | E31: ='Cash Flow'!E18 -> 43012.925 | F31: ='Cash Flow'!F18 -> 67175.922 | H31: =INDEX(Monthly!$C$89:$BJ$89,($R$2-1)*12+1) -> 43071.009 | I31: =INDEX(Monthly!$C$89:$BJ$89,($R$2-1)*12+2) -> 34045.435 | J31: =INDEX(Monthly!$C$89:$BJ$89,($R$2-1)*12+3) -> 28576.243 | K31: =INDEX(Monthly!$C$89:$BJ$89,($R$2-1)*12+4) -> 24708.152 | L31: =INDEX(Monthly!$C$89:$BJ$89,($R$2-1)*12+5) -> 22234.843 | M31: =INDEX(Monthly!$C$89:$BJ$89,($R$2-1)*12+6) -> 21156.315 | N31: =INDEX(Monthly!$C$89:$BJ$89,($R$2-1)*12+7) -> 21472.57 | O31: =INDEX(Monthly!$C$89:$BJ$89,($R$2-1)*12+8) -> 21907.412 | P31: =INDEX(Monthly!$C$89:$BJ$89,($R$2-1)*12+9) -> 22353.505 | Q31: =INDEX(Monthly!$C$89:$BJ$89,($R$2-1)*12+10) -> 22810.847 | R31: =INDEX(Monthly!$C$89:$BJ$89,($R$2-1)*12+11) -> 23279.439 | S31: =INDEX(Monthly!$C$89:$BJ$89,($R$2-1)*12+12) -> 19840.299
A39: Balance sheet at year end ($'000) | H39: ="Balance sheet at month end ($'000) — Year "&$R$2 -> Balance sheet at month end ($'000) — Year 1
B40: 1 | C40: 2 | D40: 3 | E40: 4 | F40: 5 | H40: =INDEX(Monthly!$C$4:$BJ$4,($R$2-1)*12+1) -> 1 | I40: =INDEX(Monthly!$C$4:$BJ$4,($R$2-1)*12+2) -> 2 | J40: =INDEX(Monthly!$C$4:$BJ$4,($R$2-1)*12+3) -> 3 | K40: =INDEX(Monthly!$C$4:$BJ$4,($R$2-1)*12+4) -> 4 | L40: =INDEX(Monthly!$C$4:$BJ$4,($R$2-1)*12+5) -> 5 | M40: =INDEX(Monthly!$C$4:$BJ$4,($R$2-1)*12+6) -> 6 | N40: =INDEX(Monthly!$C$4:$BJ$4,($R$2-1)*12+7) -> 7 | O40: =INDEX(Monthly!$C$4:$BJ$4,($R$2-1)*12+8) -> 8 | P40: =INDEX(Monthly!$C$4:$BJ$4,($R$2-1)*12+9) -> 9 | Q40: =INDEX(Monthly!$C$4:$BJ$4,($R$2-1)*12+10) -> 10 | R40: =INDEX(Monthly!$C$4:$BJ$4,($R$2-1)*12+11) -> 11 | S40: =INDEX(Monthly!$C$4:$BJ$4,($R$2-1)*12+12) -> 12
A41: Cash | B41: ='Balance Sheet'!B5 -> 19840.299 | C41: ='Balance Sheet'!C5 -> 18106.033 | D41: ='Balance Sheet'!D5 -> 25610.415 | E41: ='Balance Sheet'!E5 -> 43012.925 | F41: ='Balance Sheet'!F5 -> 67175.922 | H41: =INDEX(Monthly!$C$89:$BJ$89,($R$2-1)*12+1) -> 43071.009 | I41: =INDEX(Monthly!$C$89:$BJ$89,($R$2-1)*12+2) -> 34045.435 | J41: =INDEX(Monthly!$C$89:$BJ$89,($R$2-1)*12+3) -> 28576.243 | K41: =INDEX(Monthly!$C$89:$BJ$89,($R$2-1)*12+4) -> 24708.152 | L41: =INDEX(Monthly!$C$89:$BJ$89,($R$2-1)*12+5) -> 22234.843 | M41: =INDEX(Monthly!$C$89:$BJ$89,($R$2-1)*12+6) -> 21156.315 | N41: =INDEX(Monthly!$C$89:$BJ$89,($R$2-1)*12+7) -> 21472.57 | O41: =INDEX(Monthly!$C$89:$BJ$89,($R$2-1)*12+8) -> 21907.412 | P41: =INDEX(Monthly!$C$89:$BJ$89,($R$2-1)*12+9) -> 22353.505 | Q41: =INDEX(Monthly!$C$89:$BJ$89,($R$2-1)*12+10) -> 22810.847 | R41: =INDEX(Monthly!$C$89:$BJ$89,($R$2-1)*12+11) -> 23279.439 | S41: =INDEX(Monthly!$C$89:$BJ$89,($R$2-1)*12+12) -> 19840.299
A42: Accounts receivable | B42: ='Balance Sheet'!B6 -> 2083.2 | C42: ='Balance Sheet'!C6 -> 2218.7189 | D42: ='Balance Sheet'!D6 -> 2363.196 | E42: ='Balance Sheet'!E6 -> 2517.2344 | F42: ='Balance Sheet'!F6 -> 2681.4785 | H42: =INDEX(Monthly!$C$75:$BJ$75,($R$2-1)*12+1) -> 1041.6 | I42: =INDEX(Monthly!$C$75:$BJ$75,($R$2-1)*12+2) -> 1215.2 | J42: =INDEX(Monthly!$C$75:$BJ$75,($R$2-1)*12+3) -> 1881.6 | K42: =INDEX(Monthly!$C$75:$BJ$75,($R$2-1)*12+4) -> 2116.8 | L42: =INDEX(Monthly!$C$75:$BJ$75,($R$2-1)*12+5) -> 2352 | M42: =INDEX(Monthly!$C$75:$BJ$75,($R$2-1)*12+6) -> 2587.2 | N42: =INDEX(Monthly!$C$75:$BJ$75,($R$2-1)*12+7) -> 2822.4 | O42: =INDEX(Monthly!$C$75:$BJ$75,($R$2-1)*12+8) -> 2822.4 | P42: =INDEX(Monthly!$C$75:$BJ$75,($R$2-1)*12+9) -> 2822.4 | Q42: =INDEX(Monthly!$C$75:$BJ$75,($R$2-1)*12+10) -> 2822.4 | R42: =INDEX(Monthly!$C$75:$BJ$75,($R$2-1)*12+11) -> 2822.4 | S42: =INDEX(Monthly!$C$75:$BJ$75,($R$2-1)*12+12) -> 2083.2
A43: Inventory | B43: ='Balance Sheet'!B7 -> 861.6288 | C43: ='Balance Sheet'!C7 -> 918.45024 | D43: ='Balance Sheet'!D7 -> 979.08649 | E43: ='Balance Sheet'!E7 -> 1043.7988 | F43: ='Balance Sheet'!F7 -> 1112.8665 | H43: =INDEX(Monthly!$C$76:$BJ$76,($R$2-1)*12+1) -> 430.8144 | I43: =INDEX(Monthly!$C$76:$BJ$76,($R$2-1)*12+2) -> 502.6168 | J43: =INDEX(Monthly!$C$76:$BJ$76,($R$2-1)*12+3) -> 767.1744 | K43: =INDEX(Monthly!$C$76:$BJ$76,($R$2-1)*12+4) -> 863.0712 | L43: =INDEX(Monthly!$C$76:$BJ$76,($R$2-1)*12+5) -> 958.968 | M43: =INDEX(Monthly!$C$76:$BJ$76,($R$2-1)*12+6) -> 1054.8648 | N43: =INDEX(Monthly!$C$76:$BJ$76,($R$2-1)*12+7) -> 1150.7616 | O43: =INDEX(Monthly!$C$76:$BJ$76,($R$2-1)*12+8) -> 1150.7616 | P43: =INDEX(Monthly!$C$76:$BJ$76,($R$2-1)*12+9) -> 1150.7616 | Q43: =INDEX(Monthly!$C$76:$BJ$76,($R$2-1)*12+10) -> 1150.7616 | R43: =INDEX(Monthly!$C$76:$BJ$76,($R$2-1)*12+11) -> 1150.7616 | S43: =INDEX(Monthly!$C$76:$BJ$76,($R$2-1)*12+12) -> 861.6288
A44: Net fixed assets | B44: ='Balance Sheet'!B8 -> 118285.71 | C44: ='Balance Sheet'!C8 -> 100714.29 | D44: ='Balance Sheet'!D8 -> 82785.714 | E44: ='Balance Sheet'!E8 -> 64500 | F44: ='Balance Sheet'!F8 -> 45857.143 | H44: =INDEX(Monthly!$C$66:$BJ$66,($R$2-1)*12+1) -> 136357.14 | I44: =INDEX(Monthly!$C$66:$BJ$66,($R$2-1)*12+2) -> 134714.29 | J44: =INDEX(Monthly!$C$66:$BJ$66,($R$2-1)*12+3) -> 133071.43 | K44: =INDEX(Monthly!$C$66:$BJ$66,($R$2-1)*12+4) -> 131428.57 | L44: =INDEX(Monthly!$C$66:$BJ$66,($R$2-1)*12+5) -> 129785.71 | M44: =INDEX(Monthly!$C$66:$BJ$66,($R$2-1)*12+6) -> 128142.86 | N44: =INDEX(Monthly!$C$66:$BJ$66,($R$2-1)*12+7) -> 126500 | O44: =INDEX(Monthly!$C$66:$BJ$66,($R$2-1)*12+8) -> 124857.14 | P44: =INDEX(Monthly!$C$66:$BJ$66,($R$2-1)*12+9) -> 123214.29 | Q44: =INDEX(Monthly!$C$66:$BJ$66,($R$2-1)*12+10) -> 121571.43 | R44: =INDEX(Monthly!$C$66:$BJ$66,($R$2-1)*12+11) -> 119928.57 | S44: =INDEX(Monthly!$C$66:$BJ$66,($R$2-1)*12+12) -> 118285.71
A45: Total assets | B45: ='Balance Sheet'!B9 -> 141070.84 | C45: ='Balance Sheet'!C9 -> 121957.49 | D45: ='Balance Sheet'!D9 -> 111738.41 | E45: ='Balance Sheet'!E9 -> 111073.96 | F45: ='Balance Sheet'!F9 -> 116827.41 | H45: =INDEX(Monthly!$C$103:$BJ$103,($R$2-1)*12+1) -> 180900.57 | I45: =INDEX(Monthly!$C$103:$BJ$103,($R$2-1)*12+2) -> 170477.54 | J45: =INDEX(Monthly!$C$103:$BJ$103,($R$2-1)*12+3) -> 164296.45 | K45: =INDEX(Monthly!$C$103:$BJ$103,($R$2-1)*12+4) -> 159116.59 | L45: =INDEX(Monthly!$C$103:$BJ$103,($R$2-1)*12+5) -> 155331.52 | M45: =INDEX(Monthly!$C$103:$BJ$103,($R$2-1)*12+6) -> 152941.24 | N45: =INDEX(Monthly!$C$103:$BJ$103,($R$2-1)*12+7) -> 151945.73 | O45: =INDEX(Monthly!$C$103:$BJ$103,($R$2-1)*12+8) -> 150737.72 | P45: =INDEX(Monthly!$C$103:$BJ$103,($R$2-1)*12+9) -> 149540.95 | Q45: =INDEX(Monthly!$C$103:$BJ$103,($R$2-1)*12+10) -> 148355.44 | R45: =INDEX(Monthly!$C$103:$BJ$103,($R$2-1)*12+11) -> 147181.17 | S45: =INDEX(Monthly!$C$103:$BJ$103,($R$2-1)*12+12) -> 141070.84
A46: Accounts payable | B46: ='Balance Sheet'!B10 -> 2010.4672 | C46: ='Balance Sheet'!C10 -> 2143.0506 | D46: ='Balance Sheet'!D10 -> 2284.5351 | E46: ='Balance Sheet'!E10 -> 2435.5304 | F46: ='Balance Sheet'!F10 -> 2596.6885 | H46: =INDEX(Monthly!$C$77:$BJ$77,($R$2-1)*12+1) -> 1005.2336 | I46: =INDEX(Monthly!$C$77:$BJ$77,($R$2-1)*12+2) -> 1172.7725 | J46: =INDEX(Monthly!$C$77:$BJ$77,($R$2-1)*12+3) -> 1790.0736 | K46: =INDEX(Monthly!$C$77:$BJ$77,($R$2-1)*12+4) -> 2013.8328 | L46: =INDEX(Monthly!$C$77:$BJ$77,($R$2-1)*12+5) -> 2237.592 | M46: =INDEX(Monthly!$C$77:$BJ$77,($R$2-1)*12+6) -> 2461.3512 | N46: =INDEX(Monthly!$C$77:$BJ$77,($R$2-1)*12+7) -> 2685.1104 | O46: =INDEX(Monthly!$C$77:$BJ$77,($R$2-1)*12+8) -> 2685.1104 | P46: =INDEX(Monthly!$C$77:$BJ$77,($R$2-1)*12+9) -> 2685.1104 | Q46: =INDEX(Monthly!$C$77:$BJ$77,($R$2-1)*12+10) -> 2685.1104 | R46: =INDEX(Monthly!$C$77:$BJ$77,($R$2-1)*12+11) -> 2685.1104 | S46: =INDEX(Monthly!$C$77:$BJ$77,($R$2-1)*12+12) -> 2010.4672
A47: Loan | B47: ='Balance Sheet'!B11 -> 73500 | C47: ='Balance Sheet'!C11 -> 55500 | D47: ='Balance Sheet'!D11 -> 37500 | E47: ='Balance Sheet'!E11 -> 19500 | F47: ='Balance Sheet'!F11 -> 1500 | H47: =INDEX(Monthly!$C$72:$BJ$72,($R$2-1)*12+1) -> 90000 | I47: =INDEX(Monthly!$C$72:$BJ$72,($R$2-1)*12+2) -> 88500 | J47: =INDEX(Monthly!$C$72:$BJ$72,($R$2-1)*12+3) -> 87000 | K47: =INDEX(Monthly!$C$72:$BJ$72,($R$2-1)*12+4) -> 85500 | L47: =INDEX(Monthly!$C$72:$BJ$72,($R$2-1)*12+5) -> 84000 | M47: =INDEX(Monthly!$C$72:$BJ$72,($R$2-1)*12+6) -> 82500 | N47: =INDEX(Monthly!$C$72:$BJ$72,($R$2-1)*12+7) -> 81000 | O47: =INDEX(Monthly!$C$72:$BJ$72,($R$2-1)*12+8) -> 79500 | P47: =INDEX(Monthly!$C$72:$BJ$72,($R$2-1)*12+9) -> 78000 | Q47: =INDEX(Monthly!$C$72:$BJ$72,($R$2-1)*12+10) -> 76500 | R47: =INDEX(Monthly!$C$72:$BJ$72,($R$2-1)*12+11) -> 75000 | S47: =INDEX(Monthly!$C$72:$BJ$72,($R$2-1)*12+12) -> 73500
A48: Total liabilities | B48: ='Balance Sheet'!B12 -> 75510.467 | C48: ='Balance Sheet'!C12 -> 57643.051 | D48: ='Balance Sheet'!D12 -> 39784.535 | E48: ='Balance Sheet'!E12 -> 21935.53 | F48: ='Balance Sheet'!F12 -> 4096.6885 | H48: =INDEX(Monthly!$C$104:$BJ$104,($R$2-1)*12+1) -> 91005.234 | I48: =INDEX(Monthly!$C$104:$BJ$104,($R$2-1)*12+2) -> 89672.773 | J48: =INDEX(Monthly!$C$104:$BJ$104,($R$2-1)*12+3) -> 88790.074 | K48: =INDEX(Monthly!$C$104:$BJ$104,($R$2-1)*12+4) -> 87513.833 | L48: =INDEX(Monthly!$C$104:$BJ$104,($R$2-1)*12+5) -> 86237.592 | M48: =INDEX(Monthly!$C$104:$BJ$104,($R$2-1)*12+6) -> 84961.351 | N48: =INDEX(Monthly!$C$104:$BJ$104,($R$2-1)*12+7) -> 83685.11 | O48: =INDEX(Monthly!$C$104:$BJ$104,($R$2-1)*12+8) -> 82185.11 | P48: =INDEX(Monthly!$C$104:$BJ$104,($R$2-1)*12+9) -> 80685.11 | Q48: =INDEX(Monthly!$C$104:$BJ$104,($R$2-1)*12+10) -> 79185.11 | R48: =INDEX(Monthly!$C$104:$BJ$104,($R$2-1)*12+11) -> 77685.11 | S48: =INDEX(Monthly!$C$104:$BJ$104,($R$2-1)*12+12) -> 75510.467
A49: Paid-in capital | B49: ='Balance Sheet'!B13 -> 100000 | C49: ='Balance Sheet'!C13 -> 100000 | D49: ='Balance Sheet'!D13 -> 100000 | E49: ='Balance Sheet'!E13 -> 100000 | F49: ='Balance Sheet'!F13 -> 100000 | H49: =INDEX(Monthly!$C$101:$BJ$101,($R$2-1)*12+1) -> 100000 | I49: =INDEX(Monthly!$C$101:$BJ$101,($R$2-1)*12+2) -> 100000 | J49: =INDEX(Monthly!$C$101:$BJ$101,($R$2-1)*12+3) -> 100000 | K49: =INDEX(Monthly!$C$101:$BJ$101,($R$2-1)*12+4) -> 100000 | L49: =INDEX(Monthly!$C$101:$BJ$101,($R$2-1)*12+5) -> 100000 | M49: =INDEX(Monthly!$C$101:$BJ$101,($R$2-1)*12+6) -> 100000 | N49: =INDEX(Monthly!$C$101:$BJ$101,($R$2-1)*12+7) -> 100000 | O49: =INDEX(Monthly!$C$101:$BJ$101,($R$2-1)*12+8) -> 100000 | P49: =INDEX(Monthly!$C$101:$BJ$101,($R$2-1)*12+9) -> 100000 | Q49: =INDEX(Monthly!$C$101:$BJ$101,($R$2-1)*12+10) -> 100000 | R49: =INDEX(Monthly!$C$101:$BJ$101,($R$2-1)*12+11) -> 100000 | S49: =INDEX(Monthly!$C$101:$BJ$101,($R$2-1)*12+12) -> 100000
A50: Retained earnings | B50: ='Balance Sheet'!B14 -> -34439.625 | C50: ='Balance Sheet'!C14 -> -35685.562 | D50: ='Balance Sheet'!D14 -> -28046.123 | E50: ='Balance Sheet'!E14 -> -10861.572 | F50: ='Balance Sheet'!F14 -> 12730.721 | H50: =INDEX(Monthly!$C$102:$BJ$102,($R$2-1)*12+1) -> -10104.668 | I50: =INDEX(Monthly!$C$102:$BJ$102,($R$2-1)*12+2) -> -19195.235 | J50: =INDEX(Monthly!$C$102:$BJ$102,($R$2-1)*12+3) -> -24493.627 | K50: =INDEX(Monthly!$C$102:$BJ$102,($R$2-1)*12+4) -> -28397.238 | L50: =INDEX(Monthly!$C$102:$BJ$102,($R$2-1)*12+5) -> -30906.067 | M50: =INDEX(Monthly!$C$102:$BJ$102,($R$2-1)*12+6) -> -32020.114 | N50: =INDEX(Monthly!$C$102:$BJ$102,($R$2-1)*12+7) -> -31739.379 | O50: =INDEX(Monthly!$C$102:$BJ$102,($R$2-1)*12+8) -> -31447.393 | P50: =INDEX(Monthly!$C$102:$BJ$102,($R$2-1)*12+9) -> -31144.158 | Q50: =INDEX(Monthly!$C$102:$BJ$102,($R$2-1)*12+10) -> -30829.673 | R50: =INDEX(Monthly!$C$102:$BJ$102,($R$2-1)*12+11) -> -30503.938 | S50: =INDEX(Monthly!$C$102:$BJ$102,($R$2-1)*12+12) -> -34439.625
...

Sheet Scenarios
A1: Scenarios — Low / Base / High | H1: =HYPERLINK("#'Cover'!A1","◂ Contents") -> ◂ Contents
A2: All three scenarios calculated side by side, live: change any input and every column updates. Active = the scenario chosen on the Dashboard.
A5: Key drivers
A6: Driver | B6: Low | C6: Base | D6: High | E6: Active
A7: Street service days per truck per month (year average) (days) | B7: =Inputs!$B$9 -> 17 | C7: =Inputs!$C$9 -> 18 | D7: =Inputs!$D$9 -> 19 | E7: =Inputs!$E$9 -> 18
A8: Meals per street service day at maturity (year 1) (meals) | B8: =Inputs!$B$17 -> 78 | C8: =Inputs!$C$17 -> 88 | D8: =Inputs!$D$17 -> 98 | E8: =Inputs!$E$17 -> 88
A9: Average ticket per meal (year 1) ($) | B9: =Inputs!$B$19 -> 13 | C9: =Inputs!$C$19 -> 14 | D9: =Inputs!$D$19 -> 15 | E9: =Inputs!$E$19 -> 14
A10: Event and catering days per truck per month (year 1) (days) | B10: =Inputs!$B$23 -> 2.5 | C10: =Inputs!$C$23 -> 3 | D10: =Inputs!$D$23 -> 3.5 | E10: =Inputs!$E$23 -> 3
A11: Food cost, % of sales (%) | B11: =Inputs!$B$29 -> 0.345 | C11: =Inputs!$C$29 -> 0.33 | D11: =Inputs!$D$29 -> 0.315 | E11: =Inputs!$E$29 -> 0.33
A12: Truck purchase, each ($) | B12: =Inputs!$B$49 -> 95000 | C12: =Inputs!$C$49 -> 95000 | D12: =Inputs!$D$49 -> 95000 | E12: =Inputs!$E$49 -> 95000
A13: Equity raised at start ($) | B13: =Inputs!$B$71 -> 100000 | C13: =Inputs!$C$71 -> 100000 | D13: =Inputs!$D$71 -> 100000 | E13: =Inputs!$E$71 -> 100000
A15: Results by scenario ($'000)
A16: Output | B16: Low | C16: Base | D16: High | E16: Active
A17: Revenue — final year | B17: =F30 -> 264498.79 | C17: =F31 -> 406053.09 | D17: =F32 -> 588090.22 | E17: ='P&L'!F5 -> 406053.09
A18: Revenue — whole plan | B18: =SUM(B30:F30) -> 1208322.1 | C18: =SUM(B31:F31) -> 1756742.3 | D18: =SUM(B32:F32) -> 2417583.7 | E18: =SUM('P&L'!$B$5:$F$5) -> 1756742.3
A19: EBITDA — final year | B19: =F36 -> -48078.489 | C19: =F37 -> 49525.516 | D19: =F38 -> 178096.69 | E19: ='P&L'!F19 -> 49525.516
A20: EBITDA margin — final year | B20: =IF(B17=0,0,B19/B17) -> -0.18177205 | C20: =IF(C17=0,0,C19/C17) -> 0.12196808 | D20: =IF(D17=0,0,D19/D17) -> 0.30283905 | E20: =IF(E17=0,0,E19/E17) -> 0.12196808
A21: Net income — final year | B21: =F42 -> -70166.346 | C21: =F43 -> 23592.293 | D21: =F44 -> 123246.97 | E21: ='P&L'!F26 -> 23592.293
A22: Net income — whole plan | B22: =SUM(B42:F42) -> -367104.45 | C22: =SUM(B43:F43) -> 12730.721 | D22: =SUM(B44:F44) -> 390953.02 | E22: =SUM('P&L'!$B$26:$F$26) -> 12730.721
A23: Cash at the end of the plan | B23: =F48 -> -312120.36 | C23: =F49 -> 67175.922 | D23: =F50 -> 444596.24 | E23: ='Balance Sheet'!F5 -> 67175.922
A24: Lowest cash balance | B24: =MIN('Scenario calc'!$C$91:$BJ$91) -> -312120.36 | C24: =MIN('Scenario calc'!$C$211:$BJ$211) -> 9872.4151 | D24: =MIN('Scenario calc'!$C$331:$BJ$331) -> 43192.085 | E24: ='Break-even'!B18 -> 9872.4151
A25: Lowest cash point (month #) | B25: =MATCH(MIN('Scenario calc'!$C$91:$BJ$91),'Scenario calc'!$C$91:$BJ$91,0) -> 60 | C25: =MATCH(MIN('Scenario calc'!$C$211:$BJ$211),'Scenario calc'!$C$211:$BJ$211,0) -> 26 | D25: =MATCH(MIN('Scenario calc'!$C$331:$BJ$331),'Scenario calc'!$C$331:$BJ$331,0) -> 2 | E25: ='Break-even'!B6 -> 26
A26: Funding required (incl. cash buffer) | B26: =SUMPRODUCT(--('Scenario calc'!$C$6:$BJ$6<=B25),'Scenario calc'!$C$64:$BJ$64)-SUMPRODUCT(--('Scenario calc'!$C$6:$BJ$6<=B25),'Scenario calc'!$C$85:$BJ$85)-SUMPRODUCT(--('Scenario calc'!$C$6:$BJ$6<=B25),'Scenario calc'!$C$73:$BJ$73)+Inputs!$B$86 -> 544120.36 | C26: =SUMPRODUCT(--('Scenario calc'!$C$126:$BJ$126<=C25),'Scenario calc'!$C$184:$BJ$184)-SUMPRODUCT(--('Scenario calc'!$C$126:$BJ$126<=C25),'Scenario calc'!$C$205:$BJ$205)-SUMPRODUCT(--('Scenario calc'!$C$126:$BJ$126<=C25),'Scenario calc'!$C$193:$BJ$193)+Inputs!$C$86 -> 222127.58 | D26: =SUMPRODUCT(--('Scenario calc'!$C$246:$BJ$246<=D25),'Scenario calc'!$C$304:$BJ$304)-SUMPRODUCT(--('Scenario calc'!$C$246:$BJ$246<=D25),'Scenario calc'!$C$325:$BJ$325)-SUMPRODUCT(--('Scenario calc'!$C$246:$BJ$246<=D25),'Scenario calc'!$C$313:$BJ$313)+Inputs!$D$86 -> 188807.91 | E26: ='Break-even'!B12 -> 222127.58
A28: Revenue by year ($'000)
A29: Scenario | B29: 1 | C29: 2 | D29: 3 | E29: 4 | F29: 5
A30: Low | B30: =SUMIF('Scenario calc'!$C$7:$BJ$7,B$29,'Scenario calc'!$C$26:$BJ$26) -> 181039.67 | C30: =SUMIF('Scenario calc'!$C$7:$BJ$7,C$29,'Scenario calc'!$C$26:$BJ$26) -> 249243.12 | D30: =SUMIF('Scenario calc'!$C$7:$BJ$7,D$29,'Scenario calc'!$C$26:$BJ$26) -> 254227.98 | E30: =SUMIF('Scenario calc'!$C$7:$BJ$7,E$29,'Scenario calc'!$C$26:$BJ$26) -> 259312.54 | F30: =SUMIF('Scenario calc'!$C$7:$BJ$7,F$29,'Scenario calc'!$C$26:$BJ$26) -> 264498.79
A31: Base | B31: =SUMIF('Scenario calc'!$C$127:$BJ$127,B$29,'Scenario calc'!$C$146:$BJ$146) -> 273896 | C31: =SUMIF('Scenario calc'!$C$127:$BJ$127,C$29,'Scenario calc'!$C$146:$BJ$146) -> 336825.82 | D31: =SUMIF('Scenario calc'!$C$127:$BJ$127,D$29,'Scenario calc'!$C$146:$BJ$146) -> 358461.37 | E31: =SUMIF('Scenario calc'!$C$127:$BJ$127,E$29,'Scenario calc'!$C$146:$BJ$146) -> 381506.04 | F31: =SUMIF('Scenario calc'!$C$127:$BJ$127,F$29,'Scenario calc'!$C$146:$BJ$146) -> 406053.09
A32: High | B32: =SUMIF('Scenario calc'!$C$247:$BJ$247,B$29,'Scenario calc'!$C$266:$BJ$266) -> 370256.6 | C32: =SUMIF('Scenario calc'!$C$247:$BJ$247,C$29,'Scenario calc'!$C$266:$BJ$266) -> 440469.12 | D32: =SUMIF('Scenario calc'!$C$247:$BJ$247,D$29,'Scenario calc'!$C$266:$BJ$266) -> 484864.95 | E32: =SUMIF('Scenario calc'!$C$247:$BJ$247,E$29,'Scenario calc'!$C$266:$BJ$266) -> 533902.86 | F32: =SUMIF('Scenario calc'!$C$247:$BJ$247,F$29,'Scenario calc'!$C$266:$BJ$266) -> 588090.22
A34: EBITDA by year ($'000)
A35: Scenario | B35: 1 | C35: 2 | D35: 3 | E35: 4 | F35: 5
A36: Low | B36: =SUMIF('Scenario calc'!$C$7:$BJ$7,B$35,'Scenario calc'!$C$48:$BJ$48) -> -70979.563 | C36: =SUMIF('Scenario calc'!$C$7:$BJ$7,C$35,'Scenario calc'!$C$48:$BJ$48) -> -38601.113 | D36: =SUMIF('Scenario calc'!$C$7:$BJ$7,D$35,'Scenario calc'!$C$48:$BJ$48) -> -41612.953 | E36: =SUMIF('Scenario calc'!$C$7:$BJ$7,E$35,'Scenario calc'!$C$48:$BJ$48) -> -44770.097 | F36: =SUMIF('Scenario calc'!$C$7:$BJ$7,F$35,'Scenario calc'!$C$48:$BJ$48) -> -48078.489
A37: Base | B37: =SUMIF('Scenario calc'!$C$127:$BJ$127,B$35,'Scenario calc'!$C$168:$BJ$168) -> -7305.964 | C37: =SUMIF('Scenario calc'!$C$127:$BJ$127,C$35,'Scenario calc'!$C$168:$BJ$168) -> 24630.491 | D37: =SUMIF('Scenario calc'!$C$127:$BJ$127,D$35,'Scenario calc'!$C$168:$BJ$168) -> 32253.01 | E37: =SUMIF('Scenario calc'!$C$127:$BJ$127,E$35,'Scenario calc'!$C$168:$BJ$168) -> 40535.265 | F37: =SUMIF('Scenario calc'!$C$127:$BJ$127,F$35,'Scenario calc'!$C$168:$BJ$168) -> 49525.516
A38: High | B38: =SUMIF('Scenario calc'!$C$247:$BJ$247,B$35,'Scenario calc'!$C$288:$BJ$288) -> 63466.417 | C38: =SUMIF('Scenario calc'!$C$247:$BJ$247,C$35,'Scenario calc'!$C$288:$BJ$288) -> 101989.4 | D38: =SUMIF('Scenario calc'!$C$247:$BJ$247,D$35,'Scenario calc'!$C$288:$BJ$288) -> 124559.56 | E38: =SUMIF('Scenario calc'!$C$247:$BJ$247,E$35,'Scenario calc'!$C$288:$BJ$288) -> 149827.42 | F38: =SUMIF('Scenario calc'!$C$247:$BJ$247,F$35,'Scenario calc'!$C$288:$BJ$288) -> 178096.69
A40: Net income by year ($'000)
A41: Scenario | B41: 1 | C41: 2 | D41: 3 | E41: 4 | F41: 5
A42: Low | B42: =SUMIF('Scenario calc'!$C$7:$BJ$7,B$41,'Scenario calc'!$C$57:$BJ$57) -> -98113.224 | C42: =SUMIF('Scenario calc'!$C$7:$BJ$7,C$41,'Scenario calc'!$C$57:$BJ$57) -> -64477.542 | D42: =SUMIF('Scenario calc'!$C$7:$BJ$7,D$41,'Scenario calc'!$C$57:$BJ$57) -> -66226.524 | E42: =SUMIF('Scenario calc'!$C$7:$BJ$7,E$41,'Scenario calc'!$C$57:$BJ$57) -> -68120.812 | F42: =SUMIF('Scenario calc'!$C$7:$BJ$7,F$41,'Scenario calc'!$C$57:$BJ$57) -> -70166.346
A43: Base | B43: =SUMIF('Scenario calc'!$C$127:$BJ$127,B$41,'Scenario calc'!$C$177:$BJ$177) -> -34439.625 | C43: =SUMIF('Scenario calc'!$C$127:$BJ$127,C$41,'Scenario calc'!$C$177:$BJ$177) -> -1245.9377 | D43: =SUMIF('Scenario calc'!$C$127:$BJ$127,D$41,'Scenario calc'!$C$177:$BJ$177) -> 7639.439 | E43: =SUMIF('Scenario calc'!$C$127:$BJ$127,E$41,'Scenario calc'!$C$177:$BJ$177) -> 17184.551 | F43: =SUMIF('Scenario calc'!$C$127:$BJ$127,F$41,'Scenario calc'!$C$177:$BJ$177) -> 23592.293
A44: High | B44: =SUMIF('Scenario calc'!$C$247:$BJ$247,B$41,'Scenario calc'!$C$297:$BJ$297) -> 28702.877 | C44: =SUMIF('Scenario calc'!$C$247:$BJ$247,C$41,'Scenario calc'!$C$297:$BJ$297) -> 60129.245 | D44: =SUMIF('Scenario calc'!$C$247:$BJ$247,D$41,'Scenario calc'!$C$297:$BJ$297) -> 78957.328 | E44: =SUMIF('Scenario calc'!$C$247:$BJ$247,E$41,'Scenario calc'!$C$297:$BJ$297) -> 99916.598 | F44: =SUMIF('Scenario calc'!$C$247:$BJ$247,F$41,'Scenario calc'!$C$297:$BJ$297) -> 123246.97
A46: Cash at year end by year ($'000)
A47: Scenario | B47: 1 | C47: 2 | D47: 3 | E47: 4 | F47: 5
...

Sheet Break-even
A1: Startup costs, funding need and break-even | H1: =HYPERLINK("#'Cover'!A1","◂ Contents") -> ◂ Contents
A2: Live for the selected scenario. Periods are counted in months from the start of the plan.
A3: Scenario shown | B3: =CHOOSE(Dashboard!$B$4,"Low","Base","High") -> Base
A5: Startup costs & funding need (up to the lowest cash point)
A6: Lowest cash point (month #) | B6: =MATCH(MIN(Monthly!$C$89:$BJ$89),Monthly!$C$89:$BJ$89,0) -> 26
A7: Capital spending up to the lowest cash point | B7: =SUMPRODUCT(--(Monthly!$C$4:$BJ$4<=$B$6),Monthly!$C$62:$BJ$62) -> 143000
A8: Operating cash burn up to the lowest cash point | B8: =-SUMPRODUCT(--(Monthly!$C$4:$BJ$4<=$B$6),Monthly!$C$83:$BJ$83) -> -372.4151 | D8: Losses and working capital before the business funds itself
A9: Loan repayments up to the lowest cash point | B9: =-SUMPRODUCT(--(Monthly!$C$4:$BJ$4<=$B$6),Monthly!$C$71:$BJ$71) -> 37500
A10: Total uses of funds | B10: =B7+B8+B9 -> 180127.58
A11: Minimum cash buffer to keep | B11: =Inputs!$E$86 -> 42000 | D11: Input on the Inputs sheet
A12: Funding required (uses + buffer) | B12: =B10+B11 -> 222127.58
A14: Equity raised | B14: =Inputs!$E$71 -> 100000
A15: Loan drawn | B15: =Inputs!$E$72 -> 90000
A16: Total sources of funds | B16: =B14+B15 -> 190000
A17: Funding surplus / (shortfall) | B17: =B16-B12 -> -32127.585 | D17: Negative = raise at least this much more
A18: Lowest cash balance in the plan | B18: =MIN(Monthly!$C$89:$BJ$89) -> 9872.4151 | D18: Equals sources minus uses
A20: Break-even timing
A21: First month with positive EBITDA (month #) | B21: =IFERROR(MATCH(1,Monthly!$C$90:$BJ$90,0),"Not within horizon") -> 6
A22: First month with positive net income (month #) | B22: =IFERROR(MATCH(1,Monthly!$C$93:$BJ$93,0),"Not within horizon") -> 7
A23: Cash invested paid back (month #) | B23: =IF(MIN(Monthly!$C$95:$BJ$95)>=0,"No investment to pay back",IFERROR(MATCH(1,Monthly!$C$97:$BJ$97,0),"Not within horizon")) -> Not within horizon | D23: Cumulative operating + investing cash flow back to zero
A25: Annual break-even revenue
A26: Year # | B26: 1 | C26: 2 | D26: 3 | E26: 4 | F26: 5
B27: Year 1 | C27: Year 2 | D27: Year 3 | E27: Year 4 | F27: Year 5
A28: Revenue | B28: =SUMIF(Monthly!$C$5:$BJ$5,B$26,Monthly!$C$24:$BJ$24) -> 273896 | C28: =SUMIF(Monthly!$C$5:$BJ$5,C$26,Monthly!$C$24:$BJ$24) -> 336825.82 | D28: =SUMIF(Monthly!$C$5:$BJ$5,D$26,Monthly!$C$24:$BJ$24) -> 358461.37 | E28: =SUMIF(Monthly!$C$5:$BJ$5,E$26,Monthly!$C$24:$BJ$24) -> 381506.04 | F28: =SUMIF(Monthly!$C$5:$BJ$5,F$26,Monthly!$C$24:$BJ$24) -> 406053.09
A29: Gross profit | B29: =SUMIF(Monthly!$C$5:$BJ$5,B$26,Monthly!$C$33:$BJ$33) -> 161966.54 | C29: =SUMIF(Monthly!$C$5:$BJ$5,C$26,Monthly!$C$33:$BJ$33) -> 199005.1 | D29: =SUMIF(Monthly!$C$5:$BJ$5,D$26,Monthly!$C$33:$BJ$33) -> 211683.05 | E29: =SUMIF(Monthly!$C$5:$BJ$5,E$26,Monthly!$C$33:$BJ$33) -> 225178.61 | F29: =SUMIF(Monthly!$C$5:$BJ$5,F$26,Monthly!$C$33:$BJ$33) -> 239545.29
A30: Gross margin (contribution) | B30: =IF(B28=0,0,B29/B28) -> 0.5913432 | C30: =IF(C28=0,0,C29/C28) -> 0.59082496 | D30: =IF(D28=0,0,D29/D28) -> 0.5905324 | E30: =IF(E28=0,0,E29/E28) -> 0.59023605 | F30: =IF(F28=0,0,F29/F28) -> 0.58993587
A31: Operating expenses (treated as fixed) | B31: =-SUMIF(Monthly!$C$5:$BJ$5,B$26,Monthly!$C$45:$BJ$45) -> 169272.5 | C31: =-SUMIF(Monthly!$C$5:$BJ$5,C$26,Monthly!$C$45:$BJ$45) -> 174374.61 | D31: =-SUMIF(Monthly!$C$5:$BJ$5,D$26,Monthly!$C$45:$BJ$45) -> 179430.04 | E31: =-SUMIF(Monthly!$C$5:$BJ$5,E$26,Monthly!$C$45:$BJ$45) -> 184643.35 | F31: =-SUMIF(Monthly!$C$5:$BJ$5,F$26,Monthly!$C$45:$BJ$45) -> 190019.77
A32: Break-even revenue (EBITDA = 0) | B32: =IF(B30>0,B31/B30,"n/a") -> 286250.86 | C32: =IF(C30>0,C31/C30,"n/a") -> 295137.52 | D32: =IF(D30>0,D31/D30,"n/a") -> 303844.54 | E32: =IF(E30>0,E31/E30,"n/a") -> 312829.67 | F32: =IF(F30>0,F31/F30,"n/a") -> 322102.42
A33: Margin of safety (revenue above break-even) | B33: =IF(AND(ISNUMBER(B32),B28>0),(B28-B32)/B28,"n/a") -> -0.045107861 | C33: =IF(AND(ISNUMBER(C32),C28>0),(C28-C32)/C28,"n/a") -> 0.12376814 | D33: =IF(AND(ISNUMBER(D32),D28>0),(D28-D32)/D28,"n/a") -> 0.15236463 | E33: =IF(AND(ISNUMBER(E32),E28>0),(E28-E32)/E28,"n/a") -> 0.18001383 | F33: =IF(AND(ISNUMBER(F32),F28>0),(F28-F32)/F28,"n/a") -> 0.20674803
A35: Simplification: cost of sales is treated as variable and operating expenses as fixed, so break-even revenue = operating expenses ÷ gross margin.

Sheet Valuation
A1: Discounted cash flow valuation | H1: =HYPERLINK("#'Cover'!A1","◂ Contents") -> ◂ Contents
A2: Enterprise value at the start of the plan, before the funding raised in period 1. Year-end discounting.
A3: Scenario shown | B3: =CHOOSE(Dashboard!$B$4,"Low","Base","High") -> Base
A5: Assumptions (active scenario, from the Inputs sheet)
A6: Discount rate (WACC) | B6: =Inputs!$E$89 -> 0.25
A7: Terminal growth rate | B7: =Inputs!$E$90 -> 0.02
A8: Exit multiple (EV ÷ final-year EBITDA) | B8: =Inputs!$E$91 -> 4
A9: Tax rate (for the interest tax shield) | B9: =Inputs!$E$83 -> 0.21
A10: Sensitivity step: WACC | B10: =Inputs!$E$92 -> 0.01
A11: Sensitivity step: terminal growth | B11: =Inputs!$E$93 -> 0.005
A13: Free cash flow by year
A14: Year # | B14: 1 | C14: 2 | D14: 3 | E14: 4 | F14: 5
B15: Year 1 | C15: Year 2 | D15: Year 3 | E15: Year 4 | F15: Year 5
A16: EBITDA | B16: =SUMIF(Monthly!$C$5:$BJ$5,B$14,Monthly!$C$46:$BJ$46) -> -7305.964 | C16: =SUMIF(Monthly!$C$5:$BJ$5,C$14,Monthly!$C$46:$BJ$46) -> 24630.491 | D16: =SUMIF(Monthly!$C$5:$BJ$5,D$14,Monthly!$C$46:$BJ$46) -> 32253.01 | E16: =SUMIF(Monthly!$C$5:$BJ$5,E$14,Monthly!$C$46:$BJ$46) -> 40535.265 | F16: =SUMIF(Monthly!$C$5:$BJ$5,F$14,Monthly!$C$46:$BJ$46) -> 49525.516
A17: Unlevered free cash flow | B17: =SUMIF(Monthly!$C$5:$BJ$5,B$14,Monthly!$C$98:$BJ$98) -> -147798.39 | C17: =SUMIF(Monthly!$C$5:$BJ$5,C$14,Monthly!$C$98:$BJ$98) -> 20851.684 | D17: =SUMIF(Monthly!$C$5:$BJ$5,D$14,Monthly!$C$98:$BJ$98) -> 28810.532 | E17: =SUMIF(Monthly!$C$5:$BJ$5,E$14,Monthly!$C$98:$BJ$98) -> 37428.86 | F17: =SUMIF(Monthly!$C$5:$BJ$5,F$14,Monthly!$C$98:$BJ$98) -> 42909.547
A18: Discount factor | B18: =1/(1+Inputs!$E$89)^B$14 -> 0.8 | C18: =1/(1+Inputs!$E$89)^C$14 -> 0.64 | D18: =1/(1+Inputs!$E$89)^D$14 -> 0.512 | E18: =1/(1+Inputs!$E$89)^E$14 -> 0.4096 | F18: =1/(1+Inputs!$E$89)^F$14 -> 0.32768
A19: Present value of free cash flow | B19: =B17*B18 -> -118238.72 | C19: =C17*C18 -> 13345.078 | D19: =D17*D18 -> 14750.992 | E19: =E17*E18 -> 15330.861 | F19: =F17*F18 -> 14060.6
A21: Enterprise value
B22: Perpetual growth | C22: Exit multiple
A23: Present value of the plan's free cash flows | B23: =SUM($B$19:$F$19) -> -60751.184 | C23: =B23 -> -60751.184
A24: Final-year free cash flow | final-year EBITDA | B24: =$F$17 -> 42909.547 | C24: =$F$16 -> 49525.516
A25: Terminal value at the end of year 5 | B25: =IF($B$6>$B$7,B24*(1+$B$7)/($B$6-$B$7),0) -> 190294.51 | C25: =C24*$B$8 -> 198102.06
A26: Present value of the terminal value | B26: =B25/(1+$B$6)^$F$14 -> 62355.705 | C26: =C25/(1+$B$6)^$F$14 -> 64914.085
A27: Enterprise value | B27: =B23+B26 -> 1604.5212 | C27: =C23+C26 -> 4162.9003
A28: Terminal value share of enterprise value | B28: =IF(B27<>0,B26/B27,0) -> 38.862501 | C28: =IF(C27<>0,C26/C27,0) -> 15.593476
A29: Cross-check: implied exit multiple | implied perpetual growth | B29: =IF(C24>0,B25/C24,"n/a") -> 3.8423529 | C29: =IF(C25+B24<>0,(C25*$B$6-B24)/(C25+B24),"n/a") -> 0.027450833
A30: Enterprise value — average of the two methods | B30: =AVERAGE(B27,C27) -> 2883.7108
A32: Sensitivity: enterprise value (perpetual growth) by WACC and terminal growth
A33: WACC ↓ · terminal growth → | B33: =$B$7+(-2)*$B$11 -> 0.01 | C33: =$B$7+(-1)*$B$11 -> 0.015 | D33: =$B$7+(0)*$B$11 -> 0.02 | E33: =$B$7+(1)*$B$11 -> 0.025 | F33: =$B$7+(2)*$B$11 -> 0.03
A34: =$B$6+(-2)*$B$10 -> 0.23 | B34: =IF($A34>B$33,SUMPRODUCT($B$17:$F$17/(1+$A34)^$B$14:$F$14)+$F$17*(1+B$33)/($A34-B$33)/(1+$A34)^$F$14,"n/a") -> 10670.158 | C34: =IF($A34>C$33,SUMPRODUCT($B$17:$F$17/(1+$A34)^$B$14:$F$14)+$F$17*(1+C$33)/($A34-C$33)/(1+$A34)^$F$14,"n/a") -> 12651.878 | D34: =IF($A34>D$33,SUMPRODUCT($B$17:$F$17/(1+$A34)^$B$14:$F$14)+$F$17*(1+D$33)/($A34-D$33)/(1+$A34)^$F$14,"n/a") -> 14727.966 | E34: =IF($A34>E$33,SUMPRODUCT($B$17:$F$17/(1+$A34)^$B$14:$F$14)+$F$17*(1+E$33)/($A34-E$33)/(1+$A34)^$F$14,"n/a") -> 16905.326 | F34: =IF($A34>F$33,SUMPRODUCT($B$17:$F$17/(1+$A34)^$B$14:$F$14)+$F$17*(1+F$33)/($A34-F$33)/(1+$A34)^$F$14,"n/a") -> 19191.555
A35: =$B$6+(-1)*$B$10 -> 0.24 | B35: =IF($A35>B$33,SUMPRODUCT($B$17:$F$17/(1+$A35)^$B$14:$F$14)+$F$17*(1+B$33)/($A35-B$33)/(1+$A35)^$F$14,"n/a") -> 4222.4392 | C35: =IF($A35>C$33,SUMPRODUCT($B$17:$F$17/(1+$A35)^$B$14:$F$14)+$F$17*(1+C$33)/($A35-C$33)/(1+$A35)^$F$14,"n/a") -> 5976.0243 | D35: =IF($A35>D$33,SUMPRODUCT($B$17:$F$17/(1+$A35)^$B$14:$F$14)+$F$17*(1+D$33)/($A35-D$33)/(1+$A35)^$F$14,"n/a") -> 7809.3177 | E35: =IF($A35>E$33,SUMPRODUCT($B$17:$F$17/(1+$A35)^$B$14:$F$14)+$F$17*(1+E$33)/($A35-E$33)/(1+$A35)^$F$14,"n/a") -> 9727.8807 | F35: =IF($A35>F$33,SUMPRODUCT($B$17:$F$17/(1+$A35)^$B$14:$F$14)+$F$17*(1+F$33)/($A35-F$33)/(1+$A35)^$F$14,"n/a") -> 11737.804
A36: =$B$6+(0)*$B$10 -> 0.25 | B36: =IF($A36>B$33,SUMPRODUCT($B$17:$F$17/(1+$A36)^$B$14:$F$14)+$F$17*(1+B$33)/($A36-B$33)/(1+$A36)^$F$14,"n/a") -> -1579.4916 | C36: =IF($A36>C$33,SUMPRODUCT($B$17:$F$17/(1+$A36)^$B$14:$F$14)+$F$17*(1+C$33)/($A36-C$33)/(1+$A36)^$F$14,"n/a") -> -21.357674 | D36: =IF($A36>D$33,SUMPRODUCT($B$17:$F$17/(1+$A36)^$B$14:$F$14)+$F$17*(1+D$33)/($A36-D$33)/(1+$A36)^$F$14,"n/a") -> 1604.5212 | E36: =IF($A36>E$33,SUMPRODUCT($B$17:$F$17/(1+$A36)^$B$14:$F$14)+$F$17*(1+E$33)/($A36-E$33)/(1+$A36)^$F$14,"n/a") -> 3302.6613 | F36: =IF($A36>F$33,SUMPRODUCT($B$17:$F$17/(1+$A36)^$B$14:$F$14)+$F$17*(1+F$33)/($A36-F$33)/(1+$A36)^$F$14,"n/a") -> 5077.9896
