Workbook

Sheet Cover
B2: Guest house financial model (planning)
B3: 5-year financial model · monthly detail · Low / Base / High scenarios · US dollars · Full plan
B5: Purpose | D5: Revenue and profit plan
B6: Active scenario | D6: =Dashboard!C4&" (change it on the Dashboard, cell B4)" -> Base (change it on the Dashboard, cell B4)
B7: Model checks | D7: =Checks!B25 -> PASS
B8: Prepared | D8: 22 October 2026
B10: Contents
C11: PRESENTATION
B12: 1 | C12: =HYPERLINK("#Dashboard!A1","Dashboard") -> Dashboard | D12: Scenario switch, key numbers, core financials
B13: 2 | C13: =HYPERLINK("#Summary!A1","Summary") -> Summary | D13: Income statement, cash flow and balance sheet — every year and any year by month
B14: 3 | C14: =HYPERLINK("#Scenarios!A1","Scenarios") -> Scenarios | D14: Low / Base / High side by side: drivers, outputs, charts
B15: 4 | C15: =HYPERLINK("#'Break-even'!A1","Break-even") -> Break-even | D15: Startup costs, funding need, break-even timing and revenue
B16: 5 | C16: =HYPERLINK("#Valuation!A1","Valuation") -> Valuation | D16: Free cash flow, DCF (perpetual growth and exit multiple), WACC × growth sensitivity
B17: 6 | C17: =HYPERLINK("#'Sources & Uses'!A1","Sources & Uses") -> Sources & Uses | D17: Funding structure, sources and uses of cash for the first months
B18: 7 | C18: =HYPERLINK("#KPIs!A1","KPIs") -> KPIs | D18: Financial ratios, DuPont analysis, industry metrics
C19: INPUTS
B20: 8 | C20: =HYPERLINK("#Inputs!A1","Inputs") -> Inputs | D20: Every assumption, Low / Base / High, with units and comments
C21: STATEMENTS
B22: 9 | C22: =HYPERLINK("#'P&L'!A1","P&L") -> P&L | D22: Annual profit & loss
B23: 10 | C23: =HYPERLINK("#'Cash Flow'!A1","Cash Flow") -> Cash Flow | D23: Annual cash flow statement
B24: 11 | C24: =HYPERLINK("#'Balance Sheet'!A1","Balance Sheet") -> Balance Sheet | D24: Balance sheet at year end
C25: CALCULATIONS
B26: 12 | C26: =HYPERLINK("#Monthly!A1","Monthly") -> Monthly | D26: Month-by-month engine of the model
B27: 13 | C27: =HYPERLINK("#Headcount!A1","Headcount") -> Headcount | D27: Team and payroll
B28: 14 | C28: =HYPERLINK("#'Scenario calc'!A1","Scenario calc") -> Scenario calc | D28: Low, Base and High calculated side by side for the Scenarios sheet
C29: CONTROL
B30: 15 | C30: =HYPERLINK("#Checks!A1","Checks") -> Checks | D30: Live integrity checks and the overall verdict
B32: How to read this file
C33: 1000 | D33: Input you can change — yellow cell with a blue figure (Inputs sheet and the view switches)
C34: 1000 | D34: Formula — calculated, do not overwrite
C35: 1000 | D35: Link to another sheet
C36: 1000 | D36: Active value the model uses (follows the scenario)

Sheet Dashboard
A1: Dashboard | W1: =HYPERLINK("#'Cover'!A1","◂ Contents") -> ◂ Contents
A2: Guest house financial model (planning)
A4: Active scenario | B4: 2 | C4: =CHOOSE(B4,"Low","Base","High") -> Base | D4: 1 = Low · 2 = Base · 3 = High — every sheet follows this cell | S4: Model checks | T4: =Checks!B25 -> PASS
A6: REVENUE · YEAR 5 | C6: EBITDA MARGIN · YEAR 5 | H6: NET INCOME · YEAR 5 | L6: LOWEST CASH BALANCE | P6: FUNDING REQUIRED | T6: ENTERPRISE VALUE (DCF)
A7: =F12 -> 460163.93 | C7: =F17 -> 0.29432751 | H7: =F18 -> 43135.578 | L7: =F39 -> 22904.403 | P7: =F37 -> 946095.6 | T7: =F44 -> -348552.33
A8: =IF(AND(B12>0,F12>=0),(F12/B12)^(1/4)-1,"CAGR n/a") -> 0.13740984 | C8: =F16 -> 135438.9 | H8: =F19 -> 0.09373959 | L8: ='Break-even'!B6 -> 5 | P8: =IF(F38>=0,"Covered by funding raised",-F38) -> 16095.597 | T8: Average of 2 methods
A10: Core financials ($'000) — active scenario
B11: 1 | C11: 2 | D11: 3 | E11: 4 | F11: 5
A12: Revenue | B12: =SUMIF(Monthly!$C$5:$BJ$5,B$11,Monthly!$C$20:$BJ$20) -> 274944.26 | C12: =SUMIF(Monthly!$C$5:$BJ$5,C$11,Monthly!$C$20:$BJ$20) -> 396826.24 | D12: =SUMIF(Monthly!$C$5:$BJ$5,D$11,Monthly!$C$20:$BJ$20) -> 416905.65 | E12: =SUMIF(Monthly!$C$5:$BJ$5,E$11,Monthly!$C$20:$BJ$20) -> 438001.08 | F12: =SUMIF(Monthly!$C$5:$BJ$5,F$11,Monthly!$C$20:$BJ$20) -> 460163.93
A13: Gross profit | B13: =SUMIF(Monthly!$C$5:$BJ$5,B$11,Monthly!$C$29:$BJ$29) -> 165763.81 | C13: =SUMIF(Monthly!$C$5:$BJ$5,C$11,Monthly!$C$29:$BJ$29) -> 262060.42 | D13: =SUMIF(Monthly!$C$5:$BJ$5,D$11,Monthly!$C$29:$BJ$29) -> 276491.91 | E13: =SUMIF(Monthly!$C$5:$BJ$5,E$11,Monthly!$C$29:$BJ$29) -> 291688.77 | F13: =SUMIF(Monthly!$C$5:$BJ$5,F$11,Monthly!$C$29:$BJ$29) -> 307690.79
A14: Gross margin | B14: =IF(B12=0,0,B13/B12) -> 0.6028997 | C14: =IF(C12=0,0,C13/C12) -> 0.66039085 | D14: =IF(D12=0,0,D13/D12) -> 0.6632002 | E14: =IF(E12=0,0,E13/E12) -> 0.66595446 | F14: =IF(F12=0,0,F13/F12) -> 0.66865472
A15: Operating expenses | B15: =SUMIF(Monthly!$C$5:$BJ$5,B$11,Monthly!$C$41:$BJ$41) -> -155521.27 | C15: =SUMIF(Monthly!$C$5:$BJ$5,C$11,Monthly!$C$41:$BJ$41) -> -163660.36 | D15: =SUMIF(Monthly!$C$5:$BJ$5,D$11,Monthly!$C$41:$BJ$41) -> -165805.87 | E15: =SUMIF(Monthly!$C$5:$BJ$5,E$11,Monthly!$C$41:$BJ$41) -> -168705.86 | F15: =SUMIF(Monthly!$C$5:$BJ$5,F$11,Monthly!$C$41:$BJ$41) -> -172251.88
A16: EBITDA | B16: =SUMIF(Monthly!$C$5:$BJ$5,B$11,Monthly!$C$42:$BJ$42) -> 10242.544 | C16: =SUMIF(Monthly!$C$5:$BJ$5,C$11,Monthly!$C$42:$BJ$42) -> 98400.063 | D16: =SUMIF(Monthly!$C$5:$BJ$5,D$11,Monthly!$C$42:$BJ$42) -> 110686.04 | E16: =SUMIF(Monthly!$C$5:$BJ$5,E$11,Monthly!$C$42:$BJ$42) -> 122982.92 | F16: =SUMIF(Monthly!$C$5:$BJ$5,F$11,Monthly!$C$42:$BJ$42) -> 135438.9
A17: EBITDA margin | B17: =IF(B12=0,0,B16/B12) -> 0.037253166 | C17: =IF(C12=0,0,C16/C12) -> 0.24796763 | D17: =IF(D12=0,0,D16/D12) -> 0.26549423 | E17: =IF(E12=0,0,E16/E12) -> 0.28078222 | F17: =IF(F12=0,0,F16/F12) -> 0.29432751
A18: Net income | B18: =SUMIF(Monthly!$C$5:$BJ$5,B$11,Monthly!$C$51:$BJ$51) -> -70506.807 | C18: =SUMIF(Monthly!$C$5:$BJ$5,C$11,Monthly!$C$51:$BJ$51) -> 17593.913 | D18: =SUMIF(Monthly!$C$5:$BJ$5,D$11,Monthly!$C$51:$BJ$51) -> 29844.776 | E18: =SUMIF(Monthly!$C$5:$BJ$5,E$11,Monthly!$C$51:$BJ$51) -> 38127.44 | F18: =SUMIF(Monthly!$C$5:$BJ$5,F$11,Monthly!$C$51:$BJ$51) -> 43135.578
A19: Net margin | B19: =IF(B12=0,0,B18/B12) -> -0.25644037 | C19: =IF(C12=0,0,C18/C12) -> 0.044336566 | D19: =IF(D12=0,0,D18/D12) -> 0.071586402 | E19: =IF(E12=0,0,E18/E12) -> 0.087048736 | F19: =IF(F12=0,0,F18/F12) -> 0.09373959
A20: Operating cash flow | B20: =SUMIF(Monthly!$C$5:$BJ$5,B$11,Monthly!$C$83:$BJ$83) -> -19872.931 | C20: =SUMIF(Monthly!$C$5:$BJ$5,C$11,Monthly!$C$83:$BJ$83) -> 64360.735 | D20: =SUMIF(Monthly!$C$5:$BJ$5,D$11,Monthly!$C$83:$BJ$83) -> 77245.925 | E20: =SUMIF(Monthly!$C$5:$BJ$5,E$11,Monthly!$C$83:$BJ$83) -> 86182.013 | F20: =SUMIF(Monthly!$C$5:$BJ$5,F$11,Monthly!$C$83:$BJ$83) -> 91863.248
A21: Investing cash flow | B21: =SUMIF(Monthly!$C$5:$BJ$5,B$11,Monthly!$C$84:$BJ$84) -> -874000 | C21: =SUMIF(Monthly!$C$5:$BJ$5,C$11,Monthly!$C$84:$BJ$84) -> -9270 | D21: =SUMIF(Monthly!$C$5:$BJ$5,D$11,Monthly!$C$84:$BJ$84) -> -9548.1 | E21: =SUMIF(Monthly!$C$5:$BJ$5,E$11,Monthly!$C$84:$BJ$84) -> -9834.543 | F21: =SUMIF(Monthly!$C$5:$BJ$5,F$11,Monthly!$C$84:$BJ$84) -> -10129.579
A22: Financing cash flow | B22: =SUMIF(Monthly!$C$5:$BJ$5,B$11,Monthly!$C$86:$BJ$86) -> 922350.93 | C22: =SUMIF(Monthly!$C$5:$BJ$5,C$11,Monthly!$C$86:$BJ$86) -> -8202.0187 | D22: =SUMIF(Monthly!$C$5:$BJ$5,D$11,Monthly!$C$86:$BJ$86) -> -8794.9433 | E22: =SUMIF(Monthly!$C$5:$BJ$5,E$11,Monthly!$C$86:$BJ$86) -> -9430.7304 | F22: =SUMIF(Monthly!$C$5:$BJ$5,F$11,Monthly!$C$86:$BJ$86) -> -10112.479
A23: Net change in cash | B23: =SUMIF(Monthly!$C$5:$BJ$5,B$11,Monthly!$C$87:$BJ$87) -> 28478.002 | C23: =SUMIF(Monthly!$C$5:$BJ$5,C$11,Monthly!$C$87:$BJ$87) -> 46888.716 | D23: =SUMIF(Monthly!$C$5:$BJ$5,D$11,Monthly!$C$87:$BJ$87) -> 58902.881 | E23: =SUMIF(Monthly!$C$5:$BJ$5,E$11,Monthly!$C$87:$BJ$87) -> 66916.74 | F23: =SUMIF(Monthly!$C$5:$BJ$5,F$11,Monthly!$C$87:$BJ$87) -> 71621.19
A24: Year-end cash | B24: =INDEX(Monthly!$C$89:$BJ$89,B$11*12) -> 28478.002 | C24: =INDEX(Monthly!$C$89:$BJ$89,C$11*12) -> 75366.718 | D24: =INDEX(Monthly!$C$89:$BJ$89,D$11*12) -> 134269.6 | E24: =INDEX(Monthly!$C$89:$BJ$89,E$11*12) -> 201186.34 | F24: =INDEX(Monthly!$C$89:$BJ$89,F$11*12) -> 272807.53
A26: Guest house metrics
B27: 1 | C27: 2 | D27: 3 | E27: 4 | F27: 5
A28: Occupancy | B28: =KPIs!B31 -> 0.45130833 | C28: =KPIs!C31 -> 0.6324 | D28: =KPIs!D31 -> 0.645048 | E28: =KPIs!E31 -> 0.65794896 | F28: =KPIs!F31 -> 0.67110794
A29: Average daily rate | B29: =KPIs!B37 -> 155 | C29: =KPIs!C37 -> 159.65 | D29: =KPIs!D37 -> 164.4395 | E29: =KPIs!E37 -> 169.37268 | F29: =KPIs!F37 -> 174.45387
A30: RevPAR (room revenue per available room-night) | B30: =KPIs!B38 -> 69.952792 | C30: =KPIs!C38 -> 100.96266 | D30: =KPIs!D38 -> 106.07137 | E30: =KPIs!E38 -> 111.43858 | F30: =KPIs!F38 -> 117.07737
A31: Guest stays | B31: =KPIs!B32 -> 748.35127 | C31: =KPIs!C32 -> 1048.6342 | D31: =KPIs!D32 -> 1069.6069 | E31: =KPIs!E32 -> 1090.999 | F31: =KPIs!F32 -> 1112.819
A32: Team (FTE, year end) | B32: =INDEX(Headcount!$C$11:$BJ$11,B$27*12) -> 3.1 | C32: =INDEX(Headcount!$C$11:$BJ$11,C$27*12) -> 3.1 | D32: =INDEX(Headcount!$C$11:$BJ$11,D$27*12) -> 3.1 | E32: =INDEX(Headcount!$C$11:$BJ$11,E$27*12) -> 3.1 | F32: =INDEX(Headcount!$C$11:$BJ$11,F$27*12) -> 3.1
A34: Funding & valuation ($'000) — active scenario
A35: Equity raised | F35: =Inputs!$E$65 -> 430000
A36: Loan drawn | F36: =Inputs!$E$66 -> 500000
A37: Funding required (incl. cash buffer) | F37: ='Break-even'!B12 -> 946095.6
A38: Funding surplus / (shortfall) | F38: ='Break-even'!B17 -> -16095.597
A39: ="Lowest cash balance (month "&'Break-even'!B6&")" -> Lowest cash balance (month 5) | F39: ='Break-even'!B18 -> 22904.403
A40: First month with positive EBITDA | F40: ='Break-even'!B21 -> 6
A41: Cash invested paid back | F41: ='Break-even'!B23 -> Not within horizon
A42: Enterprise value — perpetual growth | F42: =Valuation!B27 -> -359389.08
A43: Enterprise value — exit multiple | F43: =Valuation!C27 -> -337715.58
A44: Enterprise value — average | F44: =Valuation!B30 -> -348552.33

Sheet Summary
A1: Financial statements summary | U1: =HYPERLINK("#'Cover'!A1","◂ Contents") -> ◂ Contents
A2: Guest house financial model (planning) | P2: Select detailed year: | R2: 1
A5: Income statement ($'000) — by year | H5: ="Income statement ($'000) — Year "&$R$2&", by month" -> Income statement ($'000) — Year 1, by month
B6: 1 | C6: 2 | D6: 3 | E6: 4 | F6: 5 | H6: =INDEX(Monthly!$C$4:$BJ$4,($R$2-1)*12+1) -> 1 | I6: =INDEX(Monthly!$C$4:$BJ$4,($R$2-1)*12+2) -> 2 | J6: =INDEX(Monthly!$C$4:$BJ$4,($R$2-1)*12+3) -> 3 | K6: =INDEX(Monthly!$C$4:$BJ$4,($R$2-1)*12+4) -> 4 | L6: =INDEX(Monthly!$C$4:$BJ$4,($R$2-1)*12+5) -> 5 | M6: =INDEX(Monthly!$C$4:$BJ$4,($R$2-1)*12+6) -> 6 | N6: =INDEX(Monthly!$C$4:$BJ$4,($R$2-1)*12+7) -> 7 | O6: =INDEX(Monthly!$C$4:$BJ$4,($R$2-1)*12+8) -> 8 | P6: =INDEX(Monthly!$C$4:$BJ$4,($R$2-1)*12+9) -> 9 | Q6: =INDEX(Monthly!$C$4:$BJ$4,($R$2-1)*12+10) -> 10 | R6: =INDEX(Monthly!$C$4:$BJ$4,($R$2-1)*12+11) -> 11 | S6: =INDEX(Monthly!$C$4:$BJ$4,($R$2-1)*12+12) -> 12
A7: Revenue | B7: ='P&L'!B5 -> 274944.26 | C7: ='P&L'!C5 -> 396826.24 | D7: ='P&L'!D5 -> 416905.65 | E7: ='P&L'!E5 -> 438001.08 | F7: ='P&L'!F5 -> 460163.93 | H7: =INDEX(Monthly!$C$20:$BJ$20,($R$2-1)*12+1) -> 11541.259 | I7: =INDEX(Monthly!$C$20:$BJ$20,($R$2-1)*12+2) -> 13272.447 | J7: =INDEX(Monthly!$C$20:$BJ$20,($R$2-1)*12+3) -> 15003.636 | K7: =INDEX(Monthly!$C$20:$BJ$20,($R$2-1)*12+4) -> 16734.825 | L7: =INDEX(Monthly!$C$20:$BJ$20,($R$2-1)*12+5) -> 18466.014 | M7: =INDEX(Monthly!$C$20:$BJ$20,($R$2-1)*12+6) -> 27541.64 | N7: =INDEX(Monthly!$C$20:$BJ$20,($R$2-1)*12+7) -> 29902.352 | O7: =INDEX(Monthly!$C$20:$BJ$20,($R$2-1)*12+8) -> 32263.064 | P7: =INDEX(Monthly!$C$20:$BJ$20,($R$2-1)*12+9) -> 25390.769 | Q7: =INDEX(Monthly!$C$20:$BJ$20,($R$2-1)*12+10) -> 27121.958 | R7: =INDEX(Monthly!$C$20:$BJ$20,($R$2-1)*12+11) -> 28853.147 | S7: =INDEX(Monthly!$C$20:$BJ$20,($R$2-1)*12+12) -> 28853.147
A8: Cost of sales | B8: ='P&L'!B6 -> -109180.45 | C8: ='P&L'!C6 -> -134765.82 | D8: ='P&L'!D6 -> -140413.74 | E8: ='P&L'!E6 -> -146312.3 | F8: ='P&L'!F6 -> -152473.15 | H8: =INDEX(Monthly!$C$28:$BJ$28,($R$2-1)*12+1) -> -6865.9223 | I8: =INDEX(Monthly!$C$28:$BJ$28,($R$2-1)*12+2) -> -7205.8106 | J8: =INDEX(Monthly!$C$28:$BJ$28,($R$2-1)*12+3) -> -7545.6989 | K8: =INDEX(Monthly!$C$28:$BJ$28,($R$2-1)*12+4) -> -7885.5873 | L8: =INDEX(Monthly!$C$28:$BJ$28,($R$2-1)*12+5) -> -8225.4756 | M8: =INDEX(Monthly!$C$28:$BJ$28,($R$2-1)*12+6) -> -10007.315 | N8: =INDEX(Monthly!$C$28:$BJ$28,($R$2-1)*12+7) -> -10470.799 | O8: =INDEX(Monthly!$C$28:$BJ$28,($R$2-1)*12+8) -> -10934.283 | P8: =INDEX(Monthly!$C$28:$BJ$28,($R$2-1)*12+9) -> -9585.029 | Q8: =INDEX(Monthly!$C$28:$BJ$28,($R$2-1)*12+10) -> -9924.9173 | R8: =INDEX(Monthly!$C$28:$BJ$28,($R$2-1)*12+11) -> -10264.806 | S8: =INDEX(Monthly!$C$28:$BJ$28,($R$2-1)*12+12) -> -10264.806
A9: Gross profit | B9: ='P&L'!B7 -> 165763.81 | C9: ='P&L'!C7 -> 262060.42 | D9: ='P&L'!D7 -> 276491.91 | E9: ='P&L'!E7 -> 291688.77 | F9: ='P&L'!F7 -> 307690.79 | H9: =INDEX(Monthly!$C$29:$BJ$29,($R$2-1)*12+1) -> 4675.3364 | I9: =INDEX(Monthly!$C$29:$BJ$29,($R$2-1)*12+2) -> 6066.6369 | J9: =INDEX(Monthly!$C$29:$BJ$29,($R$2-1)*12+3) -> 7457.9373 | K9: =INDEX(Monthly!$C$29:$BJ$29,($R$2-1)*12+4) -> 8849.2378 | L9: =INDEX(Monthly!$C$29:$BJ$29,($R$2-1)*12+5) -> 10240.538 | M9: =INDEX(Monthly!$C$29:$BJ$29,($R$2-1)*12+6) -> 17534.325 | N9: =INDEX(Monthly!$C$29:$BJ$29,($R$2-1)*12+7) -> 19431.553 | O9: =INDEX(Monthly!$C$29:$BJ$29,($R$2-1)*12+8) -> 21328.781 | P9: =INDEX(Monthly!$C$29:$BJ$29,($R$2-1)*12+9) -> 15805.74 | Q9: =INDEX(Monthly!$C$29:$BJ$29,($R$2-1)*12+10) -> 17197.041 | R9: =INDEX(Monthly!$C$29:$BJ$29,($R$2-1)*12+11) -> 18588.341 | S9: =INDEX(Monthly!$C$29:$BJ$29,($R$2-1)*12+12) -> 18588.341
A10: Gross margin | B10: ='P&L'!B8 -> 0.6028997 | C10: ='P&L'!C8 -> 0.66039085 | D10: ='P&L'!D8 -> 0.6632002 | E10: ='P&L'!E8 -> 0.66595446 | F10: ='P&L'!F8 -> 0.66865472 | H10: =IF(H7=0,0,H9/H7) -> 0.40509762 | I10: =IF(I7=0,0,I9/I7) -> 0.45708502 | J10: =IF(J7=0,0,J9/J7) -> 0.49707532 | K10: =IF(K7=0,0,K9/K7) -> 0.52879177 | L10: =IF(L7=0,0,L9/L7) -> 0.55456139 | M10: =IF(M7=0,0,M9/M7) -> 0.63664784 | N10: =IF(N7=0,0,N9/N7) -> 0.64983361 | O10: =IF(O7=0,0,O9/O7) -> 0.66108976 | ... S10: =IF(S7=0,0,S9/S7) -> 0.64423965
A11: Total operating expenses | B11: ='P&L'!B18 -> -155521.27 | C11: ='P&L'!C18 -> -163660.36 | D11: ='P&L'!D18 -> -165805.87 | E11: ='P&L'!E18 -> -168705.86 | F11: ='P&L'!F18 -> -172251.88 | H11: =INDEX(Monthly!$C$41:$BJ$41,($R$2-1)*12+1) -> -12198.264 | I11: =INDEX(Monthly!$C$41:$BJ$41,($R$2-1)*12+2) -> -12314.254 | J11: =INDEX(Monthly!$C$41:$BJ$41,($R$2-1)*12+3) -> -12430.244 | K11: =INDEX(Monthly!$C$41:$BJ$41,($R$2-1)*12+4) -> -12546.233 | L11: =INDEX(Monthly!$C$41:$BJ$41,($R$2-1)*12+5) -> -12662.223 | M11: =INDEX(Monthly!$C$41:$BJ$41,($R$2-1)*12+6) -> -13270.29 | N11: =INDEX(Monthly!$C$41:$BJ$41,($R$2-1)*12+7) -> -13428.458 | O11: =INDEX(Monthly!$C$41:$BJ$41,($R$2-1)*12+8) -> -13586.625 | P11: =INDEX(Monthly!$C$41:$BJ$41,($R$2-1)*12+9) -> -13126.182 | Q11: =INDEX(Monthly!$C$41:$BJ$41,($R$2-1)*12+10) -> -13242.171 | R11: =INDEX(Monthly!$C$41:$BJ$41,($R$2-1)*12+11) -> -13358.161 | S11: =INDEX(Monthly!$C$41:$BJ$41,($R$2-1)*12+12) -> -13358.161
A12: EBITDA | B12: ='P&L'!B19 -> 10242.544 | C12: ='P&L'!C19 -> 98400.063 | D12: ='P&L'!D19 -> 110686.04 | E12: ='P&L'!E19 -> 122982.92 | F12: ='P&L'!F19 -> 135438.9 | H12: =INDEX(Monthly!$C$42:$BJ$42,($R$2-1)*12+1) -> -7522.9279 | I12: =INDEX(Monthly!$C$42:$BJ$42,($R$2-1)*12+2) -> -6247.6171 | J12: =INDEX(Monthly!$C$42:$BJ$42,($R$2-1)*12+3) -> -4972.3063 | K12: =INDEX(Monthly!$C$42:$BJ$42,($R$2-1)*12+4) -> -3696.9955 | L12: =INDEX(Monthly!$C$42:$BJ$42,($R$2-1)*12+5) -> -2421.6847 | M12: =INDEX(Monthly!$C$42:$BJ$42,($R$2-1)*12+6) -> 4264.0356 | N12: =INDEX(Monthly!$C$42:$BJ$42,($R$2-1)*12+7) -> 6003.0958 | O12: =INDEX(Monthly!$C$42:$BJ$42,($R$2-1)*12+8) -> 7742.156 | P12: =INDEX(Monthly!$C$42:$BJ$42,($R$2-1)*12+9) -> 2679.5586 | Q12: =INDEX(Monthly!$C$42:$BJ$42,($R$2-1)*12+10) -> 3954.8694 | R12: =INDEX(Monthly!$C$42:$BJ$42,($R$2-1)*12+11) -> 5230.1802 | S12: =INDEX(Monthly!$C$42:$BJ$42,($R$2-1)*12+12) -> 5230.1802
A13: EBITDA margin | B13: ='P&L'!B20 -> 0.037253166 | C13: ='P&L'!C20 -> 0.24796763 | D13: ='P&L'!D20 -> 0.26549423 | E13: ='P&L'!E20 -> 0.28078222 | F13: ='P&L'!F20 -> 0.29432751 | H13: =IF(H7=0,0,H12/H7) -> -0.65182907 | I13: =IF(I7=0,0,I12/I7) -> -0.4707208 | J13: =IF(J7=0,0,J12/J7) -> -0.33140675 | K13: =IF(K7=0,0,K12/K7) -> -0.22091629 | L13: =IF(L7=0,0,L12/L7) -> -0.1311428 | M13: =IF(M7=0,0,M12/M7) -> 0.15482141 | N13: =IF(N7=0,0,N12/N7) -> 0.20075664 | O13: =IF(O7=0,0,O12/O7) -> 0.23996964 | ... S13: =IF(S7=0,0,S12/S7) -> 0.18126897
A14: Depreciation | B14: ='P&L'!B21 -> -45991.667 | C14: ='P&L'!C21 -> -46601.417 | D14: ='P&L'!D21 -> -47229.459 | E14: ='P&L'!E21 -> -47876.343 | F14: ='P&L'!F21 -> -48542.633 | H14: =INDEX(Monthly!$C$62:$BJ$62,($R$2-1)*12+1) -> -3809.7222 | I14: =INDEX(Monthly!$C$62:$BJ$62,($R$2-1)*12+2) -> -3813.8889 | J14: =INDEX(Monthly!$C$62:$BJ$62,($R$2-1)*12+3) -> -3818.0556 | K14: =INDEX(Monthly!$C$62:$BJ$62,($R$2-1)*12+4) -> -3822.2222 | L14: =INDEX(Monthly!$C$62:$BJ$62,($R$2-1)*12+5) -> -3826.3889 | M14: =INDEX(Monthly!$C$62:$BJ$62,($R$2-1)*12+6) -> -3830.5556 | N14: =INDEX(Monthly!$C$62:$BJ$62,($R$2-1)*12+7) -> -3834.7222 | O14: =INDEX(Monthly!$C$62:$BJ$62,($R$2-1)*12+8) -> -3838.8889 | P14: =INDEX(Monthly!$C$62:$BJ$62,($R$2-1)*12+9) -> -3843.0556 | Q14: =INDEX(Monthly!$C$62:$BJ$62,($R$2-1)*12+10) -> -3847.2222 | R14: =INDEX(Monthly!$C$62:$BJ$62,($R$2-1)*12+11) -> -3851.3889 | S14: =INDEX(Monthly!$C$62:$BJ$62,($R$2-1)*12+12) -> -3855.5556
A15: EBIT | B15: ='P&L'!B22 -> -35749.123 | C15: ='P&L'!C22 -> 51798.646 | D15: ='P&L'!D22 -> 63456.584 | E15: ='P&L'!E22 -> 75106.572 | F15: ='P&L'!F22 -> 86896.271 | H15: =INDEX(Monthly!$C$45:$BJ$45,($R$2-1)*12+1) -> -11332.65 | I15: =INDEX(Monthly!$C$45:$BJ$45,($R$2-1)*12+2) -> -10061.506 | J15: =INDEX(Monthly!$C$45:$BJ$45,($R$2-1)*12+3) -> -8790.3619 | K15: =INDEX(Monthly!$C$45:$BJ$45,($R$2-1)*12+4) -> -7519.2177 | L15: =INDEX(Monthly!$C$45:$BJ$45,($R$2-1)*12+5) -> -6248.0736 | M15: =INDEX(Monthly!$C$45:$BJ$45,($R$2-1)*12+6) -> 433.48006 | N15: =INDEX(Monthly!$C$45:$BJ$45,($R$2-1)*12+7) -> 2168.3736 | O15: =INDEX(Monthly!$C$45:$BJ$45,($R$2-1)*12+8) -> 3903.2671 | P15: =INDEX(Monthly!$C$45:$BJ$45,($R$2-1)*12+9) -> -1163.497 | Q15: =INDEX(Monthly!$C$45:$BJ$45,($R$2-1)*12+10) -> 107.64714 | R15: =INDEX(Monthly!$C$45:$BJ$45,($R$2-1)*12+11) -> 1378.7913 | S15: =INDEX(Monthly!$C$45:$BJ$45,($R$2-1)*12+12) -> 1374.6246
A16: Interest | B16: ='P&L'!B23 -> -34757.685 | C16: ='P&L'!C23 -> -34204.733 | D16: ='P&L'!D23 -> -33611.809 | E16: ='P&L'!E23 -> -32976.021 | F16: ='P&L'!F23 -> -32294.273 | H16: =INDEX(Monthly!$C$46:$BJ$46,($R$2-1)*12+1) -> -2916.6667 | I16: =INDEX(Monthly!$C$46:$BJ$46,($R$2-1)*12+2) -> -2913.0662 | J16: =INDEX(Monthly!$C$46:$BJ$46,($R$2-1)*12+3) -> -2909.4447 | K16: =INDEX(Monthly!$C$46:$BJ$46,($R$2-1)*12+4) -> -2905.802 | L16: =INDEX(Monthly!$C$46:$BJ$46,($R$2-1)*12+5) -> -2902.1381 | M16: =INDEX(Monthly!$C$46:$BJ$46,($R$2-1)*12+6) -> -2898.4529 | N16: =INDEX(Monthly!$C$46:$BJ$46,($R$2-1)*12+7) -> -2894.7461 | O16: =INDEX(Monthly!$C$46:$BJ$46,($R$2-1)*12+8) -> -2891.0178 | P16: =INDEX(Monthly!$C$46:$BJ$46,($R$2-1)*12+9) -> -2887.2676 | Q16: =INDEX(Monthly!$C$46:$BJ$46,($R$2-1)*12+10) -> -2883.4956 | R16: =INDEX(Monthly!$C$46:$BJ$46,($R$2-1)*12+11) -> -2879.7016 | S16: =INDEX(Monthly!$C$46:$BJ$46,($R$2-1)*12+12) -> -2875.8855
A17: Pre-tax income | B17: ='P&L'!B24 -> -70506.807 | C17: ='P&L'!C24 -> 17593.913 | D17: ='P&L'!D24 -> 29844.776 | E17: ='P&L'!E24 -> 42130.551 | F17: ='P&L'!F24 -> 54601.998 | H17: =INDEX(Monthly!$C$47:$BJ$47,($R$2-1)*12+1) -> -14249.317 | I17: =INDEX(Monthly!$C$47:$BJ$47,($R$2-1)*12+2) -> -12974.572 | J17: =INDEX(Monthly!$C$47:$BJ$47,($R$2-1)*12+3) -> -11699.807 | K17: =INDEX(Monthly!$C$47:$BJ$47,($R$2-1)*12+4) -> -10425.02 | L17: =INDEX(Monthly!$C$47:$BJ$47,($R$2-1)*12+5) -> -9150.2117 | M17: =INDEX(Monthly!$C$47:$BJ$47,($R$2-1)*12+6) -> -2464.9728 | N17: =INDEX(Monthly!$C$47:$BJ$47,($R$2-1)*12+7) -> -726.37254 | O17: =INDEX(Monthly!$C$47:$BJ$47,($R$2-1)*12+8) -> 1012.2494 | P17: =INDEX(Monthly!$C$47:$BJ$47,($R$2-1)*12+9) -> -4050.7646 | Q17: =INDEX(Monthly!$C$47:$BJ$47,($R$2-1)*12+10) -> -2775.8485 | R17: =INDEX(Monthly!$C$47:$BJ$47,($R$2-1)*12+11) -> -1500.9104 | S17: =INDEX(Monthly!$C$47:$BJ$47,($R$2-1)*12+12) -> -1501.2609
A18: Income tax | B18: ='P&L'!B25 -> 0 | C18: ='P&L'!C25 -> 0 | D18: ='P&L'!D25 -> 0 | E18: ='P&L'!E25 -> -4003.1107 | F18: ='P&L'!F25 -> -11466.42 | H18: =INDEX(Monthly!$C$50:$BJ$50,($R$2-1)*12+1) -> 0 | I18: =INDEX(Monthly!$C$50:$BJ$50,($R$2-1)*12+2) -> 0 | J18: =INDEX(Monthly!$C$50:$BJ$50,($R$2-1)*12+3) -> 0 | K18: =INDEX(Monthly!$C$50:$BJ$50,($R$2-1)*12+4) -> 0 | L18: =INDEX(Monthly!$C$50:$BJ$50,($R$2-1)*12+5) -> 0 | M18: =INDEX(Monthly!$C$50:$BJ$50,($R$2-1)*12+6) -> 0 | N18: =INDEX(Monthly!$C$50:$BJ$50,($R$2-1)*12+7) -> 0 | O18: =INDEX(Monthly!$C$50:$BJ$50,($R$2-1)*12+8) -> 0 | P18: =INDEX(Monthly!$C$50:$BJ$50,($R$2-1)*12+9) -> 0 | Q18: =INDEX(Monthly!$C$50:$BJ$50,($R$2-1)*12+10) -> 0 | R18: =INDEX(Monthly!$C$50:$BJ$50,($R$2-1)*12+11) -> 0 | S18: =INDEX(Monthly!$C$50:$BJ$50,($R$2-1)*12+12) -> 0
A19: Net income | B19: ='P&L'!B26 -> -70506.807 | C19: ='P&L'!C26 -> 17593.913 | D19: ='P&L'!D26 -> 29844.776 | E19: ='P&L'!E26 -> 38127.44 | F19: ='P&L'!F26 -> 43135.578 | H19: =INDEX(Monthly!$C$51:$BJ$51,($R$2-1)*12+1) -> -14249.317 | I19: =INDEX(Monthly!$C$51:$BJ$51,($R$2-1)*12+2) -> -12974.572 | J19: =INDEX(Monthly!$C$51:$BJ$51,($R$2-1)*12+3) -> -11699.807 | K19: =INDEX(Monthly!$C$51:$BJ$51,($R$2-1)*12+4) -> -10425.02 | L19: =INDEX(Monthly!$C$51:$BJ$51,($R$2-1)*12+5) -> -9150.2117 | M19: =INDEX(Monthly!$C$51:$BJ$51,($R$2-1)*12+6) -> -2464.9728 | N19: =INDEX(Monthly!$C$51:$BJ$51,($R$2-1)*12+7) -> -726.37254 | O19: =INDEX(Monthly!$C$51:$BJ$51,($R$2-1)*12+8) -> 1012.2494 | P19: =INDEX(Monthly!$C$51:$BJ$51,($R$2-1)*12+9) -> -4050.7646 | Q19: =INDEX(Monthly!$C$51:$BJ$51,($R$2-1)*12+10) -> -2775.8485 | R19: =INDEX(Monthly!$C$51:$BJ$51,($R$2-1)*12+11) -> -1500.9104 | S19: =INDEX(Monthly!$C$51:$BJ$51,($R$2-1)*12+12) -> -1501.2609
A20: Net margin | B20: ='P&L'!B27 -> -0.25644037 | C20: ='P&L'!C27 -> 0.044336566 | D20: ='P&L'!D27 -> 0.071586402 | E20: ='P&L'!E27 -> 0.087048736 | F20: ='P&L'!F27 -> 0.09373959 | H20: =IF(H7=0,0,H19/H7) -> -1.2346415 | I20: =IF(I7=0,0,I19/I7) -> -0.97755687 | J20: =IF(J7=0,0,J19/J7) -> -0.77979806 | K20: =IF(K7=0,0,K19/K7) -> -0.62295361 | L20: =IF(L7=0,0,L19/L7) -> -0.49551635 | M20: =IF(M7=0,0,M19/M7) -> -0.089499856 | N20: =IF(N7=0,0,N19/N7) -> -0.024291485 | O20: =IF(O7=0,0,O19/O7) -> 0.031374868 | ... S20: =IF(S7=0,0,S19/S7) -> -0.052031097
A22: Cash flow ($'000) — by year | H22: ="Cash flow ($'000) — Year "&$R$2&", by month" -> Cash flow ($'000) — Year 1, by month
B23: 1 | C23: 2 | D23: 3 | E23: 4 | F23: 5 | H23: =INDEX(Monthly!$C$4:$BJ$4,($R$2-1)*12+1) -> 1 | I23: =INDEX(Monthly!$C$4:$BJ$4,($R$2-1)*12+2) -> 2 | J23: =INDEX(Monthly!$C$4:$BJ$4,($R$2-1)*12+3) -> 3 | K23: =INDEX(Monthly!$C$4:$BJ$4,($R$2-1)*12+4) -> 4 | L23: =INDEX(Monthly!$C$4:$BJ$4,($R$2-1)*12+5) -> 5 | M23: =INDEX(Monthly!$C$4:$BJ$4,($R$2-1)*12+6) -> 6 | N23: =INDEX(Monthly!$C$4:$BJ$4,($R$2-1)*12+7) -> 7 | O23: =INDEX(Monthly!$C$4:$BJ$4,($R$2-1)*12+8) -> 8 | P23: =INDEX(Monthly!$C$4:$BJ$4,($R$2-1)*12+9) -> 9 | Q23: =INDEX(Monthly!$C$4:$BJ$4,($R$2-1)*12+10) -> 10 | R23: =INDEX(Monthly!$C$4:$BJ$4,($R$2-1)*12+11) -> 11 | S23: =INDEX(Monthly!$C$4:$BJ$4,($R$2-1)*12+12) -> 12
A24: Operating cash flow | B24: ='Cash Flow'!B10 -> -19872.931 | C24: ='Cash Flow'!C10 -> 64360.735 | D24: ='Cash Flow'!D10 -> 77245.925 | E24: ='Cash Flow'!E10 -> 86182.013 | F24: ='Cash Flow'!F10 -> 91863.248 | H24: =INDEX(Monthly!$C$83:$BJ$83,($R$2-1)*12+1) -> -6558.7108 | I24: =INDEX(Monthly!$C$83:$BJ$83,($R$2-1)*12+2) -> -9084.5507 | J24: =INDEX(Monthly!$C$83:$BJ$83,($R$2-1)*12+3) -> -7805.6184 | K24: =INDEX(Monthly!$C$83:$BJ$83,($R$2-1)*12+4) -> -6526.665 | L24: =INDEX(Monthly!$C$83:$BJ$83,($R$2-1)*12+5) -> -5247.6903 | M24: =INDEX(Monthly!$C$83:$BJ$83,($R$2-1)*12+6) -> 1764.702 | N24: =INDEX(Monthly!$C$83:$BJ$83,($R$2-1)*12+7) -> 3212.1668 | O24: =INDEX(Monthly!$C$83:$BJ$83,($R$2-1)*12+8) -> 4954.9554 | P24: =INDEX(Monthly!$C$83:$BJ$83,($R$2-1)*12+9) -> -509.93232 | Q24: =INDEX(Monthly!$C$83:$BJ$83,($R$2-1)*12+10) -> 1147.5063 | R24: =INDEX(Monthly!$C$83:$BJ$83,($R$2-1)*12+11) -> 2426.6111 | S24: =INDEX(Monthly!$C$83:$BJ$83,($R$2-1)*12+12) -> 2354.2947
A25: Capital spending | B25: ='Cash Flow'!B11 -> -874000 | C25: ='Cash Flow'!C11 -> -9270 | D25: ='Cash Flow'!D11 -> -9548.1 | E25: ='Cash Flow'!E11 -> -9834.543 | F25: ='Cash Flow'!F11 -> -10129.579 | H25: =INDEX(Monthly!$C$84:$BJ$84,($R$2-1)*12+1) -> -865750 | I25: =INDEX(Monthly!$C$84:$BJ$84,($R$2-1)*12+2) -> -750 | J25: =INDEX(Monthly!$C$84:$BJ$84,($R$2-1)*12+3) -> -750 | K25: =INDEX(Monthly!$C$84:$BJ$84,($R$2-1)*12+4) -> -750 | L25: =INDEX(Monthly!$C$84:$BJ$84,($R$2-1)*12+5) -> -750 | M25: =INDEX(Monthly!$C$84:$BJ$84,($R$2-1)*12+6) -> -750 | N25: =INDEX(Monthly!$C$84:$BJ$84,($R$2-1)*12+7) -> -750 | O25: =INDEX(Monthly!$C$84:$BJ$84,($R$2-1)*12+8) -> -750 | P25: =INDEX(Monthly!$C$84:$BJ$84,($R$2-1)*12+9) -> -750 | Q25: =INDEX(Monthly!$C$84:$BJ$84,($R$2-1)*12+10) -> -750 | R25: =INDEX(Monthly!$C$84:$BJ$84,($R$2-1)*12+11) -> -750 | S25: =INDEX(Monthly!$C$84:$BJ$84,($R$2-1)*12+12) -> -750
A26: Equity raised | B26: ='Cash Flow'!B12 -> 430000 | C26: ='Cash Flow'!C12 -> 0 | D26: ='Cash Flow'!D12 -> 0 | E26: ='Cash Flow'!E12 -> 0 | F26: ='Cash Flow'!F12 -> 0 | H26: =INDEX(Monthly!$C$85:$BJ$85,($R$2-1)*12+1) -> 430000 | I26: =INDEX(Monthly!$C$85:$BJ$85,($R$2-1)*12+2) -> 0 | J26: =INDEX(Monthly!$C$85:$BJ$85,($R$2-1)*12+3) -> 0 | K26: =INDEX(Monthly!$C$85:$BJ$85,($R$2-1)*12+4) -> 0 | L26: =INDEX(Monthly!$C$85:$BJ$85,($R$2-1)*12+5) -> 0 | M26: =INDEX(Monthly!$C$85:$BJ$85,($R$2-1)*12+6) -> 0 | N26: =INDEX(Monthly!$C$85:$BJ$85,($R$2-1)*12+7) -> 0 | O26: =INDEX(Monthly!$C$85:$BJ$85,($R$2-1)*12+8) -> 0 | P26: =INDEX(Monthly!$C$85:$BJ$85,($R$2-1)*12+9) -> 0 | Q26: =INDEX(Monthly!$C$85:$BJ$85,($R$2-1)*12+10) -> 0 | R26: =INDEX(Monthly!$C$85:$BJ$85,($R$2-1)*12+11) -> 0 | S26: =INDEX(Monthly!$C$85:$BJ$85,($R$2-1)*12+12) -> 0
A27: Loan drawdown | B27: ='Cash Flow'!B13 -> 500000 | C27: ='Cash Flow'!C13 -> 0 | D27: ='Cash Flow'!D13 -> 0 | E27: ='Cash Flow'!E13 -> 0 | F27: ='Cash Flow'!F13 -> 0 | H27: =INDEX(Monthly!$C$68:$BJ$68,($R$2-1)*12+1) -> 500000 | I27: =INDEX(Monthly!$C$68:$BJ$68,($R$2-1)*12+2) -> 0 | J27: =INDEX(Monthly!$C$68:$BJ$68,($R$2-1)*12+3) -> 0 | K27: =INDEX(Monthly!$C$68:$BJ$68,($R$2-1)*12+4) -> 0 | L27: =INDEX(Monthly!$C$68:$BJ$68,($R$2-1)*12+5) -> 0 | M27: =INDEX(Monthly!$C$68:$BJ$68,($R$2-1)*12+6) -> 0 | N27: =INDEX(Monthly!$C$68:$BJ$68,($R$2-1)*12+7) -> 0 | O27: =INDEX(Monthly!$C$68:$BJ$68,($R$2-1)*12+8) -> 0 | P27: =INDEX(Monthly!$C$68:$BJ$68,($R$2-1)*12+9) -> 0 | Q27: =INDEX(Monthly!$C$68:$BJ$68,($R$2-1)*12+10) -> 0 | R27: =INDEX(Monthly!$C$68:$BJ$68,($R$2-1)*12+11) -> 0 | S27: =INDEX(Monthly!$C$68:$BJ$68,($R$2-1)*12+12) -> 0
A28: Loan repayment | B28: ='Cash Flow'!B14 -> -7649.067 | C28: ='Cash Flow'!C14 -> -8202.0187 | D28: ='Cash Flow'!D14 -> -8794.9433 | E28: ='Cash Flow'!E14 -> -9430.7304 | F28: ='Cash Flow'!F14 -> -10112.479 | H28: =INDEX(Monthly!$C$70:$BJ$70,($R$2-1)*12+1) -> -617.22932 | I28: =INDEX(Monthly!$C$70:$BJ$70,($R$2-1)*12+2) -> -620.82982 | J28: =INDEX(Monthly!$C$70:$BJ$70,($R$2-1)*12+3) -> -624.45133 | K28: =INDEX(Monthly!$C$70:$BJ$70,($R$2-1)*12+4) -> -628.09396 | L28: =INDEX(Monthly!$C$70:$BJ$70,($R$2-1)*12+5) -> -631.75785 | M28: =INDEX(Monthly!$C$70:$BJ$70,($R$2-1)*12+6) -> -635.4431 | N28: =INDEX(Monthly!$C$70:$BJ$70,($R$2-1)*12+7) -> -639.14985 | O28: =INDEX(Monthly!$C$70:$BJ$70,($R$2-1)*12+8) -> -642.87823 | P28: =INDEX(Monthly!$C$70:$BJ$70,($R$2-1)*12+9) -> -646.62835 | Q28: =INDEX(Monthly!$C$70:$BJ$70,($R$2-1)*12+10) -> -650.40035 | R28: =INDEX(Monthly!$C$70:$BJ$70,($R$2-1)*12+11) -> -654.19435 | S28: =INDEX(Monthly!$C$70:$BJ$70,($R$2-1)*12+12) -> -658.01048
A29: Financing cash flow | B29: ='Cash Flow'!B15 -> 922350.93 | C29: ='Cash Flow'!C15 -> -8202.0187 | D29: ='Cash Flow'!D15 -> -8794.9433 | E29: ='Cash Flow'!E15 -> -9430.7304 | F29: ='Cash Flow'!F15 -> -10112.479 | H29: =INDEX(Monthly!$C$86:$BJ$86,($R$2-1)*12+1) -> 929382.77 | I29: =INDEX(Monthly!$C$86:$BJ$86,($R$2-1)*12+2) -> -620.82982 | J29: =INDEX(Monthly!$C$86:$BJ$86,($R$2-1)*12+3) -> -624.45133 | K29: =INDEX(Monthly!$C$86:$BJ$86,($R$2-1)*12+4) -> -628.09396 | L29: =INDEX(Monthly!$C$86:$BJ$86,($R$2-1)*12+5) -> -631.75785 | M29: =INDEX(Monthly!$C$86:$BJ$86,($R$2-1)*12+6) -> -635.4431 | N29: =INDEX(Monthly!$C$86:$BJ$86,($R$2-1)*12+7) -> -639.14985 | O29: =INDEX(Monthly!$C$86:$BJ$86,($R$2-1)*12+8) -> -642.87823 | P29: =INDEX(Monthly!$C$86:$BJ$86,($R$2-1)*12+9) -> -646.62835 | Q29: =INDEX(Monthly!$C$86:$BJ$86,($R$2-1)*12+10) -> -650.40035 | R29: =INDEX(Monthly!$C$86:$BJ$86,($R$2-1)*12+11) -> -654.19435 | S29: =INDEX(Monthly!$C$86:$BJ$86,($R$2-1)*12+12) -> -658.01048
A30: Net change in cash | B30: ='Cash Flow'!B16 -> 28478.002 | C30: ='Cash Flow'!C16 -> 46888.716 | D30: ='Cash Flow'!D16 -> 58902.881 | E30: ='Cash Flow'!E16 -> 66916.74 | F30: ='Cash Flow'!F16 -> 71621.19 | H30: =INDEX(Monthly!$C$87:$BJ$87,($R$2-1)*12+1) -> 57074.06 | I30: =INDEX(Monthly!$C$87:$BJ$87,($R$2-1)*12+2) -> -10455.381 | J30: =INDEX(Monthly!$C$87:$BJ$87,($R$2-1)*12+3) -> -9180.0697 | K30: =INDEX(Monthly!$C$87:$BJ$87,($R$2-1)*12+4) -> -7904.7589 | L30: =INDEX(Monthly!$C$87:$BJ$87,($R$2-1)*12+5) -> -6629.4481 | M30: =INDEX(Monthly!$C$87:$BJ$87,($R$2-1)*12+6) -> 379.25886 | N30: =INDEX(Monthly!$C$87:$BJ$87,($R$2-1)*12+7) -> 1823.017 | O30: =INDEX(Monthly!$C$87:$BJ$87,($R$2-1)*12+8) -> 3562.0772 | P30: =INDEX(Monthly!$C$87:$BJ$87,($R$2-1)*12+9) -> -1906.5607 | Q30: =INDEX(Monthly!$C$87:$BJ$87,($R$2-1)*12+10) -> -252.89405 | R30: =INDEX(Monthly!$C$87:$BJ$87,($R$2-1)*12+11) -> 1022.4168 | S30: =INDEX(Monthly!$C$87:$BJ$87,($R$2-1)*12+12) -> 946.28419
A31: Closing cash | B31: ='Cash Flow'!B18 -> 28478.002 | C31: ='Cash Flow'!C18 -> 75366.718 | D31: ='Cash Flow'!D18 -> 134269.6 | E31: ='Cash Flow'!E18 -> 201186.34 | F31: ='Cash Flow'!F18 -> 272807.53 | H31: =INDEX(Monthly!$C$89:$BJ$89,($R$2-1)*12+1) -> 57074.06 | I31: =INDEX(Monthly!$C$89:$BJ$89,($R$2-1)*12+2) -> 46618.679 | J31: =INDEX(Monthly!$C$89:$BJ$89,($R$2-1)*12+3) -> 37438.61 | K31: =INDEX(Monthly!$C$89:$BJ$89,($R$2-1)*12+4) -> 29533.851 | L31: =INDEX(Monthly!$C$89:$BJ$89,($R$2-1)*12+5) -> 22904.403 | M31: =INDEX(Monthly!$C$89:$BJ$89,($R$2-1)*12+6) -> 23283.661 | N31: =INDEX(Monthly!$C$89:$BJ$89,($R$2-1)*12+7) -> 25106.678 | O31: =INDEX(Monthly!$C$89:$BJ$89,($R$2-1)*12+8) -> 28668.756 | P31: =INDEX(Monthly!$C$89:$BJ$89,($R$2-1)*12+9) -> 26762.195 | Q31: =INDEX(Monthly!$C$89:$BJ$89,($R$2-1)*12+10) -> 26509.301 | R31: =INDEX(Monthly!$C$89:$BJ$89,($R$2-1)*12+11) -> 27531.718 | S31: =INDEX(Monthly!$C$89:$BJ$89,($R$2-1)*12+12) -> 28478.002
A39: Balance sheet at year end ($'000) | H39: ="Balance sheet at month end ($'000) — Year "&$R$2 -> Balance sheet at month end ($'000) — Year 1
B40: 1 | C40: 2 | D40: 3 | E40: 4 | F40: 5 | H40: =INDEX(Monthly!$C$4:$BJ$4,($R$2-1)*12+1) -> 1 | I40: =INDEX(Monthly!$C$4:$BJ$4,($R$2-1)*12+2) -> 2 | J40: =INDEX(Monthly!$C$4:$BJ$4,($R$2-1)*12+3) -> 3 | K40: =INDEX(Monthly!$C$4:$BJ$4,($R$2-1)*12+4) -> 4 | L40: =INDEX(Monthly!$C$4:$BJ$4,($R$2-1)*12+5) -> 5 | M40: =INDEX(Monthly!$C$4:$BJ$4,($R$2-1)*12+6) -> 6 | N40: =INDEX(Monthly!$C$4:$BJ$4,($R$2-1)*12+7) -> 7 | O40: =INDEX(Monthly!$C$4:$BJ$4,($R$2-1)*12+8) -> 8 | P40: =INDEX(Monthly!$C$4:$BJ$4,($R$2-1)*12+9) -> 9 | Q40: =INDEX(Monthly!$C$4:$BJ$4,($R$2-1)*12+10) -> 10 | R40: =INDEX(Monthly!$C$4:$BJ$4,($R$2-1)*12+11) -> 11 | S40: =INDEX(Monthly!$C$4:$BJ$4,($R$2-1)*12+12) -> 12
A41: Cash | B41: ='Balance Sheet'!B5 -> 28478.002 | C41: ='Balance Sheet'!C5 -> 75366.718 | D41: ='Balance Sheet'!D5 -> 134269.6 | E41: ='Balance Sheet'!E5 -> 201186.34 | F41: ='Balance Sheet'!F5 -> 272807.53 | H41: =INDEX(Monthly!$C$89:$BJ$89,($R$2-1)*12+1) -> 57074.06 | I41: =INDEX(Monthly!$C$89:$BJ$89,($R$2-1)*12+2) -> 46618.679 | J41: =INDEX(Monthly!$C$89:$BJ$89,($R$2-1)*12+3) -> 37438.61 | K41: =INDEX(Monthly!$C$89:$BJ$89,($R$2-1)*12+4) -> 29533.851 | L41: =INDEX(Monthly!$C$89:$BJ$89,($R$2-1)*12+5) -> 22904.403 | M41: =INDEX(Monthly!$C$89:$BJ$89,($R$2-1)*12+6) -> 23283.661 | N41: =INDEX(Monthly!$C$89:$BJ$89,($R$2-1)*12+7) -> 25106.678 | O41: =INDEX(Monthly!$C$89:$BJ$89,($R$2-1)*12+8) -> 28668.756 | P41: =INDEX(Monthly!$C$89:$BJ$89,($R$2-1)*12+9) -> 26762.195 | Q41: =INDEX(Monthly!$C$89:$BJ$89,($R$2-1)*12+10) -> 26509.301 | R41: =INDEX(Monthly!$C$89:$BJ$89,($R$2-1)*12+11) -> 27531.718 | S41: =INDEX(Monthly!$C$89:$BJ$89,($R$2-1)*12+12) -> 28478.002
A42: Accounts receivable | B42: ='Balance Sheet'!B6 -> 2885.3147 | C42: ='Balance Sheet'!C6 -> 3031.3116 | D42: ='Balance Sheet'!D6 -> 3184.696 | E42: ='Balance Sheet'!E6 -> 3345.8416 | F42: ='Balance Sheet'!F6 -> 3515.1412 | H42: =INDEX(Monthly!$C$75:$BJ$75,($R$2-1)*12+1) -> 1154.1259 | I42: =INDEX(Monthly!$C$75:$BJ$75,($R$2-1)*12+2) -> 1327.2447 | J42: =INDEX(Monthly!$C$75:$BJ$75,($R$2-1)*12+3) -> 1500.3636 | K42: =INDEX(Monthly!$C$75:$BJ$75,($R$2-1)*12+4) -> 1673.4825 | L42: =INDEX(Monthly!$C$75:$BJ$75,($R$2-1)*12+5) -> 1846.6014 | M42: =INDEX(Monthly!$C$75:$BJ$75,($R$2-1)*12+6) -> 2754.164 | N42: =INDEX(Monthly!$C$75:$BJ$75,($R$2-1)*12+7) -> 2990.2352 | O42: =INDEX(Monthly!$C$75:$BJ$75,($R$2-1)*12+8) -> 3226.3064 | P42: =INDEX(Monthly!$C$75:$BJ$75,($R$2-1)*12+9) -> 2539.0769 | Q42: =INDEX(Monthly!$C$75:$BJ$75,($R$2-1)*12+10) -> 2712.1958 | R42: =INDEX(Monthly!$C$75:$BJ$75,($R$2-1)*12+11) -> 2885.3147 | S42: =INDEX(Monthly!$C$75:$BJ$75,($R$2-1)*12+12) -> 2885.3147
A43: Inventory | B43: ='Balance Sheet'!B7 -> 1026.4806 | C43: ='Balance Sheet'!C7 -> 1068.9445 | D43: ='Balance Sheet'!D7 -> 1113.2728 | E43: ='Balance Sheet'!E7 -> 1159.5513 | F43: ='Balance Sheet'!F7 -> 1207.8699 | H43: =INDEX(Monthly!$C$76:$BJ$76,($R$2-1)*12+1) -> 686.59223 | I43: =INDEX(Monthly!$C$76:$BJ$76,($R$2-1)*12+2) -> 720.58106 | J43: =INDEX(Monthly!$C$76:$BJ$76,($R$2-1)*12+3) -> 754.56989 | K43: =INDEX(Monthly!$C$76:$BJ$76,($R$2-1)*12+4) -> 788.55873 | L43: =INDEX(Monthly!$C$76:$BJ$76,($R$2-1)*12+5) -> 822.54756 | M43: =INDEX(Monthly!$C$76:$BJ$76,($R$2-1)*12+6) -> 1000.7314 | N43: =INDEX(Monthly!$C$76:$BJ$76,($R$2-1)*12+7) -> 1047.0799 | O43: =INDEX(Monthly!$C$76:$BJ$76,($R$2-1)*12+8) -> 1093.4283 | P43: =INDEX(Monthly!$C$76:$BJ$76,($R$2-1)*12+9) -> 958.5029 | Q43: =INDEX(Monthly!$C$76:$BJ$76,($R$2-1)*12+10) -> 992.49173 | R43: =INDEX(Monthly!$C$76:$BJ$76,($R$2-1)*12+11) -> 1026.4806 | S43: =INDEX(Monthly!$C$76:$BJ$76,($R$2-1)*12+12) -> 1026.4806
A44: Net fixed assets | B44: ='Balance Sheet'!B8 -> 828008.33 | C44: ='Balance Sheet'!C8 -> 790676.92 | D44: ='Balance Sheet'!D8 -> 752995.56 | E44: ='Balance Sheet'!E8 -> 714953.76 | F44: ='Balance Sheet'!F8 -> 676540.7 | H44: =INDEX(Monthly!$C$64:$BJ$64,($R$2-1)*12+1) -> 861940.28 | I44: =INDEX(Monthly!$C$64:$BJ$64,($R$2-1)*12+2) -> 858876.39 | J44: =INDEX(Monthly!$C$64:$BJ$64,($R$2-1)*12+3) -> 855808.33 | K44: =INDEX(Monthly!$C$64:$BJ$64,($R$2-1)*12+4) -> 852736.11 | L44: =INDEX(Monthly!$C$64:$BJ$64,($R$2-1)*12+5) -> 849659.72 | M44: =INDEX(Monthly!$C$64:$BJ$64,($R$2-1)*12+6) -> 846579.17 | N44: =INDEX(Monthly!$C$64:$BJ$64,($R$2-1)*12+7) -> 843494.44 | O44: =INDEX(Monthly!$C$64:$BJ$64,($R$2-1)*12+8) -> 840405.56 | P44: =INDEX(Monthly!$C$64:$BJ$64,($R$2-1)*12+9) -> 837312.5 | Q44: =INDEX(Monthly!$C$64:$BJ$64,($R$2-1)*12+10) -> 834215.28 | R44: =INDEX(Monthly!$C$64:$BJ$64,($R$2-1)*12+11) -> 831113.89 | S44: =INDEX(Monthly!$C$64:$BJ$64,($R$2-1)*12+12) -> 828008.33
A45: Total assets | B45: ='Balance Sheet'!B9 -> 860398.13 | C45: ='Balance Sheet'!C9 -> 870143.89 | D45: ='Balance Sheet'!D9 -> 891563.13 | E45: ='Balance Sheet'!E9 -> 920645.49 | F45: ='Balance Sheet'!F9 -> 954071.24 | H45: =INDEX(Monthly!$C$103:$BJ$103,($R$2-1)*12+1) -> 920855.06 | I45: =INDEX(Monthly!$C$103:$BJ$103,($R$2-1)*12+2) -> 907542.89 | J45: =INDEX(Monthly!$C$103:$BJ$103,($R$2-1)*12+3) -> 895501.88 | K45: =INDEX(Monthly!$C$103:$BJ$103,($R$2-1)*12+4) -> 884732 | L45: =INDEX(Monthly!$C$103:$BJ$103,($R$2-1)*12+5) -> 875233.27 | M45: =INDEX(Monthly!$C$103:$BJ$103,($R$2-1)*12+6) -> 873617.72 | N45: =INDEX(Monthly!$C$103:$BJ$103,($R$2-1)*12+7) -> 872638.44 | O45: =INDEX(Monthly!$C$103:$BJ$103,($R$2-1)*12+8) -> 873394.05 | P45: =INDEX(Monthly!$C$103:$BJ$103,($R$2-1)*12+9) -> 867572.27 | Q45: =INDEX(Monthly!$C$103:$BJ$103,($R$2-1)*12+10) -> 864429.27 | R45: =INDEX(Monthly!$C$103:$BJ$103,($R$2-1)*12+11) -> 862557.4 | S45: =INDEX(Monthly!$C$103:$BJ$103,($R$2-1)*12+12) -> 860398.13
A46: Accounts payable | B46: ='Balance Sheet'!B10 -> 8554.0047 | C46: ='Balance Sheet'!C10 -> 8907.8707 | D46: ='Balance Sheet'!D10 -> 9277.2733 | E46: ='Balance Sheet'!E10 -> 9662.9276 | F46: ='Balance Sheet'!F10 -> 10065.583 | H46: =INDEX(Monthly!$C$77:$BJ$77,($R$2-1)*12+1) -> 5721.6019 | I46: =INDEX(Monthly!$C$77:$BJ$77,($R$2-1)*12+2) -> 6004.8422 | J46: =INDEX(Monthly!$C$77:$BJ$77,($R$2-1)*12+3) -> 6288.0825 | K46: =INDEX(Monthly!$C$77:$BJ$77,($R$2-1)*12+4) -> 6571.3227 | L46: =INDEX(Monthly!$C$77:$BJ$77,($R$2-1)*12+5) -> 6854.563 | M46: =INDEX(Monthly!$C$77:$BJ$77,($R$2-1)*12+6) -> 8339.4287 | N46: =INDEX(Monthly!$C$77:$BJ$77,($R$2-1)*12+7) -> 8725.6655 | O46: =INDEX(Monthly!$C$77:$BJ$77,($R$2-1)*12+8) -> 9111.9022 | P46: =INDEX(Monthly!$C$77:$BJ$77,($R$2-1)*12+9) -> 7987.5242 | Q46: =INDEX(Monthly!$C$77:$BJ$77,($R$2-1)*12+10) -> 8270.7644 | R46: =INDEX(Monthly!$C$77:$BJ$77,($R$2-1)*12+11) -> 8554.0047 | S46: =INDEX(Monthly!$C$77:$BJ$77,($R$2-1)*12+12) -> 8554.0047
A47: Loan | B47: ='Balance Sheet'!B11 -> 492350.93 | C47: ='Balance Sheet'!C11 -> 484148.91 | D47: ='Balance Sheet'!D11 -> 475353.97 | E47: ='Balance Sheet'!E11 -> 465923.24 | F47: ='Balance Sheet'!F11 -> 455810.76 | H47: =INDEX(Monthly!$C$72:$BJ$72,($R$2-1)*12+1) -> 499382.77 | I47: =INDEX(Monthly!$C$72:$BJ$72,($R$2-1)*12+2) -> 498761.94 | J47: =INDEX(Monthly!$C$72:$BJ$72,($R$2-1)*12+3) -> 498137.49 | K47: =INDEX(Monthly!$C$72:$BJ$72,($R$2-1)*12+4) -> 497509.4 | L47: =INDEX(Monthly!$C$72:$BJ$72,($R$2-1)*12+5) -> 496877.64 | M47: =INDEX(Monthly!$C$72:$BJ$72,($R$2-1)*12+6) -> 496242.19 | N47: =INDEX(Monthly!$C$72:$BJ$72,($R$2-1)*12+7) -> 495603.04 | O47: =INDEX(Monthly!$C$72:$BJ$72,($R$2-1)*12+8) -> 494960.17 | P47: =INDEX(Monthly!$C$72:$BJ$72,($R$2-1)*12+9) -> 494313.54 | Q47: =INDEX(Monthly!$C$72:$BJ$72,($R$2-1)*12+10) -> 493663.14 | R47: =INDEX(Monthly!$C$72:$BJ$72,($R$2-1)*12+11) -> 493008.94 | S47: =INDEX(Monthly!$C$72:$BJ$72,($R$2-1)*12+12) -> 492350.93
A48: Total liabilities | B48: ='Balance Sheet'!B12 -> 500904.94 | C48: ='Balance Sheet'!C12 -> 493056.79 | D48: ='Balance Sheet'!D12 -> 484631.24 | E48: ='Balance Sheet'!E12 -> 475586.17 | F48: ='Balance Sheet'!F12 -> 465876.34 | H48: =INDEX(Monthly!$C$104:$BJ$104,($R$2-1)*12+1) -> 505104.37 | I48: =INDEX(Monthly!$C$104:$BJ$104,($R$2-1)*12+2) -> 504766.78 | J48: =INDEX(Monthly!$C$104:$BJ$104,($R$2-1)*12+3) -> 504425.57 | K48: =INDEX(Monthly!$C$104:$BJ$104,($R$2-1)*12+4) -> 504080.72 | L48: =INDEX(Monthly!$C$104:$BJ$104,($R$2-1)*12+5) -> 503732.2 | M48: =INDEX(Monthly!$C$104:$BJ$104,($R$2-1)*12+6) -> 504581.62 | N48: =INDEX(Monthly!$C$104:$BJ$104,($R$2-1)*12+7) -> 504328.71 | O48: =INDEX(Monthly!$C$104:$BJ$104,($R$2-1)*12+8) -> 504072.07 | P48: =INDEX(Monthly!$C$104:$BJ$104,($R$2-1)*12+9) -> 502301.06 | Q48: =INDEX(Monthly!$C$104:$BJ$104,($R$2-1)*12+10) -> 501933.9 | R48: =INDEX(Monthly!$C$104:$BJ$104,($R$2-1)*12+11) -> 501562.95 | S48: =INDEX(Monthly!$C$104:$BJ$104,($R$2-1)*12+12) -> 500904.94
A49: Paid-in capital | B49: ='Balance Sheet'!B13 -> 430000 | C49: ='Balance Sheet'!C13 -> 430000 | D49: ='Balance Sheet'!D13 -> 430000 | E49: ='Balance Sheet'!E13 -> 430000 | F49: ='Balance Sheet'!F13 -> 430000 | H49: =INDEX(Monthly!$C$101:$BJ$101,($R$2-1)*12+1) -> 430000 | I49: =INDEX(Monthly!$C$101:$BJ$101,($R$2-1)*12+2) -> 430000 | J49: =INDEX(Monthly!$C$101:$BJ$101,($R$2-1)*12+3) -> 430000 | K49: =INDEX(Monthly!$C$101:$BJ$101,($R$2-1)*12+4) -> 430000 | L49: =INDEX(Monthly!$C$101:$BJ$101,($R$2-1)*12+5) -> 430000 | M49: =INDEX(Monthly!$C$101:$BJ$101,($R$2-1)*12+6) -> 430000 | N49: =INDEX(Monthly!$C$101:$BJ$101,($R$2-1)*12+7) -> 430000 | O49: =INDEX(Monthly!$C$101:$BJ$101,($R$2-1)*12+8) -> 430000 | P49: =INDEX(Monthly!$C$101:$BJ$101,($R$2-1)*12+9) -> 430000 | Q49: =INDEX(Monthly!$C$101:$BJ$101,($R$2-1)*12+10) -> 430000 | R49: =INDEX(Monthly!$C$101:$BJ$101,($R$2-1)*12+11) -> 430000 | S49: =INDEX(Monthly!$C$101:$BJ$101,($R$2-1)*12+12) -> 430000
A50: Retained earnings | B50: ='Balance Sheet'!B14 -> -70506.807 | C50: ='Balance Sheet'!C14 -> -52912.894 | D50: ='Balance Sheet'!D14 -> -23068.119 | E50: ='Balance Sheet'!E14 -> 15059.321 | F50: ='Balance Sheet'!F14 -> 58194.9 | H50: =INDEX(Monthly!$C$102:$BJ$102,($R$2-1)*12+1) -> -14249.317 | I50: =INDEX(Monthly!$C$102:$BJ$102,($R$2-1)*12+2) -> -27223.889 | J50: =INDEX(Monthly!$C$102:$BJ$102,($R$2-1)*12+3) -> -38923.696 | K50: =INDEX(Monthly!$C$102:$BJ$102,($R$2-1)*12+4) -> -49348.715 | L50: =INDEX(Monthly!$C$102:$BJ$102,($R$2-1)*12+5) -> -58498.927 | M50: =INDEX(Monthly!$C$102:$BJ$102,($R$2-1)*12+6) -> -60963.9 | N50: =INDEX(Monthly!$C$102:$BJ$102,($R$2-1)*12+7) -> -61690.272 | O50: =INDEX(Monthly!$C$102:$BJ$102,($R$2-1)*12+8) -> -60678.023 | P50: =INDEX(Monthly!$C$102:$BJ$102,($R$2-1)*12+9) -> -64728.788 | Q50: =INDEX(Monthly!$C$102:$BJ$102,($R$2-1)*12+10) -> -67504.636 | R50: =INDEX(Monthly!$C$102:$BJ$102,($R$2-1)*12+11) -> -69005.546 | S50: =INDEX(Monthly!$C$102:$BJ$102,($R$2-1)*12+12) -> -70506.807
...

Sheet Scenarios
A1: Scenarios — Low / Base / High | H1: =HYPERLINK("#'Cover'!A1","◂ Contents") -> ◂ Contents
A2: All three scenarios calculated side by side, live: change any input and every column updates. Active = the scenario chosen on the Dashboard.
A5: Key drivers
A6: Driver | B6: Low | C6: Base | D6: High | E6: Active
A7: Lettable rooms (rooms) | B7: =Inputs!$B$7 -> 10 | C7: =Inputs!$C$7 -> 10 | D7: =Inputs!$D$7 -> 10 | E7: =Inputs!$E$7 -> 10
A8: Average daily rate per occupied room (year 1) ($) | B8: =Inputs!$B$17 -> 135 | C8: =Inputs!$C$17 -> 155 | D8: =Inputs!$D$17 -> 170 | E8: =Inputs!$E$17 -> 155
A9: Average occupancy at maturity, % of room-nights (year 1) (%) | B9: =Inputs!$B$8 -> 0.5 | C9: =Inputs!$C$8 -> 0.62 | D9: =Inputs!$D$8 -> 0.7 | E9: =Inputs!$E$8 -> 0.62
A10: Property purchase (month 1; 0 = leased building) ($) | B10: =Inputs!$B$42 -> 720000 | C10: =Inputs!$C$42 -> 720000 | D10: =Inputs!$D$42 -> 720000 | E10: =Inputs!$E$42 -> 720000
A11: Loan drawn at start ($) | B11: =Inputs!$B$66 -> 500000 | C11: =Inputs!$C$66 -> 500000 | D11: =Inputs!$D$66 -> 500000 | E11: =Inputs!$E$66 -> 500000
A12: Loan interest rate per year (%) | B12: =Inputs!$B$67 -> 0.07 | C12: =Inputs!$C$67 -> 0.07 | D12: =Inputs!$D$67 -> 0.07 | E12: =Inputs!$E$67 -> 0.07
A13: Equity raised at start ($) | B13: =Inputs!$B$65 -> 430000 | C13: =Inputs!$C$65 -> 430000 | D13: =Inputs!$D$65 -> 430000 | E13: =Inputs!$E$65 -> 430000
A15: Results by scenario ($'000)
A16: Output | B16: Low | C16: Base | D16: High | E16: Active
A17: Revenue — final year | B17: =F30 -> 273320.89 | C17: =F31 -> 460163.93 | D17: =F32 -> 622023.59 | E17: ='P&L'!F5 -> 460163.93
A18: Revenue — whole plan | B18: =SUM(B30:F30) -> 1225688.3 | C18: =SUM(B31:F31) -> 1986841.2 | D18: =SUM(B32:F32) -> 2637136.3 | E18: =SUM('P&L'!$B$5:$F$5) -> 1986841.2
A19: EBITDA — final year | B19: =F36 -> -35973.656 | C19: =F37 -> 135438.9 | D19: =F38 -> 284860.42 | E19: ='P&L'!F19 -> 135438.9
A20: EBITDA margin — final year | B20: =IF(B17=0,0,B19/B17) -> -0.13161693 | C20: =IF(C17=0,0,C19/C17) -> 0.29432751 | D20: =IF(D17=0,0,D19/D17) -> 0.45795758 | E20: =IF(E17=0,0,E19/E17) -> 0.29432751
A21: Net income — final year | B21: =F42 -> -116862.68 | C21: =F43 -> 43135.578 | D21: =F44 -> 161198.89 | E21: ='P&L'!F26 -> 43135.578
A22: Net income — whole plan | B22: =SUM(B42:F42) -> -616314.1 | C22: =SUM(B43:F43) -> 58194.9 | D22: =SUM(B44:F44) -> 537535.4 | E22: =SUM('P&L'!$B$26:$F$26) -> 58194.9
A23: Cash at the end of the plan | B23: =F48 -> -401616.61 | C23: =F49 -> 272807.53 | D23: =F50 -> 751487.19 | E23: ='Balance Sheet'!F5 -> 272807.53
A24: Lowest cash balance | B24: =MIN('Scenario calc'!$C$91:$BJ$91) -> -401616.61 | C24: =MIN('Scenario calc'!$C$211:$BJ$211) -> 22904.403 | D24: =MIN('Scenario calc'!$C$331:$BJ$331) -> 54905.784 | E24: ='Break-even'!B18 -> 22904.403
A25: Lowest cash point (month #) | B25: =MATCH(MIN('Scenario calc'!$C$91:$BJ$91),'Scenario calc'!$C$91:$BJ$91,0) -> 60 | C25: =MATCH(MIN('Scenario calc'!$C$211:$BJ$211),'Scenario calc'!$C$211:$BJ$211,0) -> 5 | D25: =MATCH(MIN('Scenario calc'!$C$331:$BJ$331),'Scenario calc'!$C$331:$BJ$331,0) -> 4 | E25: ='Break-even'!B6 -> 5
A26: Funding required (incl. cash buffer) | B26: =SUMPRODUCT(--('Scenario calc'!$C$6:$BJ$6<=B25),'Scenario calc'!$C$61:$BJ$61)-SUMPRODUCT(--('Scenario calc'!$C$6:$BJ$6<=B25),'Scenario calc'!$C$85:$BJ$85)-SUMPRODUCT(--('Scenario calc'!$C$6:$BJ$6<=B25),'Scenario calc'!$C$72:$BJ$72)+Inputs!$B$80 -> 1370616.6 | C26: =SUMPRODUCT(--('Scenario calc'!$C$126:$BJ$126<=C25),'Scenario calc'!$C$181:$BJ$181)-SUMPRODUCT(--('Scenario calc'!$C$126:$BJ$126<=C25),'Scenario calc'!$C$205:$BJ$205)-SUMPRODUCT(--('Scenario calc'!$C$126:$BJ$126<=C25),'Scenario calc'!$C$192:$BJ$192)+Inputs!$C$80 -> 946095.6 | D26: =SUMPRODUCT(--('Scenario calc'!$C$246:$BJ$246<=D25),'Scenario calc'!$C$301:$BJ$301)-SUMPRODUCT(--('Scenario calc'!$C$246:$BJ$246<=D25),'Scenario calc'!$C$325:$BJ$325)-SUMPRODUCT(--('Scenario calc'!$C$246:$BJ$246<=D25),'Scenario calc'!$C$312:$BJ$312)+Inputs!$D$80 -> 914094.22 | E26: ='Break-even'!B12 -> 946095.6
A28: Revenue by year ($'000)
A29: Scenario | B29: 1 | C29: 2 | D29: 3 | E29: 4 | F29: 5
A30: Low | B30: =SUMIF('Scenario calc'!$C$7:$BJ$7,B$29,'Scenario calc'!$C$22:$BJ$22) -> 151574.4 | C30: =SUMIF('Scenario calc'!$C$7:$BJ$7,C$29,'Scenario calc'!$C$22:$BJ$22) -> 262242.86 | D30: =SUMIF('Scenario calc'!$C$7:$BJ$7,D$29,'Scenario calc'!$C$22:$BJ$22) -> 267935.39 | E30: =SUMIF('Scenario calc'!$C$7:$BJ$7,E$29,'Scenario calc'!$C$22:$BJ$22) -> 270614.74 | F30: =SUMIF('Scenario calc'!$C$7:$BJ$7,F$29,'Scenario calc'!$C$22:$BJ$22) -> 273320.89
A31: Base | B31: =SUMIF('Scenario calc'!$C$127:$BJ$127,B$29,'Scenario calc'!$C$142:$BJ$142) -> 274944.26 | C31: =SUMIF('Scenario calc'!$C$127:$BJ$127,C$29,'Scenario calc'!$C$142:$BJ$142) -> 396826.24 | D31: =SUMIF('Scenario calc'!$C$127:$BJ$127,D$29,'Scenario calc'!$C$142:$BJ$142) -> 416905.65 | E31: =SUMIF('Scenario calc'!$C$127:$BJ$127,E$29,'Scenario calc'!$C$142:$BJ$142) -> 438001.08 | F31: =SUMIF('Scenario calc'!$C$127:$BJ$127,F$29,'Scenario calc'!$C$142:$BJ$142) -> 460163.93
A32: High | B32: =SUMIF('Scenario calc'!$C$247:$BJ$247,B$29,'Scenario calc'!$C$262:$BJ$262) -> 386298.5 | C32: =SUMIF('Scenario calc'!$C$247:$BJ$247,C$29,'Scenario calc'!$C$262:$BJ$262) -> 506052.02 | D32: =SUMIF('Scenario calc'!$C$247:$BJ$247,D$29,'Scenario calc'!$C$262:$BJ$262) -> 542082.92 | E32: =SUMIF('Scenario calc'!$C$247:$BJ$247,E$29,'Scenario calc'!$C$262:$BJ$262) -> 580679.23 | F32: =SUMIF('Scenario calc'!$C$247:$BJ$247,F$29,'Scenario calc'!$C$262:$BJ$262) -> 622023.59
A34: EBITDA by year ($'000)
A35: Scenario | B35: 1 | C35: 2 | D35: 3 | E35: 4 | F35: 5
A36: Low | B36: =SUMIF('Scenario calc'!$C$7:$BJ$7,B$35,'Scenario calc'!$C$44:$BJ$44) -> -94231.305 | C36: =SUMIF('Scenario calc'!$C$7:$BJ$7,C$35,'Scenario calc'!$C$44:$BJ$44) -> -25252.574 | D36: =SUMIF('Scenario calc'!$C$7:$BJ$7,D$35,'Scenario calc'!$C$44:$BJ$44) -> -26169.782 | E36: =SUMIF('Scenario calc'!$C$7:$BJ$7,E$35,'Scenario calc'!$C$44:$BJ$44) -> -30503.789 | F36: =SUMIF('Scenario calc'!$C$7:$BJ$7,F$35,'Scenario calc'!$C$44:$BJ$44) -> -35973.656
A37: Base | B37: =SUMIF('Scenario calc'!$C$127:$BJ$127,B$35,'Scenario calc'!$C$164:$BJ$164) -> 10242.544 | C37: =SUMIF('Scenario calc'!$C$127:$BJ$127,C$35,'Scenario calc'!$C$164:$BJ$164) -> 98400.063 | D37: =SUMIF('Scenario calc'!$C$127:$BJ$127,D$35,'Scenario calc'!$C$164:$BJ$164) -> 110686.04 | E37: =SUMIF('Scenario calc'!$C$127:$BJ$127,E$35,'Scenario calc'!$C$164:$BJ$164) -> 122982.92 | F37: =SUMIF('Scenario calc'!$C$127:$BJ$127,F$35,'Scenario calc'!$C$164:$BJ$164) -> 135438.9
A38: High | B38: =SUMIF('Scenario calc'!$C$247:$BJ$247,B$35,'Scenario calc'!$C$284:$BJ$284) -> 111794.82 | C38: =SUMIF('Scenario calc'!$C$247:$BJ$247,C$35,'Scenario calc'!$C$284:$BJ$284) -> 203324.39 | D38: =SUMIF('Scenario calc'!$C$247:$BJ$247,D$35,'Scenario calc'!$C$284:$BJ$284) -> 228679.04 | E38: =SUMIF('Scenario calc'!$C$247:$BJ$247,E$35,'Scenario calc'!$C$284:$BJ$284) -> 255803.93 | F38: =SUMIF('Scenario calc'!$C$247:$BJ$247,F$35,'Scenario calc'!$C$284:$BJ$284) -> 284860.42
A40: Net income by year ($'000)
A41: Scenario | B41: 1 | C41: 2 | D41: 3 | E41: 4 | F41: 5
A42: Low | B42: =SUMIF('Scenario calc'!$C$7:$BJ$7,B$41,'Scenario calc'!$C$53:$BJ$53) -> -174980.66 | C42: =SUMIF('Scenario calc'!$C$7:$BJ$7,C$41,'Scenario calc'!$C$53:$BJ$53) -> -106061.97 | D42: =SUMIF('Scenario calc'!$C$7:$BJ$7,D$41,'Scenario calc'!$C$53:$BJ$53) -> -107023.78 | E42: =SUMIF('Scenario calc'!$C$7:$BJ$7,E$41,'Scenario calc'!$C$53:$BJ$53) -> -111385.02 | F42: =SUMIF('Scenario calc'!$C$7:$BJ$7,F$41,'Scenario calc'!$C$53:$BJ$53) -> -116862.68
A43: Base | B43: =SUMIF('Scenario calc'!$C$127:$BJ$127,B$41,'Scenario calc'!$C$173:$BJ$173) -> -70506.807 | C43: =SUMIF('Scenario calc'!$C$127:$BJ$127,C$41,'Scenario calc'!$C$173:$BJ$173) -> 17593.913 | D43: =SUMIF('Scenario calc'!$C$127:$BJ$127,D$41,'Scenario calc'!$C$173:$BJ$173) -> 29844.776 | E43: =SUMIF('Scenario calc'!$C$127:$BJ$127,E$41,'Scenario calc'!$C$173:$BJ$173) -> 38127.44 | F43: =SUMIF('Scenario calc'!$C$127:$BJ$127,F$41,'Scenario calc'!$C$173:$BJ$173) -> 43135.578
A44: High | B44: =SUMIF('Scenario calc'!$C$247:$BJ$247,B$41,'Scenario calc'!$C$293:$BJ$293) -> 24525.921 | C44: =SUMIF('Scenario calc'!$C$247:$BJ$247,C$41,'Scenario calc'!$C$293:$BJ$293) -> 96790.692 | D44: =SUMIF('Scenario calc'!$C$247:$BJ$247,D$41,'Scenario calc'!$C$293:$BJ$293) -> 116796.85 | E44: =SUMIF('Scenario calc'!$C$247:$BJ$247,E$41,'Scenario calc'!$C$293:$BJ$293) -> 138223.04 | F44: =SUMIF('Scenario calc'!$C$247:$BJ$247,F$41,'Scenario calc'!$C$293:$BJ$293) -> 161198.89
A46: Cash at year end by year ($'000)
A47: Scenario | B47: 1 | C47: 2 | D47: 3 | E47: 4 | F47: 5
...

Sheet Break-even
A1: Startup costs, funding need and break-even | H1: =HYPERLINK("#'Cover'!A1","◂ Contents") -> ◂ Contents
A2: Live for the selected scenario. Periods are counted in months from the start of the plan.
A3: Scenario shown | B3: =CHOOSE(Dashboard!$B$4,"Low","Base","High") -> Base
A5: Startup costs & funding need (up to the lowest cash point)
A6: Lowest cash point (month #) | B6: =MATCH(MIN(Monthly!$C$89:$BJ$89),Monthly!$C$89:$BJ$89,0) -> 5
A7: Capital spending up to the lowest cash point | B7: =SUMPRODUCT(--(Monthly!$C$4:$BJ$4<=$B$6),Monthly!$C$59:$BJ$59) -> 868750
A8: Operating cash burn up to the lowest cash point | B8: =-SUMPRODUCT(--(Monthly!$C$4:$BJ$4<=$B$6),Monthly!$C$83:$BJ$83) -> 35223.235 | D8: Losses and working capital before the business funds itself
A9: Loan repayments up to the lowest cash point | B9: =-SUMPRODUCT(--(Monthly!$C$4:$BJ$4<=$B$6),Monthly!$C$70:$BJ$70) -> 3122.3623
A10: Total uses of funds | B10: =B7+B8+B9 -> 907095.6
A11: Minimum cash buffer to keep | B11: =Inputs!$E$80 -> 39000 | D11: Input on the Inputs sheet
A12: Funding required (uses + buffer) | B12: =B10+B11 -> 946095.6
A14: Equity raised | B14: =Inputs!$E$65 -> 430000
A15: Loan drawn | B15: =Inputs!$E$66 -> 500000
A16: Total sources of funds | B16: =B14+B15 -> 930000
A17: Funding surplus / (shortfall) | B17: =B16-B12 -> -16095.597 | D17: Negative = raise at least this much more
A18: Lowest cash balance in the plan | B18: =MIN(Monthly!$C$89:$BJ$89) -> 22904.403 | D18: Equals sources minus uses
A20: Break-even timing
A21: First month with positive EBITDA (month #) | B21: =IFERROR(MATCH(1,Monthly!$C$90:$BJ$90,0),"Not within horizon") -> 6
A22: First month with positive net income (month #) | B22: =IFERROR(MATCH(1,Monthly!$C$93:$BJ$93,0),"Not within horizon") -> 8
A23: Cash invested paid back (month #) | B23: =IF(MIN(Monthly!$C$95:$BJ$95)>=0,"No investment to pay back",IFERROR(MATCH(1,Monthly!$C$97:$BJ$97,0),"Not within horizon")) -> Not within horizon | D23: Cumulative operating + investing cash flow back to zero
A25: Annual break-even revenue
A26: Year # | B26: 1 | C26: 2 | D26: 3 | E26: 4 | F26: 5
B27: Year 1 | C27: Year 2 | D27: Year 3 | E27: Year 4 | F27: Year 5
A28: Revenue | B28: =SUMIF(Monthly!$C$5:$BJ$5,B$26,Monthly!$C$20:$BJ$20) -> 274944.26 | C28: =SUMIF(Monthly!$C$5:$BJ$5,C$26,Monthly!$C$20:$BJ$20) -> 396826.24 | D28: =SUMIF(Monthly!$C$5:$BJ$5,D$26,Monthly!$C$20:$BJ$20) -> 416905.65 | E28: =SUMIF(Monthly!$C$5:$BJ$5,E$26,Monthly!$C$20:$BJ$20) -> 438001.08 | F28: =SUMIF(Monthly!$C$5:$BJ$5,F$26,Monthly!$C$20:$BJ$20) -> 460163.93
A29: Gross profit | B29: =SUMIF(Monthly!$C$5:$BJ$5,B$26,Monthly!$C$29:$BJ$29) -> 165763.81 | C29: =SUMIF(Monthly!$C$5:$BJ$5,C$26,Monthly!$C$29:$BJ$29) -> 262060.42 | D29: =SUMIF(Monthly!$C$5:$BJ$5,D$26,Monthly!$C$29:$BJ$29) -> 276491.91 | E29: =SUMIF(Monthly!$C$5:$BJ$5,E$26,Monthly!$C$29:$BJ$29) -> 291688.77 | F29: =SUMIF(Monthly!$C$5:$BJ$5,F$26,Monthly!$C$29:$BJ$29) -> 307690.79
A30: Gross margin (contribution) | B30: =IF(B28=0,0,B29/B28) -> 0.6028997 | C30: =IF(C28=0,0,C29/C28) -> 0.66039085 | D30: =IF(D28=0,0,D29/D28) -> 0.6632002 | E30: =IF(E28=0,0,E29/E28) -> 0.66595446 | F30: =IF(F28=0,0,F29/F28) -> 0.66865472
A31: Operating expenses (treated as fixed) | B31: =-SUMIF(Monthly!$C$5:$BJ$5,B$26,Monthly!$C$41:$BJ$41) -> 155521.27 | C31: =-SUMIF(Monthly!$C$5:$BJ$5,C$26,Monthly!$C$41:$BJ$41) -> 163660.36 | D31: =-SUMIF(Monthly!$C$5:$BJ$5,D$26,Monthly!$C$41:$BJ$41) -> 165805.87 | E31: =-SUMIF(Monthly!$C$5:$BJ$5,E$26,Monthly!$C$41:$BJ$41) -> 168705.86 | F31: =-SUMIF(Monthly!$C$5:$BJ$5,F$26,Monthly!$C$41:$BJ$41) -> 172251.88
A32: Break-even revenue (EBITDA = 0) | B32: =IF(B30>0,B31/B30,"n/a") -> 257955.45 | C32: =IF(C30>0,C31/C30,"n/a") -> 247823.48 | D32: =IF(D30>0,D31/D30,"n/a") -> 250008.77 | E32: =IF(E30>0,E31/E30,"n/a") -> 253329.42 | F32: =IF(F30>0,F31/F30,"n/a") -> 257609.61
A33: Margin of safety (revenue above break-even) | B33: =IF(AND(ISNUMBER(B32),B28>0),(B28-B32)/B28,"n/a") -> 0.06178999 | C33: =IF(AND(ISNUMBER(C32),C28>0),(C28-C32)/C28,"n/a") -> 0.37548617 | D33: =IF(AND(ISNUMBER(D32),D28>0),(D28-D32)/D28,"n/a") -> 0.4003229 | E33: =IF(AND(ISNUMBER(E32),E28>0),(E28-E32)/E28,"n/a") -> 0.42162375 | F33: =IF(AND(ISNUMBER(F32),F28>0),(F28-F32)/F28,"n/a") -> 0.44017861
A35: Simplification: cost of sales is treated as variable and operating expenses as fixed, so break-even revenue = operating expenses ÷ gross margin.

Sheet Valuation
A1: Discounted cash flow valuation | H1: =HYPERLINK("#'Cover'!A1","◂ Contents") -> ◂ Contents
A2: Enterprise value at the start of the plan, before the funding raised in period 1. Year-end discounting.
A3: Scenario shown | B3: =CHOOSE(Dashboard!$B$4,"Low","Base","High") -> Base
A5: Assumptions (active scenario, from the Inputs sheet)
A6: Discount rate (WACC) | B6: =Inputs!$E$83 -> 0.25
A7: Terminal growth rate | B7: =Inputs!$E$84 -> 0.02
A8: Exit multiple (EV ÷ final-year EBITDA) | B8: =Inputs!$E$85 -> 4
A9: Tax rate (for the interest tax shield) | B9: =Inputs!$E$77 -> 0.21
A10: Sensitivity step: WACC | B10: =Inputs!$E$86 -> 0.01
A11: Sensitivity step: terminal growth | B11: =Inputs!$E$87 -> 0.005
A13: Free cash flow by year
A14: Year # | B14: 1 | C14: 2 | D14: 3 | E14: 4 | F14: 5
B15: Year 1 | C15: Year 2 | D15: Year 3 | E15: Year 4 | F15: Year 5
A16: EBITDA | B16: =SUMIF(Monthly!$C$5:$BJ$5,B$14,Monthly!$C$42:$BJ$42) -> 10242.544 | C16: =SUMIF(Monthly!$C$5:$BJ$5,C$14,Monthly!$C$42:$BJ$42) -> 98400.063 | D16: =SUMIF(Monthly!$C$5:$BJ$5,D$14,Monthly!$C$42:$BJ$42) -> 110686.04 | E16: =SUMIF(Monthly!$C$5:$BJ$5,E$14,Monthly!$C$42:$BJ$42) -> 122982.92 | F16: =SUMIF(Monthly!$C$5:$BJ$5,F$14,Monthly!$C$42:$BJ$42) -> 135438.9
A17: Unlevered free cash flow | B17: =SUMIF(Monthly!$C$5:$BJ$5,B$14,Monthly!$C$98:$BJ$98) -> -866414.36 | C17: =SUMIF(Monthly!$C$5:$BJ$5,C$14,Monthly!$C$98:$BJ$98) -> 82112.474 | D17: =SUMIF(Monthly!$C$5:$BJ$5,D$14,Monthly!$C$98:$BJ$98) -> 94251.153 | E17: =SUMIF(Monthly!$C$5:$BJ$5,E$14,Monthly!$C$98:$BJ$98) -> 102398.53 | F17: =SUMIF(Monthly!$C$5:$BJ$5,F$14,Monthly!$C$98:$BJ$98) -> 107246.14
A18: Discount factor | B18: =1/(1+Inputs!$E$83)^B$14 -> 0.8 | C18: =1/(1+Inputs!$E$83)^C$14 -> 0.64 | D18: =1/(1+Inputs!$E$83)^D$14 -> 0.512 | E18: =1/(1+Inputs!$E$83)^E$14 -> 0.4096 | F18: =1/(1+Inputs!$E$83)^F$14 -> 0.32768
A19: Present value of free cash flow | B19: =B17*B18 -> -693131.49 | C19: =C17*C18 -> 52551.983 | D19: =D17*D18 -> 48256.591 | E19: =E17*E18 -> 41942.437 | F19: =F17*F18 -> 35142.417
A21: Enterprise value
B22: Perpetual growth | C22: Exit multiple
A23: Present value of the plan's free cash flows | B23: =SUM($B$19:$F$19) -> -515238.06 | C23: =B23 -> -515238.06
A24: Final-year free cash flow | final-year EBITDA | B24: =$F$17 -> 107246.14 | C24: =$F$16 -> 135438.9
A25: Terminal value at the end of year 5 | B25: =IF($B$6>$B$7,B24*(1+$B$7)/($B$6-$B$7),0) -> 475613.34 | C25: =C24*$B$8 -> 541755.62
A26: Present value of the terminal value | B26: =B25/(1+$B$6)^$F$14 -> 155848.98 | C26: =C25/(1+$B$6)^$F$14 -> 177522.48
A27: Enterprise value | B27: =B23+B26 -> -359389.08 | C27: =C23+C26 -> -337715.58
A28: Terminal value share of enterprise value | B28: =IF(B27<>0,B26/B27,0) -> -0.43364973 | C28: =IF(C27<>0,C26/C27,0) -> -0.52565677
A29: Cross-check: implied exit multiple | implied perpetual growth | B29: =IF(C24>0,B25/C24,"n/a") -> 3.5116449 | C29: =IF(C25+B24<>0,(C25*$B$6-B24)/(C25+B24),"n/a") -> 0.043440189
A30: Enterprise value — average of the two methods | B30: =AVERAGE(B27,C27) -> -348552.33
A32: Sensitivity: enterprise value (perpetual growth) by WACC and terminal growth
A33: WACC ↓ · terminal growth → | B33: =$B$7+(-2)*$B$11 -> 0.01 | C33: =$B$7+(-1)*$B$11 -> 0.015 | D33: =$B$7+(0)*$B$11 -> 0.02 | E33: =$B$7+(1)*$B$11 -> 0.025 | F33: =$B$7+(2)*$B$11 -> 0.03
A34: =$B$6+(-2)*$B$10 -> 0.23 | B34: =IF($A34>B$33,SUMPRODUCT($B$17:$F$17/(1+$A34)^$B$14:$F$14)+$F$17*(1+B$33)/($A34-B$33)/(1+$A34)^$F$14,"n/a") -> -341760.45 | C34: =IF($A34>C$33,SUMPRODUCT($B$17:$F$17/(1+$A34)^$B$14:$F$14)+$F$17*(1+C$33)/($A34-C$33)/(1+$A34)^$F$14,"n/a") -> -336807.43 | D34: =IF($A34>D$33,SUMPRODUCT($B$17:$F$17/(1+$A34)^$B$14:$F$14)+$F$17*(1+D$33)/($A34-D$33)/(1+$A34)^$F$14,"n/a") -> -331618.55 | E34: =IF($A34>E$33,SUMPRODUCT($B$17:$F$17/(1+$A34)^$B$14:$F$14)+$F$17*(1+E$33)/($A34-E$33)/(1+$A34)^$F$14,"n/a") -> -326176.55 | F34: =IF($A34>F$33,SUMPRODUCT($B$17:$F$17/(1+$A34)^$B$14:$F$14)+$F$17*(1+F$33)/($A34-F$33)/(1+$A34)^$F$14,"n/a") -> -320462.46
A35: =$B$6+(-1)*$B$10 -> 0.24 | B35: =IF($A35>B$33,SUMPRODUCT($B$17:$F$17/(1+$A35)^$B$14:$F$14)+$F$17*(1+B$33)/($A35-B$33)/(1+$A35)^$F$14,"n/a") -> -355345.5 | C35: =IF($A35>C$33,SUMPRODUCT($B$17:$F$17/(1+$A35)^$B$14:$F$14)+$F$17*(1+C$33)/($A35-C$33)/(1+$A35)^$F$14,"n/a") -> -350962.67 | D35: =IF($A35>D$33,SUMPRODUCT($B$17:$F$17/(1+$A35)^$B$14:$F$14)+$F$17*(1+D$33)/($A35-D$33)/(1+$A35)^$F$14,"n/a") -> -346380.62 | E35: =IF($A35>E$33,SUMPRODUCT($B$17:$F$17/(1+$A35)^$B$14:$F$14)+$F$17*(1+E$33)/($A35-E$33)/(1+$A35)^$F$14,"n/a") -> -341585.46 | F35: =IF($A35>F$33,SUMPRODUCT($B$17:$F$17/(1+$A35)^$B$14:$F$14)+$F$17*(1+F$33)/($A35-F$33)/(1+$A35)^$F$14,"n/a") -> -336561.95
