Workbook

Sheet Cover
B2: Home services financial model (growing)
B3: 3-year financial model · monthly detail · Low / Base / High scenarios · US dollars · Full plan
B5: Purpose | D5: Revenue and profit plan
B6: Active scenario | D6: =Dashboard!C4&" (change it on the Dashboard, cell B4)" -> Base (change it on the Dashboard, cell B4)
B7: Model checks | D7: =Checks!B25 -> PASS
B8: Prepared | D8: 22 October 2026
B10: Contents
C11: PRESENTATION
B12: 1 | C12: =HYPERLINK("#Dashboard!A1","Dashboard") -> Dashboard | D12: Scenario switch, key numbers, core financials
B13: 2 | C13: =HYPERLINK("#Summary!A1","Summary") -> Summary | D13: Income statement, cash flow and balance sheet — every year and any year by month
B14: 3 | C14: =HYPERLINK("#Scenarios!A1","Scenarios") -> Scenarios | D14: Low / Base / High side by side: drivers, outputs, charts
B15: 4 | C15: =HYPERLINK("#'Break-even'!A1","Break-even") -> Break-even | D15: Startup costs, funding need, break-even timing and revenue
B16: 5 | C16: =HYPERLINK("#Valuation!A1","Valuation") -> Valuation | D16: Free cash flow, DCF (perpetual growth and exit multiple), WACC × growth sensitivity
B17: 6 | C17: =HYPERLINK("#'Sources & Uses'!A1","Sources & Uses") -> Sources & Uses | D17: Funding structure, sources and uses of cash for the first months
B18: 7 | C18: =HYPERLINK("#KPIs!A1","KPIs") -> KPIs | D18: Financial ratios, DuPont analysis, industry metrics
C19: INPUTS
B20: 8 | C20: =HYPERLINK("#Inputs!A1","Inputs") -> Inputs | D20: Every assumption, Low / Base / High, with units and comments
C21: STATEMENTS
B22: 9 | C22: =HYPERLINK("#'P&L'!A1","P&L") -> P&L | D22: Annual profit & loss
B23: 10 | C23: =HYPERLINK("#'Cash Flow'!A1","Cash Flow") -> Cash Flow | D23: Annual cash flow statement
B24: 11 | C24: =HYPERLINK("#'Balance Sheet'!A1","Balance Sheet") -> Balance Sheet | D24: Balance sheet at year end
C25: CALCULATIONS
B26: 12 | C26: =HYPERLINK("#Monthly!A1","Monthly") -> Monthly | D26: Month-by-month engine of the model
B27: 13 | C27: =HYPERLINK("#Headcount!A1","Headcount") -> Headcount | D27: Team and payroll
B28: 14 | C28: =HYPERLINK("#'Scenario calc'!A1","Scenario calc") -> Scenario calc | D28: Low, Base and High calculated side by side for the Scenarios sheet
C29: CONTROL
B30: 15 | C30: =HYPERLINK("#Checks!A1","Checks") -> Checks | D30: Live integrity checks and the overall verdict
B32: How to read this file
C33: 1000 | D33: Input you can change — yellow cell with a blue figure (Inputs sheet and the view switches)
C34: 1000 | D34: Formula — calculated, do not overwrite
C35: 1000 | D35: Link to another sheet
C36: 1000 | D36: Active value the model uses (follows the scenario)

Sheet Dashboard
A1: Dashboard | W1: =HYPERLINK("#'Cover'!A1","◂ Contents") -> ◂ Contents
A2: Home services financial model (growing)
A4: Active scenario | B4: 2 | C4: =CHOOSE(B4,"Low","Base","High") -> Base | D4: 1 = Low · 2 = Base · 3 = High — every sheet follows this cell | S4: Model checks | T4: =Checks!B25 -> PASS
A6: REVENUE · YEAR 3 | C6: EBITDA MARGIN · YEAR 3 | H6: NET INCOME · YEAR 3 | L6: LOWEST CASH BALANCE | P6: FUNDING REQUIRED | T6: ENTERPRISE VALUE (DCF)
A7: =D12 -> 2376160.7 | C7: =D17 -> 0.2021959 | H7: =D18 -> 355570.65 | L7: =F38 -> 339238.12 | P7: =F36 -> 108761.88 | T7: =F43 -> 2205569.6
A8: =IF(AND(B12>0,D12>=0),(D12/B12)^(1/2)-1,"CAGR n/a") -> 0.17878891 | C8: =D16 -> 480449.96 | H8: =D19 -> 0.14964082 | L8: ='Break-even'!B6 -> 1 | P8: =IF(F37>=0,"Covered by funding raised",-F37) -> Covered by funding raised | T8: Average of 2 methods
A10: Core financials ($'000) — active scenario
B11: 1 | C11: 2 | D11: 3
A12: Revenue | B12: =SUMIF(Monthly!$C$5:$AL$5,B$11,Monthly!$C$22:$AL$22) -> 1710030 | C12: =SUMIF(Monthly!$C$5:$AL$5,C$11,Monthly!$C$22:$AL$22) -> 2015484.9 | D12: =SUMIF(Monthly!$C$5:$AL$5,D$11,Monthly!$C$22:$AL$22) -> 2376160.7
A13: Gross profit | B13: =SUMIF(Monthly!$C$5:$AL$5,B$11,Monthly!$C$30:$AL$30) -> 659822.5 | C13: =SUMIF(Monthly!$C$5:$AL$5,C$11,Monthly!$C$30:$AL$30) -> 795749.55 | D13: =SUMIF(Monthly!$C$5:$AL$5,D$11,Monthly!$C$30:$AL$30) -> 958942.46
A14: Gross margin | B14: =IF(B12=0,0,B13/B12) -> 0.38585434 | C14: =IF(C12=0,0,C13/C12) -> 0.39481791 | D14: =IF(D12=0,0,D13/D12) -> 0.40356802
A15: Operating expenses | B15: =SUMIF(Monthly!$C$5:$AL$5,B$11,Monthly!$C$40:$AL$40) -> -393750.81 | C15: =SUMIF(Monthly!$C$5:$AL$5,C$11,Monthly!$C$40:$AL$40) -> -433173.19 | D15: =SUMIF(Monthly!$C$5:$AL$5,D$11,Monthly!$C$40:$AL$40) -> -478492.5
A16: EBITDA | B16: =SUMIF(Monthly!$C$5:$AL$5,B$11,Monthly!$C$41:$AL$41) -> 266071.69 | C16: =SUMIF(Monthly!$C$5:$AL$5,C$11,Monthly!$C$41:$AL$41) -> 362576.36 | D16: =SUMIF(Monthly!$C$5:$AL$5,D$11,Monthly!$C$41:$AL$41) -> 480449.96
A17: EBITDA margin | B17: =IF(B12=0,0,B16/B12) -> 0.15559475 | C17: =IF(C12=0,0,C16/C12) -> 0.17989534 | D17: =IF(D12=0,0,D16/D12) -> 0.2021959
A18: Net income | B18: =SUMIF(Monthly!$C$5:$AL$5,B$11,Monthly!$C$50:$AL$50) -> 192564.27 | C18: =SUMIF(Monthly!$C$5:$AL$5,C$11,Monthly!$C$50:$AL$50) -> 265979.59 | D18: =SUMIF(Monthly!$C$5:$AL$5,D$11,Monthly!$C$50:$AL$50) -> 355570.65
A19: Net margin | B19: =IF(B12=0,0,B18/B12) -> 0.11260871 | C19: =IF(C12=0,0,C18/C12) -> 0.13196803 | D19: =IF(D12=0,0,D18/D12) -> 0.14964082
A20: Operating cash flow | B20: =SUMIF(Monthly!$C$5:$AL$5,B$11,Monthly!$C$74:$AL$74) -> 194710.8 | C20: =SUMIF(Monthly!$C$5:$AL$5,C$11,Monthly!$C$74:$AL$74) -> 276206.62 | D20: =SUMIF(Monthly!$C$5:$AL$5,D$11,Monthly!$C$74:$AL$74) -> 373872.07
A21: Investing cash flow | B21: =SUMIF(Monthly!$C$5:$AL$5,B$11,Monthly!$C$75:$AL$75) -> -20000 | C21: =SUMIF(Monthly!$C$5:$AL$5,C$11,Monthly!$C$75:$AL$75) -> -37800 | D21: =SUMIF(Monthly!$C$5:$AL$5,D$11,Monthly!$C$75:$AL$75) -> -42336
A22: Financing cash flow | B22: =SUMIF(Monthly!$C$5:$AL$5,B$11,Monthly!$C$77:$AL$77) -> 304166.67 | C22: =SUMIF(Monthly!$C$5:$AL$5,C$11,Monthly!$C$77:$AL$77) -> -50000 | D22: =SUMIF(Monthly!$C$5:$AL$5,D$11,Monthly!$C$77:$AL$77) -> -50000
A23: Net change in cash | B23: =SUMIF(Monthly!$C$5:$AL$5,B$11,Monthly!$C$78:$AL$78) -> 478877.47 | C23: =SUMIF(Monthly!$C$5:$AL$5,C$11,Monthly!$C$78:$AL$78) -> 188406.62 | D23: =SUMIF(Monthly!$C$5:$AL$5,D$11,Monthly!$C$78:$AL$78) -> 281536.07
A24: Year-end cash | B24: =INDEX(Monthly!$C$80:$AL$80,B$11*12) -> 478877.47 | C24: =INDEX(Monthly!$C$80:$AL$80,C$11*12) -> 667284.09 | D24: =INDEX(Monthly!$C$80:$AL$80,D$11*12) -> 948820.16
A26: Home services metrics
B27: 1 | C27: 2 | D27: 3
A28: Jobs completed | B28: =KPIs!B32 -> 3668.25 | C28: =KPIs!C32 -> 4185.4125 | D28: =KPIs!D32 -> 4776.1804
A29: Technician utilisation | B29: =KPIs!B33 -> 0.83180272 | C29: =KPIs!C33 -> 0.84738672 | D29: =KPIs!D33 -> 0.86338815
A30: Average revenue per job | B30: =KPIs!B40 -> 440 | C30: =KPIs!C40 -> 453.2 | D30: =KPIs!D40 -> 466.796
A31: Team (FTE, year end) | B31: =INDEX(Headcount!$C$10:$AL$10,B$27*12) -> 9 | C31: =INDEX(Headcount!$C$10:$AL$10,C$27*12) -> 10.04 | D31: =INDEX(Headcount!$C$10:$AL$10,D$27*12) -> 11.2008
A33: Funding & valuation ($'000) — active scenario
A34: Equity raised | F34: =Inputs!$E$54 -> 100000
A35: Loan drawn | F35: =Inputs!$E$55 -> 250000
A36: Funding required (incl. cash buffer) | F36: ='Break-even'!B12 -> 108761.88
A37: Funding surplus / (shortfall) | F37: ='Break-even'!B17 -> 241238.12
A38: ="Lowest cash balance (month "&'Break-even'!B6&")" -> Lowest cash balance (month 1) | F38: ='Break-even'!B18 -> 339238.12
A39: First month with positive EBITDA | F39: ='Break-even'!B21 -> 1
A40: Cash invested paid back | F40: ='Break-even'!B23 -> 2
A41: Enterprise value — perpetual growth | F41: =Valuation!B27 -> 2151907.5
A42: Enterprise value — exit multiple | F42: =Valuation!C27 -> 2259231.7
A43: Enterprise value — average | F43: =Valuation!B30 -> 2205569.6

Sheet Summary
A1: Financial statements summary | U1: =HYPERLINK("#'Cover'!A1","◂ Contents") -> ◂ Contents
A2: Home services financial model (growing) | P2: Select detailed year: | R2: 1
A5: Income statement ($'000) — by year | H5: ="Income statement ($'000) — Year "&$R$2&", by month" -> Income statement ($'000) — Year 1, by month
B6: 1 | C6: 2 | D6: 3 | H6: =INDEX(Monthly!$C$4:$AL$4,($R$2-1)*12+1) -> 1 | I6: =INDEX(Monthly!$C$4:$AL$4,($R$2-1)*12+2) -> 2 | J6: =INDEX(Monthly!$C$4:$AL$4,($R$2-1)*12+3) -> 3 | K6: =INDEX(Monthly!$C$4:$AL$4,($R$2-1)*12+4) -> 4 | L6: =INDEX(Monthly!$C$4:$AL$4,($R$2-1)*12+5) -> 5 | M6: =INDEX(Monthly!$C$4:$AL$4,($R$2-1)*12+6) -> 6 | N6: =INDEX(Monthly!$C$4:$AL$4,($R$2-1)*12+7) -> 7 | O6: =INDEX(Monthly!$C$4:$AL$4,($R$2-1)*12+8) -> 8 | P6: =INDEX(Monthly!$C$4:$AL$4,($R$2-1)*12+9) -> 9 | Q6: =INDEX(Monthly!$C$4:$AL$4,($R$2-1)*12+10) -> 10 | R6: =INDEX(Monthly!$C$4:$AL$4,($R$2-1)*12+11) -> 11 | S6: =INDEX(Monthly!$C$4:$AL$4,($R$2-1)*12+12) -> 12
A7: Revenue | B7: ='P&L'!B5 -> 1710030 | C7: ='P&L'!C5 -> 2015484.9 | D7: ='P&L'!D5 -> 2376160.7 | H7: =INDEX(Monthly!$C$22:$AL$22,($R$2-1)*12+1) -> 133436.67 | I7: =INDEX(Monthly!$C$22:$AL$22,($R$2-1)*12+2) -> 133436.67 | J7: =INDEX(Monthly!$C$22:$AL$22,($R$2-1)*12+3) -> 133436.67 | K7: =INDEX(Monthly!$C$22:$AL$22,($R$2-1)*12+4) -> 133436.67 | L7: =INDEX(Monthly!$C$22:$AL$22,($R$2-1)*12+5) -> 133436.67 | M7: =INDEX(Monthly!$C$22:$AL$22,($R$2-1)*12+6) -> 169700 | N7: =INDEX(Monthly!$C$22:$AL$22,($R$2-1)*12+7) -> 169700 | O7: =INDEX(Monthly!$C$22:$AL$22,($R$2-1)*12+8) -> 169700 | P7: =INDEX(Monthly!$C$22:$AL$22,($R$2-1)*12+9) -> 133436.67 | Q7: =INDEX(Monthly!$C$22:$AL$22,($R$2-1)*12+10) -> 133436.67 | R7: =INDEX(Monthly!$C$22:$AL$22,($R$2-1)*12+11) -> 133436.67 | S7: =INDEX(Monthly!$C$22:$AL$22,($R$2-1)*12+12) -> 133436.67
A8: Cost of delivery | B8: ='P&L'!B6 -> -1050207.5 | C8: ='P&L'!C6 -> -1219735.4 | D8: ='P&L'!D6 -> -1417218.2 | H8: =INDEX(Monthly!$C$29:$AL$29,($R$2-1)*12+1) -> -85250.833 | I8: =INDEX(Monthly!$C$29:$AL$29,($R$2-1)*12+2) -> -85250.833 | J8: =INDEX(Monthly!$C$29:$AL$29,($R$2-1)*12+3) -> -85250.833 | K8: =INDEX(Monthly!$C$29:$AL$29,($R$2-1)*12+4) -> -85250.833 | L8: =INDEX(Monthly!$C$29:$AL$29,($R$2-1)*12+5) -> -85250.833 | M8: =INDEX(Monthly!$C$29:$AL$29,($R$2-1)*12+6) -> -94316.667 | N8: =INDEX(Monthly!$C$29:$AL$29,($R$2-1)*12+7) -> -94316.667 | O8: =INDEX(Monthly!$C$29:$AL$29,($R$2-1)*12+8) -> -94316.667 | P8: =INDEX(Monthly!$C$29:$AL$29,($R$2-1)*12+9) -> -85250.833 | Q8: =INDEX(Monthly!$C$29:$AL$29,($R$2-1)*12+10) -> -85250.833 | R8: =INDEX(Monthly!$C$29:$AL$29,($R$2-1)*12+11) -> -85250.833 | S8: =INDEX(Monthly!$C$29:$AL$29,($R$2-1)*12+12) -> -85250.833
A9: Gross profit | B9: ='P&L'!B7 -> 659822.5 | C9: ='P&L'!C7 -> 795749.55 | D9: ='P&L'!D7 -> 958942.46 | H9: =INDEX(Monthly!$C$30:$AL$30,($R$2-1)*12+1) -> 48185.833 | I9: =INDEX(Monthly!$C$30:$AL$30,($R$2-1)*12+2) -> 48185.833 | J9: =INDEX(Monthly!$C$30:$AL$30,($R$2-1)*12+3) -> 48185.833 | K9: =INDEX(Monthly!$C$30:$AL$30,($R$2-1)*12+4) -> 48185.833 | L9: =INDEX(Monthly!$C$30:$AL$30,($R$2-1)*12+5) -> 48185.833 | M9: =INDEX(Monthly!$C$30:$AL$30,($R$2-1)*12+6) -> 75383.333 | N9: =INDEX(Monthly!$C$30:$AL$30,($R$2-1)*12+7) -> 75383.333 | O9: =INDEX(Monthly!$C$30:$AL$30,($R$2-1)*12+8) -> 75383.333 | P9: =INDEX(Monthly!$C$30:$AL$30,($R$2-1)*12+9) -> 48185.833 | Q9: =INDEX(Monthly!$C$30:$AL$30,($R$2-1)*12+10) -> 48185.833 | R9: =INDEX(Monthly!$C$30:$AL$30,($R$2-1)*12+11) -> 48185.833 | S9: =INDEX(Monthly!$C$30:$AL$30,($R$2-1)*12+12) -> 48185.833
A10: Gross margin | B10: ='P&L'!B8 -> 0.38585434 | C10: ='P&L'!C8 -> 0.39481791 | D10: ='P&L'!D8 -> 0.40356802 | H10: =IF(H7=0,0,H9/H7) -> 0.36111389 | I10: =IF(I7=0,0,I9/I7) -> 0.36111389 | J10: =IF(J7=0,0,J9/J7) -> 0.36111389 | K10: =IF(K7=0,0,K9/K7) -> 0.36111389 | L10: =IF(L7=0,0,L9/L7) -> 0.36111389 | M10: =IF(M7=0,0,M9/M7) -> 0.44421528 | N10: =IF(N7=0,0,N9/N7) -> 0.44421528 | O10: =IF(O7=0,0,O9/O7) -> 0.44421528 | ... S10: =IF(S7=0,0,S9/S7) -> 0.36111389
A11: Total operating expenses | B11: ='P&L'!B16 -> -393750.81 | C11: ='P&L'!C16 -> -433173.19 | D11: ='P&L'!D16 -> -478492.5 | H11: =INDEX(Monthly!$C$40:$AL$40,($R$2-1)*12+1) -> -32567.79 | I11: =INDEX(Monthly!$C$40:$AL$40,($R$2-1)*12+2) -> -32567.79 | J11: =INDEX(Monthly!$C$40:$AL$40,($R$2-1)*12+3) -> -32567.79 | K11: =INDEX(Monthly!$C$40:$AL$40,($R$2-1)*12+4) -> -32567.79 | L11: =INDEX(Monthly!$C$40:$AL$40,($R$2-1)*12+5) -> -32567.79 | M11: =INDEX(Monthly!$C$40:$AL$40,($R$2-1)*12+6) -> -33546.9 | N11: =INDEX(Monthly!$C$40:$AL$40,($R$2-1)*12+7) -> -33546.9 | O11: =INDEX(Monthly!$C$40:$AL$40,($R$2-1)*12+8) -> -33546.9 | P11: =INDEX(Monthly!$C$40:$AL$40,($R$2-1)*12+9) -> -32567.79 | Q11: =INDEX(Monthly!$C$40:$AL$40,($R$2-1)*12+10) -> -32567.79 | R11: =INDEX(Monthly!$C$40:$AL$40,($R$2-1)*12+11) -> -32567.79 | S11: =INDEX(Monthly!$C$40:$AL$40,($R$2-1)*12+12) -> -32567.79
A12: EBITDA | B12: ='P&L'!B17 -> 266071.69 | C12: ='P&L'!C17 -> 362576.36 | D12: ='P&L'!D17 -> 480449.96 | H12: =INDEX(Monthly!$C$41:$AL$41,($R$2-1)*12+1) -> 15618.043 | I12: =INDEX(Monthly!$C$41:$AL$41,($R$2-1)*12+2) -> 15618.043 | J12: =INDEX(Monthly!$C$41:$AL$41,($R$2-1)*12+3) -> 15618.043 | K12: =INDEX(Monthly!$C$41:$AL$41,($R$2-1)*12+4) -> 15618.043 | L12: =INDEX(Monthly!$C$41:$AL$41,($R$2-1)*12+5) -> 15618.043 | M12: =INDEX(Monthly!$C$41:$AL$41,($R$2-1)*12+6) -> 41836.433 | N12: =INDEX(Monthly!$C$41:$AL$41,($R$2-1)*12+7) -> 41836.433 | O12: =INDEX(Monthly!$C$41:$AL$41,($R$2-1)*12+8) -> 41836.433 | P12: =INDEX(Monthly!$C$41:$AL$41,($R$2-1)*12+9) -> 15618.043 | Q12: =INDEX(Monthly!$C$41:$AL$41,($R$2-1)*12+10) -> 15618.043 | R12: =INDEX(Monthly!$C$41:$AL$41,($R$2-1)*12+11) -> 15618.043 | S12: =INDEX(Monthly!$C$41:$AL$41,($R$2-1)*12+12) -> 15618.043
A13: EBITDA margin | B13: ='P&L'!B18 -> 0.15559475 | C13: ='P&L'!C18 -> 0.17989534 | D13: ='P&L'!D18 -> 0.2021959 | H13: =IF(H7=0,0,H12/H7) -> 0.11704462 | I13: =IF(I7=0,0,I12/I7) -> 0.11704462 | J13: =IF(J7=0,0,J12/J7) -> 0.11704462 | K13: =IF(K7=0,0,K12/K7) -> 0.11704462 | L13: =IF(L7=0,0,L12/L7) -> 0.11704462 | M13: =IF(M7=0,0,M12/M7) -> 0.24653172 | N13: =IF(N7=0,0,N12/N7) -> 0.24653172 | O13: =IF(O7=0,0,O12/O7) -> 0.24653172 | ... S13: =IF(S7=0,0,S12/S7) -> 0.11704462
A14: Depreciation | B14: ='P&L'!B19 -> -4000 | C14: ='P&L'!C19 -> -11560 | D14: ='P&L'!D19 -> -20027.2 | H14: =INDEX(Monthly!$C$55:$AL$55,($R$2-1)*12+1) -> -333.33333 | I14: =INDEX(Monthly!$C$55:$AL$55,($R$2-1)*12+2) -> -333.33333 | J14: =INDEX(Monthly!$C$55:$AL$55,($R$2-1)*12+3) -> -333.33333 | K14: =INDEX(Monthly!$C$55:$AL$55,($R$2-1)*12+4) -> -333.33333 | L14: =INDEX(Monthly!$C$55:$AL$55,($R$2-1)*12+5) -> -333.33333 | M14: =INDEX(Monthly!$C$55:$AL$55,($R$2-1)*12+6) -> -333.33333 | N14: =INDEX(Monthly!$C$55:$AL$55,($R$2-1)*12+7) -> -333.33333 | O14: =INDEX(Monthly!$C$55:$AL$55,($R$2-1)*12+8) -> -333.33333 | P14: =INDEX(Monthly!$C$55:$AL$55,($R$2-1)*12+9) -> -333.33333 | Q14: =INDEX(Monthly!$C$55:$AL$55,($R$2-1)*12+10) -> -333.33333 | R14: =INDEX(Monthly!$C$55:$AL$55,($R$2-1)*12+11) -> -333.33333 | S14: =INDEX(Monthly!$C$55:$AL$55,($R$2-1)*12+12) -> -333.33333
A15: EBIT | B15: ='P&L'!B20 -> 262071.69 | C15: ='P&L'!C20 -> 351016.36 | D15: ='P&L'!D20 -> 460422.76 | H15: =INDEX(Monthly!$C$44:$AL$44,($R$2-1)*12+1) -> 15284.71 | I15: =INDEX(Monthly!$C$44:$AL$44,($R$2-1)*12+2) -> 15284.71 | J15: =INDEX(Monthly!$C$44:$AL$44,($R$2-1)*12+3) -> 15284.71 | K15: =INDEX(Monthly!$C$44:$AL$44,($R$2-1)*12+4) -> 15284.71 | L15: =INDEX(Monthly!$C$44:$AL$44,($R$2-1)*12+5) -> 15284.71 | M15: =INDEX(Monthly!$C$44:$AL$44,($R$2-1)*12+6) -> 41503.1 | N15: =INDEX(Monthly!$C$44:$AL$44,($R$2-1)*12+7) -> 41503.1 | O15: =INDEX(Monthly!$C$44:$AL$44,($R$2-1)*12+8) -> 41503.1 | P15: =INDEX(Monthly!$C$44:$AL$44,($R$2-1)*12+9) -> 15284.71 | Q15: =INDEX(Monthly!$C$44:$AL$44,($R$2-1)*12+10) -> 15284.71 | R15: =INDEX(Monthly!$C$44:$AL$44,($R$2-1)*12+11) -> 15284.71 | S15: =INDEX(Monthly!$C$44:$AL$44,($R$2-1)*12+12) -> 15284.71
A16: Interest | B16: ='P&L'!B21 -> -18319.444 | C16: ='P&L'!C21 -> -14333.333 | D16: ='P&L'!D21 -> -10333.333 | H16: =INDEX(Monthly!$C$45:$AL$45,($R$2-1)*12+1) -> -1666.6667 | I16: =INDEX(Monthly!$C$45:$AL$45,($R$2-1)*12+2) -> -1652.7778 | J16: =INDEX(Monthly!$C$45:$AL$45,($R$2-1)*12+3) -> -1625 | K16: =INDEX(Monthly!$C$45:$AL$45,($R$2-1)*12+4) -> -1597.2222 | L16: =INDEX(Monthly!$C$45:$AL$45,($R$2-1)*12+5) -> -1569.4444 | M16: =INDEX(Monthly!$C$45:$AL$45,($R$2-1)*12+6) -> -1541.6667 | N16: =INDEX(Monthly!$C$45:$AL$45,($R$2-1)*12+7) -> -1513.8889 | O16: =INDEX(Monthly!$C$45:$AL$45,($R$2-1)*12+8) -> -1486.1111 | P16: =INDEX(Monthly!$C$45:$AL$45,($R$2-1)*12+9) -> -1458.3333 | Q16: =INDEX(Monthly!$C$45:$AL$45,($R$2-1)*12+10) -> -1430.5556 | R16: =INDEX(Monthly!$C$45:$AL$45,($R$2-1)*12+11) -> -1402.7778 | S16: =INDEX(Monthly!$C$45:$AL$45,($R$2-1)*12+12) -> -1375
A17: Pre-tax income | B17: ='P&L'!B22 -> 243752.25 | C17: ='P&L'!C22 -> 336683.02 | D17: ='P&L'!D22 -> 450089.43 | H17: =INDEX(Monthly!$C$46:$AL$46,($R$2-1)*12+1) -> 13618.043 | I17: =INDEX(Monthly!$C$46:$AL$46,($R$2-1)*12+2) -> 13631.932 | J17: =INDEX(Monthly!$C$46:$AL$46,($R$2-1)*12+3) -> 13659.71 | K17: =INDEX(Monthly!$C$46:$AL$46,($R$2-1)*12+4) -> 13687.488 | L17: =INDEX(Monthly!$C$46:$AL$46,($R$2-1)*12+5) -> 13715.266 | M17: =INDEX(Monthly!$C$46:$AL$46,($R$2-1)*12+6) -> 39961.433 | N17: =INDEX(Monthly!$C$46:$AL$46,($R$2-1)*12+7) -> 39989.211 | O17: =INDEX(Monthly!$C$46:$AL$46,($R$2-1)*12+8) -> 40016.989 | P17: =INDEX(Monthly!$C$46:$AL$46,($R$2-1)*12+9) -> 13826.377 | Q17: =INDEX(Monthly!$C$46:$AL$46,($R$2-1)*12+10) -> 13854.154 | R17: =INDEX(Monthly!$C$46:$AL$46,($R$2-1)*12+11) -> 13881.932 | S17: =INDEX(Monthly!$C$46:$AL$46,($R$2-1)*12+12) -> 13909.71
A18: Income tax | B18: ='P&L'!B23 -> -51187.972 | C18: ='P&L'!C23 -> -70703.435 | D18: ='P&L'!D23 -> -94518.78 | H18: =INDEX(Monthly!$C$49:$AL$49,($R$2-1)*12+1) -> -2859.7891 | I18: =INDEX(Monthly!$C$49:$AL$49,($R$2-1)*12+2) -> -2862.7058 | J18: =INDEX(Monthly!$C$49:$AL$49,($R$2-1)*12+3) -> -2868.5391 | K18: =INDEX(Monthly!$C$49:$AL$49,($R$2-1)*12+4) -> -2874.3724 | L18: =INDEX(Monthly!$C$49:$AL$49,($R$2-1)*12+5) -> -2880.2058 | M18: =INDEX(Monthly!$C$49:$AL$49,($R$2-1)*12+6) -> -8391.901 | N18: =INDEX(Monthly!$C$49:$AL$49,($R$2-1)*12+7) -> -8397.7343 | O18: =INDEX(Monthly!$C$49:$AL$49,($R$2-1)*12+8) -> -8403.5677 | P18: =INDEX(Monthly!$C$49:$AL$49,($R$2-1)*12+9) -> -2903.5391 | Q18: =INDEX(Monthly!$C$49:$AL$49,($R$2-1)*12+10) -> -2909.3724 | R18: =INDEX(Monthly!$C$49:$AL$49,($R$2-1)*12+11) -> -2915.2058 | S18: =INDEX(Monthly!$C$49:$AL$49,($R$2-1)*12+12) -> -2921.0391
A19: Net income | B19: ='P&L'!B24 -> 192564.27 | C19: ='P&L'!C24 -> 265979.59 | D19: ='P&L'!D24 -> 355570.65 | H19: =INDEX(Monthly!$C$50:$AL$50,($R$2-1)*12+1) -> 10758.254 | I19: =INDEX(Monthly!$C$50:$AL$50,($R$2-1)*12+2) -> 10769.226 | J19: =INDEX(Monthly!$C$50:$AL$50,($R$2-1)*12+3) -> 10791.171 | K19: =INDEX(Monthly!$C$50:$AL$50,($R$2-1)*12+4) -> 10813.115 | L19: =INDEX(Monthly!$C$50:$AL$50,($R$2-1)*12+5) -> 10835.06 | M19: =INDEX(Monthly!$C$50:$AL$50,($R$2-1)*12+6) -> 31569.532 | N19: =INDEX(Monthly!$C$50:$AL$50,($R$2-1)*12+7) -> 31591.477 | O19: =INDEX(Monthly!$C$50:$AL$50,($R$2-1)*12+8) -> 31613.421 | P19: =INDEX(Monthly!$C$50:$AL$50,($R$2-1)*12+9) -> 10922.838 | Q19: =INDEX(Monthly!$C$50:$AL$50,($R$2-1)*12+10) -> 10944.782 | R19: =INDEX(Monthly!$C$50:$AL$50,($R$2-1)*12+11) -> 10966.726 | S19: =INDEX(Monthly!$C$50:$AL$50,($R$2-1)*12+12) -> 10988.671
A20: Net margin | B20: ='P&L'!B25 -> 0.11260871 | C20: ='P&L'!C25 -> 0.13196803 | D20: ='P&L'!D25 -> 0.14964082 | H20: =IF(H7=0,0,H19/H7) -> 0.080624423 | I20: =IF(I7=0,0,I19/I7) -> 0.080706651 | J20: =IF(J7=0,0,J19/J7) -> 0.080871107 | K20: =IF(K7=0,0,K19/K7) -> 0.081035563 | L20: =IF(L7=0,0,L19/L7) -> 0.081200018 | M20: =IF(M7=0,0,M19/M7) -> 0.18603142 | N20: =IF(N7=0,0,N19/N7) -> 0.18616074 | O20: =IF(O7=0,0,O19/O7) -> 0.18629005 | ... S20: =IF(S7=0,0,S19/S7) -> 0.08235121
A22: Cash flow ($'000) — by year | H22: ="Cash flow ($'000) — Year "&$R$2&", by month" -> Cash flow ($'000) — Year 1, by month
B23: 1 | C23: 2 | D23: 3 | H23: =INDEX(Monthly!$C$4:$AL$4,($R$2-1)*12+1) -> 1 | I23: =INDEX(Monthly!$C$4:$AL$4,($R$2-1)*12+2) -> 2 | J23: =INDEX(Monthly!$C$4:$AL$4,($R$2-1)*12+3) -> 3 | K23: =INDEX(Monthly!$C$4:$AL$4,($R$2-1)*12+4) -> 4 | L23: =INDEX(Monthly!$C$4:$AL$4,($R$2-1)*12+5) -> 5 | M23: =INDEX(Monthly!$C$4:$AL$4,($R$2-1)*12+6) -> 6 | N23: =INDEX(Monthly!$C$4:$AL$4,($R$2-1)*12+7) -> 7 | O23: =INDEX(Monthly!$C$4:$AL$4,($R$2-1)*12+8) -> 8 | P23: =INDEX(Monthly!$C$4:$AL$4,($R$2-1)*12+9) -> 9 | Q23: =INDEX(Monthly!$C$4:$AL$4,($R$2-1)*12+10) -> 10 | R23: =INDEX(Monthly!$C$4:$AL$4,($R$2-1)*12+11) -> 11 | S23: =INDEX(Monthly!$C$4:$AL$4,($R$2-1)*12+12) -> 12
A24: Operating cash flow | B24: ='Cash Flow'!B10 -> 194710.8 | C24: ='Cash Flow'!C10 -> 276206.62 | D24: ='Cash Flow'!D10 -> 373872.07 | H24: =INDEX(Monthly!$C$74:$AL$74,($R$2-1)*12+1) -> 9238.1153 | I24: =INDEX(Monthly!$C$74:$AL$74,($R$2-1)*12+2) -> 11102.56 | J24: =INDEX(Monthly!$C$74:$AL$74,($R$2-1)*12+3) -> 11124.504 | K24: =INDEX(Monthly!$C$74:$AL$74,($R$2-1)*12+4) -> 11146.449 | L24: =INDEX(Monthly!$C$74:$AL$74,($R$2-1)*12+5) -> 11168.393 | M24: =INDEX(Monthly!$C$74:$AL$74,($R$2-1)*12+6) -> 24348.005 | N24: =INDEX(Monthly!$C$74:$AL$74,($R$2-1)*12+7) -> 31924.81 | O24: =INDEX(Monthly!$C$74:$AL$74,($R$2-1)*12+8) -> 31946.755 | P24: =INDEX(Monthly!$C$74:$AL$74,($R$2-1)*12+9) -> 18811.032 | Q24: =INDEX(Monthly!$C$74:$AL$74,($R$2-1)*12+10) -> 11278.115 | R24: =INDEX(Monthly!$C$74:$AL$74,($R$2-1)*12+11) -> 11300.06 | S24: =INDEX(Monthly!$C$74:$AL$74,($R$2-1)*12+12) -> 11322.004
A25: Capital spending | B25: ='Cash Flow'!B11 -> -20000 | C25: ='Cash Flow'!C11 -> -37800 | D25: ='Cash Flow'!D11 -> -42336 | H25: =INDEX(Monthly!$C$75:$AL$75,($R$2-1)*12+1) -> -20000 | I25: =INDEX(Monthly!$C$75:$AL$75,($R$2-1)*12+2) -> 0 | J25: =INDEX(Monthly!$C$75:$AL$75,($R$2-1)*12+3) -> 0 | K25: =INDEX(Monthly!$C$75:$AL$75,($R$2-1)*12+4) -> 0 | L25: =INDEX(Monthly!$C$75:$AL$75,($R$2-1)*12+5) -> 0 | M25: =INDEX(Monthly!$C$75:$AL$75,($R$2-1)*12+6) -> 0 | N25: =INDEX(Monthly!$C$75:$AL$75,($R$2-1)*12+7) -> 0 | O25: =INDEX(Monthly!$C$75:$AL$75,($R$2-1)*12+8) -> 0 | P25: =INDEX(Monthly!$C$75:$AL$75,($R$2-1)*12+9) -> 0 | Q25: =INDEX(Monthly!$C$75:$AL$75,($R$2-1)*12+10) -> 0 | R25: =INDEX(Monthly!$C$75:$AL$75,($R$2-1)*12+11) -> 0 | S25: =INDEX(Monthly!$C$75:$AL$75,($R$2-1)*12+12) -> 0
A26: Equity raised | B26: ='Cash Flow'!B12 -> 100000 | C26: ='Cash Flow'!C12 -> 0 | D26: ='Cash Flow'!D12 -> 0 | H26: =INDEX(Monthly!$C$76:$AL$76,($R$2-1)*12+1) -> 100000 | I26: =INDEX(Monthly!$C$76:$AL$76,($R$2-1)*12+2) -> 0 | J26: =INDEX(Monthly!$C$76:$AL$76,($R$2-1)*12+3) -> 0 | K26: =INDEX(Monthly!$C$76:$AL$76,($R$2-1)*12+4) -> 0 | L26: =INDEX(Monthly!$C$76:$AL$76,($R$2-1)*12+5) -> 0 | M26: =INDEX(Monthly!$C$76:$AL$76,($R$2-1)*12+6) -> 0 | N26: =INDEX(Monthly!$C$76:$AL$76,($R$2-1)*12+7) -> 0 | O26: =INDEX(Monthly!$C$76:$AL$76,($R$2-1)*12+8) -> 0 | P26: =INDEX(Monthly!$C$76:$AL$76,($R$2-1)*12+9) -> 0 | Q26: =INDEX(Monthly!$C$76:$AL$76,($R$2-1)*12+10) -> 0 | R26: =INDEX(Monthly!$C$76:$AL$76,($R$2-1)*12+11) -> 0 | S26: =INDEX(Monthly!$C$76:$AL$76,($R$2-1)*12+12) -> 0
A27: Loan drawdown | B27: ='Cash Flow'!B13 -> 250000 | C27: ='Cash Flow'!C13 -> 0 | D27: ='Cash Flow'!D13 -> 0 | H27: =INDEX(Monthly!$C$61:$AL$61,($R$2-1)*12+1) -> 250000 | I27: =INDEX(Monthly!$C$61:$AL$61,($R$2-1)*12+2) -> 0 | J27: =INDEX(Monthly!$C$61:$AL$61,($R$2-1)*12+3) -> 0 | K27: =INDEX(Monthly!$C$61:$AL$61,($R$2-1)*12+4) -> 0 | L27: =INDEX(Monthly!$C$61:$AL$61,($R$2-1)*12+5) -> 0 | M27: =INDEX(Monthly!$C$61:$AL$61,($R$2-1)*12+6) -> 0 | N27: =INDEX(Monthly!$C$61:$AL$61,($R$2-1)*12+7) -> 0 | O27: =INDEX(Monthly!$C$61:$AL$61,($R$2-1)*12+8) -> 0 | P27: =INDEX(Monthly!$C$61:$AL$61,($R$2-1)*12+9) -> 0 | Q27: =INDEX(Monthly!$C$61:$AL$61,($R$2-1)*12+10) -> 0 | R27: =INDEX(Monthly!$C$61:$AL$61,($R$2-1)*12+11) -> 0 | S27: =INDEX(Monthly!$C$61:$AL$61,($R$2-1)*12+12) -> 0
A28: Loan repayment | B28: ='Cash Flow'!B14 -> -45833.333 | C28: ='Cash Flow'!C14 -> -50000 | D28: ='Cash Flow'!D14 -> -50000 | H28: =INDEX(Monthly!$C$62:$AL$62,($R$2-1)*12+1) -> 0 | I28: =INDEX(Monthly!$C$62:$AL$62,($R$2-1)*12+2) -> -4166.6667 | J28: =INDEX(Monthly!$C$62:$AL$62,($R$2-1)*12+3) -> -4166.6667 | K28: =INDEX(Monthly!$C$62:$AL$62,($R$2-1)*12+4) -> -4166.6667 | L28: =INDEX(Monthly!$C$62:$AL$62,($R$2-1)*12+5) -> -4166.6667 | M28: =INDEX(Monthly!$C$62:$AL$62,($R$2-1)*12+6) -> -4166.6667 | N28: =INDEX(Monthly!$C$62:$AL$62,($R$2-1)*12+7) -> -4166.6667 | O28: =INDEX(Monthly!$C$62:$AL$62,($R$2-1)*12+8) -> -4166.6667 | P28: =INDEX(Monthly!$C$62:$AL$62,($R$2-1)*12+9) -> -4166.6667 | Q28: =INDEX(Monthly!$C$62:$AL$62,($R$2-1)*12+10) -> -4166.6667 | R28: =INDEX(Monthly!$C$62:$AL$62,($R$2-1)*12+11) -> -4166.6667 | S28: =INDEX(Monthly!$C$62:$AL$62,($R$2-1)*12+12) -> -4166.6667
A29: Financing cash flow | B29: ='Cash Flow'!B15 -> 304166.67 | C29: ='Cash Flow'!C15 -> -50000 | D29: ='Cash Flow'!D15 -> -50000 | H29: =INDEX(Monthly!$C$77:$AL$77,($R$2-1)*12+1) -> 350000 | I29: =INDEX(Monthly!$C$77:$AL$77,($R$2-1)*12+2) -> -4166.6667 | J29: =INDEX(Monthly!$C$77:$AL$77,($R$2-1)*12+3) -> -4166.6667 | K29: =INDEX(Monthly!$C$77:$AL$77,($R$2-1)*12+4) -> -4166.6667 | L29: =INDEX(Monthly!$C$77:$AL$77,($R$2-1)*12+5) -> -4166.6667 | M29: =INDEX(Monthly!$C$77:$AL$77,($R$2-1)*12+6) -> -4166.6667 | N29: =INDEX(Monthly!$C$77:$AL$77,($R$2-1)*12+7) -> -4166.6667 | O29: =INDEX(Monthly!$C$77:$AL$77,($R$2-1)*12+8) -> -4166.6667 | P29: =INDEX(Monthly!$C$77:$AL$77,($R$2-1)*12+9) -> -4166.6667 | Q29: =INDEX(Monthly!$C$77:$AL$77,($R$2-1)*12+10) -> -4166.6667 | R29: =INDEX(Monthly!$C$77:$AL$77,($R$2-1)*12+11) -> -4166.6667 | S29: =INDEX(Monthly!$C$77:$AL$77,($R$2-1)*12+12) -> -4166.6667
A30: Net change in cash | B30: ='Cash Flow'!B16 -> 478877.47 | C30: ='Cash Flow'!C16 -> 188406.62 | D30: ='Cash Flow'!D16 -> 281536.07 | H30: =INDEX(Monthly!$C$78:$AL$78,($R$2-1)*12+1) -> 339238.12 | I30: =INDEX(Monthly!$C$78:$AL$78,($R$2-1)*12+2) -> 6935.8931 | J30: =INDEX(Monthly!$C$78:$AL$78,($R$2-1)*12+3) -> 6957.8376 | K30: =INDEX(Monthly!$C$78:$AL$78,($R$2-1)*12+4) -> 6979.782 | L30: =INDEX(Monthly!$C$78:$AL$78,($R$2-1)*12+5) -> 7001.7265 | M30: =INDEX(Monthly!$C$78:$AL$78,($R$2-1)*12+6) -> 20181.338 | N30: =INDEX(Monthly!$C$78:$AL$78,($R$2-1)*12+7) -> 27758.143 | O30: =INDEX(Monthly!$C$78:$AL$78,($R$2-1)*12+8) -> 27780.088 | P30: =INDEX(Monthly!$C$78:$AL$78,($R$2-1)*12+9) -> 14644.365 | Q30: =INDEX(Monthly!$C$78:$AL$78,($R$2-1)*12+10) -> 7111.4487 | R30: =INDEX(Monthly!$C$78:$AL$78,($R$2-1)*12+11) -> 7133.3931 | S30: =INDEX(Monthly!$C$78:$AL$78,($R$2-1)*12+12) -> 7155.3376
A31: Closing cash | B31: ='Cash Flow'!B18 -> 478877.47 | C31: ='Cash Flow'!C18 -> 667284.09 | D31: ='Cash Flow'!D18 -> 948820.16 | H31: =INDEX(Monthly!$C$80:$AL$80,($R$2-1)*12+1) -> 339238.12 | I31: =INDEX(Monthly!$C$80:$AL$80,($R$2-1)*12+2) -> 346174.01 | J31: =INDEX(Monthly!$C$80:$AL$80,($R$2-1)*12+3) -> 353131.85 | K31: =INDEX(Monthly!$C$80:$AL$80,($R$2-1)*12+4) -> 360111.63 | L31: =INDEX(Monthly!$C$80:$AL$80,($R$2-1)*12+5) -> 367113.35 | M31: =INDEX(Monthly!$C$80:$AL$80,($R$2-1)*12+6) -> 387294.69 | N31: =INDEX(Monthly!$C$80:$AL$80,($R$2-1)*12+7) -> 415052.84 | O31: =INDEX(Monthly!$C$80:$AL$80,($R$2-1)*12+8) -> 442832.92 | P31: =INDEX(Monthly!$C$80:$AL$80,($R$2-1)*12+9) -> 457477.29 | Q31: =INDEX(Monthly!$C$80:$AL$80,($R$2-1)*12+10) -> 464588.74 | R31: =INDEX(Monthly!$C$80:$AL$80,($R$2-1)*12+11) -> 471722.13 | S31: =INDEX(Monthly!$C$80:$AL$80,($R$2-1)*12+12) -> 478877.47
A39: Balance sheet at year end ($'000) | H39: ="Balance sheet at month end ($'000) — Year "&$R$2 -> Balance sheet at month end ($'000) — Year 1
B40: 1 | C40: 2 | D40: 3 | H40: =INDEX(Monthly!$C$4:$AL$4,($R$2-1)*12+1) -> 1 | I40: =INDEX(Monthly!$C$4:$AL$4,($R$2-1)*12+2) -> 2 | J40: =INDEX(Monthly!$C$4:$AL$4,($R$2-1)*12+3) -> 3 | K40: =INDEX(Monthly!$C$4:$AL$4,($R$2-1)*12+4) -> 4 | L40: =INDEX(Monthly!$C$4:$AL$4,($R$2-1)*12+5) -> 5 | M40: =INDEX(Monthly!$C$4:$AL$4,($R$2-1)*12+6) -> 6 | N40: =INDEX(Monthly!$C$4:$AL$4,($R$2-1)*12+7) -> 7 | O40: =INDEX(Monthly!$C$4:$AL$4,($R$2-1)*12+8) -> 8 | P40: =INDEX(Monthly!$C$4:$AL$4,($R$2-1)*12+9) -> 9 | Q40: =INDEX(Monthly!$C$4:$AL$4,($R$2-1)*12+10) -> 10 | R40: =INDEX(Monthly!$C$4:$AL$4,($R$2-1)*12+11) -> 11 | S40: =INDEX(Monthly!$C$4:$AL$4,($R$2-1)*12+12) -> 12
A41: Cash | B41: ='Balance Sheet'!B5 -> 478877.47 | C41: ='Balance Sheet'!C5 -> 667284.09 | D41: ='Balance Sheet'!D5 -> 948820.16 | H41: =INDEX(Monthly!$C$80:$AL$80,($R$2-1)*12+1) -> 339238.12 | I41: =INDEX(Monthly!$C$80:$AL$80,($R$2-1)*12+2) -> 346174.01 | J41: =INDEX(Monthly!$C$80:$AL$80,($R$2-1)*12+3) -> 353131.85 | K41: =INDEX(Monthly!$C$80:$AL$80,($R$2-1)*12+4) -> 360111.63 | L41: =INDEX(Monthly!$C$80:$AL$80,($R$2-1)*12+5) -> 367113.35 | M41: =INDEX(Monthly!$C$80:$AL$80,($R$2-1)*12+6) -> 387294.69 | N41: =INDEX(Monthly!$C$80:$AL$80,($R$2-1)*12+7) -> 415052.84 | O41: =INDEX(Monthly!$C$80:$AL$80,($R$2-1)*12+8) -> 442832.92 | P41: =INDEX(Monthly!$C$80:$AL$80,($R$2-1)*12+9) -> 457477.29 | Q41: =INDEX(Monthly!$C$80:$AL$80,($R$2-1)*12+10) -> 464588.74 | R41: =INDEX(Monthly!$C$80:$AL$80,($R$2-1)*12+11) -> 471722.13 | S41: =INDEX(Monthly!$C$80:$AL$80,($R$2-1)*12+12) -> 478877.47
A42: Accounts receivable | B42: ='Balance Sheet'!B6 -> 44478.889 | C42: ='Balance Sheet'!C6 -> 52822.577 | D42: ='Balance Sheet'!D6 -> 62738.087 | H42: =INDEX(Monthly!$C$66:$AL$66,($R$2-1)*12+1) -> 44478.889 | I42: =INDEX(Monthly!$C$66:$AL$66,($R$2-1)*12+2) -> 44478.889 | J42: =INDEX(Monthly!$C$66:$AL$66,($R$2-1)*12+3) -> 44478.889 | K42: =INDEX(Monthly!$C$66:$AL$66,($R$2-1)*12+4) -> 44478.889 | L42: =INDEX(Monthly!$C$66:$AL$66,($R$2-1)*12+5) -> 44478.889 | M42: =INDEX(Monthly!$C$66:$AL$66,($R$2-1)*12+6) -> 56566.667 | N42: =INDEX(Monthly!$C$66:$AL$66,($R$2-1)*12+7) -> 56566.667 | O42: =INDEX(Monthly!$C$66:$AL$66,($R$2-1)*12+8) -> 56566.667 | P42: =INDEX(Monthly!$C$66:$AL$66,($R$2-1)*12+9) -> 44478.889 | Q42: =INDEX(Monthly!$C$66:$AL$66,($R$2-1)*12+10) -> 44478.889 | R42: =INDEX(Monthly!$C$66:$AL$66,($R$2-1)*12+11) -> 44478.889 | S42: =INDEX(Monthly!$C$66:$AL$66,($R$2-1)*12+12) -> 44478.889
A43: Inventory | B43: ='Balance Sheet'!B7 -> 14208.472 | C43: ='Balance Sheet'!C7 -> 16545.38 | D43: ='Balance Sheet'!D7 -> 19275.29 | H43: =INDEX(Monthly!$C$67:$AL$67,($R$2-1)*12+1) -> 14208.472 | I43: =INDEX(Monthly!$C$67:$AL$67,($R$2-1)*12+2) -> 14208.472 | J43: =INDEX(Monthly!$C$67:$AL$67,($R$2-1)*12+3) -> 14208.472 | K43: =INDEX(Monthly!$C$67:$AL$67,($R$2-1)*12+4) -> 14208.472 | L43: =INDEX(Monthly!$C$67:$AL$67,($R$2-1)*12+5) -> 14208.472 | M43: =INDEX(Monthly!$C$67:$AL$67,($R$2-1)*12+6) -> 15719.444 | N43: =INDEX(Monthly!$C$67:$AL$67,($R$2-1)*12+7) -> 15719.444 | O43: =INDEX(Monthly!$C$67:$AL$67,($R$2-1)*12+8) -> 15719.444 | P43: =INDEX(Monthly!$C$67:$AL$67,($R$2-1)*12+9) -> 14208.472 | Q43: =INDEX(Monthly!$C$67:$AL$67,($R$2-1)*12+10) -> 14208.472 | R43: =INDEX(Monthly!$C$67:$AL$67,($R$2-1)*12+11) -> 14208.472 | S43: =INDEX(Monthly!$C$67:$AL$67,($R$2-1)*12+12) -> 14208.472
A44: Net fixed assets | B44: ='Balance Sheet'!B8 -> 16000 | C44: ='Balance Sheet'!C8 -> 42240 | D44: ='Balance Sheet'!D8 -> 64548.8 | H44: =INDEX(Monthly!$C$57:$AL$57,($R$2-1)*12+1) -> 19666.667 | I44: =INDEX(Monthly!$C$57:$AL$57,($R$2-1)*12+2) -> 19333.333 | J44: =INDEX(Monthly!$C$57:$AL$57,($R$2-1)*12+3) -> 19000 | K44: =INDEX(Monthly!$C$57:$AL$57,($R$2-1)*12+4) -> 18666.667 | L44: =INDEX(Monthly!$C$57:$AL$57,($R$2-1)*12+5) -> 18333.333 | M44: =INDEX(Monthly!$C$57:$AL$57,($R$2-1)*12+6) -> 18000 | N44: =INDEX(Monthly!$C$57:$AL$57,($R$2-1)*12+7) -> 17666.667 | O44: =INDEX(Monthly!$C$57:$AL$57,($R$2-1)*12+8) -> 17333.333 | P44: =INDEX(Monthly!$C$57:$AL$57,($R$2-1)*12+9) -> 17000 | Q44: =INDEX(Monthly!$C$57:$AL$57,($R$2-1)*12+10) -> 16666.667 | R44: =INDEX(Monthly!$C$57:$AL$57,($R$2-1)*12+11) -> 16333.333 | S44: =INDEX(Monthly!$C$57:$AL$57,($R$2-1)*12+12) -> 16000
A45: Total assets | B45: ='Balance Sheet'!B9 -> 553564.83 | C45: ='Balance Sheet'!C9 -> 778892.05 | D45: ='Balance Sheet'!D9 -> 1095382.3 | H45: =INDEX(Monthly!$C$94:$AL$94,($R$2-1)*12+1) -> 417592.14 | I45: =INDEX(Monthly!$C$94:$AL$94,($R$2-1)*12+2) -> 424194.7 | J45: =INDEX(Monthly!$C$94:$AL$94,($R$2-1)*12+3) -> 430819.21 | K45: =INDEX(Monthly!$C$94:$AL$94,($R$2-1)*12+4) -> 437465.66 | L45: =INDEX(Monthly!$C$94:$AL$94,($R$2-1)*12+5) -> 444134.05 | M45: =INDEX(Monthly!$C$94:$AL$94,($R$2-1)*12+6) -> 477580.8 | N45: =INDEX(Monthly!$C$94:$AL$94,($R$2-1)*12+7) -> 505005.61 | O45: =INDEX(Monthly!$C$94:$AL$94,($R$2-1)*12+8) -> 532452.37 | P45: =INDEX(Monthly!$C$94:$AL$94,($R$2-1)*12+9) -> 533164.65 | Q45: =INDEX(Monthly!$C$94:$AL$94,($R$2-1)*12+10) -> 539942.77 | R45: =INDEX(Monthly!$C$94:$AL$94,($R$2-1)*12+11) -> 546742.83 | S45: =INDEX(Monthly!$C$94:$AL$94,($R$2-1)*12+12) -> 553564.83
A46: Accounts payable | B46: ='Balance Sheet'!B10 -> 56833.889 | C46: ='Balance Sheet'!C10 -> 66181.52 | D46: ='Balance Sheet'!D10 -> 77101.158 | H46: =INDEX(Monthly!$C$68:$AL$68,($R$2-1)*12+1) -> 56833.889 | I46: =INDEX(Monthly!$C$68:$AL$68,($R$2-1)*12+2) -> 56833.889 | J46: =INDEX(Monthly!$C$68:$AL$68,($R$2-1)*12+3) -> 56833.889 | K46: =INDEX(Monthly!$C$68:$AL$68,($R$2-1)*12+4) -> 56833.889 | L46: =INDEX(Monthly!$C$68:$AL$68,($R$2-1)*12+5) -> 56833.889 | M46: =INDEX(Monthly!$C$68:$AL$68,($R$2-1)*12+6) -> 62877.778 | N46: =INDEX(Monthly!$C$68:$AL$68,($R$2-1)*12+7) -> 62877.778 | O46: =INDEX(Monthly!$C$68:$AL$68,($R$2-1)*12+8) -> 62877.778 | P46: =INDEX(Monthly!$C$68:$AL$68,($R$2-1)*12+9) -> 56833.889 | Q46: =INDEX(Monthly!$C$68:$AL$68,($R$2-1)*12+10) -> 56833.889 | R46: =INDEX(Monthly!$C$68:$AL$68,($R$2-1)*12+11) -> 56833.889 | S46: =INDEX(Monthly!$C$68:$AL$68,($R$2-1)*12+12) -> 56833.889
A47: Loan | B47: ='Balance Sheet'!B11 -> 204166.67 | C47: ='Balance Sheet'!C11 -> 154166.67 | D47: ='Balance Sheet'!D11 -> 104166.67 | H47: =INDEX(Monthly!$C$63:$AL$63,($R$2-1)*12+1) -> 250000 | I47: =INDEX(Monthly!$C$63:$AL$63,($R$2-1)*12+2) -> 245833.33 | J47: =INDEX(Monthly!$C$63:$AL$63,($R$2-1)*12+3) -> 241666.67 | K47: =INDEX(Monthly!$C$63:$AL$63,($R$2-1)*12+4) -> 237500 | L47: =INDEX(Monthly!$C$63:$AL$63,($R$2-1)*12+5) -> 233333.33 | M47: =INDEX(Monthly!$C$63:$AL$63,($R$2-1)*12+6) -> 229166.67 | N47: =INDEX(Monthly!$C$63:$AL$63,($R$2-1)*12+7) -> 225000 | O47: =INDEX(Monthly!$C$63:$AL$63,($R$2-1)*12+8) -> 220833.33 | P47: =INDEX(Monthly!$C$63:$AL$63,($R$2-1)*12+9) -> 216666.67 | Q47: =INDEX(Monthly!$C$63:$AL$63,($R$2-1)*12+10) -> 212500 | R47: =INDEX(Monthly!$C$63:$AL$63,($R$2-1)*12+11) -> 208333.33 | S47: =INDEX(Monthly!$C$63:$AL$63,($R$2-1)*12+12) -> 204166.67
A48: Total liabilities | B48: ='Balance Sheet'!B12 -> 261000.56 | C48: ='Balance Sheet'!C12 -> 220348.19 | D48: ='Balance Sheet'!D12 -> 181267.82 | H48: =INDEX(Monthly!$C$95:$AL$95,($R$2-1)*12+1) -> 306833.89 | I48: =INDEX(Monthly!$C$95:$AL$95,($R$2-1)*12+2) -> 302667.22 | J48: =INDEX(Monthly!$C$95:$AL$95,($R$2-1)*12+3) -> 298500.56 | K48: =INDEX(Monthly!$C$95:$AL$95,($R$2-1)*12+4) -> 294333.89 | L48: =INDEX(Monthly!$C$95:$AL$95,($R$2-1)*12+5) -> 290167.22 | M48: =INDEX(Monthly!$C$95:$AL$95,($R$2-1)*12+6) -> 292044.44 | N48: =INDEX(Monthly!$C$95:$AL$95,($R$2-1)*12+7) -> 287877.78 | O48: =INDEX(Monthly!$C$95:$AL$95,($R$2-1)*12+8) -> 283711.11 | P48: =INDEX(Monthly!$C$95:$AL$95,($R$2-1)*12+9) -> 273500.56 | Q48: =INDEX(Monthly!$C$95:$AL$95,($R$2-1)*12+10) -> 269333.89 | R48: =INDEX(Monthly!$C$95:$AL$95,($R$2-1)*12+11) -> 265167.22 | S48: =INDEX(Monthly!$C$95:$AL$95,($R$2-1)*12+12) -> 261000.56
A49: Paid-in capital | B49: ='Balance Sheet'!B13 -> 100000 | C49: ='Balance Sheet'!C13 -> 100000 | D49: ='Balance Sheet'!D13 -> 100000 | H49: =INDEX(Monthly!$C$92:$AL$92,($R$2-1)*12+1) -> 100000 | I49: =INDEX(Monthly!$C$92:$AL$92,($R$2-1)*12+2) -> 100000 | J49: =INDEX(Monthly!$C$92:$AL$92,($R$2-1)*12+3) -> 100000 | K49: =INDEX(Monthly!$C$92:$AL$92,($R$2-1)*12+4) -> 100000 | L49: =INDEX(Monthly!$C$92:$AL$92,($R$2-1)*12+5) -> 100000 | M49: =INDEX(Monthly!$C$92:$AL$92,($R$2-1)*12+6) -> 100000 | N49: =INDEX(Monthly!$C$92:$AL$92,($R$2-1)*12+7) -> 100000 | O49: =INDEX(Monthly!$C$92:$AL$92,($R$2-1)*12+8) -> 100000 | P49: =INDEX(Monthly!$C$92:$AL$92,($R$2-1)*12+9) -> 100000 | Q49: =INDEX(Monthly!$C$92:$AL$92,($R$2-1)*12+10) -> 100000 | R49: =INDEX(Monthly!$C$92:$AL$92,($R$2-1)*12+11) -> 100000 | S49: =INDEX(Monthly!$C$92:$AL$92,($R$2-1)*12+12) -> 100000
A50: Retained earnings | B50: ='Balance Sheet'!B14 -> 192564.27 | C50: ='Balance Sheet'!C14 -> 458543.86 | D50: ='Balance Sheet'!D14 -> 814114.51 | H50: =INDEX(Monthly!$C$93:$AL$93,($R$2-1)*12+1) -> 10758.254 | I50: =INDEX(Monthly!$C$93:$AL$93,($R$2-1)*12+2) -> 21527.481 | J50: =INDEX(Monthly!$C$93:$AL$93,($R$2-1)*12+3) -> 32318.652 | K50: =INDEX(Monthly!$C$93:$AL$93,($R$2-1)*12+4) -> 43131.767 | L50: =INDEX(Monthly!$C$93:$AL$93,($R$2-1)*12+5) -> 53966.827 | M50: =INDEX(Monthly!$C$93:$AL$93,($R$2-1)*12+6) -> 85536.359 | N50: =INDEX(Monthly!$C$93:$AL$93,($R$2-1)*12+7) -> 117127.84 | O50: =INDEX(Monthly!$C$93:$AL$93,($R$2-1)*12+8) -> 148741.26 | P50: =INDEX(Monthly!$C$93:$AL$93,($R$2-1)*12+9) -> 159664.09 | Q50: =INDEX(Monthly!$C$93:$AL$93,($R$2-1)*12+10) -> 170608.88 | R50: =INDEX(Monthly!$C$93:$AL$93,($R$2-1)*12+11) -> 181575.6 | S50: =INDEX(Monthly!$C$93:$AL$93,($R$2-1)*12+12) -> 192564.27
...

Sheet Scenarios
A1: Scenarios — Low / Base / High | H1: =HYPERLINK("#'Cover'!A1","◂ Contents") -> ◂ Contents
A2: All three scenarios calculated side by side, live: change any input and every column updates. Active = the scenario chosen on the Dashboard.
A5: Key drivers
A6: Driver | B6: Low | C6: Base | D6: High | E6: Active
A7: Average revenue per job (year 1) ($) | B7: =Inputs!$B$20 -> 415 | C7: =Inputs!$C$20 -> 440 | D7: =Inputs!$D$20 -> 465 | E7: =Inputs!$E$20 -> 440
A8: Jobs per technician per working day (jobs) | B8: =Inputs!$B$7 -> 2.35 | C8: =Inputs!$C$7 -> 2.5 | D8: =Inputs!$D$7 -> 2.65 | E8: =Inputs!$E$7 -> 2.5
A9: Marketing budget per month ($) | B9: =Inputs!$B$11 -> 9000 | C9: =Inputs!$C$11 -> 9000 | D9: =Inputs!$D$11 -> 9000 | E9: =Inputs!$E$11 -> 9000
A10: Cost per lead ($) | B10: =Inputs!$B$13 -> 52 | C10: =Inputs!$C$13 -> 50 | D10: =Inputs!$D$13 -> 48 | E10: =Inputs!$E$13 -> 50
A11: Leads booked as jobs (%) | B11: =Inputs!$B$14 -> 0.42 | C11: =Inputs!$C$14 -> 0.45 | D11: =Inputs!$D$14 -> 0.48 | E11: =Inputs!$E$14 -> 0.45
A12: Materials & parts, % of job revenue (%) | B12: =Inputs!$B$30 -> 0.26 | C12: =Inputs!$C$30 -> 0.25 | D12: =Inputs!$D$30 -> 0.24 | E12: =Inputs!$E$30 -> 0.25
A13: Equity raised at start ($) | B13: =Inputs!$B$54 -> 100000 | C13: =Inputs!$C$54 -> 100000 | D13: =Inputs!$D$54 -> 100000 | E13: =Inputs!$E$54 -> 100000
A15: Results by scenario ($'000)
A16: Output | B16: Low | C16: Base | D16: High | E16: Active
A17: Revenue — final year | B17: =D30 -> 1796473 | C17: =D31 -> 2376160.7 | D17: =D32 -> 3040261.8 | E17: ='P&L'!D5 -> 2376160.7
A18: Revenue — whole plan | B18: =SUM(B30:D30) -> 4739987.5 | C18: =SUM(B31:D31) -> 6101675.7 | D18: =SUM(B32:D32) -> 7596136.8 | E18: =SUM('P&L'!$B$5:$D$5) -> 6101675.7
A19: EBITDA — final year | B19: =D36 -> 49597.556 | C19: =D37 -> 480449.96 | D19: =D38 -> 985565.06 | E19: ='P&L'!D17 -> 480449.96
A20: EBITDA margin — final year | B20: =IF(B17=0,0,B19/B17) -> 0.027608295 | C20: =IF(C17=0,0,C19/C17) -> 0.2021959 | D20: =IF(D17=0,0,D19/D17) -> 0.32417112 | E20: =IF(E17=0,0,E19/E17) -> 0.2021959
A21: Net income — final year | B21: =D42 -> 15445.606 | C21: =D43 -> 355570.65 | D21: =D44 -> 755174.31 | E21: ='P&L'!D24 -> 355570.65
A22: Net income — whole plan | B22: =SUM(B42:D42) -> -4174.0176 | C22: =SUM(B43:D43) -> 814114.51 | D22: =SUM(B44:D44) -> 1727783.2 | E22: =SUM('P&L'!$B$24:$D$24) -> 814114.51
A23: Cash at the end of the plan | B23: =D48 -> 139097.51 | C23: =D49 -> 948820.16 | D23: =D50 -> 1851111.7 | E23: ='Balance Sheet'!D5 -> 948820.16
A24: Lowest cash balance | B24: =MIN('Scenario calc'!$C$82:$AL$82) -> 105803.75 | C24: =MIN('Scenario calc'!$C$191:$AL$191) -> 339238.12 | D24: =MIN('Scenario calc'!$C$300:$AL$300) -> 351230.53 | E24: ='Break-even'!B18 -> 339238.12
A25: Lowest cash point (month #) | B25: =MATCH(MIN('Scenario calc'!$C$82:$AL$82),'Scenario calc'!$C$82:$AL$82,0) -> 29 | C25: =MATCH(MIN('Scenario calc'!$C$191:$AL$191),'Scenario calc'!$C$191:$AL$191,0) -> 1 | D25: =MATCH(MIN('Scenario calc'!$C$300:$AL$300),'Scenario calc'!$C$300:$AL$300,0) -> 1 | E25: ='Break-even'!B6 -> 1
A26: Funding required (incl. cash buffer) | B26: =SUMPRODUCT(--('Scenario calc'!$C$6:$AL$6<=B25),'Scenario calc'!$C$55:$AL$55)-SUMPRODUCT(--('Scenario calc'!$C$6:$AL$6<=B25),'Scenario calc'!$C$76:$AL$76)-SUMPRODUCT(--('Scenario calc'!$C$6:$AL$6<=B25),'Scenario calc'!$C$64:$AL$64)+Inputs!$B$69 -> 342196.25 | C26: =SUMPRODUCT(--('Scenario calc'!$C$115:$AL$115<=C25),'Scenario calc'!$C$164:$AL$164)-SUMPRODUCT(--('Scenario calc'!$C$115:$AL$115<=C25),'Scenario calc'!$C$185:$AL$185)-SUMPRODUCT(--('Scenario calc'!$C$115:$AL$115<=C25),'Scenario calc'!$C$173:$AL$173)+Inputs!$C$69 -> 108761.88 | D26: =SUMPRODUCT(--('Scenario calc'!$C$224:$AL$224<=D25),'Scenario calc'!$C$273:$AL$273)-SUMPRODUCT(--('Scenario calc'!$C$224:$AL$224<=D25),'Scenario calc'!$C$294:$AL$294)-SUMPRODUCT(--('Scenario calc'!$C$224:$AL$224<=D25),'Scenario calc'!$C$282:$AL$282)+Inputs!$D$69 -> 96769.474 | E26: ='Break-even'!B12 -> 108761.88
A28: Revenue by year ($'000)
A29: Scenario | B29: 1 | C29: 2 | D29: 3
A30: Low | B30: =SUMIF('Scenario calc'!$C$7:$AL$7,B$29,'Scenario calc'!$C$24:$AL$24) -> 1373007.7 | C30: =SUMIF('Scenario calc'!$C$7:$AL$7,C$29,'Scenario calc'!$C$24:$AL$24) -> 1570506.9 | D30: =SUMIF('Scenario calc'!$C$7:$AL$7,D$29,'Scenario calc'!$C$24:$AL$24) -> 1796473
A31: Base | B31: =SUMIF('Scenario calc'!$C$116:$AL$116,B$29,'Scenario calc'!$C$133:$AL$133) -> 1710030 | C31: =SUMIF('Scenario calc'!$C$116:$AL$116,C$29,'Scenario calc'!$C$133:$AL$133) -> 2015484.9 | D31: =SUMIF('Scenario calc'!$C$116:$AL$116,D$29,'Scenario calc'!$C$133:$AL$133) -> 2376160.7
A32: High | B32: =SUMIF('Scenario calc'!$C$225:$AL$225,B$29,'Scenario calc'!$C$242:$AL$242) -> 2056472.2 | C32: =SUMIF('Scenario calc'!$C$225:$AL$225,C$29,'Scenario calc'!$C$242:$AL$242) -> 2499402.8 | D32: =SUMIF('Scenario calc'!$C$225:$AL$225,D$29,'Scenario calc'!$C$242:$AL$242) -> 3040261.8
A34: EBITDA by year ($'000)
A35: Scenario | B35: 1 | C35: 2 | D35: 3
A36: Low | B36: =SUMIF('Scenario calc'!$C$7:$AL$7,B$35,'Scenario calc'!$C$43:$AL$43) -> 5760.4692 | C36: =SUMIF('Scenario calc'!$C$7:$AL$7,C$35,'Scenario calc'!$C$43:$AL$43) -> 26183.859 | D36: =SUMIF('Scenario calc'!$C$7:$AL$7,D$35,'Scenario calc'!$C$43:$AL$43) -> 49597.556
A37: Base | B37: =SUMIF('Scenario calc'!$C$116:$AL$116,B$35,'Scenario calc'!$C$152:$AL$152) -> 266071.69 | C37: =SUMIF('Scenario calc'!$C$116:$AL$116,C$35,'Scenario calc'!$C$152:$AL$152) -> 362576.36 | D37: =SUMIF('Scenario calc'!$C$116:$AL$116,D$35,'Scenario calc'!$C$152:$AL$152) -> 480449.96
A38: High | B38: =SUMIF('Scenario calc'!$C$225:$AL$225,B$35,'Scenario calc'!$C$261:$AL$261) -> 541347.1 | C38: =SUMIF('Scenario calc'!$C$225:$AL$225,C$35,'Scenario calc'!$C$261:$AL$261) -> 737680.2 | D38: =SUMIF('Scenario calc'!$C$225:$AL$225,D$35,'Scenario calc'!$C$261:$AL$261) -> 985565.06
A40: Net income by year ($'000)
A41: Scenario | B41: 1 | C41: 2 | D41: 3
A42: Low | B42: =SUMIF('Scenario calc'!$C$7:$AL$7,B$41,'Scenario calc'!$C$52:$AL$52) -> -19574.149 | C42: =SUMIF('Scenario calc'!$C$7:$AL$7,C$41,'Scenario calc'!$C$52:$AL$52) -> -45.474404 | D42: =SUMIF('Scenario calc'!$C$7:$AL$7,D$41,'Scenario calc'!$C$52:$AL$52) -> 15445.606
A43: Base | B43: =SUMIF('Scenario calc'!$C$116:$AL$116,B$41,'Scenario calc'!$C$161:$AL$161) -> 192564.27 | C43: =SUMIF('Scenario calc'!$C$116:$AL$116,C$41,'Scenario calc'!$C$161:$AL$161) -> 265979.59 | D43: =SUMIF('Scenario calc'!$C$116:$AL$116,D$41,'Scenario calc'!$C$161:$AL$161) -> 355570.65
A44: High | B44: =SUMIF('Scenario calc'!$C$225:$AL$225,B$41,'Scenario calc'!$C$270:$AL$270) -> 410031.85 | C44: =SUMIF('Scenario calc'!$C$225:$AL$225,C$41,'Scenario calc'!$C$270:$AL$270) -> 562577.06 | D44: =SUMIF('Scenario calc'!$C$225:$AL$225,D$41,'Scenario calc'!$C$270:$AL$270) -> 755174.31
A46: Cash at year end by year ($'000)
A47: Scenario | B47: 1 | C47: 2 | D47: 3
...

Sheet Break-even
A1: Startup costs, funding need and break-even | F1: =HYPERLINK("#'Cover'!A1","◂ Contents") -> ◂ Contents
A2: Live for the selected scenario. Periods are counted in months from the start of the plan.
A3: Scenario shown | B3: =CHOOSE(Dashboard!$B$4,"Low","Base","High") -> Base
A5: Startup costs & funding need (up to the lowest cash point)
A6: Lowest cash point (month #) | B6: =MATCH(MIN(Monthly!$C$80:$AL$80),Monthly!$C$80:$AL$80,0) -> 1
A7: Capital spending up to the lowest cash point | B7: =SUMPRODUCT(--(Monthly!$C$4:$AL$4<=$B$6),Monthly!$C$53:$AL$53) -> 20000
A8: Operating cash burn up to the lowest cash point | B8: =-SUMPRODUCT(--(Monthly!$C$4:$AL$4<=$B$6),Monthly!$C$74:$AL$74) -> -9238.1153 | D8: Losses and working capital before the business funds itself
A9: Loan repayments up to the lowest cash point | B9: =-SUMPRODUCT(--(Monthly!$C$4:$AL$4<=$B$6),Monthly!$C$62:$AL$62) -> 0
A10: Total uses of funds | B10: =B7+B8+B9 -> 10761.885
A11: Minimum cash buffer to keep | B11: =Inputs!$E$69 -> 98000 | D11: Input on the Inputs sheet
A12: Funding required (uses + buffer) | B12: =B10+B11 -> 108761.88
A14: Equity raised | B14: =Inputs!$E$54 -> 100000
A15: Loan drawn | B15: =Inputs!$E$55 -> 250000
A16: Total sources of funds | B16: =B14+B15 -> 350000
A17: Funding surplus / (shortfall) | B17: =B16-B12 -> 241238.12 | D17: Negative = raise at least this much more
A18: Lowest cash balance in the plan | B18: =MIN(Monthly!$C$80:$AL$80) -> 339238.12 | D18: Equals sources minus uses
A20: Break-even timing
A21: First month with positive EBITDA (month #) | B21: =IFERROR(MATCH(1,Monthly!$C$81:$AL$81,0),"Not within horizon") -> 1
A22: First month with positive net income (month #) | B22: =IFERROR(MATCH(1,Monthly!$C$84:$AL$84,0),"Not within horizon") -> 1
A23: Cash invested paid back (month #) | B23: =IF(MIN(Monthly!$C$86:$AL$86)>=0,"No investment to pay back",IFERROR(MATCH(1,Monthly!$C$88:$AL$88,0),"Not within horizon")) -> 2 | D23: Cumulative operating + investing cash flow back to zero
A25: Annual break-even revenue
A26: Year # | B26: 1 | C26: 2 | D26: 3
B27: Year 1 | C27: Year 2 | D27: Year 3
A28: Revenue | B28: =SUMIF(Monthly!$C$5:$AL$5,B$26,Monthly!$C$22:$AL$22) -> 1710030 | C28: =SUMIF(Monthly!$C$5:$AL$5,C$26,Monthly!$C$22:$AL$22) -> 2015484.9 | D28: =SUMIF(Monthly!$C$5:$AL$5,D$26,Monthly!$C$22:$AL$22) -> 2376160.7
A29: Gross profit | B29: =SUMIF(Monthly!$C$5:$AL$5,B$26,Monthly!$C$30:$AL$30) -> 659822.5 | C29: =SUMIF(Monthly!$C$5:$AL$5,C$26,Monthly!$C$30:$AL$30) -> 795749.55 | D29: =SUMIF(Monthly!$C$5:$AL$5,D$26,Monthly!$C$30:$AL$30) -> 958942.46
A30: Gross margin (contribution) | B30: =IF(B28=0,0,B29/B28) -> 0.38585434 | C30: =IF(C28=0,0,C29/C28) -> 0.39481791 | D30: =IF(D28=0,0,D29/D28) -> 0.40356802
A31: Operating expenses (treated as fixed) | B31: =-SUMIF(Monthly!$C$5:$AL$5,B$26,Monthly!$C$40:$AL$40) -> 393750.81 | C31: =-SUMIF(Monthly!$C$5:$AL$5,C$26,Monthly!$C$40:$AL$40) -> 433173.19 | D31: =-SUMIF(Monthly!$C$5:$AL$5,D$26,Monthly!$C$40:$AL$40) -> 478492.5
A32: Break-even revenue (EBITDA = 0) | B32: =IF(B30>0,B31/B30,"n/a") -> 1020464.9 | C32: =IF(C30>0,C31/C30,"n/a") -> 1097146.8 | D32: =IF(D30>0,D31/D30,"n/a") -> 1185655.2
A33: Margin of safety (revenue above break-even) | B33: =IF(AND(ISNUMBER(B32),B28>0),(B28-B32)/B28,"n/a") -> 0.40324737 | C33: =IF(AND(ISNUMBER(C32),C28>0),(C28-C32)/C28,"n/a") -> 0.4556413 | D33: =IF(AND(ISNUMBER(D32),D28>0),(D28-D32)/D28,"n/a") -> 0.50102063
A35: Simplification: cost of sales is treated as variable and operating expenses as fixed, so break-even revenue = operating expenses ÷ gross margin. In a year with zero or negative gross margin there is no break-even revenue (n/a); the chart line shows 0 there.

Sheet Valuation
A1: Discounted cash flow valuation | H1: =HYPERLINK("#'Cover'!A1","◂ Contents") -> ◂ Contents
A2: Enterprise value at the start of the plan, before the funding raised in period 1. Year-end discounting.
A3: Scenario shown | B3: =CHOOSE(Dashboard!$B$4,"Low","Base","High") -> Base
A5: Assumptions (active scenario, from the Inputs sheet)
A6: Discount rate (WACC) | B6: =Inputs!$E$72 -> 0.16
A7: Terminal growth rate | B7: =Inputs!$E$73 -> 0.02
A8: Exit multiple (EV ÷ final-year EBITDA) | B8: =Inputs!$E$74 -> 5.5
A9: Tax rate (for the interest tax shield) | B9: =Inputs!$E$66 -> 0.21
A10: Sensitivity step: WACC | B10: =Inputs!$E$75 -> 0.01
A11: Sensitivity step: terminal growth | B11: =Inputs!$E$76 -> 0.005
A13: Free cash flow by year
A14: Year # | B14: 1 | C14: 2 | D14: 3
B15: Year 1 | C15: Year 2 | D15: Year 3
A16: EBITDA | B16: =SUMIF(Monthly!$C$5:$AL$5,B$14,Monthly!$C$41:$AL$41) -> 266071.69 | C16: =SUMIF(Monthly!$C$5:$AL$5,C$14,Monthly!$C$41:$AL$41) -> 362576.36 | D16: =SUMIF(Monthly!$C$5:$AL$5,D$14,Monthly!$C$41:$AL$41) -> 480449.96
A17: Unlevered free cash flow | B17: =SUMIF(Monthly!$C$5:$AL$5,B$14,Monthly!$C$89:$AL$89) -> 189183.16 | C17: =SUMIF(Monthly!$C$5:$AL$5,C$14,Monthly!$C$89:$AL$89) -> 249729.96 | D17: =SUMIF(Monthly!$C$5:$AL$5,D$14,Monthly!$C$89:$AL$89) -> 339699.4
A18: Discount factor | B18: =1/(1+Inputs!$E$72)^B$14 -> 0.86206897 | C18: =1/(1+Inputs!$E$72)^C$14 -> 0.7431629 | D18: =1/(1+Inputs!$E$72)^D$14 -> 0.64065767
A19: Present value of free cash flow | B19: =B17*B18 -> 163088.93 | C19: =C17*C18 -> 185590.04 | D19: =D17*D18 -> 217631.03
A21: Enterprise value
B22: Perpetual growth | C22: Exit multiple
A23: Present value of the plan's free cash flows | B23: =SUM($B$19:$D$19) -> 566310 | C23: =B23 -> 566310
A24: Final-year free cash flow | final-year EBITDA | B24: =$D$17 -> 339699.4 | C24: =$D$16 -> 480449.96
A25: Terminal value at the end of year 3 | B25: =IF($B$6>$B$7,B24*(1+$B$7)/($B$6-$B$7),0) -> 2474952.8 | C25: =C24*$B$8 -> 2642474.8
A26: Present value of the terminal value | B26: =B25/(1+$B$6)^$D$14 -> 1585597.5 | C26: =C25/(1+$B$6)^$D$14 -> 1692921.7
A27: Enterprise value | B27: =B23+B26 -> 2151907.5 | C27: =C23+C26 -> 2259231.7
A28: Terminal value share of enterprise value | B28: =IF(B27<>0,B26/B27,0) -> 0.73683348 | C28: =IF(C27<>0,C26/C27,0) -> 0.74933514
A29: Cross-check: implied exit multiple | implied perpetual growth | B29: =IF(C24>0,B25/C24,"n/a") -> 5.1513227 | C29: =IF(C25+B24<>0,(C25*$B$6-B24)/(C25+B24),"n/a") -> 0.027864424
A30: Enterprise value — average of the two methods | B30: =AVERAGE(B27,C27) -> 2205569.6
A32: Sensitivity: enterprise value (perpetual growth) by WACC and terminal growth
A33: WACC ↓ · terminal growth → | B33: =$B$7+(-2)*$B$11 -> 0.01 | C33: =$B$7+(-1)*$B$11 -> 0.015 | D33: =$B$7+(0)*$B$11 -> 0.02 | E33: =$B$7+(1)*$B$11 -> 0.025 | F33: =$B$7+(2)*$B$11 -> 0.03
A34: =$B$6+(-2)*$B$10 -> 0.14 | B34: =IF($A34>B$33,SUMPRODUCT($B$17:$D$17/(1+$A34)^$B$14:$D$14)+$D$17*(1+B$33)/($A34-B$33)/(1+$A34)^$D$14,"n/a") -> 2368783.5 | C34: =IF($A34>C$33,SUMPRODUCT($B$17:$D$17/(1+$A34)^$B$14:$D$14)+$D$17*(1+C$33)/($A34-C$33)/(1+$A34)^$D$14,"n/a") -> 2449210.5 | D34: =IF($A34>D$33,SUMPRODUCT($B$17:$D$17/(1+$A34)^$B$14:$D$14)+$D$17*(1+D$33)/($A34-D$33)/(1+$A34)^$D$14,"n/a") -> 2536339.7 | E34: =IF($A34>E$33,SUMPRODUCT($B$17:$D$17/(1+$A34)^$B$14:$D$14)+$D$17*(1+E$33)/($A34-E$33)/(1+$A34)^$D$14,"n/a") -> 2631045.4 | F34: =IF($A34>F$33,SUMPRODUCT($B$17:$D$17/(1+$A34)^$B$14:$D$14)+$D$17*(1+F$33)/($A34-F$33)/(1+$A34)^$D$14,"n/a") -> 2734360.7
A35: =$B$6+(-1)*$B$10 -> 0.15 | B35: =IF($A35>B$33,SUMPRODUCT($B$17:$D$17/(1+$A35)^$B$14:$D$14)+$D$17*(1+B$33)/($A35-B$33)/(1+$A35)^$D$14,"n/a") -> 2188064.2 | C35: =IF($A35>C$33,SUMPRODUCT($B$17:$D$17/(1+$A35)^$B$14:$D$14)+$D$17*(1+C$33)/($A35-C$33)/(1+$A35)^$D$14,"n/a") -> 2256017 | D35: =IF($A35>D$33,SUMPRODUCT($B$17:$D$17/(1+$A35)^$B$14:$D$14)+$D$17*(1+D$33)/($A35-D$33)/(1+$A35)^$D$14,"n/a") -> 2329196.9 | E35: =IF($A35>E$33,SUMPRODUCT($B$17:$D$17/(1+$A35)^$B$14:$D$14)+$D$17*(1+E$33)/($A35-E$33)/(1+$A35)^$D$14,"n/a") -> 2408231.2 | F35: =IF($A35>F$33,SUMPRODUCT($B$17:$D$17/(1+$A35)^$B$14:$D$14)+$D$17*(1+F$33)/($A35-F$33)/(1+$A35)^$D$14,"n/a") -> 2493851.7
A36: =$B$6+(0)*$B$10 -> 0.16 | B36: =IF($A36>B$33,SUMPRODUCT($B$17:$D$17/(1+$A36)^$B$14:$D$14)+$D$17*(1+B$33)/($A36-B$33)/(1+$A36)^$D$14,"n/a") -> 2031692.3 | C36: =IF($A36>C$33,SUMPRODUCT($B$17:$D$17/(1+$A36)^$B$14:$D$14)+$D$17*(1+C$33)/($A36-C$33)/(1+$A36)^$D$14,"n/a") -> 2089727.2 | D36: =IF($A36>D$33,SUMPRODUCT($B$17:$D$17/(1+$A36)^$B$14:$D$14)+$D$17*(1+D$33)/($A36-D$33)/(1+$A36)^$D$14,"n/a") -> 2151907.5 | E36: =IF($A36>E$33,SUMPRODUCT($B$17:$D$17/(1+$A36)^$B$14:$D$14)+$D$17*(1+E$33)/($A36-E$33)/(1+$A36)^$D$14,"n/a") -> 2218693.7 | F36: =IF($A36>F$33,SUMPRODUCT($B$17:$D$17/(1+$A36)^$B$14:$D$14)+$D$17*(1+F$33)/($A36-F$33)/(1+$A36)^$D$14,"n/a") -> 2290617.4
A37: =$B$6+(1)*$B$10 -> 0.17 | B37: =IF($A37>B$33,SUMPRODUCT($B$17:$D$17/(1+$A37)^$B$14:$D$14)+$D$17*(1+B$33)/($A37-B$33)/(1+$A37)^$D$14,"n/a") -> 1895095 | C37: =IF($A37>C$33,SUMPRODUCT($B$17:$D$17/(1+$A37)^$B$14:$D$14)+$D$17*(1+C$33)/($A37-C$33)/(1+$A37)^$D$14,"n/a") -> 1945126.2 | D37: =IF($A37>D$33,SUMPRODUCT($B$17:$D$17/(1+$A37)^$B$14:$D$14)+$D$17*(1+D$33)/($A37-D$33)/(1+$A37)^$D$14,"n/a") -> 1998492.9 | E37: =IF($A37>E$33,SUMPRODUCT($B$17:$D$17/(1+$A37)^$B$14:$D$14)+$D$17*(1+E$33)/($A37-E$33)/(1+$A37)^$D$14,"n/a") -> 2055540 | F37: =IF($A37>F$33,SUMPRODUCT($B$17:$D$17/(1+$A37)^$B$14:$D$14)+$D$17*(1+F$33)/($A37-F$33)/(1+$A37)^$D$14,"n/a") -> 2116662
A38: =$B$6+(2)*$B$10 -> 0.18 | B38: =IF($A38>B$33,SUMPRODUCT($B$17:$D$17/(1+$A38)^$B$14:$D$14)+$D$17*(1+B$33)/($A38-B$33)/(1+$A38)^$D$14,"n/a") -> 1774775.8 | C38: =IF($A38>C$33,SUMPRODUCT($B$17:$D$17/(1+$A38)^$B$14:$D$14)+$D$17*(1+C$33)/($A38-C$33)/(1+$A38)^$D$14,"n/a") -> 1818263.7 | D38: =IF($A38>D$33,SUMPRODUCT($B$17:$D$17/(1+$A38)^$B$14:$D$14)+$D$17*(1+D$33)/($A38-D$33)/(1+$A38)^$D$14,"n/a") -> 1864469.5 | E38: =IF($A38>E$33,SUMPRODUCT($B$17:$D$17/(1+$A38)^$B$14:$D$14)+$D$17*(1+E$33)/($A38-E$33)/(1+$A38)^$D$14,"n/a") -> 1913656.4 | F38: =IF($A38>F$33,SUMPRODUCT($B$17:$D$17/(1+$A38)^$B$14:$D$14)+$D$17*(1+F$33)/($A38-F$33)/(1+$A38)^$D$14,"n/a") -> 1966122.4
A40: Free cash flow = operating cash flow + interest × (1 − tax rate) − capital spending. Cells marked n/a: WACC not above growth.

Sheet Sources & Uses
A1: Sources and uses of funds | E1: =HYPERLINK("#'Cover'!A1","◂ Contents") -> ◂ Contents
A2: Live for the selected scenario. Where the money comes from and where it goes in the period set below.
A3: Scenario shown | B3: =CHOOSE(Dashboard!$B$4,"Low","Base","High") -> Base
A5: Funding structure ($'000) — raised at the start of the plan
B6: Amount | C6: Share
A7: Equity | B7: =Inputs!$E$54 -> 100000 | C7: =IF($B$9=0,0,B7/$B$9) -> 0.28571429
A8: Debt (loan) | B8: =Inputs!$E$55 -> 250000 | C8: =IF($B$9=0,0,B8/$B$9) -> 0.71428571
A9: Total funding | B9: =B7+B8 -> 350000 | C9: =IF(B9=0,0,1) -> 1
A10: Gearing (debt ÷ equity) | B10: =IF(B7<=0,IF(B8>0,"n/a",0),B8/B7) -> 2.5 | D10: n/a: debt without positive equity
A11: Funding required by the plan (Break-even sheet) | B11: ='Break-even'!B12 -> 108761.88
A12: Funding surplus / (shortfall) | B12: ='Break-even'!B17 -> 241238.12
A14: ="Sources and uses of cash in the first "&$B$16&IF($B$16=1," month"," months")&" ($'000)" -> Sources and uses of cash in the first 12 months ($'000)
A15: Period covered (months from the start) | B15: 12 | D15: 1 to 36 (capped)
A16: Months used | B16: =MIN(36,MAX(1,ROUND(B15,0))) -> 12
A17: Sources | B17: Amount | C17: Share
A18: Equity raised | B18: =SUMPRODUCT(--(Monthly!$C$4:$AL$4<=$B$16),Monthly!$C$76:$AL$76) -> 100000 | C18: =IF($B$21=0,0,B18/$B$21) -> 0.18358366
A19: Loan drawdowns | B19: =SUMPRODUCT(--(Monthly!$C$4:$AL$4<=$B$16),Monthly!$C$61:$AL$61) -> 250000 | C19: =IF($B$21=0,0,B19/$B$21) -> 0.45895914
A20: Cash generated by operations | B20: =MAX(0,SUMPRODUCT(--(Monthly!$C$4:$AL$4<=$B$16),Monthly!$C$74:$AL$74)) -> 194710.8 | C20: =IF($B$21=0,0,B20/$B$21) -> 0.35745721
A21: Total sources | B21: =SUM(B18:B20) -> 544710.8 | C21: =IF(B21=0,0,1) -> 1
A23: Uses | B23: Amount | C23: Share
A24: Cash used by operations | B24: =MAX(0,-SUMPRODUCT(--(Monthly!$C$4:$AL$4<=$B$16),Monthly!$C$74:$AL$74)) -> 0 | C24: =IF($B$28=0,0,B24/$B$28) -> 0
A25: Capital spending | B25: =-SUMPRODUCT(--(Monthly!$C$4:$AL$4<=$B$16),Monthly!$C$75:$AL$75) -> 20000 | C25: =IF($B$28=0,0,B25/$B$28) -> 0.036716731
A26: Loan repayments | B26: =-SUMPRODUCT(--(Monthly!$C$4:$AL$4<=$B$16),Monthly!$C$62:$AL$62) -> 45833.333 | C26: =IF($B$28=0,0,B26/$B$28) -> 0.084142509
A27: Cash at the end of the period | B27: =INDEX(Monthly!$C$80:$AL$80,$B$16) -> 478877.47 | C27: =IF($B$28=0,0,B27/$B$28) -> 0.87914076
A28: Total uses | B28: =SUM(B24:B27) -> 544710.8 | C28: =IF(B28=0,0,1) -> 1
A29: Sources − uses (must be 0; opening cash is 0) | B29: =B21-B28 -> 0

Sheet KPIs
A1: KPIs & ratios | G1: =HYPERLINK("#'Cover'!A1","◂ Contents") -> ◂ Contents
A2: Home services financial model (growing) — industry metrics and financial ratios for the active scenario
A4: Financial ratios
B5: 1 | C5: 2 | D5: 3 | E5: Target
A6: Revenue growth | B6: =IF(N('P&L'!A5)<=0,"n/a",'P&L'!B5/'P&L'!A5-1) -> n/a | C6: =IF(N('P&L'!B5)<=0,"n/a",'P&L'!C5/'P&L'!B5-1) -> 0.17862549 | D6: =IF(N('P&L'!C5)<=0,"n/a",'P&L'!D5/'P&L'!C5-1) -> 0.17895235
A7: Gross margin | B7: =IF('P&L'!B5<=0,"n/a",'P&L'!B7/'P&L'!B5) -> 0.38585434 | C7: =IF('P&L'!C5<=0,"n/a",'P&L'!C7/'P&L'!C5) -> 0.39481791 | D7: =IF('P&L'!D5<=0,"n/a",'P&L'!D7/'P&L'!D5) -> 0.40356802
A8: EBITDA margin | B8: =IF('P&L'!B5<=0,"n/a",'P&L'!B17/'P&L'!B5) -> 0.15559475 | C8: =IF('P&L'!C5<=0,"n/a",'P&L'!C17/'P&L'!C5) -> 0.17989534 | D8: =IF('P&L'!D5<=0,"n/a",'P&L'!D17/'P&L'!D5) -> 0.2021959
A9: Net margin | B9: =IF('P&L'!B5<=0,"n/a",'P&L'!B24/'P&L'!B5) -> 0.11260871 | C9: =IF('P&L'!C5<=0,"n/a",'P&L'!C24/'P&L'!C5) -> 0.13196803 | D9: =IF('P&L'!D5<=0,"n/a",'P&L'!D24/'P&L'!D5) -> 0.14964082
A10: Payroll, % of revenue | B10: =IF('P&L'!B5<=0,"n/a",-SUMIF(Headcount!$C$5:$AL$5,B$5,Headcount!$C$15:$AL$15)/'P&L'!B5) -> 0.35239148 | C10: =IF('P&L'!C5<=0,"n/a",-SUMIF(Headcount!$C$5:$AL$5,C$5,Headcount!$C$15:$AL$15)/'P&L'!C5) -> 0.34385137 | D10: =IF('P&L'!D5<=0,"n/a",-SUMIF(Headcount!$C$5:$AL$5,D$5,Headcount!$C$15:$AL$15)/'P&L'!D5) -> 0.33544052
A11: Marketing, % of revenue | B11: =IF('P&L'!B5<=0,"n/a",-'P&L'!B10/'P&L'!B5) -> 0.063156787 | C11: =IF('P&L'!C5<=0,"n/a",-'P&L'!C10/'P&L'!C5) -> 0.061622886 | D11: =IF('P&L'!D5<=0,"n/a",-'P&L'!D10/'P&L'!D5) -> 0.060109571
A12: Operating expenses, % of revenue | B12: =IF('P&L'!B5<=0,"n/a",-'P&L'!B16/'P&L'!B5) -> 0.23025959 | C12: =IF('P&L'!C5<=0,"n/a",-'P&L'!C16/'P&L'!C5) -> 0.21492256 | D12: =IF('P&L'!D5<=0,"n/a",-'P&L'!D16/'P&L'!D5) -> 0.20137211
A13: Current ratio (current assets ÷ current liabilities) | B13: =IF(('Balance Sheet'!B12-'Balance Sheet'!B11)<=0,"n/a",('Balance Sheet'!B5+'Balance Sheet'!B6+'Balance Sheet'!B7)/('Balance Sheet'!B12-'Balance Sheet'!B11)) -> 9.4585262 | C13: =IF(('Balance Sheet'!C12-'Balance Sheet'!C11)<=0,"n/a",('Balance Sheet'!C5+'Balance Sheet'!C6+'Balance Sheet'!C7)/('Balance Sheet'!C12-'Balance Sheet'!C11)) -> 11.130782 | D13: =IF(('Balance Sheet'!D12-'Balance Sheet'!D11)<=0,"n/a",('Balance Sheet'!D5+'Balance Sheet'!D6+'Balance Sheet'!D7)/('Balance Sheet'!D12-'Balance Sheet'!D11)) -> 13.369884
A14: Debt ÷ equity (loan ÷ total equity) | B14: =IF('Balance Sheet'!B15<=0,"n/a",'Balance Sheet'!B11/'Balance Sheet'!B15) -> 0.69785235 | C14: =IF('Balance Sheet'!C15<=0,"n/a",'Balance Sheet'!C11/'Balance Sheet'!C15) -> 0.27601533 | D14: =IF('Balance Sheet'!D15<=0,"n/a",'Balance Sheet'!D11/'Balance Sheet'!D15) -> 0.11395363
A15: Return on assets (net income ÷ year-end assets) | B15: =IF('Balance Sheet'!B9<=0,"n/a",'P&L'!B24/'Balance Sheet'!B9) -> 0.34786219 | C15: =IF('Balance Sheet'!C9<=0,"n/a",'P&L'!C24/'Balance Sheet'!C9) -> 0.34148453 | D15: =IF('Balance Sheet'!D9<=0,"n/a",'P&L'!D24/'Balance Sheet'!D9) -> 0.32460871
A16: Return on equity (net income ÷ year-end equity) | B16: =IF('Balance Sheet'!B15<=0,"n/a",'P&L'!B24/'Balance Sheet'!B15) -> 0.65819477 | C16: =IF('Balance Sheet'!C15<=0,"n/a",'P&L'!C24/'Balance Sheet'!C15) -> 0.47620179 | D16: =IF('Balance Sheet'!D15<=0,"n/a",'P&L'!D24/'Balance Sheet'!D15) -> 0.38897823
A18: DuPont analysis — return on equity = net margin × asset turnover × equity multiplier
B19: 1 | C19: 2 | D19: 3
