Workbook

Sheet Cover
B2: Pet grooming & boarding financial model (planning)
B3: 3-year financial model · monthly detail · Low / Base / High scenarios · US dollars · Full plan
B5: Purpose | D5: Revenue and profit plan
B6: Active scenario | D6: =Dashboard!C4&" (change it on the Dashboard, cell B4)" -> Base (change it on the Dashboard, cell B4)
B7: Model checks | D7: =Checks!B25 -> PASS
B8: Prepared | D8: 22 October 2026
B10: Contents
C11: PRESENTATION
B12: 1 | C12: =HYPERLINK("#Dashboard!A1","Dashboard") -> Dashboard | D12: Scenario switch, key numbers, core financials
B13: 2 | C13: =HYPERLINK("#Summary!A1","Summary") -> Summary | D13: Income statement, cash flow and balance sheet — every year and any year by month
B14: 3 | C14: =HYPERLINK("#Scenarios!A1","Scenarios") -> Scenarios | D14: Low / Base / High side by side: drivers, outputs, charts
B15: 4 | C15: =HYPERLINK("#'Break-even'!A1","Break-even") -> Break-even | D15: Startup costs, funding need, break-even timing and revenue
B16: 5 | C16: =HYPERLINK("#Valuation!A1","Valuation") -> Valuation | D16: Free cash flow, DCF (perpetual growth and exit multiple), WACC × growth sensitivity
B17: 6 | C17: =HYPERLINK("#'Sources & Uses'!A1","Sources & Uses") -> Sources & Uses | D17: Funding structure, sources and uses of cash for the first months
B18: 7 | C18: =HYPERLINK("#KPIs!A1","KPIs") -> KPIs | D18: Financial ratios, DuPont analysis, industry metrics
C19: INPUTS
B20: 8 | C20: =HYPERLINK("#Inputs!A1","Inputs") -> Inputs | D20: Every assumption, Low / Base / High, with units and comments
C21: STATEMENTS
B22: 9 | C22: =HYPERLINK("#'P&L'!A1","P&L") -> P&L | D22: Annual profit & loss
B23: 10 | C23: =HYPERLINK("#'Cash Flow'!A1","Cash Flow") -> Cash Flow | D23: Annual cash flow statement
B24: 11 | C24: =HYPERLINK("#'Balance Sheet'!A1","Balance Sheet") -> Balance Sheet | D24: Balance sheet at year end
C25: CALCULATIONS
B26: 12 | C26: =HYPERLINK("#Monthly!A1","Monthly") -> Monthly | D26: Month-by-month engine of the model
B27: 13 | C27: =HYPERLINK("#Headcount!A1","Headcount") -> Headcount | D27: Team and payroll
B28: 14 | C28: =HYPERLINK("#'Scenario calc'!A1","Scenario calc") -> Scenario calc | D28: Low, Base and High calculated side by side for the Scenarios sheet
C29: CONTROL
B30: 15 | C30: =HYPERLINK("#Checks!A1","Checks") -> Checks | D30: Live integrity checks and the overall verdict
B32: How to read this file
C33: 1000 | D33: Input you can change — yellow cell with a blue figure (Inputs sheet and the view switches)
C34: 1000 | D34: Formula — calculated, do not overwrite
C35: 1000 | D35: Link to another sheet
C36: 1000 | D36: Active value the model uses (follows the scenario)

Sheet Dashboard
A1: Dashboard | W1: =HYPERLINK("#'Cover'!A1","◂ Contents") -> ◂ Contents
A2: Pet grooming & boarding financial model (planning)
A4: Active scenario | B4: 2 | C4: =CHOOSE(B4,"Low","Base","High") -> Base | D4: 1 = Low · 2 = Base · 3 = High — every sheet follows this cell | S4: Model checks | T4: =Checks!B25 -> PASS
A6: REVENUE · YEAR 3 | C6: EBITDA MARGIN · YEAR 3 | H6: NET INCOME · YEAR 3 | L6: LOWEST CASH BALANCE | P6: FUNDING REQUIRED | T6: ENTERPRISE VALUE (DCF)
A7: =D12 -> 886367.9 | C7: =D17 -> 0.15891443 | H7: =D18 -> 90211.054 | L7: =F39 -> 147500.34 | P7: =F37 -> 391499.66 | T7: =F44 -> 194767.25
A8: =IF(AND(B12>0,D12>=0),(D12/B12)^(1/2)-1,"CAGR n/a") -> 0.24211343 | C8: =D16 -> 140856.65 | H8: =D19 -> 0.10177608 | L8: ='Break-even'!B6 -> 10 | P8: =IF(F38>=0,"Covered by funding raised",-F38) -> Covered by funding raised | T8: Average of 2 methods
A10: Core financials ($'000) — active scenario
B11: 1 | C11: 2 | D11: 3
A12: Revenue | B12: =SUMIF(Monthly!$C$5:$AL$5,B$11,Monthly!$C$31:$AL$31) -> 574501.95 | C12: =SUMIF(Monthly!$C$5:$AL$5,C$11,Monthly!$C$31:$AL$31) -> 835486.76 | D12: =SUMIF(Monthly!$C$5:$AL$5,D$11,Monthly!$C$31:$AL$31) -> 886367.9
A13: Gross profit | B13: =SUMIF(Monthly!$C$5:$AL$5,B$11,Monthly!$C$40:$AL$40) -> 369936.66 | C13: =SUMIF(Monthly!$C$5:$AL$5,C$11,Monthly!$C$40:$AL$40) -> 556642.48 | D13: =SUMIF(Monthly!$C$5:$AL$5,D$11,Monthly!$C$40:$AL$40) -> 592006.05
A14: Gross margin | B14: =IF(B12=0,0,B13/B12) -> 0.64392586 | C14: =IF(C12=0,0,C13/C12) -> 0.66624932 | D14: =IF(D12=0,0,D13/D12) -> 0.66790105
A15: Operating expenses | B15: =SUMIF(Monthly!$C$5:$AL$5,B$11,Monthly!$C$49:$AL$49) -> -434085.06 | C15: =SUMIF(Monthly!$C$5:$AL$5,C$11,Monthly!$C$49:$AL$49) -> -444760.1 | D15: =SUMIF(Monthly!$C$5:$AL$5,D$11,Monthly!$C$49:$AL$49) -> -451149.4
A16: EBITDA | B16: =SUMIF(Monthly!$C$5:$AL$5,B$11,Monthly!$C$50:$AL$50) -> -64148.399 | C16: =SUMIF(Monthly!$C$5:$AL$5,C$11,Monthly!$C$50:$AL$50) -> 111882.38 | D16: =SUMIF(Monthly!$C$5:$AL$5,D$11,Monthly!$C$50:$AL$50) -> 140856.65
A17: EBITDA margin | B17: =IF(B12=0,0,B16/B12) -> -0.11165915 | C17: =IF(C12=0,0,C16/C12) -> 0.13391281 | D17: =IF(D12=0,0,D16/D12) -> 0.15891443
A18: Net income | B18: =SUMIF(Monthly!$C$5:$AL$5,B$11,Monthly!$C$59:$AL$59) -> -96017.149 | C18: =SUMIF(Monthly!$C$5:$AL$5,C$11,Monthly!$C$59:$AL$59) -> 80557.379 | D18: =SUMIF(Monthly!$C$5:$AL$5,D$11,Monthly!$C$59:$AL$59) -> 90211.054
A19: Net margin | B19: =IF(B12=0,0,B18/B12) -> -0.16713111 | C19: =IF(C12=0,0,C18/C12) -> 0.096419695 | D19: =IF(D12=0,0,D18/D12) -> 0.10177608
A20: Operating cash flow | B20: =SUMIF(Monthly!$C$5:$AL$5,B$11,Monthly!$C$89:$AL$89) -> -62809.527 | C20: =SUMIF(Monthly!$C$5:$AL$5,C$11,Monthly!$C$89:$AL$89) -> 105940.94 | D20: =SUMIF(Monthly!$C$5:$AL$5,D$11,Monthly!$C$89:$AL$89) -> 116873.34
A21: Investing cash flow | B21: =SUMIF(Monthly!$C$5:$AL$5,B$11,Monthly!$C$90:$AL$90) -> -189000 | C21: =SUMIF(Monthly!$C$5:$AL$5,C$11,Monthly!$C$90:$AL$90) -> -10000 | D21: =SUMIF(Monthly!$C$5:$AL$5,D$11,Monthly!$C$90:$AL$90) -> -10000
A22: Financing cash flow | B22: =SUMIF(Monthly!$C$5:$AL$5,B$11,Monthly!$C$92:$AL$92) -> 411666.67 | C22: =SUMIF(Monthly!$C$5:$AL$5,C$11,Monthly!$C$92:$AL$92) -> -20000 | D22: =SUMIF(Monthly!$C$5:$AL$5,D$11,Monthly!$C$92:$AL$92) -> -20000
A23: Net change in cash | B23: =SUMIF(Monthly!$C$5:$AL$5,B$11,Monthly!$C$93:$AL$93) -> 159857.14 | C23: =SUMIF(Monthly!$C$5:$AL$5,C$11,Monthly!$C$93:$AL$93) -> 75940.942 | D23: =SUMIF(Monthly!$C$5:$AL$5,D$11,Monthly!$C$93:$AL$93) -> 86873.338
A24: Year-end cash | B24: =INDEX(Monthly!$C$95:$AL$95,B$11*12) -> 159857.14 | C24: =INDEX(Monthly!$C$95:$AL$95,C$11*12) -> 235798.08 | D24: =INDEX(Monthly!$C$95:$AL$95,D$11*12) -> 322671.42
A26: Pet care metrics
B27: 1 | C27: 2 | D27: 3
A28: Grooms completed | B28: =KPIs!B30 -> 3619.2 | C28: =KPIs!C30 -> 5141.76 | D28: =KPIs!D30 -> 5296.0128
A29: Grooming capacity used | B29: =KPIs!B32 -> 0.52727273 | C29: =KPIs!C32 -> 0.74909091 | D29: =KPIs!D32 -> 0.77156364
A30: Boarding occupancy | B30: =KPIs!B36 -> 0.45539 | C30: =KPIs!C36 -> 0.6386 | D30: =KPIs!D36 -> 0.657758
A31: Boarding revenue per available run-night | B31: =KPIs!B43 -> 25.04645 | C31: =KPIs!C43 -> 36.17669 | D31: =KPIs!D43 -> 38.37985
A32: Team (FTE, year end) | B32: =INDEX(Headcount!$C$11:$AL$11,B$27*12) -> 8 | C32: =INDEX(Headcount!$C$11:$AL$11,C$27*12) -> 8 | D32: =INDEX(Headcount!$C$11:$AL$11,D$27*12) -> 8
A34: Funding & valuation ($'000) — active scenario
A35: Equity raised | F35: =Inputs!$E$71 -> 330000
A36: Loan drawn | F36: =Inputs!$E$72 -> 100000
A37: Funding required (incl. cash buffer) | F37: ='Break-even'!B12 -> 391499.66
A38: Funding surplus / (shortfall) | F38: ='Break-even'!B17 -> 38500.342
A39: ="Lowest cash balance (month "&'Break-even'!B6&")" -> Lowest cash balance (month 10) | F39: ='Break-even'!B18 -> 147500.34
A40: First month with positive EBITDA | F40: ='Break-even'!B21 -> 7
A41: Cash invested paid back | F41: ='Break-even'!B23 -> Not within horizon
A42: Enterprise value — perpetual growth | F42: =Valuation!B27 -> 176034.34
A43: Enterprise value — exit multiple | F43: =Valuation!C27 -> 213500.15
A44: Enterprise value — average | F44: =Valuation!B30 -> 194767.25

Sheet Summary
A1: Financial statements summary | U1: =HYPERLINK("#'Cover'!A1","◂ Contents") -> ◂ Contents
A2: Pet grooming & boarding financial model (planning) | P2: Select detailed year: | R2: 1
A5: Income statement ($'000) — by year | H5: ="Income statement ($'000) — Year "&$R$2&", by month" -> Income statement ($'000) — Year 1, by month
B6: 1 | C6: 2 | D6: 3 | H6: =INDEX(Monthly!$C$4:$AL$4,($R$2-1)*12+1) -> 1 | I6: =INDEX(Monthly!$C$4:$AL$4,($R$2-1)*12+2) -> 2 | J6: =INDEX(Monthly!$C$4:$AL$4,($R$2-1)*12+3) -> 3 | K6: =INDEX(Monthly!$C$4:$AL$4,($R$2-1)*12+4) -> 4 | L6: =INDEX(Monthly!$C$4:$AL$4,($R$2-1)*12+5) -> 5 | M6: =INDEX(Monthly!$C$4:$AL$4,($R$2-1)*12+6) -> 6 | N6: =INDEX(Monthly!$C$4:$AL$4,($R$2-1)*12+7) -> 7 | O6: =INDEX(Monthly!$C$4:$AL$4,($R$2-1)*12+8) -> 8 | P6: =INDEX(Monthly!$C$4:$AL$4,($R$2-1)*12+9) -> 9 | Q6: =INDEX(Monthly!$C$4:$AL$4,($R$2-1)*12+10) -> 10 | R6: =INDEX(Monthly!$C$4:$AL$4,($R$2-1)*12+11) -> 11 | S6: =INDEX(Monthly!$C$4:$AL$4,($R$2-1)*12+12) -> 12
A7: Revenue | B7: ='P&L'!B5 -> 574501.95 | C7: ='P&L'!C5 -> 835486.76 | D7: ='P&L'!D5 -> 886367.9 | H7: =INDEX(Monthly!$C$31:$AL$31,($R$2-1)*12+1) -> 25006.912 | I7: =INDEX(Monthly!$C$31:$AL$31,($R$2-1)*12+2) -> 28757.949 | J7: =INDEX(Monthly!$C$31:$AL$31,($R$2-1)*12+3) -> 32508.986 | K7: =INDEX(Monthly!$C$31:$AL$31,($R$2-1)*12+4) -> 36260.022 | L7: =INDEX(Monthly!$C$31:$AL$31,($R$2-1)*12+5) -> 40011.059 | M7: =INDEX(Monthly!$C$31:$AL$31,($R$2-1)*12+6) -> 50292.928 | N7: =INDEX(Monthly!$C$31:$AL$31,($R$2-1)*12+7) -> 54603.75 | O7: =INDEX(Monthly!$C$31:$AL$31,($R$2-1)*12+8) -> 58914.573 | P7: =INDEX(Monthly!$C$31:$AL$31,($R$2-1)*12+9) -> 55015.206 | Q7: =INDEX(Monthly!$C$31:$AL$31,($R$2-1)*12+10) -> 58766.243 | R7: =INDEX(Monthly!$C$31:$AL$31,($R$2-1)*12+11) -> 62517.28 | S7: =INDEX(Monthly!$C$31:$AL$31,($R$2-1)*12+12) -> 71847.04
A8: Cost of sales | B8: ='P&L'!B6 -> -204565.29 | C8: ='P&L'!C6 -> -278844.28 | D8: ='P&L'!D6 -> -294361.85 | H8: =INDEX(Monthly!$C$39:$AL$39,($R$2-1)*12+1) -> -10970.204 | I8: =INDEX(Monthly!$C$39:$AL$39,($R$2-1)*12+2) -> -12040.734 | J8: =INDEX(Monthly!$C$39:$AL$39,($R$2-1)*12+3) -> -13111.265 | K8: =INDEX(Monthly!$C$39:$AL$39,($R$2-1)*12+4) -> -14181.795 | L8: =INDEX(Monthly!$C$39:$AL$39,($R$2-1)*12+5) -> -15252.326 | M8: =INDEX(Monthly!$C$39:$AL$39,($R$2-1)*12+6) -> -17035.311 | N8: =INDEX(Monthly!$C$39:$AL$39,($R$2-1)*12+7) -> -18166.909 | O8: =INDEX(Monthly!$C$39:$AL$39,($R$2-1)*12+8) -> -19298.507 | P8: =INDEX(Monthly!$C$39:$AL$39,($R$2-1)*12+9) -> -19534.448 | Q8: =INDEX(Monthly!$C$39:$AL$39,($R$2-1)*12+10) -> -20604.979 | R8: =INDEX(Monthly!$C$39:$AL$39,($R$2-1)*12+11) -> -21675.509 | S8: =INDEX(Monthly!$C$39:$AL$39,($R$2-1)*12+12) -> -22693.301
A9: Gross profit | B9: ='P&L'!B7 -> 369936.66 | C9: ='P&L'!C7 -> 556642.48 | D9: ='P&L'!D7 -> 592006.05 | H9: =INDEX(Monthly!$C$40:$AL$40,($R$2-1)*12+1) -> 14036.708 | I9: =INDEX(Monthly!$C$40:$AL$40,($R$2-1)*12+2) -> 16717.215 | J9: =INDEX(Monthly!$C$40:$AL$40,($R$2-1)*12+3) -> 19397.721 | K9: =INDEX(Monthly!$C$40:$AL$40,($R$2-1)*12+4) -> 22078.227 | L9: =INDEX(Monthly!$C$40:$AL$40,($R$2-1)*12+5) -> 24758.733 | M9: =INDEX(Monthly!$C$40:$AL$40,($R$2-1)*12+6) -> 33257.617 | N9: =INDEX(Monthly!$C$40:$AL$40,($R$2-1)*12+7) -> 36436.841 | O9: =INDEX(Monthly!$C$40:$AL$40,($R$2-1)*12+8) -> 39616.066 | P9: =INDEX(Monthly!$C$40:$AL$40,($R$2-1)*12+9) -> 35480.758 | Q9: =INDEX(Monthly!$C$40:$AL$40,($R$2-1)*12+10) -> 38161.264 | R9: =INDEX(Monthly!$C$40:$AL$40,($R$2-1)*12+11) -> 40841.771 | S9: =INDEX(Monthly!$C$40:$AL$40,($R$2-1)*12+12) -> 49153.739
A10: Gross margin | B10: ='P&L'!B8 -> 0.64392586 | C10: ='P&L'!C8 -> 0.66624932 | D10: ='P&L'!D8 -> 0.66790105 | H10: =IF(H7=0,0,H9/H7) -> 0.56131314 | I10: =IF(I7=0,0,I9/I7) -> 0.58130761 | J10: =IF(J7=0,0,J9/J7) -> 0.59668797 | K10: =IF(K7=0,0,K9/K7) -> 0.60888619 | L10: =IF(L7=0,0,L9/L7) -> 0.61879725 | M10: =IF(M7=0,0,M9/M7) -> 0.6612782 | N10: =IF(N7=0,0,N9/N7) -> 0.66729558 | O10: =IF(O7=0,0,O9/O7) -> 0.67243237 | ... S10: =IF(S7=0,0,S9/S7) -> 0.68414424
A11: Total operating expenses | B11: ='P&L'!B15 -> -434085.06 | C11: ='P&L'!C15 -> -444760.1 | D11: ='P&L'!D15 -> -451149.4 | H11: =INDEX(Monthly!$C$49:$AL$49,($R$2-1)*12+1) -> -35487.707 | I11: =INDEX(Monthly!$C$49:$AL$49,($R$2-1)*12+2) -> -35600.238 | J11: =INDEX(Monthly!$C$49:$AL$49,($R$2-1)*12+3) -> -35712.77 | K11: =INDEX(Monthly!$C$49:$AL$49,($R$2-1)*12+4) -> -35825.301 | L11: =INDEX(Monthly!$C$49:$AL$49,($R$2-1)*12+5) -> -35937.832 | M11: =INDEX(Monthly!$C$49:$AL$49,($R$2-1)*12+6) -> -36246.288 | N11: =INDEX(Monthly!$C$49:$AL$49,($R$2-1)*12+7) -> -36375.613 | O11: =INDEX(Monthly!$C$49:$AL$49,($R$2-1)*12+8) -> -36504.937 | P11: =INDEX(Monthly!$C$49:$AL$49,($R$2-1)*12+9) -> -36387.956 | Q11: =INDEX(Monthly!$C$49:$AL$49,($R$2-1)*12+10) -> -36500.487 | R11: =INDEX(Monthly!$C$49:$AL$49,($R$2-1)*12+11) -> -36613.018 | S11: =INDEX(Monthly!$C$49:$AL$49,($R$2-1)*12+12) -> -36892.911
A12: EBITDA | B12: ='P&L'!B16 -> -64148.399 | C12: ='P&L'!C16 -> 111882.38 | D12: ='P&L'!D16 -> 140856.65 | H12: =INDEX(Monthly!$C$50:$AL$50,($R$2-1)*12+1) -> -21450.999 | I12: =INDEX(Monthly!$C$50:$AL$50,($R$2-1)*12+2) -> -18883.024 | J12: =INDEX(Monthly!$C$50:$AL$50,($R$2-1)*12+3) -> -16315.049 | K12: =INDEX(Monthly!$C$50:$AL$50,($R$2-1)*12+4) -> -13747.074 | L12: =INDEX(Monthly!$C$50:$AL$50,($R$2-1)*12+5) -> -11179.099 | M12: =INDEX(Monthly!$C$50:$AL$50,($R$2-1)*12+6) -> -2988.6708 | N12: =INDEX(Monthly!$C$50:$AL$50,($R$2-1)*12+7) -> 61.228875 | O12: =INDEX(Monthly!$C$50:$AL$50,($R$2-1)*12+8) -> 3111.1285 | P12: =INDEX(Monthly!$C$50:$AL$50,($R$2-1)*12+9) -> -907.19801 | Q12: =INDEX(Monthly!$C$50:$AL$50,($R$2-1)*12+10) -> 1660.7771 | R12: =INDEX(Monthly!$C$50:$AL$50,($R$2-1)*12+11) -> 4228.7523 | S12: =INDEX(Monthly!$C$50:$AL$50,($R$2-1)*12+12) -> 12260.827
A13: EBITDA margin | B13: ='P&L'!B17 -> -0.11165915 | C13: ='P&L'!C17 -> 0.13391281 | D13: ='P&L'!D17 -> 0.15891443 | H13: =IF(H7=0,0,H12/H7) -> -0.8578028 | I13: =IF(I7=0,0,I12/I7) -> -0.65661929 | J13: =IF(J7=0,0,J12/J7) -> -0.50186275 | K13: =IF(K7=0,0,K12/K7) -> -0.3791248 | L13: =IF(L7=0,0,L12/L7) -> -0.27940022 | M13: =IF(M7=0,0,M12/M7) -> -0.059425269 | N13: =IF(N7=0,0,N12/N7) -> 0.0011213309 | O13: =IF(O7=0,0,O12/O7) -> 0.052807453 | ... S13: =IF(S7=0,0,S12/S7) -> 0.17065181
A14: Depreciation | B14: ='P&L'!B18 -> -23625 | C14: ='P&L'!C18 -> -24875 | D14: ='P&L'!D18 -> -26125 | H14: =INDEX(Monthly!$C$70:$AL$70,($R$2-1)*12+1) -> -1968.75 | I14: =INDEX(Monthly!$C$70:$AL$70,($R$2-1)*12+2) -> -1968.75 | J14: =INDEX(Monthly!$C$70:$AL$70,($R$2-1)*12+3) -> -1968.75 | K14: =INDEX(Monthly!$C$70:$AL$70,($R$2-1)*12+4) -> -1968.75 | L14: =INDEX(Monthly!$C$70:$AL$70,($R$2-1)*12+5) -> -1968.75 | M14: =INDEX(Monthly!$C$70:$AL$70,($R$2-1)*12+6) -> -1968.75 | N14: =INDEX(Monthly!$C$70:$AL$70,($R$2-1)*12+7) -> -1968.75 | O14: =INDEX(Monthly!$C$70:$AL$70,($R$2-1)*12+8) -> -1968.75 | P14: =INDEX(Monthly!$C$70:$AL$70,($R$2-1)*12+9) -> -1968.75 | Q14: =INDEX(Monthly!$C$70:$AL$70,($R$2-1)*12+10) -> -1968.75 | R14: =INDEX(Monthly!$C$70:$AL$70,($R$2-1)*12+11) -> -1968.75 | S14: =INDEX(Monthly!$C$70:$AL$70,($R$2-1)*12+12) -> -1968.75
A15: EBIT | B15: ='P&L'!B19 -> -87773.399 | C15: ='P&L'!C19 -> 87007.379 | D15: ='P&L'!D19 -> 114731.65 | H15: =INDEX(Monthly!$C$53:$AL$53,($R$2-1)*12+1) -> -23419.749 | I15: =INDEX(Monthly!$C$53:$AL$53,($R$2-1)*12+2) -> -20851.774 | J15: =INDEX(Monthly!$C$53:$AL$53,($R$2-1)*12+3) -> -18283.799 | K15: =INDEX(Monthly!$C$53:$AL$53,($R$2-1)*12+4) -> -15715.824 | L15: =INDEX(Monthly!$C$53:$AL$53,($R$2-1)*12+5) -> -13147.849 | M15: =INDEX(Monthly!$C$53:$AL$53,($R$2-1)*12+6) -> -4957.4208 | N15: =INDEX(Monthly!$C$53:$AL$53,($R$2-1)*12+7) -> -1907.5211 | O15: =INDEX(Monthly!$C$53:$AL$53,($R$2-1)*12+8) -> 1142.3785 | P15: =INDEX(Monthly!$C$53:$AL$53,($R$2-1)*12+9) -> -2875.948 | Q15: =INDEX(Monthly!$C$53:$AL$53,($R$2-1)*12+10) -> -307.97287 | R15: =INDEX(Monthly!$C$53:$AL$53,($R$2-1)*12+11) -> 2260.0023 | S15: =INDEX(Monthly!$C$53:$AL$53,($R$2-1)*12+12) -> 10292.077
A16: Interest | B16: ='P&L'!B20 -> -8243.75 | C16: ='P&L'!C20 -> -6450 | D16: ='P&L'!D20 -> -4650 | H16: =INDEX(Monthly!$C$54:$AL$54,($R$2-1)*12+1) -> -750 | I16: =INDEX(Monthly!$C$54:$AL$54,($R$2-1)*12+2) -> -743.75 | J16: =INDEX(Monthly!$C$54:$AL$54,($R$2-1)*12+3) -> -731.25 | K16: =INDEX(Monthly!$C$54:$AL$54,($R$2-1)*12+4) -> -718.75 | L16: =INDEX(Monthly!$C$54:$AL$54,($R$2-1)*12+5) -> -706.25 | M16: =INDEX(Monthly!$C$54:$AL$54,($R$2-1)*12+6) -> -693.75 | N16: =INDEX(Monthly!$C$54:$AL$54,($R$2-1)*12+7) -> -681.25 | O16: =INDEX(Monthly!$C$54:$AL$54,($R$2-1)*12+8) -> -668.75 | P16: =INDEX(Monthly!$C$54:$AL$54,($R$2-1)*12+9) -> -656.25 | Q16: =INDEX(Monthly!$C$54:$AL$54,($R$2-1)*12+10) -> -643.75 | R16: =INDEX(Monthly!$C$54:$AL$54,($R$2-1)*12+11) -> -631.25 | S16: =INDEX(Monthly!$C$54:$AL$54,($R$2-1)*12+12) -> -618.75
A17: Pre-tax income | B17: ='P&L'!B21 -> -96017.149 | C17: ='P&L'!C21 -> 80557.379 | D17: ='P&L'!D21 -> 110081.65 | H17: =INDEX(Monthly!$C$55:$AL$55,($R$2-1)*12+1) -> -24169.749 | I17: =INDEX(Monthly!$C$55:$AL$55,($R$2-1)*12+2) -> -21595.524 | J17: =INDEX(Monthly!$C$55:$AL$55,($R$2-1)*12+3) -> -19015.049 | K17: =INDEX(Monthly!$C$55:$AL$55,($R$2-1)*12+4) -> -16434.574 | L17: =INDEX(Monthly!$C$55:$AL$55,($R$2-1)*12+5) -> -13854.099 | M17: =INDEX(Monthly!$C$55:$AL$55,($R$2-1)*12+6) -> -5651.1708 | N17: =INDEX(Monthly!$C$55:$AL$55,($R$2-1)*12+7) -> -2588.7711 | O17: =INDEX(Monthly!$C$55:$AL$55,($R$2-1)*12+8) -> 473.62852 | P17: =INDEX(Monthly!$C$55:$AL$55,($R$2-1)*12+9) -> -3532.198 | Q17: =INDEX(Monthly!$C$55:$AL$55,($R$2-1)*12+10) -> -951.72287 | R17: =INDEX(Monthly!$C$55:$AL$55,($R$2-1)*12+11) -> 1628.7523 | S17: =INDEX(Monthly!$C$55:$AL$55,($R$2-1)*12+12) -> 9673.3275
A18: Income tax | B18: ='P&L'!B22 -> 0 | C18: ='P&L'!C22 -> 0 | D18: ='P&L'!D22 -> -19870.594 | H18: =INDEX(Monthly!$C$58:$AL$58,($R$2-1)*12+1) -> 0 | I18: =INDEX(Monthly!$C$58:$AL$58,($R$2-1)*12+2) -> 0 | J18: =INDEX(Monthly!$C$58:$AL$58,($R$2-1)*12+3) -> 0 | K18: =INDEX(Monthly!$C$58:$AL$58,($R$2-1)*12+4) -> 0 | L18: =INDEX(Monthly!$C$58:$AL$58,($R$2-1)*12+5) -> 0 | M18: =INDEX(Monthly!$C$58:$AL$58,($R$2-1)*12+6) -> 0 | N18: =INDEX(Monthly!$C$58:$AL$58,($R$2-1)*12+7) -> 0 | O18: =INDEX(Monthly!$C$58:$AL$58,($R$2-1)*12+8) -> 0 | P18: =INDEX(Monthly!$C$58:$AL$58,($R$2-1)*12+9) -> 0 | Q18: =INDEX(Monthly!$C$58:$AL$58,($R$2-1)*12+10) -> 0 | R18: =INDEX(Monthly!$C$58:$AL$58,($R$2-1)*12+11) -> 0 | S18: =INDEX(Monthly!$C$58:$AL$58,($R$2-1)*12+12) -> 0
A19: Net income | B19: ='P&L'!B23 -> -96017.149 | C19: ='P&L'!C23 -> 80557.379 | D19: ='P&L'!D23 -> 90211.054 | H19: =INDEX(Monthly!$C$59:$AL$59,($R$2-1)*12+1) -> -24169.749 | I19: =INDEX(Monthly!$C$59:$AL$59,($R$2-1)*12+2) -> -21595.524 | J19: =INDEX(Monthly!$C$59:$AL$59,($R$2-1)*12+3) -> -19015.049 | K19: =INDEX(Monthly!$C$59:$AL$59,($R$2-1)*12+4) -> -16434.574 | L19: =INDEX(Monthly!$C$59:$AL$59,($R$2-1)*12+5) -> -13854.099 | M19: =INDEX(Monthly!$C$59:$AL$59,($R$2-1)*12+6) -> -5651.1708 | N19: =INDEX(Monthly!$C$59:$AL$59,($R$2-1)*12+7) -> -2588.7711 | O19: =INDEX(Monthly!$C$59:$AL$59,($R$2-1)*12+8) -> 473.62852 | P19: =INDEX(Monthly!$C$59:$AL$59,($R$2-1)*12+9) -> -3532.198 | Q19: =INDEX(Monthly!$C$59:$AL$59,($R$2-1)*12+10) -> -951.72287 | R19: =INDEX(Monthly!$C$59:$AL$59,($R$2-1)*12+11) -> 1628.7523 | S19: =INDEX(Monthly!$C$59:$AL$59,($R$2-1)*12+12) -> 9673.3275
A20: Net margin | B20: ='P&L'!B24 -> -0.16713111 | C20: ='P&L'!C24 -> 0.096419695 | D20: ='P&L'!D24 -> 0.10177608 | H20: =IF(H7=0,0,H19/H7) -> -0.96652274 | I20: =IF(I7=0,0,I19/I7) -> -0.75094104 | J20: =IF(J7=0,0,J19/J7) -> -0.58491671 | K20: =IF(K7=0,0,K19/K7) -> -0.45324224 | L20: =IF(L7=0,0,L19/L7) -> -0.34625673 | M20: =IF(M7=0,0,M19/M7) -> -0.11236512 | N20: =IF(N7=0,0,N19/N7) -> -0.047410134 | O20: =IF(O7=0,0,O19/O7) -> 0.0080392422 | ... S20: =IF(S7=0,0,S19/S7) -> 0.1346378
A22: Cash flow ($'000) — by year | H22: ="Cash flow ($'000) — Year "&$R$2&", by month" -> Cash flow ($'000) — Year 1, by month
B23: 1 | C23: 2 | D23: 3 | H23: =INDEX(Monthly!$C$4:$AL$4,($R$2-1)*12+1) -> 1 | I23: =INDEX(Monthly!$C$4:$AL$4,($R$2-1)*12+2) -> 2 | J23: =INDEX(Monthly!$C$4:$AL$4,($R$2-1)*12+3) -> 3 | K23: =INDEX(Monthly!$C$4:$AL$4,($R$2-1)*12+4) -> 4 | L23: =INDEX(Monthly!$C$4:$AL$4,($R$2-1)*12+5) -> 5 | M23: =INDEX(Monthly!$C$4:$AL$4,($R$2-1)*12+6) -> 6 | N23: =INDEX(Monthly!$C$4:$AL$4,($R$2-1)*12+7) -> 7 | O23: =INDEX(Monthly!$C$4:$AL$4,($R$2-1)*12+8) -> 8 | P23: =INDEX(Monthly!$C$4:$AL$4,($R$2-1)*12+9) -> 9 | Q23: =INDEX(Monthly!$C$4:$AL$4,($R$2-1)*12+10) -> 10 | R23: =INDEX(Monthly!$C$4:$AL$4,($R$2-1)*12+11) -> 11 | S23: =INDEX(Monthly!$C$4:$AL$4,($R$2-1)*12+12) -> 12
A24: Operating cash flow | B24: ='Cash Flow'!B10 -> -62809.527 | C24: ='Cash Flow'!C10 -> 105940.94 | D24: ='Cash Flow'!D10 -> 116873.34 | H24: =INDEX(Monthly!$C$89:$AL$89,($R$2-1)*12+1) -> -16920.331 | I24: =INDEX(Monthly!$C$89:$AL$89,($R$2-1)*12+2) -> -19198.84 | J24: =INDEX(Monthly!$C$89:$AL$89,($R$2-1)*12+3) -> -16618.365 | K24: =INDEX(Monthly!$C$89:$AL$89,($R$2-1)*12+4) -> -14037.89 | L24: =INDEX(Monthly!$C$89:$AL$89,($R$2-1)*12+5) -> -11457.415 | M24: =INDEX(Monthly!$C$89:$AL$89,($R$2-1)*12+6) -> -3238.6549 | N24: =INDEX(Monthly!$C$89:$AL$89,($R$2-1)*12+7) -> -190.7305 | O24: =INDEX(Monthly!$C$89:$AL$89,($R$2-1)*12+8) -> 2871.6691 | P24: =INDEX(Monthly!$C$89:$AL$89,($R$2-1)*12+9) -> -1154.0609 | Q24: =INDEX(Monthly!$C$89:$AL$89,($R$2-1)*12+10) -> 1444.9607 | R24: =INDEX(Monthly!$C$89:$AL$89,($R$2-1)*12+11) -> 4025.4358 | S24: =INDEX(Monthly!$C$89:$AL$89,($R$2-1)*12+12) -> 11664.695
A25: Capital spending | B25: ='Cash Flow'!B11 -> -189000 | C25: ='Cash Flow'!C11 -> -10000 | D25: ='Cash Flow'!D11 -> -10000 | H25: =INDEX(Monthly!$C$90:$AL$90,($R$2-1)*12+1) -> -189000 | I25: =INDEX(Monthly!$C$90:$AL$90,($R$2-1)*12+2) -> 0 | J25: =INDEX(Monthly!$C$90:$AL$90,($R$2-1)*12+3) -> 0 | K25: =INDEX(Monthly!$C$90:$AL$90,($R$2-1)*12+4) -> 0 | L25: =INDEX(Monthly!$C$90:$AL$90,($R$2-1)*12+5) -> 0 | M25: =INDEX(Monthly!$C$90:$AL$90,($R$2-1)*12+6) -> 0 | N25: =INDEX(Monthly!$C$90:$AL$90,($R$2-1)*12+7) -> 0 | O25: =INDEX(Monthly!$C$90:$AL$90,($R$2-1)*12+8) -> 0 | P25: =INDEX(Monthly!$C$90:$AL$90,($R$2-1)*12+9) -> 0 | Q25: =INDEX(Monthly!$C$90:$AL$90,($R$2-1)*12+10) -> 0 | R25: =INDEX(Monthly!$C$90:$AL$90,($R$2-1)*12+11) -> 0 | S25: =INDEX(Monthly!$C$90:$AL$90,($R$2-1)*12+12) -> 0
A26: Equity raised | B26: ='Cash Flow'!B12 -> 330000 | C26: ='Cash Flow'!C12 -> 0 | D26: ='Cash Flow'!D12 -> 0 | H26: =INDEX(Monthly!$C$91:$AL$91,($R$2-1)*12+1) -> 330000 | I26: =INDEX(Monthly!$C$91:$AL$91,($R$2-1)*12+2) -> 0 | J26: =INDEX(Monthly!$C$91:$AL$91,($R$2-1)*12+3) -> 0 | K26: =INDEX(Monthly!$C$91:$AL$91,($R$2-1)*12+4) -> 0 | L26: =INDEX(Monthly!$C$91:$AL$91,($R$2-1)*12+5) -> 0 | M26: =INDEX(Monthly!$C$91:$AL$91,($R$2-1)*12+6) -> 0 | N26: =INDEX(Monthly!$C$91:$AL$91,($R$2-1)*12+7) -> 0 | O26: =INDEX(Monthly!$C$91:$AL$91,($R$2-1)*12+8) -> 0 | P26: =INDEX(Monthly!$C$91:$AL$91,($R$2-1)*12+9) -> 0 | Q26: =INDEX(Monthly!$C$91:$AL$91,($R$2-1)*12+10) -> 0 | R26: =INDEX(Monthly!$C$91:$AL$91,($R$2-1)*12+11) -> 0 | S26: =INDEX(Monthly!$C$91:$AL$91,($R$2-1)*12+12) -> 0
A27: Loan drawdown | B27: ='Cash Flow'!B13 -> 100000 | C27: ='Cash Flow'!C13 -> 0 | D27: ='Cash Flow'!D13 -> 0 | H27: =INDEX(Monthly!$C$76:$AL$76,($R$2-1)*12+1) -> 100000 | I27: =INDEX(Monthly!$C$76:$AL$76,($R$2-1)*12+2) -> 0 | J27: =INDEX(Monthly!$C$76:$AL$76,($R$2-1)*12+3) -> 0 | K27: =INDEX(Monthly!$C$76:$AL$76,($R$2-1)*12+4) -> 0 | L27: =INDEX(Monthly!$C$76:$AL$76,($R$2-1)*12+5) -> 0 | M27: =INDEX(Monthly!$C$76:$AL$76,($R$2-1)*12+6) -> 0 | N27: =INDEX(Monthly!$C$76:$AL$76,($R$2-1)*12+7) -> 0 | O27: =INDEX(Monthly!$C$76:$AL$76,($R$2-1)*12+8) -> 0 | P27: =INDEX(Monthly!$C$76:$AL$76,($R$2-1)*12+9) -> 0 | Q27: =INDEX(Monthly!$C$76:$AL$76,($R$2-1)*12+10) -> 0 | R27: =INDEX(Monthly!$C$76:$AL$76,($R$2-1)*12+11) -> 0 | S27: =INDEX(Monthly!$C$76:$AL$76,($R$2-1)*12+12) -> 0
A28: Loan repayment | B28: ='Cash Flow'!B14 -> -18333.333 | C28: ='Cash Flow'!C14 -> -20000 | D28: ='Cash Flow'!D14 -> -20000 | H28: =INDEX(Monthly!$C$77:$AL$77,($R$2-1)*12+1) -> 0 | I28: =INDEX(Monthly!$C$77:$AL$77,($R$2-1)*12+2) -> -1666.6667 | J28: =INDEX(Monthly!$C$77:$AL$77,($R$2-1)*12+3) -> -1666.6667 | K28: =INDEX(Monthly!$C$77:$AL$77,($R$2-1)*12+4) -> -1666.6667 | L28: =INDEX(Monthly!$C$77:$AL$77,($R$2-1)*12+5) -> -1666.6667 | M28: =INDEX(Monthly!$C$77:$AL$77,($R$2-1)*12+6) -> -1666.6667 | N28: =INDEX(Monthly!$C$77:$AL$77,($R$2-1)*12+7) -> -1666.6667 | O28: =INDEX(Monthly!$C$77:$AL$77,($R$2-1)*12+8) -> -1666.6667 | P28: =INDEX(Monthly!$C$77:$AL$77,($R$2-1)*12+9) -> -1666.6667 | Q28: =INDEX(Monthly!$C$77:$AL$77,($R$2-1)*12+10) -> -1666.6667 | R28: =INDEX(Monthly!$C$77:$AL$77,($R$2-1)*12+11) -> -1666.6667 | S28: =INDEX(Monthly!$C$77:$AL$77,($R$2-1)*12+12) -> -1666.6667
A29: Financing cash flow | B29: ='Cash Flow'!B15 -> 411666.67 | C29: ='Cash Flow'!C15 -> -20000 | D29: ='Cash Flow'!D15 -> -20000 | H29: =INDEX(Monthly!$C$92:$AL$92,($R$2-1)*12+1) -> 430000 | I29: =INDEX(Monthly!$C$92:$AL$92,($R$2-1)*12+2) -> -1666.6667 | J29: =INDEX(Monthly!$C$92:$AL$92,($R$2-1)*12+3) -> -1666.6667 | K29: =INDEX(Monthly!$C$92:$AL$92,($R$2-1)*12+4) -> -1666.6667 | L29: =INDEX(Monthly!$C$92:$AL$92,($R$2-1)*12+5) -> -1666.6667 | M29: =INDEX(Monthly!$C$92:$AL$92,($R$2-1)*12+6) -> -1666.6667 | N29: =INDEX(Monthly!$C$92:$AL$92,($R$2-1)*12+7) -> -1666.6667 | O29: =INDEX(Monthly!$C$92:$AL$92,($R$2-1)*12+8) -> -1666.6667 | P29: =INDEX(Monthly!$C$92:$AL$92,($R$2-1)*12+9) -> -1666.6667 | Q29: =INDEX(Monthly!$C$92:$AL$92,($R$2-1)*12+10) -> -1666.6667 | R29: =INDEX(Monthly!$C$92:$AL$92,($R$2-1)*12+11) -> -1666.6667 | S29: =INDEX(Monthly!$C$92:$AL$92,($R$2-1)*12+12) -> -1666.6667
A30: Net change in cash | B30: ='Cash Flow'!B16 -> 159857.14 | C30: ='Cash Flow'!C16 -> 75940.942 | D30: ='Cash Flow'!D16 -> 86873.338 | H30: =INDEX(Monthly!$C$93:$AL$93,($R$2-1)*12+1) -> 224079.67 | I30: =INDEX(Monthly!$C$93:$AL$93,($R$2-1)*12+2) -> -20865.507 | J30: =INDEX(Monthly!$C$93:$AL$93,($R$2-1)*12+3) -> -18285.032 | K30: =INDEX(Monthly!$C$93:$AL$93,($R$2-1)*12+4) -> -15704.557 | L30: =INDEX(Monthly!$C$93:$AL$93,($R$2-1)*12+5) -> -13124.082 | M30: =INDEX(Monthly!$C$93:$AL$93,($R$2-1)*12+6) -> -4905.3216 | N30: =INDEX(Monthly!$C$93:$AL$93,($R$2-1)*12+7) -> -1857.3972 | O30: =INDEX(Monthly!$C$93:$AL$93,($R$2-1)*12+8) -> 1205.0025 | P30: =INDEX(Monthly!$C$93:$AL$93,($R$2-1)*12+9) -> -2820.7275 | Q30: =INDEX(Monthly!$C$93:$AL$93,($R$2-1)*12+10) -> -221.70597 | R30: =INDEX(Monthly!$C$93:$AL$93,($R$2-1)*12+11) -> 2358.7692 | S30: =INDEX(Monthly!$C$93:$AL$93,($R$2-1)*12+12) -> 9998.0284
A31: Closing cash | B31: ='Cash Flow'!B18 -> 159857.14 | C31: ='Cash Flow'!C18 -> 235798.08 | D31: ='Cash Flow'!D18 -> 322671.42 | H31: =INDEX(Monthly!$C$95:$AL$95,($R$2-1)*12+1) -> 224079.67 | I31: =INDEX(Monthly!$C$95:$AL$95,($R$2-1)*12+2) -> 203214.16 | J31: =INDEX(Monthly!$C$95:$AL$95,($R$2-1)*12+3) -> 184929.13 | K31: =INDEX(Monthly!$C$95:$AL$95,($R$2-1)*12+4) -> 169224.57 | L31: =INDEX(Monthly!$C$95:$AL$95,($R$2-1)*12+5) -> 156100.49 | M31: =INDEX(Monthly!$C$95:$AL$95,($R$2-1)*12+6) -> 151195.17 | N31: =INDEX(Monthly!$C$95:$AL$95,($R$2-1)*12+7) -> 149337.77 | O31: =INDEX(Monthly!$C$95:$AL$95,($R$2-1)*12+8) -> 150542.78 | P31: =INDEX(Monthly!$C$95:$AL$95,($R$2-1)*12+9) -> 147722.05 | Q31: =INDEX(Monthly!$C$95:$AL$95,($R$2-1)*12+10) -> 147500.34 | R31: =INDEX(Monthly!$C$95:$AL$95,($R$2-1)*12+11) -> 149859.11 | S31: =INDEX(Monthly!$C$95:$AL$95,($R$2-1)*12+12) -> 159857.14
A39: Balance sheet at year end ($'000) | H39: ="Balance sheet at month end ($'000) — Year "&$R$2 -> Balance sheet at month end ($'000) — Year 1
B40: 1 | C40: 2 | D40: 3 | H40: =INDEX(Monthly!$C$4:$AL$4,($R$2-1)*12+1) -> 1 | I40: =INDEX(Monthly!$C$4:$AL$4,($R$2-1)*12+2) -> 2 | J40: =INDEX(Monthly!$C$4:$AL$4,($R$2-1)*12+3) -> 3 | K40: =INDEX(Monthly!$C$4:$AL$4,($R$2-1)*12+4) -> 4 | L40: =INDEX(Monthly!$C$4:$AL$4,($R$2-1)*12+5) -> 5 | M40: =INDEX(Monthly!$C$4:$AL$4,($R$2-1)*12+6) -> 6 | N40: =INDEX(Monthly!$C$4:$AL$4,($R$2-1)*12+7) -> 7 | O40: =INDEX(Monthly!$C$4:$AL$4,($R$2-1)*12+8) -> 8 | P40: =INDEX(Monthly!$C$4:$AL$4,($R$2-1)*12+9) -> 9 | Q40: =INDEX(Monthly!$C$4:$AL$4,($R$2-1)*12+10) -> 10 | R40: =INDEX(Monthly!$C$4:$AL$4,($R$2-1)*12+11) -> 11 | S40: =INDEX(Monthly!$C$4:$AL$4,($R$2-1)*12+12) -> 12
A41: Cash | B41: ='Balance Sheet'!B5 -> 159857.14 | C41: ='Balance Sheet'!C5 -> 235798.08 | D41: ='Balance Sheet'!D5 -> 322671.42 | H41: =INDEX(Monthly!$C$95:$AL$95,($R$2-1)*12+1) -> 224079.67 | I41: =INDEX(Monthly!$C$95:$AL$95,($R$2-1)*12+2) -> 203214.16 | J41: =INDEX(Monthly!$C$95:$AL$95,($R$2-1)*12+3) -> 184929.13 | K41: =INDEX(Monthly!$C$95:$AL$95,($R$2-1)*12+4) -> 169224.57 | L41: =INDEX(Monthly!$C$95:$AL$95,($R$2-1)*12+5) -> 156100.49 | M41: =INDEX(Monthly!$C$95:$AL$95,($R$2-1)*12+6) -> 151195.17 | N41: =INDEX(Monthly!$C$95:$AL$95,($R$2-1)*12+7) -> 149337.77 | O41: =INDEX(Monthly!$C$95:$AL$95,($R$2-1)*12+8) -> 150542.78 | P41: =INDEX(Monthly!$C$95:$AL$95,($R$2-1)*12+9) -> 147722.05 | Q41: =INDEX(Monthly!$C$95:$AL$95,($R$2-1)*12+10) -> 147500.34 | R41: =INDEX(Monthly!$C$95:$AL$95,($R$2-1)*12+11) -> 149859.11 | S41: =INDEX(Monthly!$C$95:$AL$95,($R$2-1)*12+12) -> 159857.14
A42: Accounts receivable | B42: ='Balance Sheet'!B6 -> 4789.8027 | C42: ='Balance Sheet'!C6 -> 5081.5016 | D42: ='Balance Sheet'!D6 -> 5390.9651 | H42: =INDEX(Monthly!$C$81:$AL$81,($R$2-1)*12+1) -> 1667.1275 | I42: =INDEX(Monthly!$C$81:$AL$81,($R$2-1)*12+2) -> 1917.1966 | J42: =INDEX(Monthly!$C$81:$AL$81,($R$2-1)*12+3) -> 2167.2657 | K42: =INDEX(Monthly!$C$81:$AL$81,($R$2-1)*12+4) -> 2417.3348 | L42: =INDEX(Monthly!$C$81:$AL$81,($R$2-1)*12+5) -> 2667.4039 | M42: =INDEX(Monthly!$C$81:$AL$81,($R$2-1)*12+6) -> 3352.8619 | N42: =INDEX(Monthly!$C$81:$AL$81,($R$2-1)*12+7) -> 3640.25 | O42: =INDEX(Monthly!$C$81:$AL$81,($R$2-1)*12+8) -> 3927.6382 | P42: =INDEX(Monthly!$C$81:$AL$81,($R$2-1)*12+9) -> 3667.6804 | Q42: =INDEX(Monthly!$C$81:$AL$81,($R$2-1)*12+10) -> 3917.7495 | R42: =INDEX(Monthly!$C$81:$AL$81,($R$2-1)*12+11) -> 4167.8187 | S42: =INDEX(Monthly!$C$81:$AL$81,($R$2-1)*12+12) -> 4789.8027
A43: Inventory | B43: ='Balance Sheet'!B7 -> 4538.6603 | C43: ='Balance Sheet'!C7 -> 4791.3747 | D43: ='Balance Sheet'!D7 -> 5058.7687 | H43: =INDEX(Monthly!$C$82:$AL$82,($R$2-1)*12+1) -> 2194.0407 | I43: =INDEX(Monthly!$C$82:$AL$82,($R$2-1)*12+2) -> 2408.1469 | J43: =INDEX(Monthly!$C$82:$AL$82,($R$2-1)*12+3) -> 2622.253 | K43: =INDEX(Monthly!$C$82:$AL$82,($R$2-1)*12+4) -> 2836.3591 | L43: =INDEX(Monthly!$C$82:$AL$82,($R$2-1)*12+5) -> 3050.4652 | M43: =INDEX(Monthly!$C$82:$AL$82,($R$2-1)*12+6) -> 3407.0622 | N43: =INDEX(Monthly!$C$82:$AL$82,($R$2-1)*12+7) -> 3633.3818 | O43: =INDEX(Monthly!$C$82:$AL$82,($R$2-1)*12+8) -> 3859.7014 | P43: =INDEX(Monthly!$C$82:$AL$82,($R$2-1)*12+9) -> 3906.8896 | Q43: =INDEX(Monthly!$C$82:$AL$82,($R$2-1)*12+10) -> 4120.9958 | R43: =INDEX(Monthly!$C$82:$AL$82,($R$2-1)*12+11) -> 4335.1019 | S43: =INDEX(Monthly!$C$82:$AL$82,($R$2-1)*12+12) -> 4538.6603
A44: Net fixed assets | B44: ='Balance Sheet'!B8 -> 165375 | C44: ='Balance Sheet'!C8 -> 150500 | D44: ='Balance Sheet'!D8 -> 134375 | H44: =INDEX(Monthly!$C$72:$AL$72,($R$2-1)*12+1) -> 187031.25 | I44: =INDEX(Monthly!$C$72:$AL$72,($R$2-1)*12+2) -> 185062.5 | J44: =INDEX(Monthly!$C$72:$AL$72,($R$2-1)*12+3) -> 183093.75 | K44: =INDEX(Monthly!$C$72:$AL$72,($R$2-1)*12+4) -> 181125 | L44: =INDEX(Monthly!$C$72:$AL$72,($R$2-1)*12+5) -> 179156.25 | M44: =INDEX(Monthly!$C$72:$AL$72,($R$2-1)*12+6) -> 177187.5 | N44: =INDEX(Monthly!$C$72:$AL$72,($R$2-1)*12+7) -> 175218.75 | O44: =INDEX(Monthly!$C$72:$AL$72,($R$2-1)*12+8) -> 173250 | P44: =INDEX(Monthly!$C$72:$AL$72,($R$2-1)*12+9) -> 171281.25 | Q44: =INDEX(Monthly!$C$72:$AL$72,($R$2-1)*12+10) -> 169312.5 | R44: =INDEX(Monthly!$C$72:$AL$72,($R$2-1)*12+11) -> 167343.75 | S44: =INDEX(Monthly!$C$72:$AL$72,($R$2-1)*12+12) -> 165375
A45: Total assets | B45: ='Balance Sheet'!B9 -> 334560.6 | C45: ='Balance Sheet'!C9 -> 396170.96 | D45: ='Balance Sheet'!D9 -> 467496.15 | H45: =INDEX(Monthly!$C$109:$AL$109,($R$2-1)*12+1) -> 414972.09 | I45: =INDEX(Monthly!$C$109:$AL$109,($R$2-1)*12+2) -> 392602.01 | J45: =INDEX(Monthly!$C$109:$AL$109,($R$2-1)*12+3) -> 372812.4 | K45: =INDEX(Monthly!$C$109:$AL$109,($R$2-1)*12+4) -> 355603.27 | L45: =INDEX(Monthly!$C$109:$AL$109,($R$2-1)*12+5) -> 340974.61 | M45: =INDEX(Monthly!$C$109:$AL$109,($R$2-1)*12+6) -> 335142.59 | N45: =INDEX(Monthly!$C$109:$AL$109,($R$2-1)*12+7) -> 331830.15 | O45: =INDEX(Monthly!$C$109:$AL$109,($R$2-1)*12+8) -> 331580.12 | P45: =INDEX(Monthly!$C$109:$AL$109,($R$2-1)*12+9) -> 326577.87 | Q45: =INDEX(Monthly!$C$109:$AL$109,($R$2-1)*12+10) -> 324851.59 | R45: =INDEX(Monthly!$C$109:$AL$109,($R$2-1)*12+11) -> 325705.78 | S45: =INDEX(Monthly!$C$109:$AL$109,($R$2-1)*12+12) -> 334560.6
A46: Accounts payable | B46: ='Balance Sheet'!B10 -> 18911.084 | C46: ='Balance Sheet'!C10 -> 19964.061 | D46: ='Balance Sheet'!D10 -> 21078.203 | H46: =INDEX(Monthly!$C$83:$AL$83,($R$2-1)*12+1) -> 9141.8364 | I46: =INDEX(Monthly!$C$83:$AL$83,($R$2-1)*12+2) -> 10033.945 | J46: =INDEX(Monthly!$C$83:$AL$83,($R$2-1)*12+3) -> 10926.054 | K46: =INDEX(Monthly!$C$83:$AL$83,($R$2-1)*12+4) -> 11818.163 | L46: =INDEX(Monthly!$C$83:$AL$83,($R$2-1)*12+5) -> 12710.272 | M46: =INDEX(Monthly!$C$83:$AL$83,($R$2-1)*12+6) -> 14196.092 | N46: =INDEX(Monthly!$C$83:$AL$83,($R$2-1)*12+7) -> 15139.091 | O46: =INDEX(Monthly!$C$83:$AL$83,($R$2-1)*12+8) -> 16082.089 | P46: =INDEX(Monthly!$C$83:$AL$83,($R$2-1)*12+9) -> 16278.707 | Q46: =INDEX(Monthly!$C$83:$AL$83,($R$2-1)*12+10) -> 17170.816 | R46: =INDEX(Monthly!$C$83:$AL$83,($R$2-1)*12+11) -> 18062.924 | S46: =INDEX(Monthly!$C$83:$AL$83,($R$2-1)*12+12) -> 18911.084
A47: Loan | B47: ='Balance Sheet'!B11 -> 81666.667 | C47: ='Balance Sheet'!C11 -> 61666.667 | D47: ='Balance Sheet'!D11 -> 41666.667 | H47: =INDEX(Monthly!$C$78:$AL$78,($R$2-1)*12+1) -> 100000 | I47: =INDEX(Monthly!$C$78:$AL$78,($R$2-1)*12+2) -> 98333.333 | J47: =INDEX(Monthly!$C$78:$AL$78,($R$2-1)*12+3) -> 96666.667 | K47: =INDEX(Monthly!$C$78:$AL$78,($R$2-1)*12+4) -> 95000 | L47: =INDEX(Monthly!$C$78:$AL$78,($R$2-1)*12+5) -> 93333.333 | M47: =INDEX(Monthly!$C$78:$AL$78,($R$2-1)*12+6) -> 91666.667 | N47: =INDEX(Monthly!$C$78:$AL$78,($R$2-1)*12+7) -> 90000 | O47: =INDEX(Monthly!$C$78:$AL$78,($R$2-1)*12+8) -> 88333.333 | P47: =INDEX(Monthly!$C$78:$AL$78,($R$2-1)*12+9) -> 86666.667 | Q47: =INDEX(Monthly!$C$78:$AL$78,($R$2-1)*12+10) -> 85000 | R47: =INDEX(Monthly!$C$78:$AL$78,($R$2-1)*12+11) -> 83333.333 | S47: =INDEX(Monthly!$C$78:$AL$78,($R$2-1)*12+12) -> 81666.667
A48: Total liabilities | B48: ='Balance Sheet'!B12 -> 100577.75 | C48: ='Balance Sheet'!C12 -> 81630.728 | D48: ='Balance Sheet'!D12 -> 62744.87 | H48: =INDEX(Monthly!$C$110:$AL$110,($R$2-1)*12+1) -> 109141.84 | I48: =INDEX(Monthly!$C$110:$AL$110,($R$2-1)*12+2) -> 108367.28 | J48: =INDEX(Monthly!$C$110:$AL$110,($R$2-1)*12+3) -> 107592.72 | K48: =INDEX(Monthly!$C$110:$AL$110,($R$2-1)*12+4) -> 106818.16 | L48: =INDEX(Monthly!$C$110:$AL$110,($R$2-1)*12+5) -> 106043.6 | M48: =INDEX(Monthly!$C$110:$AL$110,($R$2-1)*12+6) -> 105862.76 | N48: =INDEX(Monthly!$C$110:$AL$110,($R$2-1)*12+7) -> 105139.09 | O48: =INDEX(Monthly!$C$110:$AL$110,($R$2-1)*12+8) -> 104415.42 | P48: =INDEX(Monthly!$C$110:$AL$110,($R$2-1)*12+9) -> 102945.37 | Q48: =INDEX(Monthly!$C$110:$AL$110,($R$2-1)*12+10) -> 102170.82 | R48: =INDEX(Monthly!$C$110:$AL$110,($R$2-1)*12+11) -> 101396.26 | S48: =INDEX(Monthly!$C$110:$AL$110,($R$2-1)*12+12) -> 100577.75
A49: Paid-in capital | B49: ='Balance Sheet'!B13 -> 330000 | C49: ='Balance Sheet'!C13 -> 330000 | D49: ='Balance Sheet'!D13 -> 330000 | H49: =INDEX(Monthly!$C$107:$AL$107,($R$2-1)*12+1) -> 330000 | I49: =INDEX(Monthly!$C$107:$AL$107,($R$2-1)*12+2) -> 330000 | J49: =INDEX(Monthly!$C$107:$AL$107,($R$2-1)*12+3) -> 330000 | K49: =INDEX(Monthly!$C$107:$AL$107,($R$2-1)*12+4) -> 330000 | L49: =INDEX(Monthly!$C$107:$AL$107,($R$2-1)*12+5) -> 330000 | M49: =INDEX(Monthly!$C$107:$AL$107,($R$2-1)*12+6) -> 330000 | N49: =INDEX(Monthly!$C$107:$AL$107,($R$2-1)*12+7) -> 330000 | O49: =INDEX(Monthly!$C$107:$AL$107,($R$2-1)*12+8) -> 330000 | P49: =INDEX(Monthly!$C$107:$AL$107,($R$2-1)*12+9) -> 330000 | Q49: =INDEX(Monthly!$C$107:$AL$107,($R$2-1)*12+10) -> 330000 | R49: =INDEX(Monthly!$C$107:$AL$107,($R$2-1)*12+11) -> 330000 | S49: =INDEX(Monthly!$C$107:$AL$107,($R$2-1)*12+12) -> 330000
A50: Retained earnings | B50: ='Balance Sheet'!B14 -> -96017.149 | C50: ='Balance Sheet'!C14 -> -15459.77 | D50: ='Balance Sheet'!D14 -> 74751.284 | H50: =INDEX(Monthly!$C$108:$AL$108,($R$2-1)*12+1) -> -24169.749 | I50: =INDEX(Monthly!$C$108:$AL$108,($R$2-1)*12+2) -> -45765.273 | J50: =INDEX(Monthly!$C$108:$AL$108,($R$2-1)*12+3) -> -64780.322 | K50: =INDEX(Monthly!$C$108:$AL$108,($R$2-1)*12+4) -> -81214.896 | L50: =INDEX(Monthly!$C$108:$AL$108,($R$2-1)*12+5) -> -95068.994 | M50: =INDEX(Monthly!$C$108:$AL$108,($R$2-1)*12+6) -> -100720.16 | N50: =INDEX(Monthly!$C$108:$AL$108,($R$2-1)*12+7) -> -103308.94 | O50: =INDEX(Monthly!$C$108:$AL$108,($R$2-1)*12+8) -> -102835.31 | P50: =INDEX(Monthly!$C$108:$AL$108,($R$2-1)*12+9) -> -106367.51 | Q50: =INDEX(Monthly!$C$108:$AL$108,($R$2-1)*12+10) -> -107319.23 | R50: =INDEX(Monthly!$C$108:$AL$108,($R$2-1)*12+11) -> -105690.48 | S50: =INDEX(Monthly!$C$108:$AL$108,($R$2-1)*12+12) -> -96017.149
...

Sheet Scenarios
A1: Scenarios — Low / Base / High | H1: =HYPERLINK("#'Cover'!A1","◂ Contents") -> ◂ Contents
A2: All three scenarios calculated side by side, live: change any input and every column updates. Active = the scenario chosen on the Dashboard.
A5: Key drivers
A6: Driver | B6: Low | C6: Base | D6: High | E6: Active
A7: Grooming appointments per operating day at maturity (year 1) (grooms) | B7: =Inputs!$B$7 -> 13 | C7: =Inputs!$C$7 -> 16 | D7: =Inputs!$D$7 -> 19 | E7: =Inputs!$E$7 -> 16
A8: Average price per groom (year 1) ($) | B8: =Inputs!$B$19 -> 68 | C8: =Inputs!$C$19 -> 75 | D8: =Inputs!$D$19 -> 82 | E8: =Inputs!$E$19 -> 75
A9: Kennel runs / suites (runs) | B9: =Inputs!$B$25 -> 30 | C9: =Inputs!$C$25 -> 30 | D9: =Inputs!$D$25 -> 30 | E9: =Inputs!$E$25 -> 30
A10: Average boarding occupancy at maturity, % of run-nights (year 1) (%) | B10: =Inputs!$B$26 -> 0.5 | C10: =Inputs!$C$26 -> 0.62 | D10: =Inputs!$D$26 -> 0.72 | E10: =Inputs!$E$26 -> 0.62
A11: Average nightly rate per run (year 1) ($) | B11: =Inputs!$B$30 -> 50 | C11: =Inputs!$C$30 -> 55 | D11: =Inputs!$D$30 -> 60 | E11: =Inputs!$E$30 -> 55
A12: Shop rent or land cost per month ($) | B12: =Inputs!$B$38 -> 9000 | C12: =Inputs!$C$38 -> 9000 | D12: =Inputs!$D$38 -> 9000 | E12: =Inputs!$E$38 -> 9000
A13: Equity raised at start ($) | B13: =Inputs!$B$71 -> 330000 | C13: =Inputs!$C$71 -> 330000 | D13: =Inputs!$D$71 -> 330000 | E13: =Inputs!$E$71 -> 330000
A15: Results by scenario ($'000)
A16: Output | B16: Low | C16: Base | D16: High | E16: Active
A17: Revenue — final year | B17: =D30 -> 585276.25 | C17: =D31 -> 886367.9 | D17: =D32 -> 1226561.8 | E17: ='P&L'!D5 -> 886367.9
A18: Revenue — whole plan | B18: =SUM(B30:D30) -> 1489471.5 | C18: =SUM(B31:D31) -> 2296356.6 | D18: =SUM(B32:D32) -> 3176853.7 | E18: =SUM('P&L'!$B$5:$D$5) -> 2296356.6
A19: EBITDA — final year | B19: =D36 -> -90341.043 | C19: =D37 -> 140856.65 | D19: =D38 -> 399100.86 | E19: ='P&L'!D16 -> 140856.65
A20: EBITDA margin — final year | B20: =IF(B17=0,0,B19/B17) -> -0.15435624 | C20: =IF(C17=0,0,C19/C17) -> 0.15891443 | D20: =IF(D17=0,0,D19/D17) -> 0.32538179 | E20: =IF(E17=0,0,E19/E17) -> 0.15891443
A21: Net income — final year | B21: =D42 -> -121116.04 | C21: =D43 -> 90211.054 | D21: =D44 -> 290977.43 | E21: ='P&L'!D23 -> 90211.054
A22: Net income — whole plan | B22: =SUM(B42:D42) -> -516992.08 | C22: =SUM(B43:D43) -> 74751.284 | D22: =SUM(B44:D44) -> 607492.17 | E22: =SUM('P&L'!$B$23:$D$23) -> 74751.284
A23: Cash at the end of the plan | B23: =D48 -> -270553.71 | C23: =D49 -> 322671.42 | D23: =D50 -> 856969.37 | E23: ='Balance Sheet'!D5 -> 322671.42
A24: Lowest cash balance | B24: =MIN('Scenario calc'!$C$97:$AL$97) -> -270553.71 | C24: =MIN('Scenario calc'!$C$223:$AL$223) -> 147500.34 | D24: =MIN('Scenario calc'!$C$349:$AL$349) -> 220781.46 | E24: ='Break-even'!B18 -> 147500.34
A25: Lowest cash point (month #) | B25: =MATCH(MIN('Scenario calc'!$C$97:$AL$97),'Scenario calc'!$C$97:$AL$97,0) -> 36 | C25: =MATCH(MIN('Scenario calc'!$C$223:$AL$223),'Scenario calc'!$C$223:$AL$223,0) -> 10 | D25: =MATCH(MIN('Scenario calc'!$C$349:$AL$349),'Scenario calc'!$C$349:$AL$349,0) -> 4 | E25: ='Break-even'!B6 -> 10
A26: Funding required (incl. cash buffer) | B26: =SUMPRODUCT(--('Scenario calc'!$C$6:$AL$6<=B25),'Scenario calc'!$C$69:$AL$69)-SUMPRODUCT(--('Scenario calc'!$C$6:$AL$6<=B25),'Scenario calc'!$C$91:$AL$91)-SUMPRODUCT(--('Scenario calc'!$C$6:$AL$6<=B25),'Scenario calc'!$C$79:$AL$79)+Inputs!$B$86 -> 809553.71 | C26: =SUMPRODUCT(--('Scenario calc'!$C$132:$AL$132<=C25),'Scenario calc'!$C$195:$AL$195)-SUMPRODUCT(--('Scenario calc'!$C$132:$AL$132<=C25),'Scenario calc'!$C$217:$AL$217)-SUMPRODUCT(--('Scenario calc'!$C$132:$AL$132<=C25),'Scenario calc'!$C$205:$AL$205)+Inputs!$C$86 -> 391499.66 | D26: =SUMPRODUCT(--('Scenario calc'!$C$258:$AL$258<=D25),'Scenario calc'!$C$321:$AL$321)-SUMPRODUCT(--('Scenario calc'!$C$258:$AL$258<=D25),'Scenario calc'!$C$343:$AL$343)-SUMPRODUCT(--('Scenario calc'!$C$258:$AL$258<=D25),'Scenario calc'!$C$331:$AL$331)+Inputs!$D$86 -> 318218.54 | E26: ='Break-even'!B12 -> 391499.66
A28: Revenue by year ($'000)
A29: Scenario | B29: 1 | C29: 2 | D29: 3
A30: Low | B30: =SUMIF('Scenario calc'!$C$7:$AL$7,B$29,'Scenario calc'!$C$33:$AL$33) -> 331698.3 | C30: =SUMIF('Scenario calc'!$C$7:$AL$7,C$29,'Scenario calc'!$C$33:$AL$33) -> 572496.99 | D30: =SUMIF('Scenario calc'!$C$7:$AL$7,D$29,'Scenario calc'!$C$33:$AL$33) -> 585276.25
A31: Base | B31: =SUMIF('Scenario calc'!$C$133:$AL$133,B$29,'Scenario calc'!$C$159:$AL$159) -> 574501.95 | C31: =SUMIF('Scenario calc'!$C$133:$AL$133,C$29,'Scenario calc'!$C$159:$AL$159) -> 835486.76 | D31: =SUMIF('Scenario calc'!$C$133:$AL$133,D$29,'Scenario calc'!$C$159:$AL$159) -> 886367.9
A32: High | B32: =SUMIF('Scenario calc'!$C$259:$AL$259,B$29,'Scenario calc'!$C$285:$AL$285) -> 832792.8 | C32: =SUMIF('Scenario calc'!$C$259:$AL$259,C$29,'Scenario calc'!$C$285:$AL$285) -> 1117499.1 | D32: =SUMIF('Scenario calc'!$C$259:$AL$259,D$29,'Scenario calc'!$C$285:$AL$285) -> 1226561.8
A34: EBITDA by year ($'000)
A35: Scenario | B35: 1 | C35: 2 | D35: 3
A36: Low | B36: =SUMIF('Scenario calc'!$C$7:$AL$7,B$35,'Scenario calc'!$C$52:$AL$52) -> -243337.02 | C36: =SUMIF('Scenario calc'!$C$7:$AL$7,C$35,'Scenario calc'!$C$52:$AL$52) -> -89345.268 | D36: =SUMIF('Scenario calc'!$C$7:$AL$7,D$35,'Scenario calc'!$C$52:$AL$52) -> -90341.043
A37: Base | B37: =SUMIF('Scenario calc'!$C$133:$AL$133,B$35,'Scenario calc'!$C$178:$AL$178) -> -64148.399 | C37: =SUMIF('Scenario calc'!$C$133:$AL$133,C$35,'Scenario calc'!$C$178:$AL$178) -> 111882.38 | D37: =SUMIF('Scenario calc'!$C$133:$AL$133,D$35,'Scenario calc'!$C$178:$AL$178) -> 140856.65
A38: High | B38: =SUMIF('Scenario calc'!$C$259:$AL$259,B$35,'Scenario calc'!$C$304:$AL$304) -> 134331.52 | C38: =SUMIF('Scenario calc'!$C$259:$AL$259,C$35,'Scenario calc'!$C$304:$AL$304) -> 329513.8 | D38: =SUMIF('Scenario calc'!$C$259:$AL$259,D$35,'Scenario calc'!$C$304:$AL$304) -> 399100.86
A40: Net income by year ($'000)
A41: Scenario | B41: 1 | C41: 2 | D41: 3
A42: Low | B42: =SUMIF('Scenario calc'!$C$7:$AL$7,B$41,'Scenario calc'!$C$61:$AL$61) -> -275205.77 | C42: =SUMIF('Scenario calc'!$C$7:$AL$7,C$41,'Scenario calc'!$C$61:$AL$61) -> -120670.27 | D42: =SUMIF('Scenario calc'!$C$7:$AL$7,D$41,'Scenario calc'!$C$61:$AL$61) -> -121116.04
A43: Base | B43: =SUMIF('Scenario calc'!$C$133:$AL$133,B$41,'Scenario calc'!$C$187:$AL$187) -> -96017.149 | C43: =SUMIF('Scenario calc'!$C$133:$AL$133,C$41,'Scenario calc'!$C$187:$AL$187) -> 80557.379 | D43: =SUMIF('Scenario calc'!$C$133:$AL$133,D$41,'Scenario calc'!$C$187:$AL$187) -> 90211.054
A44: High | B44: =SUMIF('Scenario calc'!$C$259:$AL$259,B$41,'Scenario calc'!$C$313:$AL$313) -> 80945.59 | C44: =SUMIF('Scenario calc'!$C$259:$AL$259,C$41,'Scenario calc'!$C$313:$AL$313) -> 235569.15 | D44: =SUMIF('Scenario calc'!$C$259:$AL$259,D$41,'Scenario calc'!$C$313:$AL$313) -> 290977.43
A46: Cash at year end by year ($'000)
A47: Scenario | B47: 1 | C47: 2 | D47: 3
...

Sheet Break-even
A1: Startup costs, funding need and break-even | F1: =HYPERLINK("#'Cover'!A1","◂ Contents") -> ◂ Contents
A2: Live for the selected scenario. Periods are counted in months from the start of the plan.
A3: Scenario shown | B3: =CHOOSE(Dashboard!$B$4,"Low","Base","High") -> Base
A5: Startup costs & funding need (up to the lowest cash point)
A6: Lowest cash point (month #) | B6: =MATCH(MIN(Monthly!$C$95:$AL$95),Monthly!$C$95:$AL$95,0) -> 10
A7: Capital spending up to the lowest cash point | B7: =SUMPRODUCT(--(Monthly!$C$4:$AL$4<=$B$6),Monthly!$C$67:$AL$67) -> 189000
A8: Operating cash burn up to the lowest cash point | B8: =-SUMPRODUCT(--(Monthly!$C$4:$AL$4<=$B$6),Monthly!$C$89:$AL$89) -> 78499.658 | D8: Losses and working capital before the business funds itself
A9: Loan repayments up to the lowest cash point | B9: =-SUMPRODUCT(--(Monthly!$C$4:$AL$4<=$B$6),Monthly!$C$77:$AL$77) -> 15000
A10: Total uses of funds | B10: =B7+B8+B9 -> 282499.66
A11: Minimum cash buffer to keep | B11: =Inputs!$E$86 -> 109000 | D11: Input on the Inputs sheet
A12: Funding required (uses + buffer) | B12: =B10+B11 -> 391499.66
A14: Equity raised | B14: =Inputs!$E$71 -> 330000
A15: Loan drawn | B15: =Inputs!$E$72 -> 100000
A16: Total sources of funds | B16: =B14+B15 -> 430000
A17: Funding surplus / (shortfall) | B17: =B16-B12 -> 38500.342 | D17: Negative = raise at least this much more
A18: Lowest cash balance in the plan | B18: =MIN(Monthly!$C$95:$AL$95) -> 147500.34 | D18: Equals sources minus uses
A20: Break-even timing
A21: First month with positive EBITDA (month #) | B21: =IFERROR(MATCH(1,Monthly!$C$96:$AL$96,0),"Not within horizon") -> 7
A22: First month with positive net income (month #) | B22: =IFERROR(MATCH(1,Monthly!$C$99:$AL$99,0),"Not within horizon") -> 8
A23: Cash invested paid back (month #) | B23: =IF(MIN(Monthly!$C$101:$AL$101)>=0,"No investment to pay back",IFERROR(MATCH(1,Monthly!$C$103:$AL$103,0),"Not within horizon")) -> Not within horizon | D23: Cumulative operating + investing cash flow back to zero
A25: Annual break-even revenue
A26: Year # | B26: 1 | C26: 2 | D26: 3
B27: Year 1 | C27: Year 2 | D27: Year 3
A28: Revenue | B28: =SUMIF(Monthly!$C$5:$AL$5,B$26,Monthly!$C$31:$AL$31) -> 574501.95 | C28: =SUMIF(Monthly!$C$5:$AL$5,C$26,Monthly!$C$31:$AL$31) -> 835486.76 | D28: =SUMIF(Monthly!$C$5:$AL$5,D$26,Monthly!$C$31:$AL$31) -> 886367.9
A29: Gross profit | B29: =SUMIF(Monthly!$C$5:$AL$5,B$26,Monthly!$C$40:$AL$40) -> 369936.66 | C29: =SUMIF(Monthly!$C$5:$AL$5,C$26,Monthly!$C$40:$AL$40) -> 556642.48 | D29: =SUMIF(Monthly!$C$5:$AL$5,D$26,Monthly!$C$40:$AL$40) -> 592006.05
A30: Gross margin (contribution) | B30: =IF(B28=0,0,B29/B28) -> 0.64392586 | C30: =IF(C28=0,0,C29/C28) -> 0.66624932 | D30: =IF(D28=0,0,D29/D28) -> 0.66790105
A31: Operating expenses (treated as fixed) | B31: =-SUMIF(Monthly!$C$5:$AL$5,B$26,Monthly!$C$49:$AL$49) -> 434085.06 | C31: =-SUMIF(Monthly!$C$5:$AL$5,C$26,Monthly!$C$49:$AL$49) -> 444760.1 | D31: =-SUMIF(Monthly!$C$5:$AL$5,D$26,Monthly!$C$49:$AL$49) -> 451149.4
A32: Break-even revenue (EBITDA = 0) | B32: =IF(B30>0,B31/B30,"n/a") -> 674122.73 | C32: =IF(C30>0,C31/C30,"n/a") -> 667558.06 | D32: =IF(D30>0,D31/D30,"n/a") -> 675473.42
A33: Margin of safety (revenue above break-even) | B33: =IF(AND(ISNUMBER(B32),B28>0),(B28-B32)/B28,"n/a") -> -0.17340374 | C33: =IF(AND(ISNUMBER(C32),C28>0),(C28-C32)/C28,"n/a") -> 0.20099504 | D33: =IF(AND(ISNUMBER(D32),D28>0),(D28-D32)/D28,"n/a") -> 0.2379311
A35: Simplification: cost of sales is treated as variable and operating expenses as fixed, so break-even revenue = operating expenses ÷ gross margin.

Sheet Valuation
A1: Discounted cash flow valuation | H1: =HYPERLINK("#'Cover'!A1","◂ Contents") -> ◂ Contents
A2: Enterprise value at the start of the plan, before the funding raised in period 1. Year-end discounting.
A3: Scenario shown | B3: =CHOOSE(Dashboard!$B$4,"Low","Base","High") -> Base
A5: Assumptions (active scenario, from the Inputs sheet)
A6: Discount rate (WACC) | B6: =Inputs!$E$89 -> 0.25
A7: Terminal growth rate | B7: =Inputs!$E$90 -> 0.02
A8: Exit multiple (EV ÷ final-year EBITDA) | B8: =Inputs!$E$91 -> 4
A9: Tax rate (for the interest tax shield) | B9: =Inputs!$E$83 -> 0.21
A10: Sensitivity step: WACC | B10: =Inputs!$E$92 -> 0.01
A11: Sensitivity step: terminal growth | B11: =Inputs!$E$93 -> 0.005
A13: Free cash flow by year
A14: Year # | B14: 1 | C14: 2 | D14: 3
B15: Year 1 | C15: Year 2 | D15: Year 3
A16: EBITDA | B16: =SUMIF(Monthly!$C$5:$AL$5,B$14,Monthly!$C$50:$AL$50) -> -64148.399 | C16: =SUMIF(Monthly!$C$5:$AL$5,C$14,Monthly!$C$50:$AL$50) -> 111882.38 | D16: =SUMIF(Monthly!$C$5:$AL$5,D$14,Monthly!$C$50:$AL$50) -> 140856.65
A17: Unlevered free cash flow | B17: =SUMIF(Monthly!$C$5:$AL$5,B$14,Monthly!$C$104:$AL$104) -> -245296.96 | C17: =SUMIF(Monthly!$C$5:$AL$5,C$14,Monthly!$C$104:$AL$104) -> 101036.44 | D17: =SUMIF(Monthly!$C$5:$AL$5,D$14,Monthly!$C$104:$AL$104) -> 110546.84
A18: Discount factor | B18: =1/(1+Inputs!$E$89)^B$14 -> 0.8 | C18: =1/(1+Inputs!$E$89)^C$14 -> 0.64 | D18: =1/(1+Inputs!$E$89)^D$14 -> 0.512
A19: Present value of free cash flow | B19: =B17*B18 -> -196237.57 | C19: =C17*C18 -> 64663.323 | D19: =D17*D18 -> 56599.981
A21: Enterprise value
B22: Perpetual growth | C22: Exit multiple
A23: Present value of the plan's free cash flows | B23: =SUM($B$19:$D$19) -> -74974.268 | C23: =B23 -> -74974.268
A24: Final-year free cash flow | final-year EBITDA | B24: =$D$17 -> 110546.84 | C24: =$D$16 -> 140856.65
A25: Terminal value at the end of year 3 | B25: =IF($B$6>$B$7,B24*(1+$B$7)/($B$6-$B$7),0) -> 490251.2 | C25: =C24*$B$8 -> 563426.59
A26: Present value of the terminal value | B26: =B25/(1+$B$6)^$D$14 -> 251008.61 | C26: =C25/(1+$B$6)^$D$14 -> 288474.42
A27: Enterprise value | B27: =B23+B26 -> 176034.34 | C27: =C23+C26 -> 213500.15
A28: Terminal value share of enterprise value | B28: =IF(B27<>0,B26/B27,0) -> 1.425907 | C28: =IF(C27<>0,C26/C27,0) -> 1.3511673
A29: Cross-check: implied exit multiple | implied perpetual growth | B29: =IF(C24>0,B25/C24,"n/a") -> 3.4804974 | C29: =IF(C25+B24<>0,(C25*$B$6-B24)/(C25+B24),"n/a") -> 0.044971818
A30: Enterprise value — average of the two methods | B30: =AVERAGE(B27,C27) -> 194767.25
A32: Sensitivity: enterprise value (perpetual growth) by WACC and terminal growth
A33: WACC ↓ · terminal growth → | B33: =$B$7+(-2)*$B$11 -> 0.01 | C33: =$B$7+(-1)*$B$11 -> 0.015 | D33: =$B$7+(0)*$B$11 -> 0.02 | E33: =$B$7+(1)*$B$11 -> 0.025 | F33: =$B$7+(2)*$B$11 -> 0.03
A34: =$B$6+(-2)*$B$10 -> 0.23 | B34: =IF($A34>B$33,SUMPRODUCT($B$17:$D$17/(1+$A34)^$B$14:$D$14)+$D$17*(1+B$33)/($A34-B$33)/(1+$A34)^$D$14,"n/a") -> 199488.93 | C34: =IF($A34>C$33,SUMPRODUCT($B$17:$D$17/(1+$A34)^$B$14:$D$14)+$D$17*(1+C$33)/($A34-C$33)/(1+$A34)^$D$14,"n/a") -> 207212.98 | D34: =IF($A34>D$33,SUMPRODUCT($B$17:$D$17/(1+$A34)^$B$14:$D$14)+$D$17*(1+D$33)/($A34-D$33)/(1+$A34)^$D$14,"n/a") -> 215304.84 | E34: =IF($A34>E$33,SUMPRODUCT($B$17:$D$17/(1+$A34)^$B$14:$D$14)+$D$17*(1+E$33)/($A34-E$33)/(1+$A34)^$D$14,"n/a") -> 223791.42 | F34: =IF($A34>F$33,SUMPRODUCT($B$17:$D$17/(1+$A34)^$B$14:$D$14)+$D$17*(1+F$33)/($A34-F$33)/(1+$A34)^$D$14,"n/a") -> 232702.34
A35: =$B$6+(-1)*$B$10 -> 0.24 | B35: =IF($A35>B$33,SUMPRODUCT($B$17:$D$17/(1+$A35)^$B$14:$D$14)+$D$17*(1+B$33)/($A35-B$33)/(1+$A35)^$D$14,"n/a") -> 180480.38 | C35: =IF($A35>C$33,SUMPRODUCT($B$17:$D$17/(1+$A35)^$B$14:$D$14)+$D$17*(1+C$33)/($A35-C$33)/(1+$A35)^$D$14,"n/a") -> 187426.83 | D35: =IF($A35>D$33,SUMPRODUCT($B$17:$D$17/(1+$A35)^$B$14:$D$14)+$D$17*(1+D$33)/($A35-D$33)/(1+$A35)^$D$14,"n/a") -> 194689.02 | E35: =IF($A35>E$33,SUMPRODUCT($B$17:$D$17/(1+$A35)^$B$14:$D$14)+$D$17*(1+E$33)/($A35-E$33)/(1+$A35)^$D$14,"n/a") -> 202288.99 | F35: =IF($A35>F$33,SUMPRODUCT($B$17:$D$17/(1+$A35)^$B$14:$D$14)+$D$17*(1+F$33)/($A35-F$33)/(1+$A35)^$D$14,"n/a") -> 210250.86
A36: =$B$6+(0)*$B$10 -> 0.25 | B36: =IF($A36>B$33,SUMPRODUCT($B$17:$D$17/(1+$A36)^$B$14:$D$14)+$D$17*(1+B$33)/($A36-B$33)/(1+$A36)^$D$14,"n/a") -> 163217.32 | C36: =IF($A36>C$33,SUMPRODUCT($B$17:$D$17/(1+$A36)^$B$14:$D$14)+$D$17*(1+C$33)/($A36-C$33)/(1+$A36)^$D$14,"n/a") -> 169489.48 | D36: =IF($A36>D$33,SUMPRODUCT($B$17:$D$17/(1+$A36)^$B$14:$D$14)+$D$17*(1+D$33)/($A36-D$33)/(1+$A36)^$D$14,"n/a") -> 176034.34 | E36: =IF($A36>E$33,SUMPRODUCT($B$17:$D$17/(1+$A36)^$B$14:$D$14)+$D$17*(1+E$33)/($A36-E$33)/(1+$A36)^$D$14,"n/a") -> 182870.09 | F36: =IF($A36>F$33,SUMPRODUCT($B$17:$D$17/(1+$A36)^$B$14:$D$14)+$D$17*(1+F$33)/($A36-F$33)/(1+$A36)^$D$14,"n/a") -> 190016.55
A37: =$B$6+(1)*$B$10 -> 0.26 | B37: =IF($A37>B$33,SUMPRODUCT($B$17:$D$17/(1+$A37)^$B$14:$D$14)+$D$17*(1+B$33)/($A37-B$33)/(1+$A37)^$D$14,"n/a") -> 147486.53 | C37: =IF($A37>C$33,SUMPRODUCT($B$17:$D$17/(1+$A37)^$B$14:$D$14)+$D$17*(1+C$33)/($A37-C$33)/(1+$A37)^$D$14,"n/a") -> 153170.73 | D37: =IF($A37>D$33,SUMPRODUCT($B$17:$D$17/(1+$A37)^$B$14:$D$14)+$D$17*(1+D$33)/($A37-D$33)/(1+$A37)^$D$14,"n/a") -> 159091.77 | E37: =IF($A37>E$33,SUMPRODUCT($B$17:$D$17/(1+$A37)^$B$14:$D$14)+$D$17*(1+E$33)/($A37-E$33)/(1+$A37)^$D$14,"n/a") -> 165264.77 | F37: =IF($A37>F$33,SUMPRODUCT($B$17:$D$17/(1+$A37)^$B$14:$D$14)+$D$17*(1+F$33)/($A37-F$33)/(1+$A37)^$D$14,"n/a") -> 171706.16
A38: =$B$6+(2)*$B$10 -> 0.27 | B38: =IF($A38>B$33,SUMPRODUCT($B$17:$D$17/(1+$A38)^$B$14:$D$14)+$D$17*(1+B$33)/($A38-B$33)/(1+$A38)^$D$14,"n/a") -> 133107.72 | C38: =IF($A38>C$33,SUMPRODUCT($B$17:$D$17/(1+$A38)^$B$14:$D$14)+$D$17*(1+C$33)/($A38-C$33)/(1+$A38)^$D$14,"n/a") -> 138276.59 | D38: =IF($A38>D$33,SUMPRODUCT($B$17:$D$17/(1+$A38)^$B$14:$D$14)+$D$17*(1+D$33)/($A38-D$33)/(1+$A38)^$D$14,"n/a") -> 143652.21 | E38: =IF($A38>E$33,SUMPRODUCT($B$17:$D$17/(1+$A38)^$B$14:$D$14)+$D$17*(1+E$33)/($A38-E$33)/(1+$A38)^$D$14,"n/a") -> 149247.25 | F38: =IF($A38>F$33,SUMPRODUCT($B$17:$D$17/(1+$A38)^$B$14:$D$14)+$D$17*(1+F$33)/($A38-F$33)/(1+$A38)^$D$14,"n/a") -> 155075.41
A40: Free cash flow = operating cash flow + interest × (1 − tax rate) − capital spending. Cells marked n/a: WACC not above growth.

Sheet Sources & Uses
A1: Sources and uses of funds | E1: =HYPERLINK("#'Cover'!A1","◂ Contents") -> ◂ Contents
A2: Live for the selected scenario. Where the money comes from and where it goes in the period set below.
A3: Scenario shown | B3: =CHOOSE(Dashboard!$B$4,"Low","Base","High") -> Base
A5: Funding structure ($'000) — raised at the start of the plan
B6: Amount | C6: Share
A7: Equity | B7: =Inputs!$E$71 -> 330000 | C7: =IF($B$9=0,0,B7/$B$9) -> 0.76744186
A8: Debt (loan) | B8: =Inputs!$E$72 -> 100000 | C8: =IF($B$9=0,0,B8/$B$9) -> 0.23255814
A9: Total funding | B9: =B7+B8 -> 430000 | C9: =IF(B9=0,0,1) -> 1
A10: Gearing (debt ÷ equity) | B10: =IF(B7<=0,IF(B8>0,"n/a",0),B8/B7) -> 0.3030303 | D10: n/a: debt without positive equity
A11: Funding required by the plan (Break-even sheet) | B11: ='Break-even'!B12 -> 391499.66
A12: Funding surplus / (shortfall) | B12: ='Break-even'!B17 -> 38500.342
A14: ="Sources and uses of cash in the first "&$B$16&IF($B$16=1," month"," months")&" ($'000)" -> Sources and uses of cash in the first 12 months ($'000)
A15: Period covered (months from the start) | B15: 12 | D15: 1 to 36 (capped)
A16: Months used | B16: =MIN(36,MAX(1,ROUND(B15,0))) -> 12
A17: Sources | B17: Amount | C17: Share
A18: Equity raised | B18: =SUMPRODUCT(--(Monthly!$C$4:$AL$4<=$B$16),Monthly!$C$91:$AL$91) -> 330000 | C18: =IF($B$21=0,0,B18/$B$21) -> 0.76744186
A19: Loan drawdowns | B19: =SUMPRODUCT(--(Monthly!$C$4:$AL$4<=$B$16),Monthly!$C$76:$AL$76) -> 100000 | C19: =IF($B$21=0,0,B19/$B$21) -> 0.23255814
A20: Cash generated by operations | B20: =MAX(0,SUMPRODUCT(--(Monthly!$C$4:$AL$4<=$B$16),Monthly!$C$89:$AL$89)) -> 0 | C20: =IF($B$21=0,0,B20/$B$21) -> 0
A21: Total sources | B21: =SUM(B18:B20) -> 430000 | C21: =IF(B21=0,0,1) -> 1
A23: Uses | B23: Amount | C23: Share
A24: Cash used by operations | B24: =MAX(0,-SUMPRODUCT(--(Monthly!$C$4:$AL$4<=$B$16),Monthly!$C$89:$AL$89)) -> 62809.527 | C24: =IF($B$28=0,0,B24/$B$28) -> 0.14606867
A25: Capital spending | B25: =-SUMPRODUCT(--(Monthly!$C$4:$AL$4<=$B$16),Monthly!$C$90:$AL$90) -> 189000 | C25: =IF($B$28=0,0,B25/$B$28) -> 0.43953488
A26: Loan repayments | B26: =-SUMPRODUCT(--(Monthly!$C$4:$AL$4<=$B$16),Monthly!$C$77:$AL$77) -> 18333.333 | C26: =IF($B$28=0,0,B26/$B$28) -> 0.042635659
A27: Cash at the end of the period | B27: =INDEX(Monthly!$C$95:$AL$95,$B$16) -> 159857.14 | C27: =IF($B$28=0,0,B27/$B$28) -> 0.37176079
A28: Total uses | B28: =SUM(B24:B27) -> 430000 | C28: =IF(B28=0,0,1) -> 1
A29: Sources − uses (must be 0; opening cash is 0) | B29: =B21-B28 -> 0

Sheet KPIs
A1: KPIs & ratios | G1: =HYPERLINK("#'Cover'!A1","◂ Contents") -> ◂ Contents
A2: Pet grooming & boarding financial model (planning) — industry metrics and financial ratios for the active scenario
A4: Financial ratios
B5: 1 | C5: 2 | D5: 3 | E5: Target
A6: Revenue growth | B6: =IF(N('P&L'!A5)<=0,"n/a",'P&L'!B5/'P&L'!A5-1) -> n/a | C6: =IF(N('P&L'!B5)<=0,"n/a",'P&L'!C5/'P&L'!B5-1) -> 0.45428011 | D6: =IF(N('P&L'!C5)<=0,"n/a",'P&L'!D5/'P&L'!C5-1) -> 0.0609
A7: Gross margin | B7: =IF('P&L'!B5<=0,"n/a",'P&L'!B7/'P&L'!B5) -> 0.64392586 | C7: =IF('P&L'!C5<=0,"n/a",'P&L'!C7/'P&L'!C5) -> 0.66624932 | D7: =IF('P&L'!D5<=0,"n/a",'P&L'!D7/'P&L'!D5) -> 0.66790105
A8: EBITDA margin | B8: =IF('P&L'!B5<=0,"n/a",'P&L'!B16/'P&L'!B5) -> -0.11165915 | C8: =IF('P&L'!C5<=0,"n/a",'P&L'!C16/'P&L'!C5) -> 0.13391281 | D8: =IF('P&L'!D5<=0,"n/a",'P&L'!D16/'P&L'!D5) -> 0.15891443
A9: Net margin | B9: =IF('P&L'!B5<=0,"n/a",'P&L'!B23/'P&L'!B5) -> -0.16713111 | C9: =IF('P&L'!C5<=0,"n/a",'P&L'!C23/'P&L'!C5) -> 0.096419695 | D9: =IF('P&L'!D5<=0,"n/a",'P&L'!D23/'P&L'!D5) -> 0.10177608
A10: Payroll, % of revenue | B10: =IF('P&L'!B5<=0,"n/a",-SUMIF(Headcount!$C$5:$AL$5,B$5,Headcount!$C$17:$AL$17)/'P&L'!B5) -> 0.39834504 | C10: =IF('P&L'!C5<=0,"n/a",-SUMIF(Headcount!$C$5:$AL$5,C$5,Headcount!$C$17:$AL$17)/'P&L'!C5) -> 0.28212955 | D10: =IF('P&L'!D5<=0,"n/a",-SUMIF(Headcount!$C$5:$AL$5,D$5,Headcount!$C$17:$AL$17)/'P&L'!D5) -> 0.27391218
A11: Marketing, % of revenue | B11: =IF('P&L'!B5<=0,"n/a",-'P&L'!B13/'P&L'!B5) -> 0.073106802 | C11: =IF('P&L'!C5<=0,"n/a",-'P&L'!C13/'P&L'!C5) -> 0.040216077 | D11: =IF('P&L'!D5<=0,"n/a",-'P&L'!D13/'P&L'!D5) -> 0.030326008
A12: Operating expenses, % of revenue | B12: =IF('P&L'!B5<=0,"n/a",-'P&L'!B15/'P&L'!B5) -> 0.75558501 | C12: =IF('P&L'!C5<=0,"n/a",-'P&L'!C15/'P&L'!C5) -> 0.53233651 | D12: =IF('P&L'!D5<=0,"n/a",-'P&L'!D15/'P&L'!D5) -> 0.50898662
A13: Current ratio (current assets ÷ current liabilities) | B13: =IF(('Balance Sheet'!B12-'Balance Sheet'!B11)<=0,"n/a",('Balance Sheet'!B5+'Balance Sheet'!B6+'Balance Sheet'!B7)/('Balance Sheet'!B12-'Balance Sheet'!B11)) -> 8.9463723 | C13: =IF(('Balance Sheet'!C12-'Balance Sheet'!C11)<=0,"n/a",('Balance Sheet'!C5+'Balance Sheet'!C6+'Balance Sheet'!C7)/('Balance Sheet'!C12-'Balance Sheet'!C11)) -> 12.30566 | D13: =IF(('Balance Sheet'!D12-'Balance Sheet'!D11)<=0,"n/a",('Balance Sheet'!D5+'Balance Sheet'!D6+'Balance Sheet'!D7)/('Balance Sheet'!D12-'Balance Sheet'!D11)) -> 15.804059
A14: Debt ÷ equity (loan ÷ total equity) | B14: =IF('Balance Sheet'!B15<=0,"n/a",'Balance Sheet'!B11/'Balance Sheet'!B15) -> 0.34902843 | C14: =IF('Balance Sheet'!C15<=0,"n/a",'Balance Sheet'!C11/'Balance Sheet'!C15) -> 0.19605335 | D14: =IF('Balance Sheet'!D15<=0,"n/a",'Balance Sheet'!D11/'Balance Sheet'!D15) -> 0.10294388
A15: Return on assets (net income ÷ year-end assets) | B15: =IF('Balance Sheet'!B9<=0,"n/a",'P&L'!B23/'Balance Sheet'!B9) -> -0.28699479 | C15: =IF('Balance Sheet'!C9<=0,"n/a",'P&L'!C23/'Balance Sheet'!C9) -> 0.20333994 | D15: =IF('Balance Sheet'!D9<=0,"n/a",'P&L'!D23/'Balance Sheet'!D9) -> 0.19296641
