Workbook

Sheet Cover
B2: Rental property financial model (early)
B3: 5-year financial model · monthly detail · Low / Base / High scenarios · US dollars · Full plan
B5: Purpose | D5: Revenue and profit plan
B6: Active scenario | D6: =Dashboard!C4&" (change it on the Dashboard, cell B4)" -> Base (change it on the Dashboard, cell B4)
B7: Model checks | D7: =Checks!B30 -> PASS
B8: Prepared | D8: 21 October 2026
B10: Contents
C11: PRESENTATION
B12: 1 | C12: =HYPERLINK("#Dashboard!A1","Dashboard") -> Dashboard | D12: Scenario switch, key numbers, core financials
B13: 2 | C13: =HYPERLINK("#Summary!A1","Summary") -> Summary | D13: Income statement, cash flow and balance sheet — every year and any year by month
B14: 3 | C14: =HYPERLINK("#'Break-even'!A1","Break-even") -> Break-even | D14: Startup costs, funding need, break-even timing and revenue
B15: 4 | C15: =HYPERLINK("#Valuation!A1","Valuation") -> Valuation | D15: Free cash flow, DCF (perpetual growth and exit multiple), WACC × growth sensitivity
B16: 5 | C16: =HYPERLINK("#'Sources & Uses'!A1","Sources & Uses") -> Sources & Uses | D16: Funding structure, sources and uses of cash for the first months
B17: 6 | C17: =HYPERLINK("#KPIs!A1","KPIs") -> KPIs | D17: Financial ratios, DuPont analysis, industry metrics
B18: 7 | C18: =HYPERLINK("#Returns!A1","Returns") -> Returns | D18: Property returns: unlevered and levered IRR, NPV, multiple
C19: INPUTS
B20: 8 | C20: =HYPERLINK("#Inputs!A1","Inputs") -> Inputs | D20: Every assumption, Low / Base / High, with units and comments
C21: STATEMENTS
B22: 9 | C22: =HYPERLINK("#'P&L'!A1","P&L") -> P&L | D22: Annual profit & loss
B23: 10 | C23: =HYPERLINK("#'Cash Flow'!A1","Cash Flow") -> Cash Flow | D23: Annual cash flow statement
B24: 11 | C24: =HYPERLINK("#'Balance Sheet'!A1","Balance Sheet") -> Balance Sheet | D24: Balance sheet at year end
C25: CALCULATIONS
B26: 12 | C26: =HYPERLINK("#Monthly!A1","Monthly") -> Monthly | D26: Month-by-month engine of the model
B27: 13 | C27: =HYPERLINK("#Headcount!A1","Headcount") -> Headcount | D27: Team and payroll
C28: CONTROL
B29: 14 | C29: =HYPERLINK("#Checks!A1","Checks") -> Checks | D29: Live integrity checks and the overall verdict
B31: How to read this file
C32: 1000 | D32: Input you can change — yellow cell with a blue figure (Inputs sheet and the view switches)
C33: 1000 | D33: Formula — calculated, do not overwrite
C34: 1000 | D34: Link to another sheet
C35: 1000 | D35: Active value the model uses (follows the scenario)

Sheet Dashboard
A1: Dashboard | W1: =HYPERLINK("#'Cover'!A1","◂ Contents") -> ◂ Contents
A2: Rental property financial model (early)
A4: Active scenario | B4: 2 | C4: =CHOOSE(B4,"Low","Base","High") -> Base | D4: 1 = Low · 2 = Base · 3 = High — every sheet follows this cell | S4: Model checks | T4: =Checks!B30 -> PASS
A6: REVENUE · YEAR 5 | C6: EBITDA MARGIN · YEAR 5 | H6: NET INCOME · YEAR 5 | L6: LOWEST CASH BALANCE | P6: FUNDING REQUIRED | T6: ENTERPRISE VALUE (DCF)
A7: =F12 -> 221331.31 | C7: =F17 -> 0.63737605 | H7: =F18 -> 9742.0455 | L7: =F38 -> 58003.017 | P7: =F36 -> 1913997 | T7: =F43 -> -986206.56
A8: =IF(AND(B12>0,F12>=0),(F12/B12)^(1/4)-1,"CAGR n/a") -> 0.03 | C8: =F16 -> 141071.27 | H8: =F19 -> 0.044015669 | L8: ='Break-even'!B6 -> 1 | P8: =IF(F37>=0,"Covered by funding raised",-F37) -> Covered by funding raised | T8: Average of 2 methods
A10: Core financials ($'000) — active scenario
B11: 1 | C11: 2 | D11: 3 | E11: 4 | F11: 5
A12: Revenue | B12: =SUMIF(Monthly!$C$5:$BJ$5,B$11,Monthly!$C$12:$BJ$12) -> 196650 | C12: =SUMIF(Monthly!$C$5:$BJ$5,C$11,Monthly!$C$12:$BJ$12) -> 202549.5 | D12: =SUMIF(Monthly!$C$5:$BJ$5,D$11,Monthly!$C$12:$BJ$12) -> 208625.98 | E12: =SUMIF(Monthly!$C$5:$BJ$5,E$11,Monthly!$C$12:$BJ$12) -> 214884.76 | F12: =SUMIF(Monthly!$C$5:$BJ$5,F$11,Monthly!$C$12:$BJ$12) -> 221331.31
A13: Gross profit | B13: =SUMIF(Monthly!$C$5:$BJ$5,B$11,Monthly!$C$18:$BJ$18) -> 174222 | C13: =SUMIF(Monthly!$C$5:$BJ$5,C$11,Monthly!$C$18:$BJ$18) -> 179448.66 | D13: =SUMIF(Monthly!$C$5:$BJ$5,D$11,Monthly!$C$18:$BJ$18) -> 184832.12 | E13: =SUMIF(Monthly!$C$5:$BJ$5,E$11,Monthly!$C$18:$BJ$18) -> 190377.08 | F13: =SUMIF(Monthly!$C$5:$BJ$5,F$11,Monthly!$C$18:$BJ$18) -> 196088.4
A14: Gross margin | B14: =IF(B12=0,0,B13/B12) -> 0.88594966 | C14: =IF(C12=0,0,C13/C12) -> 0.88594966 | D14: =IF(D12=0,0,D13/D12) -> 0.88594966 | E14: =IF(E12=0,0,E13/E12) -> 0.88594966 | F14: =IF(F12=0,0,F13/F12) -> 0.88594966
A15: Operating expenses | B15: =SUMIF(Monthly!$C$5:$BJ$5,B$11,Monthly!$C$25:$BJ$25) -> -48882 | C15: =SUMIF(Monthly!$C$5:$BJ$5,C$11,Monthly!$C$25:$BJ$25) -> -50348.46 | D15: =SUMIF(Monthly!$C$5:$BJ$5,D$11,Monthly!$C$25:$BJ$25) -> -51858.914 | E15: =SUMIF(Monthly!$C$5:$BJ$5,E$11,Monthly!$C$25:$BJ$25) -> -53414.681 | F15: =SUMIF(Monthly!$C$5:$BJ$5,F$11,Monthly!$C$25:$BJ$25) -> -55017.122
A16: EBITDA | B16: =SUMIF(Monthly!$C$5:$BJ$5,B$11,Monthly!$C$26:$BJ$26) -> 125340 | C16: =SUMIF(Monthly!$C$5:$BJ$5,C$11,Monthly!$C$26:$BJ$26) -> 129100.2 | D16: =SUMIF(Monthly!$C$5:$BJ$5,D$11,Monthly!$C$26:$BJ$26) -> 132973.21 | E16: =SUMIF(Monthly!$C$5:$BJ$5,E$11,Monthly!$C$26:$BJ$26) -> 136962.4 | F16: =SUMIF(Monthly!$C$5:$BJ$5,F$11,Monthly!$C$26:$BJ$26) -> 141071.27
A17: EBITDA margin | B17: =IF(B12=0,0,B16/B12) -> 0.63737605 | C17: =IF(C12=0,0,C16/C12) -> 0.63737605 | D17: =IF(D12=0,0,D16/D12) -> 0.63737605 | E17: =IF(E12=0,0,E16/E12) -> 0.63737605 | F17: =IF(F12=0,0,F16/F12) -> 0.63737605
A18: Net income | B18: =SUMIF(Monthly!$C$5:$BJ$5,B$11,Monthly!$C$35:$BJ$35) -> -9205.6762 | C18: =SUMIF(Monthly!$C$5:$BJ$5,C$11,Monthly!$C$35:$BJ$35) -> -4678.9386 | D18: =SUMIF(Monthly!$C$5:$BJ$5,D$11,Monthly!$C$35:$BJ$35) -> 16.812047 | E18: =SUMIF(Monthly!$C$5:$BJ$5,E$11,Monthly!$C$35:$BJ$35) -> 4888.8702 | F18: =SUMIF(Monthly!$C$5:$BJ$5,F$11,Monthly!$C$35:$BJ$35) -> 9742.0455
A19: Net margin | B19: =IF(B12=0,0,B18/B12) -> -0.04681249 | C19: =IF(C12=0,0,C18/C12) -> -0.023100223 | D19: =IF(D12=0,0,D18/D12) -> 8.0584628e-05 | E19: =IF(E12=0,0,E18/E12) -> 0.022751125 | F19: =IF(F12=0,0,F18/F12) -> 0.044015669
A20: Operating cash flow | B20: =SUMIF(Monthly!$C$5:$BJ$5,B$11,Monthly!$C$65:$BJ$65) -> 48669.41 | C20: =SUMIF(Monthly!$C$5:$BJ$5,C$11,Monthly!$C$65:$BJ$65) -> 52421.419 | D20: =SUMIF(Monthly!$C$5:$BJ$5,D$11,Monthly!$C$65:$BJ$65) -> 57253.699 | E20: =SUMIF(Monthly!$C$5:$BJ$5,E$11,Monthly!$C$65:$BJ$65) -> 62266.382 | F20: =SUMIF(Monthly!$C$5:$BJ$5,F$11,Monthly!$C$65:$BJ$65) -> 67264.401
A21: Investing cash flow | B21: =SUMIF(Monthly!$C$5:$BJ$5,B$11,Monthly!$C$66:$BJ$66) -> -1909000 | C21: =SUMIF(Monthly!$C$5:$BJ$5,C$11,Monthly!$C$66:$BJ$66) -> -3605 | D21: =SUMIF(Monthly!$C$5:$BJ$5,D$11,Monthly!$C$66:$BJ$66) -> -3713.15 | E21: =SUMIF(Monthly!$C$5:$BJ$5,E$11,Monthly!$C$66:$BJ$66) -> -3824.5445 | F21: =SUMIF(Monthly!$C$5:$BJ$5,F$11,Monthly!$C$66:$BJ$66) -> -3939.2808
A22: Financing cash flow | B22: =SUMIF(Monthly!$C$5:$BJ$5,B$11,Monthly!$C$68:$BJ$68) -> 1946587.3 | C22: =SUMIF(Monthly!$C$5:$BJ$5,C$11,Monthly!$C$68:$BJ$68) -> -14310.979 | D22: =SUMIF(Monthly!$C$5:$BJ$5,D$11,Monthly!$C$68:$BJ$68) -> -15269.412 | E22: =SUMIF(Monthly!$C$5:$BJ$5,E$11,Monthly!$C$68:$BJ$68) -> -16292.033 | F22: =SUMIF(Monthly!$C$5:$BJ$5,F$11,Monthly!$C$68:$BJ$68) -> -17383.141
A23: Net change in cash | B23: =SUMIF(Monthly!$C$5:$BJ$5,B$11,Monthly!$C$69:$BJ$69) -> 86256.705 | C23: =SUMIF(Monthly!$C$5:$BJ$5,C$11,Monthly!$C$69:$BJ$69) -> 34505.44 | D23: =SUMIF(Monthly!$C$5:$BJ$5,D$11,Monthly!$C$69:$BJ$69) -> 38271.137 | E23: =SUMIF(Monthly!$C$5:$BJ$5,E$11,Monthly!$C$69:$BJ$69) -> 42149.805 | F23: =SUMIF(Monthly!$C$5:$BJ$5,F$11,Monthly!$C$69:$BJ$69) -> 45941.98
A24: Year-end cash | B24: =INDEX(Monthly!$C$71:$BJ$71,B$11*12) -> 86256.705 | C24: =INDEX(Monthly!$C$71:$BJ$71,C$11*12) -> 120762.14 | D24: =INDEX(Monthly!$C$71:$BJ$71,D$11*12) -> 159033.28 | E24: =INDEX(Monthly!$C$71:$BJ$71,E$11*12) -> 201183.09 | F24: =INDEX(Monthly!$C$71:$BJ$71,F$11*12) -> 247125.07
A26: Property metrics
B27: 1 | C27: 2 | D27: 3 | E27: 4 | F27: 5
A28: Net operating income (NOI) | B28: =KPIs!B33 -> 125340 | C28: =KPIs!C33 -> 129100.2 | D28: =KPIs!D33 -> 132973.21 | E28: =KPIs!E33 -> 136962.4 | F28: =KPIs!F33 -> 141071.27
A29: Economic occupancy | B29: =KPIs!B31 -> 0.95 | C29: =KPIs!C31 -> 0.95 | D29: =KPIs!D31 -> 0.95 | E29: =KPIs!E31 -> 0.95 | F29: =KPIs!F31 -> 0.95
A30: Debt service (interest + principal) | B30: =KPIs!B38 -> 91017.795 | C30: =KPIs!C38 -> 91017.795 | D30: =KPIs!D38 -> 91017.795 | E30: =KPIs!E38 -> 91017.795 | F30: =KPIs!F38 -> 91017.795
A31: Debt service coverage | B31: =KPIs!B39 -> 1.3770933 | C31: =KPIs!C39 -> 1.4184061 | D31: =KPIs!D39 -> 1.4609583 | E31: =KPIs!E39 -> 1.5047871 | F31: =KPIs!F39 -> 1.5499307
A33: Funding & valuation ($'000) — active scenario
A34: Equity raised | F34: =Inputs!$E$34 -> 760000
A35: Loan drawn | F35: =Inputs!$E$35 -> 1200000
A36: Funding required (incl. cash buffer) | F36: ='Break-even'!B12 -> 1913997
A37: Funding surplus / (shortfall) | F37: ='Break-even'!B17 -> 46003.017
A38: ="Lowest cash balance (month "&'Break-even'!B6&")" -> Lowest cash balance (month 1) | F38: ='Break-even'!B18 -> 58003.017
A39: First month with positive EBITDA | F39: ='Break-even'!B21 -> 1
A40: Cash invested paid back | F40: ='Break-even'!B23 -> Not within horizon
A41: Enterprise value — perpetual growth | F41: =Valuation!B27 -> -975424.3
A42: Enterprise value — exit multiple | F42: =Valuation!C27 -> -996988.81
A43: Enterprise value — average | F43: =Valuation!B30 -> -986206.56

Sheet Summary
A1: Financial statements summary | U1: =HYPERLINK("#'Cover'!A1","◂ Contents") -> ◂ Contents
A2: Rental property financial model (early) | P2: Select detailed year: | R2: 1
A5: Income statement ($'000) — by year | H5: ="Income statement ($'000) — Year "&$R$2&", by month" -> Income statement ($'000) — Year 1, by month
B6: 1 | C6: 2 | D6: 3 | E6: 4 | F6: 5 | H6: =INDEX(Monthly!$C$4:$BJ$4,($R$2-1)*12+1) -> 1 | I6: =INDEX(Monthly!$C$4:$BJ$4,($R$2-1)*12+2) -> 2 | J6: =INDEX(Monthly!$C$4:$BJ$4,($R$2-1)*12+3) -> 3 | K6: =INDEX(Monthly!$C$4:$BJ$4,($R$2-1)*12+4) -> 4 | L6: =INDEX(Monthly!$C$4:$BJ$4,($R$2-1)*12+5) -> 5 | M6: =INDEX(Monthly!$C$4:$BJ$4,($R$2-1)*12+6) -> 6 | N6: =INDEX(Monthly!$C$4:$BJ$4,($R$2-1)*12+7) -> 7 | O6: =INDEX(Monthly!$C$4:$BJ$4,($R$2-1)*12+8) -> 8 | P6: =INDEX(Monthly!$C$4:$BJ$4,($R$2-1)*12+9) -> 9 | Q6: =INDEX(Monthly!$C$4:$BJ$4,($R$2-1)*12+10) -> 10 | R6: =INDEX(Monthly!$C$4:$BJ$4,($R$2-1)*12+11) -> 11 | S6: =INDEX(Monthly!$C$4:$BJ$4,($R$2-1)*12+12) -> 12
A7: Revenue | B7: ='P&L'!B5 -> 196650 | C7: ='P&L'!C5 -> 202549.5 | D7: ='P&L'!D5 -> 208625.98 | E7: ='P&L'!E5 -> 214884.76 | F7: ='P&L'!F5 -> 221331.31 | H7: =INDEX(Monthly!$C$12:$BJ$12,($R$2-1)*12+1) -> 16387.5 | I7: =INDEX(Monthly!$C$12:$BJ$12,($R$2-1)*12+2) -> 16387.5 | J7: =INDEX(Monthly!$C$12:$BJ$12,($R$2-1)*12+3) -> 16387.5 | K7: =INDEX(Monthly!$C$12:$BJ$12,($R$2-1)*12+4) -> 16387.5 | L7: =INDEX(Monthly!$C$12:$BJ$12,($R$2-1)*12+5) -> 16387.5 | M7: =INDEX(Monthly!$C$12:$BJ$12,($R$2-1)*12+6) -> 16387.5 | N7: =INDEX(Monthly!$C$12:$BJ$12,($R$2-1)*12+7) -> 16387.5 | O7: =INDEX(Monthly!$C$12:$BJ$12,($R$2-1)*12+8) -> 16387.5 | P7: =INDEX(Monthly!$C$12:$BJ$12,($R$2-1)*12+9) -> 16387.5 | Q7: =INDEX(Monthly!$C$12:$BJ$12,($R$2-1)*12+10) -> 16387.5 | R7: =INDEX(Monthly!$C$12:$BJ$12,($R$2-1)*12+11) -> 16387.5 | S7: =INDEX(Monthly!$C$12:$BJ$12,($R$2-1)*12+12) -> 16387.5
A8: Direct property costs | B8: ='P&L'!B6 -> -22428 | C8: ='P&L'!C6 -> -23100.84 | D8: ='P&L'!D6 -> -23793.865 | E8: ='P&L'!E6 -> -24507.681 | F8: ='P&L'!F6 -> -25242.912 | H8: =INDEX(Monthly!$C$17:$BJ$17,($R$2-1)*12+1) -> -1869 | I8: =INDEX(Monthly!$C$17:$BJ$17,($R$2-1)*12+2) -> -1869 | J8: =INDEX(Monthly!$C$17:$BJ$17,($R$2-1)*12+3) -> -1869 | K8: =INDEX(Monthly!$C$17:$BJ$17,($R$2-1)*12+4) -> -1869 | L8: =INDEX(Monthly!$C$17:$BJ$17,($R$2-1)*12+5) -> -1869 | M8: =INDEX(Monthly!$C$17:$BJ$17,($R$2-1)*12+6) -> -1869 | N8: =INDEX(Monthly!$C$17:$BJ$17,($R$2-1)*12+7) -> -1869 | O8: =INDEX(Monthly!$C$17:$BJ$17,($R$2-1)*12+8) -> -1869 | P8: =INDEX(Monthly!$C$17:$BJ$17,($R$2-1)*12+9) -> -1869 | Q8: =INDEX(Monthly!$C$17:$BJ$17,($R$2-1)*12+10) -> -1869 | R8: =INDEX(Monthly!$C$17:$BJ$17,($R$2-1)*12+11) -> -1869 | S8: =INDEX(Monthly!$C$17:$BJ$17,($R$2-1)*12+12) -> -1869
A9: Gross profit | B9: ='P&L'!B7 -> 174222 | C9: ='P&L'!C7 -> 179448.66 | D9: ='P&L'!D7 -> 184832.12 | E9: ='P&L'!E7 -> 190377.08 | F9: ='P&L'!F7 -> 196088.4 | H9: =INDEX(Monthly!$C$18:$BJ$18,($R$2-1)*12+1) -> 14518.5 | I9: =INDEX(Monthly!$C$18:$BJ$18,($R$2-1)*12+2) -> 14518.5 | J9: =INDEX(Monthly!$C$18:$BJ$18,($R$2-1)*12+3) -> 14518.5 | K9: =INDEX(Monthly!$C$18:$BJ$18,($R$2-1)*12+4) -> 14518.5 | L9: =INDEX(Monthly!$C$18:$BJ$18,($R$2-1)*12+5) -> 14518.5 | M9: =INDEX(Monthly!$C$18:$BJ$18,($R$2-1)*12+6) -> 14518.5 | N9: =INDEX(Monthly!$C$18:$BJ$18,($R$2-1)*12+7) -> 14518.5 | O9: =INDEX(Monthly!$C$18:$BJ$18,($R$2-1)*12+8) -> 14518.5 | P9: =INDEX(Monthly!$C$18:$BJ$18,($R$2-1)*12+9) -> 14518.5 | Q9: =INDEX(Monthly!$C$18:$BJ$18,($R$2-1)*12+10) -> 14518.5 | R9: =INDEX(Monthly!$C$18:$BJ$18,($R$2-1)*12+11) -> 14518.5 | S9: =INDEX(Monthly!$C$18:$BJ$18,($R$2-1)*12+12) -> 14518.5
A10: Gross margin | B10: ='P&L'!B8 -> 0.88594966 | C10: ='P&L'!C8 -> 0.88594966 | D10: ='P&L'!D8 -> 0.88594966 | E10: ='P&L'!E8 -> 0.88594966 | F10: ='P&L'!F8 -> 0.88594966 | H10: =IF(H7=0,0,H9/H7) -> 0.88594966 | I10: =IF(I7=0,0,I9/I7) -> 0.88594966 | J10: =IF(J7=0,0,J9/J7) -> 0.88594966 | K10: =IF(K7=0,0,K9/K7) -> 0.88594966 | L10: =IF(L7=0,0,L9/L7) -> 0.88594966 | M10: =IF(M7=0,0,M9/M7) -> 0.88594966 | N10: =IF(N7=0,0,N9/N7) -> 0.88594966 | O10: =IF(O7=0,0,O9/O7) -> 0.88594966 | ... S10: =IF(S7=0,0,S9/S7) -> 0.88594966
A11: Total operating expenses | B11: ='P&L'!B13 -> -48882 | C11: ='P&L'!C13 -> -50348.46 | D11: ='P&L'!D13 -> -51858.914 | E11: ='P&L'!E13 -> -53414.681 | F11: ='P&L'!F13 -> -55017.122 | H11: =INDEX(Monthly!$C$25:$BJ$25,($R$2-1)*12+1) -> -4073.5 | I11: =INDEX(Monthly!$C$25:$BJ$25,($R$2-1)*12+2) -> -4073.5 | J11: =INDEX(Monthly!$C$25:$BJ$25,($R$2-1)*12+3) -> -4073.5 | K11: =INDEX(Monthly!$C$25:$BJ$25,($R$2-1)*12+4) -> -4073.5 | L11: =INDEX(Monthly!$C$25:$BJ$25,($R$2-1)*12+5) -> -4073.5 | M11: =INDEX(Monthly!$C$25:$BJ$25,($R$2-1)*12+6) -> -4073.5 | N11: =INDEX(Monthly!$C$25:$BJ$25,($R$2-1)*12+7) -> -4073.5 | O11: =INDEX(Monthly!$C$25:$BJ$25,($R$2-1)*12+8) -> -4073.5 | P11: =INDEX(Monthly!$C$25:$BJ$25,($R$2-1)*12+9) -> -4073.5 | Q11: =INDEX(Monthly!$C$25:$BJ$25,($R$2-1)*12+10) -> -4073.5 | R11: =INDEX(Monthly!$C$25:$BJ$25,($R$2-1)*12+11) -> -4073.5 | S11: =INDEX(Monthly!$C$25:$BJ$25,($R$2-1)*12+12) -> -4073.5
A12: EBITDA | B12: ='P&L'!B14 -> 125340 | C12: ='P&L'!C14 -> 129100.2 | D12: ='P&L'!D14 -> 132973.21 | E12: ='P&L'!E14 -> 136962.4 | F12: ='P&L'!F14 -> 141071.27 | H12: =INDEX(Monthly!$C$26:$BJ$26,($R$2-1)*12+1) -> 10445 | I12: =INDEX(Monthly!$C$26:$BJ$26,($R$2-1)*12+2) -> 10445 | J12: =INDEX(Monthly!$C$26:$BJ$26,($R$2-1)*12+3) -> 10445 | K12: =INDEX(Monthly!$C$26:$BJ$26,($R$2-1)*12+4) -> 10445 | L12: =INDEX(Monthly!$C$26:$BJ$26,($R$2-1)*12+5) -> 10445 | M12: =INDEX(Monthly!$C$26:$BJ$26,($R$2-1)*12+6) -> 10445 | N12: =INDEX(Monthly!$C$26:$BJ$26,($R$2-1)*12+7) -> 10445 | O12: =INDEX(Monthly!$C$26:$BJ$26,($R$2-1)*12+8) -> 10445 | P12: =INDEX(Monthly!$C$26:$BJ$26,($R$2-1)*12+9) -> 10445 | Q12: =INDEX(Monthly!$C$26:$BJ$26,($R$2-1)*12+10) -> 10445 | R12: =INDEX(Monthly!$C$26:$BJ$26,($R$2-1)*12+11) -> 10445 | S12: =INDEX(Monthly!$C$26:$BJ$26,($R$2-1)*12+12) -> 10445
A13: EBITDA margin | B13: ='P&L'!B15 -> 0.63737605 | C13: ='P&L'!C15 -> 0.63737605 | D13: ='P&L'!D15 -> 0.63737605 | E13: ='P&L'!E15 -> 0.63737605 | F13: ='P&L'!F15 -> 0.63737605 | H13: =IF(H7=0,0,H12/H7) -> 0.63737605 | I13: =IF(I7=0,0,I12/I7) -> 0.63737605 | J13: =IF(J7=0,0,J12/J7) -> 0.63737605 | K13: =IF(K7=0,0,K12/K7) -> 0.63737605 | L13: =IF(L7=0,0,L12/L7) -> 0.63737605 | M13: =IF(M7=0,0,M12/M7) -> 0.63737605 | N13: =IF(N7=0,0,N12/N7) -> 0.63737605 | O13: =IF(O7=0,0,O12/O7) -> 0.63737605 | ... S13: =IF(S7=0,0,S12/S7) -> 0.63737605
A14: Depreciation | B14: ='P&L'!B16 -> -56940.586 | C14: ='P&L'!C16 -> -57072.323 | D14: ='P&L'!D16 -> -57208.011 | E14: ='P&L'!E16 -> -57347.77 | F14: ='P&L'!F16 -> -57491.721 | H14: =INDEX(Monthly!$C$44:$BJ$44,($R$2-1)*12+1) -> -4740.0977 | I14: =INDEX(Monthly!$C$44:$BJ$44,($R$2-1)*12+2) -> -4740.9979 | J14: =INDEX(Monthly!$C$44:$BJ$44,($R$2-1)*12+3) -> -4741.8981 | K14: =INDEX(Monthly!$C$44:$BJ$44,($R$2-1)*12+4) -> -4742.7984 | L14: =INDEX(Monthly!$C$44:$BJ$44,($R$2-1)*12+5) -> -4743.6986 | M14: =INDEX(Monthly!$C$44:$BJ$44,($R$2-1)*12+6) -> -4744.5988 | N14: =INDEX(Monthly!$C$44:$BJ$44,($R$2-1)*12+7) -> -4745.499 | O14: =INDEX(Monthly!$C$44:$BJ$44,($R$2-1)*12+8) -> -4746.3992 | P14: =INDEX(Monthly!$C$44:$BJ$44,($R$2-1)*12+9) -> -4747.2994 | Q14: =INDEX(Monthly!$C$44:$BJ$44,($R$2-1)*12+10) -> -4748.1996 | R14: =INDEX(Monthly!$C$44:$BJ$44,($R$2-1)*12+11) -> -4749.0998 | S14: =INDEX(Monthly!$C$44:$BJ$44,($R$2-1)*12+12) -> -4750
A15: EBIT | B15: ='P&L'!B17 -> 68399.414 | C15: ='P&L'!C17 -> 72027.877 | D15: ='P&L'!D17 -> 75765.195 | E15: ='P&L'!E17 -> 79614.633 | F15: ='P&L'!F17 -> 83579.553 | H15: =INDEX(Monthly!$C$29:$BJ$29,($R$2-1)*12+1) -> 5704.9023 | I15: =INDEX(Monthly!$C$29:$BJ$29,($R$2-1)*12+2) -> 5704.0021 | J15: =INDEX(Monthly!$C$29:$BJ$29,($R$2-1)*12+3) -> 5703.1019 | K15: =INDEX(Monthly!$C$29:$BJ$29,($R$2-1)*12+4) -> 5702.2016 | L15: =INDEX(Monthly!$C$29:$BJ$29,($R$2-1)*12+5) -> 5701.3014 | M15: =INDEX(Monthly!$C$29:$BJ$29,($R$2-1)*12+6) -> 5700.4012 | N15: =INDEX(Monthly!$C$29:$BJ$29,($R$2-1)*12+7) -> 5699.501 | O15: =INDEX(Monthly!$C$29:$BJ$29,($R$2-1)*12+8) -> 5698.6008 | P15: =INDEX(Monthly!$C$29:$BJ$29,($R$2-1)*12+9) -> 5697.7006 | Q15: =INDEX(Monthly!$C$29:$BJ$29,($R$2-1)*12+10) -> 5696.8004 | R15: =INDEX(Monthly!$C$29:$BJ$29,($R$2-1)*12+11) -> 5695.9002 | S15: =INDEX(Monthly!$C$29:$BJ$29,($R$2-1)*12+12) -> 5695
A16: Interest | B16: ='P&L'!B18 -> -77605.09 | C16: ='P&L'!C18 -> -76706.816 | D16: ='P&L'!D18 -> -75748.383 | E16: ='P&L'!E18 -> -74725.762 | F16: ='P&L'!F18 -> -73634.655 | H16: =INDEX(Monthly!$C$30:$BJ$30,($R$2-1)*12+1) -> -6500 | I16: =INDEX(Monthly!$C$30:$BJ$30,($R$2-1)*12+2) -> -6494.1239 | J16: =INDEX(Monthly!$C$30:$BJ$30,($R$2-1)*12+3) -> -6488.216 | K16: =INDEX(Monthly!$C$30:$BJ$30,($R$2-1)*12+4) -> -6482.2761 | L16: =INDEX(Monthly!$C$30:$BJ$30,($R$2-1)*12+5) -> -6476.304 | M16: =INDEX(Monthly!$C$30:$BJ$30,($R$2-1)*12+6) -> -6470.2995 | N16: =INDEX(Monthly!$C$30:$BJ$30,($R$2-1)*12+7) -> -6464.2626 | O16: =INDEX(Monthly!$C$30:$BJ$30,($R$2-1)*12+8) -> -6458.1929 | P16: =INDEX(Monthly!$C$30:$BJ$30,($R$2-1)*12+9) -> -6452.0904 | Q16: =INDEX(Monthly!$C$30:$BJ$30,($R$2-1)*12+10) -> -6445.9548 | R16: =INDEX(Monthly!$C$30:$BJ$30,($R$2-1)*12+11) -> -6439.7859 | S16: =INDEX(Monthly!$C$30:$BJ$30,($R$2-1)*12+12) -> -6433.5837
A17: Pre-tax income | B17: ='P&L'!B19 -> -9205.6762 | C17: ='P&L'!C19 -> -4678.9386 | D17: ='P&L'!D19 -> 16.812047 | E17: ='P&L'!E19 -> 4888.8702 | F17: ='P&L'!F19 -> 9944.8983 | H17: =INDEX(Monthly!$C$31:$BJ$31,($R$2-1)*12+1) -> -795.09774 | I17: =INDEX(Monthly!$C$31:$BJ$31,($R$2-1)*12+2) -> -790.12185 | J17: =INDEX(Monthly!$C$31:$BJ$31,($R$2-1)*12+3) -> -785.11414 | K17: =INDEX(Monthly!$C$31:$BJ$31,($R$2-1)*12+4) -> -780.07443 | L17: =INDEX(Monthly!$C$31:$BJ$31,($R$2-1)*12+5) -> -775.00254 | M17: =INDEX(Monthly!$C$31:$BJ$31,($R$2-1)*12+6) -> -769.89831 | N17: =INDEX(Monthly!$C$31:$BJ$31,($R$2-1)*12+7) -> -764.76155 | O17: =INDEX(Monthly!$C$31:$BJ$31,($R$2-1)*12+8) -> -759.59209 | P17: =INDEX(Monthly!$C$31:$BJ$31,($R$2-1)*12+9) -> -754.38975 | Q17: =INDEX(Monthly!$C$31:$BJ$31,($R$2-1)*12+10) -> -749.15436 | R17: =INDEX(Monthly!$C$31:$BJ$31,($R$2-1)*12+11) -> -743.88573 | S17: =INDEX(Monthly!$C$31:$BJ$31,($R$2-1)*12+12) -> -738.58369
A18: Income tax | B18: ='P&L'!B20 -> 0 | C18: ='P&L'!C20 -> 0 | D18: ='P&L'!D20 -> 0 | E18: ='P&L'!E20 -> 0 | F18: ='P&L'!F20 -> -202.85282 | H18: =INDEX(Monthly!$C$34:$BJ$34,($R$2-1)*12+1) -> 0 | I18: =INDEX(Monthly!$C$34:$BJ$34,($R$2-1)*12+2) -> 0 | J18: =INDEX(Monthly!$C$34:$BJ$34,($R$2-1)*12+3) -> 0 | K18: =INDEX(Monthly!$C$34:$BJ$34,($R$2-1)*12+4) -> 0 | L18: =INDEX(Monthly!$C$34:$BJ$34,($R$2-1)*12+5) -> 0 | M18: =INDEX(Monthly!$C$34:$BJ$34,($R$2-1)*12+6) -> 0 | N18: =INDEX(Monthly!$C$34:$BJ$34,($R$2-1)*12+7) -> 0 | O18: =INDEX(Monthly!$C$34:$BJ$34,($R$2-1)*12+8) -> 0 | P18: =INDEX(Monthly!$C$34:$BJ$34,($R$2-1)*12+9) -> 0 | Q18: =INDEX(Monthly!$C$34:$BJ$34,($R$2-1)*12+10) -> 0 | R18: =INDEX(Monthly!$C$34:$BJ$34,($R$2-1)*12+11) -> 0 | S18: =INDEX(Monthly!$C$34:$BJ$34,($R$2-1)*12+12) -> 0
A19: Net income | B19: ='P&L'!B21 -> -9205.6762 | C19: ='P&L'!C21 -> -4678.9386 | D19: ='P&L'!D21 -> 16.812047 | E19: ='P&L'!E21 -> 4888.8702 | F19: ='P&L'!F21 -> 9742.0455 | H19: =INDEX(Monthly!$C$35:$BJ$35,($R$2-1)*12+1) -> -795.09774 | I19: =INDEX(Monthly!$C$35:$BJ$35,($R$2-1)*12+2) -> -790.12185 | J19: =INDEX(Monthly!$C$35:$BJ$35,($R$2-1)*12+3) -> -785.11414 | K19: =INDEX(Monthly!$C$35:$BJ$35,($R$2-1)*12+4) -> -780.07443 | L19: =INDEX(Monthly!$C$35:$BJ$35,($R$2-1)*12+5) -> -775.00254 | M19: =INDEX(Monthly!$C$35:$BJ$35,($R$2-1)*12+6) -> -769.89831 | N19: =INDEX(Monthly!$C$35:$BJ$35,($R$2-1)*12+7) -> -764.76155 | O19: =INDEX(Monthly!$C$35:$BJ$35,($R$2-1)*12+8) -> -759.59209 | P19: =INDEX(Monthly!$C$35:$BJ$35,($R$2-1)*12+9) -> -754.38975 | Q19: =INDEX(Monthly!$C$35:$BJ$35,($R$2-1)*12+10) -> -749.15436 | R19: =INDEX(Monthly!$C$35:$BJ$35,($R$2-1)*12+11) -> -743.88573 | S19: =INDEX(Monthly!$C$35:$BJ$35,($R$2-1)*12+12) -> -738.58369
A20: Net margin | B20: ='P&L'!B22 -> -0.04681249 | C20: ='P&L'!C22 -> -0.023100223 | D20: ='P&L'!D22 -> 8.0584628e-05 | E20: ='P&L'!E22 -> 0.022751125 | F20: ='P&L'!F22 -> 0.044015669 | H20: =IF(H7=0,0,H19/H7) -> -0.04851855 | I20: =IF(I7=0,0,I19/I7) -> -0.048214911 | J20: =IF(J7=0,0,J19/J7) -> -0.04790933 | K20: =IF(K7=0,0,K19/K7) -> -0.047601796 | L20: =IF(L7=0,0,L19/L7) -> -0.047292299 | M20: =IF(M7=0,0,M19/M7) -> -0.046980827 | N20: =IF(N7=0,0,N19/N7) -> -0.046667371 | O20: =IF(O7=0,0,O19/O7) -> -0.04635192 | ... S20: =IF(S7=0,0,S19/S7) -> -0.045069943
A22: Cash flow ($'000) — by year | H22: ="Cash flow ($'000) — Year "&$R$2&", by month" -> Cash flow ($'000) — Year 1, by month
B23: 1 | C23: 2 | D23: 3 | E23: 4 | F23: 5 | H23: =INDEX(Monthly!$C$4:$BJ$4,($R$2-1)*12+1) -> 1 | I23: =INDEX(Monthly!$C$4:$BJ$4,($R$2-1)*12+2) -> 2 | J23: =INDEX(Monthly!$C$4:$BJ$4,($R$2-1)*12+3) -> 3 | K23: =INDEX(Monthly!$C$4:$BJ$4,($R$2-1)*12+4) -> 4 | L23: =INDEX(Monthly!$C$4:$BJ$4,($R$2-1)*12+5) -> 5 | M23: =INDEX(Monthly!$C$4:$BJ$4,($R$2-1)*12+6) -> 6 | N23: =INDEX(Monthly!$C$4:$BJ$4,($R$2-1)*12+7) -> 7 | O23: =INDEX(Monthly!$C$4:$BJ$4,($R$2-1)*12+8) -> 8 | P23: =INDEX(Monthly!$C$4:$BJ$4,($R$2-1)*12+9) -> 9 | Q23: =INDEX(Monthly!$C$4:$BJ$4,($R$2-1)*12+10) -> 10 | R23: =INDEX(Monthly!$C$4:$BJ$4,($R$2-1)*12+11) -> 11 | S23: =INDEX(Monthly!$C$4:$BJ$4,($R$2-1)*12+12) -> 12
A24: Operating cash flow | B24: ='Cash Flow'!B10 -> 48669.41 | C24: ='Cash Flow'!C10 -> 52421.419 | D24: ='Cash Flow'!D10 -> 57253.699 | E24: ='Cash Flow'!E10 -> 62266.382 | F24: ='Cash Flow'!F10 -> 67264.401 | H24: =INDEX(Monthly!$C$65:$BJ$65,($R$2-1)*12+1) -> 4879.5 | I24: =INDEX(Monthly!$C$65:$BJ$65,($R$2-1)*12+2) -> 3950.8761 | J24: =INDEX(Monthly!$C$65:$BJ$65,($R$2-1)*12+3) -> 3956.784 | K24: =INDEX(Monthly!$C$65:$BJ$65,($R$2-1)*12+4) -> 3962.7239 | L24: =INDEX(Monthly!$C$65:$BJ$65,($R$2-1)*12+5) -> 3968.696 | M24: =INDEX(Monthly!$C$65:$BJ$65,($R$2-1)*12+6) -> 3974.7005 | N24: =INDEX(Monthly!$C$65:$BJ$65,($R$2-1)*12+7) -> 3980.7374 | O24: =INDEX(Monthly!$C$65:$BJ$65,($R$2-1)*12+8) -> 3986.8071 | P24: =INDEX(Monthly!$C$65:$BJ$65,($R$2-1)*12+9) -> 3992.9096 | Q24: =INDEX(Monthly!$C$65:$BJ$65,($R$2-1)*12+10) -> 3999.0452 | R24: =INDEX(Monthly!$C$65:$BJ$65,($R$2-1)*12+11) -> 4005.2141 | S24: =INDEX(Monthly!$C$65:$BJ$65,($R$2-1)*12+12) -> 4011.4163
A25: Capital spending | B25: ='Cash Flow'!B11 -> -1909000 | C25: ='Cash Flow'!C11 -> -3605 | D25: ='Cash Flow'!D11 -> -3713.15 | E25: ='Cash Flow'!E11 -> -3824.5445 | F25: ='Cash Flow'!F11 -> -3939.2808 | H25: =INDEX(Monthly!$C$66:$BJ$66,($R$2-1)*12+1) -> -1905791.7 | I25: =INDEX(Monthly!$C$66:$BJ$66,($R$2-1)*12+2) -> -291.66667 | J25: =INDEX(Monthly!$C$66:$BJ$66,($R$2-1)*12+3) -> -291.66667 | K25: =INDEX(Monthly!$C$66:$BJ$66,($R$2-1)*12+4) -> -291.66667 | L25: =INDEX(Monthly!$C$66:$BJ$66,($R$2-1)*12+5) -> -291.66667 | M25: =INDEX(Monthly!$C$66:$BJ$66,($R$2-1)*12+6) -> -291.66667 | N25: =INDEX(Monthly!$C$66:$BJ$66,($R$2-1)*12+7) -> -291.66667 | O25: =INDEX(Monthly!$C$66:$BJ$66,($R$2-1)*12+8) -> -291.66667 | P25: =INDEX(Monthly!$C$66:$BJ$66,($R$2-1)*12+9) -> -291.66667 | Q25: =INDEX(Monthly!$C$66:$BJ$66,($R$2-1)*12+10) -> -291.66667 | R25: =INDEX(Monthly!$C$66:$BJ$66,($R$2-1)*12+11) -> -291.66667 | S25: =INDEX(Monthly!$C$66:$BJ$66,($R$2-1)*12+12) -> -291.66667
A26: Equity raised | B26: ='Cash Flow'!B12 -> 760000 | C26: ='Cash Flow'!C12 -> 0 | D26: ='Cash Flow'!D12 -> 0 | E26: ='Cash Flow'!E12 -> 0 | F26: ='Cash Flow'!F12 -> 0 | H26: =INDEX(Monthly!$C$67:$BJ$67,($R$2-1)*12+1) -> 760000 | I26: =INDEX(Monthly!$C$67:$BJ$67,($R$2-1)*12+2) -> 0 | J26: =INDEX(Monthly!$C$67:$BJ$67,($R$2-1)*12+3) -> 0 | K26: =INDEX(Monthly!$C$67:$BJ$67,($R$2-1)*12+4) -> 0 | L26: =INDEX(Monthly!$C$67:$BJ$67,($R$2-1)*12+5) -> 0 | M26: =INDEX(Monthly!$C$67:$BJ$67,($R$2-1)*12+6) -> 0 | N26: =INDEX(Monthly!$C$67:$BJ$67,($R$2-1)*12+7) -> 0 | O26: =INDEX(Monthly!$C$67:$BJ$67,($R$2-1)*12+8) -> 0 | P26: =INDEX(Monthly!$C$67:$BJ$67,($R$2-1)*12+9) -> 0 | Q26: =INDEX(Monthly!$C$67:$BJ$67,($R$2-1)*12+10) -> 0 | R26: =INDEX(Monthly!$C$67:$BJ$67,($R$2-1)*12+11) -> 0 | S26: =INDEX(Monthly!$C$67:$BJ$67,($R$2-1)*12+12) -> 0
A27: Loan drawdown | B27: ='Cash Flow'!B13 -> 1200000 | C27: ='Cash Flow'!C13 -> 0 | D27: ='Cash Flow'!D13 -> 0 | E27: ='Cash Flow'!E13 -> 0 | F27: ='Cash Flow'!F13 -> 0 | H27: =INDEX(Monthly!$C$50:$BJ$50,($R$2-1)*12+1) -> 1200000 | I27: =INDEX(Monthly!$C$50:$BJ$50,($R$2-1)*12+2) -> 0 | J27: =INDEX(Monthly!$C$50:$BJ$50,($R$2-1)*12+3) -> 0 | K27: =INDEX(Monthly!$C$50:$BJ$50,($R$2-1)*12+4) -> 0 | L27: =INDEX(Monthly!$C$50:$BJ$50,($R$2-1)*12+5) -> 0 | M27: =INDEX(Monthly!$C$50:$BJ$50,($R$2-1)*12+6) -> 0 | N27: =INDEX(Monthly!$C$50:$BJ$50,($R$2-1)*12+7) -> 0 | O27: =INDEX(Monthly!$C$50:$BJ$50,($R$2-1)*12+8) -> 0 | P27: =INDEX(Monthly!$C$50:$BJ$50,($R$2-1)*12+9) -> 0 | Q27: =INDEX(Monthly!$C$50:$BJ$50,($R$2-1)*12+10) -> 0 | R27: =INDEX(Monthly!$C$50:$BJ$50,($R$2-1)*12+11) -> 0 | S27: =INDEX(Monthly!$C$50:$BJ$50,($R$2-1)*12+12) -> 0
A28: Loan repayment | B28: ='Cash Flow'!B14 -> -13412.706 | C28: ='Cash Flow'!C14 -> -14310.979 | D28: ='Cash Flow'!D14 -> -15269.412 | E28: ='Cash Flow'!E14 -> -16292.033 | F28: ='Cash Flow'!F14 -> -17383.141 | H28: =INDEX(Monthly!$C$52:$BJ$52,($R$2-1)*12+1) -> -1084.8163 | I28: =INDEX(Monthly!$C$52:$BJ$52,($R$2-1)*12+2) -> -1090.6924 | J28: =INDEX(Monthly!$C$52:$BJ$52,($R$2-1)*12+3) -> -1096.6003 | K28: =INDEX(Monthly!$C$52:$BJ$52,($R$2-1)*12+4) -> -1102.5402 | L28: =INDEX(Monthly!$C$52:$BJ$52,($R$2-1)*12+5) -> -1108.5123 | M28: =INDEX(Monthly!$C$52:$BJ$52,($R$2-1)*12+6) -> -1114.5167 | N28: =INDEX(Monthly!$C$52:$BJ$52,($R$2-1)*12+7) -> -1120.5537 | O28: =INDEX(Monthly!$C$52:$BJ$52,($R$2-1)*12+8) -> -1126.6234 | P28: =INDEX(Monthly!$C$52:$BJ$52,($R$2-1)*12+9) -> -1132.7259 | Q28: =INDEX(Monthly!$C$52:$BJ$52,($R$2-1)*12+10) -> -1138.8615 | R28: =INDEX(Monthly!$C$52:$BJ$52,($R$2-1)*12+11) -> -1145.0303 | S28: =INDEX(Monthly!$C$52:$BJ$52,($R$2-1)*12+12) -> -1151.2326
A29: Financing cash flow | B29: ='Cash Flow'!B15 -> 1946587.3 | C29: ='Cash Flow'!C15 -> -14310.979 | D29: ='Cash Flow'!D15 -> -15269.412 | E29: ='Cash Flow'!E15 -> -16292.033 | F29: ='Cash Flow'!F15 -> -17383.141 | H29: =INDEX(Monthly!$C$68:$BJ$68,($R$2-1)*12+1) -> 1958915.2 | I29: =INDEX(Monthly!$C$68:$BJ$68,($R$2-1)*12+2) -> -1090.6924 | J29: =INDEX(Monthly!$C$68:$BJ$68,($R$2-1)*12+3) -> -1096.6003 | K29: =INDEX(Monthly!$C$68:$BJ$68,($R$2-1)*12+4) -> -1102.5402 | L29: =INDEX(Monthly!$C$68:$BJ$68,($R$2-1)*12+5) -> -1108.5123 | M29: =INDEX(Monthly!$C$68:$BJ$68,($R$2-1)*12+6) -> -1114.5167 | N29: =INDEX(Monthly!$C$68:$BJ$68,($R$2-1)*12+7) -> -1120.5537 | O29: =INDEX(Monthly!$C$68:$BJ$68,($R$2-1)*12+8) -> -1126.6234 | P29: =INDEX(Monthly!$C$68:$BJ$68,($R$2-1)*12+9) -> -1132.7259 | Q29: =INDEX(Monthly!$C$68:$BJ$68,($R$2-1)*12+10) -> -1138.8615 | R29: =INDEX(Monthly!$C$68:$BJ$68,($R$2-1)*12+11) -> -1145.0303 | S29: =INDEX(Monthly!$C$68:$BJ$68,($R$2-1)*12+12) -> -1151.2326
A30: Net change in cash | B30: ='Cash Flow'!B16 -> 86256.705 | C30: ='Cash Flow'!C16 -> 34505.44 | D30: ='Cash Flow'!D16 -> 38271.137 | E30: ='Cash Flow'!E16 -> 42149.805 | F30: ='Cash Flow'!F16 -> 45941.98 | H30: =INDEX(Monthly!$C$69:$BJ$69,($R$2-1)*12+1) -> 58003.017 | I30: =INDEX(Monthly!$C$69:$BJ$69,($R$2-1)*12+2) -> 2568.5171 | J30: =INDEX(Monthly!$C$69:$BJ$69,($R$2-1)*12+3) -> 2568.5171 | K30: =INDEX(Monthly!$C$69:$BJ$69,($R$2-1)*12+4) -> 2568.5171 | L30: =INDEX(Monthly!$C$69:$BJ$69,($R$2-1)*12+5) -> 2568.5171 | M30: =INDEX(Monthly!$C$69:$BJ$69,($R$2-1)*12+6) -> 2568.5171 | N30: =INDEX(Monthly!$C$69:$BJ$69,($R$2-1)*12+7) -> 2568.5171 | O30: =INDEX(Monthly!$C$69:$BJ$69,($R$2-1)*12+8) -> 2568.5171 | P30: =INDEX(Monthly!$C$69:$BJ$69,($R$2-1)*12+9) -> 2568.5171 | Q30: =INDEX(Monthly!$C$69:$BJ$69,($R$2-1)*12+10) -> 2568.5171 | R30: =INDEX(Monthly!$C$69:$BJ$69,($R$2-1)*12+11) -> 2568.5171 | S30: =INDEX(Monthly!$C$69:$BJ$69,($R$2-1)*12+12) -> 2568.5171
A31: Closing cash | B31: ='Cash Flow'!B18 -> 86256.705 | C31: ='Cash Flow'!C18 -> 120762.14 | D31: ='Cash Flow'!D18 -> 159033.28 | E31: ='Cash Flow'!E18 -> 201183.09 | F31: ='Cash Flow'!F18 -> 247125.07 | H31: =INDEX(Monthly!$C$71:$BJ$71,($R$2-1)*12+1) -> 58003.017 | I31: =INDEX(Monthly!$C$71:$BJ$71,($R$2-1)*12+2) -> 60571.534 | J31: =INDEX(Monthly!$C$71:$BJ$71,($R$2-1)*12+3) -> 63140.051 | K31: =INDEX(Monthly!$C$71:$BJ$71,($R$2-1)*12+4) -> 65708.568 | L31: =INDEX(Monthly!$C$71:$BJ$71,($R$2-1)*12+5) -> 68277.085 | M31: =INDEX(Monthly!$C$71:$BJ$71,($R$2-1)*12+6) -> 70845.602 | N31: =INDEX(Monthly!$C$71:$BJ$71,($R$2-1)*12+7) -> 73414.119 | O31: =INDEX(Monthly!$C$71:$BJ$71,($R$2-1)*12+8) -> 75982.636 | P31: =INDEX(Monthly!$C$71:$BJ$71,($R$2-1)*12+9) -> 78551.153 | Q31: =INDEX(Monthly!$C$71:$BJ$71,($R$2-1)*12+10) -> 81119.671 | R31: =INDEX(Monthly!$C$71:$BJ$71,($R$2-1)*12+11) -> 83688.188 | S31: =INDEX(Monthly!$C$71:$BJ$71,($R$2-1)*12+12) -> 86256.705
A39: Balance sheet at year end ($'000) | H39: ="Balance sheet at month end ($'000) — Year "&$R$2 -> Balance sheet at month end ($'000) — Year 1
B40: 1 | C40: 2 | D40: 3 | E40: 4 | F40: 5 | H40: =INDEX(Monthly!$C$4:$BJ$4,($R$2-1)*12+1) -> 1 | I40: =INDEX(Monthly!$C$4:$BJ$4,($R$2-1)*12+2) -> 2 | J40: =INDEX(Monthly!$C$4:$BJ$4,($R$2-1)*12+3) -> 3 | K40: =INDEX(Monthly!$C$4:$BJ$4,($R$2-1)*12+4) -> 4 | L40: =INDEX(Monthly!$C$4:$BJ$4,($R$2-1)*12+5) -> 5 | M40: =INDEX(Monthly!$C$4:$BJ$4,($R$2-1)*12+6) -> 6 | N40: =INDEX(Monthly!$C$4:$BJ$4,($R$2-1)*12+7) -> 7 | O40: =INDEX(Monthly!$C$4:$BJ$4,($R$2-1)*12+8) -> 8 | P40: =INDEX(Monthly!$C$4:$BJ$4,($R$2-1)*12+9) -> 9 | Q40: =INDEX(Monthly!$C$4:$BJ$4,($R$2-1)*12+10) -> 10 | R40: =INDEX(Monthly!$C$4:$BJ$4,($R$2-1)*12+11) -> 11 | S40: =INDEX(Monthly!$C$4:$BJ$4,($R$2-1)*12+12) -> 12
A41: Cash | B41: ='Balance Sheet'!B5 -> 86256.705 | C41: ='Balance Sheet'!C5 -> 120762.14 | D41: ='Balance Sheet'!D5 -> 159033.28 | E41: ='Balance Sheet'!E5 -> 201183.09 | F41: ='Balance Sheet'!F5 -> 247125.07 | H41: =INDEX(Monthly!$C$71:$BJ$71,($R$2-1)*12+1) -> 58003.017 | I41: =INDEX(Monthly!$C$71:$BJ$71,($R$2-1)*12+2) -> 60571.534 | J41: =INDEX(Monthly!$C$71:$BJ$71,($R$2-1)*12+3) -> 63140.051 | K41: =INDEX(Monthly!$C$71:$BJ$71,($R$2-1)*12+4) -> 65708.568 | L41: =INDEX(Monthly!$C$71:$BJ$71,($R$2-1)*12+5) -> 68277.085 | M41: =INDEX(Monthly!$C$71:$BJ$71,($R$2-1)*12+6) -> 70845.602 | N41: =INDEX(Monthly!$C$71:$BJ$71,($R$2-1)*12+7) -> 73414.119 | O41: =INDEX(Monthly!$C$71:$BJ$71,($R$2-1)*12+8) -> 75982.636 | P41: =INDEX(Monthly!$C$71:$BJ$71,($R$2-1)*12+9) -> 78551.153 | Q41: =INDEX(Monthly!$C$71:$BJ$71,($R$2-1)*12+10) -> 81119.671 | R41: =INDEX(Monthly!$C$71:$BJ$71,($R$2-1)*12+11) -> 83688.188 | S41: =INDEX(Monthly!$C$71:$BJ$71,($R$2-1)*12+12) -> 86256.705
A42: Accounts receivable | B42: ='Balance Sheet'!B6 -> 0 | C42: ='Balance Sheet'!C6 -> 0 | D42: ='Balance Sheet'!D6 -> 0 | E42: ='Balance Sheet'!E6 -> 0 | F42: ='Balance Sheet'!F6 -> 0 | H42: =INDEX(Monthly!$C$57:$BJ$57,($R$2-1)*12+1) -> 0 | I42: =INDEX(Monthly!$C$57:$BJ$57,($R$2-1)*12+2) -> 0 | J42: =INDEX(Monthly!$C$57:$BJ$57,($R$2-1)*12+3) -> 0 | K42: =INDEX(Monthly!$C$57:$BJ$57,($R$2-1)*12+4) -> 0 | L42: =INDEX(Monthly!$C$57:$BJ$57,($R$2-1)*12+5) -> 0 | M42: =INDEX(Monthly!$C$57:$BJ$57,($R$2-1)*12+6) -> 0 | N42: =INDEX(Monthly!$C$57:$BJ$57,($R$2-1)*12+7) -> 0 | O42: =INDEX(Monthly!$C$57:$BJ$57,($R$2-1)*12+8) -> 0 | P42: =INDEX(Monthly!$C$57:$BJ$57,($R$2-1)*12+9) -> 0 | Q42: =INDEX(Monthly!$C$57:$BJ$57,($R$2-1)*12+10) -> 0 | R42: =INDEX(Monthly!$C$57:$BJ$57,($R$2-1)*12+11) -> 0 | S42: =INDEX(Monthly!$C$57:$BJ$57,($R$2-1)*12+12) -> 0
A43: Inventory | B43: ='Balance Sheet'!B7 -> 0 | C43: ='Balance Sheet'!C7 -> 0 | D43: ='Balance Sheet'!D7 -> 0 | E43: ='Balance Sheet'!E7 -> 0 | F43: ='Balance Sheet'!F7 -> 0 | H43: =INDEX(Monthly!$C$58:$BJ$58,($R$2-1)*12+1) -> 0 | I43: =INDEX(Monthly!$C$58:$BJ$58,($R$2-1)*12+2) -> 0 | J43: =INDEX(Monthly!$C$58:$BJ$58,($R$2-1)*12+3) -> 0 | K43: =INDEX(Monthly!$C$58:$BJ$58,($R$2-1)*12+4) -> 0 | L43: =INDEX(Monthly!$C$58:$BJ$58,($R$2-1)*12+5) -> 0 | M43: =INDEX(Monthly!$C$58:$BJ$58,($R$2-1)*12+6) -> 0 | N43: =INDEX(Monthly!$C$58:$BJ$58,($R$2-1)*12+7) -> 0 | O43: =INDEX(Monthly!$C$58:$BJ$58,($R$2-1)*12+8) -> 0 | P43: =INDEX(Monthly!$C$58:$BJ$58,($R$2-1)*12+9) -> 0 | Q43: =INDEX(Monthly!$C$58:$BJ$58,($R$2-1)*12+10) -> 0 | R43: =INDEX(Monthly!$C$58:$BJ$58,($R$2-1)*12+11) -> 0 | S43: =INDEX(Monthly!$C$58:$BJ$58,($R$2-1)*12+12) -> 0
A44: Net fixed assets | B44: ='Balance Sheet'!B8 -> 1852059.4 | C44: ='Balance Sheet'!C8 -> 1798592.1 | D44: ='Balance Sheet'!D8 -> 1745097.2 | E44: ='Balance Sheet'!E8 -> 1691574 | F44: ='Balance Sheet'!F8 -> 1638021.6 | H44: =INDEX(Monthly!$C$46:$BJ$46,($R$2-1)*12+1) -> 1901051.6 | I44: =INDEX(Monthly!$C$46:$BJ$46,($R$2-1)*12+2) -> 1896602.2 | J44: =INDEX(Monthly!$C$46:$BJ$46,($R$2-1)*12+3) -> 1892152 | K44: =INDEX(Monthly!$C$46:$BJ$46,($R$2-1)*12+4) -> 1887700.9 | L44: =INDEX(Monthly!$C$46:$BJ$46,($R$2-1)*12+5) -> 1883248.8 | M44: =INDEX(Monthly!$C$46:$BJ$46,($R$2-1)*12+6) -> 1878795.9 | N44: =INDEX(Monthly!$C$46:$BJ$46,($R$2-1)*12+7) -> 1874342.1 | O44: =INDEX(Monthly!$C$46:$BJ$46,($R$2-1)*12+8) -> 1869887.3 | P44: =INDEX(Monthly!$C$46:$BJ$46,($R$2-1)*12+9) -> 1865431.7 | Q44: =INDEX(Monthly!$C$46:$BJ$46,($R$2-1)*12+10) -> 1860975.2 | R44: =INDEX(Monthly!$C$46:$BJ$46,($R$2-1)*12+11) -> 1856517.7 | S44: =INDEX(Monthly!$C$46:$BJ$46,($R$2-1)*12+12) -> 1852059.4
A45: Total assets | B45: ='Balance Sheet'!B9 -> 1938316.1 | C45: ='Balance Sheet'!C9 -> 1919354.2 | D45: ='Balance Sheet'!D9 -> 1904130.5 | E45: ='Balance Sheet'!E9 -> 1892757.1 | F45: ='Balance Sheet'!F9 -> 1885146.6 | H45: =INDEX(Monthly!$C$85:$BJ$85,($R$2-1)*12+1) -> 1959054.6 | I45: =INDEX(Monthly!$C$85:$BJ$85,($R$2-1)*12+2) -> 1957173.8 | J45: =INDEX(Monthly!$C$85:$BJ$85,($R$2-1)*12+3) -> 1955292.1 | K45: =INDEX(Monthly!$C$85:$BJ$85,($R$2-1)*12+4) -> 1953409.4 | L45: =INDEX(Monthly!$C$85:$BJ$85,($R$2-1)*12+5) -> 1951525.9 | M45: =INDEX(Monthly!$C$85:$BJ$85,($R$2-1)*12+6) -> 1949641.5 | N45: =INDEX(Monthly!$C$85:$BJ$85,($R$2-1)*12+7) -> 1947756.2 | O45: =INDEX(Monthly!$C$85:$BJ$85,($R$2-1)*12+8) -> 1945870 | P45: =INDEX(Monthly!$C$85:$BJ$85,($R$2-1)*12+9) -> 1943982.9 | Q45: =INDEX(Monthly!$C$85:$BJ$85,($R$2-1)*12+10) -> 1942094.9 | R45: =INDEX(Monthly!$C$85:$BJ$85,($R$2-1)*12+11) -> 1940205.9 | S45: =INDEX(Monthly!$C$85:$BJ$85,($R$2-1)*12+12) -> 1938316.1
A46: Accounts payable | B46: ='Balance Sheet'!B10 -> 934.5 | C46: ='Balance Sheet'!C10 -> 962.535 | D46: ='Balance Sheet'!D10 -> 991.41105 | E46: ='Balance Sheet'!E10 -> 1021.1534 | F46: ='Balance Sheet'!F10 -> 1051.788 | H46: =INDEX(Monthly!$C$59:$BJ$59,($R$2-1)*12+1) -> 934.5 | I46: =INDEX(Monthly!$C$59:$BJ$59,($R$2-1)*12+2) -> 934.5 | J46: =INDEX(Monthly!$C$59:$BJ$59,($R$2-1)*12+3) -> 934.5 | K46: =INDEX(Monthly!$C$59:$BJ$59,($R$2-1)*12+4) -> 934.5 | L46: =INDEX(Monthly!$C$59:$BJ$59,($R$2-1)*12+5) -> 934.5 | M46: =INDEX(Monthly!$C$59:$BJ$59,($R$2-1)*12+6) -> 934.5 | N46: =INDEX(Monthly!$C$59:$BJ$59,($R$2-1)*12+7) -> 934.5 | O46: =INDEX(Monthly!$C$59:$BJ$59,($R$2-1)*12+8) -> 934.5 | P46: =INDEX(Monthly!$C$59:$BJ$59,($R$2-1)*12+9) -> 934.5 | Q46: =INDEX(Monthly!$C$59:$BJ$59,($R$2-1)*12+10) -> 934.5 | R46: =INDEX(Monthly!$C$59:$BJ$59,($R$2-1)*12+11) -> 934.5 | S46: =INDEX(Monthly!$C$59:$BJ$59,($R$2-1)*12+12) -> 934.5
A47: Loan | B47: ='Balance Sheet'!B11 -> 1186587.3 | C47: ='Balance Sheet'!C11 -> 1172276.3 | D47: ='Balance Sheet'!D11 -> 1157006.9 | E47: ='Balance Sheet'!E11 -> 1140714.9 | F47: ='Balance Sheet'!F11 -> 1123331.7 | H47: =INDEX(Monthly!$C$54:$BJ$54,($R$2-1)*12+1) -> 1198915.2 | I47: =INDEX(Monthly!$C$54:$BJ$54,($R$2-1)*12+2) -> 1197824.5 | J47: =INDEX(Monthly!$C$54:$BJ$54,($R$2-1)*12+3) -> 1196727.9 | K47: =INDEX(Monthly!$C$54:$BJ$54,($R$2-1)*12+4) -> 1195625.4 | L47: =INDEX(Monthly!$C$54:$BJ$54,($R$2-1)*12+5) -> 1194516.8 | M47: =INDEX(Monthly!$C$54:$BJ$54,($R$2-1)*12+6) -> 1193402.3 | N47: =INDEX(Monthly!$C$54:$BJ$54,($R$2-1)*12+7) -> 1192281.8 | O47: =INDEX(Monthly!$C$54:$BJ$54,($R$2-1)*12+8) -> 1191155.1 | P47: =INDEX(Monthly!$C$54:$BJ$54,($R$2-1)*12+9) -> 1190022.4 | Q47: =INDEX(Monthly!$C$54:$BJ$54,($R$2-1)*12+10) -> 1188883.6 | R47: =INDEX(Monthly!$C$54:$BJ$54,($R$2-1)*12+11) -> 1187738.5 | S47: =INDEX(Monthly!$C$54:$BJ$54,($R$2-1)*12+12) -> 1186587.3
A48: Total liabilities | B48: ='Balance Sheet'!B12 -> 1187521.8 | C48: ='Balance Sheet'!C12 -> 1173238.9 | D48: ='Balance Sheet'!D12 -> 1157998.3 | E48: ='Balance Sheet'!E12 -> 1141736 | F48: ='Balance Sheet'!F12 -> 1124383.5 | H48: =INDEX(Monthly!$C$86:$BJ$86,($R$2-1)*12+1) -> 1199849.7 | I48: =INDEX(Monthly!$C$86:$BJ$86,($R$2-1)*12+2) -> 1198759 | J48: =INDEX(Monthly!$C$86:$BJ$86,($R$2-1)*12+3) -> 1197662.4 | K48: =INDEX(Monthly!$C$86:$BJ$86,($R$2-1)*12+4) -> 1196559.9 | L48: =INDEX(Monthly!$C$86:$BJ$86,($R$2-1)*12+5) -> 1195451.3 | M48: =INDEX(Monthly!$C$86:$BJ$86,($R$2-1)*12+6) -> 1194336.8 | N48: =INDEX(Monthly!$C$86:$BJ$86,($R$2-1)*12+7) -> 1193216.3 | O48: =INDEX(Monthly!$C$86:$BJ$86,($R$2-1)*12+8) -> 1192089.6 | P48: =INDEX(Monthly!$C$86:$BJ$86,($R$2-1)*12+9) -> 1190956.9 | Q48: =INDEX(Monthly!$C$86:$BJ$86,($R$2-1)*12+10) -> 1189818.1 | R48: =INDEX(Monthly!$C$86:$BJ$86,($R$2-1)*12+11) -> 1188673 | S48: =INDEX(Monthly!$C$86:$BJ$86,($R$2-1)*12+12) -> 1187521.8
A49: Paid-in capital | B49: ='Balance Sheet'!B13 -> 760000 | C49: ='Balance Sheet'!C13 -> 760000 | D49: ='Balance Sheet'!D13 -> 760000 | E49: ='Balance Sheet'!E13 -> 760000 | F49: ='Balance Sheet'!F13 -> 760000 | H49: =INDEX(Monthly!$C$83:$BJ$83,($R$2-1)*12+1) -> 760000 | I49: =INDEX(Monthly!$C$83:$BJ$83,($R$2-1)*12+2) -> 760000 | J49: =INDEX(Monthly!$C$83:$BJ$83,($R$2-1)*12+3) -> 760000 | K49: =INDEX(Monthly!$C$83:$BJ$83,($R$2-1)*12+4) -> 760000 | L49: =INDEX(Monthly!$C$83:$BJ$83,($R$2-1)*12+5) -> 760000 | M49: =INDEX(Monthly!$C$83:$BJ$83,($R$2-1)*12+6) -> 760000 | N49: =INDEX(Monthly!$C$83:$BJ$83,($R$2-1)*12+7) -> 760000 | O49: =INDEX(Monthly!$C$83:$BJ$83,($R$2-1)*12+8) -> 760000 | P49: =INDEX(Monthly!$C$83:$BJ$83,($R$2-1)*12+9) -> 760000 | Q49: =INDEX(Monthly!$C$83:$BJ$83,($R$2-1)*12+10) -> 760000 | R49: =INDEX(Monthly!$C$83:$BJ$83,($R$2-1)*12+11) -> 760000 | S49: =INDEX(Monthly!$C$83:$BJ$83,($R$2-1)*12+12) -> 760000
A50: Retained earnings | B50: ='Balance Sheet'!B14 -> -9205.6762 | C50: ='Balance Sheet'!C14 -> -13884.615 | D50: ='Balance Sheet'!D14 -> -13867.803 | E50: ='Balance Sheet'!E14 -> -8978.9325 | F50: ='Balance Sheet'!F14 -> 763.11298 | H50: =INDEX(Monthly!$C$84:$BJ$84,($R$2-1)*12+1) -> -795.09774 | I50: =INDEX(Monthly!$C$84:$BJ$84,($R$2-1)*12+2) -> -1585.2196 | J50: =INDEX(Monthly!$C$84:$BJ$84,($R$2-1)*12+3) -> -2370.3337 | K50: =INDEX(Monthly!$C$84:$BJ$84,($R$2-1)*12+4) -> -3150.4082 | L50: =INDEX(Monthly!$C$84:$BJ$84,($R$2-1)*12+5) -> -3925.4107 | M50: =INDEX(Monthly!$C$84:$BJ$84,($R$2-1)*12+6) -> -4695.309 | N50: =INDEX(Monthly!$C$84:$BJ$84,($R$2-1)*12+7) -> -5460.0706 | O50: =INDEX(Monthly!$C$84:$BJ$84,($R$2-1)*12+8) -> -6219.6627 | P50: =INDEX(Monthly!$C$84:$BJ$84,($R$2-1)*12+9) -> -6974.0524 | Q50: =INDEX(Monthly!$C$84:$BJ$84,($R$2-1)*12+10) -> -7723.2068 | R50: =INDEX(Monthly!$C$84:$BJ$84,($R$2-1)*12+11) -> -8467.0925 | S50: =INDEX(Monthly!$C$84:$BJ$84,($R$2-1)*12+12) -> -9205.6762
...

Sheet Break-even
A1: Startup costs, funding need and break-even | H1: =HYPERLINK("#'Cover'!A1","◂ Contents") -> ◂ Contents
A2: Live for the selected scenario. Periods are counted in months from the start of the plan.
A3: Scenario shown | B3: =CHOOSE(Dashboard!$B$4,"Low","Base","High") -> Base
A5: Startup costs & funding need (up to the lowest cash point)
A6: Lowest cash point (month #) | B6: =MATCH(MIN(Monthly!$C$71:$BJ$71),Monthly!$C$71:$BJ$71,0) -> 1
A7: Capital spending up to the lowest cash point | B7: =SUMPRODUCT(--(Monthly!$C$4:$BJ$4<=$B$6),Monthly!$C$41:$BJ$41) -> 1905791.7
A8: Operating cash burn up to the lowest cash point | B8: =-SUMPRODUCT(--(Monthly!$C$4:$BJ$4<=$B$6),Monthly!$C$65:$BJ$65) -> -4879.5 | D8: Losses and working capital before the business funds itself
A9: Loan repayments up to the lowest cash point | B9: =-SUMPRODUCT(--(Monthly!$C$4:$BJ$4<=$B$6),Monthly!$C$52:$BJ$52) -> 1084.8163
A10: Total uses of funds | B10: =B7+B8+B9 -> 1901997
A11: Minimum cash buffer to keep | B11: =Inputs!$E$49 -> 12000 | D11: Input on the Inputs sheet
A12: Funding required (uses + buffer) | B12: =B10+B11 -> 1913997
A14: Equity raised | B14: =Inputs!$E$34 -> 760000
A15: Loan drawn | B15: =Inputs!$E$35 -> 1200000
A16: Total sources of funds | B16: =B14+B15 -> 1960000
A17: Funding surplus / (shortfall) | B17: =B16-B12 -> 46003.017 | D17: Negative = raise at least this much more
A18: Lowest cash balance in the plan | B18: =MIN(Monthly!$C$71:$BJ$71) -> 58003.017 | D18: Equals sources minus uses
A20: Break-even timing
A21: First month with positive EBITDA (month #) | B21: =IFERROR(MATCH(1,Monthly!$C$72:$BJ$72,0),"Not within horizon") -> 1
A22: First month with positive net income (month #) | B22: =IFERROR(MATCH(1,Monthly!$C$75:$BJ$75,0),"Not within horizon") -> 31
A23: Cash invested paid back (month #) | B23: =IF(MIN(Monthly!$C$77:$BJ$77)>=0,"No investment to pay back",IFERROR(MATCH(1,Monthly!$C$79:$BJ$79,0),"Not within horizon")) -> Not within horizon | D23: Cumulative operating + investing cash flow back to zero
A25: Annual break-even revenue
A26: Year # | B26: 1 | C26: 2 | D26: 3 | E26: 4 | F26: 5
B27: Year 1 | C27: Year 2 | D27: Year 3 | E27: Year 4 | F27: Year 5
A28: Revenue | B28: =SUMIF(Monthly!$C$5:$BJ$5,B$26,Monthly!$C$12:$BJ$12) -> 196650 | C28: =SUMIF(Monthly!$C$5:$BJ$5,C$26,Monthly!$C$12:$BJ$12) -> 202549.5 | D28: =SUMIF(Monthly!$C$5:$BJ$5,D$26,Monthly!$C$12:$BJ$12) -> 208625.98 | E28: =SUMIF(Monthly!$C$5:$BJ$5,E$26,Monthly!$C$12:$BJ$12) -> 214884.76 | F28: =SUMIF(Monthly!$C$5:$BJ$5,F$26,Monthly!$C$12:$BJ$12) -> 221331.31
A29: Gross profit | B29: =SUMIF(Monthly!$C$5:$BJ$5,B$26,Monthly!$C$18:$BJ$18) -> 174222 | C29: =SUMIF(Monthly!$C$5:$BJ$5,C$26,Monthly!$C$18:$BJ$18) -> 179448.66 | D29: =SUMIF(Monthly!$C$5:$BJ$5,D$26,Monthly!$C$18:$BJ$18) -> 184832.12 | E29: =SUMIF(Monthly!$C$5:$BJ$5,E$26,Monthly!$C$18:$BJ$18) -> 190377.08 | F29: =SUMIF(Monthly!$C$5:$BJ$5,F$26,Monthly!$C$18:$BJ$18) -> 196088.4
A30: Gross margin (contribution) | B30: =IF(B28=0,0,B29/B28) -> 0.88594966 | C30: =IF(C28=0,0,C29/C28) -> 0.88594966 | D30: =IF(D28=0,0,D29/D28) -> 0.88594966 | E30: =IF(E28=0,0,E29/E28) -> 0.88594966 | F30: =IF(F28=0,0,F29/F28) -> 0.88594966
A31: Operating expenses (treated as fixed) | B31: =-SUMIF(Monthly!$C$5:$BJ$5,B$26,Monthly!$C$25:$BJ$25) -> 48882 | C31: =-SUMIF(Monthly!$C$5:$BJ$5,C$26,Monthly!$C$25:$BJ$25) -> 50348.46 | D31: =-SUMIF(Monthly!$C$5:$BJ$5,D$26,Monthly!$C$25:$BJ$25) -> 51858.914 | E31: =-SUMIF(Monthly!$C$5:$BJ$5,E$26,Monthly!$C$25:$BJ$25) -> 53414.681 | F31: =-SUMIF(Monthly!$C$5:$BJ$5,F$26,Monthly!$C$25:$BJ$25) -> 55017.122
A32: Break-even revenue (EBITDA = 0) | B32: =IF(B30>0,B31/B30,"n/a") -> 55174.693 | C32: =IF(C30>0,C31/C30,"n/a") -> 56829.933 | D32: =IF(D30>0,D31/D30,"n/a") -> 58534.831 | E32: =IF(E30>0,E31/E30,"n/a") -> 60290.876 | F32: =IF(F30>0,F31/F30,"n/a") -> 62099.603
A33: Margin of safety (revenue above break-even) | B33: =IF(AND(ISNUMBER(B32),B28>0),(B28-B32)/B28,"n/a") -> 0.71942694 | C33: =IF(AND(ISNUMBER(C32),C28>0),(C28-C32)/C28,"n/a") -> 0.71942694 | D33: =IF(AND(ISNUMBER(D32),D28>0),(D28-D32)/D28,"n/a") -> 0.71942694 | E33: =IF(AND(ISNUMBER(E32),E28>0),(E28-E32)/E28,"n/a") -> 0.71942694 | F33: =IF(AND(ISNUMBER(F32),F28>0),(F28-F32)/F28,"n/a") -> 0.71942694
A35: Simplification: cost of sales is treated as variable and operating expenses as fixed, so break-even revenue = operating expenses ÷ gross margin.

Sheet Valuation
A1: Discounted cash flow valuation | H1: =HYPERLINK("#'Cover'!A1","◂ Contents") -> ◂ Contents
A2: Enterprise value at the start of the plan, before the funding raised in period 1. Year-end discounting.
A3: Scenario shown | B3: =CHOOSE(Dashboard!$B$4,"Low","Base","High") -> Base
A5: Assumptions (active scenario, from the Inputs sheet)
A6: Discount rate (WACC) | B6: =Inputs!$E$52 -> 0.2
A7: Terminal growth rate | B7: =Inputs!$E$53 -> 0.02
A8: Exit multiple (EV ÷ final-year EBITDA) | B8: =Inputs!$E$54 -> 4.5
A9: Tax rate (for the interest tax shield) | B9: =Inputs!$E$46 -> 0.21
A10: Sensitivity step: WACC | B10: =Inputs!$E$55 -> 0.01
A11: Sensitivity step: terminal growth | B11: =Inputs!$E$56 -> 0.005
A13: Free cash flow by year
A14: Year # | B14: 1 | C14: 2 | D14: 3 | E14: 4 | F14: 5
B15: Year 1 | C15: Year 2 | D15: Year 3 | E15: Year 4 | F15: Year 5
A16: EBITDA | B16: =SUMIF(Monthly!$C$5:$BJ$5,B$14,Monthly!$C$26:$BJ$26) -> 125340 | C16: =SUMIF(Monthly!$C$5:$BJ$5,C$14,Monthly!$C$26:$BJ$26) -> 129100.2 | D16: =SUMIF(Monthly!$C$5:$BJ$5,D$14,Monthly!$C$26:$BJ$26) -> 132973.21 | E16: =SUMIF(Monthly!$C$5:$BJ$5,E$14,Monthly!$C$26:$BJ$26) -> 136962.4 | F16: =SUMIF(Monthly!$C$5:$BJ$5,F$14,Monthly!$C$26:$BJ$26) -> 141071.27
A17: Unlevered free cash flow | B17: =SUMIF(Monthly!$C$5:$BJ$5,B$14,Monthly!$C$80:$BJ$80) -> -1799022.6 | C17: =SUMIF(Monthly!$C$5:$BJ$5,C$14,Monthly!$C$80:$BJ$80) -> 109414.8 | D17: =SUMIF(Monthly!$C$5:$BJ$5,D$14,Monthly!$C$80:$BJ$80) -> 113381.77 | E17: =SUMIF(Monthly!$C$5:$BJ$5,E$14,Monthly!$C$80:$BJ$80) -> 117475.19 | F17: =SUMIF(Monthly!$C$5:$BJ$5,F$14,Monthly!$C$80:$BJ$80) -> 121496.5
A18: Discount factor | B18: =1/(1+Inputs!$E$52)^B$14 -> 0.83333333 | C18: =1/(1+Inputs!$E$52)^C$14 -> 0.69444444 | D18: =1/(1+Inputs!$E$52)^D$14 -> 0.5787037 | E18: =1/(1+Inputs!$E$52)^E$14 -> 0.48225309 | F18: =1/(1+Inputs!$E$52)^F$14 -> 0.40187757
A19: Present value of free cash flow | B19: =B17*B18 -> -1499185.5 | C19: =C17*C18 -> 75982.503 | D19: =D17*D18 -> 65614.451 | E19: =E17*E18 -> 56652.773 | F19: =F17*F18 -> 48826.717
A21: Enterprise value
B22: Perpetual growth | C22: Exit multiple
A23: Present value of the plan's free cash flows | B23: =SUM($B$19:$F$19) -> -1252109 | C23: =B23 -> -1252109
A24: Final-year free cash flow | final-year EBITDA | B24: =$F$17 -> 121496.5 | C24: =$F$16 -> 141071.27
A25: Terminal value at the end of year 5 | B25: =IF($B$6>$B$7,B24*(1+$B$7)/($B$6-$B$7),0) -> 688480.15 | C25: =C24*$B$8 -> 634820.73
A26: Present value of the terminal value | B26: =B25/(1+$B$6)^$F$14 -> 276684.73 | C26: =C25/(1+$B$6)^$F$14 -> 255120.22
A27: Enterprise value | B27: =B23+B26 -> -975424.3 | C27: =C23+C26 -> -996988.81
A28: Terminal value share of enterprise value | B28: =IF(B27<>0,B26/B27,0) -> -0.28365577 | C28: =IF(C27<>0,C26/C27,0) -> -0.25589075
A29: Cross-check: implied exit multiple | implied perpetual growth | B29: =IF(C24>0,B25/C24,"n/a") -> 4.880371 | C29: =IF(C25+B24<>0,(C25*$B$6-B24)/(C25+B24),"n/a") -> 0.0072293066
A30: Enterprise value — average of the two methods | B30: =AVERAGE(B27,C27) -> -986206.56
A32: Sensitivity: enterprise value (perpetual growth) by WACC and terminal growth
A33: WACC ↓ · terminal growth → | B33: =$B$7+(-2)*$B$11 -> 0.01 | C33: =$B$7+(-1)*$B$11 -> 0.015 | D33: =$B$7+(0)*$B$11 -> 0.02 | E33: =$B$7+(1)*$B$11 -> 0.025 | F33: =$B$7+(2)*$B$11 -> 0.03
A34: =$B$6+(-2)*$B$10 -> 0.18 | B34: =IF($A34>B$33,SUMPRODUCT($B$17:$F$17/(1+$A34)^$B$14:$F$14)+$F$17*(1+B$33)/($A34-B$33)/(1+$A34)^$F$14,"n/a") -> -947788.63 | C34: =IF($A34>C$33,SUMPRODUCT($B$17:$F$17/(1+$A34)^$B$14:$F$14)+$F$17*(1+C$33)/($A34-C$33)/(1+$A34)^$F$14,"n/a") -> -936618.12 | D34: =IF($A34>D$33,SUMPRODUCT($B$17:$F$17/(1+$A34)^$B$14:$F$14)+$F$17*(1+D$33)/($A34-D$33)/(1+$A34)^$F$14,"n/a") -> -924749.46 | E34: =IF($A34>E$33,SUMPRODUCT($B$17:$F$17/(1+$A34)^$B$14:$F$14)+$F$17*(1+E$33)/($A34-E$33)/(1+$A34)^$F$14,"n/a") -> -912115.08 | F34: =IF($A34>F$33,SUMPRODUCT($B$17:$F$17/(1+$A34)^$B$14:$F$14)+$F$17*(1+F$33)/($A34-F$33)/(1+$A34)^$F$14,"n/a") -> -898638.4
A35: =$B$6+(-1)*$B$10 -> 0.19 | B35: =IF($A35>B$33,SUMPRODUCT($B$17:$F$17/(1+$A35)^$B$14:$F$14)+$F$17*(1+B$33)/($A35-B$33)/(1+$A35)^$F$14,"n/a") -> -972063.34 | C35: =IF($A35>C$33,SUMPRODUCT($B$17:$F$17/(1+$A35)^$B$14:$F$14)+$F$17*(1+C$33)/($A35-C$33)/(1+$A35)^$F$14,"n/a") -> -962446.43 | D35: =IF($A35>D$33,SUMPRODUCT($B$17:$F$17/(1+$A35)^$B$14:$F$14)+$F$17*(1+D$33)/($A35-D$33)/(1+$A35)^$F$14,"n/a") -> -952263.83 | E35: =IF($A35>E$33,SUMPRODUCT($B$17:$F$17/(1+$A35)^$B$14:$F$14)+$F$17*(1+E$33)/($A35-E$33)/(1+$A35)^$F$14,"n/a") -> -941464.09 | F35: =IF($A35>F$33,SUMPRODUCT($B$17:$F$17/(1+$A35)^$B$14:$F$14)+$F$17*(1+F$33)/($A35-F$33)/(1+$A35)^$F$14,"n/a") -> -929989.38
A36: =$B$6+(0)*$B$10 -> 0.2 | B36: =IF($A36>B$33,SUMPRODUCT($B$17:$F$17/(1+$A36)^$B$14:$F$14)+$F$17*(1+B$33)/($A36-B$33)/(1+$A36)^$F$14,"n/a") -> -992556.48 | C36: =IF($A36>C$33,SUMPRODUCT($B$17:$F$17/(1+$A36)^$B$14:$F$14)+$F$17*(1+C$33)/($A36-C$33)/(1+$A36)^$F$14,"n/a") -> -984221.9 | D36: =IF($A36>D$33,SUMPRODUCT($B$17:$F$17/(1+$A36)^$B$14:$F$14)+$F$17*(1+D$33)/($A36-D$33)/(1+$A36)^$F$14,"n/a") -> -975424.3 | E36: =IF($A36>E$33,SUMPRODUCT($B$17:$F$17/(1+$A36)^$B$14:$F$14)+$F$17*(1+E$33)/($A36-E$33)/(1+$A36)^$F$14,"n/a") -> -966123.97 | F36: =IF($A36>F$33,SUMPRODUCT($B$17:$F$17/(1+$A36)^$B$14:$F$14)+$F$17*(1+F$33)/($A36-F$33)/(1+$A36)^$F$14,"n/a") -> -956276.57
A37: =$B$6+(1)*$B$10 -> 0.21 | B37: =IF($A37>B$33,SUMPRODUCT($B$17:$F$17/(1+$A37)^$B$14:$F$14)+$F$17*(1+B$33)/($A37-B$33)/(1+$A37)^$F$14,"n/a") -> -1009864.6 | C37: =IF($A37>C$33,SUMPRODUCT($B$17:$F$17/(1+$A37)^$B$14:$F$14)+$F$17*(1+C$33)/($A37-C$33)/(1+$A37)^$F$14,"n/a") -> -1002598 | D37: =IF($A37>D$33,SUMPRODUCT($B$17:$F$17/(1+$A37)^$B$14:$F$14)+$F$17*(1+D$33)/($A37-D$33)/(1+$A37)^$F$14,"n/a") -> -994949.04 | E37: =IF($A37>E$33,SUMPRODUCT($B$17:$F$17/(1+$A37)^$B$14:$F$14)+$F$17*(1+E$33)/($A37-E$33)/(1+$A37)^$F$14,"n/a") -> -986886.59 | F37: =IF($A37>F$33,SUMPRODUCT($B$17:$F$17/(1+$A37)^$B$14:$F$14)+$F$17*(1+F$33)/($A37-F$33)/(1+$A37)^$F$14,"n/a") -> -978376.23
A38: =$B$6+(2)*$B$10 -> 0.22 | B38: =IF($A38>B$33,SUMPRODUCT($B$17:$F$17/(1+$A38)^$B$14:$F$14)+$F$17*(1+B$33)/($A38-B$33)/(1+$A38)^$F$14,"n/a") -> -1024469.6 | C38: =IF($A38>C$33,SUMPRODUCT($B$17:$F$17/(1+$A38)^$B$14:$F$14)+$F$17*(1+C$33)/($A38-C$33)/(1+$A38)^$F$14,"n/a") -> -1018099.8 | D38: =IF($A38>D$33,SUMPRODUCT($B$17:$F$17/(1+$A38)^$B$14:$F$14)+$F$17*(1+D$33)/($A38-D$33)/(1+$A38)^$F$14,"n/a") -> -1011411.6 | E38: =IF($A38>E$33,SUMPRODUCT($B$17:$F$17/(1+$A38)^$B$14:$F$14)+$F$17*(1+E$33)/($A38-E$33)/(1+$A38)^$F$14,"n/a") -> -1004380.4 | F38: =IF($A38>F$33,SUMPRODUCT($B$17:$F$17/(1+$A38)^$B$14:$F$14)+$F$17*(1+F$33)/($A38-F$33)/(1+$A38)^$F$14,"n/a") -> -996979.14
A40: Free cash flow = operating cash flow + interest × (1 − tax rate) − capital spending. Cells marked n/a: WACC not above growth.

Sheet Sources & Uses
A1: Sources and uses of funds | E1: =HYPERLINK("#'Cover'!A1","◂ Contents") -> ◂ Contents
A2: Live for the selected scenario. Where the money comes from and where it goes in the period set below.
A3: Scenario shown | B3: =CHOOSE(Dashboard!$B$4,"Low","Base","High") -> Base
A5: Funding structure ($'000) — raised at the start of the plan
B6: Amount | C6: Share
A7: Equity | B7: =Inputs!$E$34 -> 760000 | C7: =IF($B$9=0,0,B7/$B$9) -> 0.3877551
A8: Debt (loan) | B8: =Inputs!$E$35 -> 1200000 | C8: =IF($B$9=0,0,B8/$B$9) -> 0.6122449
A9: Total funding | B9: =B7+B8 -> 1960000 | C9: =IF(B9=0,0,1) -> 1
A10: Gearing (debt ÷ equity) | B10: =IF(B7<=0,IF(B8>0,"n/a",0),B8/B7) -> 1.5789474 | D10: n/a: debt without positive equity
A11: Funding required by the plan (Break-even sheet) | B11: ='Break-even'!B12 -> 1913997
A12: Funding surplus / (shortfall) | B12: ='Break-even'!B17 -> 46003.017
A14: ="Sources and uses of cash in the first "&$B$16&IF($B$16=1," month"," months")&" ($'000)" -> Sources and uses of cash in the first 12 months ($'000)
A15: Period covered (months from the start) | B15: 12 | D15: 1 to 60 (capped)
A16: Months used | B16: =MIN(60,MAX(1,ROUND(B15,0))) -> 12
A17: Sources | B17: Amount | C17: Share
A18: Equity raised | B18: =SUMPRODUCT(--(Monthly!$C$4:$BJ$4<=$B$16),Monthly!$C$67:$BJ$67) -> 760000 | C18: =IF($B$21=0,0,B18/$B$21) -> 0.37835992
A19: Loan drawdowns | B19: =SUMPRODUCT(--(Monthly!$C$4:$BJ$4<=$B$16),Monthly!$C$50:$BJ$50) -> 1200000 | C19: =IF($B$21=0,0,B19/$B$21) -> 0.5974104
A20: Cash generated by operations | B20: =MAX(0,SUMPRODUCT(--(Monthly!$C$4:$BJ$4<=$B$16),Monthly!$C$65:$BJ$65)) -> 48669.41 | C20: =IF($B$21=0,0,B20/$B$21) -> 0.024229677
A21: Total sources | B21: =SUM(B18:B20) -> 2008669.4 | C21: =IF(B21=0,0,1) -> 1
A23: Uses | B23: Amount | C23: Share
A24: Cash used by operations | B24: =MAX(0,-SUMPRODUCT(--(Monthly!$C$4:$BJ$4<=$B$16),Monthly!$C$65:$BJ$65)) -> 0 | C24: =IF($B$28=0,0,B24/$B$28) -> 0
A25: Capital spending | B25: =-SUMPRODUCT(--(Monthly!$C$4:$BJ$4<=$B$16),Monthly!$C$66:$BJ$66) -> 1909000 | C25: =IF($B$28=0,0,B25/$B$28) -> 0.95038038
A26: Loan repayments | B26: =-SUMPRODUCT(--(Monthly!$C$4:$BJ$4<=$B$16),Monthly!$C$52:$BJ$52) -> 13412.706 | C26: =IF($B$28=0,0,B26/$B$28) -> 0.0066774082
A27: Cash at the end of the period | B27: =INDEX(Monthly!$C$71:$BJ$71,$B$16) -> 86256.705 | C27: =IF($B$28=0,0,B27/$B$28) -> 0.04294221
A28: Total uses | B28: =SUM(B24:B27) -> 2008669.4 | C28: =IF(B28=0,0,1) -> 1
A29: Sources − uses (must be 0; opening cash is 0) | B29: =B21-B28 -> 0

Sheet KPIs
A1: KPIs & ratios | I1: =HYPERLINK("#'Cover'!A1","◂ Contents") -> ◂ Contents
A2: Rental property financial model (early) — industry metrics and financial ratios for the active scenario
A4: Financial ratios
B5: 1 | C5: 2 | D5: 3 | E5: 4 | F5: 5 | G5: Target
A6: Revenue growth | B6: =IF(N('P&L'!A5)<=0,"n/a",'P&L'!B5/'P&L'!A5-1) -> n/a | C6: =IF(N('P&L'!B5)<=0,"n/a",'P&L'!C5/'P&L'!B5-1) -> 0.03 | D6: =IF(N('P&L'!C5)<=0,"n/a",'P&L'!D5/'P&L'!C5-1) -> 0.03 | E6: =IF(N('P&L'!D5)<=0,"n/a",'P&L'!E5/'P&L'!D5-1) -> 0.03 | F6: =IF(N('P&L'!E5)<=0,"n/a",'P&L'!F5/'P&L'!E5-1) -> 0.03
A7: Gross margin | B7: =IF('P&L'!B5<=0,"n/a",'P&L'!B7/'P&L'!B5) -> 0.88594966 | C7: =IF('P&L'!C5<=0,"n/a",'P&L'!C7/'P&L'!C5) -> 0.88594966 | D7: =IF('P&L'!D5<=0,"n/a",'P&L'!D7/'P&L'!D5) -> 0.88594966 | E7: =IF('P&L'!E5<=0,"n/a",'P&L'!E7/'P&L'!E5) -> 0.88594966 | F7: =IF('P&L'!F5<=0,"n/a",'P&L'!F7/'P&L'!F5) -> 0.88594966
A8: EBITDA margin | B8: =IF('P&L'!B5<=0,"n/a",'P&L'!B14/'P&L'!B5) -> 0.63737605 | C8: =IF('P&L'!C5<=0,"n/a",'P&L'!C14/'P&L'!C5) -> 0.63737605 | D8: =IF('P&L'!D5<=0,"n/a",'P&L'!D14/'P&L'!D5) -> 0.63737605 | E8: =IF('P&L'!E5<=0,"n/a",'P&L'!E14/'P&L'!E5) -> 0.63737605 | F8: =IF('P&L'!F5<=0,"n/a",'P&L'!F14/'P&L'!F5) -> 0.63737605
A9: Net margin | B9: =IF('P&L'!B5<=0,"n/a",'P&L'!B21/'P&L'!B5) -> -0.04681249 | C9: =IF('P&L'!C5<=0,"n/a",'P&L'!C21/'P&L'!C5) -> -0.023100223 | D9: =IF('P&L'!D5<=0,"n/a",'P&L'!D21/'P&L'!D5) -> 8.0584628e-05 | E9: =IF('P&L'!E5<=0,"n/a",'P&L'!E21/'P&L'!E5) -> 0.022751125 | F9: =IF('P&L'!F5<=0,"n/a",'P&L'!F21/'P&L'!F5) -> 0.044015669
A10: Payroll, % of revenue | B10: =IF('P&L'!B5<=0,"n/a",-SUMIF(Headcount!$C$5:$BJ$5,B$5,Headcount!$C$7:$BJ$7)/'P&L'!B5) -> 0 | C10: =IF('P&L'!C5<=0,"n/a",-SUMIF(Headcount!$C$5:$BJ$5,C$5,Headcount!$C$7:$BJ$7)/'P&L'!C5) -> 0 | D10: =IF('P&L'!D5<=0,"n/a",-SUMIF(Headcount!$C$5:$BJ$5,D$5,Headcount!$C$7:$BJ$7)/'P&L'!D5) -> 0 | E10: =IF('P&L'!E5<=0,"n/a",-SUMIF(Headcount!$C$5:$BJ$5,E$5,Headcount!$C$7:$BJ$7)/'P&L'!E5) -> 0 | F10: =IF('P&L'!F5<=0,"n/a",-SUMIF(Headcount!$C$5:$BJ$5,F$5,Headcount!$C$7:$BJ$7)/'P&L'!F5) -> 0
A11: Operating expenses, % of revenue | B11: =IF('P&L'!B5<=0,"n/a",-'P&L'!B13/'P&L'!B5) -> 0.24857361 | C11: =IF('P&L'!C5<=0,"n/a",-'P&L'!C13/'P&L'!C5) -> 0.24857361 | D11: =IF('P&L'!D5<=0,"n/a",-'P&L'!D13/'P&L'!D5) -> 0.24857361 | E11: =IF('P&L'!E5<=0,"n/a",-'P&L'!E13/'P&L'!E5) -> 0.24857361 | F11: =IF('P&L'!F5<=0,"n/a",-'P&L'!F13/'P&L'!F5) -> 0.24857361
A12: Current ratio (current assets ÷ current liabilities) | B12: =IF(('Balance Sheet'!B12-'Balance Sheet'!B11)<=0,"n/a",('Balance Sheet'!B5+'Balance Sheet'!B6+'Balance Sheet'!B7)/('Balance Sheet'!B12-'Balance Sheet'!B11)) -> 92.30252 | C12: =IF(('Balance Sheet'!C12-'Balance Sheet'!C11)<=0,"n/a",('Balance Sheet'!C5+'Balance Sheet'!C6+'Balance Sheet'!C7)/('Balance Sheet'!C12-'Balance Sheet'!C11)) -> 125.4626 | D12: =IF(('Balance Sheet'!D12-'Balance Sheet'!D11)<=0,"n/a",('Balance Sheet'!D5+'Balance Sheet'!D6+'Balance Sheet'!D7)/('Balance Sheet'!D12-'Balance Sheet'!D11)) -> 160.41104 | E12: =IF(('Balance Sheet'!E12-'Balance Sheet'!E11)<=0,"n/a",('Balance Sheet'!E5+'Balance Sheet'!E6+'Balance Sheet'!E7)/('Balance Sheet'!E12-'Balance Sheet'!E11)) -> 197.01554 | F12: =IF(('Balance Sheet'!F12-'Balance Sheet'!F11)<=0,"n/a",('Balance Sheet'!F5+'Balance Sheet'!F6+'Balance Sheet'!F7)/('Balance Sheet'!F12-'Balance Sheet'!F11)) -> 234.95711
A13: Debt ÷ equity (loan ÷ total equity) | B13: =IF('Balance Sheet'!B15<=0,"n/a",'Balance Sheet'!B11/'Balance Sheet'!B15) -> 1.5804425 | C13: =IF('Balance Sheet'!C15<=0,"n/a",'Balance Sheet'!C11/'Balance Sheet'!C15) -> 1.571173 | D13: =IF('Balance Sheet'!D15<=0,"n/a",'Balance Sheet'!D11/'Balance Sheet'!D15) -> 1.5506728 | E13: =IF('Balance Sheet'!E15<=0,"n/a",'Balance Sheet'!E11/'Balance Sheet'!E15) -> 1.5188853 | F13: =IF('Balance Sheet'!F15<=0,"n/a",'Balance Sheet'!F11/'Balance Sheet'!F15) -> 1.4765854
A14: Return on assets (net income ÷ year-end assets) | B14: =IF('Balance Sheet'!B9<=0,"n/a",'P&L'!B21/'Balance Sheet'!B9) -> -0.0047493162 | C14: =IF('Balance Sheet'!C9<=0,"n/a",'P&L'!C21/'Balance Sheet'!C9) -> -0.0024377671 | D14: =IF('Balance Sheet'!D9<=0,"n/a",'P&L'!D21/'Balance Sheet'!D9) -> 8.8292516e-06 | E14: =IF('Balance Sheet'!E9<=0,"n/a",'P&L'!E21/'Balance Sheet'!E9) -> 0.0025829359 | F14: =IF('Balance Sheet'!F9<=0,"n/a",'P&L'!F21/'Balance Sheet'!F9) -> 0.0051677919
A15: Return on equity (net income ÷ year-end equity) | B15: =IF('Balance Sheet'!B15<=0,"n/a",'P&L'!B21/'Balance Sheet'!B15) -> -0.012261249 | C15: =IF('Balance Sheet'!C15<=0,"n/a",'P&L'!C21/'Balance Sheet'!C15) -> -0.0062710656 | D15: =IF('Balance Sheet'!D15<=0,"n/a",'P&L'!D21/'Balance Sheet'!D15) -> 2.2532264e-05 | E15: =IF('Balance Sheet'!E15<=0,"n/a",'P&L'!E21/'Balance Sheet'!E15) -> 0.0065096312 | F15: =IF('Balance Sheet'!F15<=0,"n/a",'P&L'!F21/'Balance Sheet'!F15) -> 0.012805623
A17: DuPont analysis — return on equity = net margin × asset turnover × equity multiplier
B18: 1 | C18: 2 | D18: 3 | E18: 4 | F18: 5
A19: Net margin | B19: =IF('P&L'!B5<=0,"n/a",'P&L'!B21/'P&L'!B5) -> -0.04681249 | C19: =IF('P&L'!C5<=0,"n/a",'P&L'!C21/'P&L'!C5) -> -0.023100223 | D19: =IF('P&L'!D5<=0,"n/a",'P&L'!D21/'P&L'!D5) -> 8.0584628e-05 | E19: =IF('P&L'!E5<=0,"n/a",'P&L'!E21/'P&L'!E5) -> 0.022751125 | F19: =IF('P&L'!F5<=0,"n/a",'P&L'!F21/'P&L'!F5) -> 0.044015669
