Workbook

Sheet Cover
B2: Retail / e-commerce financial model (growing)
B3: 5-year financial model · monthly detail · Low / Base / High scenarios · US dollars · Full plan
B5: Purpose | D5: Revenue and profit plan
B6: Active scenario | D6: =Dashboard!C4&" (change it on the Dashboard, cell B4)" -> Base (change it on the Dashboard, cell B4)
B7: Model checks | D7: =Checks!B25 -> PASS
B8: Prepared | D8: 22 October 2026
B10: Contents
C11: PRESENTATION
B12: 1 | C12: =HYPERLINK("#Dashboard!A1","Dashboard") -> Dashboard | D12: Scenario switch, key numbers, core financials
B13: 2 | C13: =HYPERLINK("#Summary!A1","Summary") -> Summary | D13: Income statement, cash flow and balance sheet — every year and any year by month
B14: 3 | C14: =HYPERLINK("#Scenarios!A1","Scenarios") -> Scenarios | D14: Low / Base / High side by side: drivers, outputs, charts
B15: 4 | C15: =HYPERLINK("#'Break-even'!A1","Break-even") -> Break-even | D15: Startup costs, funding need, break-even timing and revenue
B16: 5 | C16: =HYPERLINK("#Valuation!A1","Valuation") -> Valuation | D16: Free cash flow, DCF (perpetual growth and exit multiple), WACC × growth sensitivity
B17: 6 | C17: =HYPERLINK("#'Sources & Uses'!A1","Sources & Uses") -> Sources & Uses | D17: Funding structure, sources and uses of cash for the first months
B18: 7 | C18: =HYPERLINK("#KPIs!A1","KPIs") -> KPIs | D18: Financial ratios, DuPont analysis, industry metrics
C19: INPUTS
B20: 8 | C20: =HYPERLINK("#Inputs!A1","Inputs") -> Inputs | D20: Every assumption, Low / Base / High, with units and comments
C21: STATEMENTS
B22: 9 | C22: =HYPERLINK("#'P&L'!A1","P&L") -> P&L | D22: Annual profit & loss
B23: 10 | C23: =HYPERLINK("#'Cash Flow'!A1","Cash Flow") -> Cash Flow | D23: Annual cash flow statement
B24: 11 | C24: =HYPERLINK("#'Balance Sheet'!A1","Balance Sheet") -> Balance Sheet | D24: Balance sheet at year end
C25: CALCULATIONS
B26: 12 | C26: =HYPERLINK("#Monthly!A1","Monthly") -> Monthly | D26: Month-by-month engine of the model
B27: 13 | C27: =HYPERLINK("#Headcount!A1","Headcount") -> Headcount | D27: Team and payroll
B28: 14 | C28: =HYPERLINK("#'Scenario calc'!A1","Scenario calc") -> Scenario calc | D28: Low, Base and High calculated side by side for the Scenarios sheet
C29: CONTROL
B30: 15 | C30: =HYPERLINK("#Checks!A1","Checks") -> Checks | D30: Live integrity checks and the overall verdict
B32: How to read this file
C33: 1000 | D33: Input you can change — yellow cell with a blue figure (Inputs sheet and the view switches)
C34: 1000 | D34: Formula — calculated, do not overwrite
C35: 1000 | D35: Link to another sheet
C36: 1000 | D36: Active value the model uses (follows the scenario)

Sheet Dashboard
A1: Dashboard | W1: =HYPERLINK("#'Cover'!A1","◂ Contents") -> ◂ Contents
A2: Retail / e-commerce financial model (growing)
A4: Active scenario | B4: 2 | C4: =CHOOSE(B4,"Low","Base","High") -> Base | D4: 1 = Low · 2 = Base · 3 = High — every sheet follows this cell | S4: Model checks | T4: =Checks!B25 -> PASS
A6: REVENUE · YEAR 5 | C6: EBITDA MARGIN · YEAR 5 | H6: NET INCOME · YEAR 5 | L6: LOWEST CASH BALANCE | P6: FUNDING REQUIRED | T6: ENTERPRISE VALUE (DCF)
A7: =F12 -> 14322508 | C7: =F17 -> 0.11067312 | H7: =F18 -> 1141341.2 | L7: =F39 -> 1260305.1 | P7: =F37 -> 1459694.9 | T7: =F44 -> 4528906.2
A8: =IF(AND(B12>0,F12>=0),(F12/B12)^(1/4)-1,"CAGR n/a") -> 0.26946145 | C8: =F16 -> 1585116.7 | H8: =F19 -> 0.07968864 | L8: ='Break-even'!B6 -> 13 | P8: =IF(F38>=0,"Covered by funding raised",-F38) -> Covered by funding raised | T8: Average of 2 methods
A10: Core financials ($'000) — active scenario
B11: 1 | C11: 2 | D11: 3 | E11: 4 | F11: 5
A12: Revenue | B12: =SUMIF(Monthly!$C$5:$BJ$5,B$11,Monthly!$C$25:$BJ$25) -> 5514942.9 | C12: =SUMIF(Monthly!$C$5:$BJ$5,C$11,Monthly!$C$25:$BJ$25) -> 7179087.9 | D12: =SUMIF(Monthly!$C$5:$BJ$5,D$11,Monthly!$C$25:$BJ$25) -> 9149574.9 | E12: =SUMIF(Monthly!$C$5:$BJ$5,E$11,Monthly!$C$25:$BJ$25) -> 11499932 | F12: =SUMIF(Monthly!$C$5:$BJ$5,F$11,Monthly!$C$25:$BJ$25) -> 14322508
A13: Gross profit | B13: =SUMIF(Monthly!$C$5:$BJ$5,B$11,Monthly!$C$27:$BJ$27) -> 3198666.9 | C13: =SUMIF(Monthly!$C$5:$BJ$5,C$11,Monthly!$C$27:$BJ$27) -> 4163871 | D13: =SUMIF(Monthly!$C$5:$BJ$5,D$11,Monthly!$C$27:$BJ$27) -> 5306753.4 | E13: =SUMIF(Monthly!$C$5:$BJ$5,E$11,Monthly!$C$27:$BJ$27) -> 6669960.6 | F13: =SUMIF(Monthly!$C$5:$BJ$5,F$11,Monthly!$C$27:$BJ$27) -> 8307054.9
A14: Gross margin | B14: =IF(B12=0,0,B13/B12) -> 0.58 | C14: =IF(C12=0,0,C13/C12) -> 0.58 | D14: =IF(D12=0,0,D13/D12) -> 0.58 | E14: =IF(E12=0,0,E13/E12) -> 0.58 | F14: =IF(F12=0,0,F13/F12) -> 0.58
A15: Operating expenses | B15: =SUMIF(Monthly!$C$5:$BJ$5,B$11,Monthly!$C$38:$BJ$38) -> -2881171.1 | C15: =SUMIF(Monthly!$C$5:$BJ$5,C$11,Monthly!$C$38:$BJ$38) -> -3582127.2 | D15: =SUMIF(Monthly!$C$5:$BJ$5,D$11,Monthly!$C$38:$BJ$38) -> -4429385.6 | E15: =SUMIF(Monthly!$C$5:$BJ$5,E$11,Monthly!$C$38:$BJ$38) -> -5460233 | F15: =SUMIF(Monthly!$C$5:$BJ$5,F$11,Monthly!$C$38:$BJ$38) -> -6721938.2
A16: EBITDA | B16: =SUMIF(Monthly!$C$5:$BJ$5,B$11,Monthly!$C$39:$BJ$39) -> 317495.71 | C16: =SUMIF(Monthly!$C$5:$BJ$5,C$11,Monthly!$C$39:$BJ$39) -> 581743.74 | D16: =SUMIF(Monthly!$C$5:$BJ$5,D$11,Monthly!$C$39:$BJ$39) -> 877367.82 | E16: =SUMIF(Monthly!$C$5:$BJ$5,E$11,Monthly!$C$39:$BJ$39) -> 1209727.6 | F16: =SUMIF(Monthly!$C$5:$BJ$5,F$11,Monthly!$C$39:$BJ$39) -> 1585116.7
A17: EBITDA margin | B17: =IF(B12=0,0,B16/B12) -> 0.057570082 | C17: =IF(C12=0,0,C16/C12) -> 0.0810331 | D17: =IF(D12=0,0,D16/D12) -> 0.095891649 | E17: =IF(E12=0,0,E16/E12) -> 0.10519433 | F17: =IF(F12=0,0,F16/F12) -> 0.11067312
A18: Net income | B18: =SUMIF(Monthly!$C$5:$BJ$5,B$11,Monthly!$C$48:$BJ$48) -> 182376.89 | C18: =SUMIF(Monthly!$C$5:$BJ$5,C$11,Monthly!$C$48:$BJ$48) -> 380502.32 | D18: =SUMIF(Monthly!$C$5:$BJ$5,D$11,Monthly!$C$48:$BJ$48) -> 603436.77 | E18: =SUMIF(Monthly!$C$5:$BJ$5,E$11,Monthly!$C$48:$BJ$48) -> 855392.43 | F18: =SUMIF(Monthly!$C$5:$BJ$5,F$11,Monthly!$C$48:$BJ$48) -> 1141341.2
A19: Net margin | B19: =IF(B12=0,0,B18/B12) -> 0.033069589 | C19: =IF(C12=0,0,C18/C12) -> 0.053001485 | D19: =IF(D12=0,0,D18/D12) -> 0.065952438 | E19: =IF(E12=0,0,E18/E12) -> 0.07438239 | F19: =IF(F12=0,0,F18/F12) -> 0.07968864
A20: Operating cash flow | B20: =SUMIF(Monthly!$C$5:$BJ$5,B$11,Monthly!$C$72:$BJ$72) -> -146060.15 | C20: =SUMIF(Monthly!$C$5:$BJ$5,C$11,Monthly!$C$72:$BJ$72) -> 334798.67 | D20: =SUMIF(Monthly!$C$5:$BJ$5,D$11,Monthly!$C$72:$BJ$72) -> 557937.43 | E20: =SUMIF(Monthly!$C$5:$BJ$5,E$11,Monthly!$C$72:$BJ$72) -> 804972.77 | F20: =SUMIF(Monthly!$C$5:$BJ$5,F$11,Monthly!$C$72:$BJ$72) -> 1079551.3
A21: Investing cash flow | B21: =SUMIF(Monthly!$C$5:$BJ$5,B$11,Monthly!$C$73:$BJ$73) -> -350000 | C21: =SUMIF(Monthly!$C$5:$BJ$5,C$11,Monthly!$C$73:$BJ$73) -> -150000 | D21: =SUMIF(Monthly!$C$5:$BJ$5,D$11,Monthly!$C$73:$BJ$73) -> -150000 | E21: =SUMIF(Monthly!$C$5:$BJ$5,E$11,Monthly!$C$73:$BJ$73) -> -150000 | F21: =SUMIF(Monthly!$C$5:$BJ$5,F$11,Monthly!$C$73:$BJ$73) -> -150000
A22: Financing cash flow | B22: =SUMIF(Monthly!$C$5:$BJ$5,B$11,Monthly!$C$75:$BJ$75) -> 1908333.3 | C22: =SUMIF(Monthly!$C$5:$BJ$5,C$11,Monthly!$C$75:$BJ$75) -> -100000 | D22: =SUMIF(Monthly!$C$5:$BJ$5,D$11,Monthly!$C$75:$BJ$75) -> -100000 | E22: =SUMIF(Monthly!$C$5:$BJ$5,E$11,Monthly!$C$75:$BJ$75) -> -100000 | F22: =SUMIF(Monthly!$C$5:$BJ$5,F$11,Monthly!$C$75:$BJ$75) -> -100000
A23: Net change in cash | B23: =SUMIF(Monthly!$C$5:$BJ$5,B$11,Monthly!$C$76:$BJ$76) -> 1412273.2 | C23: =SUMIF(Monthly!$C$5:$BJ$5,C$11,Monthly!$C$76:$BJ$76) -> 84798.669 | D23: =SUMIF(Monthly!$C$5:$BJ$5,D$11,Monthly!$C$76:$BJ$76) -> 307937.43 | E23: =SUMIF(Monthly!$C$5:$BJ$5,E$11,Monthly!$C$76:$BJ$76) -> 554972.77 | F23: =SUMIF(Monthly!$C$5:$BJ$5,F$11,Monthly!$C$76:$BJ$76) -> 829551.32
A24: Year-end cash | B24: =INDEX(Monthly!$C$78:$BJ$78,B$11*12) -> 1412273.2 | C24: =INDEX(Monthly!$C$78:$BJ$78,C$11*12) -> 1497071.8 | D24: =INDEX(Monthly!$C$78:$BJ$78,D$11*12) -> 1805009.3 | E24: =INDEX(Monthly!$C$78:$BJ$78,E$11*12) -> 2359982 | F24: =INDEX(Monthly!$C$78:$BJ$78,F$11*12) -> 3189533.4
A26: Retail metrics
B27: 1 | C27: 2 | D27: 3 | E27: 4 | F27: 5
A28: Online gross sales | B28: =KPIs!B33 -> 5002714.3 | C28: =KPIs!C33 -> 6255514.3 | D28: =KPIs!D33 -> 7825294.3 | E28: =KPIs!E33 -> 9793054.8 | F28: =KPIs!F33 -> 12260690
A29: Store gross sales | B29: =KPIs!B38 -> 1125000 | C29: =KPIs!C38 -> 1721250 | D29: =KPIs!D38 -> 2340900 | E29: =KPIs!E38 -> 2984647.5 | F29: =KPIs!F38 -> 3653208.5
A30: Online orders | B30: =KPIs!B30 -> 66702.857 | C30: =KPIs!C30 -> 81771.429 | D30: =KPIs!D30 -> 100285.71 | E30: =KPIs!E30 -> 123042.86 | F30: =KPIs!F30 -> 151026.43
A31: Stores open (year end) | B31: =KPIs!B37 -> 2 | C31: =KPIs!C37 -> 3 | D31: =KPIs!D37 -> 4 | E31: =KPIs!E37 -> 5 | F31: =KPIs!F37 -> 6
A32: Team (FTE, year end) | B32: =INDEX(Headcount!$C$12:$BJ$12,B$27*12) -> 21 | C32: =INDEX(Headcount!$C$12:$BJ$12,C$27*12) -> 25.85 | D32: =INDEX(Headcount!$C$12:$BJ$12,D$27*12) -> 31.8875 | E32: =INDEX(Headcount!$C$12:$BJ$12,E$27*12) -> 39.418625 | F32: =INDEX(Headcount!$C$12:$BJ$12,F$27*12) -> 48.831819
A34: Funding & valuation ($'000) — active scenario
A35: Equity raised | F35: =Inputs!$E$58 -> 1500000
A36: Loan drawn | F36: =Inputs!$E$59 -> 500000
A37: Funding required (incl. cash buffer) | F37: ='Break-even'!B12 -> 1459694.9
A38: Funding surplus / (shortfall) | F38: ='Break-even'!B17 -> 540305.08
A39: ="Lowest cash balance (month "&'Break-even'!B6&")" -> Lowest cash balance (month 13) | F39: ='Break-even'!B18 -> 1260305.1
A40: First month with positive EBITDA | F40: ='Break-even'!B21 -> 1
A41: Cash invested paid back | F41: ='Break-even'!B23 -> 36
A42: Enterprise value — perpetual growth | F42: =Valuation!B27 -> 4072114.7
A43: Enterprise value — exit multiple | F43: =Valuation!C27 -> 4985697.7
A44: Enterprise value — average | F44: =Valuation!B30 -> 4528906.2

Sheet Summary
A1: Financial statements summary | U1: =HYPERLINK("#'Cover'!A1","◂ Contents") -> ◂ Contents
A2: Retail / e-commerce financial model (growing) | P2: Select detailed year: | R2: 1
A5: Income statement ($'000) — by year | H5: ="Income statement ($'000) — Year "&$R$2&", by month" -> Income statement ($'000) — Year 1, by month
B6: 1 | C6: 2 | D6: 3 | E6: 4 | F6: 5 | H6: =INDEX(Monthly!$C$4:$BJ$4,($R$2-1)*12+1) -> 1 | I6: =INDEX(Monthly!$C$4:$BJ$4,($R$2-1)*12+2) -> 2 | J6: =INDEX(Monthly!$C$4:$BJ$4,($R$2-1)*12+3) -> 3 | K6: =INDEX(Monthly!$C$4:$BJ$4,($R$2-1)*12+4) -> 4 | L6: =INDEX(Monthly!$C$4:$BJ$4,($R$2-1)*12+5) -> 5 | M6: =INDEX(Monthly!$C$4:$BJ$4,($R$2-1)*12+6) -> 6 | N6: =INDEX(Monthly!$C$4:$BJ$4,($R$2-1)*12+7) -> 7 | O6: =INDEX(Monthly!$C$4:$BJ$4,($R$2-1)*12+8) -> 8 | P6: =INDEX(Monthly!$C$4:$BJ$4,($R$2-1)*12+9) -> 9 | Q6: =INDEX(Monthly!$C$4:$BJ$4,($R$2-1)*12+10) -> 10 | R6: =INDEX(Monthly!$C$4:$BJ$4,($R$2-1)*12+11) -> 11 | S6: =INDEX(Monthly!$C$4:$BJ$4,($R$2-1)*12+12) -> 12
A7: Revenue | B7: ='P&L'!B5 -> 5514942.9 | C7: ='P&L'!C5 -> 7179087.9 | D7: ='P&L'!D5 -> 9149574.9 | E7: ='P&L'!E5 -> 11499932 | F7: ='P&L'!F5 -> 14322508 | H7: =INDEX(Monthly!$C$25:$BJ$25,($R$2-1)*12+1) -> 442852.07 | I7: =INDEX(Monthly!$C$25:$BJ$25,($R$2-1)*12+2) -> 442852.07 | J7: =INDEX(Monthly!$C$25:$BJ$25,($R$2-1)*12+3) -> 442852.07 | K7: =INDEX(Monthly!$C$25:$BJ$25,($R$2-1)*12+4) -> 442852.07 | L7: =INDEX(Monthly!$C$25:$BJ$25,($R$2-1)*12+5) -> 442852.07 | M7: =INDEX(Monthly!$C$25:$BJ$25,($R$2-1)*12+6) -> 442852.07 | N7: =INDEX(Monthly!$C$25:$BJ$25,($R$2-1)*12+7) -> 442852.07 | O7: =INDEX(Monthly!$C$25:$BJ$25,($R$2-1)*12+8) -> 442852.07 | P7: =INDEX(Monthly!$C$25:$BJ$25,($R$2-1)*12+9) -> 442852.07 | Q7: =INDEX(Monthly!$C$25:$BJ$25,($R$2-1)*12+10) -> 442852.07 | R7: =INDEX(Monthly!$C$25:$BJ$25,($R$2-1)*12+11) -> 543211.07 | S7: =INDEX(Monthly!$C$25:$BJ$25,($R$2-1)*12+12) -> 543211.07
A8: Product cost | B8: ='P&L'!B6 -> -2316276 | C8: ='P&L'!C6 -> -3015216.9 | D8: ='P&L'!D6 -> -3842821.4 | E8: ='P&L'!E6 -> -4829971.5 | F8: ='P&L'!F6 -> -6015453.6 | H8: =INDEX(Monthly!$C$26:$BJ$26,($R$2-1)*12+1) -> -185997.87 | I8: =INDEX(Monthly!$C$26:$BJ$26,($R$2-1)*12+2) -> -185997.87 | J8: =INDEX(Monthly!$C$26:$BJ$26,($R$2-1)*12+3) -> -185997.87 | K8: =INDEX(Monthly!$C$26:$BJ$26,($R$2-1)*12+4) -> -185997.87 | L8: =INDEX(Monthly!$C$26:$BJ$26,($R$2-1)*12+5) -> -185997.87 | M8: =INDEX(Monthly!$C$26:$BJ$26,($R$2-1)*12+6) -> -185997.87 | N8: =INDEX(Monthly!$C$26:$BJ$26,($R$2-1)*12+7) -> -185997.87 | O8: =INDEX(Monthly!$C$26:$BJ$26,($R$2-1)*12+8) -> -185997.87 | P8: =INDEX(Monthly!$C$26:$BJ$26,($R$2-1)*12+9) -> -185997.87 | Q8: =INDEX(Monthly!$C$26:$BJ$26,($R$2-1)*12+10) -> -185997.87 | R8: =INDEX(Monthly!$C$26:$BJ$26,($R$2-1)*12+11) -> -228148.65 | S8: =INDEX(Monthly!$C$26:$BJ$26,($R$2-1)*12+12) -> -228148.65
A9: Gross profit | B9: ='P&L'!B7 -> 3198666.9 | C9: ='P&L'!C7 -> 4163871 | D9: ='P&L'!D7 -> 5306753.4 | E9: ='P&L'!E7 -> 6669960.6 | F9: ='P&L'!F7 -> 8307054.9 | H9: =INDEX(Monthly!$C$27:$BJ$27,($R$2-1)*12+1) -> 256854.2 | I9: =INDEX(Monthly!$C$27:$BJ$27,($R$2-1)*12+2) -> 256854.2 | J9: =INDEX(Monthly!$C$27:$BJ$27,($R$2-1)*12+3) -> 256854.2 | K9: =INDEX(Monthly!$C$27:$BJ$27,($R$2-1)*12+4) -> 256854.2 | L9: =INDEX(Monthly!$C$27:$BJ$27,($R$2-1)*12+5) -> 256854.2 | M9: =INDEX(Monthly!$C$27:$BJ$27,($R$2-1)*12+6) -> 256854.2 | N9: =INDEX(Monthly!$C$27:$BJ$27,($R$2-1)*12+7) -> 256854.2 | O9: =INDEX(Monthly!$C$27:$BJ$27,($R$2-1)*12+8) -> 256854.2 | P9: =INDEX(Monthly!$C$27:$BJ$27,($R$2-1)*12+9) -> 256854.2 | Q9: =INDEX(Monthly!$C$27:$BJ$27,($R$2-1)*12+10) -> 256854.2 | R9: =INDEX(Monthly!$C$27:$BJ$27,($R$2-1)*12+11) -> 315062.42 | S9: =INDEX(Monthly!$C$27:$BJ$27,($R$2-1)*12+12) -> 315062.42
A10: Gross margin | B10: ='P&L'!B8 -> 0.58 | C10: ='P&L'!C8 -> 0.58 | D10: ='P&L'!D8 -> 0.58 | E10: ='P&L'!E8 -> 0.58 | F10: ='P&L'!F8 -> 0.58 | H10: =IF(H7=0,0,H9/H7) -> 0.58 | I10: =IF(I7=0,0,I9/I7) -> 0.58 | J10: =IF(J7=0,0,J9/J7) -> 0.58 | K10: =IF(K7=0,0,K9/K7) -> 0.58 | L10: =IF(L7=0,0,L9/L7) -> 0.58 | M10: =IF(M7=0,0,M9/M7) -> 0.58 | N10: =IF(N7=0,0,N9/N7) -> 0.58 | O10: =IF(O7=0,0,O9/O7) -> 0.58 | ... S10: =IF(S7=0,0,S9/S7) -> 0.58
A11: Total operating expenses | B11: ='P&L'!B17 -> -2881171.1 | C11: ='P&L'!C17 -> -3582127.2 | D11: ='P&L'!D17 -> -4429385.6 | E11: ='P&L'!E17 -> -5460233 | F11: ='P&L'!F17 -> -6721938.2 | H11: =INDEX(Monthly!$C$38:$BJ$38,($R$2-1)*12+1) -> -238213.4 | I11: =INDEX(Monthly!$C$38:$BJ$38,($R$2-1)*12+2) -> -238213.4 | J11: =INDEX(Monthly!$C$38:$BJ$38,($R$2-1)*12+3) -> -238213.4 | K11: =INDEX(Monthly!$C$38:$BJ$38,($R$2-1)*12+4) -> -238213.4 | L11: =INDEX(Monthly!$C$38:$BJ$38,($R$2-1)*12+5) -> -238213.4 | M11: =INDEX(Monthly!$C$38:$BJ$38,($R$2-1)*12+6) -> -238213.4 | N11: =INDEX(Monthly!$C$38:$BJ$38,($R$2-1)*12+7) -> -238213.4 | O11: =INDEX(Monthly!$C$38:$BJ$38,($R$2-1)*12+8) -> -238213.4 | P11: =INDEX(Monthly!$C$38:$BJ$38,($R$2-1)*12+9) -> -238213.4 | Q11: =INDEX(Monthly!$C$38:$BJ$38,($R$2-1)*12+10) -> -238213.4 | R11: =INDEX(Monthly!$C$38:$BJ$38,($R$2-1)*12+11) -> -249518.57 | S11: =INDEX(Monthly!$C$38:$BJ$38,($R$2-1)*12+12) -> -249518.57
A12: EBITDA | B12: ='P&L'!B18 -> 317495.71 | C12: ='P&L'!C18 -> 581743.74 | D12: ='P&L'!D18 -> 877367.82 | E12: ='P&L'!E18 -> 1209727.6 | F12: ='P&L'!F18 -> 1585116.7 | H12: =INDEX(Monthly!$C$39:$BJ$39,($R$2-1)*12+1) -> 18640.801 | I12: =INDEX(Monthly!$C$39:$BJ$39,($R$2-1)*12+2) -> 18640.801 | J12: =INDEX(Monthly!$C$39:$BJ$39,($R$2-1)*12+3) -> 18640.801 | K12: =INDEX(Monthly!$C$39:$BJ$39,($R$2-1)*12+4) -> 18640.801 | L12: =INDEX(Monthly!$C$39:$BJ$39,($R$2-1)*12+5) -> 18640.801 | M12: =INDEX(Monthly!$C$39:$BJ$39,($R$2-1)*12+6) -> 18640.801 | N12: =INDEX(Monthly!$C$39:$BJ$39,($R$2-1)*12+7) -> 18640.801 | O12: =INDEX(Monthly!$C$39:$BJ$39,($R$2-1)*12+8) -> 18640.801 | P12: =INDEX(Monthly!$C$39:$BJ$39,($R$2-1)*12+9) -> 18640.801 | Q12: =INDEX(Monthly!$C$39:$BJ$39,($R$2-1)*12+10) -> 18640.801 | R12: =INDEX(Monthly!$C$39:$BJ$39,($R$2-1)*12+11) -> 65543.851 | S12: =INDEX(Monthly!$C$39:$BJ$39,($R$2-1)*12+12) -> 65543.851
A13: EBITDA margin | B13: ='P&L'!B19 -> 0.057570082 | C13: ='P&L'!C19 -> 0.0810331 | D13: ='P&L'!D19 -> 0.095891649 | E13: ='P&L'!E19 -> 0.10519433 | F13: ='P&L'!F19 -> 0.11067312 | H13: =IF(H7=0,0,H12/H7) -> 0.042092614 | I13: =IF(I7=0,0,I12/I7) -> 0.042092614 | J13: =IF(J7=0,0,J12/J7) -> 0.042092614 | K13: =IF(K7=0,0,K12/K7) -> 0.042092614 | L13: =IF(L7=0,0,L12/L7) -> 0.042092614 | M13: =IF(M7=0,0,M12/M7) -> 0.042092614 | N13: =IF(N7=0,0,N12/N7) -> 0.042092614 | O13: =IF(O7=0,0,O12/O7) -> 0.042092614 | ... S13: =IF(S7=0,0,S12/S7) -> 0.12066001
A14: Depreciation | B14: ='P&L'!B20 -> -50000 | C14: ='P&L'!C20 -> -71428.571 | D14: ='P&L'!D20 -> -92857.143 | E14: ='P&L'!E20 -> -114285.71 | F14: ='P&L'!F20 -> -135714.29 | H14: =INDEX(Monthly!$C$53:$BJ$53,($R$2-1)*12+1) -> -4166.6667 | I14: =INDEX(Monthly!$C$53:$BJ$53,($R$2-1)*12+2) -> -4166.6667 | J14: =INDEX(Monthly!$C$53:$BJ$53,($R$2-1)*12+3) -> -4166.6667 | K14: =INDEX(Monthly!$C$53:$BJ$53,($R$2-1)*12+4) -> -4166.6667 | L14: =INDEX(Monthly!$C$53:$BJ$53,($R$2-1)*12+5) -> -4166.6667 | M14: =INDEX(Monthly!$C$53:$BJ$53,($R$2-1)*12+6) -> -4166.6667 | N14: =INDEX(Monthly!$C$53:$BJ$53,($R$2-1)*12+7) -> -4166.6667 | O14: =INDEX(Monthly!$C$53:$BJ$53,($R$2-1)*12+8) -> -4166.6667 | P14: =INDEX(Monthly!$C$53:$BJ$53,($R$2-1)*12+9) -> -4166.6667 | Q14: =INDEX(Monthly!$C$53:$BJ$53,($R$2-1)*12+10) -> -4166.6667 | R14: =INDEX(Monthly!$C$53:$BJ$53,($R$2-1)*12+11) -> -4166.6667 | S14: =INDEX(Monthly!$C$53:$BJ$53,($R$2-1)*12+12) -> -4166.6667
A15: EBIT | B15: ='P&L'!B21 -> 267495.71 | C15: ='P&L'!C21 -> 510315.17 | D15: ='P&L'!D21 -> 784510.68 | E15: ='P&L'!E21 -> 1095441.9 | F15: ='P&L'!F21 -> 1449402.4 | H15: =INDEX(Monthly!$C$42:$BJ$42,($R$2-1)*12+1) -> 14474.135 | I15: =INDEX(Monthly!$C$42:$BJ$42,($R$2-1)*12+2) -> 14474.135 | J15: =INDEX(Monthly!$C$42:$BJ$42,($R$2-1)*12+3) -> 14474.135 | K15: =INDEX(Monthly!$C$42:$BJ$42,($R$2-1)*12+4) -> 14474.135 | L15: =INDEX(Monthly!$C$42:$BJ$42,($R$2-1)*12+5) -> 14474.135 | M15: =INDEX(Monthly!$C$42:$BJ$42,($R$2-1)*12+6) -> 14474.135 | N15: =INDEX(Monthly!$C$42:$BJ$42,($R$2-1)*12+7) -> 14474.135 | O15: =INDEX(Monthly!$C$42:$BJ$42,($R$2-1)*12+8) -> 14474.135 | P15: =INDEX(Monthly!$C$42:$BJ$42,($R$2-1)*12+9) -> 14474.135 | Q15: =INDEX(Monthly!$C$42:$BJ$42,($R$2-1)*12+10) -> 14474.135 | R15: =INDEX(Monthly!$C$42:$BJ$42,($R$2-1)*12+11) -> 61377.185 | S15: =INDEX(Monthly!$C$42:$BJ$42,($R$2-1)*12+12) -> 61377.185
A16: Interest | B16: ='P&L'!B22 -> -36638.889 | C16: ='P&L'!C22 -> -28666.667 | D16: ='P&L'!D22 -> -20666.667 | E16: ='P&L'!E22 -> -12666.667 | F16: ='P&L'!F22 -> -4666.6667 | H16: =INDEX(Monthly!$C$43:$BJ$43,($R$2-1)*12+1) -> -3333.3333 | I16: =INDEX(Monthly!$C$43:$BJ$43,($R$2-1)*12+2) -> -3305.5556 | J16: =INDEX(Monthly!$C$43:$BJ$43,($R$2-1)*12+3) -> -3250 | K16: =INDEX(Monthly!$C$43:$BJ$43,($R$2-1)*12+4) -> -3194.4444 | L16: =INDEX(Monthly!$C$43:$BJ$43,($R$2-1)*12+5) -> -3138.8889 | M16: =INDEX(Monthly!$C$43:$BJ$43,($R$2-1)*12+6) -> -3083.3333 | N16: =INDEX(Monthly!$C$43:$BJ$43,($R$2-1)*12+7) -> -3027.7778 | O16: =INDEX(Monthly!$C$43:$BJ$43,($R$2-1)*12+8) -> -2972.2222 | P16: =INDEX(Monthly!$C$43:$BJ$43,($R$2-1)*12+9) -> -2916.6667 | Q16: =INDEX(Monthly!$C$43:$BJ$43,($R$2-1)*12+10) -> -2861.1111 | R16: =INDEX(Monthly!$C$43:$BJ$43,($R$2-1)*12+11) -> -2805.5556 | S16: =INDEX(Monthly!$C$43:$BJ$43,($R$2-1)*12+12) -> -2750
A17: Pre-tax income | B17: ='P&L'!B23 -> 230856.83 | C17: ='P&L'!C23 -> 481648.5 | D17: ='P&L'!D23 -> 763844.01 | E17: ='P&L'!E23 -> 1082775.2 | F17: ='P&L'!F23 -> 1444735.7 | H17: =INDEX(Monthly!$C$44:$BJ$44,($R$2-1)*12+1) -> 11140.801 | I17: =INDEX(Monthly!$C$44:$BJ$44,($R$2-1)*12+2) -> 11168.579 | J17: =INDEX(Monthly!$C$44:$BJ$44,($R$2-1)*12+3) -> 11224.135 | K17: =INDEX(Monthly!$C$44:$BJ$44,($R$2-1)*12+4) -> 11279.69 | L17: =INDEX(Monthly!$C$44:$BJ$44,($R$2-1)*12+5) -> 11335.246 | M17: =INDEX(Monthly!$C$44:$BJ$44,($R$2-1)*12+6) -> 11390.801 | N17: =INDEX(Monthly!$C$44:$BJ$44,($R$2-1)*12+7) -> 11446.357 | O17: =INDEX(Monthly!$C$44:$BJ$44,($R$2-1)*12+8) -> 11501.912 | P17: =INDEX(Monthly!$C$44:$BJ$44,($R$2-1)*12+9) -> 11557.468 | Q17: =INDEX(Monthly!$C$44:$BJ$44,($R$2-1)*12+10) -> 11613.023 | R17: =INDEX(Monthly!$C$44:$BJ$44,($R$2-1)*12+11) -> 58571.629 | S17: =INDEX(Monthly!$C$44:$BJ$44,($R$2-1)*12+12) -> 58627.185
A18: Income tax | B18: ='P&L'!B24 -> -48479.933 | C18: ='P&L'!C24 -> -101146.19 | D18: ='P&L'!D24 -> -160407.24 | E18: ='P&L'!E24 -> -227382.8 | F18: ='P&L'!F24 -> -303394.5 | H18: =INDEX(Monthly!$C$47:$BJ$47,($R$2-1)*12+1) -> -2339.5682 | I18: =INDEX(Monthly!$C$47:$BJ$47,($R$2-1)*12+2) -> -2345.4016 | J18: =INDEX(Monthly!$C$47:$BJ$47,($R$2-1)*12+3) -> -2357.0682 | K18: =INDEX(Monthly!$C$47:$BJ$47,($R$2-1)*12+4) -> -2368.7349 | L18: =INDEX(Monthly!$C$47:$BJ$47,($R$2-1)*12+5) -> -2380.4016 | M18: =INDEX(Monthly!$C$47:$BJ$47,($R$2-1)*12+6) -> -2392.0682 | N18: =INDEX(Monthly!$C$47:$BJ$47,($R$2-1)*12+7) -> -2403.7349 | O18: =INDEX(Monthly!$C$47:$BJ$47,($R$2-1)*12+8) -> -2415.4016 | P18: =INDEX(Monthly!$C$47:$BJ$47,($R$2-1)*12+9) -> -2427.0682 | Q18: =INDEX(Monthly!$C$47:$BJ$47,($R$2-1)*12+10) -> -2438.7349 | R18: =INDEX(Monthly!$C$47:$BJ$47,($R$2-1)*12+11) -> -12300.042 | S18: =INDEX(Monthly!$C$47:$BJ$47,($R$2-1)*12+12) -> -12311.709
A19: Net income | B19: ='P&L'!B25 -> 182376.89 | C19: ='P&L'!C25 -> 380502.32 | D19: ='P&L'!D25 -> 603436.77 | E19: ='P&L'!E25 -> 855392.43 | F19: ='P&L'!F25 -> 1141341.2 | H19: =INDEX(Monthly!$C$48:$BJ$48,($R$2-1)*12+1) -> 8801.2329 | I19: =INDEX(Monthly!$C$48:$BJ$48,($R$2-1)*12+2) -> 8823.1774 | J19: =INDEX(Monthly!$C$48:$BJ$48,($R$2-1)*12+3) -> 8867.0663 | K19: =INDEX(Monthly!$C$48:$BJ$48,($R$2-1)*12+4) -> 8910.9552 | L19: =INDEX(Monthly!$C$48:$BJ$48,($R$2-1)*12+5) -> 8954.8441 | M19: =INDEX(Monthly!$C$48:$BJ$48,($R$2-1)*12+6) -> 8998.7329 | N19: =INDEX(Monthly!$C$48:$BJ$48,($R$2-1)*12+7) -> 9042.6218 | O19: =INDEX(Monthly!$C$48:$BJ$48,($R$2-1)*12+8) -> 9086.5107 | P19: =INDEX(Monthly!$C$48:$BJ$48,($R$2-1)*12+9) -> 9130.3996 | Q19: =INDEX(Monthly!$C$48:$BJ$48,($R$2-1)*12+10) -> 9174.2885 | R19: =INDEX(Monthly!$C$48:$BJ$48,($R$2-1)*12+11) -> 46271.587 | S19: =INDEX(Monthly!$C$48:$BJ$48,($R$2-1)*12+12) -> 46315.476
A20: Net margin | B20: ='P&L'!B26 -> 0.033069589 | C20: ='P&L'!C26 -> 0.053001485 | D20: ='P&L'!D26 -> 0.065952438 | E20: ='P&L'!E26 -> 0.07438239 | F20: ='P&L'!F26 -> 0.07968864 | H20: =IF(H7=0,0,H19/H7) -> 0.019873979 | I20: =IF(I7=0,0,I19/I7) -> 0.019923532 | J20: =IF(J7=0,0,J19/J7) -> 0.020022637 | K20: =IF(K7=0,0,K19/K7) -> 0.020121742 | L20: =IF(L7=0,0,L19/L7) -> 0.020220847 | M20: =IF(M7=0,0,M19/M7) -> 0.020319952 | N20: =IF(N7=0,0,N19/N7) -> 0.020419057 | O20: =IF(O7=0,0,O19/O7) -> 0.020518162 | ... S20: =IF(S7=0,0,S19/S7) -> 0.085262393
A22: Cash flow ($'000) — by year | H22: ="Cash flow ($'000) — Year "&$R$2&", by month" -> Cash flow ($'000) — Year 1, by month
B23: 1 | C23: 2 | D23: 3 | E23: 4 | F23: 5 | H23: =INDEX(Monthly!$C$4:$BJ$4,($R$2-1)*12+1) -> 1 | I23: =INDEX(Monthly!$C$4:$BJ$4,($R$2-1)*12+2) -> 2 | J23: =INDEX(Monthly!$C$4:$BJ$4,($R$2-1)*12+3) -> 3 | K23: =INDEX(Monthly!$C$4:$BJ$4,($R$2-1)*12+4) -> 4 | L23: =INDEX(Monthly!$C$4:$BJ$4,($R$2-1)*12+5) -> 5 | M23: =INDEX(Monthly!$C$4:$BJ$4,($R$2-1)*12+6) -> 6 | N23: =INDEX(Monthly!$C$4:$BJ$4,($R$2-1)*12+7) -> 7 | O23: =INDEX(Monthly!$C$4:$BJ$4,($R$2-1)*12+8) -> 8 | P23: =INDEX(Monthly!$C$4:$BJ$4,($R$2-1)*12+9) -> 9 | Q23: =INDEX(Monthly!$C$4:$BJ$4,($R$2-1)*12+10) -> 10 | R23: =INDEX(Monthly!$C$4:$BJ$4,($R$2-1)*12+11) -> 11 | S23: =INDEX(Monthly!$C$4:$BJ$4,($R$2-1)*12+12) -> 12
A24: Operating cash flow | B24: ='Cash Flow'!B10 -> -146060.15 | C24: ='Cash Flow'!C10 -> 334798.67 | D24: ='Cash Flow'!D10 -> 557937.43 | E24: ='Cash Flow'!E10 -> 804972.77 | F24: ='Cash Flow'!F10 -> 1079551.3 | H24: =INDEX(Monthly!$C$72:$BJ$72,($R$2-1)*12+1) -> -295552.38 | I24: =INDEX(Monthly!$C$72:$BJ$72,($R$2-1)*12+2) -> 12989.844 | J24: =INDEX(Monthly!$C$72:$BJ$72,($R$2-1)*12+3) -> 13033.733 | K24: =INDEX(Monthly!$C$72:$BJ$72,($R$2-1)*12+4) -> 13077.622 | L24: =INDEX(Monthly!$C$72:$BJ$72,($R$2-1)*12+5) -> 13121.511 | M24: =INDEX(Monthly!$C$72:$BJ$72,($R$2-1)*12+6) -> 13165.4 | N24: =INDEX(Monthly!$C$72:$BJ$72,($R$2-1)*12+7) -> 13209.288 | O24: =INDEX(Monthly!$C$72:$BJ$72,($R$2-1)*12+8) -> 13253.177 | P24: =INDEX(Monthly!$C$72:$BJ$72,($R$2-1)*12+9) -> 13297.066 | Q24: =INDEX(Monthly!$C$72:$BJ$72,($R$2-1)*12+10) -> 13340.955 | R24: =INDEX(Monthly!$C$72:$BJ$72,($R$2-1)*12+11) -> -19478.516 | S24: =INDEX(Monthly!$C$72:$BJ$72,($R$2-1)*12+12) -> 50482.142
A25: Capital spending | B25: ='Cash Flow'!B11 -> -350000 | C25: ='Cash Flow'!C11 -> -150000 | D25: ='Cash Flow'!D11 -> -150000 | E25: ='Cash Flow'!E11 -> -150000 | F25: ='Cash Flow'!F11 -> -150000 | H25: =INDEX(Monthly!$C$73:$BJ$73,($R$2-1)*12+1) -> -350000 | I25: =INDEX(Monthly!$C$73:$BJ$73,($R$2-1)*12+2) -> 0 | J25: =INDEX(Monthly!$C$73:$BJ$73,($R$2-1)*12+3) -> 0 | K25: =INDEX(Monthly!$C$73:$BJ$73,($R$2-1)*12+4) -> 0 | L25: =INDEX(Monthly!$C$73:$BJ$73,($R$2-1)*12+5) -> 0 | M25: =INDEX(Monthly!$C$73:$BJ$73,($R$2-1)*12+6) -> 0 | N25: =INDEX(Monthly!$C$73:$BJ$73,($R$2-1)*12+7) -> 0 | O25: =INDEX(Monthly!$C$73:$BJ$73,($R$2-1)*12+8) -> 0 | P25: =INDEX(Monthly!$C$73:$BJ$73,($R$2-1)*12+9) -> 0 | Q25: =INDEX(Monthly!$C$73:$BJ$73,($R$2-1)*12+10) -> 0 | R25: =INDEX(Monthly!$C$73:$BJ$73,($R$2-1)*12+11) -> 0 | S25: =INDEX(Monthly!$C$73:$BJ$73,($R$2-1)*12+12) -> 0
A26: Equity raised | B26: ='Cash Flow'!B12 -> 1500000 | C26: ='Cash Flow'!C12 -> 0 | D26: ='Cash Flow'!D12 -> 0 | E26: ='Cash Flow'!E12 -> 0 | F26: ='Cash Flow'!F12 -> 0 | H26: =INDEX(Monthly!$C$74:$BJ$74,($R$2-1)*12+1) -> 1500000 | I26: =INDEX(Monthly!$C$74:$BJ$74,($R$2-1)*12+2) -> 0 | J26: =INDEX(Monthly!$C$74:$BJ$74,($R$2-1)*12+3) -> 0 | K26: =INDEX(Monthly!$C$74:$BJ$74,($R$2-1)*12+4) -> 0 | L26: =INDEX(Monthly!$C$74:$BJ$74,($R$2-1)*12+5) -> 0 | M26: =INDEX(Monthly!$C$74:$BJ$74,($R$2-1)*12+6) -> 0 | N26: =INDEX(Monthly!$C$74:$BJ$74,($R$2-1)*12+7) -> 0 | O26: =INDEX(Monthly!$C$74:$BJ$74,($R$2-1)*12+8) -> 0 | P26: =INDEX(Monthly!$C$74:$BJ$74,($R$2-1)*12+9) -> 0 | Q26: =INDEX(Monthly!$C$74:$BJ$74,($R$2-1)*12+10) -> 0 | R26: =INDEX(Monthly!$C$74:$BJ$74,($R$2-1)*12+11) -> 0 | S26: =INDEX(Monthly!$C$74:$BJ$74,($R$2-1)*12+12) -> 0
A27: Loan drawdown | B27: ='Cash Flow'!B13 -> 500000 | C27: ='Cash Flow'!C13 -> 0 | D27: ='Cash Flow'!D13 -> 0 | E27: ='Cash Flow'!E13 -> 0 | F27: ='Cash Flow'!F13 -> 0 | H27: =INDEX(Monthly!$C$59:$BJ$59,($R$2-1)*12+1) -> 500000 | I27: =INDEX(Monthly!$C$59:$BJ$59,($R$2-1)*12+2) -> 0 | J27: =INDEX(Monthly!$C$59:$BJ$59,($R$2-1)*12+3) -> 0 | K27: =INDEX(Monthly!$C$59:$BJ$59,($R$2-1)*12+4) -> 0 | L27: =INDEX(Monthly!$C$59:$BJ$59,($R$2-1)*12+5) -> 0 | M27: =INDEX(Monthly!$C$59:$BJ$59,($R$2-1)*12+6) -> 0 | N27: =INDEX(Monthly!$C$59:$BJ$59,($R$2-1)*12+7) -> 0 | O27: =INDEX(Monthly!$C$59:$BJ$59,($R$2-1)*12+8) -> 0 | P27: =INDEX(Monthly!$C$59:$BJ$59,($R$2-1)*12+9) -> 0 | Q27: =INDEX(Monthly!$C$59:$BJ$59,($R$2-1)*12+10) -> 0 | R27: =INDEX(Monthly!$C$59:$BJ$59,($R$2-1)*12+11) -> 0 | S27: =INDEX(Monthly!$C$59:$BJ$59,($R$2-1)*12+12) -> 0
A28: Loan repayment | B28: ='Cash Flow'!B14 -> -91666.667 | C28: ='Cash Flow'!C14 -> -100000 | D28: ='Cash Flow'!D14 -> -100000 | E28: ='Cash Flow'!E14 -> -100000 | F28: ='Cash Flow'!F14 -> -100000 | H28: =INDEX(Monthly!$C$60:$BJ$60,($R$2-1)*12+1) -> 0 | I28: =INDEX(Monthly!$C$60:$BJ$60,($R$2-1)*12+2) -> -8333.3333 | J28: =INDEX(Monthly!$C$60:$BJ$60,($R$2-1)*12+3) -> -8333.3333 | K28: =INDEX(Monthly!$C$60:$BJ$60,($R$2-1)*12+4) -> -8333.3333 | L28: =INDEX(Monthly!$C$60:$BJ$60,($R$2-1)*12+5) -> -8333.3333 | M28: =INDEX(Monthly!$C$60:$BJ$60,($R$2-1)*12+6) -> -8333.3333 | N28: =INDEX(Monthly!$C$60:$BJ$60,($R$2-1)*12+7) -> -8333.3333 | O28: =INDEX(Monthly!$C$60:$BJ$60,($R$2-1)*12+8) -> -8333.3333 | P28: =INDEX(Monthly!$C$60:$BJ$60,($R$2-1)*12+9) -> -8333.3333 | Q28: =INDEX(Monthly!$C$60:$BJ$60,($R$2-1)*12+10) -> -8333.3333 | R28: =INDEX(Monthly!$C$60:$BJ$60,($R$2-1)*12+11) -> -8333.3333 | S28: =INDEX(Monthly!$C$60:$BJ$60,($R$2-1)*12+12) -> -8333.3333
A29: Financing cash flow | B29: ='Cash Flow'!B15 -> 1908333.3 | C29: ='Cash Flow'!C15 -> -100000 | D29: ='Cash Flow'!D15 -> -100000 | E29: ='Cash Flow'!E15 -> -100000 | F29: ='Cash Flow'!F15 -> -100000 | H29: =INDEX(Monthly!$C$75:$BJ$75,($R$2-1)*12+1) -> 2000000 | I29: =INDEX(Monthly!$C$75:$BJ$75,($R$2-1)*12+2) -> -8333.3333 | J29: =INDEX(Monthly!$C$75:$BJ$75,($R$2-1)*12+3) -> -8333.3333 | K29: =INDEX(Monthly!$C$75:$BJ$75,($R$2-1)*12+4) -> -8333.3333 | L29: =INDEX(Monthly!$C$75:$BJ$75,($R$2-1)*12+5) -> -8333.3333 | M29: =INDEX(Monthly!$C$75:$BJ$75,($R$2-1)*12+6) -> -8333.3333 | N29: =INDEX(Monthly!$C$75:$BJ$75,($R$2-1)*12+7) -> -8333.3333 | O29: =INDEX(Monthly!$C$75:$BJ$75,($R$2-1)*12+8) -> -8333.3333 | P29: =INDEX(Monthly!$C$75:$BJ$75,($R$2-1)*12+9) -> -8333.3333 | Q29: =INDEX(Monthly!$C$75:$BJ$75,($R$2-1)*12+10) -> -8333.3333 | R29: =INDEX(Monthly!$C$75:$BJ$75,($R$2-1)*12+11) -> -8333.3333 | S29: =INDEX(Monthly!$C$75:$BJ$75,($R$2-1)*12+12) -> -8333.3333
A30: Net change in cash | B30: ='Cash Flow'!B16 -> 1412273.2 | C30: ='Cash Flow'!C16 -> 84798.669 | D30: ='Cash Flow'!D16 -> 307937.43 | E30: ='Cash Flow'!E16 -> 554972.77 | F30: ='Cash Flow'!F16 -> 829551.32 | H30: =INDEX(Monthly!$C$76:$BJ$76,($R$2-1)*12+1) -> 1354447.6 | I30: =INDEX(Monthly!$C$76:$BJ$76,($R$2-1)*12+2) -> 4656.5107 | J30: =INDEX(Monthly!$C$76:$BJ$76,($R$2-1)*12+3) -> 4700.3996 | K30: =INDEX(Monthly!$C$76:$BJ$76,($R$2-1)*12+4) -> 4744.2885 | L30: =INDEX(Monthly!$C$76:$BJ$76,($R$2-1)*12+5) -> 4788.1774 | M30: =INDEX(Monthly!$C$76:$BJ$76,($R$2-1)*12+6) -> 4832.0663 | N30: =INDEX(Monthly!$C$76:$BJ$76,($R$2-1)*12+7) -> 4875.9552 | O30: =INDEX(Monthly!$C$76:$BJ$76,($R$2-1)*12+8) -> 4919.8441 | P30: =INDEX(Monthly!$C$76:$BJ$76,($R$2-1)*12+9) -> 4963.7329 | Q30: =INDEX(Monthly!$C$76:$BJ$76,($R$2-1)*12+10) -> 5007.6218 | R30: =INDEX(Monthly!$C$76:$BJ$76,($R$2-1)*12+11) -> -27811.85 | S30: =INDEX(Monthly!$C$76:$BJ$76,($R$2-1)*12+12) -> 42148.809
A31: Closing cash | B31: ='Cash Flow'!B18 -> 1412273.2 | C31: ='Cash Flow'!C18 -> 1497071.8 | D31: ='Cash Flow'!D18 -> 1805009.3 | E31: ='Cash Flow'!E18 -> 2359982 | F31: ='Cash Flow'!F18 -> 3189533.4 | H31: =INDEX(Monthly!$C$78:$BJ$78,($R$2-1)*12+1) -> 1354447.6 | I31: =INDEX(Monthly!$C$78:$BJ$78,($R$2-1)*12+2) -> 1359104.1 | J31: =INDEX(Monthly!$C$78:$BJ$78,($R$2-1)*12+3) -> 1363804.5 | K31: =INDEX(Monthly!$C$78:$BJ$78,($R$2-1)*12+4) -> 1368548.8 | L31: =INDEX(Monthly!$C$78:$BJ$78,($R$2-1)*12+5) -> 1373337 | M31: =INDEX(Monthly!$C$78:$BJ$78,($R$2-1)*12+6) -> 1378169.1 | N31: =INDEX(Monthly!$C$78:$BJ$78,($R$2-1)*12+7) -> 1383045 | O31: =INDEX(Monthly!$C$78:$BJ$78,($R$2-1)*12+8) -> 1387964.9 | P31: =INDEX(Monthly!$C$78:$BJ$78,($R$2-1)*12+9) -> 1392928.6 | Q31: =INDEX(Monthly!$C$78:$BJ$78,($R$2-1)*12+10) -> 1397936.2 | R31: =INDEX(Monthly!$C$78:$BJ$78,($R$2-1)*12+11) -> 1370124.4 | S31: =INDEX(Monthly!$C$78:$BJ$78,($R$2-1)*12+12) -> 1412273.2
A39: Balance sheet at year end ($'000) | H39: ="Balance sheet at month end ($'000) — Year "&$R$2 -> Balance sheet at month end ($'000) — Year 1
B40: 1 | C40: 2 | D40: 3 | E40: 4 | F40: 5 | H40: =INDEX(Monthly!$C$4:$BJ$4,($R$2-1)*12+1) -> 1 | I40: =INDEX(Monthly!$C$4:$BJ$4,($R$2-1)*12+2) -> 2 | J40: =INDEX(Monthly!$C$4:$BJ$4,($R$2-1)*12+3) -> 3 | K40: =INDEX(Monthly!$C$4:$BJ$4,($R$2-1)*12+4) -> 4 | L40: =INDEX(Monthly!$C$4:$BJ$4,($R$2-1)*12+5) -> 5 | M40: =INDEX(Monthly!$C$4:$BJ$4,($R$2-1)*12+6) -> 6 | N40: =INDEX(Monthly!$C$4:$BJ$4,($R$2-1)*12+7) -> 7 | O40: =INDEX(Monthly!$C$4:$BJ$4,($R$2-1)*12+8) -> 8 | P40: =INDEX(Monthly!$C$4:$BJ$4,($R$2-1)*12+9) -> 9 | Q40: =INDEX(Monthly!$C$4:$BJ$4,($R$2-1)*12+10) -> 10 | R40: =INDEX(Monthly!$C$4:$BJ$4,($R$2-1)*12+11) -> 11 | S40: =INDEX(Monthly!$C$4:$BJ$4,($R$2-1)*12+12) -> 12
A41: Cash | B41: ='Balance Sheet'!B5 -> 1412273.2 | C41: ='Balance Sheet'!C5 -> 1497071.8 | D41: ='Balance Sheet'!D5 -> 1805009.3 | E41: ='Balance Sheet'!E5 -> 2359982 | F41: ='Balance Sheet'!F5 -> 3189533.4 | H41: =INDEX(Monthly!$C$78:$BJ$78,($R$2-1)*12+1) -> 1354447.6 | I41: =INDEX(Monthly!$C$78:$BJ$78,($R$2-1)*12+2) -> 1359104.1 | J41: =INDEX(Monthly!$C$78:$BJ$78,($R$2-1)*12+3) -> 1363804.5 | K41: =INDEX(Monthly!$C$78:$BJ$78,($R$2-1)*12+4) -> 1368548.8 | L41: =INDEX(Monthly!$C$78:$BJ$78,($R$2-1)*12+5) -> 1373337 | M41: =INDEX(Monthly!$C$78:$BJ$78,($R$2-1)*12+6) -> 1378169.1 | N41: =INDEX(Monthly!$C$78:$BJ$78,($R$2-1)*12+7) -> 1383045 | O41: =INDEX(Monthly!$C$78:$BJ$78,($R$2-1)*12+8) -> 1387964.9 | P41: =INDEX(Monthly!$C$78:$BJ$78,($R$2-1)*12+9) -> 1392928.6 | Q41: =INDEX(Monthly!$C$78:$BJ$78,($R$2-1)*12+10) -> 1397936.2 | R41: =INDEX(Monthly!$C$78:$BJ$78,($R$2-1)*12+11) -> 1370124.4 | S41: =INDEX(Monthly!$C$78:$BJ$78,($R$2-1)*12+12) -> 1412273.2
A42: Accounts receivable | B42: ='Balance Sheet'!B6 -> 36214.071 | C42: ='Balance Sheet'!C6 -> 47422.896 | D42: ='Balance Sheet'!D6 -> 60662.751 | E42: ='Balance Sheet'!E6 -> 76424.031 | F42: ='Balance Sheet'!F6 -> 95323.953 | H42: =INDEX(Monthly!$C$64:$BJ$64,($R$2-1)*12+1) -> 29523.471 | I42: =INDEX(Monthly!$C$64:$BJ$64,($R$2-1)*12+2) -> 29523.471 | J42: =INDEX(Monthly!$C$64:$BJ$64,($R$2-1)*12+3) -> 29523.471 | K42: =INDEX(Monthly!$C$64:$BJ$64,($R$2-1)*12+4) -> 29523.471 | L42: =INDEX(Monthly!$C$64:$BJ$64,($R$2-1)*12+5) -> 29523.471 | M42: =INDEX(Monthly!$C$64:$BJ$64,($R$2-1)*12+6) -> 29523.471 | N42: =INDEX(Monthly!$C$64:$BJ$64,($R$2-1)*12+7) -> 29523.471 | O42: =INDEX(Monthly!$C$64:$BJ$64,($R$2-1)*12+8) -> 29523.471 | P42: =INDEX(Monthly!$C$64:$BJ$64,($R$2-1)*12+9) -> 29523.471 | Q42: =INDEX(Monthly!$C$64:$BJ$64,($R$2-1)*12+10) -> 29523.471 | R42: =INDEX(Monthly!$C$64:$BJ$64,($R$2-1)*12+11) -> 36214.071 | S42: =INDEX(Monthly!$C$64:$BJ$64,($R$2-1)*12+12) -> 36214.071
A43: Inventory | B43: ='Balance Sheet'!B7 -> 570371.62 | C43: ='Balance Sheet'!C7 -> 746910.62 | D43: ='Balance Sheet'!D7 -> 955438.33 | E43: ='Balance Sheet'!E7 -> 1203678.5 | F43: ='Balance Sheet'!F7 -> 1501352.3 | H43: =INDEX(Monthly!$C$65:$BJ$65,($R$2-1)*12+1) -> 464994.67 | I43: =INDEX(Monthly!$C$65:$BJ$65,($R$2-1)*12+2) -> 464994.67 | J43: =INDEX(Monthly!$C$65:$BJ$65,($R$2-1)*12+3) -> 464994.67 | K43: =INDEX(Monthly!$C$65:$BJ$65,($R$2-1)*12+4) -> 464994.67 | L43: =INDEX(Monthly!$C$65:$BJ$65,($R$2-1)*12+5) -> 464994.67 | M43: =INDEX(Monthly!$C$65:$BJ$65,($R$2-1)*12+6) -> 464994.67 | N43: =INDEX(Monthly!$C$65:$BJ$65,($R$2-1)*12+7) -> 464994.67 | O43: =INDEX(Monthly!$C$65:$BJ$65,($R$2-1)*12+8) -> 464994.67 | P43: =INDEX(Monthly!$C$65:$BJ$65,($R$2-1)*12+9) -> 464994.67 | Q43: =INDEX(Monthly!$C$65:$BJ$65,($R$2-1)*12+10) -> 464994.67 | R43: =INDEX(Monthly!$C$65:$BJ$65,($R$2-1)*12+11) -> 570371.62 | S43: =INDEX(Monthly!$C$65:$BJ$65,($R$2-1)*12+12) -> 570371.62
A44: Net fixed assets | B44: ='Balance Sheet'!B8 -> 300000 | C44: ='Balance Sheet'!C8 -> 378571.43 | D44: ='Balance Sheet'!D8 -> 435714.29 | E44: ='Balance Sheet'!E8 -> 471428.57 | F44: ='Balance Sheet'!F8 -> 485714.29 | H44: =INDEX(Monthly!$C$55:$BJ$55,($R$2-1)*12+1) -> 345833.33 | I44: =INDEX(Monthly!$C$55:$BJ$55,($R$2-1)*12+2) -> 341666.67 | J44: =INDEX(Monthly!$C$55:$BJ$55,($R$2-1)*12+3) -> 337500 | K44: =INDEX(Monthly!$C$55:$BJ$55,($R$2-1)*12+4) -> 333333.33 | L44: =INDEX(Monthly!$C$55:$BJ$55,($R$2-1)*12+5) -> 329166.67 | M44: =INDEX(Monthly!$C$55:$BJ$55,($R$2-1)*12+6) -> 325000 | N44: =INDEX(Monthly!$C$55:$BJ$55,($R$2-1)*12+7) -> 320833.33 | O44: =INDEX(Monthly!$C$55:$BJ$55,($R$2-1)*12+8) -> 316666.67 | P44: =INDEX(Monthly!$C$55:$BJ$55,($R$2-1)*12+9) -> 312500 | Q44: =INDEX(Monthly!$C$55:$BJ$55,($R$2-1)*12+10) -> 308333.33 | R44: =INDEX(Monthly!$C$55:$BJ$55,($R$2-1)*12+11) -> 304166.67 | S44: =INDEX(Monthly!$C$55:$BJ$55,($R$2-1)*12+12) -> 300000
A45: Total assets | B45: ='Balance Sheet'!B9 -> 2318858.9 | C45: ='Balance Sheet'!C9 -> 2669976.8 | D45: ='Balance Sheet'!D9 -> 3256824.6 | E45: ='Balance Sheet'!E9 -> 4111513.1 | F45: ='Balance Sheet'!F9 -> 5271923.9 | H45: =INDEX(Monthly!$C$92:$BJ$92,($R$2-1)*12+1) -> 2194799.1 | I45: =INDEX(Monthly!$C$92:$BJ$92,($R$2-1)*12+2) -> 2195288.9 | J45: =INDEX(Monthly!$C$92:$BJ$92,($R$2-1)*12+3) -> 2195822.7 | K45: =INDEX(Monthly!$C$92:$BJ$92,($R$2-1)*12+4) -> 2196400.3 | L45: =INDEX(Monthly!$C$92:$BJ$92,($R$2-1)*12+5) -> 2197021.8 | M45: =INDEX(Monthly!$C$92:$BJ$92,($R$2-1)*12+6) -> 2197687.2 | N45: =INDEX(Monthly!$C$92:$BJ$92,($R$2-1)*12+7) -> 2198396.5 | O45: =INDEX(Monthly!$C$92:$BJ$92,($R$2-1)*12+8) -> 2199149.7 | P45: =INDEX(Monthly!$C$92:$BJ$92,($R$2-1)*12+9) -> 2199946.7 | Q45: =INDEX(Monthly!$C$92:$BJ$92,($R$2-1)*12+10) -> 2200787.7 | R45: =INDEX(Monthly!$C$92:$BJ$92,($R$2-1)*12+11) -> 2280876.7 | S45: =INDEX(Monthly!$C$92:$BJ$92,($R$2-1)*12+12) -> 2318858.9
A46: Accounts payable | B46: ='Balance Sheet'!B10 -> 228148.65 | C46: ='Balance Sheet'!C10 -> 298764.25 | D46: ='Balance Sheet'!D10 -> 382175.33 | E46: ='Balance Sheet'!E10 -> 481471.4 | F46: ='Balance Sheet'!F10 -> 600540.91 | H46: =INDEX(Monthly!$C$66:$BJ$66,($R$2-1)*12+1) -> 185997.87 | I46: =INDEX(Monthly!$C$66:$BJ$66,($R$2-1)*12+2) -> 185997.87 | J46: =INDEX(Monthly!$C$66:$BJ$66,($R$2-1)*12+3) -> 185997.87 | K46: =INDEX(Monthly!$C$66:$BJ$66,($R$2-1)*12+4) -> 185997.87 | L46: =INDEX(Monthly!$C$66:$BJ$66,($R$2-1)*12+5) -> 185997.87 | M46: =INDEX(Monthly!$C$66:$BJ$66,($R$2-1)*12+6) -> 185997.87 | N46: =INDEX(Monthly!$C$66:$BJ$66,($R$2-1)*12+7) -> 185997.87 | O46: =INDEX(Monthly!$C$66:$BJ$66,($R$2-1)*12+8) -> 185997.87 | P46: =INDEX(Monthly!$C$66:$BJ$66,($R$2-1)*12+9) -> 185997.87 | Q46: =INDEX(Monthly!$C$66:$BJ$66,($R$2-1)*12+10) -> 185997.87 | R46: =INDEX(Monthly!$C$66:$BJ$66,($R$2-1)*12+11) -> 228148.65 | S46: =INDEX(Monthly!$C$66:$BJ$66,($R$2-1)*12+12) -> 228148.65
A47: Loan | B47: ='Balance Sheet'!B11 -> 408333.33 | C47: ='Balance Sheet'!C11 -> 308333.33 | D47: ='Balance Sheet'!D11 -> 208333.33 | E47: ='Balance Sheet'!E11 -> 108333.33 | F47: ='Balance Sheet'!F11 -> 8333.3333 | H47: =INDEX(Monthly!$C$61:$BJ$61,($R$2-1)*12+1) -> 500000 | I47: =INDEX(Monthly!$C$61:$BJ$61,($R$2-1)*12+2) -> 491666.67 | J47: =INDEX(Monthly!$C$61:$BJ$61,($R$2-1)*12+3) -> 483333.33 | K47: =INDEX(Monthly!$C$61:$BJ$61,($R$2-1)*12+4) -> 475000 | L47: =INDEX(Monthly!$C$61:$BJ$61,($R$2-1)*12+5) -> 466666.67 | M47: =INDEX(Monthly!$C$61:$BJ$61,($R$2-1)*12+6) -> 458333.33 | N47: =INDEX(Monthly!$C$61:$BJ$61,($R$2-1)*12+7) -> 450000 | O47: =INDEX(Monthly!$C$61:$BJ$61,($R$2-1)*12+8) -> 441666.67 | P47: =INDEX(Monthly!$C$61:$BJ$61,($R$2-1)*12+9) -> 433333.33 | Q47: =INDEX(Monthly!$C$61:$BJ$61,($R$2-1)*12+10) -> 425000 | R47: =INDEX(Monthly!$C$61:$BJ$61,($R$2-1)*12+11) -> 416666.67 | S47: =INDEX(Monthly!$C$61:$BJ$61,($R$2-1)*12+12) -> 408333.33
A48: Total liabilities | B48: ='Balance Sheet'!B12 -> 636481.98 | C48: ='Balance Sheet'!C12 -> 607097.58 | D48: ='Balance Sheet'!D12 -> 590508.67 | E48: ='Balance Sheet'!E12 -> 589804.73 | F48: ='Balance Sheet'!F12 -> 608874.24 | H48: =INDEX(Monthly!$C$93:$BJ$93,($R$2-1)*12+1) -> 685997.87 | I48: =INDEX(Monthly!$C$93:$BJ$93,($R$2-1)*12+2) -> 677664.54 | J48: =INDEX(Monthly!$C$93:$BJ$93,($R$2-1)*12+3) -> 669331.2 | K48: =INDEX(Monthly!$C$93:$BJ$93,($R$2-1)*12+4) -> 660997.87 | L48: =INDEX(Monthly!$C$93:$BJ$93,($R$2-1)*12+5) -> 652664.54 | M48: =INDEX(Monthly!$C$93:$BJ$93,($R$2-1)*12+6) -> 644331.2 | N48: =INDEX(Monthly!$C$93:$BJ$93,($R$2-1)*12+7) -> 635997.87 | O48: =INDEX(Monthly!$C$93:$BJ$93,($R$2-1)*12+8) -> 627664.54 | P48: =INDEX(Monthly!$C$93:$BJ$93,($R$2-1)*12+9) -> 619331.2 | Q48: =INDEX(Monthly!$C$93:$BJ$93,($R$2-1)*12+10) -> 610997.87 | R48: =INDEX(Monthly!$C$93:$BJ$93,($R$2-1)*12+11) -> 644815.32 | S48: =INDEX(Monthly!$C$93:$BJ$93,($R$2-1)*12+12) -> 636481.98
A49: Paid-in capital | B49: ='Balance Sheet'!B13 -> 1500000 | C49: ='Balance Sheet'!C13 -> 1500000 | D49: ='Balance Sheet'!D13 -> 1500000 | E49: ='Balance Sheet'!E13 -> 1500000 | F49: ='Balance Sheet'!F13 -> 1500000 | H49: =INDEX(Monthly!$C$90:$BJ$90,($R$2-1)*12+1) -> 1500000 | I49: =INDEX(Monthly!$C$90:$BJ$90,($R$2-1)*12+2) -> 1500000 | J49: =INDEX(Monthly!$C$90:$BJ$90,($R$2-1)*12+3) -> 1500000 | K49: =INDEX(Monthly!$C$90:$BJ$90,($R$2-1)*12+4) -> 1500000 | L49: =INDEX(Monthly!$C$90:$BJ$90,($R$2-1)*12+5) -> 1500000 | M49: =INDEX(Monthly!$C$90:$BJ$90,($R$2-1)*12+6) -> 1500000 | N49: =INDEX(Monthly!$C$90:$BJ$90,($R$2-1)*12+7) -> 1500000 | O49: =INDEX(Monthly!$C$90:$BJ$90,($R$2-1)*12+8) -> 1500000 | P49: =INDEX(Monthly!$C$90:$BJ$90,($R$2-1)*12+9) -> 1500000 | Q49: =INDEX(Monthly!$C$90:$BJ$90,($R$2-1)*12+10) -> 1500000 | R49: =INDEX(Monthly!$C$90:$BJ$90,($R$2-1)*12+11) -> 1500000 | S49: =INDEX(Monthly!$C$90:$BJ$90,($R$2-1)*12+12) -> 1500000
A50: Retained earnings | B50: ='Balance Sheet'!B14 -> 182376.89 | C50: ='Balance Sheet'!C14 -> 562879.21 | D50: ='Balance Sheet'!D14 -> 1166316 | E50: ='Balance Sheet'!E14 -> 2021708.4 | F50: ='Balance Sheet'!F14 -> 3163049.6 | H50: =INDEX(Monthly!$C$91:$BJ$91,($R$2-1)*12+1) -> 8801.2329 | I50: =INDEX(Monthly!$C$91:$BJ$91,($R$2-1)*12+2) -> 17624.41 | J50: =INDEX(Monthly!$C$91:$BJ$91,($R$2-1)*12+3) -> 26491.477 | K50: =INDEX(Monthly!$C$91:$BJ$91,($R$2-1)*12+4) -> 35402.432 | L50: =INDEX(Monthly!$C$91:$BJ$91,($R$2-1)*12+5) -> 44357.276 | M50: =INDEX(Monthly!$C$91:$BJ$91,($R$2-1)*12+6) -> 53356.009 | N50: =INDEX(Monthly!$C$91:$BJ$91,($R$2-1)*12+7) -> 62398.631 | O50: =INDEX(Monthly!$C$91:$BJ$91,($R$2-1)*12+8) -> 71485.141 | P50: =INDEX(Monthly!$C$91:$BJ$91,($R$2-1)*12+9) -> 80615.541 | Q50: =INDEX(Monthly!$C$91:$BJ$91,($R$2-1)*12+10) -> 89789.829 | R50: =INDEX(Monthly!$C$91:$BJ$91,($R$2-1)*12+11) -> 136061.42 | S50: =INDEX(Monthly!$C$91:$BJ$91,($R$2-1)*12+12) -> 182376.89
...

Sheet Scenarios
A1: Scenarios — Low / Base / High | H1: =HYPERLINK("#'Cover'!A1","◂ Contents") -> ◂ Contents
A2: All three scenarios calculated side by side, live: change any input and every column updates. Active = the scenario chosen on the Dashboard.
A5: Key drivers
A6: Driver | B6: Low | C6: Base | D6: High | E6: Active
A7: Website visits per month (year 1, non-paid) (# / month) | B7: =Inputs!$B$7 -> 65000 | C7: =Inputs!$C$7 -> 80000 | D7: =Inputs!$D$7 -> 100000 | E7: =Inputs!$E$7 -> 80000
A8: Conversion rate (orders ÷ visits) (%) | B8: =Inputs!$B$9 -> 0.02 | C8: =Inputs!$C$9 -> 0.024 | D8: =Inputs!$D$9 -> 0.028 | E8: =Inputs!$E$9 -> 0.024
A9: Average order value (before returns) ($) | B9: =Inputs!$B$10 -> 65 | C9: =Inputs!$C$10 -> 75 | D9: =Inputs!$D$10 -> 85 | E9: =Inputs!$E$10 -> 75
A10: Paid ads budget per month (year 1) ($ / month) | B10: =Inputs!$B$13 -> 50000 | C10: =Inputs!$C$13 -> 50000 | D10: =Inputs!$D$13 -> 50000 | E10: =Inputs!$E$13 -> 50000
A11: Product cost, % of net sales (%) | B11: =Inputs!$B$30 -> 0.45 | C11: =Inputs!$C$30 -> 0.42 | D11: =Inputs!$D$30 -> 0.39 | E11: =Inputs!$E$30 -> 0.42
A12: Stores open at start (#) | B12: =Inputs!$B$18 -> 2 | C12: =Inputs!$C$18 -> 2 | D12: =Inputs!$D$18 -> 2 | E12: =Inputs!$E$18 -> 2
A13: Equity raised at start ($) | B13: =Inputs!$B$58 -> 1500000 | C13: =Inputs!$C$58 -> 1500000 | D13: =Inputs!$D$58 -> 1500000 | E13: =Inputs!$E$58 -> 1500000
A15: Results by scenario ($'000)
A16: Output | B16: Low | C16: Base | D16: High | E16: Active
A17: Revenue — final year | B17: =F30 -> 6972588.8 | C17: =F31 -> 14322508 | D17: =F32 -> 31530129 | E17: ='P&L'!F5 -> 14322508
A18: Revenue — whole plan | B18: =SUM(B30:F30) -> 25478839 | C18: =SUM(B31:F31) -> 47666046 | D18: =SUM(B32:F32) -> 92721302 | E18: =SUM('P&L'!$B$5:$F$5) -> 47666046
A19: EBITDA — final year | B19: =F36 -> -2181544.9 | C19: =F37 -> 1585116.7 | D19: =F38 -> 11124362 | E19: ='P&L'!F18 -> 1585116.7
A20: EBITDA margin — final year | B20: =IF(B17=0,0,B19/B17) -> -0.31287445 | C20: =IF(C17=0,0,C19/C17) -> 0.11067312 | D20: =IF(D17=0,0,D19/D17) -> 0.35281688 | E20: =IF(E17=0,0,E19/E17) -> 0.11067312
A21: Net income — final year | B21: =F42 -> -2321925.8 | C21: =F43 -> 1141341.2 | D21: =F44 -> 8677345 | E21: ='P&L'!F25 -> 1141341.2
A22: Net income — whole plan | B22: =SUM(B42:F42) -> -7543588.7 | C22: =SUM(B43:F43) -> 3163049.6 | D22: =SUM(B44:F44) -> 23191560 | E22: =SUM('P&L'!$B$25:$F$25) -> 3163049.6
A23: Cash at the end of the plan | B23: =F48 -> -7029882.6 | C23: =F49 -> 3189533.4 | D23: =F50 -> 22123099 | E23: ='Balance Sheet'!F5 -> 3189533.4
A24: Lowest cash balance | B24: =MIN('Scenario calc'!$C$80:$BJ$80) -> -7029882.6 | C24: =MIN('Scenario calc'!$C$191:$BJ$191) -> 1260305.1 | D24: =MIN('Scenario calc'!$C$302:$BJ$302) -> 1323640.8 | E24: ='Break-even'!B18 -> 1260305.1
A25: Lowest cash point (month #) | B25: =MATCH(MIN('Scenario calc'!$C$80:$BJ$80),'Scenario calc'!$C$80:$BJ$80,0) -> 60 | C25: =MATCH(MIN('Scenario calc'!$C$191:$BJ$191),'Scenario calc'!$C$191:$BJ$191,0) -> 13 | D25: =MATCH(MIN('Scenario calc'!$C$302:$BJ$302),'Scenario calc'!$C$302:$BJ$302,0) -> 1 | E25: ='Break-even'!B6 -> 13
A26: Funding required (incl. cash buffer) | B26: =SUMPRODUCT(--('Scenario calc'!$C$6:$BJ$6<=B25),'Scenario calc'!$C$53:$BJ$53)-SUMPRODUCT(--('Scenario calc'!$C$6:$BJ$6<=B25),'Scenario calc'!$C$74:$BJ$74)-SUMPRODUCT(--('Scenario calc'!$C$6:$BJ$6<=B25),'Scenario calc'!$C$62:$BJ$62)+Inputs!$B$73 -> 9749882.6 | C26: =SUMPRODUCT(--('Scenario calc'!$C$117:$BJ$117<=C25),'Scenario calc'!$C$164:$BJ$164)-SUMPRODUCT(--('Scenario calc'!$C$117:$BJ$117<=C25),'Scenario calc'!$C$185:$BJ$185)-SUMPRODUCT(--('Scenario calc'!$C$117:$BJ$117<=C25),'Scenario calc'!$C$173:$BJ$173)+Inputs!$C$73 -> 1459694.9 | D26: =SUMPRODUCT(--('Scenario calc'!$C$228:$BJ$228<=D25),'Scenario calc'!$C$275:$BJ$275)-SUMPRODUCT(--('Scenario calc'!$C$228:$BJ$228<=D25),'Scenario calc'!$C$296:$BJ$296)-SUMPRODUCT(--('Scenario calc'!$C$228:$BJ$228<=D25),'Scenario calc'!$C$284:$BJ$284)+Inputs!$D$73 -> 1396359.2 | E26: ='Break-even'!B12 -> 1459694.9
A28: Revenue by year ($'000)
A29: Scenario | B29: 1 | C29: 2 | D29: 3 | E29: 4 | F29: 5
A30: Low | B30: =SUMIF('Scenario calc'!$C$7:$BJ$7,B$29,'Scenario calc'!$C$27:$BJ$27) -> 3375914.7 | C30: =SUMIF('Scenario calc'!$C$7:$BJ$7,C$29,'Scenario calc'!$C$27:$BJ$27) -> 4163772.8 | D30: =SUMIF('Scenario calc'!$C$7:$BJ$7,D$29,'Scenario calc'!$C$27:$BJ$27) -> 5017510.1 | E30: =SUMIF('Scenario calc'!$C$7:$BJ$7,E$29,'Scenario calc'!$C$27:$BJ$27) -> 5949053.1 | F30: =SUMIF('Scenario calc'!$C$7:$BJ$7,F$29,'Scenario calc'!$C$27:$BJ$27) -> 6972588.8
A31: Base | B31: =SUMIF('Scenario calc'!$C$118:$BJ$118,B$29,'Scenario calc'!$C$138:$BJ$138) -> 5514942.9 | C31: =SUMIF('Scenario calc'!$C$118:$BJ$118,C$29,'Scenario calc'!$C$138:$BJ$138) -> 7179087.9 | D31: =SUMIF('Scenario calc'!$C$118:$BJ$118,D$29,'Scenario calc'!$C$138:$BJ$138) -> 9149574.9 | E31: =SUMIF('Scenario calc'!$C$118:$BJ$118,E$29,'Scenario calc'!$C$138:$BJ$138) -> 11499932 | F31: =SUMIF('Scenario calc'!$C$118:$BJ$118,F$29,'Scenario calc'!$C$138:$BJ$138) -> 14322508
A32: High | B32: =SUMIF('Scenario calc'!$C$229:$BJ$229,B$29,'Scenario calc'!$C$249:$BJ$249) -> 8858395.6 | C32: =SUMIF('Scenario calc'!$C$229:$BJ$229,C$29,'Scenario calc'!$C$249:$BJ$249) -> 12317220 | D32: =SUMIF('Scenario calc'!$C$229:$BJ$229,D$29,'Scenario calc'!$C$249:$BJ$249) -> 16913743 | E32: =SUMIF('Scenario calc'!$C$229:$BJ$229,E$29,'Scenario calc'!$C$249:$BJ$249) -> 23101814 | F32: =SUMIF('Scenario calc'!$C$229:$BJ$229,F$29,'Scenario calc'!$C$249:$BJ$249) -> 31530129
A34: EBITDA by year ($'000)
A35: Scenario | B35: 1 | C35: 2 | D35: 3 | E35: 4 | F35: 5
A36: Low | B36: =SUMIF('Scenario calc'!$C$7:$BJ$7,B$35,'Scenario calc'!$C$41:$BJ$41) -> -833184.37 | C36: =SUMIF('Scenario calc'!$C$7:$BJ$7,C$35,'Scenario calc'!$C$41:$BJ$41) -> -1015637.3 | D36: =SUMIF('Scenario calc'!$C$7:$BJ$7,D$35,'Scenario calc'!$C$41:$BJ$41) -> -1283745 | E36: =SUMIF('Scenario calc'!$C$7:$BJ$7,E$35,'Scenario calc'!$C$41:$BJ$41) -> -1661885.9 | F36: =SUMIF('Scenario calc'!$C$7:$BJ$7,F$35,'Scenario calc'!$C$41:$BJ$41) -> -2181544.9
A37: Base | B37: =SUMIF('Scenario calc'!$C$118:$BJ$118,B$35,'Scenario calc'!$C$152:$BJ$152) -> 317495.71 | C37: =SUMIF('Scenario calc'!$C$118:$BJ$118,C$35,'Scenario calc'!$C$152:$BJ$152) -> 581743.74 | D37: =SUMIF('Scenario calc'!$C$118:$BJ$118,D$35,'Scenario calc'!$C$152:$BJ$152) -> 877367.82 | E37: =SUMIF('Scenario calc'!$C$118:$BJ$118,E$35,'Scenario calc'!$C$152:$BJ$152) -> 1209727.6 | F37: =SUMIF('Scenario calc'!$C$118:$BJ$118,F$35,'Scenario calc'!$C$152:$BJ$152) -> 1585116.7
A38: High | B38: =SUMIF('Scenario calc'!$C$229:$BJ$229,B$35,'Scenario calc'!$C$263:$BJ$263) -> 2273994.9 | C38: =SUMIF('Scenario calc'!$C$229:$BJ$229,C$35,'Scenario calc'!$C$263:$BJ$263) -> 3538011.2 | D38: =SUMIF('Scenario calc'!$C$229:$BJ$229,D$35,'Scenario calc'!$C$263:$BJ$263) -> 5279916.7 | E38: =SUMIF('Scenario calc'!$C$229:$BJ$229,E$35,'Scenario calc'!$C$263:$BJ$263) -> 7707712.2 | F38: =SUMIF('Scenario calc'!$C$229:$BJ$229,F$35,'Scenario calc'!$C$263:$BJ$263) -> 11124362
A40: Net income by year ($'000)
A41: Scenario | B41: 1 | C41: 2 | D41: 3 | E41: 4 | F41: 5
A42: Low | B42: =SUMIF('Scenario calc'!$C$7:$BJ$7,B$41,'Scenario calc'!$C$50:$BJ$50) -> -919823.26 | C42: =SUMIF('Scenario calc'!$C$7:$BJ$7,C$41,'Scenario calc'!$C$50:$BJ$50) -> -1115732.5 | D42: =SUMIF('Scenario calc'!$C$7:$BJ$7,D$41,'Scenario calc'!$C$50:$BJ$50) -> -1397268.8 | E42: =SUMIF('Scenario calc'!$C$7:$BJ$7,E$41,'Scenario calc'!$C$50:$BJ$50) -> -1788838.3 | F42: =SUMIF('Scenario calc'!$C$7:$BJ$7,F$41,'Scenario calc'!$C$50:$BJ$50) -> -2321925.8
A43: Base | B43: =SUMIF('Scenario calc'!$C$118:$BJ$118,B$41,'Scenario calc'!$C$161:$BJ$161) -> 182376.89 | C43: =SUMIF('Scenario calc'!$C$118:$BJ$118,C$41,'Scenario calc'!$C$161:$BJ$161) -> 380502.32 | D43: =SUMIF('Scenario calc'!$C$118:$BJ$118,D$41,'Scenario calc'!$C$161:$BJ$161) -> 603436.77 | E43: =SUMIF('Scenario calc'!$C$118:$BJ$118,E$41,'Scenario calc'!$C$161:$BJ$161) -> 855392.43 | F43: =SUMIF('Scenario calc'!$C$118:$BJ$118,F$41,'Scenario calc'!$C$161:$BJ$161) -> 1141341.2
A44: High | B44: =SUMIF('Scenario calc'!$C$229:$BJ$229,B$41,'Scenario calc'!$C$272:$BJ$272) -> 1728011.3 | C44: =SUMIF('Scenario calc'!$C$229:$BJ$229,C$41,'Scenario calc'!$C$272:$BJ$272) -> 2715953.6 | D44: =SUMIF('Scenario calc'!$C$229:$BJ$229,D$41,'Scenario calc'!$C$272:$BJ$272) -> 4081450.4 | E44: =SUMIF('Scenario calc'!$C$229:$BJ$229,E$41,'Scenario calc'!$C$272:$BJ$272) -> 5988800.2 | F44: =SUMIF('Scenario calc'!$C$229:$BJ$229,F$41,'Scenario calc'!$C$272:$BJ$272) -> 8677345
A46: Cash at year end by year ($'000)
A47: Scenario | B47: 1 | C47: 2 | D47: 3 | E47: 4 | F47: 5
...

Sheet Break-even
A1: Startup costs, funding need and break-even | H1: =HYPERLINK("#'Cover'!A1","◂ Contents") -> ◂ Contents
A2: Live for the selected scenario. Periods are counted in months from the start of the plan.
A3: Scenario shown | B3: =CHOOSE(Dashboard!$B$4,"Low","Base","High") -> Base
A5: Startup costs & funding need (up to the lowest cash point)
A6: Lowest cash point (month #) | B6: =MATCH(MIN(Monthly!$C$78:$BJ$78),Monthly!$C$78:$BJ$78,0) -> 13
A7: Capital spending up to the lowest cash point | B7: =SUMPRODUCT(--(Monthly!$C$4:$BJ$4<=$B$6),Monthly!$C$51:$BJ$51) -> 500000
A8: Operating cash burn up to the lowest cash point | B8: =-SUMPRODUCT(--(Monthly!$C$4:$BJ$4<=$B$6),Monthly!$C$72:$BJ$72) -> 139694.92 | D8: Losses and working capital before the business funds itself
A9: Loan repayments up to the lowest cash point | B9: =-SUMPRODUCT(--(Monthly!$C$4:$BJ$4<=$B$6),Monthly!$C$60:$BJ$60) -> 100000
A10: Total uses of funds | B10: =B7+B8+B9 -> 739694.92
A11: Minimum cash buffer to keep | B11: =Inputs!$E$73 -> 720000 | D11: Input on the Inputs sheet
A12: Funding required (uses + buffer) | B12: =B10+B11 -> 1459694.9
A14: Equity raised | B14: =Inputs!$E$58 -> 1500000
A15: Loan drawn | B15: =Inputs!$E$59 -> 500000
A16: Total sources of funds | B16: =B14+B15 -> 2000000
A17: Funding surplus / (shortfall) | B17: =B16-B12 -> 540305.08 | D17: Negative = raise at least this much more
A18: Lowest cash balance in the plan | B18: =MIN(Monthly!$C$78:$BJ$78) -> 1260305.1 | D18: Equals sources minus uses
A20: Break-even timing
A21: First month with positive EBITDA (month #) | B21: =IFERROR(MATCH(1,Monthly!$C$79:$BJ$79,0),"Not within horizon") -> 1
A22: First month with positive net income (month #) | B22: =IFERROR(MATCH(1,Monthly!$C$82:$BJ$82,0),"Not within horizon") -> 1
A23: Cash invested paid back (month #) | B23: =IF(MIN(Monthly!$C$84:$BJ$84)>=0,"No investment to pay back",IFERROR(MATCH(1,Monthly!$C$86:$BJ$86,0),"Not within horizon")) -> 36 | D23: Cumulative operating + investing cash flow back to zero
A25: Annual break-even revenue
A26: Year # | B26: 1 | C26: 2 | D26: 3 | E26: 4 | F26: 5
B27: Year 1 | C27: Year 2 | D27: Year 3 | E27: Year 4 | F27: Year 5
A28: Revenue | B28: =SUMIF(Monthly!$C$5:$BJ$5,B$26,Monthly!$C$25:$BJ$25) -> 5514942.9 | C28: =SUMIF(Monthly!$C$5:$BJ$5,C$26,Monthly!$C$25:$BJ$25) -> 7179087.9 | D28: =SUMIF(Monthly!$C$5:$BJ$5,D$26,Monthly!$C$25:$BJ$25) -> 9149574.9 | E28: =SUMIF(Monthly!$C$5:$BJ$5,E$26,Monthly!$C$25:$BJ$25) -> 11499932 | F28: =SUMIF(Monthly!$C$5:$BJ$5,F$26,Monthly!$C$25:$BJ$25) -> 14322508
A29: Gross profit | B29: =SUMIF(Monthly!$C$5:$BJ$5,B$26,Monthly!$C$27:$BJ$27) -> 3198666.9 | C29: =SUMIF(Monthly!$C$5:$BJ$5,C$26,Monthly!$C$27:$BJ$27) -> 4163871 | D29: =SUMIF(Monthly!$C$5:$BJ$5,D$26,Monthly!$C$27:$BJ$27) -> 5306753.4 | E29: =SUMIF(Monthly!$C$5:$BJ$5,E$26,Monthly!$C$27:$BJ$27) -> 6669960.6 | F29: =SUMIF(Monthly!$C$5:$BJ$5,F$26,Monthly!$C$27:$BJ$27) -> 8307054.9
A30: Gross margin (contribution) | B30: =IF(B28=0,0,B29/B28) -> 0.58 | C30: =IF(C28=0,0,C29/C28) -> 0.58 | D30: =IF(D28=0,0,D29/D28) -> 0.58 | E30: =IF(E28=0,0,E29/E28) -> 0.58 | F30: =IF(F28=0,0,F29/F28) -> 0.58
A31: Operating expenses (treated as fixed) | B31: =-SUMIF(Monthly!$C$5:$BJ$5,B$26,Monthly!$C$38:$BJ$38) -> 2881171.1 | C31: =-SUMIF(Monthly!$C$5:$BJ$5,C$26,Monthly!$C$38:$BJ$38) -> 3582127.2 | D31: =-SUMIF(Monthly!$C$5:$BJ$5,D$26,Monthly!$C$38:$BJ$38) -> 4429385.6 | E31: =-SUMIF(Monthly!$C$5:$BJ$5,E$26,Monthly!$C$38:$BJ$38) -> 5460233 | F31: =-SUMIF(Monthly!$C$5:$BJ$5,F$26,Monthly!$C$38:$BJ$38) -> 6721938.2
A32: Break-even revenue (EBITDA = 0) | B32: =IF(B30>0,B31/B30,"n/a") -> 4967536.5 | C32: =IF(C30>0,C31/C30,"n/a") -> 6176081.4 | D32: =IF(D30>0,D31/D30,"n/a") -> 7636871.7 | E32: =IF(E30>0,E31/E30,"n/a") -> 9414194.8 | F32: =IF(F30>0,F31/F30,"n/a") -> 11589549
A33: Margin of safety (revenue above break-even) | B33: =IF(AND(ISNUMBER(B32),B28>0),(B28-B32)/B28,"n/a") -> 0.099258763 | C33: =IF(AND(ISNUMBER(C32),C28>0),(C28-C32)/C28,"n/a") -> 0.13971224 | D33: =IF(AND(ISNUMBER(D32),D28>0),(D28-D32)/D28,"n/a") -> 0.16533043 | E33: =IF(AND(ISNUMBER(E32),E28>0),(E28-E32)/E28,"n/a") -> 0.18136953 | F33: =IF(AND(ISNUMBER(F32),F28>0),(F28-F32)/F28,"n/a") -> 0.19081572
A35: Simplification: cost of sales is treated as variable and operating expenses as fixed, so break-even revenue = operating expenses ÷ gross margin. In a year with zero or negative gross margin there is no break-even revenue (n/a); the chart line shows 0 there.

Sheet Valuation
A1: Discounted cash flow valuation | H1: =HYPERLINK("#'Cover'!A1","◂ Contents") -> ◂ Contents
A2: Enterprise value at the start of the plan, before the funding raised in period 1. Year-end discounting.
A3: Scenario shown | B3: =CHOOSE(Dashboard!$B$4,"Low","Base","High") -> Base
A5: Assumptions (active scenario, from the Inputs sheet)
A6: Discount rate (WACC) | B6: =Inputs!$E$76 -> 0.16
A7: Terminal growth rate | B7: =Inputs!$E$77 -> 0.02
A8: Exit multiple (EV ÷ final-year EBITDA) | B8: =Inputs!$E$78 -> 5.5
A9: Tax rate (for the interest tax shield) | B9: =Inputs!$E$70 -> 0.21
A10: Sensitivity step: WACC | B10: =Inputs!$E$79 -> 0.01
A11: Sensitivity step: terminal growth | B11: =Inputs!$E$80 -> 0.005
A13: Free cash flow by year
A14: Year # | B14: 1 | C14: 2 | D14: 3 | E14: 4 | F14: 5
B15: Year 1 | C15: Year 2 | D15: Year 3 | E15: Year 4 | F15: Year 5
A16: EBITDA | B16: =SUMIF(Monthly!$C$5:$BJ$5,B$14,Monthly!$C$39:$BJ$39) -> 317495.71 | C16: =SUMIF(Monthly!$C$5:$BJ$5,C$14,Monthly!$C$39:$BJ$39) -> 581743.74 | D16: =SUMIF(Monthly!$C$5:$BJ$5,D$14,Monthly!$C$39:$BJ$39) -> 877367.82 | E16: =SUMIF(Monthly!$C$5:$BJ$5,E$14,Monthly!$C$39:$BJ$39) -> 1209727.6 | F16: =SUMIF(Monthly!$C$5:$BJ$5,F$14,Monthly!$C$39:$BJ$39) -> 1585116.7
A17: Unlevered free cash flow | B17: =SUMIF(Monthly!$C$5:$BJ$5,B$14,Monthly!$C$87:$BJ$87) -> -467115.43 | C17: =SUMIF(Monthly!$C$5:$BJ$5,C$14,Monthly!$C$87:$BJ$87) -> 207445.34 | D17: =SUMIF(Monthly!$C$5:$BJ$5,D$14,Monthly!$C$87:$BJ$87) -> 424264.1 | E17: =SUMIF(Monthly!$C$5:$BJ$5,E$14,Monthly!$C$87:$BJ$87) -> 664979.44 | F17: =SUMIF(Monthly!$C$5:$BJ$5,F$14,Monthly!$C$87:$BJ$87) -> 933237.98
A18: Discount factor | B18: =1/(1+Inputs!$E$76)^B$14 -> 0.86206897 | C18: =1/(1+Inputs!$E$76)^C$14 -> 0.7431629 | D18: =1/(1+Inputs!$E$76)^D$14 -> 0.64065767 | E18: =1/(1+Inputs!$E$76)^E$14 -> 0.5522911 | F18: =1/(1+Inputs!$E$76)^F$14 -> 0.47611302
A19: Present value of free cash flow | B19: =B17*B18 -> -402685.72 | C19: =C17*C18 -> 154165.68 | D19: =D17*D18 -> 271808.05 | E19: =E17*E18 -> 367262.22 | F19: =F17*F18 -> 444326.75
A21: Enterprise value
B22: Perpetual growth | C22: Exit multiple
A23: Present value of the plan's free cash flows | B23: =SUM($B$19:$F$19) -> 834876.98 | C23: =B23 -> 834876.98
A24: Final-year free cash flow | final-year EBITDA | B24: =$F$17 -> 933237.98 | C24: =$F$16 -> 1585116.7
A25: Terminal value at the end of year 5 | B25: =IF($B$6>$B$7,B24*(1+$B$7)/($B$6-$B$7),0) -> 6799305.3 | C25: =C24*$B$8 -> 8718141.7
A26: Present value of the terminal value | B26: =B25/(1+$B$6)^$F$14 -> 3237237.8 | C26: =C25/(1+$B$6)^$F$14 -> 4150820.7
A27: Enterprise value | B27: =B23+B26 -> 4072114.7 | C27: =C23+C26 -> 4985697.7
A28: Terminal value share of enterprise value | B28: =IF(B27<>0,B26/B27,0) -> 0.79497705 | C28: =IF(C27<>0,C26/C27,0) -> 0.83254561
A29: Cross-check: implied exit multiple | implied perpetual growth | B29: =IF(C24>0,B25/C24,"n/a") -> 4.2894668 | C29: =IF(C25+B24<>0,(C25*$B$6-B24)/(C25+B24),"n/a") -> 0.047834061
A30: Enterprise value — average of the two methods | B30: =AVERAGE(B27,C27) -> 4528906.2
A32: Sensitivity: enterprise value (perpetual growth) by WACC and terminal growth
A33: WACC ↓ · terminal growth → | B33: =$B$7+(-2)*$B$11 -> 0.01 | C33: =$B$7+(-1)*$B$11 -> 0.015 | D33: =$B$7+(0)*$B$11 -> 0.02 | E33: =$B$7+(1)*$B$11 -> 0.025 | F33: =$B$7+(2)*$B$11 -> 0.03
A34: =$B$6+(-2)*$B$10 -> 0.14 | B34: =IF($A34>B$33,SUMPRODUCT($B$17:$F$17/(1+$A34)^$B$14:$F$14)+$F$17*(1+B$33)/($A34-B$33)/(1+$A34)^$F$14,"n/a") -> 4680358 | C34: =IF($A34>C$33,SUMPRODUCT($B$17:$F$17/(1+$A34)^$B$14:$F$14)+$F$17*(1+C$33)/($A34-C$33)/(1+$A34)^$F$14,"n/a") -> 4850373.9 | D34: =IF($A34>D$33,SUMPRODUCT($B$17:$F$17/(1+$A34)^$B$14:$F$14)+$F$17*(1+D$33)/($A34-D$33)/(1+$A34)^$F$14,"n/a") -> 5034557.8 | E34: =IF($A34>E$33,SUMPRODUCT($B$17:$F$17/(1+$A34)^$B$14:$F$14)+$F$17*(1+E$33)/($A34-E$33)/(1+$A34)^$F$14,"n/a") -> 5234757.8 | F34: =IF($A34>F$33,SUMPRODUCT($B$17:$F$17/(1+$A34)^$B$14:$F$14)+$F$17*(1+F$33)/($A34-F$33)/(1+$A34)^$F$14,"n/a") -> 5453157.7
A35: =$B$6+(-1)*$B$10 -> 0.15 | B35: =IF($A35>B$33,SUMPRODUCT($B$17:$F$17/(1+$A35)^$B$14:$F$14)+$F$17*(1+B$33)/($A35-B$33)/(1+$A35)^$F$14,"n/a") -> 4221134.7 | C35: =IF($A35>C$33,SUMPRODUCT($B$17:$F$17/(1+$A35)^$B$14:$F$14)+$F$17*(1+C$33)/($A35-C$33)/(1+$A35)^$F$14,"n/a") -> 4362293.9 | D35: =IF($A35>D$33,SUMPRODUCT($B$17:$F$17/(1+$A35)^$B$14:$F$14)+$F$17*(1+D$33)/($A35-D$33)/(1+$A35)^$F$14,"n/a") -> 4514311.6 | E35: =IF($A35>E$33,SUMPRODUCT($B$17:$F$17/(1+$A35)^$B$14:$F$14)+$F$17*(1+E$33)/($A35-E$33)/(1+$A35)^$F$14,"n/a") -> 4678490.6 | F35: =IF($A35>F$33,SUMPRODUCT($B$17:$F$17/(1+$A35)^$B$14:$F$14)+$F$17*(1+F$33)/($A35-F$33)/(1+$A35)^$F$14,"n/a") -> 4856351.2
A36: =$B$6+(0)*$B$10 -> 0.16 | B36: =IF($A36>B$33,SUMPRODUCT($B$17:$F$17/(1+$A36)^$B$14:$F$14)+$F$17*(1+B$33)/($A36-B$33)/(1+$A36)^$F$14,"n/a") -> 3826677.1 | C36: =IF($A36>C$33,SUMPRODUCT($B$17:$F$17/(1+$A36)^$B$14:$F$14)+$F$17*(1+C$33)/($A36-C$33)/(1+$A36)^$F$14,"n/a") -> 3945164.2 | D36: =IF($A36>D$33,SUMPRODUCT($B$17:$F$17/(1+$A36)^$B$14:$F$14)+$F$17*(1+D$33)/($A36-D$33)/(1+$A36)^$F$14,"n/a") -> 4072114.7 | E36: =IF($A36>E$33,SUMPRODUCT($B$17:$F$17/(1+$A36)^$B$14:$F$14)+$F$17*(1+E$33)/($A36-E$33)/(1+$A36)^$F$14,"n/a") -> 4208469 | F36: =IF($A36>F$33,SUMPRODUCT($B$17:$F$17/(1+$A36)^$B$14:$F$14)+$F$17*(1+F$33)/($A36-F$33)/(1+$A36)^$F$14,"n/a") -> 4355312
