Workbook

Sheet Cover
B2: SaaS financial model (early)
B3: 5-year financial model · monthly detail · Low / Base / High scenarios · US dollars · Full plan
B5: Purpose | D5: Revenue and profit plan
B6: Active scenario | D6: =Dashboard!C4&" (change it on the Dashboard, cell B4)" -> Base (change it on the Dashboard, cell B4)
B7: Model checks | D7: =Checks!B25 -> PASS WITH WARNINGS
B8: Prepared | D8: 21 October 2026
B10: Contents
C11: PRESENTATION
B12: 1 | C12: =HYPERLINK("#Dashboard!A1","Dashboard") -> Dashboard | D12: Scenario switch, key numbers, core financials
B13: 2 | C13: =HYPERLINK("#Summary!A1","Summary") -> Summary | D13: Income statement, cash flow and balance sheet — every year and any year by month
B14: 3 | C14: =HYPERLINK("#Scenarios!A1","Scenarios") -> Scenarios | D14: Low / Base / High side by side: drivers, outputs, charts
B15: 4 | C15: =HYPERLINK("#'Break-even'!A1","Break-even") -> Break-even | D15: Startup costs, funding need, break-even timing and revenue
B16: 5 | C16: =HYPERLINK("#Valuation!A1","Valuation") -> Valuation | D16: Free cash flow, DCF (perpetual growth and exit multiple), WACC × growth sensitivity
B17: 6 | C17: =HYPERLINK("#'Sources & Uses'!A1","Sources & Uses") -> Sources & Uses | D17: Funding structure, sources and uses of cash for the first months
B18: 7 | C18: =HYPERLINK("#KPIs!A1","KPIs") -> KPIs | D18: Financial ratios, DuPont analysis, industry metrics
C19: INPUTS
B20: 8 | C20: =HYPERLINK("#Inputs!A1","Inputs") -> Inputs | D20: Every assumption, Low / Base / High, with units and comments
C21: STATEMENTS
B22: 9 | C22: =HYPERLINK("#'P&L'!A1","P&L") -> P&L | D22: Annual profit & loss
B23: 10 | C23: =HYPERLINK("#'Cash Flow'!A1","Cash Flow") -> Cash Flow | D23: Annual cash flow statement
B24: 11 | C24: =HYPERLINK("#'Balance Sheet'!A1","Balance Sheet") -> Balance Sheet | D24: Balance sheet at year end
C25: CALCULATIONS
B26: 12 | C26: =HYPERLINK("#Monthly!A1","Monthly") -> Monthly | D26: Month-by-month engine of the model
B27: 13 | C27: =HYPERLINK("#Headcount!A1","Headcount") -> Headcount | D27: Team and payroll
B28: 14 | C28: =HYPERLINK("#'Scenario calc'!A1","Scenario calc") -> Scenario calc | D28: Low, Base and High calculated side by side for the Scenarios sheet
C29: CONTROL
B30: 15 | C30: =HYPERLINK("#Checks!A1","Checks") -> Checks | D30: Live integrity checks and the overall verdict
B32: How to read this file
C33: 1000 | D33: Input you can change — yellow cell with a blue figure (Inputs sheet and the view switches)
C34: 1000 | D34: Formula — calculated, do not overwrite
C35: 1000 | D35: Link to another sheet
C36: 1000 | D36: Active value the model uses (follows the scenario)

Sheet Dashboard
A1: Dashboard | W1: =HYPERLINK("#'Cover'!A1","◂ Contents") -> ◂ Contents
A2: SaaS financial model (early)
A4: Active scenario | B4: 2 | C4: =CHOOSE(B4,"Low","Base","High") -> Base | D4: 1 = Low · 2 = Base · 3 = High — every sheet follows this cell | S4: Model checks | T4: =Checks!B25 -> PASS WITH WARNINGS
A6: REVENUE · YEAR 5 | C6: EBITDA MARGIN · YEAR 5 | H6: NET INCOME · YEAR 5 | L6: LOWEST CASH BALANCE | P6: FUNDING REQUIRED | T6: ENTERPRISE VALUE (DCF)
A7: =F12 -> 1939020.9 | C7: =F17 -> -1.5391458 | H7: =F18 -> -2984436 | L7: =F38 -> -4291369.5 | P7: =F36 -> 7516369.5 | T7: =F43 -> -9830787.7
A8: =IF(AND(B12>0,F12>=0),(F12/B12)^(1/4)-1,"CAGR n/a") -> 0.71257638 | C8: =F16 -> -2984436 | H8: =F19 -> -1.5391458 | L8: ='Break-even'!B6 -> 60 | P8: =IF(F37>=0,"Covered by funding raised",-F37) -> 4516369.5 | T8: Average of 2 methods
A10: Core financials ($'000) — active scenario
B11: 1 | C11: 2 | D11: 3 | E11: 4 | F11: 5
A12: Revenue | B12: =SUMIF(Monthly!$C$5:$BJ$5,B$11,Monthly!$C$24:$BJ$24) -> 225414.94 | C12: =SUMIF(Monthly!$C$5:$BJ$5,C$11,Monthly!$C$24:$BJ$24) -> 591123.33 | D12: =SUMIF(Monthly!$C$5:$BJ$5,D$11,Monthly!$C$24:$BJ$24) -> 979388.56 | E12: =SUMIF(Monthly!$C$5:$BJ$5,E$11,Monthly!$C$24:$BJ$24) -> 1418382.1 | F12: =SUMIF(Monthly!$C$5:$BJ$5,F$11,Monthly!$C$24:$BJ$24) -> 1939020.9
A13: Gross profit | B13: =SUMIF(Monthly!$C$5:$BJ$5,B$11,Monthly!$C$26:$BJ$26) -> 198403.52 | C13: =SUMIF(Monthly!$C$5:$BJ$5,C$11,Monthly!$C$26:$BJ$26) -> 520687.04 | D13: =SUMIF(Monthly!$C$5:$BJ$5,D$11,Monthly!$C$26:$BJ$26) -> 863384.95 | E13: =SUMIF(Monthly!$C$5:$BJ$5,E$11,Monthly!$C$26:$BJ$26) -> 1251317.7 | F13: =SUMIF(Monthly!$C$5:$BJ$5,F$11,Monthly!$C$26:$BJ$26) -> 1711809.6
A14: Gross margin | B14: =IF(B12=0,0,B13/B12) -> 0.88017025 | C14: =IF(C12=0,0,C13/C12) -> 0.88084332 | D14: =IF(D12=0,0,D13/D12) -> 0.88155507 | E14: =IF(E12=0,0,E13/E12) -> 0.88221481 | F14: =IF(F12=0,0,F13/F12) -> 0.88282162
A15: Operating expenses | B15: =SUMIF(Monthly!$C$5:$BJ$5,B$11,Monthly!$C$34:$BJ$34) -> -901800 | C15: =SUMIF(Monthly!$C$5:$BJ$5,C$11,Monthly!$C$34:$BJ$34) -> -1341360 | D15: =SUMIF(Monthly!$C$5:$BJ$5,D$11,Monthly!$C$34:$BJ$34) -> -2019837.6 | E15: =SUMIF(Monthly!$C$5:$BJ$5,E$11,Monthly!$C$34:$BJ$34) -> -3069482.3 | F15: =SUMIF(Monthly!$C$5:$BJ$5,F$11,Monthly!$C$34:$BJ$34) -> -4696245.6
A16: EBITDA | B16: =SUMIF(Monthly!$C$5:$BJ$5,B$11,Monthly!$C$35:$BJ$35) -> -703396.48 | C16: =SUMIF(Monthly!$C$5:$BJ$5,C$11,Monthly!$C$35:$BJ$35) -> -820672.96 | D16: =SUMIF(Monthly!$C$5:$BJ$5,D$11,Monthly!$C$35:$BJ$35) -> -1156452.6 | E16: =SUMIF(Monthly!$C$5:$BJ$5,E$11,Monthly!$C$35:$BJ$35) -> -1818164.6 | F16: =SUMIF(Monthly!$C$5:$BJ$5,F$11,Monthly!$C$35:$BJ$35) -> -2984436
A17: EBITDA margin | B17: =IF(B12=0,0,B16/B12) -> -3.1204519 | C17: =IF(C12=0,0,C16/C12) -> -1.3883278 | D17: =IF(D12=0,0,D16/D12) -> -1.1807904 | E17: =IF(E12=0,0,E16/E12) -> -1.2818581 | F17: =IF(F12=0,0,F16/F12) -> -1.5391458
A18: Net income | B18: =SUMIF(Monthly!$C$5:$BJ$5,B$11,Monthly!$C$44:$BJ$44) -> -710063.14 | C18: =SUMIF(Monthly!$C$5:$BJ$5,C$11,Monthly!$C$44:$BJ$44) -> -827339.63 | D18: =SUMIF(Monthly!$C$5:$BJ$5,D$11,Monthly!$C$44:$BJ$44) -> -1163119.3 | E18: =SUMIF(Monthly!$C$5:$BJ$5,E$11,Monthly!$C$44:$BJ$44) -> -1818164.6 | F18: =SUMIF(Monthly!$C$5:$BJ$5,F$11,Monthly!$C$44:$BJ$44) -> -2984436
A19: Net margin | B19: =IF(B12=0,0,B18/B12) -> -3.150027 | C19: =IF(C12=0,0,C18/C12) -> -1.3996058 | D19: =IF(D12=0,0,D18/D12) -> -1.1875974 | E19: =IF(E12=0,0,E18/E12) -> -1.2818581 | F19: =IF(F12=0,0,F18/F12) -> -1.5391458
A20: Operating cash flow | B20: =SUMIF(Monthly!$C$5:$BJ$5,B$11,Monthly!$C$70:$BJ$70) -> -665196.51 | C20: =SUMIF(Monthly!$C$5:$BJ$5,C$11,Monthly!$C$70:$BJ$70) -> -785208.42 | D20: =SUMIF(Monthly!$C$5:$BJ$5,D$11,Monthly!$C$70:$BJ$70) -> -1117614.5 | E20: =SUMIF(Monthly!$C$5:$BJ$5,E$11,Monthly!$C$70:$BJ$70) -> -1773179.4 | F20: =SUMIF(Monthly!$C$5:$BJ$5,F$11,Monthly!$C$70:$BJ$70) -> -2930170.7
A21: Investing cash flow | B21: =SUMIF(Monthly!$C$5:$BJ$5,B$11,Monthly!$C$71:$BJ$71) -> -20000 | C21: =SUMIF(Monthly!$C$5:$BJ$5,C$11,Monthly!$C$71:$BJ$71) -> 0 | D21: =SUMIF(Monthly!$C$5:$BJ$5,D$11,Monthly!$C$71:$BJ$71) -> 0 | E21: =SUMIF(Monthly!$C$5:$BJ$5,E$11,Monthly!$C$71:$BJ$71) -> 0 | F21: =SUMIF(Monthly!$C$5:$BJ$5,F$11,Monthly!$C$71:$BJ$71) -> 0
A22: Financing cash flow | B22: =SUMIF(Monthly!$C$5:$BJ$5,B$11,Monthly!$C$73:$BJ$73) -> 3000000 | C22: =SUMIF(Monthly!$C$5:$BJ$5,C$11,Monthly!$C$73:$BJ$73) -> 0 | D22: =SUMIF(Monthly!$C$5:$BJ$5,D$11,Monthly!$C$73:$BJ$73) -> 0 | E22: =SUMIF(Monthly!$C$5:$BJ$5,E$11,Monthly!$C$73:$BJ$73) -> 0 | F22: =SUMIF(Monthly!$C$5:$BJ$5,F$11,Monthly!$C$73:$BJ$73) -> 0
A23: Net change in cash | B23: =SUMIF(Monthly!$C$5:$BJ$5,B$11,Monthly!$C$74:$BJ$74) -> 2314803.5 | C23: =SUMIF(Monthly!$C$5:$BJ$5,C$11,Monthly!$C$74:$BJ$74) -> -785208.42 | D23: =SUMIF(Monthly!$C$5:$BJ$5,D$11,Monthly!$C$74:$BJ$74) -> -1117614.5 | E23: =SUMIF(Monthly!$C$5:$BJ$5,E$11,Monthly!$C$74:$BJ$74) -> -1773179.4 | F23: =SUMIF(Monthly!$C$5:$BJ$5,F$11,Monthly!$C$74:$BJ$74) -> -2930170.7
A24: Year-end cash | B24: =INDEX(Monthly!$C$76:$BJ$76,B$11*12) -> 2314803.5 | C24: =INDEX(Monthly!$C$76:$BJ$76,C$11*12) -> 1529595.1 | D24: =INDEX(Monthly!$C$76:$BJ$76,D$11*12) -> 411980.55 | E24: =INDEX(Monthly!$C$76:$BJ$76,E$11*12) -> -1361198.8 | F24: =INDEX(Monthly!$C$76:$BJ$76,F$11*12) -> -4291369.5
A26: SaaS metrics
B27: 1 | C27: 2 | D27: 3 | E27: 4 | F27: 5
A28: Paying customers (year end) | B28: =KPIs!B29 -> 324.70508 | C28: =KPIs!C29 -> 602.20821 | D28: =KPIs!D29 -> 886.05465 | E28: =KPIs!E29 -> 1197.339 | F28: =KPIs!F29 -> 1556.7378
A29: ARR (year-end MRR × 12) | B29: =KPIs!B33 -> 397045.08 | C29: =KPIs!C33 -> 766645.33 | D29: =KPIs!D33 -> 1171790.9 | E29: =KPIs!E33 -> 1641396.1 | F29: =KPIs!F33 -> 2208189.2
A30: LTV ÷ CAC | B30: =KPIs!B42 -> 11.128003 | C30: =KPIs!C42 -> 11.983709 | D30: =KPIs!D42 -> 12.897559 | E30: =KPIs!E42 -> 13.87231 | F30: =KPIs!F42 -> 14.916711
A31: Team (FTE, year end) | B31: =INDEX(Headcount!$C$12:$BJ$12,B$27*12) -> 6 | C31: =INDEX(Headcount!$C$12:$BJ$12,C$27*12) -> 9 | D31: =INDEX(Headcount!$C$12:$BJ$12,D$27*12) -> 13.5 | E31: =INDEX(Headcount!$C$12:$BJ$12,E$27*12) -> 20.25 | F31: =INDEX(Headcount!$C$12:$BJ$12,F$27*12) -> 30.375
A33: Funding & valuation ($'000) — active scenario
A34: Equity raised | F34: =Inputs!$E$46 -> 3000000
A35: Loan drawn | F35: =Inputs!$E$47 -> 0
A36: Funding required (incl. cash buffer) | F36: ='Break-even'!B12 -> 7516369.5
A37: Funding surplus / (shortfall) | F37: ='Break-even'!B17 -> -4516369.5
A38: ="Lowest cash balance (month "&'Break-even'!B6&")" -> Lowest cash balance (month 60) | F38: ='Break-even'!B18 -> -4291369.5
A39: First month with positive EBITDA | F39: ='Break-even'!B21 -> Not within horizon
A40: Cash invested paid back | F40: ='Break-even'!B23 -> Not within horizon
A41: Enterprise value — perpetual growth | F41: =Valuation!B27 -> -10468635
A42: Enterprise value — exit multiple | F42: =Valuation!C27 -> -9192940.1
A43: Enterprise value — average | F43: =Valuation!B30 -> -9830787.7

Sheet Summary
A1: Financial statements summary | U1: =HYPERLINK("#'Cover'!A1","◂ Contents") -> ◂ Contents
A2: SaaS financial model (early) | P2: Select detailed year: | R2: 1
A5: Income statement ($'000) — by year | H5: ="Income statement ($'000) — Year "&$R$2&", by month" -> Income statement ($'000) — Year 1, by month
B6: 1 | C6: 2 | D6: 3 | E6: 4 | F6: 5 | H6: =INDEX(Monthly!$C$4:$BJ$4,($R$2-1)*12+1) -> 1 | I6: =INDEX(Monthly!$C$4:$BJ$4,($R$2-1)*12+2) -> 2 | J6: =INDEX(Monthly!$C$4:$BJ$4,($R$2-1)*12+3) -> 3 | K6: =INDEX(Monthly!$C$4:$BJ$4,($R$2-1)*12+4) -> 4 | L6: =INDEX(Monthly!$C$4:$BJ$4,($R$2-1)*12+5) -> 5 | M6: =INDEX(Monthly!$C$4:$BJ$4,($R$2-1)*12+6) -> 6 | N6: =INDEX(Monthly!$C$4:$BJ$4,($R$2-1)*12+7) -> 7 | O6: =INDEX(Monthly!$C$4:$BJ$4,($R$2-1)*12+8) -> 8 | P6: =INDEX(Monthly!$C$4:$BJ$4,($R$2-1)*12+9) -> 9 | Q6: =INDEX(Monthly!$C$4:$BJ$4,($R$2-1)*12+10) -> 10 | R6: =INDEX(Monthly!$C$4:$BJ$4,($R$2-1)*12+11) -> 11 | S6: =INDEX(Monthly!$C$4:$BJ$4,($R$2-1)*12+12) -> 12
A7: Revenue | B7: ='P&L'!B5 -> 225414.94 | C7: ='P&L'!C5 -> 591123.33 | D7: ='P&L'!D5 -> 979388.56 | E7: ='P&L'!E5 -> 1418382.1 | F7: ='P&L'!F5 -> 1939020.9 | H7: =INDEX(Monthly!$C$24:$BJ$24,($R$2-1)*12+1) -> 4406.875 | I7: =INDEX(Monthly!$C$24:$BJ$24,($R$2-1)*12+2) -> 7244.7031 | J7: =INDEX(Monthly!$C$24:$BJ$24,($R$2-1)*12+3) -> 10011.586 | K7: =INDEX(Monthly!$C$24:$BJ$24,($R$2-1)*12+4) -> 12709.296 | L7: =INDEX(Monthly!$C$24:$BJ$24,($R$2-1)*12+5) -> 15339.564 | M7: =INDEX(Monthly!$C$24:$BJ$24,($R$2-1)*12+6) -> 17904.074 | N7: =INDEX(Monthly!$C$24:$BJ$24,($R$2-1)*12+7) -> 20404.473 | O7: =INDEX(Monthly!$C$24:$BJ$24,($R$2-1)*12+8) -> 22842.361 | P7: =INDEX(Monthly!$C$24:$BJ$24,($R$2-1)*12+9) -> 25219.302 | Q7: =INDEX(Monthly!$C$24:$BJ$24,($R$2-1)*12+10) -> 27536.819 | R7: =INDEX(Monthly!$C$24:$BJ$24,($R$2-1)*12+11) -> 29796.399 | S7: =INDEX(Monthly!$C$24:$BJ$24,($R$2-1)*12+12) -> 31999.489
A8: Hosting, payment fees & support | B8: ='P&L'!B6 -> -27011.416 | C8: ='P&L'!C6 -> -70436.294 | D8: ='P&L'!D6 -> -116003.61 | E8: ='P&L'!E6 -> -167064.4 | F8: ='P&L'!F6 -> -227211.34 | H8: =INDEX(Monthly!$C$25:$BJ$25,($R$2-1)*12+1) -> -529.56528 | I8: =INDEX(Monthly!$C$25:$BJ$25,($R$2-1)*12+2) -> -870.23731 | J8: =INDEX(Monthly!$C$25:$BJ$25,($R$2-1)*12+3) -> -1202.1081 | K8: =INDEX(Monthly!$C$25:$BJ$25,($R$2-1)*12+4) -> -1525.4062 | L8: =INDEX(Monthly!$C$25:$BJ$25,($R$2-1)*12+5) -> -1840.3542 | M8: =INDEX(Monthly!$C$25:$BJ$25,($R$2-1)*12+6) -> -2147.1689 | N8: =INDEX(Monthly!$C$25:$BJ$25,($R$2-1)*12+7) -> -2446.0615 | O8: =INDEX(Monthly!$C$25:$BJ$25,($R$2-1)*12+8) -> -2737.2374 | P8: =INDEX(Monthly!$C$25:$BJ$25,($R$2-1)*12+9) -> -3020.897 | Q8: =INDEX(Monthly!$C$25:$BJ$25,($R$2-1)*12+10) -> -3297.2353 | R8: =INDEX(Monthly!$C$25:$BJ$25,($R$2-1)*12+11) -> -3566.4422 | S8: =INDEX(Monthly!$C$25:$BJ$25,($R$2-1)*12+12) -> -3828.7027
A9: Gross profit | B9: ='P&L'!B7 -> 198403.52 | C9: ='P&L'!C7 -> 520687.04 | D9: ='P&L'!D7 -> 863384.95 | E9: ='P&L'!E7 -> 1251317.7 | F9: ='P&L'!F7 -> 1711809.6 | H9: =INDEX(Monthly!$C$26:$BJ$26,($R$2-1)*12+1) -> 3877.3097 | I9: =INDEX(Monthly!$C$26:$BJ$26,($R$2-1)*12+2) -> 6374.4658 | J9: =INDEX(Monthly!$C$26:$BJ$26,($R$2-1)*12+3) -> 8809.4774 | K9: =INDEX(Monthly!$C$26:$BJ$26,($R$2-1)*12+4) -> 11183.89 | L9: =INDEX(Monthly!$C$26:$BJ$26,($R$2-1)*12+5) -> 13499.209 | M9: =INDEX(Monthly!$C$26:$BJ$26,($R$2-1)*12+6) -> 15756.905 | N9: =INDEX(Monthly!$C$26:$BJ$26,($R$2-1)*12+7) -> 17958.411 | O9: =INDEX(Monthly!$C$26:$BJ$26,($R$2-1)*12+8) -> 20105.123 | P9: =INDEX(Monthly!$C$26:$BJ$26,($R$2-1)*12+9) -> 22198.405 | Q9: =INDEX(Monthly!$C$26:$BJ$26,($R$2-1)*12+10) -> 24239.584 | R9: =INDEX(Monthly!$C$26:$BJ$26,($R$2-1)*12+11) -> 26229.956 | S9: =INDEX(Monthly!$C$26:$BJ$26,($R$2-1)*12+12) -> 28170.786
A10: Gross margin | B10: ='P&L'!B8 -> 0.88017025 | C10: ='P&L'!C8 -> 0.88084332 | D10: ='P&L'!D8 -> 0.88155507 | E10: ='P&L'!E8 -> 0.88221481 | F10: ='P&L'!F8 -> 0.88282162 | H10: =IF(H7=0,0,H9/H7) -> 0.87983202 | I10: =IF(I7=0,0,I9/I7) -> 0.87987951 | J10: =IF(J7=0,0,J9/J7) -> 0.8799283 | K10: =IF(K7=0,0,K9/K7) -> 0.87997713 | L10: =IF(L7=0,0,L9/L7) -> 0.88002565 | M10: =IF(M7=0,0,M9/M7) -> 0.88007373 | N10: =IF(N7=0,0,N9/N7) -> 0.88012131 | O10: =IF(O7=0,0,O9/O7) -> 0.88016837 | ... S10: =IF(S7=0,0,S9/S7) -> 0.88035113
A11: Total operating expenses | B11: ='P&L'!B14 -> -901800 | C11: ='P&L'!C14 -> -1341360 | D11: ='P&L'!D14 -> -2019837.6 | E11: ='P&L'!E14 -> -3069482.3 | F11: ='P&L'!F14 -> -4696245.6 | H11: =INDEX(Monthly!$C$34:$BJ$34,($R$2-1)*12+1) -> -75150 | I11: =INDEX(Monthly!$C$34:$BJ$34,($R$2-1)*12+2) -> -75150 | J11: =INDEX(Monthly!$C$34:$BJ$34,($R$2-1)*12+3) -> -75150 | K11: =INDEX(Monthly!$C$34:$BJ$34,($R$2-1)*12+4) -> -75150 | L11: =INDEX(Monthly!$C$34:$BJ$34,($R$2-1)*12+5) -> -75150 | M11: =INDEX(Monthly!$C$34:$BJ$34,($R$2-1)*12+6) -> -75150 | N11: =INDEX(Monthly!$C$34:$BJ$34,($R$2-1)*12+7) -> -75150 | O11: =INDEX(Monthly!$C$34:$BJ$34,($R$2-1)*12+8) -> -75150 | P11: =INDEX(Monthly!$C$34:$BJ$34,($R$2-1)*12+9) -> -75150 | Q11: =INDEX(Monthly!$C$34:$BJ$34,($R$2-1)*12+10) -> -75150 | R11: =INDEX(Monthly!$C$34:$BJ$34,($R$2-1)*12+11) -> -75150 | S11: =INDEX(Monthly!$C$34:$BJ$34,($R$2-1)*12+12) -> -75150
A12: EBITDA | B12: ='P&L'!B15 -> -703396.48 | C12: ='P&L'!C15 -> -820672.96 | D12: ='P&L'!D15 -> -1156452.6 | E12: ='P&L'!E15 -> -1818164.6 | F12: ='P&L'!F15 -> -2984436 | H12: =INDEX(Monthly!$C$35:$BJ$35,($R$2-1)*12+1) -> -71272.69 | I12: =INDEX(Monthly!$C$35:$BJ$35,($R$2-1)*12+2) -> -68775.534 | J12: =INDEX(Monthly!$C$35:$BJ$35,($R$2-1)*12+3) -> -66340.523 | K12: =INDEX(Monthly!$C$35:$BJ$35,($R$2-1)*12+4) -> -63966.11 | L12: =INDEX(Monthly!$C$35:$BJ$35,($R$2-1)*12+5) -> -61650.791 | M12: =INDEX(Monthly!$C$35:$BJ$35,($R$2-1)*12+6) -> -59393.095 | N12: =INDEX(Monthly!$C$35:$BJ$35,($R$2-1)*12+7) -> -57191.589 | O12: =INDEX(Monthly!$C$35:$BJ$35,($R$2-1)*12+8) -> -55044.877 | P12: =INDEX(Monthly!$C$35:$BJ$35,($R$2-1)*12+9) -> -52951.595 | Q12: =INDEX(Monthly!$C$35:$BJ$35,($R$2-1)*12+10) -> -50910.416 | R12: =INDEX(Monthly!$C$35:$BJ$35,($R$2-1)*12+11) -> -48920.044 | S12: =INDEX(Monthly!$C$35:$BJ$35,($R$2-1)*12+12) -> -46979.214
A13: EBITDA margin | B13: ='P&L'!B16 -> -3.1204519 | C13: ='P&L'!C16 -> -1.3883278 | D13: ='P&L'!D16 -> -1.1807904 | E13: ='P&L'!E16 -> -1.2818581 | F13: ='P&L'!F16 -> -1.5391458 | H13: =IF(H7=0,0,H12/H7) -> -16.173068 | I13: =IF(I7=0,0,I12/I7) -> -9.4932164 | J13: =IF(J7=0,0,J12/J7) -> -6.6263752 | K13: =IF(K7=0,0,K12/K7) -> -5.0330176 | L13: =IF(L7=0,0,L12/L7) -> -4.0190707 | M13: =IF(M7=0,0,M12/M7) -> -3.3172949 | N13: =IF(N7=0,0,N12/N7) -> -2.8028947 | O13: =IF(O7=0,0,O12/O7) -> -2.4097718 | ... S13: =IF(S7=0,0,S12/S7) -> -1.4681239
A14: Depreciation | B14: ='P&L'!B17 -> -6666.6667 | C14: ='P&L'!C17 -> -6666.6667 | D14: ='P&L'!D17 -> -6666.6667 | E14: ='P&L'!E17 -> 0 | F14: ='P&L'!F17 -> 0 | H14: =INDEX(Monthly!$C$49:$BJ$49,($R$2-1)*12+1) -> -555.55556 | I14: =INDEX(Monthly!$C$49:$BJ$49,($R$2-1)*12+2) -> -555.55556 | J14: =INDEX(Monthly!$C$49:$BJ$49,($R$2-1)*12+3) -> -555.55556 | K14: =INDEX(Monthly!$C$49:$BJ$49,($R$2-1)*12+4) -> -555.55556 | L14: =INDEX(Monthly!$C$49:$BJ$49,($R$2-1)*12+5) -> -555.55556 | M14: =INDEX(Monthly!$C$49:$BJ$49,($R$2-1)*12+6) -> -555.55556 | N14: =INDEX(Monthly!$C$49:$BJ$49,($R$2-1)*12+7) -> -555.55556 | O14: =INDEX(Monthly!$C$49:$BJ$49,($R$2-1)*12+8) -> -555.55556 | P14: =INDEX(Monthly!$C$49:$BJ$49,($R$2-1)*12+9) -> -555.55556 | Q14: =INDEX(Monthly!$C$49:$BJ$49,($R$2-1)*12+10) -> -555.55556 | R14: =INDEX(Monthly!$C$49:$BJ$49,($R$2-1)*12+11) -> -555.55556 | S14: =INDEX(Monthly!$C$49:$BJ$49,($R$2-1)*12+12) -> -555.55556
A15: EBIT | B15: ='P&L'!B18 -> -710063.14 | C15: ='P&L'!C18 -> -827339.63 | D15: ='P&L'!D18 -> -1163119.3 | E15: ='P&L'!E18 -> -1818164.6 | F15: ='P&L'!F18 -> -2984436 | H15: =INDEX(Monthly!$C$38:$BJ$38,($R$2-1)*12+1) -> -71828.246 | I15: =INDEX(Monthly!$C$38:$BJ$38,($R$2-1)*12+2) -> -69331.09 | J15: =INDEX(Monthly!$C$38:$BJ$38,($R$2-1)*12+3) -> -66896.078 | K15: =INDEX(Monthly!$C$38:$BJ$38,($R$2-1)*12+4) -> -64521.666 | L15: =INDEX(Monthly!$C$38:$BJ$38,($R$2-1)*12+5) -> -62206.346 | M15: =INDEX(Monthly!$C$38:$BJ$38,($R$2-1)*12+6) -> -59948.65 | N15: =INDEX(Monthly!$C$38:$BJ$38,($R$2-1)*12+7) -> -57747.144 | O15: =INDEX(Monthly!$C$38:$BJ$38,($R$2-1)*12+8) -> -55600.432 | P15: =INDEX(Monthly!$C$38:$BJ$38,($R$2-1)*12+9) -> -53507.151 | Q15: =INDEX(Monthly!$C$38:$BJ$38,($R$2-1)*12+10) -> -51465.972 | R15: =INDEX(Monthly!$C$38:$BJ$38,($R$2-1)*12+11) -> -49475.599 | S15: =INDEX(Monthly!$C$38:$BJ$38,($R$2-1)*12+12) -> -47534.77
A16: Interest | B16: ='P&L'!B19 -> 0 | C16: ='P&L'!C19 -> 0 | D16: ='P&L'!D19 -> 0 | E16: ='P&L'!E19 -> 0 | F16: ='P&L'!F19 -> 0 | H16: =INDEX(Monthly!$C$39:$BJ$39,($R$2-1)*12+1) -> 0 | I16: =INDEX(Monthly!$C$39:$BJ$39,($R$2-1)*12+2) -> 0 | J16: =INDEX(Monthly!$C$39:$BJ$39,($R$2-1)*12+3) -> 0 | K16: =INDEX(Monthly!$C$39:$BJ$39,($R$2-1)*12+4) -> 0 | L16: =INDEX(Monthly!$C$39:$BJ$39,($R$2-1)*12+5) -> 0 | M16: =INDEX(Monthly!$C$39:$BJ$39,($R$2-1)*12+6) -> 0 | N16: =INDEX(Monthly!$C$39:$BJ$39,($R$2-1)*12+7) -> 0 | O16: =INDEX(Monthly!$C$39:$BJ$39,($R$2-1)*12+8) -> 0 | P16: =INDEX(Monthly!$C$39:$BJ$39,($R$2-1)*12+9) -> 0 | Q16: =INDEX(Monthly!$C$39:$BJ$39,($R$2-1)*12+10) -> 0 | R16: =INDEX(Monthly!$C$39:$BJ$39,($R$2-1)*12+11) -> 0 | S16: =INDEX(Monthly!$C$39:$BJ$39,($R$2-1)*12+12) -> 0
A17: Pre-tax income | B17: ='P&L'!B20 -> -710063.14 | C17: ='P&L'!C20 -> -827339.63 | D17: ='P&L'!D20 -> -1163119.3 | E17: ='P&L'!E20 -> -1818164.6 | F17: ='P&L'!F20 -> -2984436 | H17: =INDEX(Monthly!$C$40:$BJ$40,($R$2-1)*12+1) -> -71828.246 | I17: =INDEX(Monthly!$C$40:$BJ$40,($R$2-1)*12+2) -> -69331.09 | J17: =INDEX(Monthly!$C$40:$BJ$40,($R$2-1)*12+3) -> -66896.078 | K17: =INDEX(Monthly!$C$40:$BJ$40,($R$2-1)*12+4) -> -64521.666 | L17: =INDEX(Monthly!$C$40:$BJ$40,($R$2-1)*12+5) -> -62206.346 | M17: =INDEX(Monthly!$C$40:$BJ$40,($R$2-1)*12+6) -> -59948.65 | N17: =INDEX(Monthly!$C$40:$BJ$40,($R$2-1)*12+7) -> -57747.144 | O17: =INDEX(Monthly!$C$40:$BJ$40,($R$2-1)*12+8) -> -55600.432 | P17: =INDEX(Monthly!$C$40:$BJ$40,($R$2-1)*12+9) -> -53507.151 | Q17: =INDEX(Monthly!$C$40:$BJ$40,($R$2-1)*12+10) -> -51465.972 | R17: =INDEX(Monthly!$C$40:$BJ$40,($R$2-1)*12+11) -> -49475.599 | S17: =INDEX(Monthly!$C$40:$BJ$40,($R$2-1)*12+12) -> -47534.77
A18: Income tax | B18: ='P&L'!B21 -> 0 | C18: ='P&L'!C21 -> 0 | D18: ='P&L'!D21 -> 0 | E18: ='P&L'!E21 -> 0 | F18: ='P&L'!F21 -> 0 | H18: =INDEX(Monthly!$C$43:$BJ$43,($R$2-1)*12+1) -> 0 | I18: =INDEX(Monthly!$C$43:$BJ$43,($R$2-1)*12+2) -> 0 | J18: =INDEX(Monthly!$C$43:$BJ$43,($R$2-1)*12+3) -> 0 | K18: =INDEX(Monthly!$C$43:$BJ$43,($R$2-1)*12+4) -> 0 | L18: =INDEX(Monthly!$C$43:$BJ$43,($R$2-1)*12+5) -> 0 | M18: =INDEX(Monthly!$C$43:$BJ$43,($R$2-1)*12+6) -> 0 | N18: =INDEX(Monthly!$C$43:$BJ$43,($R$2-1)*12+7) -> 0 | O18: =INDEX(Monthly!$C$43:$BJ$43,($R$2-1)*12+8) -> 0 | P18: =INDEX(Monthly!$C$43:$BJ$43,($R$2-1)*12+9) -> 0 | Q18: =INDEX(Monthly!$C$43:$BJ$43,($R$2-1)*12+10) -> 0 | R18: =INDEX(Monthly!$C$43:$BJ$43,($R$2-1)*12+11) -> 0 | S18: =INDEX(Monthly!$C$43:$BJ$43,($R$2-1)*12+12) -> 0
A19: Net income | B19: ='P&L'!B22 -> -710063.14 | C19: ='P&L'!C22 -> -827339.63 | D19: ='P&L'!D22 -> -1163119.3 | E19: ='P&L'!E22 -> -1818164.6 | F19: ='P&L'!F22 -> -2984436 | H19: =INDEX(Monthly!$C$44:$BJ$44,($R$2-1)*12+1) -> -71828.246 | I19: =INDEX(Monthly!$C$44:$BJ$44,($R$2-1)*12+2) -> -69331.09 | J19: =INDEX(Monthly!$C$44:$BJ$44,($R$2-1)*12+3) -> -66896.078 | K19: =INDEX(Monthly!$C$44:$BJ$44,($R$2-1)*12+4) -> -64521.666 | L19: =INDEX(Monthly!$C$44:$BJ$44,($R$2-1)*12+5) -> -62206.346 | M19: =INDEX(Monthly!$C$44:$BJ$44,($R$2-1)*12+6) -> -59948.65 | N19: =INDEX(Monthly!$C$44:$BJ$44,($R$2-1)*12+7) -> -57747.144 | O19: =INDEX(Monthly!$C$44:$BJ$44,($R$2-1)*12+8) -> -55600.432 | P19: =INDEX(Monthly!$C$44:$BJ$44,($R$2-1)*12+9) -> -53507.151 | Q19: =INDEX(Monthly!$C$44:$BJ$44,($R$2-1)*12+10) -> -51465.972 | R19: =INDEX(Monthly!$C$44:$BJ$44,($R$2-1)*12+11) -> -49475.599 | S19: =INDEX(Monthly!$C$44:$BJ$44,($R$2-1)*12+12) -> -47534.77
A20: Net margin | B20: ='P&L'!B23 -> -3.150027 | C20: ='P&L'!C23 -> -1.3996058 | D20: ='P&L'!D23 -> -1.1875974 | E20: ='P&L'!E23 -> -1.2818581 | F20: ='P&L'!F23 -> -1.5391458 | H20: =IF(H7=0,0,H19/H7) -> -16.299134 | I20: =IF(I7=0,0,I19/I7) -> -9.5699007 | J20: =IF(J7=0,0,J19/J7) -> -6.6818665 | K20: =IF(K7=0,0,K19/K7) -> -5.0767302 | L20: =IF(L7=0,0,L19/L7) -> -4.0552879 | M20: =IF(M7=0,0,M19/M7) -> -3.3483244 | N20: =IF(N7=0,0,N19/N7) -> -2.8301219 | O20: =IF(O7=0,0,O19/O7) -> -2.4340931 | ... S20: =IF(S7=0,0,S19/S7) -> -1.4854853
A22: Cash flow ($'000) — by year | H22: ="Cash flow ($'000) — Year "&$R$2&", by month" -> Cash flow ($'000) — Year 1, by month
B23: 1 | C23: 2 | D23: 3 | E23: 4 | F23: 5 | H23: =INDEX(Monthly!$C$4:$BJ$4,($R$2-1)*12+1) -> 1 | I23: =INDEX(Monthly!$C$4:$BJ$4,($R$2-1)*12+2) -> 2 | J23: =INDEX(Monthly!$C$4:$BJ$4,($R$2-1)*12+3) -> 3 | K23: =INDEX(Monthly!$C$4:$BJ$4,($R$2-1)*12+4) -> 4 | L23: =INDEX(Monthly!$C$4:$BJ$4,($R$2-1)*12+5) -> 5 | M23: =INDEX(Monthly!$C$4:$BJ$4,($R$2-1)*12+6) -> 6 | N23: =INDEX(Monthly!$C$4:$BJ$4,($R$2-1)*12+7) -> 7 | O23: =INDEX(Monthly!$C$4:$BJ$4,($R$2-1)*12+8) -> 8 | P23: =INDEX(Monthly!$C$4:$BJ$4,($R$2-1)*12+9) -> 9 | Q23: =INDEX(Monthly!$C$4:$BJ$4,($R$2-1)*12+10) -> 10 | R23: =INDEX(Monthly!$C$4:$BJ$4,($R$2-1)*12+11) -> 11 | S23: =INDEX(Monthly!$C$4:$BJ$4,($R$2-1)*12+12) -> 12
A24: Operating cash flow | B24: ='Cash Flow'!B11 -> -665196.51 | C24: ='Cash Flow'!C11 -> -785208.42 | D24: ='Cash Flow'!D11 -> -1117614.5 | E24: ='Cash Flow'!E11 -> -1773179.4 | F24: ='Cash Flow'!F11 -> -2930170.7 | H24: =INDEX(Monthly!$C$70:$BJ$70,($R$2-1)*12+1) -> -64465.104 | I24: =INDEX(Monthly!$C$70:$BJ$70,($R$2-1)*12+2) -> -65545.546 | J24: =INDEX(Monthly!$C$70:$BJ$70,($R$2-1)*12+3) -> -63191.569 | K24: =INDEX(Monthly!$C$70:$BJ$70,($R$2-1)*12+4) -> -60896.156 | L24: =INDEX(Monthly!$C$70:$BJ$70,($R$2-1)*12+5) -> -58657.853 | M24: =INDEX(Monthly!$C$70:$BJ$70,($R$2-1)*12+6) -> -56475.24 | N24: =INDEX(Monthly!$C$70:$BJ$70,($R$2-1)*12+7) -> -54346.932 | O24: =INDEX(Monthly!$C$70:$BJ$70,($R$2-1)*12+8) -> -52271.581 | P24: =INDEX(Monthly!$C$70:$BJ$70,($R$2-1)*12+9) -> -50247.869 | Q24: =INDEX(Monthly!$C$70:$BJ$70,($R$2-1)*12+10) -> -48274.513 | R24: =INDEX(Monthly!$C$70:$BJ$70,($R$2-1)*12+11) -> -46350.26 | S24: =INDEX(Monthly!$C$70:$BJ$70,($R$2-1)*12+12) -> -44473.892
A25: Capital spending | B25: ='Cash Flow'!B12 -> -20000 | C25: ='Cash Flow'!C12 -> 0 | D25: ='Cash Flow'!D12 -> 0 | E25: ='Cash Flow'!E12 -> 0 | F25: ='Cash Flow'!F12 -> 0 | H25: =INDEX(Monthly!$C$71:$BJ$71,($R$2-1)*12+1) -> -20000 | I25: =INDEX(Monthly!$C$71:$BJ$71,($R$2-1)*12+2) -> 0 | J25: =INDEX(Monthly!$C$71:$BJ$71,($R$2-1)*12+3) -> 0 | K25: =INDEX(Monthly!$C$71:$BJ$71,($R$2-1)*12+4) -> 0 | L25: =INDEX(Monthly!$C$71:$BJ$71,($R$2-1)*12+5) -> 0 | M25: =INDEX(Monthly!$C$71:$BJ$71,($R$2-1)*12+6) -> 0 | N25: =INDEX(Monthly!$C$71:$BJ$71,($R$2-1)*12+7) -> 0 | O25: =INDEX(Monthly!$C$71:$BJ$71,($R$2-1)*12+8) -> 0 | P25: =INDEX(Monthly!$C$71:$BJ$71,($R$2-1)*12+9) -> 0 | Q25: =INDEX(Monthly!$C$71:$BJ$71,($R$2-1)*12+10) -> 0 | R25: =INDEX(Monthly!$C$71:$BJ$71,($R$2-1)*12+11) -> 0 | S25: =INDEX(Monthly!$C$71:$BJ$71,($R$2-1)*12+12) -> 0
A26: Equity raised | B26: ='Cash Flow'!B13 -> 3000000 | C26: ='Cash Flow'!C13 -> 0 | D26: ='Cash Flow'!D13 -> 0 | E26: ='Cash Flow'!E13 -> 0 | F26: ='Cash Flow'!F13 -> 0 | H26: =INDEX(Monthly!$C$72:$BJ$72,($R$2-1)*12+1) -> 3000000 | I26: =INDEX(Monthly!$C$72:$BJ$72,($R$2-1)*12+2) -> 0 | J26: =INDEX(Monthly!$C$72:$BJ$72,($R$2-1)*12+3) -> 0 | K26: =INDEX(Monthly!$C$72:$BJ$72,($R$2-1)*12+4) -> 0 | L26: =INDEX(Monthly!$C$72:$BJ$72,($R$2-1)*12+5) -> 0 | M26: =INDEX(Monthly!$C$72:$BJ$72,($R$2-1)*12+6) -> 0 | N26: =INDEX(Monthly!$C$72:$BJ$72,($R$2-1)*12+7) -> 0 | O26: =INDEX(Monthly!$C$72:$BJ$72,($R$2-1)*12+8) -> 0 | P26: =INDEX(Monthly!$C$72:$BJ$72,($R$2-1)*12+9) -> 0 | Q26: =INDEX(Monthly!$C$72:$BJ$72,($R$2-1)*12+10) -> 0 | R26: =INDEX(Monthly!$C$72:$BJ$72,($R$2-1)*12+11) -> 0 | S26: =INDEX(Monthly!$C$72:$BJ$72,($R$2-1)*12+12) -> 0
A27: Loan drawdown | B27: ='Cash Flow'!B14 -> 0 | C27: ='Cash Flow'!C14 -> 0 | D27: ='Cash Flow'!D14 -> 0 | E27: ='Cash Flow'!E14 -> 0 | F27: ='Cash Flow'!F14 -> 0 | H27: =INDEX(Monthly!$C$55:$BJ$55,($R$2-1)*12+1) -> 0 | I27: =INDEX(Monthly!$C$55:$BJ$55,($R$2-1)*12+2) -> 0 | J27: =INDEX(Monthly!$C$55:$BJ$55,($R$2-1)*12+3) -> 0 | K27: =INDEX(Monthly!$C$55:$BJ$55,($R$2-1)*12+4) -> 0 | L27: =INDEX(Monthly!$C$55:$BJ$55,($R$2-1)*12+5) -> 0 | M27: =INDEX(Monthly!$C$55:$BJ$55,($R$2-1)*12+6) -> 0 | N27: =INDEX(Monthly!$C$55:$BJ$55,($R$2-1)*12+7) -> 0 | O27: =INDEX(Monthly!$C$55:$BJ$55,($R$2-1)*12+8) -> 0 | P27: =INDEX(Monthly!$C$55:$BJ$55,($R$2-1)*12+9) -> 0 | Q27: =INDEX(Monthly!$C$55:$BJ$55,($R$2-1)*12+10) -> 0 | R27: =INDEX(Monthly!$C$55:$BJ$55,($R$2-1)*12+11) -> 0 | S27: =INDEX(Monthly!$C$55:$BJ$55,($R$2-1)*12+12) -> 0
A28: Loan repayment | B28: ='Cash Flow'!B15 -> 0 | C28: ='Cash Flow'!C15 -> 0 | D28: ='Cash Flow'!D15 -> 0 | E28: ='Cash Flow'!E15 -> 0 | F28: ='Cash Flow'!F15 -> 0 | H28: =INDEX(Monthly!$C$56:$BJ$56,($R$2-1)*12+1) -> 0 | I28: =INDEX(Monthly!$C$56:$BJ$56,($R$2-1)*12+2) -> 0 | J28: =INDEX(Monthly!$C$56:$BJ$56,($R$2-1)*12+3) -> 0 | K28: =INDEX(Monthly!$C$56:$BJ$56,($R$2-1)*12+4) -> 0 | L28: =INDEX(Monthly!$C$56:$BJ$56,($R$2-1)*12+5) -> 0 | M28: =INDEX(Monthly!$C$56:$BJ$56,($R$2-1)*12+6) -> 0 | N28: =INDEX(Monthly!$C$56:$BJ$56,($R$2-1)*12+7) -> 0 | O28: =INDEX(Monthly!$C$56:$BJ$56,($R$2-1)*12+8) -> 0 | P28: =INDEX(Monthly!$C$56:$BJ$56,($R$2-1)*12+9) -> 0 | Q28: =INDEX(Monthly!$C$56:$BJ$56,($R$2-1)*12+10) -> 0 | R28: =INDEX(Monthly!$C$56:$BJ$56,($R$2-1)*12+11) -> 0 | S28: =INDEX(Monthly!$C$56:$BJ$56,($R$2-1)*12+12) -> 0
A29: Financing cash flow | B29: ='Cash Flow'!B16 -> 3000000 | C29: ='Cash Flow'!C16 -> 0 | D29: ='Cash Flow'!D16 -> 0 | E29: ='Cash Flow'!E16 -> 0 | F29: ='Cash Flow'!F16 -> 0 | H29: =INDEX(Monthly!$C$73:$BJ$73,($R$2-1)*12+1) -> 3000000 | I29: =INDEX(Monthly!$C$73:$BJ$73,($R$2-1)*12+2) -> 0 | J29: =INDEX(Monthly!$C$73:$BJ$73,($R$2-1)*12+3) -> 0 | K29: =INDEX(Monthly!$C$73:$BJ$73,($R$2-1)*12+4) -> 0 | L29: =INDEX(Monthly!$C$73:$BJ$73,($R$2-1)*12+5) -> 0 | M29: =INDEX(Monthly!$C$73:$BJ$73,($R$2-1)*12+6) -> 0 | N29: =INDEX(Monthly!$C$73:$BJ$73,($R$2-1)*12+7) -> 0 | O29: =INDEX(Monthly!$C$73:$BJ$73,($R$2-1)*12+8) -> 0 | P29: =INDEX(Monthly!$C$73:$BJ$73,($R$2-1)*12+9) -> 0 | Q29: =INDEX(Monthly!$C$73:$BJ$73,($R$2-1)*12+10) -> 0 | R29: =INDEX(Monthly!$C$73:$BJ$73,($R$2-1)*12+11) -> 0 | S29: =INDEX(Monthly!$C$73:$BJ$73,($R$2-1)*12+12) -> 0
A30: Net change in cash | B30: ='Cash Flow'!B17 -> 2314803.5 | C30: ='Cash Flow'!C17 -> -785208.42 | D30: ='Cash Flow'!D17 -> -1117614.5 | E30: ='Cash Flow'!E17 -> -1773179.4 | F30: ='Cash Flow'!F17 -> -2930170.7 | H30: =INDEX(Monthly!$C$74:$BJ$74,($R$2-1)*12+1) -> 2915534.9 | I30: =INDEX(Monthly!$C$74:$BJ$74,($R$2-1)*12+2) -> -65545.546 | J30: =INDEX(Monthly!$C$74:$BJ$74,($R$2-1)*12+3) -> -63191.569 | K30: =INDEX(Monthly!$C$74:$BJ$74,($R$2-1)*12+4) -> -60896.156 | L30: =INDEX(Monthly!$C$74:$BJ$74,($R$2-1)*12+5) -> -58657.853 | M30: =INDEX(Monthly!$C$74:$BJ$74,($R$2-1)*12+6) -> -56475.24 | N30: =INDEX(Monthly!$C$74:$BJ$74,($R$2-1)*12+7) -> -54346.932 | O30: =INDEX(Monthly!$C$74:$BJ$74,($R$2-1)*12+8) -> -52271.581 | P30: =INDEX(Monthly!$C$74:$BJ$74,($R$2-1)*12+9) -> -50247.869 | Q30: =INDEX(Monthly!$C$74:$BJ$74,($R$2-1)*12+10) -> -48274.513 | R30: =INDEX(Monthly!$C$74:$BJ$74,($R$2-1)*12+11) -> -46350.26 | S30: =INDEX(Monthly!$C$74:$BJ$74,($R$2-1)*12+12) -> -44473.892
A31: Closing cash | B31: ='Cash Flow'!B19 -> 2314803.5 | C31: ='Cash Flow'!C19 -> 1529595.1 | D31: ='Cash Flow'!D19 -> 411980.55 | E31: ='Cash Flow'!E19 -> -1361198.8 | F31: ='Cash Flow'!F19 -> -4291369.5 | H31: =INDEX(Monthly!$C$76:$BJ$76,($R$2-1)*12+1) -> 2915534.9 | I31: =INDEX(Monthly!$C$76:$BJ$76,($R$2-1)*12+2) -> 2849989.3 | J31: =INDEX(Monthly!$C$76:$BJ$76,($R$2-1)*12+3) -> 2786797.8 | K31: =INDEX(Monthly!$C$76:$BJ$76,($R$2-1)*12+4) -> 2725901.6 | L31: =INDEX(Monthly!$C$76:$BJ$76,($R$2-1)*12+5) -> 2667243.8 | M31: =INDEX(Monthly!$C$76:$BJ$76,($R$2-1)*12+6) -> 2610768.5 | N31: =INDEX(Monthly!$C$76:$BJ$76,($R$2-1)*12+7) -> 2556421.6 | O31: =INDEX(Monthly!$C$76:$BJ$76,($R$2-1)*12+8) -> 2504150 | P31: =INDEX(Monthly!$C$76:$BJ$76,($R$2-1)*12+9) -> 2453902.2 | Q31: =INDEX(Monthly!$C$76:$BJ$76,($R$2-1)*12+10) -> 2405627.6 | R31: =INDEX(Monthly!$C$76:$BJ$76,($R$2-1)*12+11) -> 2359277.4 | S31: =INDEX(Monthly!$C$76:$BJ$76,($R$2-1)*12+12) -> 2314803.5
A39: Balance sheet at year end ($'000) | H39: ="Balance sheet at month end ($'000) — Year "&$R$2 -> Balance sheet at month end ($'000) — Year 1
B40: 1 | C40: 2 | D40: 3 | E40: 4 | F40: 5 | H40: =INDEX(Monthly!$C$4:$BJ$4,($R$2-1)*12+1) -> 1 | I40: =INDEX(Monthly!$C$4:$BJ$4,($R$2-1)*12+2) -> 2 | J40: =INDEX(Monthly!$C$4:$BJ$4,($R$2-1)*12+3) -> 3 | K40: =INDEX(Monthly!$C$4:$BJ$4,($R$2-1)*12+4) -> 4 | L40: =INDEX(Monthly!$C$4:$BJ$4,($R$2-1)*12+5) -> 5 | M40: =INDEX(Monthly!$C$4:$BJ$4,($R$2-1)*12+6) -> 6 | N40: =INDEX(Monthly!$C$4:$BJ$4,($R$2-1)*12+7) -> 7 | O40: =INDEX(Monthly!$C$4:$BJ$4,($R$2-1)*12+8) -> 8 | P40: =INDEX(Monthly!$C$4:$BJ$4,($R$2-1)*12+9) -> 9 | Q40: =INDEX(Monthly!$C$4:$BJ$4,($R$2-1)*12+10) -> 10 | R40: =INDEX(Monthly!$C$4:$BJ$4,($R$2-1)*12+11) -> 11 | S40: =INDEX(Monthly!$C$4:$BJ$4,($R$2-1)*12+12) -> 12
A41: Cash | B41: ='Balance Sheet'!B5 -> 2314803.5 | C41: ='Balance Sheet'!C5 -> 1529595.1 | D41: ='Balance Sheet'!D5 -> 411980.55 | E41: ='Balance Sheet'!E5 -> -1361198.8 | F41: ='Balance Sheet'!F5 -> -4291369.5 | H41: =INDEX(Monthly!$C$76:$BJ$76,($R$2-1)*12+1) -> 2915534.9 | I41: =INDEX(Monthly!$C$76:$BJ$76,($R$2-1)*12+2) -> 2849989.3 | J41: =INDEX(Monthly!$C$76:$BJ$76,($R$2-1)*12+3) -> 2786797.8 | K41: =INDEX(Monthly!$C$76:$BJ$76,($R$2-1)*12+4) -> 2725901.6 | L41: =INDEX(Monthly!$C$76:$BJ$76,($R$2-1)*12+5) -> 2667243.8 | M41: =INDEX(Monthly!$C$76:$BJ$76,($R$2-1)*12+6) -> 2610768.5 | N41: =INDEX(Monthly!$C$76:$BJ$76,($R$2-1)*12+7) -> 2556421.6 | O41: =INDEX(Monthly!$C$76:$BJ$76,($R$2-1)*12+8) -> 2504150 | P41: =INDEX(Monthly!$C$76:$BJ$76,($R$2-1)*12+9) -> 2453902.2 | Q41: =INDEX(Monthly!$C$76:$BJ$76,($R$2-1)*12+10) -> 2405627.6 | R41: =INDEX(Monthly!$C$76:$BJ$76,($R$2-1)*12+11) -> 2359277.4 | S41: =INDEX(Monthly!$C$76:$BJ$76,($R$2-1)*12+12) -> 2314803.5
A42: Accounts receivable | B42: ='Balance Sheet'!B6 -> 5333.2481 | C42: ='Balance Sheet'!C6 -> 10462.475 | D42: ='Balance Sheet'!D6 -> 16071.669 | E42: ='Balance Sheet'!E6 -> 22561.633 | F42: ='Balance Sheet'!F6 -> 30385.013 | H42: =INDEX(Monthly!$C$60:$BJ$60,($R$2-1)*12+1) -> 734.47917 | I42: =INDEX(Monthly!$C$60:$BJ$60,($R$2-1)*12+2) -> 1207.4505 | J42: =INDEX(Monthly!$C$60:$BJ$60,($R$2-1)*12+3) -> 1668.5976 | K42: =INDEX(Monthly!$C$60:$BJ$60,($R$2-1)*12+4) -> 2118.216 | L42: =INDEX(Monthly!$C$60:$BJ$60,($R$2-1)*12+5) -> 2556.5939 | M42: =INDEX(Monthly!$C$60:$BJ$60,($R$2-1)*12+6) -> 2984.0124 | N42: =INDEX(Monthly!$C$60:$BJ$60,($R$2-1)*12+7) -> 3400.7454 | O42: =INDEX(Monthly!$C$60:$BJ$60,($R$2-1)*12+8) -> 3807.0601 | P42: =INDEX(Monthly!$C$60:$BJ$60,($R$2-1)*12+9) -> 4203.217 | Q42: =INDEX(Monthly!$C$60:$BJ$60,($R$2-1)*12+10) -> 4589.4699 | R42: =INDEX(Monthly!$C$60:$BJ$60,($R$2-1)*12+11) -> 4966.0665 | S42: =INDEX(Monthly!$C$60:$BJ$60,($R$2-1)*12+12) -> 5333.2481
A43: Inventory | B43: ='Balance Sheet'!B7 -> 0 | C43: ='Balance Sheet'!C7 -> 0 | D43: ='Balance Sheet'!D7 -> 0 | E43: ='Balance Sheet'!E7 -> 0 | F43: ='Balance Sheet'!F7 -> 0 | H43: =INDEX(Monthly!$C$61:$BJ$61,($R$2-1)*12+1) -> 0 | I43: =INDEX(Monthly!$C$61:$BJ$61,($R$2-1)*12+2) -> 0 | J43: =INDEX(Monthly!$C$61:$BJ$61,($R$2-1)*12+3) -> 0 | K43: =INDEX(Monthly!$C$61:$BJ$61,($R$2-1)*12+4) -> 0 | L43: =INDEX(Monthly!$C$61:$BJ$61,($R$2-1)*12+5) -> 0 | M43: =INDEX(Monthly!$C$61:$BJ$61,($R$2-1)*12+6) -> 0 | N43: =INDEX(Monthly!$C$61:$BJ$61,($R$2-1)*12+7) -> 0 | O43: =INDEX(Monthly!$C$61:$BJ$61,($R$2-1)*12+8) -> 0 | P43: =INDEX(Monthly!$C$61:$BJ$61,($R$2-1)*12+9) -> 0 | Q43: =INDEX(Monthly!$C$61:$BJ$61,($R$2-1)*12+10) -> 0 | R43: =INDEX(Monthly!$C$61:$BJ$61,($R$2-1)*12+11) -> 0 | S43: =INDEX(Monthly!$C$61:$BJ$61,($R$2-1)*12+12) -> 0
A44: Net fixed assets | B44: ='Balance Sheet'!B8 -> 13333.333 | C44: ='Balance Sheet'!C8 -> 6666.6667 | D44: ='Balance Sheet'!D8 -> 0 | E44: ='Balance Sheet'!E8 -> 0 | F44: ='Balance Sheet'!F8 -> 0 | H44: =INDEX(Monthly!$C$51:$BJ$51,($R$2-1)*12+1) -> 19444.444 | I44: =INDEX(Monthly!$C$51:$BJ$51,($R$2-1)*12+2) -> 18888.889 | J44: =INDEX(Monthly!$C$51:$BJ$51,($R$2-1)*12+3) -> 18333.333 | K44: =INDEX(Monthly!$C$51:$BJ$51,($R$2-1)*12+4) -> 17777.778 | L44: =INDEX(Monthly!$C$51:$BJ$51,($R$2-1)*12+5) -> 17222.222 | M44: =INDEX(Monthly!$C$51:$BJ$51,($R$2-1)*12+6) -> 16666.667 | N44: =INDEX(Monthly!$C$51:$BJ$51,($R$2-1)*12+7) -> 16111.111 | O44: =INDEX(Monthly!$C$51:$BJ$51,($R$2-1)*12+8) -> 15555.556 | P44: =INDEX(Monthly!$C$51:$BJ$51,($R$2-1)*12+9) -> 15000 | Q44: =INDEX(Monthly!$C$51:$BJ$51,($R$2-1)*12+10) -> 14444.444 | R44: =INDEX(Monthly!$C$51:$BJ$51,($R$2-1)*12+11) -> 13888.889 | S44: =INDEX(Monthly!$C$51:$BJ$51,($R$2-1)*12+12) -> 13333.333
A45: Total assets | B45: ='Balance Sheet'!B9 -> 2333470.1 | C45: ='Balance Sheet'!C9 -> 1546724.2 | D45: ='Balance Sheet'!D9 -> 428052.22 | E45: ='Balance Sheet'!E9 -> -1338637.2 | F45: ='Balance Sheet'!F9 -> -4260984.5 | H45: =INDEX(Monthly!$C$94:$BJ$94,($R$2-1)*12+1) -> 2935713.8 | I45: =INDEX(Monthly!$C$94:$BJ$94,($R$2-1)*12+2) -> 2870085.7 | J45: =INDEX(Monthly!$C$94:$BJ$94,($R$2-1)*12+3) -> 2806799.7 | K45: =INDEX(Monthly!$C$94:$BJ$94,($R$2-1)*12+4) -> 2745797.6 | L45: =INDEX(Monthly!$C$94:$BJ$94,($R$2-1)*12+5) -> 2687022.6 | M45: =INDEX(Monthly!$C$94:$BJ$94,($R$2-1)*12+6) -> 2630419.2 | N45: =INDEX(Monthly!$C$94:$BJ$94,($R$2-1)*12+7) -> 2575933.5 | O45: =INDEX(Monthly!$C$94:$BJ$94,($R$2-1)*12+8) -> 2523512.6 | P45: =INDEX(Monthly!$C$94:$BJ$94,($R$2-1)*12+9) -> 2473105.4 | Q45: =INDEX(Monthly!$C$94:$BJ$94,($R$2-1)*12+10) -> 2424661.6 | R45: =INDEX(Monthly!$C$94:$BJ$94,($R$2-1)*12+11) -> 2378132.3 | S45: =INDEX(Monthly!$C$94:$BJ$94,($R$2-1)*12+12) -> 2333470.1
A46: Accounts payable | B46: ='Balance Sheet'!B10 -> 3828.7027 | C46: ='Balance Sheet'!C10 -> 7462.4506 | D46: ='Balance Sheet'!D10 -> 11395.215 | E46: ='Balance Sheet'!E10 -> 15909.839 | F46: ='Balance Sheet'!F10 -> 21319.292 | H46: =INDEX(Monthly!$C$62:$BJ$62,($R$2-1)*12+1) -> 529.56528 | I46: =INDEX(Monthly!$C$62:$BJ$62,($R$2-1)*12+2) -> 870.23731 | J46: =INDEX(Monthly!$C$62:$BJ$62,($R$2-1)*12+3) -> 1202.1081 | K46: =INDEX(Monthly!$C$62:$BJ$62,($R$2-1)*12+4) -> 1525.4062 | L46: =INDEX(Monthly!$C$62:$BJ$62,($R$2-1)*12+5) -> 1840.3542 | M46: =INDEX(Monthly!$C$62:$BJ$62,($R$2-1)*12+6) -> 2147.1689 | N46: =INDEX(Monthly!$C$62:$BJ$62,($R$2-1)*12+7) -> 2446.0615 | O46: =INDEX(Monthly!$C$62:$BJ$62,($R$2-1)*12+8) -> 2737.2374 | P46: =INDEX(Monthly!$C$62:$BJ$62,($R$2-1)*12+9) -> 3020.897 | Q46: =INDEX(Monthly!$C$62:$BJ$62,($R$2-1)*12+10) -> 3297.2353 | R46: =INDEX(Monthly!$C$62:$BJ$62,($R$2-1)*12+11) -> 3566.4422 | S46: =INDEX(Monthly!$C$62:$BJ$62,($R$2-1)*12+12) -> 3828.7027
A47: Deferred revenue (annual plans, ~6 months unearned) | B47: ='Balance Sheet'!B11 -> 39704.508 | C47: ='Balance Sheet'!C11 -> 76664.533 | D47: ='Balance Sheet'!D11 -> 117179.09 | E47: ='Balance Sheet'!E11 -> 164139.61 | F47: ='Balance Sheet'!F11 -> 220818.92 | H47: =INDEX(Monthly!$C$66:$BJ$66,($R$2-1)*12+1) -> 7012.5 | I47: =INDEX(Monthly!$C$66:$BJ$66,($R$2-1)*12+2) -> 10374.788 | J47: =INDEX(Monthly!$C$66:$BJ$66,($R$2-1)*12+3) -> 13653.018 | K47: =INDEX(Monthly!$C$66:$BJ$66,($R$2-1)*12+4) -> 16849.292 | L47: =INDEX(Monthly!$C$66:$BJ$66,($R$2-1)*12+5) -> 19965.66 | M47: =INDEX(Monthly!$C$66:$BJ$66,($R$2-1)*12+6) -> 23004.119 | N47: =INDEX(Monthly!$C$66:$BJ$66,($R$2-1)*12+7) -> 25966.616 | O47: =INDEX(Monthly!$C$66:$BJ$66,($R$2-1)*12+8) -> 28855.05 | P47: =INDEX(Monthly!$C$66:$BJ$66,($R$2-1)*12+9) -> 31671.274 | Q47: =INDEX(Monthly!$C$66:$BJ$66,($R$2-1)*12+10) -> 34417.092 | R47: =INDEX(Monthly!$C$66:$BJ$66,($R$2-1)*12+11) -> 37094.265 | S47: =INDEX(Monthly!$C$66:$BJ$66,($R$2-1)*12+12) -> 39704.508
A48: Loan | B48: ='Balance Sheet'!B12 -> 0 | C48: ='Balance Sheet'!C12 -> 0 | D48: ='Balance Sheet'!D12 -> 0 | E48: ='Balance Sheet'!E12 -> 0 | F48: ='Balance Sheet'!F12 -> 0 | H48: =INDEX(Monthly!$C$57:$BJ$57,($R$2-1)*12+1) -> 0 | I48: =INDEX(Monthly!$C$57:$BJ$57,($R$2-1)*12+2) -> 0 | J48: =INDEX(Monthly!$C$57:$BJ$57,($R$2-1)*12+3) -> 0 | K48: =INDEX(Monthly!$C$57:$BJ$57,($R$2-1)*12+4) -> 0 | L48: =INDEX(Monthly!$C$57:$BJ$57,($R$2-1)*12+5) -> 0 | M48: =INDEX(Monthly!$C$57:$BJ$57,($R$2-1)*12+6) -> 0 | N48: =INDEX(Monthly!$C$57:$BJ$57,($R$2-1)*12+7) -> 0 | O48: =INDEX(Monthly!$C$57:$BJ$57,($R$2-1)*12+8) -> 0 | P48: =INDEX(Monthly!$C$57:$BJ$57,($R$2-1)*12+9) -> 0 | Q48: =INDEX(Monthly!$C$57:$BJ$57,($R$2-1)*12+10) -> 0 | R48: =INDEX(Monthly!$C$57:$BJ$57,($R$2-1)*12+11) -> 0 | S48: =INDEX(Monthly!$C$57:$BJ$57,($R$2-1)*12+12) -> 0
A49: Total liabilities | B49: ='Balance Sheet'!B13 -> 43533.211 | C49: ='Balance Sheet'!C13 -> 84126.984 | D49: ='Balance Sheet'!D13 -> 128574.31 | E49: ='Balance Sheet'!E13 -> 180049.45 | F49: ='Balance Sheet'!F13 -> 242138.21 | H49: =INDEX(Monthly!$C$95:$BJ$95,($R$2-1)*12+1) -> 7542.0653 | I49: =INDEX(Monthly!$C$95:$BJ$95,($R$2-1)*12+2) -> 11245.025 | J49: =INDEX(Monthly!$C$95:$BJ$95,($R$2-1)*12+3) -> 14855.126 | K49: =INDEX(Monthly!$C$95:$BJ$95,($R$2-1)*12+4) -> 18374.699 | L49: =INDEX(Monthly!$C$95:$BJ$95,($R$2-1)*12+5) -> 21806.014 | M49: =INDEX(Monthly!$C$95:$BJ$95,($R$2-1)*12+6) -> 25151.287 | N49: =INDEX(Monthly!$C$95:$BJ$95,($R$2-1)*12+7) -> 28412.677 | O49: =INDEX(Monthly!$C$95:$BJ$95,($R$2-1)*12+8) -> 31592.288 | P49: =INDEX(Monthly!$C$95:$BJ$95,($R$2-1)*12+9) -> 34692.171 | Q49: =INDEX(Monthly!$C$95:$BJ$95,($R$2-1)*12+10) -> 37714.327 | R49: =INDEX(Monthly!$C$95:$BJ$95,($R$2-1)*12+11) -> 40660.707 | S49: =INDEX(Monthly!$C$95:$BJ$95,($R$2-1)*12+12) -> 43533.211
A50: Paid-in capital | B50: ='Balance Sheet'!B14 -> 3000000 | C50: ='Balance Sheet'!C14 -> 3000000 | D50: ='Balance Sheet'!D14 -> 3000000 | E50: ='Balance Sheet'!E14 -> 3000000 | F50: ='Balance Sheet'!F14 -> 3000000 | H50: =INDEX(Monthly!$C$92:$BJ$92,($R$2-1)*12+1) -> 3000000 | I50: =INDEX(Monthly!$C$92:$BJ$92,($R$2-1)*12+2) -> 3000000 | J50: =INDEX(Monthly!$C$92:$BJ$92,($R$2-1)*12+3) -> 3000000 | K50: =INDEX(Monthly!$C$92:$BJ$92,($R$2-1)*12+4) -> 3000000 | L50: =INDEX(Monthly!$C$92:$BJ$92,($R$2-1)*12+5) -> 3000000 | M50: =INDEX(Monthly!$C$92:$BJ$92,($R$2-1)*12+6) -> 3000000 | N50: =INDEX(Monthly!$C$92:$BJ$92,($R$2-1)*12+7) -> 3000000 | O50: =INDEX(Monthly!$C$92:$BJ$92,($R$2-1)*12+8) -> 3000000 | P50: =INDEX(Monthly!$C$92:$BJ$92,($R$2-1)*12+9) -> 3000000 | Q50: =INDEX(Monthly!$C$92:$BJ$92,($R$2-1)*12+10) -> 3000000 | R50: =INDEX(Monthly!$C$92:$BJ$92,($R$2-1)*12+11) -> 3000000 | S50: =INDEX(Monthly!$C$92:$BJ$92,($R$2-1)*12+12) -> 3000000
...

Sheet Scenarios
A1: Scenarios — Low / Base / High | H1: =HYPERLINK("#'Cover'!A1","◂ Contents") -> ◂ Contents
A2: All three scenarios calculated side by side, live: change any input and every column updates. Active = the scenario chosen on the Dashboard.
A5: Key drivers
A6: Driver | B6: Low | C6: Base | D6: High | E6: Active
A7: Paying customers at start (#) | B7: =Inputs!$B$7 -> 30 | C7: =Inputs!$C$7 -> 30 | D7: =Inputs!$D$7 -> 30 | E7: =Inputs!$E$7 -> 30
A8: Average MRR per new customer (ARPA) ($ / month) | B8: =Inputs!$B$8 -> 79 | C8: =Inputs!$C$8 -> 99 | D8: =Inputs!$D$8 -> 119 | E8: =Inputs!$E$8 -> 99
A9: Customer churn per month (%) | B9: =Inputs!$B$10 -> 0.045 | C9: =Inputs!$C$10 -> 0.03 | D9: =Inputs!$D$10 -> 0.02 | E9: =Inputs!$E$10 -> 0.03
A10: Organic / referral new customers per month (year 1) (# / month) | B10: =Inputs!$B$12 -> 8 | C10: =Inputs!$C$12 -> 12 | D10: =Inputs!$D$12 -> 18 | E10: =Inputs!$E$12 -> 12
A11: Paid marketing budget per month (year 1) ($ / month) | B11: =Inputs!$B$14 -> 8000 | C11: =Inputs!$C$14 -> 8000 | D11: =Inputs!$D$14 -> 8000 | E11: =Inputs!$E$14 -> 8000
A12: Paid customer acquisition cost (CAC) ($) | B12: =Inputs!$B$16 -> 600 | C12: =Inputs!$C$16 -> 450 | D12: =Inputs!$D$16 -> 350 | E12: =Inputs!$E$16 -> 450
A13: Equity raised at start ($) | B13: =Inputs!$B$46 -> 3000000 | C13: =Inputs!$C$46 -> 3000000 | D13: =Inputs!$D$46 -> 3000000 | E13: =Inputs!$E$46 -> 3000000
A15: Results by scenario ($'000)
A16: Output | B16: Low | C16: Base | D16: High | E16: Active
A17: Revenue — final year | B17: =F30 -> 624519.48 | C17: =F31 -> 1939020.9 | D17: =F32 -> 5409456.9 | E17: ='P&L'!F5 -> 1939020.9
A18: Revenue — whole plan | B18: =SUM(B30:F30) -> 1947132 | C18: =SUM(B31:F31) -> 5153329.9 | D18: =SUM(B32:F32) -> 12539642 | E18: =SUM('P&L'!$B$5:$F$5) -> 5153329.9
A19: EBITDA — final year | B19: =F36 -> -4170384.4 | C19: =F37 -> -2984436 | D19: =F38 -> 229990.22 | E19: ='P&L'!F15 -> -2984436
A20: EBITDA margin — final year | B20: =IF(B17=0,0,B19/B17) -> -6.6777492 | C20: =IF(C17=0,0,C19/C17) -> -1.5391458 | D20: =IF(D17=0,0,D19/D17) -> 0.042516324 | E20: =IF(E17=0,0,E19/E17) -> -1.5391458
A21: Net income — final year | B21: =F42 -> -4170384.4 | C21: =F43 -> -2984436 | D21: =F44 -> 229990.22 | E21: ='P&L'!F22 -> -2984436
A22: Net income — whole plan | B22: =SUM(B42:F42) -> -10409191 | C22: =SUM(B43:F43) -> -7503122.7 | D22: =SUM(B44:F44) -> -637423.03 | E22: =SUM('P&L'!$B$22:$F$22) -> -7503122.7
A23: Cash at the end of the plan | B23: =F48 -> -7342086.9 | C23: =F49 -> -4291369.5 | D23: =F50 -> 2972134.9 | E23: ='Balance Sheet'!F5 -> -4291369.5
A24: Lowest cash balance | B24: =MIN('Scenario calc'!$C$78:$BJ$78) -> -7342086.9 | C24: =MIN('Scenario calc'!$C$191:$BJ$191) -> -4291369.5 | D24: =MIN('Scenario calc'!$C$304:$BJ$304) -> 2138580.4 | E24: ='Break-even'!B18 -> -4291369.5
A25: Lowest cash point (month #) | B25: =MATCH(MIN('Scenario calc'!$C$78:$BJ$78),'Scenario calc'!$C$78:$BJ$78,0) -> 60 | C25: =MATCH(MIN('Scenario calc'!$C$191:$BJ$191),'Scenario calc'!$C$191:$BJ$191,0) -> 60 | D25: =MATCH(MIN('Scenario calc'!$C$304:$BJ$304),'Scenario calc'!$C$304:$BJ$304,0) -> 30 | E25: ='Break-even'!B6 -> 60
A26: Funding required (incl. cash buffer) | B26: =SUMPRODUCT(--('Scenario calc'!$C$6:$BJ$6<=B25),'Scenario calc'!$C$49:$BJ$49)-SUMPRODUCT(--('Scenario calc'!$C$6:$BJ$6<=B25),'Scenario calc'!$C$72:$BJ$72)-SUMPRODUCT(--('Scenario calc'!$C$6:$BJ$6<=B25),'Scenario calc'!$C$58:$BJ$58)+Inputs!$B$61 -> 10567087 | C26: =SUMPRODUCT(--('Scenario calc'!$C$119:$BJ$119<=C25),'Scenario calc'!$C$162:$BJ$162)-SUMPRODUCT(--('Scenario calc'!$C$119:$BJ$119<=C25),'Scenario calc'!$C$185:$BJ$185)-SUMPRODUCT(--('Scenario calc'!$C$119:$BJ$119<=C25),'Scenario calc'!$C$171:$BJ$171)+Inputs!$C$61 -> 7516369.5 | D26: =SUMPRODUCT(--('Scenario calc'!$C$232:$BJ$232<=D25),'Scenario calc'!$C$275:$BJ$275)-SUMPRODUCT(--('Scenario calc'!$C$232:$BJ$232<=D25),'Scenario calc'!$C$298:$BJ$298)-SUMPRODUCT(--('Scenario calc'!$C$232:$BJ$232<=D25),'Scenario calc'!$C$284:$BJ$284)+Inputs!$D$61 -> 1086419.6 | E26: ='Break-even'!B12 -> 7516369.5
A28: Revenue by year ($'000)
A29: Scenario | B29: 1 | C29: 2 | D29: 3 | E29: 4 | F29: 5
A30: Low | B30: =SUMIF('Scenario calc'!$C$7:$BJ$7,B$29,'Scenario calc'!$C$26:$BJ$26) -> 125924.63 | C30: =SUMIF('Scenario calc'!$C$7:$BJ$7,C$29,'Scenario calc'!$C$26:$BJ$26) -> 280162.87 | D30: =SUMIF('Scenario calc'!$C$7:$BJ$7,D$29,'Scenario calc'!$C$26:$BJ$26) -> 402920.19 | E30: =SUMIF('Scenario calc'!$C$7:$BJ$7,E$29,'Scenario calc'!$C$26:$BJ$26) -> 513604.81 | F30: =SUMIF('Scenario calc'!$C$7:$BJ$7,F$29,'Scenario calc'!$C$26:$BJ$26) -> 624519.48
A31: Base | B31: =SUMIF('Scenario calc'!$C$120:$BJ$120,B$29,'Scenario calc'!$C$139:$BJ$139) -> 225414.94 | C31: =SUMIF('Scenario calc'!$C$120:$BJ$120,C$29,'Scenario calc'!$C$139:$BJ$139) -> 591123.33 | D31: =SUMIF('Scenario calc'!$C$120:$BJ$120,D$29,'Scenario calc'!$C$139:$BJ$139) -> 979388.56 | E31: =SUMIF('Scenario calc'!$C$120:$BJ$120,E$29,'Scenario calc'!$C$139:$BJ$139) -> 1418382.1 | F31: =SUMIF('Scenario calc'!$C$120:$BJ$120,F$29,'Scenario calc'!$C$139:$BJ$139) -> 1939020.9
A32: High | B32: =SUMIF('Scenario calc'!$C$233:$BJ$233,B$29,'Scenario calc'!$C$252:$BJ$252) -> 378410.1 | C32: =SUMIF('Scenario calc'!$C$233:$BJ$233,C$29,'Scenario calc'!$C$252:$BJ$252) -> 1133100.3 | D32: =SUMIF('Scenario calc'!$C$233:$BJ$233,D$29,'Scenario calc'!$C$252:$BJ$252) -> 2128410.7 | E32: =SUMIF('Scenario calc'!$C$233:$BJ$233,E$29,'Scenario calc'!$C$252:$BJ$252) -> 3490263.9 | F32: =SUMIF('Scenario calc'!$C$233:$BJ$233,F$29,'Scenario calc'!$C$252:$BJ$252) -> 5409456.9
A34: EBITDA by year ($'000)
A35: Scenario | B35: 1 | C35: 2 | D35: 3 | E35: 4 | F35: 5
A36: Low | B36: =SUMIF('Scenario calc'!$C$7:$BJ$7,B$35,'Scenario calc'!$C$37:$BJ$37) -> -795768.28 | C36: =SUMIF('Scenario calc'!$C$7:$BJ$7,C$35,'Scenario calc'!$C$37:$BJ$37) -> -1105455.8 | D36: =SUMIF('Scenario calc'!$C$7:$BJ$7,D$35,'Scenario calc'!$C$37:$BJ$37) -> -1680568.6 | E36: =SUMIF('Scenario calc'!$C$7:$BJ$7,E$35,'Scenario calc'!$C$37:$BJ$37) -> -2637014 | F36: =SUMIF('Scenario calc'!$C$7:$BJ$7,F$35,'Scenario calc'!$C$37:$BJ$37) -> -4170384.4
A37: Base | B37: =SUMIF('Scenario calc'!$C$120:$BJ$120,B$35,'Scenario calc'!$C$150:$BJ$150) -> -703396.48 | C37: =SUMIF('Scenario calc'!$C$120:$BJ$120,C$35,'Scenario calc'!$C$150:$BJ$150) -> -820672.96 | D37: =SUMIF('Scenario calc'!$C$120:$BJ$120,D$35,'Scenario calc'!$C$150:$BJ$150) -> -1156452.6 | E37: =SUMIF('Scenario calc'!$C$120:$BJ$120,E$35,'Scenario calc'!$C$150:$BJ$150) -> -1818164.6 | F37: =SUMIF('Scenario calc'!$C$120:$BJ$120,F$35,'Scenario calc'!$C$150:$BJ$150) -> -2984436
A38: High | B38: =SUMIF('Scenario calc'!$C$233:$BJ$233,B$35,'Scenario calc'!$C$263:$BJ$263) -> -558259.05 | C38: =SUMIF('Scenario calc'!$C$233:$BJ$233,C$35,'Scenario calc'!$C$263:$BJ$263) -> -311798.28 | D38: =SUMIF('Scenario calc'!$C$233:$BJ$233,D$35,'Scenario calc'!$C$263:$BJ$263) -> -84273.989 | E38: =SUMIF('Scenario calc'!$C$233:$BJ$233,E$35,'Scenario calc'!$C$263:$BJ$263) -> 106918.07 | F38: =SUMIF('Scenario calc'!$C$233:$BJ$233,F$35,'Scenario calc'!$C$263:$BJ$263) -> 229990.22
A40: Net income by year ($'000)
A41: Scenario | B41: 1 | C41: 2 | D41: 3 | E41: 4 | F41: 5
A42: Low | B42: =SUMIF('Scenario calc'!$C$7:$BJ$7,B$41,'Scenario calc'!$C$46:$BJ$46) -> -802434.94 | C42: =SUMIF('Scenario calc'!$C$7:$BJ$7,C$41,'Scenario calc'!$C$46:$BJ$46) -> -1112122.4 | D42: =SUMIF('Scenario calc'!$C$7:$BJ$7,D$41,'Scenario calc'!$C$46:$BJ$46) -> -1687235.3 | E42: =SUMIF('Scenario calc'!$C$7:$BJ$7,E$41,'Scenario calc'!$C$46:$BJ$46) -> -2637014 | F42: =SUMIF('Scenario calc'!$C$7:$BJ$7,F$41,'Scenario calc'!$C$46:$BJ$46) -> -4170384.4
A43: Base | B43: =SUMIF('Scenario calc'!$C$120:$BJ$120,B$41,'Scenario calc'!$C$159:$BJ$159) -> -710063.14 | C43: =SUMIF('Scenario calc'!$C$120:$BJ$120,C$41,'Scenario calc'!$C$159:$BJ$159) -> -827339.63 | D43: =SUMIF('Scenario calc'!$C$120:$BJ$120,D$41,'Scenario calc'!$C$159:$BJ$159) -> -1163119.3 | E43: =SUMIF('Scenario calc'!$C$120:$BJ$120,E$41,'Scenario calc'!$C$159:$BJ$159) -> -1818164.6 | F43: =SUMIF('Scenario calc'!$C$120:$BJ$120,F$41,'Scenario calc'!$C$159:$BJ$159) -> -2984436
A44: High | B44: =SUMIF('Scenario calc'!$C$233:$BJ$233,B$41,'Scenario calc'!$C$272:$BJ$272) -> -564925.72 | C44: =SUMIF('Scenario calc'!$C$233:$BJ$233,C$41,'Scenario calc'!$C$272:$BJ$272) -> -318464.95 | D44: =SUMIF('Scenario calc'!$C$233:$BJ$233,D$41,'Scenario calc'!$C$272:$BJ$272) -> -90940.655 | E44: =SUMIF('Scenario calc'!$C$233:$BJ$233,E$41,'Scenario calc'!$C$272:$BJ$272) -> 106918.07 | F44: =SUMIF('Scenario calc'!$C$233:$BJ$233,F$41,'Scenario calc'!$C$272:$BJ$272) -> 229990.22
A46: Cash at year end by year ($'000)
A47: Scenario | B47: 1 | C47: 2 | D47: 3 | E47: 4 | F47: 5
...

Sheet Break-even
A1: Startup costs, funding need and break-even | H1: =HYPERLINK("#'Cover'!A1","◂ Contents") -> ◂ Contents
A2: Live for the selected scenario. Periods are counted in months from the start of the plan.
A3: Scenario shown | B3: =CHOOSE(Dashboard!$B$4,"Low","Base","High") -> Base
A5: Startup costs & funding need (up to the lowest cash point)
A6: Lowest cash point (month #) | B6: =MATCH(MIN(Monthly!$C$76:$BJ$76),Monthly!$C$76:$BJ$76,0) -> 60
A7: Capital spending up to the lowest cash point | B7: =SUMPRODUCT(--(Monthly!$C$4:$BJ$4<=$B$6),Monthly!$C$47:$BJ$47) -> 20000
A8: Operating cash burn up to the lowest cash point | B8: =-SUMPRODUCT(--(Monthly!$C$4:$BJ$4<=$B$6),Monthly!$C$70:$BJ$70) -> 7271369.5 | D8: Losses and working capital before the business funds itself
A9: Loan repayments up to the lowest cash point | B9: =-SUMPRODUCT(--(Monthly!$C$4:$BJ$4<=$B$6),Monthly!$C$56:$BJ$56) -> 0
A10: Total uses of funds | B10: =B7+B8+B9 -> 7291369.5
A11: Minimum cash buffer to keep | B11: =Inputs!$E$61 -> 225000 | D11: Input on the Inputs sheet
A12: Funding required (uses + buffer) | B12: =B10+B11 -> 7516369.5
A14: Equity raised | B14: =Inputs!$E$46 -> 3000000
A15: Loan drawn | B15: =Inputs!$E$47 -> 0
A16: Total sources of funds | B16: =B14+B15 -> 3000000
A17: Funding surplus / (shortfall) | B17: =B16-B12 -> -4516369.5 | D17: Negative = raise at least this much more
A18: Lowest cash balance in the plan | B18: =MIN(Monthly!$C$76:$BJ$76) -> -4291369.5 | D18: Equals sources minus uses
A20: Break-even timing
A21: First month with positive EBITDA (month #) | B21: =IFERROR(MATCH(1,Monthly!$C$77:$BJ$77,0),"Not within horizon") -> Not within horizon
A22: First month with positive net income (month #) | B22: =IFERROR(MATCH(1,Monthly!$C$84:$BJ$84,0),"Not within horizon") -> Not within horizon
A23: Cash invested paid back (month #) | B23: =IF(MIN(Monthly!$C$86:$BJ$86)>=0,"No investment to pay back",IFERROR(MATCH(1,Monthly!$C$88:$BJ$88,0),"Not within horizon")) -> Not within horizon | D23: Cumulative operating + investing cash flow back to zero
A25: Annual break-even revenue
A26: Year # | B26: 1 | C26: 2 | D26: 3 | E26: 4 | F26: 5
B27: Year 1 | C27: Year 2 | D27: Year 3 | E27: Year 4 | F27: Year 5
A28: Revenue | B28: =SUMIF(Monthly!$C$5:$BJ$5,B$26,Monthly!$C$24:$BJ$24) -> 225414.94 | C28: =SUMIF(Monthly!$C$5:$BJ$5,C$26,Monthly!$C$24:$BJ$24) -> 591123.33 | D28: =SUMIF(Monthly!$C$5:$BJ$5,D$26,Monthly!$C$24:$BJ$24) -> 979388.56 | E28: =SUMIF(Monthly!$C$5:$BJ$5,E$26,Monthly!$C$24:$BJ$24) -> 1418382.1 | F28: =SUMIF(Monthly!$C$5:$BJ$5,F$26,Monthly!$C$24:$BJ$24) -> 1939020.9
A29: Gross profit | B29: =SUMIF(Monthly!$C$5:$BJ$5,B$26,Monthly!$C$26:$BJ$26) -> 198403.52 | C29: =SUMIF(Monthly!$C$5:$BJ$5,C$26,Monthly!$C$26:$BJ$26) -> 520687.04 | D29: =SUMIF(Monthly!$C$5:$BJ$5,D$26,Monthly!$C$26:$BJ$26) -> 863384.95 | E29: =SUMIF(Monthly!$C$5:$BJ$5,E$26,Monthly!$C$26:$BJ$26) -> 1251317.7 | F29: =SUMIF(Monthly!$C$5:$BJ$5,F$26,Monthly!$C$26:$BJ$26) -> 1711809.6
A30: Gross margin (contribution) | B30: =IF(B28=0,0,B29/B28) -> 0.88017025 | C30: =IF(C28=0,0,C29/C28) -> 0.88084332 | D30: =IF(D28=0,0,D29/D28) -> 0.88155507 | E30: =IF(E28=0,0,E29/E28) -> 0.88221481 | F30: =IF(F28=0,0,F29/F28) -> 0.88282162
A31: Operating expenses (treated as fixed) | B31: =-SUMIF(Monthly!$C$5:$BJ$5,B$26,Monthly!$C$34:$BJ$34) -> 901800 | C31: =-SUMIF(Monthly!$C$5:$BJ$5,C$26,Monthly!$C$34:$BJ$34) -> 1341360 | D31: =-SUMIF(Monthly!$C$5:$BJ$5,D$26,Monthly!$C$34:$BJ$34) -> 2019837.6 | E31: =-SUMIF(Monthly!$C$5:$BJ$5,E$26,Monthly!$C$34:$BJ$34) -> 3069482.3 | F31: =-SUMIF(Monthly!$C$5:$BJ$5,F$26,Monthly!$C$34:$BJ$34) -> 4696245.6
A32: Break-even revenue (EBITDA = 0) | B32: =IF(B30>0,B31/B30,"n/a") -> 1024574.5 | C32: =IF(C30>0,C31/C30,"n/a") -> 1522813.4 | D32: =IF(D30>0,D31/D30,"n/a") -> 2291221.1 | E32: =IF(E30>0,E31/E30,"n/a") -> 3479291.2 | F32: =IF(F30>0,F31/F30,"n/a") -> 5319586.1
A33: Margin of safety (revenue above break-even) | B33: =IF(AND(ISNUMBER(B32),B28>0),(B28-B32)/B28,"n/a") -> -3.5452822 | C33: =IF(AND(ISNUMBER(C32),C28>0),(C28-C32)/C28,"n/a") -> -1.5761348 | D33: =IF(AND(ISNUMBER(D32),D28>0),(D28-D32)/D28,"n/a") -> -1.3394404 | E33: =IF(AND(ISNUMBER(E32),E28>0),(E28-E32)/E28,"n/a") -> -1.453 | F33: =IF(AND(ISNUMBER(F32),F28>0),(F28-F32)/F28,"n/a") -> -1.7434392
A35: Simplification: cost of sales is treated as variable and operating expenses as fixed, so break-even revenue = operating expenses ÷ gross margin.

Sheet Valuation
A1: Discounted cash flow valuation | H1: =HYPERLINK("#'Cover'!A1","◂ Contents") -> ◂ Contents
A2: Enterprise value at the start of the plan, before the funding raised in period 1. Year-end discounting.
A3: Scenario shown | B3: =CHOOSE(Dashboard!$B$4,"Low","Base","High") -> Base
A5: Assumptions (active scenario, from the Inputs sheet)
A6: Discount rate (WACC) | B6: =Inputs!$E$64 -> 0.2
A7: Terminal growth rate | B7: =Inputs!$E$65 -> 0.02
A8: Exit multiple (EV ÷ final-year EBITDA) | B8: =Inputs!$E$66 -> 4.5
A9: Tax rate (for the interest tax shield) | B9: =Inputs!$E$58 -> 0.21
A10: Sensitivity step: WACC | B10: =Inputs!$E$67 -> 0.01
A11: Sensitivity step: terminal growth | B11: =Inputs!$E$68 -> 0.005
A13: Free cash flow by year
A14: Year # | B14: 1 | C14: 2 | D14: 3 | E14: 4 | F14: 5
B15: Year 1 | C15: Year 2 | D15: Year 3 | E15: Year 4 | F15: Year 5
A16: EBITDA | B16: =SUMIF(Monthly!$C$5:$BJ$5,B$14,Monthly!$C$35:$BJ$35) -> -703396.48 | C16: =SUMIF(Monthly!$C$5:$BJ$5,C$14,Monthly!$C$35:$BJ$35) -> -820672.96 | D16: =SUMIF(Monthly!$C$5:$BJ$5,D$14,Monthly!$C$35:$BJ$35) -> -1156452.6 | E16: =SUMIF(Monthly!$C$5:$BJ$5,E$14,Monthly!$C$35:$BJ$35) -> -1818164.6 | F16: =SUMIF(Monthly!$C$5:$BJ$5,F$14,Monthly!$C$35:$BJ$35) -> -2984436
A17: Unlevered free cash flow | B17: =SUMIF(Monthly!$C$5:$BJ$5,B$14,Monthly!$C$89:$BJ$89) -> -685196.51 | C17: =SUMIF(Monthly!$C$5:$BJ$5,C$14,Monthly!$C$89:$BJ$89) -> -785208.42 | D17: =SUMIF(Monthly!$C$5:$BJ$5,D$14,Monthly!$C$89:$BJ$89) -> -1117614.5 | E17: =SUMIF(Monthly!$C$5:$BJ$5,E$14,Monthly!$C$89:$BJ$89) -> -1773179.4 | F17: =SUMIF(Monthly!$C$5:$BJ$5,F$14,Monthly!$C$89:$BJ$89) -> -2930170.7
A18: Discount factor | B18: =1/(1+Inputs!$E$64)^B$14 -> 0.83333333 | C18: =1/(1+Inputs!$E$64)^C$14 -> 0.69444444 | D18: =1/(1+Inputs!$E$64)^D$14 -> 0.5787037 | E18: =1/(1+Inputs!$E$64)^E$14 -> 0.48225309 | F18: =1/(1+Inputs!$E$64)^F$14 -> 0.40187757
A19: Present value of free cash flow | B19: =B17*B18 -> -570997.1 | C19: =C17*C18 -> -545283.62 | D19: =D17*D18 -> -646767.66 | E19: =E17*E18 -> -855121.23 | F19: =F17*F18 -> -1177569.9
A21: Enterprise value
B22: Perpetual growth | C22: Exit multiple
A23: Present value of the plan's free cash flows | B23: =SUM($B$19:$F$19) -> -3795739.5 | C23: =B23 -> -3795739.5
A24: Final-year free cash flow | final-year EBITDA | B24: =$F$17 -> -2930170.7 | C24: =$F$16 -> -2984436
A25: Terminal value at the end of year 5 | B25: =IF($B$6>$B$7,B24*(1+$B$7)/($B$6-$B$7),0) -> -16604300 | C25: =C24*$B$8 -> -13429962
A26: Present value of the terminal value | B26: =B25/(1+$B$6)^$F$14 -> -6672895.9 | C26: =C25/(1+$B$6)^$F$14 -> -5397200.6
A27: Enterprise value | B27: =B23+B26 -> -10468635 | C27: =C23+C26 -> -9192940.1
A28: Terminal value share of enterprise value | B28: =IF(B27<>0,B26/B27,0) -> 0.63741793 | C28: =IF(C27<>0,C26/C27,0) -> 0.58710277
A29: Cross-check: implied exit multiple | implied perpetual growth | B29: =IF(C24>0,B25/C24,"n/a") -> n/a | C29: =IF(C25+B24<>0,(C25*$B$6-B24)/(C25+B24),"n/a") -> -0.014925198
A30: Enterprise value — average of the two methods | B30: =AVERAGE(B27,C27) -> -9830787.7
A32: Sensitivity: enterprise value (perpetual growth) by WACC and terminal growth
A33: WACC ↓ · terminal growth → | B33: =$B$7+(-2)*$B$11 -> 0.01 | C33: =$B$7+(-1)*$B$11 -> 0.015 | D33: =$B$7+(0)*$B$11 -> 0.02 | E33: =$B$7+(1)*$B$11 -> 0.025 | F33: =$B$7+(2)*$B$11 -> 0.03
A34: =$B$6+(-2)*$B$10 -> 0.18 | B34: =IF($A34>B$33,SUMPRODUCT($B$17:$F$17/(1+$A34)^$B$14:$F$14)+$F$17*(1+B$33)/($A34-B$33)/(1+$A34)^$F$14,"n/a") -> -11629691 | C34: =IF($A34>C$33,SUMPRODUCT($B$17:$F$17/(1+$A34)^$B$14:$F$14)+$F$17*(1+C$33)/($A34-C$33)/(1+$A34)^$F$14,"n/a") -> -11899094 | D34: =IF($A34>D$33,SUMPRODUCT($B$17:$F$17/(1+$A34)^$B$14:$F$14)+$F$17*(1+D$33)/($A34-D$33)/(1+$A34)^$F$14,"n/a") -> -12185334 | E34: =IF($A34>E$33,SUMPRODUCT($B$17:$F$17/(1+$A34)^$B$14:$F$14)+$F$17*(1+E$33)/($A34-E$33)/(1+$A34)^$F$14,"n/a") -> -12490042 | F34: =IF($A34>F$33,SUMPRODUCT($B$17:$F$17/(1+$A34)^$B$14:$F$14)+$F$17*(1+F$33)/($A34-F$33)/(1+$A34)^$F$14,"n/a") -> -12815063
A35: =$B$6+(-1)*$B$10 -> 0.19 | B35: =IF($A35>B$33,SUMPRODUCT($B$17:$F$17/(1+$A35)^$B$14:$F$14)+$F$17*(1+B$33)/($A35-B$33)/(1+$A35)^$F$14,"n/a") -> -10795413 | C35: =IF($A35>C$33,SUMPRODUCT($B$17:$F$17/(1+$A35)^$B$14:$F$14)+$F$17*(1+C$33)/($A35-C$33)/(1+$A35)^$F$14,"n/a") -> -11027347 | D35: =IF($A35>D$33,SUMPRODUCT($B$17:$F$17/(1+$A35)^$B$14:$F$14)+$F$17*(1+D$33)/($A35-D$33)/(1+$A35)^$F$14,"n/a") -> -11272924 | E35: =IF($A35>E$33,SUMPRODUCT($B$17:$F$17/(1+$A35)^$B$14:$F$14)+$F$17*(1+E$33)/($A35-E$33)/(1+$A35)^$F$14,"n/a") -> -11533385 | F35: =IF($A35>F$33,SUMPRODUCT($B$17:$F$17/(1+$A35)^$B$14:$F$14)+$F$17*(1+F$33)/($A35-F$33)/(1+$A35)^$F$14,"n/a") -> -11810125
A36: =$B$6+(0)*$B$10 -> 0.2 | B36: =IF($A36>B$33,SUMPRODUCT($B$17:$F$17/(1+$A36)^$B$14:$F$14)+$F$17*(1+B$33)/($A36-B$33)/(1+$A36)^$F$14,"n/a") -> -10055453 | C36: =IF($A36>C$33,SUMPRODUCT($B$17:$F$17/(1+$A36)^$B$14:$F$14)+$F$17*(1+C$33)/($A36-C$33)/(1+$A36)^$F$14,"n/a") -> -10256461 | D36: =IF($A36>D$33,SUMPRODUCT($B$17:$F$17/(1+$A36)^$B$14:$F$14)+$F$17*(1+D$33)/($A36-D$33)/(1+$A36)^$F$14,"n/a") -> -10468635 | E36: =IF($A36>E$33,SUMPRODUCT($B$17:$F$17/(1+$A36)^$B$14:$F$14)+$F$17*(1+E$33)/($A36-E$33)/(1+$A36)^$F$14,"n/a") -> -10692934 | F36: =IF($A36>F$33,SUMPRODUCT($B$17:$F$17/(1+$A36)^$B$14:$F$14)+$F$17*(1+F$33)/($A36-F$33)/(1+$A36)^$F$14,"n/a") -> -10930428
A37: =$B$6+(1)*$B$10 -> 0.21 | B37: =IF($A37>B$33,SUMPRODUCT($B$17:$F$17/(1+$A37)^$B$14:$F$14)+$F$17*(1+B$33)/($A37-B$33)/(1+$A37)^$F$14,"n/a") -> -9395382.7 | C37: =IF($A37>C$33,SUMPRODUCT($B$17:$F$17/(1+$A37)^$B$14:$F$14)+$F$17*(1+C$33)/($A37-C$33)/(1+$A37)^$F$14,"n/a") -> -9570632.3 | D37: =IF($A37>D$33,SUMPRODUCT($B$17:$F$17/(1+$A37)^$B$14:$F$14)+$F$17*(1+D$33)/($A37-D$33)/(1+$A37)^$F$14,"n/a") -> -9755105.4 | E37: =IF($A37>E$33,SUMPRODUCT($B$17:$F$17/(1+$A37)^$B$14:$F$14)+$F$17*(1+E$33)/($A37-E$33)/(1+$A37)^$F$14,"n/a") -> -9949550.1 | F37: =IF($A37>F$33,SUMPRODUCT($B$17:$F$17/(1+$A37)^$B$14:$F$14)+$F$17*(1+F$33)/($A37-F$33)/(1+$A37)^$F$14,"n/a") -> -10154797
