Workbook

Sheet Cover
B2: Hair salon financial model (planning)
B3: 5-year financial model · monthly detail · Low / Base / High scenarios · US dollars · Full plan
B5: Purpose | D5: Revenue and profit plan
B6: Active scenario | D6: =Dashboard!C4&" (change it on the Dashboard, cell B4)" -> Base (change it on the Dashboard, cell B4)
B7: Model checks | D7: =Checks!B24 -> PASS
B8: Prepared | D8: 21 October 2026
B10: Contents
C11: PRESENTATION
B12: 1 | C12: =HYPERLINK("#Dashboard!A1","Dashboard") -> Dashboard | D12: Scenario switch, key numbers, core financials
B13: 2 | C13: =HYPERLINK("#Summary!A1","Summary") -> Summary | D13: Income statement, cash flow and balance sheet — every year and any year by month
B14: 3 | C14: =HYPERLINK("#'Break-even'!A1","Break-even") -> Break-even | D14: Startup costs, funding need, break-even timing and revenue
B15: 4 | C15: =HYPERLINK("#Valuation!A1","Valuation") -> Valuation | D15: Free cash flow, DCF (perpetual growth and exit multiple), WACC × growth sensitivity
B16: 5 | C16: =HYPERLINK("#'Sources & Uses'!A1","Sources & Uses") -> Sources & Uses | D16: Funding structure, sources and uses of cash for the first months
B17: 6 | C17: =HYPERLINK("#KPIs!A1","KPIs") -> KPIs | D17: Financial ratios, DuPont analysis, industry metrics
C18: INPUTS
B19: 7 | C19: =HYPERLINK("#Inputs!A1","Inputs") -> Inputs | D19: Every assumption, Low / Base / High, with units and comments
C20: STATEMENTS
B21: 8 | C21: =HYPERLINK("#'P&L'!A1","P&L") -> P&L | D21: Annual profit & loss
B22: 9 | C22: =HYPERLINK("#'Cash Flow'!A1","Cash Flow") -> Cash Flow | D22: Annual cash flow statement
B23: 10 | C23: =HYPERLINK("#'Balance Sheet'!A1","Balance Sheet") -> Balance Sheet | D23: Balance sheet at year end
C24: CALCULATIONS
B25: 11 | C25: =HYPERLINK("#Monthly!A1","Monthly") -> Monthly | D25: Month-by-month engine of the model
B26: 12 | C26: =HYPERLINK("#Headcount!A1","Headcount") -> Headcount | D26: Team and payroll
C27: CONTROL
B28: 13 | C28: =HYPERLINK("#Checks!A1","Checks") -> Checks | D28: Live integrity checks and the overall verdict
B30: How to read this file
C31: 1000 | D31: Input you can change — yellow cell with a blue figure (Inputs sheet and the view switches)
C32: 1000 | D32: Formula — calculated, do not overwrite
C33: 1000 | D33: Link to another sheet
C34: 1000 | D34: Active value the model uses (follows the scenario)

Sheet Dashboard
A1: Dashboard | W1: =HYPERLINK("#'Cover'!A1","◂ Contents") -> ◂ Contents
A2: Hair salon financial model (planning)
A4: Active scenario | B4: 2 | C4: =CHOOSE(B4,"Low","Base","High") -> Base | D4: 1 = Low · 2 = Base · 3 = High — every sheet follows this cell | S4: Model checks | T4: =Checks!B24 -> PASS
A6: REVENUE · YEAR 5 | C6: EBITDA MARGIN · YEAR 5 | H6: NET INCOME · YEAR 5 | L6: LOWEST CASH BALANCE | P6: FUNDING REQUIRED | T6: ENTERPRISE VALUE (DCF)
A7: =F12 -> 942164.33 | C7: =F17 -> 0.1591247 | H7: =F18 -> 103543.94 | L7: =F38 -> 43432.925 | P7: =F36 -> 236567.08 | T7: =F43 -> 185713.55
A8: =IF(AND(B12>0,F12>=0),(F12/B12)^(1/4)-1,"CAGR n/a") -> 0.18422539 | C8: =F16 -> 149921.61 | H8: =F19 -> 0.10990009 | L8: ='Break-even'!B6 -> 24 | P8: =IF(F37>=0,"Covered by funding raised",-F37) -> 16567.075 | T8: Average of 2 methods
A10: Core financials ($'000) — active scenario
B11: 1 | C11: 2 | D11: 3 | E11: 4 | F11: 5
A12: Revenue | B12: =SUMIF(Monthly!$C$5:$BJ$5,B$11,Monthly!$C$21:$BJ$21) -> 479059.2 | C12: =SUMIF(Monthly!$C$5:$BJ$5,C$11,Monthly!$C$21:$BJ$21) -> 598797.5 | D12: =SUMIF(Monthly!$C$5:$BJ$5,D$11,Monthly!$C$21:$BJ$21) -> 725288.95 | E12: =SUMIF(Monthly!$C$5:$BJ$5,E$11,Monthly!$C$21:$BJ$21) -> 858830.97 | F12: =SUMIF(Monthly!$C$5:$BJ$5,F$11,Monthly!$C$21:$BJ$21) -> 942164.33
A13: Gross profit | B13: =SUMIF(Monthly!$C$5:$BJ$5,B$11,Monthly!$C$29:$BJ$29) -> 208964.51 | C13: =SUMIF(Monthly!$C$5:$BJ$5,C$11,Monthly!$C$29:$BJ$29) -> 258778.29 | D13: =SUMIF(Monthly!$C$5:$BJ$5,D$11,Monthly!$C$29:$BJ$29) -> 311392.84 | E13: =SUMIF(Monthly!$C$5:$BJ$5,E$11,Monthly!$C$29:$BJ$29) -> 366931.36 | F13: =SUMIF(Monthly!$C$5:$BJ$5,F$11,Monthly!$C$29:$BJ$29) -> 401730.62
A14: Gross margin | B14: =IF(B12=0,0,B13/B12) -> 0.43619767 | C14: =IF(C12=0,0,C13/C12) -> 0.43216328 | D14: =IF(D12=0,0,D13/D12) -> 0.42933625 | E14: =IF(E12=0,0,E13/E12) -> 0.42724514 | F14: =IF(F12=0,0,F13/F12) -> 0.42639125
A15: Operating expenses | B15: =SUMIF(Monthly!$C$5:$BJ$5,B$11,Monthly!$C$40:$BJ$40) -> -239720 | C15: =SUMIF(Monthly!$C$5:$BJ$5,C$11,Monthly!$C$40:$BJ$40) -> -242609.6 | D15: =SUMIF(Monthly!$C$5:$BJ$5,D$11,Monthly!$C$40:$BJ$40) -> -245585.89 | E15: =SUMIF(Monthly!$C$5:$BJ$5,E$11,Monthly!$C$40:$BJ$40) -> -248651.46 | F15: =SUMIF(Monthly!$C$5:$BJ$5,F$11,Monthly!$C$40:$BJ$40) -> -251809.01
A16: EBITDA | B16: =SUMIF(Monthly!$C$5:$BJ$5,B$11,Monthly!$C$41:$BJ$41) -> -30755.494 | C16: =SUMIF(Monthly!$C$5:$BJ$5,C$11,Monthly!$C$41:$BJ$41) -> 16168.694 | D16: =SUMIF(Monthly!$C$5:$BJ$5,D$11,Monthly!$C$41:$BJ$41) -> 65806.954 | E16: =SUMIF(Monthly!$C$5:$BJ$5,E$11,Monthly!$C$41:$BJ$41) -> 118279.9 | F16: =SUMIF(Monthly!$C$5:$BJ$5,F$11,Monthly!$C$41:$BJ$41) -> 149921.61
A17: EBITDA margin | B17: =IF(B12=0,0,B16/B12) -> -0.064199778 | C17: =IF(C12=0,0,C16/C12) -> 0.02700194 | D17: =IF(D12=0,0,D16/D12) -> 0.090732051 | E17: =IF(E12=0,0,E16/E12) -> 0.13772198 | F17: =IF(F12=0,0,F16/F12) -> 0.1591247
A18: Net income | B18: =SUMIF(Monthly!$C$5:$BJ$5,B$11,Monthly!$C$50:$BJ$50) -> -54084.939 | C18: =SUMIF(Monthly!$C$5:$BJ$5,C$11,Monthly!$C$50:$BJ$50) -> -6044.6391 | D18: =SUMIF(Monthly!$C$5:$BJ$5,D$11,Monthly!$C$50:$BJ$50) -> 44713.621 | E18: =SUMIF(Monthly!$C$5:$BJ$5,E$11,Monthly!$C$50:$BJ$50) -> 80899.537 | F18: =SUMIF(Monthly!$C$5:$BJ$5,F$11,Monthly!$C$50:$BJ$50) -> 103543.94
A19: Net margin | B19: =IF(B12=0,0,B18/B12) -> -0.11289824 | C19: =IF(C12=0,0,C18/C12) -> -0.01009463 | D19: =IF(D12=0,0,D18/D12) -> 0.061649389 | E19: =IF(E12=0,0,E18/E12) -> 0.094197275 | F19: =IF(F12=0,0,F18/F12) -> 0.10990009
A20: Operating cash flow | B20: =SUMIF(Monthly!$C$5:$BJ$5,B$11,Monthly!$C$74:$BJ$74) -> -34795.064 | C20: =SUMIF(Monthly!$C$5:$BJ$5,C$11,Monthly!$C$74:$BJ$74) -> 12461.322 | D20: =SUMIF(Monthly!$C$5:$BJ$5,D$11,Monthly!$C$74:$BJ$74) -> 63236.959 | E20: =SUMIF(Monthly!$C$5:$BJ$5,E$11,Monthly!$C$74:$BJ$74) -> 99441.019 | F20: =SUMIF(Monthly!$C$5:$BJ$5,F$11,Monthly!$C$74:$BJ$74) -> 121955.06
A21: Investing cash flow | B21: =SUMIF(Monthly!$C$5:$BJ$5,B$11,Monthly!$C$75:$BJ$75) -> -127400 | C21: =SUMIF(Monthly!$C$5:$BJ$5,C$11,Monthly!$C$75:$BJ$75) -> 0 | D21: =SUMIF(Monthly!$C$5:$BJ$5,D$11,Monthly!$C$75:$BJ$75) -> 0 | E21: =SUMIF(Monthly!$C$5:$BJ$5,E$11,Monthly!$C$75:$BJ$75) -> 0 | F21: =SUMIF(Monthly!$C$5:$BJ$5,F$11,Monthly!$C$75:$BJ$75) -> 0
A22: Financing cash flow | B22: =SUMIF(Monthly!$C$5:$BJ$5,B$11,Monthly!$C$77:$BJ$77) -> 207166.67 | C22: =SUMIF(Monthly!$C$5:$BJ$5,C$11,Monthly!$C$77:$BJ$77) -> -14000 | D22: =SUMIF(Monthly!$C$5:$BJ$5,D$11,Monthly!$C$77:$BJ$77) -> -14000 | E22: =SUMIF(Monthly!$C$5:$BJ$5,E$11,Monthly!$C$77:$BJ$77) -> -14000 | F22: =SUMIF(Monthly!$C$5:$BJ$5,F$11,Monthly!$C$77:$BJ$77) -> -14000
A23: Net change in cash | B23: =SUMIF(Monthly!$C$5:$BJ$5,B$11,Monthly!$C$78:$BJ$78) -> 44971.603 | C23: =SUMIF(Monthly!$C$5:$BJ$5,C$11,Monthly!$C$78:$BJ$78) -> -1538.678 | D23: =SUMIF(Monthly!$C$5:$BJ$5,D$11,Monthly!$C$78:$BJ$78) -> 49236.959 | E23: =SUMIF(Monthly!$C$5:$BJ$5,E$11,Monthly!$C$78:$BJ$78) -> 85441.019 | F23: =SUMIF(Monthly!$C$5:$BJ$5,F$11,Monthly!$C$78:$BJ$78) -> 107955.06
A24: Year-end cash | B24: =INDEX(Monthly!$C$80:$BJ$80,B$11*12) -> 44971.603 | C24: =INDEX(Monthly!$C$80:$BJ$80,C$11*12) -> 43432.925 | D24: =INDEX(Monthly!$C$80:$BJ$80,D$11*12) -> 92669.884 | E24: =INDEX(Monthly!$C$80:$BJ$80,E$11*12) -> 178110.9 | F24: =INDEX(Monthly!$C$80:$BJ$80,F$11*12) -> 286065.97
A26: Salon metrics
B27: 1 | C27: 2 | D27: 3 | E27: 4 | F27: 5
A28: Services performed | B28: =KPIs!B34 -> 6220.8 | C28: =KPIs!C34 -> 7603.2 | D28: =KPIs!D34 -> 8985.6 | E28: =KPIs!E34 -> 10368 | F28: =KPIs!F34 -> 11059.2
A29: Chair utilisation | B29: =KPIs!B33 -> 0.45 | C29: =KPIs!C33 -> 0.55 | D29: =KPIs!D33 -> 0.65 | E29: =KPIs!E33 -> 0.75 | F29: =KPIs!F33 -> 0.8
A30: Revenue per service (service revenue ÷ services) | B30: =KPIs!B37 -> 68 | C30: =KPIs!C37 -> 70.04 | D30: =KPIs!D37 -> 72.1412 | E30: =KPIs!E37 -> 74.305436 | F30: =KPIs!F37 -> 76.534599
A31: Team (FTE, year end) | B31: =INDEX(Headcount!$C$11:$BJ$11,B$27*12) -> 2.5 | C31: =INDEX(Headcount!$C$11:$BJ$11,C$27*12) -> 2.5 | D31: =INDEX(Headcount!$C$11:$BJ$11,D$27*12) -> 2.5 | E31: =INDEX(Headcount!$C$11:$BJ$11,E$27*12) -> 2.5 | F31: =INDEX(Headcount!$C$11:$BJ$11,F$27*12) -> 2.5
A33: Funding & valuation ($'000) — active scenario
A34: Equity raised | F34: =Inputs!$E$69 -> 150000
A35: Loan drawn | F35: =Inputs!$E$70 -> 70000
A36: Funding required (incl. cash buffer) | F36: ='Break-even'!B12 -> 236567.08
A37: Funding surplus / (shortfall) | F37: ='Break-even'!B17 -> -16567.075
A38: ="Lowest cash balance (month "&'Break-even'!B6&")" -> Lowest cash balance (month 24) | F38: ='Break-even'!B18 -> 43432.925
A39: First month with positive EBITDA | F39: ='Break-even'!B21 -> 13
A40: Cash invested paid back | F40: ='Break-even'!B23 -> 47
A41: Enterprise value — perpetual growth | F41: =Valuation!B27 -> 176447.85
A42: Enterprise value — exit multiple | F42: =Valuation!C27 -> 194979.25
A43: Enterprise value — average | F43: =Valuation!B30 -> 185713.55

Sheet Summary
A1: Financial statements summary | U1: =HYPERLINK("#'Cover'!A1","◂ Contents") -> ◂ Contents
A2: Hair salon financial model (planning) | P2: Select detailed year: | R2: 1
A5: Income statement ($'000) — by year | H5: ="Income statement ($'000) — Year "&$R$2&", by month" -> Income statement ($'000) — Year 1, by month
B6: 1 | C6: 2 | D6: 3 | E6: 4 | F6: 5 | H6: =INDEX(Monthly!$C$4:$BJ$4,($R$2-1)*12+1) -> 1 | I6: =INDEX(Monthly!$C$4:$BJ$4,($R$2-1)*12+2) -> 2 | J6: =INDEX(Monthly!$C$4:$BJ$4,($R$2-1)*12+3) -> 3 | K6: =INDEX(Monthly!$C$4:$BJ$4,($R$2-1)*12+4) -> 4 | L6: =INDEX(Monthly!$C$4:$BJ$4,($R$2-1)*12+5) -> 5 | M6: =INDEX(Monthly!$C$4:$BJ$4,($R$2-1)*12+6) -> 6 | N6: =INDEX(Monthly!$C$4:$BJ$4,($R$2-1)*12+7) -> 7 | O6: =INDEX(Monthly!$C$4:$BJ$4,($R$2-1)*12+8) -> 8 | P6: =INDEX(Monthly!$C$4:$BJ$4,($R$2-1)*12+9) -> 9 | Q6: =INDEX(Monthly!$C$4:$BJ$4,($R$2-1)*12+10) -> 10 | R6: =INDEX(Monthly!$C$4:$BJ$4,($R$2-1)*12+11) -> 11 | S6: =INDEX(Monthly!$C$4:$BJ$4,($R$2-1)*12+12) -> 12
A7: Revenue | B7: ='P&L'!B5 -> 479059.2 | C7: ='P&L'!C5 -> 598797.5 | D7: ='P&L'!D5 -> 725288.95 | E7: ='P&L'!E5 -> 858830.97 | F7: ='P&L'!F5 -> 942164.33 | H7: =INDEX(Monthly!$C$21:$BJ$21,($R$2-1)*12+1) -> 39921.6 | I7: =INDEX(Monthly!$C$21:$BJ$21,($R$2-1)*12+2) -> 39921.6 | J7: =INDEX(Monthly!$C$21:$BJ$21,($R$2-1)*12+3) -> 39921.6 | K7: =INDEX(Monthly!$C$21:$BJ$21,($R$2-1)*12+4) -> 39921.6 | L7: =INDEX(Monthly!$C$21:$BJ$21,($R$2-1)*12+5) -> 39921.6 | M7: =INDEX(Monthly!$C$21:$BJ$21,($R$2-1)*12+6) -> 39921.6 | N7: =INDEX(Monthly!$C$21:$BJ$21,($R$2-1)*12+7) -> 39921.6 | O7: =INDEX(Monthly!$C$21:$BJ$21,($R$2-1)*12+8) -> 39921.6 | P7: =INDEX(Monthly!$C$21:$BJ$21,($R$2-1)*12+9) -> 39921.6 | Q7: =INDEX(Monthly!$C$21:$BJ$21,($R$2-1)*12+10) -> 39921.6 | R7: =INDEX(Monthly!$C$21:$BJ$21,($R$2-1)*12+11) -> 39921.6 | S7: =INDEX(Monthly!$C$21:$BJ$21,($R$2-1)*12+12) -> 39921.6
A8: Cost of sales | B8: ='P&L'!B6 -> -270094.69 | C8: ='P&L'!C6 -> -340019.21 | D8: ='P&L'!D6 -> -413896.11 | E8: ='P&L'!E6 -> -491899.61 | F8: ='P&L'!F6 -> -540433.7 | H8: =INDEX(Monthly!$C$28:$BJ$28,($R$2-1)*12+1) -> -22507.891 | I8: =INDEX(Monthly!$C$28:$BJ$28,($R$2-1)*12+2) -> -22507.891 | J8: =INDEX(Monthly!$C$28:$BJ$28,($R$2-1)*12+3) -> -22507.891 | K8: =INDEX(Monthly!$C$28:$BJ$28,($R$2-1)*12+4) -> -22507.891 | L8: =INDEX(Monthly!$C$28:$BJ$28,($R$2-1)*12+5) -> -22507.891 | M8: =INDEX(Monthly!$C$28:$BJ$28,($R$2-1)*12+6) -> -22507.891 | N8: =INDEX(Monthly!$C$28:$BJ$28,($R$2-1)*12+7) -> -22507.891 | O8: =INDEX(Monthly!$C$28:$BJ$28,($R$2-1)*12+8) -> -22507.891 | P8: =INDEX(Monthly!$C$28:$BJ$28,($R$2-1)*12+9) -> -22507.891 | Q8: =INDEX(Monthly!$C$28:$BJ$28,($R$2-1)*12+10) -> -22507.891 | R8: =INDEX(Monthly!$C$28:$BJ$28,($R$2-1)*12+11) -> -22507.891 | S8: =INDEX(Monthly!$C$28:$BJ$28,($R$2-1)*12+12) -> -22507.891
A9: Gross profit | B9: ='P&L'!B7 -> 208964.51 | C9: ='P&L'!C7 -> 258778.29 | D9: ='P&L'!D7 -> 311392.84 | E9: ='P&L'!E7 -> 366931.36 | F9: ='P&L'!F7 -> 401730.62 | H9: =INDEX(Monthly!$C$29:$BJ$29,($R$2-1)*12+1) -> 17413.709 | I9: =INDEX(Monthly!$C$29:$BJ$29,($R$2-1)*12+2) -> 17413.709 | J9: =INDEX(Monthly!$C$29:$BJ$29,($R$2-1)*12+3) -> 17413.709 | K9: =INDEX(Monthly!$C$29:$BJ$29,($R$2-1)*12+4) -> 17413.709 | L9: =INDEX(Monthly!$C$29:$BJ$29,($R$2-1)*12+5) -> 17413.709 | M9: =INDEX(Monthly!$C$29:$BJ$29,($R$2-1)*12+6) -> 17413.709 | N9: =INDEX(Monthly!$C$29:$BJ$29,($R$2-1)*12+7) -> 17413.709 | O9: =INDEX(Monthly!$C$29:$BJ$29,($R$2-1)*12+8) -> 17413.709 | P9: =INDEX(Monthly!$C$29:$BJ$29,($R$2-1)*12+9) -> 17413.709 | Q9: =INDEX(Monthly!$C$29:$BJ$29,($R$2-1)*12+10) -> 17413.709 | R9: =INDEX(Monthly!$C$29:$BJ$29,($R$2-1)*12+11) -> 17413.709 | S9: =INDEX(Monthly!$C$29:$BJ$29,($R$2-1)*12+12) -> 17413.709
A10: Gross margin | B10: ='P&L'!B8 -> 0.43619767 | C10: ='P&L'!C8 -> 0.43216328 | D10: ='P&L'!D8 -> 0.42933625 | E10: ='P&L'!E8 -> 0.42724514 | F10: ='P&L'!F8 -> 0.42639125 | H10: =IF(H7=0,0,H9/H7) -> 0.43619767 | I10: =IF(I7=0,0,I9/I7) -> 0.43619767 | J10: =IF(J7=0,0,J9/J7) -> 0.43619767 | K10: =IF(K7=0,0,K9/K7) -> 0.43619767 | L10: =IF(L7=0,0,L9/L7) -> 0.43619767 | M10: =IF(M7=0,0,M9/M7) -> 0.43619767 | N10: =IF(N7=0,0,N9/N7) -> 0.43619767 | O10: =IF(O7=0,0,O9/O7) -> 0.43619767 | ... S10: =IF(S7=0,0,S9/S7) -> 0.43619767
A11: Total operating expenses | B11: ='P&L'!B17 -> -239720 | C11: ='P&L'!C17 -> -242609.6 | D11: ='P&L'!D17 -> -245585.89 | E11: ='P&L'!E17 -> -248651.46 | F11: ='P&L'!F17 -> -251809.01 | H11: =INDEX(Monthly!$C$40:$BJ$40,($R$2-1)*12+1) -> -19976.667 | I11: =INDEX(Monthly!$C$40:$BJ$40,($R$2-1)*12+2) -> -19976.667 | J11: =INDEX(Monthly!$C$40:$BJ$40,($R$2-1)*12+3) -> -19976.667 | K11: =INDEX(Monthly!$C$40:$BJ$40,($R$2-1)*12+4) -> -19976.667 | L11: =INDEX(Monthly!$C$40:$BJ$40,($R$2-1)*12+5) -> -19976.667 | M11: =INDEX(Monthly!$C$40:$BJ$40,($R$2-1)*12+6) -> -19976.667 | N11: =INDEX(Monthly!$C$40:$BJ$40,($R$2-1)*12+7) -> -19976.667 | O11: =INDEX(Monthly!$C$40:$BJ$40,($R$2-1)*12+8) -> -19976.667 | P11: =INDEX(Monthly!$C$40:$BJ$40,($R$2-1)*12+9) -> -19976.667 | Q11: =INDEX(Monthly!$C$40:$BJ$40,($R$2-1)*12+10) -> -19976.667 | R11: =INDEX(Monthly!$C$40:$BJ$40,($R$2-1)*12+11) -> -19976.667 | S11: =INDEX(Monthly!$C$40:$BJ$40,($R$2-1)*12+12) -> -19976.667
A12: EBITDA | B12: ='P&L'!B18 -> -30755.494 | C12: ='P&L'!C18 -> 16168.694 | D12: ='P&L'!D18 -> 65806.954 | E12: ='P&L'!E18 -> 118279.9 | F12: ='P&L'!F18 -> 149921.61 | H12: =INDEX(Monthly!$C$41:$BJ$41,($R$2-1)*12+1) -> -2562.9579 | I12: =INDEX(Monthly!$C$41:$BJ$41,($R$2-1)*12+2) -> -2562.9579 | J12: =INDEX(Monthly!$C$41:$BJ$41,($R$2-1)*12+3) -> -2562.9579 | K12: =INDEX(Monthly!$C$41:$BJ$41,($R$2-1)*12+4) -> -2562.9579 | L12: =INDEX(Monthly!$C$41:$BJ$41,($R$2-1)*12+5) -> -2562.9579 | M12: =INDEX(Monthly!$C$41:$BJ$41,($R$2-1)*12+6) -> -2562.9579 | N12: =INDEX(Monthly!$C$41:$BJ$41,($R$2-1)*12+7) -> -2562.9579 | O12: =INDEX(Monthly!$C$41:$BJ$41,($R$2-1)*12+8) -> -2562.9579 | P12: =INDEX(Monthly!$C$41:$BJ$41,($R$2-1)*12+9) -> -2562.9579 | Q12: =INDEX(Monthly!$C$41:$BJ$41,($R$2-1)*12+10) -> -2562.9579 | R12: =INDEX(Monthly!$C$41:$BJ$41,($R$2-1)*12+11) -> -2562.9579 | S12: =INDEX(Monthly!$C$41:$BJ$41,($R$2-1)*12+12) -> -2562.9579
A13: EBITDA margin | B13: ='P&L'!B19 -> -0.064199778 | C13: ='P&L'!C19 -> 0.02700194 | D13: ='P&L'!D19 -> 0.090732051 | E13: ='P&L'!E19 -> 0.13772198 | F13: ='P&L'!F19 -> 0.1591247 | H13: =IF(H7=0,0,H12/H7) -> -0.064199778 | I13: =IF(I7=0,0,I12/I7) -> -0.064199778 | J13: =IF(J7=0,0,J12/J7) -> -0.064199778 | K13: =IF(K7=0,0,K12/K7) -> -0.064199778 | L13: =IF(L7=0,0,L12/L7) -> -0.064199778 | M13: =IF(M7=0,0,M12/M7) -> -0.064199778 | N13: =IF(N7=0,0,N12/N7) -> -0.064199778 | O13: =IF(O7=0,0,O12/O7) -> -0.064199778 | ... S13: =IF(S7=0,0,S12/S7) -> -0.064199778
A14: Depreciation | B14: ='P&L'!B20 -> -18200 | C14: ='P&L'!C20 -> -18200 | D14: ='P&L'!D20 -> -18200 | E14: ='P&L'!E20 -> -18200 | F14: ='P&L'!F20 -> -18200 | H14: =INDEX(Monthly!$C$55:$BJ$55,($R$2-1)*12+1) -> -1516.6667 | I14: =INDEX(Monthly!$C$55:$BJ$55,($R$2-1)*12+2) -> -1516.6667 | J14: =INDEX(Monthly!$C$55:$BJ$55,($R$2-1)*12+3) -> -1516.6667 | K14: =INDEX(Monthly!$C$55:$BJ$55,($R$2-1)*12+4) -> -1516.6667 | L14: =INDEX(Monthly!$C$55:$BJ$55,($R$2-1)*12+5) -> -1516.6667 | M14: =INDEX(Monthly!$C$55:$BJ$55,($R$2-1)*12+6) -> -1516.6667 | N14: =INDEX(Monthly!$C$55:$BJ$55,($R$2-1)*12+7) -> -1516.6667 | O14: =INDEX(Monthly!$C$55:$BJ$55,($R$2-1)*12+8) -> -1516.6667 | P14: =INDEX(Monthly!$C$55:$BJ$55,($R$2-1)*12+9) -> -1516.6667 | Q14: =INDEX(Monthly!$C$55:$BJ$55,($R$2-1)*12+10) -> -1516.6667 | R14: =INDEX(Monthly!$C$55:$BJ$55,($R$2-1)*12+11) -> -1516.6667 | S14: =INDEX(Monthly!$C$55:$BJ$55,($R$2-1)*12+12) -> -1516.6667
A15: EBIT | B15: ='P&L'!B21 -> -48955.494 | C15: ='P&L'!C21 -> -2031.3057 | D15: ='P&L'!D21 -> 47606.954 | E15: ='P&L'!E21 -> 100079.9 | F15: ='P&L'!F21 -> 131721.61 | H15: =INDEX(Monthly!$C$44:$BJ$44,($R$2-1)*12+1) -> -4079.6245 | I15: =INDEX(Monthly!$C$44:$BJ$44,($R$2-1)*12+2) -> -4079.6245 | J15: =INDEX(Monthly!$C$44:$BJ$44,($R$2-1)*12+3) -> -4079.6245 | K15: =INDEX(Monthly!$C$44:$BJ$44,($R$2-1)*12+4) -> -4079.6245 | L15: =INDEX(Monthly!$C$44:$BJ$44,($R$2-1)*12+5) -> -4079.6245 | M15: =INDEX(Monthly!$C$44:$BJ$44,($R$2-1)*12+6) -> -4079.6245 | N15: =INDEX(Monthly!$C$44:$BJ$44,($R$2-1)*12+7) -> -4079.6245 | O15: =INDEX(Monthly!$C$44:$BJ$44,($R$2-1)*12+8) -> -4079.6245 | P15: =INDEX(Monthly!$C$44:$BJ$44,($R$2-1)*12+9) -> -4079.6245 | Q15: =INDEX(Monthly!$C$44:$BJ$44,($R$2-1)*12+10) -> -4079.6245 | R15: =INDEX(Monthly!$C$44:$BJ$44,($R$2-1)*12+11) -> -4079.6245 | S15: =INDEX(Monthly!$C$44:$BJ$44,($R$2-1)*12+12) -> -4079.6245
A16: Interest | B16: ='P&L'!B22 -> -5129.4444 | C16: ='P&L'!C22 -> -4013.3333 | D16: ='P&L'!D22 -> -2893.3333 | E16: ='P&L'!E22 -> -1773.3333 | F16: ='P&L'!F22 -> -653.33333 | H16: =INDEX(Monthly!$C$45:$BJ$45,($R$2-1)*12+1) -> -466.66667 | I16: =INDEX(Monthly!$C$45:$BJ$45,($R$2-1)*12+2) -> -462.77778 | J16: =INDEX(Monthly!$C$45:$BJ$45,($R$2-1)*12+3) -> -455 | K16: =INDEX(Monthly!$C$45:$BJ$45,($R$2-1)*12+4) -> -447.22222 | L16: =INDEX(Monthly!$C$45:$BJ$45,($R$2-1)*12+5) -> -439.44444 | M16: =INDEX(Monthly!$C$45:$BJ$45,($R$2-1)*12+6) -> -431.66667 | N16: =INDEX(Monthly!$C$45:$BJ$45,($R$2-1)*12+7) -> -423.88889 | O16: =INDEX(Monthly!$C$45:$BJ$45,($R$2-1)*12+8) -> -416.11111 | P16: =INDEX(Monthly!$C$45:$BJ$45,($R$2-1)*12+9) -> -408.33333 | Q16: =INDEX(Monthly!$C$45:$BJ$45,($R$2-1)*12+10) -> -400.55556 | R16: =INDEX(Monthly!$C$45:$BJ$45,($R$2-1)*12+11) -> -392.77778 | S16: =INDEX(Monthly!$C$45:$BJ$45,($R$2-1)*12+12) -> -385
A17: Pre-tax income | B17: ='P&L'!B23 -> -54084.939 | C17: ='P&L'!C23 -> -6044.6391 | D17: ='P&L'!D23 -> 44713.621 | E17: ='P&L'!E23 -> 98306.565 | F17: ='P&L'!F23 -> 131068.28 | H17: =INDEX(Monthly!$C$46:$BJ$46,($R$2-1)*12+1) -> -4546.2912 | I17: =INDEX(Monthly!$C$46:$BJ$46,($R$2-1)*12+2) -> -4542.4023 | J17: =INDEX(Monthly!$C$46:$BJ$46,($R$2-1)*12+3) -> -4534.6245 | K17: =INDEX(Monthly!$C$46:$BJ$46,($R$2-1)*12+4) -> -4526.8468 | L17: =INDEX(Monthly!$C$46:$BJ$46,($R$2-1)*12+5) -> -4519.069 | M17: =INDEX(Monthly!$C$46:$BJ$46,($R$2-1)*12+6) -> -4511.2912 | N17: =INDEX(Monthly!$C$46:$BJ$46,($R$2-1)*12+7) -> -4503.5134 | O17: =INDEX(Monthly!$C$46:$BJ$46,($R$2-1)*12+8) -> -4495.7356 | P17: =INDEX(Monthly!$C$46:$BJ$46,($R$2-1)*12+9) -> -4487.9579 | Q17: =INDEX(Monthly!$C$46:$BJ$46,($R$2-1)*12+10) -> -4480.1801 | R17: =INDEX(Monthly!$C$46:$BJ$46,($R$2-1)*12+11) -> -4472.4023 | S17: =INDEX(Monthly!$C$46:$BJ$46,($R$2-1)*12+12) -> -4464.6245
A18: Income tax | B18: ='P&L'!B24 -> 0 | C18: ='P&L'!C24 -> 0 | D18: ='P&L'!D24 -> 0 | E18: ='P&L'!E24 -> -17407.028 | F18: ='P&L'!F24 -> -27524.339 | H18: =INDEX(Monthly!$C$49:$BJ$49,($R$2-1)*12+1) -> 0 | I18: =INDEX(Monthly!$C$49:$BJ$49,($R$2-1)*12+2) -> 0 | J18: =INDEX(Monthly!$C$49:$BJ$49,($R$2-1)*12+3) -> 0 | K18: =INDEX(Monthly!$C$49:$BJ$49,($R$2-1)*12+4) -> 0 | L18: =INDEX(Monthly!$C$49:$BJ$49,($R$2-1)*12+5) -> 0 | M18: =INDEX(Monthly!$C$49:$BJ$49,($R$2-1)*12+6) -> 0 | N18: =INDEX(Monthly!$C$49:$BJ$49,($R$2-1)*12+7) -> 0 | O18: =INDEX(Monthly!$C$49:$BJ$49,($R$2-1)*12+8) -> 0 | P18: =INDEX(Monthly!$C$49:$BJ$49,($R$2-1)*12+9) -> 0 | Q18: =INDEX(Monthly!$C$49:$BJ$49,($R$2-1)*12+10) -> 0 | R18: =INDEX(Monthly!$C$49:$BJ$49,($R$2-1)*12+11) -> 0 | S18: =INDEX(Monthly!$C$49:$BJ$49,($R$2-1)*12+12) -> 0
A19: Net income | B19: ='P&L'!B25 -> -54084.939 | C19: ='P&L'!C25 -> -6044.6391 | D19: ='P&L'!D25 -> 44713.621 | E19: ='P&L'!E25 -> 80899.537 | F19: ='P&L'!F25 -> 103543.94 | H19: =INDEX(Monthly!$C$50:$BJ$50,($R$2-1)*12+1) -> -4546.2912 | I19: =INDEX(Monthly!$C$50:$BJ$50,($R$2-1)*12+2) -> -4542.4023 | J19: =INDEX(Monthly!$C$50:$BJ$50,($R$2-1)*12+3) -> -4534.6245 | K19: =INDEX(Monthly!$C$50:$BJ$50,($R$2-1)*12+4) -> -4526.8468 | L19: =INDEX(Monthly!$C$50:$BJ$50,($R$2-1)*12+5) -> -4519.069 | M19: =INDEX(Monthly!$C$50:$BJ$50,($R$2-1)*12+6) -> -4511.2912 | N19: =INDEX(Monthly!$C$50:$BJ$50,($R$2-1)*12+7) -> -4503.5134 | O19: =INDEX(Monthly!$C$50:$BJ$50,($R$2-1)*12+8) -> -4495.7356 | P19: =INDEX(Monthly!$C$50:$BJ$50,($R$2-1)*12+9) -> -4487.9579 | Q19: =INDEX(Monthly!$C$50:$BJ$50,($R$2-1)*12+10) -> -4480.1801 | R19: =INDEX(Monthly!$C$50:$BJ$50,($R$2-1)*12+11) -> -4472.4023 | S19: =INDEX(Monthly!$C$50:$BJ$50,($R$2-1)*12+12) -> -4464.6245
A20: Net margin | B20: ='P&L'!B26 -> -0.11289824 | C20: ='P&L'!C26 -> -0.01009463 | D20: ='P&L'!D26 -> 0.061649389 | E20: ='P&L'!E26 -> 0.094197275 | F20: ='P&L'!F26 -> 0.10990009 | H20: =IF(H7=0,0,H19/H7) -> -0.11388049 | I20: =IF(I7=0,0,I19/I7) -> -0.11378307 | J20: =IF(J7=0,0,J19/J7) -> -0.11358825 | K20: =IF(K7=0,0,K19/K7) -> -0.11339342 | L20: =IF(L7=0,0,L19/L7) -> -0.11319859 | M20: =IF(M7=0,0,M19/M7) -> -0.11300377 | N20: =IF(N7=0,0,N19/N7) -> -0.11280894 | O20: =IF(O7=0,0,O19/O7) -> -0.11261411 | ... S20: =IF(S7=0,0,S19/S7) -> -0.11183481
A22: Cash flow ($'000) — by year | H22: ="Cash flow ($'000) — Year "&$R$2&", by month" -> Cash flow ($'000) — Year 1, by month
B23: 1 | C23: 2 | D23: 3 | E23: 4 | F23: 5 | H23: =INDEX(Monthly!$C$4:$BJ$4,($R$2-1)*12+1) -> 1 | I23: =INDEX(Monthly!$C$4:$BJ$4,($R$2-1)*12+2) -> 2 | J23: =INDEX(Monthly!$C$4:$BJ$4,($R$2-1)*12+3) -> 3 | K23: =INDEX(Monthly!$C$4:$BJ$4,($R$2-1)*12+4) -> 4 | L23: =INDEX(Monthly!$C$4:$BJ$4,($R$2-1)*12+5) -> 5 | M23: =INDEX(Monthly!$C$4:$BJ$4,($R$2-1)*12+6) -> 6 | N23: =INDEX(Monthly!$C$4:$BJ$4,($R$2-1)*12+7) -> 7 | O23: =INDEX(Monthly!$C$4:$BJ$4,($R$2-1)*12+8) -> 8 | P23: =INDEX(Monthly!$C$4:$BJ$4,($R$2-1)*12+9) -> 9 | Q23: =INDEX(Monthly!$C$4:$BJ$4,($R$2-1)*12+10) -> 10 | R23: =INDEX(Monthly!$C$4:$BJ$4,($R$2-1)*12+11) -> 11 | S23: =INDEX(Monthly!$C$4:$BJ$4,($R$2-1)*12+12) -> 12
A24: Operating cash flow | B24: ='Cash Flow'!B10 -> -34795.064 | C24: ='Cash Flow'!C10 -> 12461.322 | D24: ='Cash Flow'!D10 -> 63236.959 | E24: ='Cash Flow'!E10 -> 99441.019 | F24: ='Cash Flow'!F10 -> 121955.06 | H24: =INDEX(Monthly!$C$74:$BJ$74,($R$2-1)*12+1) -> -1939.7493 | I24: =INDEX(Monthly!$C$74:$BJ$74,($R$2-1)*12+2) -> -3025.7356 | J24: =INDEX(Monthly!$C$74:$BJ$74,($R$2-1)*12+3) -> -3017.9579 | K24: =INDEX(Monthly!$C$74:$BJ$74,($R$2-1)*12+4) -> -3010.1801 | L24: =INDEX(Monthly!$C$74:$BJ$74,($R$2-1)*12+5) -> -3002.4023 | M24: =INDEX(Monthly!$C$74:$BJ$74,($R$2-1)*12+6) -> -2994.6245 | N24: =INDEX(Monthly!$C$74:$BJ$74,($R$2-1)*12+7) -> -2986.8468 | O24: =INDEX(Monthly!$C$74:$BJ$74,($R$2-1)*12+8) -> -2979.069 | P24: =INDEX(Monthly!$C$74:$BJ$74,($R$2-1)*12+9) -> -2971.2912 | Q24: =INDEX(Monthly!$C$74:$BJ$74,($R$2-1)*12+10) -> -2963.5134 | R24: =INDEX(Monthly!$C$74:$BJ$74,($R$2-1)*12+11) -> -2955.7356 | S24: =INDEX(Monthly!$C$74:$BJ$74,($R$2-1)*12+12) -> -2947.9579
A25: Capital spending | B25: ='Cash Flow'!B11 -> -127400 | C25: ='Cash Flow'!C11 -> 0 | D25: ='Cash Flow'!D11 -> 0 | E25: ='Cash Flow'!E11 -> 0 | F25: ='Cash Flow'!F11 -> 0 | H25: =INDEX(Monthly!$C$75:$BJ$75,($R$2-1)*12+1) -> -127400 | I25: =INDEX(Monthly!$C$75:$BJ$75,($R$2-1)*12+2) -> 0 | J25: =INDEX(Monthly!$C$75:$BJ$75,($R$2-1)*12+3) -> 0 | K25: =INDEX(Monthly!$C$75:$BJ$75,($R$2-1)*12+4) -> 0 | L25: =INDEX(Monthly!$C$75:$BJ$75,($R$2-1)*12+5) -> 0 | M25: =INDEX(Monthly!$C$75:$BJ$75,($R$2-1)*12+6) -> 0 | N25: =INDEX(Monthly!$C$75:$BJ$75,($R$2-1)*12+7) -> 0 | O25: =INDEX(Monthly!$C$75:$BJ$75,($R$2-1)*12+8) -> 0 | P25: =INDEX(Monthly!$C$75:$BJ$75,($R$2-1)*12+9) -> 0 | Q25: =INDEX(Monthly!$C$75:$BJ$75,($R$2-1)*12+10) -> 0 | R25: =INDEX(Monthly!$C$75:$BJ$75,($R$2-1)*12+11) -> 0 | S25: =INDEX(Monthly!$C$75:$BJ$75,($R$2-1)*12+12) -> 0
A26: Equity raised | B26: ='Cash Flow'!B12 -> 150000 | C26: ='Cash Flow'!C12 -> 0 | D26: ='Cash Flow'!D12 -> 0 | E26: ='Cash Flow'!E12 -> 0 | F26: ='Cash Flow'!F12 -> 0 | H26: =INDEX(Monthly!$C$76:$BJ$76,($R$2-1)*12+1) -> 150000 | I26: =INDEX(Monthly!$C$76:$BJ$76,($R$2-1)*12+2) -> 0 | J26: =INDEX(Monthly!$C$76:$BJ$76,($R$2-1)*12+3) -> 0 | K26: =INDEX(Monthly!$C$76:$BJ$76,($R$2-1)*12+4) -> 0 | L26: =INDEX(Monthly!$C$76:$BJ$76,($R$2-1)*12+5) -> 0 | M26: =INDEX(Monthly!$C$76:$BJ$76,($R$2-1)*12+6) -> 0 | N26: =INDEX(Monthly!$C$76:$BJ$76,($R$2-1)*12+7) -> 0 | O26: =INDEX(Monthly!$C$76:$BJ$76,($R$2-1)*12+8) -> 0 | P26: =INDEX(Monthly!$C$76:$BJ$76,($R$2-1)*12+9) -> 0 | Q26: =INDEX(Monthly!$C$76:$BJ$76,($R$2-1)*12+10) -> 0 | R26: =INDEX(Monthly!$C$76:$BJ$76,($R$2-1)*12+11) -> 0 | S26: =INDEX(Monthly!$C$76:$BJ$76,($R$2-1)*12+12) -> 0
A27: Loan drawdown | B27: ='Cash Flow'!B13 -> 70000 | C27: ='Cash Flow'!C13 -> 0 | D27: ='Cash Flow'!D13 -> 0 | E27: ='Cash Flow'!E13 -> 0 | F27: ='Cash Flow'!F13 -> 0 | H27: =INDEX(Monthly!$C$61:$BJ$61,($R$2-1)*12+1) -> 70000 | I27: =INDEX(Monthly!$C$61:$BJ$61,($R$2-1)*12+2) -> 0 | J27: =INDEX(Monthly!$C$61:$BJ$61,($R$2-1)*12+3) -> 0 | K27: =INDEX(Monthly!$C$61:$BJ$61,($R$2-1)*12+4) -> 0 | L27: =INDEX(Monthly!$C$61:$BJ$61,($R$2-1)*12+5) -> 0 | M27: =INDEX(Monthly!$C$61:$BJ$61,($R$2-1)*12+6) -> 0 | N27: =INDEX(Monthly!$C$61:$BJ$61,($R$2-1)*12+7) -> 0 | O27: =INDEX(Monthly!$C$61:$BJ$61,($R$2-1)*12+8) -> 0 | P27: =INDEX(Monthly!$C$61:$BJ$61,($R$2-1)*12+9) -> 0 | Q27: =INDEX(Monthly!$C$61:$BJ$61,($R$2-1)*12+10) -> 0 | R27: =INDEX(Monthly!$C$61:$BJ$61,($R$2-1)*12+11) -> 0 | S27: =INDEX(Monthly!$C$61:$BJ$61,($R$2-1)*12+12) -> 0
A28: Loan repayment | B28: ='Cash Flow'!B14 -> -12833.333 | C28: ='Cash Flow'!C14 -> -14000 | D28: ='Cash Flow'!D14 -> -14000 | E28: ='Cash Flow'!E14 -> -14000 | F28: ='Cash Flow'!F14 -> -14000 | H28: =INDEX(Monthly!$C$62:$BJ$62,($R$2-1)*12+1) -> 0 | I28: =INDEX(Monthly!$C$62:$BJ$62,($R$2-1)*12+2) -> -1166.6667 | J28: =INDEX(Monthly!$C$62:$BJ$62,($R$2-1)*12+3) -> -1166.6667 | K28: =INDEX(Monthly!$C$62:$BJ$62,($R$2-1)*12+4) -> -1166.6667 | L28: =INDEX(Monthly!$C$62:$BJ$62,($R$2-1)*12+5) -> -1166.6667 | M28: =INDEX(Monthly!$C$62:$BJ$62,($R$2-1)*12+6) -> -1166.6667 | N28: =INDEX(Monthly!$C$62:$BJ$62,($R$2-1)*12+7) -> -1166.6667 | O28: =INDEX(Monthly!$C$62:$BJ$62,($R$2-1)*12+8) -> -1166.6667 | P28: =INDEX(Monthly!$C$62:$BJ$62,($R$2-1)*12+9) -> -1166.6667 | Q28: =INDEX(Monthly!$C$62:$BJ$62,($R$2-1)*12+10) -> -1166.6667 | R28: =INDEX(Monthly!$C$62:$BJ$62,($R$2-1)*12+11) -> -1166.6667 | S28: =INDEX(Monthly!$C$62:$BJ$62,($R$2-1)*12+12) -> -1166.6667
A29: Financing cash flow | B29: ='Cash Flow'!B15 -> 207166.67 | C29: ='Cash Flow'!C15 -> -14000 | D29: ='Cash Flow'!D15 -> -14000 | E29: ='Cash Flow'!E15 -> -14000 | F29: ='Cash Flow'!F15 -> -14000 | H29: =INDEX(Monthly!$C$77:$BJ$77,($R$2-1)*12+1) -> 220000 | I29: =INDEX(Monthly!$C$77:$BJ$77,($R$2-1)*12+2) -> -1166.6667 | J29: =INDEX(Monthly!$C$77:$BJ$77,($R$2-1)*12+3) -> -1166.6667 | K29: =INDEX(Monthly!$C$77:$BJ$77,($R$2-1)*12+4) -> -1166.6667 | L29: =INDEX(Monthly!$C$77:$BJ$77,($R$2-1)*12+5) -> -1166.6667 | M29: =INDEX(Monthly!$C$77:$BJ$77,($R$2-1)*12+6) -> -1166.6667 | N29: =INDEX(Monthly!$C$77:$BJ$77,($R$2-1)*12+7) -> -1166.6667 | O29: =INDEX(Monthly!$C$77:$BJ$77,($R$2-1)*12+8) -> -1166.6667 | P29: =INDEX(Monthly!$C$77:$BJ$77,($R$2-1)*12+9) -> -1166.6667 | Q29: =INDEX(Monthly!$C$77:$BJ$77,($R$2-1)*12+10) -> -1166.6667 | R29: =INDEX(Monthly!$C$77:$BJ$77,($R$2-1)*12+11) -> -1166.6667 | S29: =INDEX(Monthly!$C$77:$BJ$77,($R$2-1)*12+12) -> -1166.6667
A30: Net change in cash | B30: ='Cash Flow'!B16 -> 44971.603 | C30: ='Cash Flow'!C16 -> -1538.678 | D30: ='Cash Flow'!D16 -> 49236.959 | E30: ='Cash Flow'!E16 -> 85441.019 | F30: ='Cash Flow'!F16 -> 107955.06 | H30: =INDEX(Monthly!$C$78:$BJ$78,($R$2-1)*12+1) -> 90660.251 | I30: =INDEX(Monthly!$C$78:$BJ$78,($R$2-1)*12+2) -> -4192.4023 | J30: =INDEX(Monthly!$C$78:$BJ$78,($R$2-1)*12+3) -> -4184.6245 | K30: =INDEX(Monthly!$C$78:$BJ$78,($R$2-1)*12+4) -> -4176.8468 | L30: =INDEX(Monthly!$C$78:$BJ$78,($R$2-1)*12+5) -> -4169.069 | M30: =INDEX(Monthly!$C$78:$BJ$78,($R$2-1)*12+6) -> -4161.2912 | N30: =INDEX(Monthly!$C$78:$BJ$78,($R$2-1)*12+7) -> -4153.5134 | O30: =INDEX(Monthly!$C$78:$BJ$78,($R$2-1)*12+8) -> -4145.7356 | P30: =INDEX(Monthly!$C$78:$BJ$78,($R$2-1)*12+9) -> -4137.9579 | Q30: =INDEX(Monthly!$C$78:$BJ$78,($R$2-1)*12+10) -> -4130.1801 | R30: =INDEX(Monthly!$C$78:$BJ$78,($R$2-1)*12+11) -> -4122.4023 | S30: =INDEX(Monthly!$C$78:$BJ$78,($R$2-1)*12+12) -> -4114.6245
A31: Closing cash | B31: ='Cash Flow'!B18 -> 44971.603 | C31: ='Cash Flow'!C18 -> 43432.925 | D31: ='Cash Flow'!D18 -> 92669.884 | E31: ='Cash Flow'!E18 -> 178110.9 | F31: ='Cash Flow'!F18 -> 286065.97 | H31: =INDEX(Monthly!$C$80:$BJ$80,($R$2-1)*12+1) -> 90660.251 | I31: =INDEX(Monthly!$C$80:$BJ$80,($R$2-1)*12+2) -> 86467.848 | J31: =INDEX(Monthly!$C$80:$BJ$80,($R$2-1)*12+3) -> 82283.224 | K31: =INDEX(Monthly!$C$80:$BJ$80,($R$2-1)*12+4) -> 78106.377 | L31: =INDEX(Monthly!$C$80:$BJ$80,($R$2-1)*12+5) -> 73937.308 | M31: =INDEX(Monthly!$C$80:$BJ$80,($R$2-1)*12+6) -> 69776.017 | N31: =INDEX(Monthly!$C$80:$BJ$80,($R$2-1)*12+7) -> 65622.503 | O31: =INDEX(Monthly!$C$80:$BJ$80,($R$2-1)*12+8) -> 61476.768 | P31: =INDEX(Monthly!$C$80:$BJ$80,($R$2-1)*12+9) -> 57338.81 | Q31: =INDEX(Monthly!$C$80:$BJ$80,($R$2-1)*12+10) -> 53208.63 | R31: =INDEX(Monthly!$C$80:$BJ$80,($R$2-1)*12+11) -> 49086.228 | S31: =INDEX(Monthly!$C$80:$BJ$80,($R$2-1)*12+12) -> 44971.603
A39: Balance sheet at year end ($'000) | H39: ="Balance sheet at month end ($'000) — Year "&$R$2 -> Balance sheet at month end ($'000) — Year 1
B40: 1 | C40: 2 | D40: 3 | E40: 4 | F40: 5 | H40: =INDEX(Monthly!$C$4:$BJ$4,($R$2-1)*12+1) -> 1 | I40: =INDEX(Monthly!$C$4:$BJ$4,($R$2-1)*12+2) -> 2 | J40: =INDEX(Monthly!$C$4:$BJ$4,($R$2-1)*12+3) -> 3 | K40: =INDEX(Monthly!$C$4:$BJ$4,($R$2-1)*12+4) -> 4 | L40: =INDEX(Monthly!$C$4:$BJ$4,($R$2-1)*12+5) -> 5 | M40: =INDEX(Monthly!$C$4:$BJ$4,($R$2-1)*12+6) -> 6 | N40: =INDEX(Monthly!$C$4:$BJ$4,($R$2-1)*12+7) -> 7 | O40: =INDEX(Monthly!$C$4:$BJ$4,($R$2-1)*12+8) -> 8 | P40: =INDEX(Monthly!$C$4:$BJ$4,($R$2-1)*12+9) -> 9 | Q40: =INDEX(Monthly!$C$4:$BJ$4,($R$2-1)*12+10) -> 10 | R40: =INDEX(Monthly!$C$4:$BJ$4,($R$2-1)*12+11) -> 11 | S40: =INDEX(Monthly!$C$4:$BJ$4,($R$2-1)*12+12) -> 12
A41: Cash | B41: ='Balance Sheet'!B5 -> 44971.603 | C41: ='Balance Sheet'!C5 -> 43432.925 | D41: ='Balance Sheet'!D5 -> 92669.884 | E41: ='Balance Sheet'!E5 -> 178110.9 | F41: ='Balance Sheet'!F5 -> 286065.97 | H41: =INDEX(Monthly!$C$80:$BJ$80,($R$2-1)*12+1) -> 90660.251 | I41: =INDEX(Monthly!$C$80:$BJ$80,($R$2-1)*12+2) -> 86467.848 | J41: =INDEX(Monthly!$C$80:$BJ$80,($R$2-1)*12+3) -> 82283.224 | K41: =INDEX(Monthly!$C$80:$BJ$80,($R$2-1)*12+4) -> 78106.377 | L41: =INDEX(Monthly!$C$80:$BJ$80,($R$2-1)*12+5) -> 73937.308 | M41: =INDEX(Monthly!$C$80:$BJ$80,($R$2-1)*12+6) -> 69776.017 | N41: =INDEX(Monthly!$C$80:$BJ$80,($R$2-1)*12+7) -> 65622.503 | O41: =INDEX(Monthly!$C$80:$BJ$80,($R$2-1)*12+8) -> 61476.768 | P41: =INDEX(Monthly!$C$80:$BJ$80,($R$2-1)*12+9) -> 57338.81 | Q41: =INDEX(Monthly!$C$80:$BJ$80,($R$2-1)*12+10) -> 53208.63 | R41: =INDEX(Monthly!$C$80:$BJ$80,($R$2-1)*12+11) -> 49086.228 | S41: =INDEX(Monthly!$C$80:$BJ$80,($R$2-1)*12+12) -> 44971.603
A42: Accounts receivable | B42: ='Balance Sheet'!B6 -> 2661.44 | C42: ='Balance Sheet'!C6 -> 3326.6528 | D42: ='Balance Sheet'!D6 -> 4029.3831 | E42: ='Balance Sheet'!E6 -> 4771.2832 | F42: ='Balance Sheet'!F6 -> 5234.2463 | H42: =INDEX(Monthly!$C$66:$BJ$66,($R$2-1)*12+1) -> 2661.44 | I42: =INDEX(Monthly!$C$66:$BJ$66,($R$2-1)*12+2) -> 2661.44 | J42: =INDEX(Monthly!$C$66:$BJ$66,($R$2-1)*12+3) -> 2661.44 | K42: =INDEX(Monthly!$C$66:$BJ$66,($R$2-1)*12+4) -> 2661.44 | L42: =INDEX(Monthly!$C$66:$BJ$66,($R$2-1)*12+5) -> 2661.44 | M42: =INDEX(Monthly!$C$66:$BJ$66,($R$2-1)*12+6) -> 2661.44 | N42: =INDEX(Monthly!$C$66:$BJ$66,($R$2-1)*12+7) -> 2661.44 | O42: =INDEX(Monthly!$C$66:$BJ$66,($R$2-1)*12+8) -> 2661.44 | P42: =INDEX(Monthly!$C$66:$BJ$66,($R$2-1)*12+9) -> 2661.44 | Q42: =INDEX(Monthly!$C$66:$BJ$66,($R$2-1)*12+10) -> 2661.44 | R42: =INDEX(Monthly!$C$66:$BJ$66,($R$2-1)*12+11) -> 2661.44 | S42: =INDEX(Monthly!$C$66:$BJ$66,($R$2-1)*12+12) -> 2661.44
A43: Inventory | B43: ='Balance Sheet'!B7 -> 11253.946 | C43: ='Balance Sheet'!C7 -> 14167.467 | D43: ='Balance Sheet'!D7 -> 17245.671 | E43: ='Balance Sheet'!E7 -> 20495.817 | F43: ='Balance Sheet'!F7 -> 22518.071 | H43: =INDEX(Monthly!$C$67:$BJ$67,($R$2-1)*12+1) -> 11253.946 | I43: =INDEX(Monthly!$C$67:$BJ$67,($R$2-1)*12+2) -> 11253.946 | J43: =INDEX(Monthly!$C$67:$BJ$67,($R$2-1)*12+3) -> 11253.946 | K43: =INDEX(Monthly!$C$67:$BJ$67,($R$2-1)*12+4) -> 11253.946 | L43: =INDEX(Monthly!$C$67:$BJ$67,($R$2-1)*12+5) -> 11253.946 | M43: =INDEX(Monthly!$C$67:$BJ$67,($R$2-1)*12+6) -> 11253.946 | N43: =INDEX(Monthly!$C$67:$BJ$67,($R$2-1)*12+7) -> 11253.946 | O43: =INDEX(Monthly!$C$67:$BJ$67,($R$2-1)*12+8) -> 11253.946 | P43: =INDEX(Monthly!$C$67:$BJ$67,($R$2-1)*12+9) -> 11253.946 | Q43: =INDEX(Monthly!$C$67:$BJ$67,($R$2-1)*12+10) -> 11253.946 | R43: =INDEX(Monthly!$C$67:$BJ$67,($R$2-1)*12+11) -> 11253.946 | S43: =INDEX(Monthly!$C$67:$BJ$67,($R$2-1)*12+12) -> 11253.946
A44: Net fixed assets | B44: ='Balance Sheet'!B8 -> 109200 | C44: ='Balance Sheet'!C8 -> 91000 | D44: ='Balance Sheet'!D8 -> 72800 | E44: ='Balance Sheet'!E8 -> 54600 | F44: ='Balance Sheet'!F8 -> 36400 | H44: =INDEX(Monthly!$C$57:$BJ$57,($R$2-1)*12+1) -> 125883.33 | I44: =INDEX(Monthly!$C$57:$BJ$57,($R$2-1)*12+2) -> 124366.67 | J44: =INDEX(Monthly!$C$57:$BJ$57,($R$2-1)*12+3) -> 122850 | K44: =INDEX(Monthly!$C$57:$BJ$57,($R$2-1)*12+4) -> 121333.33 | L44: =INDEX(Monthly!$C$57:$BJ$57,($R$2-1)*12+5) -> 119816.67 | M44: =INDEX(Monthly!$C$57:$BJ$57,($R$2-1)*12+6) -> 118300 | N44: =INDEX(Monthly!$C$57:$BJ$57,($R$2-1)*12+7) -> 116783.33 | O44: =INDEX(Monthly!$C$57:$BJ$57,($R$2-1)*12+8) -> 115266.67 | P44: =INDEX(Monthly!$C$57:$BJ$57,($R$2-1)*12+9) -> 113750 | Q44: =INDEX(Monthly!$C$57:$BJ$57,($R$2-1)*12+10) -> 112233.33 | R44: =INDEX(Monthly!$C$57:$BJ$57,($R$2-1)*12+11) -> 110716.67 | S44: =INDEX(Monthly!$C$57:$BJ$57,($R$2-1)*12+12) -> 109200
A45: Total assets | B45: ='Balance Sheet'!B9 -> 168086.99 | C45: ='Balance Sheet'!C9 -> 151927.04 | D45: ='Balance Sheet'!D9 -> 186744.94 | E45: ='Balance Sheet'!E9 -> 257978 | F45: ='Balance Sheet'!F9 -> 350218.28 | H45: =INDEX(Monthly!$C$94:$BJ$94,($R$2-1)*12+1) -> 230458.97 | I45: =INDEX(Monthly!$C$94:$BJ$94,($R$2-1)*12+2) -> 224749.9 | J45: =INDEX(Monthly!$C$94:$BJ$94,($R$2-1)*12+3) -> 219048.61 | K45: =INDEX(Monthly!$C$94:$BJ$94,($R$2-1)*12+4) -> 213355.1 | L45: =INDEX(Monthly!$C$94:$BJ$94,($R$2-1)*12+5) -> 207669.36 | M45: =INDEX(Monthly!$C$94:$BJ$94,($R$2-1)*12+6) -> 201991.4 | N45: =INDEX(Monthly!$C$94:$BJ$94,($R$2-1)*12+7) -> 196321.22 | O45: =INDEX(Monthly!$C$94:$BJ$94,($R$2-1)*12+8) -> 190658.82 | P45: =INDEX(Monthly!$C$94:$BJ$94,($R$2-1)*12+9) -> 185004.2 | Q45: =INDEX(Monthly!$C$94:$BJ$94,($R$2-1)*12+10) -> 179357.35 | R45: =INDEX(Monthly!$C$94:$BJ$94,($R$2-1)*12+11) -> 173718.28 | S45: =INDEX(Monthly!$C$94:$BJ$94,($R$2-1)*12+12) -> 168086.99
A46: Accounts payable | B46: ='Balance Sheet'!B10 -> 15005.261 | C46: ='Balance Sheet'!C10 -> 18889.956 | D46: ='Balance Sheet'!D10 -> 22994.228 | E46: ='Balance Sheet'!E10 -> 27327.756 | F46: ='Balance Sheet'!F10 -> 30024.095 | H46: =INDEX(Monthly!$C$68:$BJ$68,($R$2-1)*12+1) -> 15005.261 | I46: =INDEX(Monthly!$C$68:$BJ$68,($R$2-1)*12+2) -> 15005.261 | J46: =INDEX(Monthly!$C$68:$BJ$68,($R$2-1)*12+3) -> 15005.261 | K46: =INDEX(Monthly!$C$68:$BJ$68,($R$2-1)*12+4) -> 15005.261 | L46: =INDEX(Monthly!$C$68:$BJ$68,($R$2-1)*12+5) -> 15005.261 | M46: =INDEX(Monthly!$C$68:$BJ$68,($R$2-1)*12+6) -> 15005.261 | N46: =INDEX(Monthly!$C$68:$BJ$68,($R$2-1)*12+7) -> 15005.261 | O46: =INDEX(Monthly!$C$68:$BJ$68,($R$2-1)*12+8) -> 15005.261 | P46: =INDEX(Monthly!$C$68:$BJ$68,($R$2-1)*12+9) -> 15005.261 | Q46: =INDEX(Monthly!$C$68:$BJ$68,($R$2-1)*12+10) -> 15005.261 | R46: =INDEX(Monthly!$C$68:$BJ$68,($R$2-1)*12+11) -> 15005.261 | S46: =INDEX(Monthly!$C$68:$BJ$68,($R$2-1)*12+12) -> 15005.261
A47: Loan | B47: ='Balance Sheet'!B11 -> 57166.667 | C47: ='Balance Sheet'!C11 -> 43166.667 | D47: ='Balance Sheet'!D11 -> 29166.667 | E47: ='Balance Sheet'!E11 -> 15166.667 | F47: ='Balance Sheet'!F11 -> 1166.6667 | H47: =INDEX(Monthly!$C$63:$BJ$63,($R$2-1)*12+1) -> 70000 | I47: =INDEX(Monthly!$C$63:$BJ$63,($R$2-1)*12+2) -> 68833.333 | J47: =INDEX(Monthly!$C$63:$BJ$63,($R$2-1)*12+3) -> 67666.667 | K47: =INDEX(Monthly!$C$63:$BJ$63,($R$2-1)*12+4) -> 66500 | L47: =INDEX(Monthly!$C$63:$BJ$63,($R$2-1)*12+5) -> 65333.333 | M47: =INDEX(Monthly!$C$63:$BJ$63,($R$2-1)*12+6) -> 64166.667 | N47: =INDEX(Monthly!$C$63:$BJ$63,($R$2-1)*12+7) -> 63000 | O47: =INDEX(Monthly!$C$63:$BJ$63,($R$2-1)*12+8) -> 61833.333 | P47: =INDEX(Monthly!$C$63:$BJ$63,($R$2-1)*12+9) -> 60666.667 | Q47: =INDEX(Monthly!$C$63:$BJ$63,($R$2-1)*12+10) -> 59500 | R47: =INDEX(Monthly!$C$63:$BJ$63,($R$2-1)*12+11) -> 58333.333 | S47: =INDEX(Monthly!$C$63:$BJ$63,($R$2-1)*12+12) -> 57166.667
A48: Total liabilities | B48: ='Balance Sheet'!B12 -> 72171.927 | C48: ='Balance Sheet'!C12 -> 62056.623 | D48: ='Balance Sheet'!D12 -> 52160.895 | E48: ='Balance Sheet'!E12 -> 42494.423 | F48: ='Balance Sheet'!F12 -> 31190.761 | H48: =INDEX(Monthly!$C$95:$BJ$95,($R$2-1)*12+1) -> 85005.261 | I48: =INDEX(Monthly!$C$95:$BJ$95,($R$2-1)*12+2) -> 83838.594 | J48: =INDEX(Monthly!$C$95:$BJ$95,($R$2-1)*12+3) -> 82671.927 | K48: =INDEX(Monthly!$C$95:$BJ$95,($R$2-1)*12+4) -> 81505.261 | L48: =INDEX(Monthly!$C$95:$BJ$95,($R$2-1)*12+5) -> 80338.594 | M48: =INDEX(Monthly!$C$95:$BJ$95,($R$2-1)*12+6) -> 79171.927 | N48: =INDEX(Monthly!$C$95:$BJ$95,($R$2-1)*12+7) -> 78005.261 | O48: =INDEX(Monthly!$C$95:$BJ$95,($R$2-1)*12+8) -> 76838.594 | P48: =INDEX(Monthly!$C$95:$BJ$95,($R$2-1)*12+9) -> 75671.927 | Q48: =INDEX(Monthly!$C$95:$BJ$95,($R$2-1)*12+10) -> 74505.261 | R48: =INDEX(Monthly!$C$95:$BJ$95,($R$2-1)*12+11) -> 73338.594 | S48: =INDEX(Monthly!$C$95:$BJ$95,($R$2-1)*12+12) -> 72171.927
A49: Paid-in capital | B49: ='Balance Sheet'!B13 -> 150000 | C49: ='Balance Sheet'!C13 -> 150000 | D49: ='Balance Sheet'!D13 -> 150000 | E49: ='Balance Sheet'!E13 -> 150000 | F49: ='Balance Sheet'!F13 -> 150000 | H49: =INDEX(Monthly!$C$92:$BJ$92,($R$2-1)*12+1) -> 150000 | I49: =INDEX(Monthly!$C$92:$BJ$92,($R$2-1)*12+2) -> 150000 | J49: =INDEX(Monthly!$C$92:$BJ$92,($R$2-1)*12+3) -> 150000 | K49: =INDEX(Monthly!$C$92:$BJ$92,($R$2-1)*12+4) -> 150000 | L49: =INDEX(Monthly!$C$92:$BJ$92,($R$2-1)*12+5) -> 150000 | M49: =INDEX(Monthly!$C$92:$BJ$92,($R$2-1)*12+6) -> 150000 | N49: =INDEX(Monthly!$C$92:$BJ$92,($R$2-1)*12+7) -> 150000 | O49: =INDEX(Monthly!$C$92:$BJ$92,($R$2-1)*12+8) -> 150000 | P49: =INDEX(Monthly!$C$92:$BJ$92,($R$2-1)*12+9) -> 150000 | Q49: =INDEX(Monthly!$C$92:$BJ$92,($R$2-1)*12+10) -> 150000 | R49: =INDEX(Monthly!$C$92:$BJ$92,($R$2-1)*12+11) -> 150000 | S49: =INDEX(Monthly!$C$92:$BJ$92,($R$2-1)*12+12) -> 150000
A50: Retained earnings | B50: ='Balance Sheet'!B14 -> -54084.939 | C50: ='Balance Sheet'!C14 -> -60129.578 | D50: ='Balance Sheet'!D14 -> -15415.957 | E50: ='Balance Sheet'!E14 -> 65483.58 | F50: ='Balance Sheet'!F14 -> 169027.52 | H50: =INDEX(Monthly!$C$93:$BJ$93,($R$2-1)*12+1) -> -4546.2912 | I50: =INDEX(Monthly!$C$93:$BJ$93,($R$2-1)*12+2) -> -9088.6935 | J50: =INDEX(Monthly!$C$93:$BJ$93,($R$2-1)*12+3) -> -13623.318 | K50: =INDEX(Monthly!$C$93:$BJ$93,($R$2-1)*12+4) -> -18150.165 | L50: =INDEX(Monthly!$C$93:$BJ$93,($R$2-1)*12+5) -> -22669.234 | M50: =INDEX(Monthly!$C$93:$BJ$93,($R$2-1)*12+6) -> -27180.525 | N50: =INDEX(Monthly!$C$93:$BJ$93,($R$2-1)*12+7) -> -31684.038 | O50: =INDEX(Monthly!$C$93:$BJ$93,($R$2-1)*12+8) -> -36179.774 | P50: =INDEX(Monthly!$C$93:$BJ$93,($R$2-1)*12+9) -> -40667.732 | Q50: =INDEX(Monthly!$C$93:$BJ$93,($R$2-1)*12+10) -> -45147.912 | R50: =INDEX(Monthly!$C$93:$BJ$93,($R$2-1)*12+11) -> -49620.314 | S50: =INDEX(Monthly!$C$93:$BJ$93,($R$2-1)*12+12) -> -54084.939
...

Sheet Break-even
A1: Startup costs, funding need and break-even | H1: =HYPERLINK("#'Cover'!A1","◂ Contents") -> ◂ Contents
A2: Live for the selected scenario. Periods are counted in months from the start of the plan.
A3: Scenario shown | B3: =CHOOSE(Dashboard!$B$4,"Low","Base","High") -> Base
A5: Startup costs & funding need (up to the lowest cash point)
A6: Lowest cash point (month #) | B6: =MATCH(MIN(Monthly!$C$80:$BJ$80),Monthly!$C$80:$BJ$80,0) -> 24
A7: Capital spending up to the lowest cash point | B7: =SUMPRODUCT(--(Monthly!$C$4:$BJ$4<=$B$6),Monthly!$C$53:$BJ$53) -> 127400
A8: Operating cash burn up to the lowest cash point | B8: =-SUMPRODUCT(--(Monthly!$C$4:$BJ$4<=$B$6),Monthly!$C$74:$BJ$74) -> 22333.742 | D8: Losses and working capital before the business funds itself
A9: Loan repayments up to the lowest cash point | B9: =-SUMPRODUCT(--(Monthly!$C$4:$BJ$4<=$B$6),Monthly!$C$62:$BJ$62) -> 26833.333
A10: Total uses of funds | B10: =B7+B8+B9 -> 176567.08
A11: Minimum cash buffer to keep | B11: =Inputs!$E$84 -> 60000 | D11: Input on the Inputs sheet
A12: Funding required (uses + buffer) | B12: =B10+B11 -> 236567.08
A14: Equity raised | B14: =Inputs!$E$69 -> 150000
A15: Loan drawn | B15: =Inputs!$E$70 -> 70000
A16: Total sources of funds | B16: =B14+B15 -> 220000
A17: Funding surplus / (shortfall) | B17: =B16-B12 -> -16567.075 | D17: Negative = raise at least this much more
A18: Lowest cash balance in the plan | B18: =MIN(Monthly!$C$80:$BJ$80) -> 43432.925 | D18: Equals sources minus uses
A20: Break-even timing
A21: First month with positive EBITDA (month #) | B21: =IFERROR(MATCH(1,Monthly!$C$81:$BJ$81,0),"Not within horizon") -> 13
A22: First month with positive net income (month #) | B22: =IFERROR(MATCH(1,Monthly!$C$84:$BJ$84,0),"Not within horizon") -> 25
A23: Cash invested paid back (month #) | B23: =IF(MIN(Monthly!$C$86:$BJ$86)>=0,"No investment to pay back",IFERROR(MATCH(1,Monthly!$C$88:$BJ$88,0),"Not within horizon")) -> 47 | D23: Cumulative operating + investing cash flow back to zero
A25: Annual break-even revenue
A26: Year # | B26: 1 | C26: 2 | D26: 3 | E26: 4 | F26: 5
B27: Year 1 | C27: Year 2 | D27: Year 3 | E27: Year 4 | F27: Year 5
A28: Revenue | B28: =SUMIF(Monthly!$C$5:$BJ$5,B$26,Monthly!$C$21:$BJ$21) -> 479059.2 | C28: =SUMIF(Monthly!$C$5:$BJ$5,C$26,Monthly!$C$21:$BJ$21) -> 598797.5 | D28: =SUMIF(Monthly!$C$5:$BJ$5,D$26,Monthly!$C$21:$BJ$21) -> 725288.95 | E28: =SUMIF(Monthly!$C$5:$BJ$5,E$26,Monthly!$C$21:$BJ$21) -> 858830.97 | F28: =SUMIF(Monthly!$C$5:$BJ$5,F$26,Monthly!$C$21:$BJ$21) -> 942164.33
A29: Gross profit | B29: =SUMIF(Monthly!$C$5:$BJ$5,B$26,Monthly!$C$29:$BJ$29) -> 208964.51 | C29: =SUMIF(Monthly!$C$5:$BJ$5,C$26,Monthly!$C$29:$BJ$29) -> 258778.29 | D29: =SUMIF(Monthly!$C$5:$BJ$5,D$26,Monthly!$C$29:$BJ$29) -> 311392.84 | E29: =SUMIF(Monthly!$C$5:$BJ$5,E$26,Monthly!$C$29:$BJ$29) -> 366931.36 | F29: =SUMIF(Monthly!$C$5:$BJ$5,F$26,Monthly!$C$29:$BJ$29) -> 401730.62
A30: Gross margin (contribution) | B30: =IF(B28=0,0,B29/B28) -> 0.43619767 | C30: =IF(C28=0,0,C29/C28) -> 0.43216328 | D30: =IF(D28=0,0,D29/D28) -> 0.42933625 | E30: =IF(E28=0,0,E29/E28) -> 0.42724514 | F30: =IF(F28=0,0,F29/F28) -> 0.42639125
A31: Operating expenses (treated as fixed) | B31: =-SUMIF(Monthly!$C$5:$BJ$5,B$26,Monthly!$C$40:$BJ$40) -> 239720 | C31: =-SUMIF(Monthly!$C$5:$BJ$5,C$26,Monthly!$C$40:$BJ$40) -> 242609.6 | D31: =-SUMIF(Monthly!$C$5:$BJ$5,D$26,Monthly!$C$40:$BJ$40) -> 245585.89 | E31: =-SUMIF(Monthly!$C$5:$BJ$5,E$26,Monthly!$C$40:$BJ$40) -> 248651.46 | F31: =-SUMIF(Monthly!$C$5:$BJ$5,F$26,Monthly!$C$40:$BJ$40) -> 251809.01
A32: Break-even revenue (EBITDA = 0) | B32: =IF(B30>0,B31/B30,"n/a") -> 549567.36 | C32: =IF(C30>0,C31/C30,"n/a") -> 561384.11 | D32: =IF(D30>0,D31/D30,"n/a") -> 572012.93 | E32: =IF(E30>0,E31/E30,"n/a") -> 581987.81 | F32: =IF(F30>0,F31/F30,"n/a") -> 590558.58
A33: Margin of safety (revenue above break-even) | B33: =IF(AND(ISNUMBER(B32),B28>0),(B28-B32)/B28,"n/a") -> -0.14718047 | C33: =IF(AND(ISNUMBER(C32),C28>0),(C28-C32)/C28,"n/a") -> 0.062480875 | D33: =IF(AND(ISNUMBER(D32),D28>0),(D28-D32)/D28,"n/a") -> 0.21133098 | E33: =IF(AND(ISNUMBER(E32),E28>0),(E28-E32)/E28,"n/a") -> 0.32234884 | F33: =IF(AND(ISNUMBER(F32),F28>0),(F28-F32)/F28,"n/a") -> 0.37318941
A35: Simplification: cost of sales is treated as variable and operating expenses as fixed, so break-even revenue = operating expenses ÷ gross margin.

Sheet Valuation
A1: Discounted cash flow valuation | H1: =HYPERLINK("#'Cover'!A1","◂ Contents") -> ◂ Contents
A2: Enterprise value at the start of the plan, before the funding raised in period 1. Year-end discounting.
A3: Scenario shown | B3: =CHOOSE(Dashboard!$B$4,"Low","Base","High") -> Base
A5: Assumptions (active scenario, from the Inputs sheet)
A6: Discount rate (WACC) | B6: =Inputs!$E$87 -> 0.25
A7: Terminal growth rate | B7: =Inputs!$E$88 -> 0.02
A8: Exit multiple (EV ÷ final-year EBITDA) | B8: =Inputs!$E$89 -> 4
A9: Tax rate (for the interest tax shield) | B9: =Inputs!$E$81 -> 0.21
A10: Sensitivity step: WACC | B10: =Inputs!$E$90 -> 0.01
A11: Sensitivity step: terminal growth | B11: =Inputs!$E$91 -> 0.005
A13: Free cash flow by year
A14: Year # | B14: 1 | C14: 2 | D14: 3 | E14: 4 | F14: 5
B15: Year 1 | C15: Year 2 | D15: Year 3 | E15: Year 4 | F15: Year 5
A16: EBITDA | B16: =SUMIF(Monthly!$C$5:$BJ$5,B$14,Monthly!$C$41:$BJ$41) -> -30755.494 | C16: =SUMIF(Monthly!$C$5:$BJ$5,C$14,Monthly!$C$41:$BJ$41) -> 16168.694 | D16: =SUMIF(Monthly!$C$5:$BJ$5,D$14,Monthly!$C$41:$BJ$41) -> 65806.954 | E16: =SUMIF(Monthly!$C$5:$BJ$5,E$14,Monthly!$C$41:$BJ$41) -> 118279.9 | F16: =SUMIF(Monthly!$C$5:$BJ$5,F$14,Monthly!$C$41:$BJ$41) -> 149921.61
A17: Unlevered free cash flow | B17: =SUMIF(Monthly!$C$5:$BJ$5,B$14,Monthly!$C$89:$BJ$89) -> -158142.8 | C17: =SUMIF(Monthly!$C$5:$BJ$5,C$14,Monthly!$C$89:$BJ$89) -> 15631.855 | D17: =SUMIF(Monthly!$C$5:$BJ$5,D$14,Monthly!$C$89:$BJ$89) -> 65522.692 | E17: =SUMIF(Monthly!$C$5:$BJ$5,E$14,Monthly!$C$89:$BJ$89) -> 100841.95 | F17: =SUMIF(Monthly!$C$5:$BJ$5,F$14,Monthly!$C$89:$BJ$89) -> 122471.2
A18: Discount factor | B18: =1/(1+Inputs!$E$87)^B$14 -> 0.8 | C18: =1/(1+Inputs!$E$87)^C$14 -> 0.64 | D18: =1/(1+Inputs!$E$87)^D$14 -> 0.512 | E18: =1/(1+Inputs!$E$87)^E$14 -> 0.4096 | F18: =1/(1+Inputs!$E$87)^F$14 -> 0.32768
A19: Present value of free cash flow | B19: =B17*B18 -> -126514.24 | C19: =C17*C18 -> 10004.387 | D19: =D17*D18 -> 33547.618 | E19: =E17*E18 -> 41304.864 | F19: =F17*F18 -> 40131.362
A21: Enterprise value
B22: Perpetual growth | C22: Exit multiple
A23: Present value of the plan's free cash flows | B23: =SUM($B$19:$F$19) -> -1526.0112 | C23: =B23 -> -1526.0112
A24: Final-year free cash flow | final-year EBITDA | B24: =$F$17 -> 122471.2 | C24: =$F$16 -> 149921.61
A25: Terminal value at the end of year 5 | B25: =IF($B$6>$B$7,B24*(1+$B$7)/($B$6-$B$7),0) -> 543133.13 | C25: =C24*$B$8 -> 599686.45
A26: Present value of the terminal value | B26: =B25/(1+$B$6)^$F$14 -> 177973.86 | C26: =C25/(1+$B$6)^$F$14 -> 196505.26
A27: Enterprise value | B27: =B23+B26 -> 176447.85 | C27: =C23+C26 -> 194979.25
A28: Terminal value share of enterprise value | B28: =IF(B27<>0,B26/B27,0) -> 1.0086485 | C28: =IF(C27<>0,C26/C27,0) -> 1.0078265
A29: Cross-check: implied exit multiple | implied perpetual growth | B29: =IF(C24>0,B25/C24,"n/a") -> 3.6227807 | C29: =IF(C25+B24<>0,(C25*$B$6-B24)/(C25+B24),"n/a") -> 0.038011669
A30: Enterprise value — average of the two methods | B30: =AVERAGE(B27,C27) -> 185713.55
A32: Sensitivity: enterprise value (perpetual growth) by WACC and terminal growth
A33: WACC ↓ · terminal growth → | B33: =$B$7+(-2)*$B$11 -> 0.01 | C33: =$B$7+(-1)*$B$11 -> 0.015 | D33: =$B$7+(0)*$B$11 -> 0.02 | E33: =$B$7+(1)*$B$11 -> 0.025 | F33: =$B$7+(2)*$B$11 -> 0.03
A34: =$B$6+(-2)*$B$10 -> 0.23 | B34: =IF($A34>B$33,SUMPRODUCT($B$17:$F$17/(1+$A34)^$B$14:$F$14)+$F$17*(1+B$33)/($A34-B$33)/(1+$A34)^$F$14,"n/a") -> 204244.7 | C34: =IF($A34>C$33,SUMPRODUCT($B$17:$F$17/(1+$A34)^$B$14:$F$14)+$F$17*(1+C$33)/($A34-C$33)/(1+$A34)^$F$14,"n/a") -> 209900.87 | D34: =IF($A34>D$33,SUMPRODUCT($B$17:$F$17/(1+$A34)^$B$14:$F$14)+$F$17*(1+D$33)/($A34-D$33)/(1+$A34)^$F$14,"n/a") -> 215826.38 | E34: =IF($A34>E$33,SUMPRODUCT($B$17:$F$17/(1+$A34)^$B$14:$F$14)+$F$17*(1+E$33)/($A34-E$33)/(1+$A34)^$F$14,"n/a") -> 222040.94 | F34: =IF($A34>F$33,SUMPRODUCT($B$17:$F$17/(1+$A34)^$B$14:$F$14)+$F$17*(1+F$33)/($A34-F$33)/(1+$A34)^$F$14,"n/a") -> 228566.23
A35: =$B$6+(-1)*$B$10 -> 0.24 | B35: =IF($A35>B$33,SUMPRODUCT($B$17:$F$17/(1+$A35)^$B$14:$F$14)+$F$17*(1+B$33)/($A35-B$33)/(1+$A35)^$F$14,"n/a") -> 184877.63 | C35: =IF($A35>C$33,SUMPRODUCT($B$17:$F$17/(1+$A35)^$B$14:$F$14)+$F$17*(1+C$33)/($A35-C$33)/(1+$A35)^$F$14,"n/a") -> 189882.66 | D35: =IF($A35>D$33,SUMPRODUCT($B$17:$F$17/(1+$A35)^$B$14:$F$14)+$F$17*(1+D$33)/($A35-D$33)/(1+$A35)^$F$14,"n/a") -> 195115.19 | E35: =IF($A35>E$33,SUMPRODUCT($B$17:$F$17/(1+$A35)^$B$14:$F$14)+$F$17*(1+E$33)/($A35-E$33)/(1+$A35)^$F$14,"n/a") -> 200591.1 | F35: =IF($A35>F$33,SUMPRODUCT($B$17:$F$17/(1+$A35)^$B$14:$F$14)+$F$17*(1+F$33)/($A35-F$33)/(1+$A35)^$F$14,"n/a") -> 206327.76
A36: =$B$6+(0)*$B$10 -> 0.25 | B36: =IF($A36>B$33,SUMPRODUCT($B$17:$F$17/(1+$A36)^$B$14:$F$14)+$F$17*(1+B$33)/($A36-B$33)/(1+$A36)^$F$14,"n/a") -> 167360.14 | C36: =IF($A36>C$33,SUMPRODUCT($B$17:$F$17/(1+$A36)^$B$14:$F$14)+$F$17*(1+C$33)/($A36-C$33)/(1+$A36)^$F$14,"n/a") -> 171807.32 | D36: =IF($A36>D$33,SUMPRODUCT($B$17:$F$17/(1+$A36)^$B$14:$F$14)+$F$17*(1+D$33)/($A36-D$33)/(1+$A36)^$F$14,"n/a") -> 176447.85 | E36: =IF($A36>E$33,SUMPRODUCT($B$17:$F$17/(1+$A36)^$B$14:$F$14)+$F$17*(1+E$33)/($A36-E$33)/(1+$A36)^$F$14,"n/a") -> 181294.64 | F36: =IF($A36>F$33,SUMPRODUCT($B$17:$F$17/(1+$A36)^$B$14:$F$14)+$F$17*(1+F$33)/($A36-F$33)/(1+$A36)^$F$14,"n/a") -> 186361.73
A37: =$B$6+(1)*$B$10 -> 0.26 | B37: =IF($A37>B$33,SUMPRODUCT($B$17:$F$17/(1+$A37)^$B$14:$F$14)+$F$17*(1+B$33)/($A37-B$33)/(1+$A37)^$F$14,"n/a") -> 151462.55 | C37: =IF($A37>C$33,SUMPRODUCT($B$17:$F$17/(1+$A37)^$B$14:$F$14)+$F$17*(1+C$33)/($A37-C$33)/(1+$A37)^$F$14,"n/a") -> 155429.13 | D37: =IF($A37>D$33,SUMPRODUCT($B$17:$F$17/(1+$A37)^$B$14:$F$14)+$F$17*(1+D$33)/($A37-D$33)/(1+$A37)^$F$14,"n/a") -> 159560.98 | E37: =IF($A37>E$33,SUMPRODUCT($B$17:$F$17/(1+$A37)^$B$14:$F$14)+$F$17*(1+E$33)/($A37-E$33)/(1+$A37)^$F$14,"n/a") -> 163868.65 | F37: =IF($A37>F$33,SUMPRODUCT($B$17:$F$17/(1+$A37)^$B$14:$F$14)+$F$17*(1+F$33)/($A37-F$33)/(1+$A37)^$F$14,"n/a") -> 168363.61
A38: =$B$6+(2)*$B$10 -> 0.27 | B38: =IF($A38>B$33,SUMPRODUCT($B$17:$F$17/(1+$A38)^$B$14:$F$14)+$F$17*(1+B$33)/($A38-B$33)/(1+$A38)^$F$14,"n/a") -> 136990.88 | C38: =IF($A38>C$33,SUMPRODUCT($B$17:$F$17/(1+$A38)^$B$14:$F$14)+$F$17*(1+C$33)/($A38-C$33)/(1+$A38)^$F$14,"n/a") -> 140541.26 | D38: =IF($A38>D$33,SUMPRODUCT($B$17:$F$17/(1+$A38)^$B$14:$F$14)+$F$17*(1+D$33)/($A38-D$33)/(1+$A38)^$F$14,"n/a") -> 144233.66 | E38: =IF($A38>E$33,SUMPRODUCT($B$17:$F$17/(1+$A38)^$B$14:$F$14)+$F$17*(1+E$33)/($A38-E$33)/(1+$A38)^$F$14,"n/a") -> 148076.78 | F38: =IF($A38>F$33,SUMPRODUCT($B$17:$F$17/(1+$A38)^$B$14:$F$14)+$F$17*(1+F$33)/($A38-F$33)/(1+$A38)^$F$14,"n/a") -> 152080.02
A40: Free cash flow = operating cash flow + interest × (1 − tax rate) − capital spending. Cells marked n/a: WACC not above growth.

Sheet Sources & Uses
A1: Sources and uses of funds | E1: =HYPERLINK("#'Cover'!A1","◂ Contents") -> ◂ Contents
A2: Live for the selected scenario. Where the money comes from and where it goes in the period set below.
A3: Scenario shown | B3: =CHOOSE(Dashboard!$B$4,"Low","Base","High") -> Base
A5: Funding structure ($'000) — raised at the start of the plan
B6: Amount | C6: Share
A7: Equity | B7: =Inputs!$E$69 -> 150000 | C7: =IF($B$9=0,0,B7/$B$9) -> 0.68181818
A8: Debt (loan) | B8: =Inputs!$E$70 -> 70000 | C8: =IF($B$9=0,0,B8/$B$9) -> 0.31818182
A9: Total funding | B9: =B7+B8 -> 220000 | C9: =IF(B9=0,0,1) -> 1
A10: Gearing (debt ÷ equity) | B10: =IF(B7<=0,IF(B8>0,"n/a",0),B8/B7) -> 0.46666667 | D10: n/a: debt without positive equity
A11: Funding required by the plan (Break-even sheet) | B11: ='Break-even'!B12 -> 236567.08
A12: Funding surplus / (shortfall) | B12: ='Break-even'!B17 -> -16567.075
A14: ="Sources and uses of cash in the first "&$B$16&IF($B$16=1," month"," months")&" ($'000)" -> Sources and uses of cash in the first 12 months ($'000)
A15: Period covered (months from the start) | B15: 12 | D15: 1 to 60 (capped)
A16: Months used | B16: =MIN(60,MAX(1,ROUND(B15,0))) -> 12
A17: Sources | B17: Amount | C17: Share
A18: Equity raised | B18: =SUMPRODUCT(--(Monthly!$C$4:$BJ$4<=$B$16),Monthly!$C$76:$BJ$76) -> 150000 | C18: =IF($B$21=0,0,B18/$B$21) -> 0.68181818
A19: Loan drawdowns | B19: =SUMPRODUCT(--(Monthly!$C$4:$BJ$4<=$B$16),Monthly!$C$61:$BJ$61) -> 70000 | C19: =IF($B$21=0,0,B19/$B$21) -> 0.31818182
A20: Cash generated by operations | B20: =MAX(0,SUMPRODUCT(--(Monthly!$C$4:$BJ$4<=$B$16),Monthly!$C$74:$BJ$74)) -> 0 | C20: =IF($B$21=0,0,B20/$B$21) -> 0
A21: Total sources | B21: =SUM(B18:B20) -> 220000 | C21: =IF(B21=0,0,1) -> 1
A23: Uses | B23: Amount | C23: Share
A24: Cash used by operations | B24: =MAX(0,-SUMPRODUCT(--(Monthly!$C$4:$BJ$4<=$B$16),Monthly!$C$74:$BJ$74)) -> 34795.064 | C24: =IF($B$28=0,0,B24/$B$28) -> 0.15815938
A25: Capital spending | B25: =-SUMPRODUCT(--(Monthly!$C$4:$BJ$4<=$B$16),Monthly!$C$75:$BJ$75) -> 127400 | C25: =IF($B$28=0,0,B25/$B$28) -> 0.57909091
A26: Loan repayments | B26: =-SUMPRODUCT(--(Monthly!$C$4:$BJ$4<=$B$16),Monthly!$C$62:$BJ$62) -> 12833.333 | C26: =IF($B$28=0,0,B26/$B$28) -> 0.058333333
A27: Cash at the end of the period | B27: =INDEX(Monthly!$C$80:$BJ$80,$B$16) -> 44971.603 | C27: =IF($B$28=0,0,B27/$B$28) -> 0.20441638
A28: Total uses | B28: =SUM(B24:B27) -> 220000 | C28: =IF(B28=0,0,1) -> 1
A29: Sources − uses (must be 0; opening cash is 0) | B29: =B21-B28 -> 0

Sheet KPIs
A1: KPIs & ratios | I1: =HYPERLINK("#'Cover'!A1","◂ Contents") -> ◂ Contents
A2: Hair salon financial model (planning) — industry metrics and financial ratios for the active scenario
A4: Financial ratios
B5: 1 | C5: 2 | D5: 3 | E5: 4 | F5: 5 | G5: Target
A6: Revenue growth | B6: =IF(N('P&L'!A5)<=0,"n/a",'P&L'!B5/'P&L'!A5-1) -> n/a | C6: =IF(N('P&L'!B5)<=0,"n/a",'P&L'!C5/'P&L'!B5-1) -> 0.24994469 | D6: =IF(N('P&L'!C5)<=0,"n/a",'P&L'!D5/'P&L'!C5-1) -> 0.21124245 | E6: =IF(N('P&L'!D5)<=0,"n/a",'P&L'!E5/'P&L'!D5-1) -> 0.1841225 | F6: =IF(N('P&L'!E5)<=0,"n/a",'P&L'!F5/'P&L'!E5-1) -> 0.097031147
A7: Gross margin | B7: =IF('P&L'!B5<=0,"n/a",'P&L'!B7/'P&L'!B5) -> 0.43619767 | C7: =IF('P&L'!C5<=0,"n/a",'P&L'!C7/'P&L'!C5) -> 0.43216328 | D7: =IF('P&L'!D5<=0,"n/a",'P&L'!D7/'P&L'!D5) -> 0.42933625 | E7: =IF('P&L'!E5<=0,"n/a",'P&L'!E7/'P&L'!E5) -> 0.42724514 | F7: =IF('P&L'!F5<=0,"n/a",'P&L'!F7/'P&L'!F5) -> 0.42639125
A8: EBITDA margin | B8: =IF('P&L'!B5<=0,"n/a",'P&L'!B18/'P&L'!B5) -> -0.064199778 | C8: =IF('P&L'!C5<=0,"n/a",'P&L'!C18/'P&L'!C5) -> 0.02700194 | D8: =IF('P&L'!D5<=0,"n/a",'P&L'!D18/'P&L'!D5) -> 0.090732051 | E8: =IF('P&L'!E5<=0,"n/a",'P&L'!E18/'P&L'!E5) -> 0.13772198 | F8: =IF('P&L'!F5<=0,"n/a",'P&L'!F18/'P&L'!F5) -> 0.1591247
A9: Net margin | B9: =IF('P&L'!B5<=0,"n/a",'P&L'!B25/'P&L'!B5) -> -0.11289824 | C9: =IF('P&L'!C5<=0,"n/a",'P&L'!C25/'P&L'!C5) -> -0.01009463 | D9: =IF('P&L'!D5<=0,"n/a",'P&L'!D25/'P&L'!D5) -> 0.061649389 | E9: =IF('P&L'!E5<=0,"n/a",'P&L'!E25/'P&L'!E5) -> 0.094197275 | F9: =IF('P&L'!F5<=0,"n/a",'P&L'!F25/'P&L'!F5) -> 0.10990009
A10: Payroll, % of revenue | B10: =IF('P&L'!B5<=0,"n/a",-SUMIF(Headcount!$C$5:$BJ$5,B$5,Headcount!$C$17:$BJ$17)/'P&L'!B5) -> 0.20106075 | C10: =IF('P&L'!C5<=0,"n/a",-SUMIF(Headcount!$C$5:$BJ$5,C$5,Headcount!$C$17:$BJ$17)/'P&L'!C5) -> 0.16568139 | D10: =IF('P&L'!D5<=0,"n/a",-SUMIF(Headcount!$C$5:$BJ$5,D$5,Headcount!$C$17:$BJ$17)/'P&L'!D5) -> 0.1408899 | E10: =IF('P&L'!E5<=0,"n/a",-SUMIF(Headcount!$C$5:$BJ$5,E$5,Headcount!$C$17:$BJ$17)/'P&L'!E5) -> 0.12255201 | F10: =IF('P&L'!F5<=0,"n/a",-SUMIF(Headcount!$C$5:$BJ$5,F$5,Headcount!$C$17:$BJ$17)/'P&L'!F5) -> 0.1150638
A11: Marketing, % of revenue | B11: =IF('P&L'!B5<=0,"n/a",-'P&L'!B10/'P&L'!B5) -> 0.062622741 | C11: =IF('P&L'!C5<=0,"n/a",-'P&L'!C10/'P&L'!C5) -> 0.050100409 | D11: =IF('P&L'!D5<=0,"n/a",-'P&L'!D10/'P&L'!D5) -> 0.041362825 | E11: =IF('P&L'!E5<=0,"n/a",-'P&L'!E10/'P&L'!E5) -> 0.034931204 | F11: =IF('P&L'!F5<=0,"n/a",-'P&L'!F10/'P&L'!F5) -> 0.031841579
A12: Operating expenses, % of revenue | B12: =IF('P&L'!B5<=0,"n/a",-'P&L'!B17/'P&L'!B5) -> 0.50039745 | C12: =IF('P&L'!C5<=0,"n/a",-'P&L'!C17/'P&L'!C5) -> 0.40516134 | D12: =IF('P&L'!D5<=0,"n/a",-'P&L'!D17/'P&L'!D5) -> 0.3386042 | E12: =IF('P&L'!E5<=0,"n/a",-'P&L'!E17/'P&L'!E5) -> 0.28952317 | F12: =IF('P&L'!F5<=0,"n/a",-'P&L'!F17/'P&L'!F5) -> 0.26726655
A13: Current ratio (current assets ÷ current liabilities) | B13: =IF(('Balance Sheet'!B12-'Balance Sheet'!B11)<=0,"n/a",('Balance Sheet'!B5+'Balance Sheet'!B6+'Balance Sheet'!B7)/('Balance Sheet'!B12-'Balance Sheet'!B11)) -> 3.9244229 | C13: =IF(('Balance Sheet'!C12-'Balance Sheet'!C11)<=0,"n/a",('Balance Sheet'!C5+'Balance Sheet'!C6+'Balance Sheet'!C7)/('Balance Sheet'!C12-'Balance Sheet'!C11)) -> 3.2253672 | D13: =IF(('Balance Sheet'!D12-'Balance Sheet'!D11)<=0,"n/a",('Balance Sheet'!D5+'Balance Sheet'!D6+'Balance Sheet'!D7)/('Balance Sheet'!D12-'Balance Sheet'!D11)) -> 4.9553712 | E13: =IF(('Balance Sheet'!E12-'Balance Sheet'!E11)<=0,"n/a",('Balance Sheet'!E5+'Balance Sheet'!E6+'Balance Sheet'!E7)/('Balance Sheet'!E12-'Balance Sheet'!E11)) -> 7.4421772 | F13: =IF(('Balance Sheet'!F12-'Balance Sheet'!F11)<=0,"n/a",('Balance Sheet'!F5+'Balance Sheet'!F6+'Balance Sheet'!F7)/('Balance Sheet'!F12-'Balance Sheet'!F11)) -> 10.452215
A14: Debt ÷ equity (loan ÷ total equity) | B14: =IF('Balance Sheet'!B15<=0,"n/a",'Balance Sheet'!B11/'Balance Sheet'!B15) -> 0.59601345 | C14: =IF('Balance Sheet'!C15<=0,"n/a",'Balance Sheet'!C11/'Balance Sheet'!C15) -> 0.48032117 | D14: =IF('Balance Sheet'!D15<=0,"n/a",'Balance Sheet'!D11/'Balance Sheet'!D15) -> 0.21671712 | E14: =IF('Balance Sheet'!E15<=0,"n/a",'Balance Sheet'!E11/'Balance Sheet'!E15) -> 0.070384327 | F14: =IF('Balance Sheet'!F15<=0,"n/a",'Balance Sheet'!F11/'Balance Sheet'!F15) -> 0.0036569468
A15: Return on assets (net income ÷ year-end assets) | B15: =IF('Balance Sheet'!B9<=0,"n/a",'P&L'!B25/'Balance Sheet'!B9) -> -0.32176755 | C15: =IF('Balance Sheet'!C9<=0,"n/a",'P&L'!C25/'Balance Sheet'!C9) -> -0.039786458 | D15: =IF('Balance Sheet'!D9<=0,"n/a",'P&L'!D25/'Balance Sheet'!D9) -> 0.23943686 | E15: =IF('Balance Sheet'!E9<=0,"n/a",'P&L'!E25/'Balance Sheet'!E9) -> 0.31359083 | F15: =IF('Balance Sheet'!F9<=0,"n/a",'P&L'!F25/'Balance Sheet'!F9) -> 0.29565544
A16: Return on equity (net income ÷ year-end equity) | B16: =IF('Balance Sheet'!B15<=0,"n/a",'P&L'!B25/'Balance Sheet'!B15) -> -0.56388369 | C16: =IF('Balance Sheet'!C15<=0,"n/a",'P&L'!C25/'Balance Sheet'!C15) -> -0.067259493 | D16: =IF('Balance Sheet'!D15<=0,"n/a",'P&L'!D25/'Balance Sheet'!D15) -> 0.33223568 | E16: =IF('Balance Sheet'!E15<=0,"n/a",'P&L'!E25/'Balance Sheet'!E15) -> 0.37543249 | F16: =IF('Balance Sheet'!F15<=0,"n/a",'P&L'!F25/'Balance Sheet'!F15) -> 0.32456116
A18: DuPont analysis — return on equity = net margin × asset turnover × equity multiplier
B19: 1 | C19: 2 | D19: 3 | E19: 4 | F19: 5
