Workbook

Sheet Cover
B2: Professional services financial model (growing)
B3: 5-year financial model · monthly detail · Low / Base / High scenarios · US dollars · Full plan
B5: Purpose | D5: Revenue and profit plan
B6: Active scenario | D6: =Dashboard!C4&" (change it on the Dashboard, cell B4)" -> Base (change it on the Dashboard, cell B4)
B7: Model checks | D7: =Checks!B25 -> PASS
B8: Prepared | D8: 21 October 2026
B10: Contents
C11: PRESENTATION
B12: 1 | C12: =HYPERLINK("#Dashboard!A1","Dashboard") -> Dashboard | D12: Scenario switch, key numbers, core financials
B13: 2 | C13: =HYPERLINK("#Summary!A1","Summary") -> Summary | D13: Income statement, cash flow and balance sheet — every year and any year by month
B14: 3 | C14: =HYPERLINK("#Scenarios!A1","Scenarios") -> Scenarios | D14: Low / Base / High side by side: drivers, outputs, charts
B15: 4 | C15: =HYPERLINK("#'Break-even'!A1","Break-even") -> Break-even | D15: Startup costs, funding need, break-even timing and revenue
B16: 5 | C16: =HYPERLINK("#Valuation!A1","Valuation") -> Valuation | D16: Free cash flow, DCF (perpetual growth and exit multiple), WACC × growth sensitivity
B17: 6 | C17: =HYPERLINK("#'Sources & Uses'!A1","Sources & Uses") -> Sources & Uses | D17: Funding structure, sources and uses of cash for the first months
B18: 7 | C18: =HYPERLINK("#KPIs!A1","KPIs") -> KPIs | D18: Financial ratios, DuPont analysis, industry metrics
C19: INPUTS
B20: 8 | C20: =HYPERLINK("#Inputs!A1","Inputs") -> Inputs | D20: Every assumption, Low / Base / High, with units and comments
C21: STATEMENTS
B22: 9 | C22: =HYPERLINK("#'P&L'!A1","P&L") -> P&L | D22: Annual profit & loss
B23: 10 | C23: =HYPERLINK("#'Cash Flow'!A1","Cash Flow") -> Cash Flow | D23: Annual cash flow statement
B24: 11 | C24: =HYPERLINK("#'Balance Sheet'!A1","Balance Sheet") -> Balance Sheet | D24: Balance sheet at year end
C25: CALCULATIONS
B26: 12 | C26: =HYPERLINK("#Monthly!A1","Monthly") -> Monthly | D26: Month-by-month engine of the model
B27: 13 | C27: =HYPERLINK("#Headcount!A1","Headcount") -> Headcount | D27: Team and payroll
B28: 14 | C28: =HYPERLINK("#'Scenario calc'!A1","Scenario calc") -> Scenario calc | D28: Low, Base and High calculated side by side for the Scenarios sheet
C29: CONTROL
B30: 15 | C30: =HYPERLINK("#Checks!A1","Checks") -> Checks | D30: Live integrity checks and the overall verdict
B32: How to read this file
C33: 1000 | D33: Input you can change — yellow cell with a blue figure (Inputs sheet and the view switches)
C34: 1000 | D34: Formula — calculated, do not overwrite
C35: 1000 | D35: Link to another sheet
C36: 1000 | D36: Active value the model uses (follows the scenario)

Sheet Dashboard
A1: Dashboard | W1: =HYPERLINK("#'Cover'!A1","◂ Contents") -> ◂ Contents
A2: Professional services financial model (growing)
A4: Active scenario | B4: 2 | C4: =CHOOSE(B4,"Low","Base","High") -> Base | D4: 1 = Low · 2 = Base · 3 = High — every sheet follows this cell | S4: Model checks | T4: =Checks!B25 -> PASS
A6: REVENUE · YEAR 5 | C6: EBITDA MARGIN · YEAR 5 | H6: NET INCOME · YEAR 5 | L6: LOWEST CASH BALANCE | P6: FUNDING REQUIRED | T6: ENTERPRISE VALUE (DCF)
A7: =F12 -> 12793894 | C7: =F17 -> 0.30377587 | H7: =F18 -> 3059361.6 | L7: =F39 -> 57680.317 | P7: =F37 -> 630319.68 | T7: =F44 -> 14337567
A8: =IF(AND(B12>0,F12>=0),(F12/B12)^(1/4)-1,"CAGR n/a") -> 0.29807045 | C8: =F16 -> 3886476.3 | H8: =F19 -> 0.2391267 | L8: ='Break-even'!B6 -> 1 | P8: =IF(F38>=0,"Covered by funding raised",-F38) -> 130319.68 | T8: Average of 2 methods
A10: Core financials ($'000) — active scenario
B11: 1 | C11: 2 | D11: 3 | E11: 4 | F11: 5
A12: Revenue | B12: =SUMIF(Monthly!$C$5:$BJ$5,B$11,Monthly!$C$22:$BJ$22) -> 4506192 | C12: =SUMIF(Monthly!$C$5:$BJ$5,C$11,Monthly!$C$22:$BJ$22) -> 5835961.9 | D12: =SUMIF(Monthly!$C$5:$BJ$5,D$11,Monthly!$C$22:$BJ$22) -> 7569836 | E12: =SUMIF(Monthly!$C$5:$BJ$5,E$11,Monthly!$C$22:$BJ$22) -> 9833787.5 | F12: =SUMIF(Monthly!$C$5:$BJ$5,F$11,Monthly!$C$22:$BJ$22) -> 12793894
A13: Gross profit | B13: =SUMIF(Monthly!$C$5:$BJ$5,B$11,Monthly!$C$29:$BJ$29) -> 1803006.2 | C13: =SUMIF(Monthly!$C$5:$BJ$5,C$11,Monthly!$C$29:$BJ$29) -> 2345931 | D13: =SUMIF(Monthly!$C$5:$BJ$5,D$11,Monthly!$C$29:$BJ$29) -> 3056789.8 | E13: =SUMIF(Monthly!$C$5:$BJ$5,E$11,Monthly!$C$29:$BJ$29) -> 3988708.6 | F13: =SUMIF(Monthly!$C$5:$BJ$5,F$11,Monthly!$C$29:$BJ$29) -> 5211925.2
A14: Gross margin | B14: =IF(B12=0,0,B13/B12) -> 0.40011749 | C14: =IF(C12=0,0,C13/C12) -> 0.40197847 | D14: =IF(D12=0,0,D13/D12) -> 0.40381189 | E14: =IF(E12=0,0,E13/E12) -> 0.40561265 | F14: =IF(F12=0,0,F13/F12) -> 0.40737599
A15: Operating expenses | B15: =SUMIF(Monthly!$C$5:$BJ$5,B$11,Monthly!$C$37:$BJ$37) -> -752400 | C15: =SUMIF(Monthly!$C$5:$BJ$5,C$11,Monthly!$C$37:$BJ$37) -> -856317 | D15: =SUMIF(Monthly!$C$5:$BJ$5,D$11,Monthly!$C$37:$BJ$37) -> -982891.4 | E15: =SUMIF(Monthly!$C$5:$BJ$5,E$11,Monthly!$C$37:$BJ$37) -> -1137191.4 | F15: =SUMIF(Monthly!$C$5:$BJ$5,F$11,Monthly!$C$37:$BJ$37) -> -1325448.9
A16: EBITDA | B16: =SUMIF(Monthly!$C$5:$BJ$5,B$11,Monthly!$C$38:$BJ$38) -> 1050606.2 | C16: =SUMIF(Monthly!$C$5:$BJ$5,C$11,Monthly!$C$38:$BJ$38) -> 1489614 | D16: =SUMIF(Monthly!$C$5:$BJ$5,D$11,Monthly!$C$38:$BJ$38) -> 2073898.4 | E16: =SUMIF(Monthly!$C$5:$BJ$5,E$11,Monthly!$C$38:$BJ$38) -> 2851517.2 | F16: =SUMIF(Monthly!$C$5:$BJ$5,F$11,Monthly!$C$38:$BJ$38) -> 3886476.3
A17: EBITDA margin | B17: =IF(B12=0,0,B16/B12) -> 0.23314724 | C17: =IF(C12=0,0,C16/C12) -> 0.25524739 | D17: =IF(D12=0,0,D16/D12) -> 0.27396874 | E17: =IF(E12=0,0,E16/E12) -> 0.28997141 | F17: =IF(F12=0,0,F16/F12) -> 0.30377587
A18: Net income | B18: =SUMIF(Monthly!$C$5:$BJ$5,B$11,Monthly!$C$47:$BJ$47) -> 808921.04 | C18: =SUMIF(Monthly!$C$5:$BJ$5,C$11,Monthly!$C$47:$BJ$47) -> 1158256.4 | D18: =SUMIF(Monthly!$C$5:$BJ$5,D$11,Monthly!$C$47:$BJ$47) -> 1622369.1 | E18: =SUMIF(Monthly!$C$5:$BJ$5,E$11,Monthly!$C$47:$BJ$47) -> 2239215.9 | F18: =SUMIF(Monthly!$C$5:$BJ$5,F$11,Monthly!$C$47:$BJ$47) -> 3059361.6
A19: Net margin | B19: =IF(B12=0,0,B18/B12) -> 0.17951322 | C19: =IF(C12=0,0,C18/C12) -> 0.19846881 | D19: =IF(D12=0,0,D18/D12) -> 0.21432024 | E19: =IF(E12=0,0,E18/E12) -> 0.22770636 | F19: =IF(F12=0,0,F18/F12) -> 0.2391267
A20: Operating cash flow | B20: =SUMIF(Monthly!$C$5:$BJ$5,B$11,Monthly!$C$71:$BJ$71) -> 370279.78 | C20: =SUMIF(Monthly!$C$5:$BJ$5,C$11,Monthly!$C$71:$BJ$71) -> 1036820.4 | D20: =SUMIF(Monthly!$C$5:$BJ$5,D$11,Monthly!$C$71:$BJ$71) -> 1460260.5 | E20: =SUMIF(Monthly!$C$5:$BJ$5,E$11,Monthly!$C$71:$BJ$71) -> 2023723.4 | F20: =SUMIF(Monthly!$C$5:$BJ$5,F$11,Monthly!$C$71:$BJ$71) -> 2773718.7
A21: Investing cash flow | B21: =SUMIF(Monthly!$C$5:$BJ$5,B$11,Monthly!$C$72:$BJ$72) -> -60000 | C21: =SUMIF(Monthly!$C$5:$BJ$5,C$11,Monthly!$C$72:$BJ$72) -> 0 | D21: =SUMIF(Monthly!$C$5:$BJ$5,D$11,Monthly!$C$72:$BJ$72) -> 0 | E21: =SUMIF(Monthly!$C$5:$BJ$5,E$11,Monthly!$C$72:$BJ$72) -> 0 | F21: =SUMIF(Monthly!$C$5:$BJ$5,F$11,Monthly!$C$72:$BJ$72) -> 0
A22: Financing cash flow | B22: =SUMIF(Monthly!$C$5:$BJ$5,B$11,Monthly!$C$74:$BJ$74) -> 463333.33 | C22: =SUMIF(Monthly!$C$5:$BJ$5,C$11,Monthly!$C$74:$BJ$74) -> -40000 | D22: =SUMIF(Monthly!$C$5:$BJ$5,D$11,Monthly!$C$74:$BJ$74) -> -40000 | E22: =SUMIF(Monthly!$C$5:$BJ$5,E$11,Monthly!$C$74:$BJ$74) -> -40000 | F22: =SUMIF(Monthly!$C$5:$BJ$5,F$11,Monthly!$C$74:$BJ$74) -> -40000
A23: Net change in cash | B23: =SUMIF(Monthly!$C$5:$BJ$5,B$11,Monthly!$C$75:$BJ$75) -> 773613.11 | C23: =SUMIF(Monthly!$C$5:$BJ$5,C$11,Monthly!$C$75:$BJ$75) -> 996820.38 | D23: =SUMIF(Monthly!$C$5:$BJ$5,D$11,Monthly!$C$75:$BJ$75) -> 1420260.5 | E23: =SUMIF(Monthly!$C$5:$BJ$5,E$11,Monthly!$C$75:$BJ$75) -> 1983723.4 | F23: =SUMIF(Monthly!$C$5:$BJ$5,F$11,Monthly!$C$75:$BJ$75) -> 2733718.7
A24: Year-end cash | B24: =INDEX(Monthly!$C$77:$BJ$77,B$11*12) -> 773613.11 | C24: =INDEX(Monthly!$C$77:$BJ$77,C$11*12) -> 1770433.5 | D24: =INDEX(Monthly!$C$77:$BJ$77,D$11*12) -> 3190694 | E24: =INDEX(Monthly!$C$77:$BJ$77,E$11*12) -> 5174417.3 | F24: =INDEX(Monthly!$C$77:$BJ$77,F$11*12) -> 7908136
A26: Services metrics
B27: 1 | C27: 2 | D27: 3 | E27: 4 | F27: 5
A28: Billable hours | B28: =KPIs!B30 -> 24960 | C28: =KPIs!C30 -> 31572 | D28: =KPIs!D30 -> 39992.4 | E28: =KPIs!E30 -> 50728.68 | F28: =KPIs!F30 -> 64433.556
A29: Utilisation of billable employees | B29: =KPIs!B34 -> 0.7 | C29: =KPIs!C34 -> 0.70294118 | D29: =KPIs!D34 -> 0.70576037 | E29: =KPIs!E34 -> 0.70845655 | F29: =KPIs!F34 -> 0.71102952
A30: Effective rate per billable hour | B30: =KPIs!B41 -> 180.53654 | C30: =KPIs!C41 -> 184.84613 | D30: =KPIs!D41 -> 189.28186 | E30: =KPIs!E41 -> 193.85065 | F30: =KPIs!F41 -> 198.55949
A31: Revenue per billable FTE | B31: =KPIs!B42 -> 281637 | C31: =KPIs!C42 -> 286076.56 | D31: =KPIs!D42 -> 290700.31 | E31: =KPIs!E42 -> 295521.92 | F31: =KPIs!F42 -> 300554.74
A32: Team (FTE, year end) | B32: =INDEX(Headcount!$C$12:$BJ$12,B$27*12) -> 21 | C32: =INDEX(Headcount!$C$12:$BJ$12,C$27*12) -> 26.25 | D32: =INDEX(Headcount!$C$12:$BJ$12,D$27*12) -> 32.8875 | E32: =INDEX(Headcount!$C$12:$BJ$12,E$27*12) -> 41.294625 | F32: =INDEX(Headcount!$C$12:$BJ$12,F$27*12) -> 51.961819
A34: Funding & valuation ($'000) — active scenario
A35: Equity raised | F35: =Inputs!$E$54 -> 300000
A36: Loan drawn | F36: =Inputs!$E$55 -> 200000
A37: Funding required (incl. cash buffer) | F37: ='Break-even'!B12 -> 630319.68
A38: Funding surplus / (shortfall) | F38: ='Break-even'!B17 -> -130319.68
A39: ="Lowest cash balance (month "&'Break-even'!B6&")" -> Lowest cash balance (month 1) | F39: ='Break-even'!B18 -> 57680.317
A40: First month with positive EBITDA | F40: ='Break-even'!B21 -> 1
A41: Cash invested paid back | F41: ='Break-even'!B23 -> 8
A42: Enterprise value — perpetual growth | F42: =Valuation!B27 -> 14062289
A43: Enterprise value — exit multiple | F43: =Valuation!C27 -> 14612844
A44: Enterprise value — average | F44: =Valuation!B30 -> 14337567

Sheet Summary
A1: Financial statements summary | U1: =HYPERLINK("#'Cover'!A1","◂ Contents") -> ◂ Contents
A2: Professional services financial model (growing) | P2: Select detailed year: | R2: 1
A5: Income statement ($'000) — by year | H5: ="Income statement ($'000) — Year "&$R$2&", by month" -> Income statement ($'000) — Year 1, by month
B6: 1 | C6: 2 | D6: 3 | E6: 4 | F6: 5 | H6: =INDEX(Monthly!$C$4:$BJ$4,($R$2-1)*12+1) -> 1 | I6: =INDEX(Monthly!$C$4:$BJ$4,($R$2-1)*12+2) -> 2 | J6: =INDEX(Monthly!$C$4:$BJ$4,($R$2-1)*12+3) -> 3 | K6: =INDEX(Monthly!$C$4:$BJ$4,($R$2-1)*12+4) -> 4 | L6: =INDEX(Monthly!$C$4:$BJ$4,($R$2-1)*12+5) -> 5 | M6: =INDEX(Monthly!$C$4:$BJ$4,($R$2-1)*12+6) -> 6 | N6: =INDEX(Monthly!$C$4:$BJ$4,($R$2-1)*12+7) -> 7 | O6: =INDEX(Monthly!$C$4:$BJ$4,($R$2-1)*12+8) -> 8 | P6: =INDEX(Monthly!$C$4:$BJ$4,($R$2-1)*12+9) -> 9 | Q6: =INDEX(Monthly!$C$4:$BJ$4,($R$2-1)*12+10) -> 10 | R6: =INDEX(Monthly!$C$4:$BJ$4,($R$2-1)*12+11) -> 11 | S6: =INDEX(Monthly!$C$4:$BJ$4,($R$2-1)*12+12) -> 12
A7: Revenue | B7: ='P&L'!B5 -> 4506192 | C7: ='P&L'!C5 -> 5835961.9 | D7: ='P&L'!D5 -> 7569836 | E7: ='P&L'!E5 -> 9833787.5 | F7: ='P&L'!F5 -> 12793894 | H7: =INDEX(Monthly!$C$22:$BJ$22,($R$2-1)*12+1) -> 375516 | I7: =INDEX(Monthly!$C$22:$BJ$22,($R$2-1)*12+2) -> 375516 | J7: =INDEX(Monthly!$C$22:$BJ$22,($R$2-1)*12+3) -> 375516 | K7: =INDEX(Monthly!$C$22:$BJ$22,($R$2-1)*12+4) -> 375516 | L7: =INDEX(Monthly!$C$22:$BJ$22,($R$2-1)*12+5) -> 375516 | M7: =INDEX(Monthly!$C$22:$BJ$22,($R$2-1)*12+6) -> 375516 | N7: =INDEX(Monthly!$C$22:$BJ$22,($R$2-1)*12+7) -> 375516 | O7: =INDEX(Monthly!$C$22:$BJ$22,($R$2-1)*12+8) -> 375516 | P7: =INDEX(Monthly!$C$22:$BJ$22,($R$2-1)*12+9) -> 375516 | Q7: =INDEX(Monthly!$C$22:$BJ$22,($R$2-1)*12+10) -> 375516 | R7: =INDEX(Monthly!$C$22:$BJ$22,($R$2-1)*12+11) -> 375516 | S7: =INDEX(Monthly!$C$22:$BJ$22,($R$2-1)*12+12) -> 375516
A8: Cost of delivery | B8: ='P&L'!B6 -> -2703185.8 | C8: ='P&L'!C6 -> -3490030.9 | D8: ='P&L'!D6 -> -4513046.2 | E8: ='P&L'!E6 -> -5845079 | F8: ='P&L'!F6 -> -7581968.8 | H8: =INDEX(Monthly!$C$28:$BJ$28,($R$2-1)*12+1) -> -225265.48 | I8: =INDEX(Monthly!$C$28:$BJ$28,($R$2-1)*12+2) -> -225265.48 | J8: =INDEX(Monthly!$C$28:$BJ$28,($R$2-1)*12+3) -> -225265.48 | K8: =INDEX(Monthly!$C$28:$BJ$28,($R$2-1)*12+4) -> -225265.48 | L8: =INDEX(Monthly!$C$28:$BJ$28,($R$2-1)*12+5) -> -225265.48 | M8: =INDEX(Monthly!$C$28:$BJ$28,($R$2-1)*12+6) -> -225265.48 | N8: =INDEX(Monthly!$C$28:$BJ$28,($R$2-1)*12+7) -> -225265.48 | O8: =INDEX(Monthly!$C$28:$BJ$28,($R$2-1)*12+8) -> -225265.48 | P8: =INDEX(Monthly!$C$28:$BJ$28,($R$2-1)*12+9) -> -225265.48 | Q8: =INDEX(Monthly!$C$28:$BJ$28,($R$2-1)*12+10) -> -225265.48 | R8: =INDEX(Monthly!$C$28:$BJ$28,($R$2-1)*12+11) -> -225265.48 | S8: =INDEX(Monthly!$C$28:$BJ$28,($R$2-1)*12+12) -> -225265.48
A9: Gross profit | B9: ='P&L'!B7 -> 1803006.2 | C9: ='P&L'!C7 -> 2345931 | D9: ='P&L'!D7 -> 3056789.8 | E9: ='P&L'!E7 -> 3988708.6 | F9: ='P&L'!F7 -> 5211925.2 | H9: =INDEX(Monthly!$C$29:$BJ$29,($R$2-1)*12+1) -> 150250.52 | I9: =INDEX(Monthly!$C$29:$BJ$29,($R$2-1)*12+2) -> 150250.52 | J9: =INDEX(Monthly!$C$29:$BJ$29,($R$2-1)*12+3) -> 150250.52 | K9: =INDEX(Monthly!$C$29:$BJ$29,($R$2-1)*12+4) -> 150250.52 | L9: =INDEX(Monthly!$C$29:$BJ$29,($R$2-1)*12+5) -> 150250.52 | M9: =INDEX(Monthly!$C$29:$BJ$29,($R$2-1)*12+6) -> 150250.52 | N9: =INDEX(Monthly!$C$29:$BJ$29,($R$2-1)*12+7) -> 150250.52 | O9: =INDEX(Monthly!$C$29:$BJ$29,($R$2-1)*12+8) -> 150250.52 | P9: =INDEX(Monthly!$C$29:$BJ$29,($R$2-1)*12+9) -> 150250.52 | Q9: =INDEX(Monthly!$C$29:$BJ$29,($R$2-1)*12+10) -> 150250.52 | R9: =INDEX(Monthly!$C$29:$BJ$29,($R$2-1)*12+11) -> 150250.52 | S9: =INDEX(Monthly!$C$29:$BJ$29,($R$2-1)*12+12) -> 150250.52
A10: Gross margin | B10: ='P&L'!B8 -> 0.40011749 | C10: ='P&L'!C8 -> 0.40197847 | D10: ='P&L'!D8 -> 0.40381189 | E10: ='P&L'!E8 -> 0.40561265 | F10: ='P&L'!F8 -> 0.40737599 | H10: =IF(H7=0,0,H9/H7) -> 0.40011749 | I10: =IF(I7=0,0,I9/I7) -> 0.40011749 | J10: =IF(J7=0,0,J9/J7) -> 0.40011749 | K10: =IF(K7=0,0,K9/K7) -> 0.40011749 | L10: =IF(L7=0,0,L9/L7) -> 0.40011749 | M10: =IF(M7=0,0,M9/M7) -> 0.40011749 | N10: =IF(N7=0,0,N9/N7) -> 0.40011749 | O10: =IF(O7=0,0,O9/O7) -> 0.40011749 | ... S10: =IF(S7=0,0,S9/S7) -> 0.40011749
A11: Total operating expenses | B11: ='P&L'!B14 -> -752400 | C11: ='P&L'!C14 -> -856317 | D11: ='P&L'!D14 -> -982891.4 | E11: ='P&L'!E14 -> -1137191.4 | F11: ='P&L'!F14 -> -1325448.9 | H11: =INDEX(Monthly!$C$37:$BJ$37,($R$2-1)*12+1) -> -62700 | I11: =INDEX(Monthly!$C$37:$BJ$37,($R$2-1)*12+2) -> -62700 | J11: =INDEX(Monthly!$C$37:$BJ$37,($R$2-1)*12+3) -> -62700 | K11: =INDEX(Monthly!$C$37:$BJ$37,($R$2-1)*12+4) -> -62700 | L11: =INDEX(Monthly!$C$37:$BJ$37,($R$2-1)*12+5) -> -62700 | M11: =INDEX(Monthly!$C$37:$BJ$37,($R$2-1)*12+6) -> -62700 | N11: =INDEX(Monthly!$C$37:$BJ$37,($R$2-1)*12+7) -> -62700 | O11: =INDEX(Monthly!$C$37:$BJ$37,($R$2-1)*12+8) -> -62700 | P11: =INDEX(Monthly!$C$37:$BJ$37,($R$2-1)*12+9) -> -62700 | Q11: =INDEX(Monthly!$C$37:$BJ$37,($R$2-1)*12+10) -> -62700 | R11: =INDEX(Monthly!$C$37:$BJ$37,($R$2-1)*12+11) -> -62700 | S11: =INDEX(Monthly!$C$37:$BJ$37,($R$2-1)*12+12) -> -62700
A12: EBITDA | B12: ='P&L'!B15 -> 1050606.2 | C12: ='P&L'!C15 -> 1489614 | D12: ='P&L'!D15 -> 2073898.4 | E12: ='P&L'!E15 -> 2851517.2 | F12: ='P&L'!F15 -> 3886476.3 | H12: =INDEX(Monthly!$C$38:$BJ$38,($R$2-1)*12+1) -> 87550.52 | I12: =INDEX(Monthly!$C$38:$BJ$38,($R$2-1)*12+2) -> 87550.52 | J12: =INDEX(Monthly!$C$38:$BJ$38,($R$2-1)*12+3) -> 87550.52 | K12: =INDEX(Monthly!$C$38:$BJ$38,($R$2-1)*12+4) -> 87550.52 | L12: =INDEX(Monthly!$C$38:$BJ$38,($R$2-1)*12+5) -> 87550.52 | M12: =INDEX(Monthly!$C$38:$BJ$38,($R$2-1)*12+6) -> 87550.52 | N12: =INDEX(Monthly!$C$38:$BJ$38,($R$2-1)*12+7) -> 87550.52 | O12: =INDEX(Monthly!$C$38:$BJ$38,($R$2-1)*12+8) -> 87550.52 | P12: =INDEX(Monthly!$C$38:$BJ$38,($R$2-1)*12+9) -> 87550.52 | Q12: =INDEX(Monthly!$C$38:$BJ$38,($R$2-1)*12+10) -> 87550.52 | R12: =INDEX(Monthly!$C$38:$BJ$38,($R$2-1)*12+11) -> 87550.52 | S12: =INDEX(Monthly!$C$38:$BJ$38,($R$2-1)*12+12) -> 87550.52
A13: EBITDA margin | B13: ='P&L'!B16 -> 0.23314724 | C13: ='P&L'!C16 -> 0.25524739 | D13: ='P&L'!D16 -> 0.27396874 | E13: ='P&L'!E16 -> 0.28997141 | F13: ='P&L'!F16 -> 0.30377587 | H13: =IF(H7=0,0,H12/H7) -> 0.23314724 | I13: =IF(I7=0,0,I12/I7) -> 0.23314724 | J13: =IF(J7=0,0,J12/J7) -> 0.23314724 | K13: =IF(K7=0,0,K12/K7) -> 0.23314724 | L13: =IF(L7=0,0,L12/L7) -> 0.23314724 | M13: =IF(M7=0,0,M12/M7) -> 0.23314724 | N13: =IF(N7=0,0,N12/N7) -> 0.23314724 | O13: =IF(O7=0,0,O12/O7) -> 0.23314724 | ... S13: =IF(S7=0,0,S12/S7) -> 0.23314724
A14: Depreciation | B14: ='P&L'!B17 -> -12000 | C14: ='P&L'!C17 -> -12000 | D14: ='P&L'!D17 -> -12000 | E14: ='P&L'!E17 -> -12000 | F14: ='P&L'!F17 -> -12000 | H14: =INDEX(Monthly!$C$52:$BJ$52,($R$2-1)*12+1) -> -1000 | I14: =INDEX(Monthly!$C$52:$BJ$52,($R$2-1)*12+2) -> -1000 | J14: =INDEX(Monthly!$C$52:$BJ$52,($R$2-1)*12+3) -> -1000 | K14: =INDEX(Monthly!$C$52:$BJ$52,($R$2-1)*12+4) -> -1000 | L14: =INDEX(Monthly!$C$52:$BJ$52,($R$2-1)*12+5) -> -1000 | M14: =INDEX(Monthly!$C$52:$BJ$52,($R$2-1)*12+6) -> -1000 | N14: =INDEX(Monthly!$C$52:$BJ$52,($R$2-1)*12+7) -> -1000 | O14: =INDEX(Monthly!$C$52:$BJ$52,($R$2-1)*12+8) -> -1000 | P14: =INDEX(Monthly!$C$52:$BJ$52,($R$2-1)*12+9) -> -1000 | Q14: =INDEX(Monthly!$C$52:$BJ$52,($R$2-1)*12+10) -> -1000 | R14: =INDEX(Monthly!$C$52:$BJ$52,($R$2-1)*12+11) -> -1000 | S14: =INDEX(Monthly!$C$52:$BJ$52,($R$2-1)*12+12) -> -1000
A15: EBIT | B15: ='P&L'!B18 -> 1038606.2 | C15: ='P&L'!C18 -> 1477614 | D15: ='P&L'!D18 -> 2061898.4 | E15: ='P&L'!E18 -> 2839517.2 | F15: ='P&L'!F18 -> 3874476.3 | H15: =INDEX(Monthly!$C$41:$BJ$41,($R$2-1)*12+1) -> 86550.52 | I15: =INDEX(Monthly!$C$41:$BJ$41,($R$2-1)*12+2) -> 86550.52 | J15: =INDEX(Monthly!$C$41:$BJ$41,($R$2-1)*12+3) -> 86550.52 | K15: =INDEX(Monthly!$C$41:$BJ$41,($R$2-1)*12+4) -> 86550.52 | L15: =INDEX(Monthly!$C$41:$BJ$41,($R$2-1)*12+5) -> 86550.52 | M15: =INDEX(Monthly!$C$41:$BJ$41,($R$2-1)*12+6) -> 86550.52 | N15: =INDEX(Monthly!$C$41:$BJ$41,($R$2-1)*12+7) -> 86550.52 | O15: =INDEX(Monthly!$C$41:$BJ$41,($R$2-1)*12+8) -> 86550.52 | P15: =INDEX(Monthly!$C$41:$BJ$41,($R$2-1)*12+9) -> 86550.52 | Q15: =INDEX(Monthly!$C$41:$BJ$41,($R$2-1)*12+10) -> 86550.52 | R15: =INDEX(Monthly!$C$41:$BJ$41,($R$2-1)*12+11) -> 86550.52 | S15: =INDEX(Monthly!$C$41:$BJ$41,($R$2-1)*12+12) -> 86550.52
A16: Interest | B16: ='P&L'!B19 -> -14655.556 | C16: ='P&L'!C19 -> -11466.667 | D16: ='P&L'!D19 -> -8266.6667 | E16: ='P&L'!E19 -> -5066.6667 | F16: ='P&L'!F19 -> -1866.6667 | H16: =INDEX(Monthly!$C$42:$BJ$42,($R$2-1)*12+1) -> -1333.3333 | I16: =INDEX(Monthly!$C$42:$BJ$42,($R$2-1)*12+2) -> -1322.2222 | J16: =INDEX(Monthly!$C$42:$BJ$42,($R$2-1)*12+3) -> -1300 | K16: =INDEX(Monthly!$C$42:$BJ$42,($R$2-1)*12+4) -> -1277.7778 | L16: =INDEX(Monthly!$C$42:$BJ$42,($R$2-1)*12+5) -> -1255.5556 | M16: =INDEX(Monthly!$C$42:$BJ$42,($R$2-1)*12+6) -> -1233.3333 | N16: =INDEX(Monthly!$C$42:$BJ$42,($R$2-1)*12+7) -> -1211.1111 | O16: =INDEX(Monthly!$C$42:$BJ$42,($R$2-1)*12+8) -> -1188.8889 | P16: =INDEX(Monthly!$C$42:$BJ$42,($R$2-1)*12+9) -> -1166.6667 | Q16: =INDEX(Monthly!$C$42:$BJ$42,($R$2-1)*12+10) -> -1144.4444 | R16: =INDEX(Monthly!$C$42:$BJ$42,($R$2-1)*12+11) -> -1122.2222 | S16: =INDEX(Monthly!$C$42:$BJ$42,($R$2-1)*12+12) -> -1100
A17: Pre-tax income | B17: ='P&L'!B20 -> 1023950.7 | C17: ='P&L'!C20 -> 1466147.3 | D17: ='P&L'!D20 -> 2053631.8 | E17: ='P&L'!E20 -> 2834450.6 | F17: ='P&L'!F20 -> 3872609.6 | H17: =INDEX(Monthly!$C$43:$BJ$43,($R$2-1)*12+1) -> 85217.187 | I17: =INDEX(Monthly!$C$43:$BJ$43,($R$2-1)*12+2) -> 85228.298 | J17: =INDEX(Monthly!$C$43:$BJ$43,($R$2-1)*12+3) -> 85250.52 | K17: =INDEX(Monthly!$C$43:$BJ$43,($R$2-1)*12+4) -> 85272.742 | L17: =INDEX(Monthly!$C$43:$BJ$43,($R$2-1)*12+5) -> 85294.964 | M17: =INDEX(Monthly!$C$43:$BJ$43,($R$2-1)*12+6) -> 85317.187 | N17: =INDEX(Monthly!$C$43:$BJ$43,($R$2-1)*12+7) -> 85339.409 | O17: =INDEX(Monthly!$C$43:$BJ$43,($R$2-1)*12+8) -> 85361.631 | P17: =INDEX(Monthly!$C$43:$BJ$43,($R$2-1)*12+9) -> 85383.853 | Q17: =INDEX(Monthly!$C$43:$BJ$43,($R$2-1)*12+10) -> 85406.076 | R17: =INDEX(Monthly!$C$43:$BJ$43,($R$2-1)*12+11) -> 85428.298 | S17: =INDEX(Monthly!$C$43:$BJ$43,($R$2-1)*12+12) -> 85450.52
A18: Income tax | B18: ='P&L'!B21 -> -215029.64 | C18: ='P&L'!C21 -> -307890.94 | D18: ='P&L'!D21 -> -431262.67 | E18: ='P&L'!E21 -> -595234.62 | F18: ='P&L'!F21 -> -813248.02 | H18: =INDEX(Monthly!$C$46:$BJ$46,($R$2-1)*12+1) -> -17895.609 | I18: =INDEX(Monthly!$C$46:$BJ$46,($R$2-1)*12+2) -> -17897.943 | J18: =INDEX(Monthly!$C$46:$BJ$46,($R$2-1)*12+3) -> -17902.609 | K18: =INDEX(Monthly!$C$46:$BJ$46,($R$2-1)*12+4) -> -17907.276 | L18: =INDEX(Monthly!$C$46:$BJ$46,($R$2-1)*12+5) -> -17911.943 | M18: =INDEX(Monthly!$C$46:$BJ$46,($R$2-1)*12+6) -> -17916.609 | N18: =INDEX(Monthly!$C$46:$BJ$46,($R$2-1)*12+7) -> -17921.276 | O18: =INDEX(Monthly!$C$46:$BJ$46,($R$2-1)*12+8) -> -17925.943 | P18: =INDEX(Monthly!$C$46:$BJ$46,($R$2-1)*12+9) -> -17930.609 | Q18: =INDEX(Monthly!$C$46:$BJ$46,($R$2-1)*12+10) -> -17935.276 | R18: =INDEX(Monthly!$C$46:$BJ$46,($R$2-1)*12+11) -> -17939.943 | S18: =INDEX(Monthly!$C$46:$BJ$46,($R$2-1)*12+12) -> -17944.609
A19: Net income | B19: ='P&L'!B22 -> 808921.04 | C19: ='P&L'!C22 -> 1158256.4 | D19: ='P&L'!D22 -> 1622369.1 | E19: ='P&L'!E22 -> 2239215.9 | F19: ='P&L'!F22 -> 3059361.6 | H19: =INDEX(Monthly!$C$47:$BJ$47,($R$2-1)*12+1) -> 67321.577 | I19: =INDEX(Monthly!$C$47:$BJ$47,($R$2-1)*12+2) -> 67330.355 | J19: =INDEX(Monthly!$C$47:$BJ$47,($R$2-1)*12+3) -> 67347.911 | K19: =INDEX(Monthly!$C$47:$BJ$47,($R$2-1)*12+4) -> 67365.466 | L19: =INDEX(Monthly!$C$47:$BJ$47,($R$2-1)*12+5) -> 67383.022 | M19: =INDEX(Monthly!$C$47:$BJ$47,($R$2-1)*12+6) -> 67400.577 | N19: =INDEX(Monthly!$C$47:$BJ$47,($R$2-1)*12+7) -> 67418.133 | O19: =INDEX(Monthly!$C$47:$BJ$47,($R$2-1)*12+8) -> 67435.689 | P19: =INDEX(Monthly!$C$47:$BJ$47,($R$2-1)*12+9) -> 67453.244 | Q19: =INDEX(Monthly!$C$47:$BJ$47,($R$2-1)*12+10) -> 67470.8 | R19: =INDEX(Monthly!$C$47:$BJ$47,($R$2-1)*12+11) -> 67488.355 | S19: =INDEX(Monthly!$C$47:$BJ$47,($R$2-1)*12+12) -> 67505.911
A20: Net margin | B20: ='P&L'!B23 -> 0.17951322 | C20: ='P&L'!C23 -> 0.19846881 | D20: ='P&L'!D23 -> 0.21432024 | E20: ='P&L'!E23 -> 0.22770636 | F20: ='P&L'!F23 -> 0.2391267 | H20: =IF(H7=0,0,H19/H7) -> 0.17927752 | I20: =IF(I7=0,0,I19/I7) -> 0.1793009 | J20: =IF(J7=0,0,J19/J7) -> 0.17934765 | K20: =IF(K7=0,0,K19/K7) -> 0.1793944 | L20: =IF(L7=0,0,L19/L7) -> 0.17944115 | M20: =IF(M7=0,0,M19/M7) -> 0.1794879 | N20: =IF(N7=0,0,N19/N7) -> 0.17953465 | O20: =IF(O7=0,0,O19/O7) -> 0.1795814 | ... S20: =IF(S7=0,0,S19/S7) -> 0.1797684
A22: Cash flow ($'000) — by year | H22: ="Cash flow ($'000) — Year "&$R$2&", by month" -> Cash flow ($'000) — Year 1, by month
B23: 1 | C23: 2 | D23: 3 | E23: 4 | F23: 5 | H23: =INDEX(Monthly!$C$4:$BJ$4,($R$2-1)*12+1) -> 1 | I23: =INDEX(Monthly!$C$4:$BJ$4,($R$2-1)*12+2) -> 2 | J23: =INDEX(Monthly!$C$4:$BJ$4,($R$2-1)*12+3) -> 3 | K23: =INDEX(Monthly!$C$4:$BJ$4,($R$2-1)*12+4) -> 4 | L23: =INDEX(Monthly!$C$4:$BJ$4,($R$2-1)*12+5) -> 5 | M23: =INDEX(Monthly!$C$4:$BJ$4,($R$2-1)*12+6) -> 6 | N23: =INDEX(Monthly!$C$4:$BJ$4,($R$2-1)*12+7) -> 7 | O23: =INDEX(Monthly!$C$4:$BJ$4,($R$2-1)*12+8) -> 8 | P23: =INDEX(Monthly!$C$4:$BJ$4,($R$2-1)*12+9) -> 9 | Q23: =INDEX(Monthly!$C$4:$BJ$4,($R$2-1)*12+10) -> 10 | R23: =INDEX(Monthly!$C$4:$BJ$4,($R$2-1)*12+11) -> 11 | S23: =INDEX(Monthly!$C$4:$BJ$4,($R$2-1)*12+12) -> 12
A24: Operating cash flow | B24: ='Cash Flow'!B10 -> 370279.78 | C24: ='Cash Flow'!C10 -> 1036820.4 | D24: ='Cash Flow'!D10 -> 1460260.5 | E24: ='Cash Flow'!E10 -> 2023723.4 | F24: ='Cash Flow'!F10 -> 2773718.7 | H24: =INDEX(Monthly!$C$71:$BJ$71,($R$2-1)*12+1) -> -382319.68 | I24: =INDEX(Monthly!$C$71:$BJ$71,($R$2-1)*12+2) -> 68330.355 | J24: =INDEX(Monthly!$C$71:$BJ$71,($R$2-1)*12+3) -> 68347.911 | K24: =INDEX(Monthly!$C$71:$BJ$71,($R$2-1)*12+4) -> 68365.466 | L24: =INDEX(Monthly!$C$71:$BJ$71,($R$2-1)*12+5) -> 68383.022 | M24: =INDEX(Monthly!$C$71:$BJ$71,($R$2-1)*12+6) -> 68400.577 | N24: =INDEX(Monthly!$C$71:$BJ$71,($R$2-1)*12+7) -> 68418.133 | O24: =INDEX(Monthly!$C$71:$BJ$71,($R$2-1)*12+8) -> 68435.689 | P24: =INDEX(Monthly!$C$71:$BJ$71,($R$2-1)*12+9) -> 68453.244 | Q24: =INDEX(Monthly!$C$71:$BJ$71,($R$2-1)*12+10) -> 68470.8 | R24: =INDEX(Monthly!$C$71:$BJ$71,($R$2-1)*12+11) -> 68488.355 | S24: =INDEX(Monthly!$C$71:$BJ$71,($R$2-1)*12+12) -> 68505.911
A25: Capital spending | B25: ='Cash Flow'!B11 -> -60000 | C25: ='Cash Flow'!C11 -> 0 | D25: ='Cash Flow'!D11 -> 0 | E25: ='Cash Flow'!E11 -> 0 | F25: ='Cash Flow'!F11 -> 0 | H25: =INDEX(Monthly!$C$72:$BJ$72,($R$2-1)*12+1) -> -60000 | I25: =INDEX(Monthly!$C$72:$BJ$72,($R$2-1)*12+2) -> 0 | J25: =INDEX(Monthly!$C$72:$BJ$72,($R$2-1)*12+3) -> 0 | K25: =INDEX(Monthly!$C$72:$BJ$72,($R$2-1)*12+4) -> 0 | L25: =INDEX(Monthly!$C$72:$BJ$72,($R$2-1)*12+5) -> 0 | M25: =INDEX(Monthly!$C$72:$BJ$72,($R$2-1)*12+6) -> 0 | N25: =INDEX(Monthly!$C$72:$BJ$72,($R$2-1)*12+7) -> 0 | O25: =INDEX(Monthly!$C$72:$BJ$72,($R$2-1)*12+8) -> 0 | P25: =INDEX(Monthly!$C$72:$BJ$72,($R$2-1)*12+9) -> 0 | Q25: =INDEX(Monthly!$C$72:$BJ$72,($R$2-1)*12+10) -> 0 | R25: =INDEX(Monthly!$C$72:$BJ$72,($R$2-1)*12+11) -> 0 | S25: =INDEX(Monthly!$C$72:$BJ$72,($R$2-1)*12+12) -> 0
A26: Equity raised | B26: ='Cash Flow'!B12 -> 300000 | C26: ='Cash Flow'!C12 -> 0 | D26: ='Cash Flow'!D12 -> 0 | E26: ='Cash Flow'!E12 -> 0 | F26: ='Cash Flow'!F12 -> 0 | H26: =INDEX(Monthly!$C$73:$BJ$73,($R$2-1)*12+1) -> 300000 | I26: =INDEX(Monthly!$C$73:$BJ$73,($R$2-1)*12+2) -> 0 | J26: =INDEX(Monthly!$C$73:$BJ$73,($R$2-1)*12+3) -> 0 | K26: =INDEX(Monthly!$C$73:$BJ$73,($R$2-1)*12+4) -> 0 | L26: =INDEX(Monthly!$C$73:$BJ$73,($R$2-1)*12+5) -> 0 | M26: =INDEX(Monthly!$C$73:$BJ$73,($R$2-1)*12+6) -> 0 | N26: =INDEX(Monthly!$C$73:$BJ$73,($R$2-1)*12+7) -> 0 | O26: =INDEX(Monthly!$C$73:$BJ$73,($R$2-1)*12+8) -> 0 | P26: =INDEX(Monthly!$C$73:$BJ$73,($R$2-1)*12+9) -> 0 | Q26: =INDEX(Monthly!$C$73:$BJ$73,($R$2-1)*12+10) -> 0 | R26: =INDEX(Monthly!$C$73:$BJ$73,($R$2-1)*12+11) -> 0 | S26: =INDEX(Monthly!$C$73:$BJ$73,($R$2-1)*12+12) -> 0
A27: Loan drawdown | B27: ='Cash Flow'!B13 -> 200000 | C27: ='Cash Flow'!C13 -> 0 | D27: ='Cash Flow'!D13 -> 0 | E27: ='Cash Flow'!E13 -> 0 | F27: ='Cash Flow'!F13 -> 0 | H27: =INDEX(Monthly!$C$58:$BJ$58,($R$2-1)*12+1) -> 200000 | I27: =INDEX(Monthly!$C$58:$BJ$58,($R$2-1)*12+2) -> 0 | J27: =INDEX(Monthly!$C$58:$BJ$58,($R$2-1)*12+3) -> 0 | K27: =INDEX(Monthly!$C$58:$BJ$58,($R$2-1)*12+4) -> 0 | L27: =INDEX(Monthly!$C$58:$BJ$58,($R$2-1)*12+5) -> 0 | M27: =INDEX(Monthly!$C$58:$BJ$58,($R$2-1)*12+6) -> 0 | N27: =INDEX(Monthly!$C$58:$BJ$58,($R$2-1)*12+7) -> 0 | O27: =INDEX(Monthly!$C$58:$BJ$58,($R$2-1)*12+8) -> 0 | P27: =INDEX(Monthly!$C$58:$BJ$58,($R$2-1)*12+9) -> 0 | Q27: =INDEX(Monthly!$C$58:$BJ$58,($R$2-1)*12+10) -> 0 | R27: =INDEX(Monthly!$C$58:$BJ$58,($R$2-1)*12+11) -> 0 | S27: =INDEX(Monthly!$C$58:$BJ$58,($R$2-1)*12+12) -> 0
A28: Loan repayment | B28: ='Cash Flow'!B14 -> -36666.667 | C28: ='Cash Flow'!C14 -> -40000 | D28: ='Cash Flow'!D14 -> -40000 | E28: ='Cash Flow'!E14 -> -40000 | F28: ='Cash Flow'!F14 -> -40000 | H28: =INDEX(Monthly!$C$59:$BJ$59,($R$2-1)*12+1) -> 0 | I28: =INDEX(Monthly!$C$59:$BJ$59,($R$2-1)*12+2) -> -3333.3333 | J28: =INDEX(Monthly!$C$59:$BJ$59,($R$2-1)*12+3) -> -3333.3333 | K28: =INDEX(Monthly!$C$59:$BJ$59,($R$2-1)*12+4) -> -3333.3333 | L28: =INDEX(Monthly!$C$59:$BJ$59,($R$2-1)*12+5) -> -3333.3333 | M28: =INDEX(Monthly!$C$59:$BJ$59,($R$2-1)*12+6) -> -3333.3333 | N28: =INDEX(Monthly!$C$59:$BJ$59,($R$2-1)*12+7) -> -3333.3333 | O28: =INDEX(Monthly!$C$59:$BJ$59,($R$2-1)*12+8) -> -3333.3333 | P28: =INDEX(Monthly!$C$59:$BJ$59,($R$2-1)*12+9) -> -3333.3333 | Q28: =INDEX(Monthly!$C$59:$BJ$59,($R$2-1)*12+10) -> -3333.3333 | R28: =INDEX(Monthly!$C$59:$BJ$59,($R$2-1)*12+11) -> -3333.3333 | S28: =INDEX(Monthly!$C$59:$BJ$59,($R$2-1)*12+12) -> -3333.3333
A29: Financing cash flow | B29: ='Cash Flow'!B15 -> 463333.33 | C29: ='Cash Flow'!C15 -> -40000 | D29: ='Cash Flow'!D15 -> -40000 | E29: ='Cash Flow'!E15 -> -40000 | F29: ='Cash Flow'!F15 -> -40000 | H29: =INDEX(Monthly!$C$74:$BJ$74,($R$2-1)*12+1) -> 500000 | I29: =INDEX(Monthly!$C$74:$BJ$74,($R$2-1)*12+2) -> -3333.3333 | J29: =INDEX(Monthly!$C$74:$BJ$74,($R$2-1)*12+3) -> -3333.3333 | K29: =INDEX(Monthly!$C$74:$BJ$74,($R$2-1)*12+4) -> -3333.3333 | L29: =INDEX(Monthly!$C$74:$BJ$74,($R$2-1)*12+5) -> -3333.3333 | M29: =INDEX(Monthly!$C$74:$BJ$74,($R$2-1)*12+6) -> -3333.3333 | N29: =INDEX(Monthly!$C$74:$BJ$74,($R$2-1)*12+7) -> -3333.3333 | O29: =INDEX(Monthly!$C$74:$BJ$74,($R$2-1)*12+8) -> -3333.3333 | P29: =INDEX(Monthly!$C$74:$BJ$74,($R$2-1)*12+9) -> -3333.3333 | Q29: =INDEX(Monthly!$C$74:$BJ$74,($R$2-1)*12+10) -> -3333.3333 | R29: =INDEX(Monthly!$C$74:$BJ$74,($R$2-1)*12+11) -> -3333.3333 | S29: =INDEX(Monthly!$C$74:$BJ$74,($R$2-1)*12+12) -> -3333.3333
A30: Net change in cash | B30: ='Cash Flow'!B16 -> 773613.11 | C30: ='Cash Flow'!C16 -> 996820.38 | D30: ='Cash Flow'!D16 -> 1420260.5 | E30: ='Cash Flow'!E16 -> 1983723.4 | F30: ='Cash Flow'!F16 -> 2733718.7 | H30: =INDEX(Monthly!$C$75:$BJ$75,($R$2-1)*12+1) -> 57680.317 | I30: =INDEX(Monthly!$C$75:$BJ$75,($R$2-1)*12+2) -> 64997.022 | J30: =INDEX(Monthly!$C$75:$BJ$75,($R$2-1)*12+3) -> 65014.577 | K30: =INDEX(Monthly!$C$75:$BJ$75,($R$2-1)*12+4) -> 65032.133 | L30: =INDEX(Monthly!$C$75:$BJ$75,($R$2-1)*12+5) -> 65049.689 | M30: =INDEX(Monthly!$C$75:$BJ$75,($R$2-1)*12+6) -> 65067.244 | N30: =INDEX(Monthly!$C$75:$BJ$75,($R$2-1)*12+7) -> 65084.8 | O30: =INDEX(Monthly!$C$75:$BJ$75,($R$2-1)*12+8) -> 65102.355 | P30: =INDEX(Monthly!$C$75:$BJ$75,($R$2-1)*12+9) -> 65119.911 | Q30: =INDEX(Monthly!$C$75:$BJ$75,($R$2-1)*12+10) -> 65137.466 | R30: =INDEX(Monthly!$C$75:$BJ$75,($R$2-1)*12+11) -> 65155.022 | S30: =INDEX(Monthly!$C$75:$BJ$75,($R$2-1)*12+12) -> 65172.577
A31: Closing cash | B31: ='Cash Flow'!B18 -> 773613.11 | C31: ='Cash Flow'!C18 -> 1770433.5 | D31: ='Cash Flow'!D18 -> 3190694 | E31: ='Cash Flow'!E18 -> 5174417.3 | F31: ='Cash Flow'!F18 -> 7908136 | H31: =INDEX(Monthly!$C$77:$BJ$77,($R$2-1)*12+1) -> 57680.317 | I31: =INDEX(Monthly!$C$77:$BJ$77,($R$2-1)*12+2) -> 122677.34 | J31: =INDEX(Monthly!$C$77:$BJ$77,($R$2-1)*12+3) -> 187691.92 | K31: =INDEX(Monthly!$C$77:$BJ$77,($R$2-1)*12+4) -> 252724.05 | L31: =INDEX(Monthly!$C$77:$BJ$77,($R$2-1)*12+5) -> 317773.74 | M31: =INDEX(Monthly!$C$77:$BJ$77,($R$2-1)*12+6) -> 382840.98 | N31: =INDEX(Monthly!$C$77:$BJ$77,($R$2-1)*12+7) -> 447925.78 | O31: =INDEX(Monthly!$C$77:$BJ$77,($R$2-1)*12+8) -> 513028.14 | P31: =INDEX(Monthly!$C$77:$BJ$77,($R$2-1)*12+9) -> 578148.05 | Q31: =INDEX(Monthly!$C$77:$BJ$77,($R$2-1)*12+10) -> 643285.51 | R31: =INDEX(Monthly!$C$77:$BJ$77,($R$2-1)*12+11) -> 708440.54 | S31: =INDEX(Monthly!$C$77:$BJ$77,($R$2-1)*12+12) -> 773613.11
A39: Balance sheet at year end ($'000) | H39: ="Balance sheet at month end ($'000) — Year "&$R$2 -> Balance sheet at month end ($'000) — Year 1
B40: 1 | C40: 2 | D40: 3 | E40: 4 | F40: 5 | H40: =INDEX(Monthly!$C$4:$BJ$4,($R$2-1)*12+1) -> 1 | I40: =INDEX(Monthly!$C$4:$BJ$4,($R$2-1)*12+2) -> 2 | J40: =INDEX(Monthly!$C$4:$BJ$4,($R$2-1)*12+3) -> 3 | K40: =INDEX(Monthly!$C$4:$BJ$4,($R$2-1)*12+4) -> 4 | L40: =INDEX(Monthly!$C$4:$BJ$4,($R$2-1)*12+5) -> 5 | M40: =INDEX(Monthly!$C$4:$BJ$4,($R$2-1)*12+6) -> 6 | N40: =INDEX(Monthly!$C$4:$BJ$4,($R$2-1)*12+7) -> 7 | O40: =INDEX(Monthly!$C$4:$BJ$4,($R$2-1)*12+8) -> 8 | P40: =INDEX(Monthly!$C$4:$BJ$4,($R$2-1)*12+9) -> 9 | Q40: =INDEX(Monthly!$C$4:$BJ$4,($R$2-1)*12+10) -> 10 | R40: =INDEX(Monthly!$C$4:$BJ$4,($R$2-1)*12+11) -> 11 | S40: =INDEX(Monthly!$C$4:$BJ$4,($R$2-1)*12+12) -> 12
A41: Cash | B41: ='Balance Sheet'!B5 -> 773613.11 | C41: ='Balance Sheet'!C5 -> 1770433.5 | D41: ='Balance Sheet'!D5 -> 3190694 | E41: ='Balance Sheet'!E5 -> 5174417.3 | F41: ='Balance Sheet'!F5 -> 7908136 | H41: =INDEX(Monthly!$C$77:$BJ$77,($R$2-1)*12+1) -> 57680.317 | I41: =INDEX(Monthly!$C$77:$BJ$77,($R$2-1)*12+2) -> 122677.34 | J41: =INDEX(Monthly!$C$77:$BJ$77,($R$2-1)*12+3) -> 187691.92 | K41: =INDEX(Monthly!$C$77:$BJ$77,($R$2-1)*12+4) -> 252724.05 | L41: =INDEX(Monthly!$C$77:$BJ$77,($R$2-1)*12+5) -> 317773.74 | M41: =INDEX(Monthly!$C$77:$BJ$77,($R$2-1)*12+6) -> 382840.98 | N41: =INDEX(Monthly!$C$77:$BJ$77,($R$2-1)*12+7) -> 447925.78 | O41: =INDEX(Monthly!$C$77:$BJ$77,($R$2-1)*12+8) -> 513028.14 | P41: =INDEX(Monthly!$C$77:$BJ$77,($R$2-1)*12+9) -> 578148.05 | Q41: =INDEX(Monthly!$C$77:$BJ$77,($R$2-1)*12+10) -> 643285.51 | R41: =INDEX(Monthly!$C$77:$BJ$77,($R$2-1)*12+11) -> 708440.54 | S41: =INDEX(Monthly!$C$77:$BJ$77,($R$2-1)*12+12) -> 773613.11
A42: Accounts receivable | B42: ='Balance Sheet'!B6 -> 563274 | C42: ='Balance Sheet'!C6 -> 729495.23 | D42: ='Balance Sheet'!D6 -> 946229.5 | E42: ='Balance Sheet'!E6 -> 1229223.4 | F42: ='Balance Sheet'!F6 -> 1599236.8 | H42: =INDEX(Monthly!$C$63:$BJ$63,($R$2-1)*12+1) -> 563274 | I42: =INDEX(Monthly!$C$63:$BJ$63,($R$2-1)*12+2) -> 563274 | J42: =INDEX(Monthly!$C$63:$BJ$63,($R$2-1)*12+3) -> 563274 | K42: =INDEX(Monthly!$C$63:$BJ$63,($R$2-1)*12+4) -> 563274 | L42: =INDEX(Monthly!$C$63:$BJ$63,($R$2-1)*12+5) -> 563274 | M42: =INDEX(Monthly!$C$63:$BJ$63,($R$2-1)*12+6) -> 563274 | N42: =INDEX(Monthly!$C$63:$BJ$63,($R$2-1)*12+7) -> 563274 | O42: =INDEX(Monthly!$C$63:$BJ$63,($R$2-1)*12+8) -> 563274 | P42: =INDEX(Monthly!$C$63:$BJ$63,($R$2-1)*12+9) -> 563274 | Q42: =INDEX(Monthly!$C$63:$BJ$63,($R$2-1)*12+10) -> 563274 | R42: =INDEX(Monthly!$C$63:$BJ$63,($R$2-1)*12+11) -> 563274 | S42: =INDEX(Monthly!$C$63:$BJ$63,($R$2-1)*12+12) -> 563274
A43: Inventory | B43: ='Balance Sheet'!B7 -> 0 | C43: ='Balance Sheet'!C7 -> 0 | D43: ='Balance Sheet'!D7 -> 0 | E43: ='Balance Sheet'!E7 -> 0 | F43: ='Balance Sheet'!F7 -> 0 | H43: =INDEX(Monthly!$C$64:$BJ$64,($R$2-1)*12+1) -> 0 | I43: =INDEX(Monthly!$C$64:$BJ$64,($R$2-1)*12+2) -> 0 | J43: =INDEX(Monthly!$C$64:$BJ$64,($R$2-1)*12+3) -> 0 | K43: =INDEX(Monthly!$C$64:$BJ$64,($R$2-1)*12+4) -> 0 | L43: =INDEX(Monthly!$C$64:$BJ$64,($R$2-1)*12+5) -> 0 | M43: =INDEX(Monthly!$C$64:$BJ$64,($R$2-1)*12+6) -> 0 | N43: =INDEX(Monthly!$C$64:$BJ$64,($R$2-1)*12+7) -> 0 | O43: =INDEX(Monthly!$C$64:$BJ$64,($R$2-1)*12+8) -> 0 | P43: =INDEX(Monthly!$C$64:$BJ$64,($R$2-1)*12+9) -> 0 | Q43: =INDEX(Monthly!$C$64:$BJ$64,($R$2-1)*12+10) -> 0 | R43: =INDEX(Monthly!$C$64:$BJ$64,($R$2-1)*12+11) -> 0 | S43: =INDEX(Monthly!$C$64:$BJ$64,($R$2-1)*12+12) -> 0
A44: Net fixed assets | B44: ='Balance Sheet'!B8 -> 48000 | C44: ='Balance Sheet'!C8 -> 36000 | D44: ='Balance Sheet'!D8 -> 24000 | E44: ='Balance Sheet'!E8 -> 12000 | F44: ='Balance Sheet'!F8 -> 0 | H44: =INDEX(Monthly!$C$54:$BJ$54,($R$2-1)*12+1) -> 59000 | I44: =INDEX(Monthly!$C$54:$BJ$54,($R$2-1)*12+2) -> 58000 | J44: =INDEX(Monthly!$C$54:$BJ$54,($R$2-1)*12+3) -> 57000 | K44: =INDEX(Monthly!$C$54:$BJ$54,($R$2-1)*12+4) -> 56000 | L44: =INDEX(Monthly!$C$54:$BJ$54,($R$2-1)*12+5) -> 55000 | M44: =INDEX(Monthly!$C$54:$BJ$54,($R$2-1)*12+6) -> 54000 | N44: =INDEX(Monthly!$C$54:$BJ$54,($R$2-1)*12+7) -> 53000 | O44: =INDEX(Monthly!$C$54:$BJ$54,($R$2-1)*12+8) -> 52000 | P44: =INDEX(Monthly!$C$54:$BJ$54,($R$2-1)*12+9) -> 51000 | Q44: =INDEX(Monthly!$C$54:$BJ$54,($R$2-1)*12+10) -> 50000 | R44: =INDEX(Monthly!$C$54:$BJ$54,($R$2-1)*12+11) -> 49000 | S44: =INDEX(Monthly!$C$54:$BJ$54,($R$2-1)*12+12) -> 48000
A45: Total assets | B45: ='Balance Sheet'!B9 -> 1384887.1 | C45: ='Balance Sheet'!C9 -> 2535928.7 | D45: ='Balance Sheet'!D9 -> 4160923.5 | E45: ='Balance Sheet'!E9 -> 6415640.8 | F45: ='Balance Sheet'!F9 -> 9507372.8 | H45: =INDEX(Monthly!$C$91:$BJ$91,($R$2-1)*12+1) -> 679954.32 | I45: =INDEX(Monthly!$C$91:$BJ$91,($R$2-1)*12+2) -> 743951.34 | J45: =INDEX(Monthly!$C$91:$BJ$91,($R$2-1)*12+3) -> 807965.92 | K45: =INDEX(Monthly!$C$91:$BJ$91,($R$2-1)*12+4) -> 871998.05 | L45: =INDEX(Monthly!$C$91:$BJ$91,($R$2-1)*12+5) -> 936047.74 | M45: =INDEX(Monthly!$C$91:$BJ$91,($R$2-1)*12+6) -> 1000115 | N45: =INDEX(Monthly!$C$91:$BJ$91,($R$2-1)*12+7) -> 1064199.8 | O45: =INDEX(Monthly!$C$91:$BJ$91,($R$2-1)*12+8) -> 1128302.1 | P45: =INDEX(Monthly!$C$91:$BJ$91,($R$2-1)*12+9) -> 1192422 | Q45: =INDEX(Monthly!$C$91:$BJ$91,($R$2-1)*12+10) -> 1256559.5 | R45: =INDEX(Monthly!$C$91:$BJ$91,($R$2-1)*12+11) -> 1320714.5 | S45: =INDEX(Monthly!$C$91:$BJ$91,($R$2-1)*12+12) -> 1384887.1
A46: Accounts payable | B46: ='Balance Sheet'!B10 -> 112632.74 | C46: ='Balance Sheet'!C10 -> 145417.95 | D46: ='Balance Sheet'!D10 -> 188043.59 | E46: ='Balance Sheet'!E10 -> 243544.96 | F46: ='Balance Sheet'!F10 -> 315915.37 | H46: =INDEX(Monthly!$C$65:$BJ$65,($R$2-1)*12+1) -> 112632.74 | I46: =INDEX(Monthly!$C$65:$BJ$65,($R$2-1)*12+2) -> 112632.74 | J46: =INDEX(Monthly!$C$65:$BJ$65,($R$2-1)*12+3) -> 112632.74 | K46: =INDEX(Monthly!$C$65:$BJ$65,($R$2-1)*12+4) -> 112632.74 | L46: =INDEX(Monthly!$C$65:$BJ$65,($R$2-1)*12+5) -> 112632.74 | M46: =INDEX(Monthly!$C$65:$BJ$65,($R$2-1)*12+6) -> 112632.74 | N46: =INDEX(Monthly!$C$65:$BJ$65,($R$2-1)*12+7) -> 112632.74 | O46: =INDEX(Monthly!$C$65:$BJ$65,($R$2-1)*12+8) -> 112632.74 | P46: =INDEX(Monthly!$C$65:$BJ$65,($R$2-1)*12+9) -> 112632.74 | Q46: =INDEX(Monthly!$C$65:$BJ$65,($R$2-1)*12+10) -> 112632.74 | R46: =INDEX(Monthly!$C$65:$BJ$65,($R$2-1)*12+11) -> 112632.74 | S46: =INDEX(Monthly!$C$65:$BJ$65,($R$2-1)*12+12) -> 112632.74
A47: Loan | B47: ='Balance Sheet'!B11 -> 163333.33 | C47: ='Balance Sheet'!C11 -> 123333.33 | D47: ='Balance Sheet'!D11 -> 83333.333 | E47: ='Balance Sheet'!E11 -> 43333.333 | F47: ='Balance Sheet'!F11 -> 3333.3333 | H47: =INDEX(Monthly!$C$60:$BJ$60,($R$2-1)*12+1) -> 200000 | I47: =INDEX(Monthly!$C$60:$BJ$60,($R$2-1)*12+2) -> 196666.67 | J47: =INDEX(Monthly!$C$60:$BJ$60,($R$2-1)*12+3) -> 193333.33 | K47: =INDEX(Monthly!$C$60:$BJ$60,($R$2-1)*12+4) -> 190000 | L47: =INDEX(Monthly!$C$60:$BJ$60,($R$2-1)*12+5) -> 186666.67 | M47: =INDEX(Monthly!$C$60:$BJ$60,($R$2-1)*12+6) -> 183333.33 | N47: =INDEX(Monthly!$C$60:$BJ$60,($R$2-1)*12+7) -> 180000 | O47: =INDEX(Monthly!$C$60:$BJ$60,($R$2-1)*12+8) -> 176666.67 | P47: =INDEX(Monthly!$C$60:$BJ$60,($R$2-1)*12+9) -> 173333.33 | Q47: =INDEX(Monthly!$C$60:$BJ$60,($R$2-1)*12+10) -> 170000 | R47: =INDEX(Monthly!$C$60:$BJ$60,($R$2-1)*12+11) -> 166666.67 | S47: =INDEX(Monthly!$C$60:$BJ$60,($R$2-1)*12+12) -> 163333.33
A48: Total liabilities | B48: ='Balance Sheet'!B12 -> 275966.07 | C48: ='Balance Sheet'!C12 -> 268751.29 | D48: ='Balance Sheet'!D12 -> 271376.93 | E48: ='Balance Sheet'!E12 -> 286878.29 | F48: ='Balance Sheet'!F12 -> 319248.7 | H48: =INDEX(Monthly!$C$92:$BJ$92,($R$2-1)*12+1) -> 312632.74 | I48: =INDEX(Monthly!$C$92:$BJ$92,($R$2-1)*12+2) -> 309299.41 | J48: =INDEX(Monthly!$C$92:$BJ$92,($R$2-1)*12+3) -> 305966.07 | K48: =INDEX(Monthly!$C$92:$BJ$92,($R$2-1)*12+4) -> 302632.74 | L48: =INDEX(Monthly!$C$92:$BJ$92,($R$2-1)*12+5) -> 299299.41 | M48: =INDEX(Monthly!$C$92:$BJ$92,($R$2-1)*12+6) -> 295966.07 | N48: =INDEX(Monthly!$C$92:$BJ$92,($R$2-1)*12+7) -> 292632.74 | O48: =INDEX(Monthly!$C$92:$BJ$92,($R$2-1)*12+8) -> 289299.41 | P48: =INDEX(Monthly!$C$92:$BJ$92,($R$2-1)*12+9) -> 285966.07 | Q48: =INDEX(Monthly!$C$92:$BJ$92,($R$2-1)*12+10) -> 282632.74 | R48: =INDEX(Monthly!$C$92:$BJ$92,($R$2-1)*12+11) -> 279299.41 | S48: =INDEX(Monthly!$C$92:$BJ$92,($R$2-1)*12+12) -> 275966.07
A49: Paid-in capital | B49: ='Balance Sheet'!B13 -> 300000 | C49: ='Balance Sheet'!C13 -> 300000 | D49: ='Balance Sheet'!D13 -> 300000 | E49: ='Balance Sheet'!E13 -> 300000 | F49: ='Balance Sheet'!F13 -> 300000 | H49: =INDEX(Monthly!$C$89:$BJ$89,($R$2-1)*12+1) -> 300000 | I49: =INDEX(Monthly!$C$89:$BJ$89,($R$2-1)*12+2) -> 300000 | J49: =INDEX(Monthly!$C$89:$BJ$89,($R$2-1)*12+3) -> 300000 | K49: =INDEX(Monthly!$C$89:$BJ$89,($R$2-1)*12+4) -> 300000 | L49: =INDEX(Monthly!$C$89:$BJ$89,($R$2-1)*12+5) -> 300000 | M49: =INDEX(Monthly!$C$89:$BJ$89,($R$2-1)*12+6) -> 300000 | N49: =INDEX(Monthly!$C$89:$BJ$89,($R$2-1)*12+7) -> 300000 | O49: =INDEX(Monthly!$C$89:$BJ$89,($R$2-1)*12+8) -> 300000 | P49: =INDEX(Monthly!$C$89:$BJ$89,($R$2-1)*12+9) -> 300000 | Q49: =INDEX(Monthly!$C$89:$BJ$89,($R$2-1)*12+10) -> 300000 | R49: =INDEX(Monthly!$C$89:$BJ$89,($R$2-1)*12+11) -> 300000 | S49: =INDEX(Monthly!$C$89:$BJ$89,($R$2-1)*12+12) -> 300000
A50: Retained earnings | B50: ='Balance Sheet'!B14 -> 808921.04 | C50: ='Balance Sheet'!C14 -> 1967177.4 | D50: ='Balance Sheet'!D14 -> 3589546.5 | E50: ='Balance Sheet'!E14 -> 5828762.5 | F50: ='Balance Sheet'!F14 -> 8888124.1 | H50: =INDEX(Monthly!$C$90:$BJ$90,($R$2-1)*12+1) -> 67321.577 | I50: =INDEX(Monthly!$C$90:$BJ$90,($R$2-1)*12+2) -> 134651.93 | J50: =INDEX(Monthly!$C$90:$BJ$90,($R$2-1)*12+3) -> 201999.84 | K50: =INDEX(Monthly!$C$90:$BJ$90,($R$2-1)*12+4) -> 269365.31 | L50: =INDEX(Monthly!$C$90:$BJ$90,($R$2-1)*12+5) -> 336748.33 | M50: =INDEX(Monthly!$C$90:$BJ$90,($R$2-1)*12+6) -> 404148.91 | N50: =INDEX(Monthly!$C$90:$BJ$90,($R$2-1)*12+7) -> 471567.04 | O50: =INDEX(Monthly!$C$90:$BJ$90,($R$2-1)*12+8) -> 539002.73 | P50: =INDEX(Monthly!$C$90:$BJ$90,($R$2-1)*12+9) -> 606455.97 | Q50: =INDEX(Monthly!$C$90:$BJ$90,($R$2-1)*12+10) -> 673926.77 | R50: =INDEX(Monthly!$C$90:$BJ$90,($R$2-1)*12+11) -> 741415.13 | S50: =INDEX(Monthly!$C$90:$BJ$90,($R$2-1)*12+12) -> 808921.04
...

Sheet Scenarios
A1: Scenarios — Low / Base / High | H1: =HYPERLINK("#'Cover'!A1","◂ Contents") -> ◂ Contents
A2: All three scenarios calculated side by side, live: change any input and every column updates. Active = the scenario chosen on the Dashboard.
A5: Key drivers
A6: Driver | B6: Low | C6: Base | D6: High | E6: Active
A7: Hourly rate — partners & senior consultants ($ / hour) | B7: =Inputs!$B$14 -> 300 | C7: =Inputs!$C$14 -> 350 | D7: =Inputs!$D$14 -> 400 | E7: =Inputs!$E$14 -> 350
A8: Hourly rate — consultants ($ / hour) | B8: =Inputs!$B$15 -> 150 | C8: =Inputs!$C$15 -> 175 | D8: =Inputs!$D$15 -> 200 | E8: =Inputs!$E$15 -> 175
A9: Utilisation — consultants (%) | B9: =Inputs!$B$9 -> 0.68 | C9: =Inputs!$C$9 -> 0.75 | D9: =Inputs!$D$9 -> 0.8 | E9: =Inputs!$E$9 -> 0.75
A10: Contractor billable hours per month (year 1) (hours) | B10: =Inputs!$B$10 -> 300 | C10: =Inputs!$C$10 -> 400 | D10: =Inputs!$D$10 -> 500 | E10: =Inputs!$E$10 -> 400
A11: Customer payment terms (receivable days) (days) | B11: =Inputs!$B$60 -> 45 | C11: =Inputs!$C$60 -> 45 | D11: =Inputs!$D$60 -> 45 | E11: =Inputs!$E$60 -> 45
A12: Equity raised at start ($) | B12: =Inputs!$B$54 -> 300000 | C12: =Inputs!$C$54 -> 300000 | D12: =Inputs!$D$54 -> 300000 | E12: =Inputs!$E$54 -> 300000
A14: Results by scenario ($'000)
A15: Output | B15: Low | C15: Base | D15: High | E15: Active
A16: Revenue — final year | B16: =F29 -> 8830004.7 | C16: =F30 -> 12793894 | D16: =F31 -> 17866027 | E16: ='P&L'!F5 -> 12793894
A17: Revenue — whole plan | B17: =SUM(B29:F29) -> 28675279 | C17: =SUM(B30:F30) -> 40539671 | D17: =SUM(B31:F31) -> 54922754 | E17: =SUM('P&L'!$B$5:$F$5) -> 40539671
A18: EBITDA — final year | B18: =F35 -> 397861.74 | C18: =F36 -> 3886476.3 | D18: =F37 -> 8264572 | E18: ='P&L'!F15 -> 3886476.3
A19: EBITDA margin — final year | B19: =IF(B16=0,0,B18/B16) -> 0.045057931 | C19: =IF(C16=0,0,C18/C16) -> 0.30377587 | D19: =IF(D16=0,0,D18/D16) -> 0.4625859 | E19: =IF(E16=0,0,E18/E16) -> 0.30377587
A20: Net income — final year | B20: =F41 -> 303356.11 | C20: =F42 -> 3059361.6 | D20: =F43 -> 6518057.2 | E20: ='P&L'!F22 -> 3059361.6
A21: Net income — whole plan | B21: =SUM(B41:F41) -> 533999.64 | C21: =SUM(B42:F42) -> 8888124.1 | D21: =SUM(B43:F43) -> 18925064 | E21: =SUM('P&L'!$B$22:$F$22) -> 8888124.1
A22: Cash at the end of the plan | B22: =F47 -> 29694.634 | C22: =F48 -> 7908136 | D22: =F49 -> 17339977 | E22: ='Balance Sheet'!F5 -> 7908136
A23: Lowest cash balance | B23: =MIN('Scenario calc'!$C$79:$BJ$79) -> -222811.69 | C23: =MIN('Scenario calc'!$C$189:$BJ$189) -> 57680.317 | D23: =MIN('Scenario calc'!$C$299:$BJ$299) -> -20466.901 | E23: ='Break-even'!B18 -> 57680.317
A24: Lowest cash point (month #) | B24: =MATCH(MIN('Scenario calc'!$C$79:$BJ$79),'Scenario calc'!$C$79:$BJ$79,0) -> 49 | C24: =MATCH(MIN('Scenario calc'!$C$189:$BJ$189),'Scenario calc'!$C$189:$BJ$189,0) -> 1 | D24: =MATCH(MIN('Scenario calc'!$C$299:$BJ$299),'Scenario calc'!$C$299:$BJ$299,0) -> 1 | E24: ='Break-even'!B6 -> 1
A25: Funding required (incl. cash buffer) | B25: =SUMPRODUCT(--('Scenario calc'!$C$6:$BJ$6<=B24),'Scenario calc'!$C$52:$BJ$52)-SUMPRODUCT(--('Scenario calc'!$C$6:$BJ$6<=B24),'Scenario calc'!$C$73:$BJ$73)-SUMPRODUCT(--('Scenario calc'!$C$6:$BJ$6<=B24),'Scenario calc'!$C$61:$BJ$61)+Inputs!$B$69 -> 910811.69 | C25: =SUMPRODUCT(--('Scenario calc'!$C$116:$BJ$116<=C24),'Scenario calc'!$C$162:$BJ$162)-SUMPRODUCT(--('Scenario calc'!$C$116:$BJ$116<=C24),'Scenario calc'!$C$183:$BJ$183)-SUMPRODUCT(--('Scenario calc'!$C$116:$BJ$116<=C24),'Scenario calc'!$C$171:$BJ$171)+Inputs!$C$69 -> 630319.68 | D25: =SUMPRODUCT(--('Scenario calc'!$C$226:$BJ$226<=D24),'Scenario calc'!$C$272:$BJ$272)-SUMPRODUCT(--('Scenario calc'!$C$226:$BJ$226<=D24),'Scenario calc'!$C$293:$BJ$293)-SUMPRODUCT(--('Scenario calc'!$C$226:$BJ$226<=D24),'Scenario calc'!$C$281:$BJ$281)+Inputs!$D$69 -> 708466.9 | E25: ='Break-even'!B12 -> 630319.68
A27: Revenue by year ($'000)
A28: Scenario | B28: 1 | C28: 2 | D28: 3 | E28: 4 | F28: 5
A29: Low | B29: =SUMIF('Scenario calc'!$C$7:$BJ$7,B$28,'Scenario calc'!$C$24:$BJ$24) -> 3332736 | C29: =SUMIF('Scenario calc'!$C$7:$BJ$7,C$28,'Scenario calc'!$C$24:$BJ$24) -> 4231789.1 | D29: =SUMIF('Scenario calc'!$C$7:$BJ$7,D$28,'Scenario calc'!$C$24:$BJ$24) -> 5391180.3 | E29: =SUMIF('Scenario calc'!$C$7:$BJ$7,E$28,'Scenario calc'!$C$24:$BJ$24) -> 6889569.3 | F29: =SUMIF('Scenario calc'!$C$7:$BJ$7,F$28,'Scenario calc'!$C$24:$BJ$24) -> 8830004.7
A30: Base | B30: =SUMIF('Scenario calc'!$C$117:$BJ$117,B$28,'Scenario calc'!$C$134:$BJ$134) -> 4506192 | C30: =SUMIF('Scenario calc'!$C$117:$BJ$117,C$28,'Scenario calc'!$C$134:$BJ$134) -> 5835961.9 | D30: =SUMIF('Scenario calc'!$C$117:$BJ$117,D$28,'Scenario calc'!$C$134:$BJ$134) -> 7569836 | E30: =SUMIF('Scenario calc'!$C$117:$BJ$117,E$28,'Scenario calc'!$C$134:$BJ$134) -> 9833787.5 | F30: =SUMIF('Scenario calc'!$C$117:$BJ$117,F$28,'Scenario calc'!$C$134:$BJ$134) -> 12793894
A31: High | B31: =SUMIF('Scenario calc'!$C$227:$BJ$227,B$28,'Scenario calc'!$C$244:$BJ$244) -> 5791212 | C31: =SUMIF('Scenario calc'!$C$227:$BJ$227,C$28,'Scenario calc'!$C$244:$BJ$244) -> 7661148.8 | D31: =SUMIF('Scenario calc'!$C$227:$BJ$227,D$28,'Scenario calc'!$C$244:$BJ$244) -> 10147498 | E31: =SUMIF('Scenario calc'!$C$227:$BJ$227,E$28,'Scenario calc'!$C$244:$BJ$244) -> 13456869 | F31: =SUMIF('Scenario calc'!$C$227:$BJ$227,F$28,'Scenario calc'!$C$244:$BJ$244) -> 17866027
A33: EBITDA by year ($'000)
A34: Scenario | B34: 1 | C34: 2 | D34: 3 | E34: 4 | F34: 5
A35: Low | B35: =SUMIF('Scenario calc'!$C$7:$BJ$7,B$34,'Scenario calc'!$C$40:$BJ$40) -> -30973.44 | C35: =SUMIF('Scenario calc'!$C$7:$BJ$7,C$34,'Scenario calc'!$C$40:$BJ$40) -> 37714.494 | D35: =SUMIF('Scenario calc'!$C$7:$BJ$7,D$34,'Scenario calc'!$C$40:$BJ$40) -> 127633.63 | E35: =SUMIF('Scenario calc'!$C$7:$BJ$7,E$34,'Scenario calc'!$C$40:$BJ$40) -> 245034.7 | F35: =SUMIF('Scenario calc'!$C$7:$BJ$7,F$34,'Scenario calc'!$C$40:$BJ$40) -> 397861.74
A36: Base | B36: =SUMIF('Scenario calc'!$C$117:$BJ$117,B$34,'Scenario calc'!$C$150:$BJ$150) -> 1050606.2 | C36: =SUMIF('Scenario calc'!$C$117:$BJ$117,C$34,'Scenario calc'!$C$150:$BJ$150) -> 1489614 | D36: =SUMIF('Scenario calc'!$C$117:$BJ$117,D$34,'Scenario calc'!$C$150:$BJ$150) -> 2073898.4 | E36: =SUMIF('Scenario calc'!$C$117:$BJ$117,E$34,'Scenario calc'!$C$150:$BJ$150) -> 2851517.2 | F36: =SUMIF('Scenario calc'!$C$117:$BJ$117,F$34,'Scenario calc'!$C$150:$BJ$150) -> 3886476.3
A37: High | B37: =SUMIF('Scenario calc'!$C$227:$BJ$227,B$34,'Scenario calc'!$C$260:$BJ$260) -> 2248031.7 | C37: =SUMIF('Scenario calc'!$C$227:$BJ$227,C$34,'Scenario calc'!$C$260:$BJ$260) -> 3149413 | D37: =SUMIF('Scenario calc'!$C$227:$BJ$227,D$34,'Scenario calc'!$C$260:$BJ$260) -> 4370542.9 | E37: =SUMIF('Scenario calc'!$C$227:$BJ$227,E$34,'Scenario calc'!$C$260:$BJ$260) -> 6024539.1 | F37: =SUMIF('Scenario calc'!$C$227:$BJ$227,F$34,'Scenario calc'!$C$260:$BJ$260) -> 8264572
A39: Net income by year ($'000)
A40: Scenario | B40: 1 | C40: 2 | D40: 3 | E40: 4 | F40: 5
A41: Low | B41: =SUMIF('Scenario calc'!$C$7:$BJ$7,B$40,'Scenario calc'!$C$49:$BJ$49) -> -57628.996 | C41: =SUMIF('Scenario calc'!$C$7:$BJ$7,C$40,'Scenario calc'!$C$49:$BJ$49) -> 14247.827 | D41: =SUMIF('Scenario calc'!$C$7:$BJ$7,D$40,'Scenario calc'!$C$49:$BJ$49) -> 93929.949 | E41: =SUMIF('Scenario calc'!$C$7:$BJ$7,E$40,'Scenario calc'!$C$49:$BJ$49) -> 180094.75 | F41: =SUMIF('Scenario calc'!$C$7:$BJ$7,F$40,'Scenario calc'!$C$49:$BJ$49) -> 303356.11
A42: Base | B42: =SUMIF('Scenario calc'!$C$117:$BJ$117,B$40,'Scenario calc'!$C$159:$BJ$159) -> 808921.04 | C42: =SUMIF('Scenario calc'!$C$117:$BJ$117,C$40,'Scenario calc'!$C$159:$BJ$159) -> 1158256.4 | D42: =SUMIF('Scenario calc'!$C$117:$BJ$117,D$40,'Scenario calc'!$C$159:$BJ$159) -> 1622369.1 | E42: =SUMIF('Scenario calc'!$C$117:$BJ$117,E$40,'Scenario calc'!$C$159:$BJ$159) -> 2239215.9 | F42: =SUMIF('Scenario calc'!$C$117:$BJ$117,F$40,'Scenario calc'!$C$159:$BJ$159) -> 3059361.6
A43: High | B43: =SUMIF('Scenario calc'!$C$227:$BJ$227,B$40,'Scenario calc'!$C$269:$BJ$269) -> 1754887.2 | C43: =SUMIF('Scenario calc'!$C$227:$BJ$227,C$40,'Scenario calc'!$C$269:$BJ$269) -> 2469497.6 | D43: =SUMIF('Scenario calc'!$C$227:$BJ$227,D$40,'Scenario calc'!$C$269:$BJ$269) -> 3436718.3 | E43: =SUMIF('Scenario calc'!$C$227:$BJ$227,E$40,'Scenario calc'!$C$269:$BJ$269) -> 4745903.2 | F43: =SUMIF('Scenario calc'!$C$227:$BJ$227,F$40,'Scenario calc'!$C$269:$BJ$269) -> 6518057.2
A45: Cash at year end by year ($'000)
A46: Scenario | B46: 1 | C46: 2 | D46: 3 | E46: 4 | F46: 5
A47: Low | B47: =INDEX('Scenario calc'!$C$79:$BJ$79,B$46*12) -> 49916.898 | C47: =INDEX('Scenario calc'!$C$79:$BJ$79,C$46*12) -> -45948.235 | D47: =INDEX('Scenario calc'!$C$79:$BJ$79,D$46*12) -> -85654.791 | E47: =INDEX('Scenario calc'!$C$79:$BJ$79,E$46*12) -> -69746.669 | F47: =INDEX('Scenario calc'!$C$79:$BJ$79,F$46*12) -> 29694.634
...

Sheet Break-even
A1: Startup costs, funding need and break-even | H1: =HYPERLINK("#'Cover'!A1","◂ Contents") -> ◂ Contents
A2: Live for the selected scenario. Periods are counted in months from the start of the plan.
A3: Scenario shown | B3: =CHOOSE(Dashboard!$B$4,"Low","Base","High") -> Base
A5: Startup costs & funding need (up to the lowest cash point)
A6: Lowest cash point (month #) | B6: =MATCH(MIN(Monthly!$C$77:$BJ$77),Monthly!$C$77:$BJ$77,0) -> 1
A7: Capital spending up to the lowest cash point | B7: =SUMPRODUCT(--(Monthly!$C$4:$BJ$4<=$B$6),Monthly!$C$50:$BJ$50) -> 60000
A8: Operating cash burn up to the lowest cash point | B8: =-SUMPRODUCT(--(Monthly!$C$4:$BJ$4<=$B$6),Monthly!$C$71:$BJ$71) -> 382319.68 | D8: Losses and working capital before the business funds itself
A9: Loan repayments up to the lowest cash point | B9: =-SUMPRODUCT(--(Monthly!$C$4:$BJ$4<=$B$6),Monthly!$C$59:$BJ$59) -> 0
A10: Total uses of funds | B10: =B7+B8+B9 -> 442319.68
A11: Minimum cash buffer to keep | B11: =Inputs!$E$69 -> 188000 | D11: Input on the Inputs sheet
A12: Funding required (uses + buffer) | B12: =B10+B11 -> 630319.68
A14: Equity raised | B14: =Inputs!$E$54 -> 300000
A15: Loan drawn | B15: =Inputs!$E$55 -> 200000
A16: Total sources of funds | B16: =B14+B15 -> 500000
A17: Funding surplus / (shortfall) | B17: =B16-B12 -> -130319.68 | D17: Negative = raise at least this much more
A18: Lowest cash balance in the plan | B18: =MIN(Monthly!$C$77:$BJ$77) -> 57680.317 | D18: Equals sources minus uses
A20: Break-even timing
A21: First month with positive EBITDA (month #) | B21: =IFERROR(MATCH(1,Monthly!$C$78:$BJ$78,0),"Not within horizon") -> 1
A22: First month with positive net income (month #) | B22: =IFERROR(MATCH(1,Monthly!$C$81:$BJ$81,0),"Not within horizon") -> 1
A23: Cash invested paid back (month #) | B23: =IF(MIN(Monthly!$C$83:$BJ$83)>=0,"No investment to pay back",IFERROR(MATCH(1,Monthly!$C$85:$BJ$85,0),"Not within horizon")) -> 8 | D23: Cumulative operating + investing cash flow back to zero
A25: Annual break-even revenue
A26: Year # | B26: 1 | C26: 2 | D26: 3 | E26: 4 | F26: 5
B27: Year 1 | C27: Year 2 | D27: Year 3 | E27: Year 4 | F27: Year 5
A28: Revenue | B28: =SUMIF(Monthly!$C$5:$BJ$5,B$26,Monthly!$C$22:$BJ$22) -> 4506192 | C28: =SUMIF(Monthly!$C$5:$BJ$5,C$26,Monthly!$C$22:$BJ$22) -> 5835961.9 | D28: =SUMIF(Monthly!$C$5:$BJ$5,D$26,Monthly!$C$22:$BJ$22) -> 7569836 | E28: =SUMIF(Monthly!$C$5:$BJ$5,E$26,Monthly!$C$22:$BJ$22) -> 9833787.5 | F28: =SUMIF(Monthly!$C$5:$BJ$5,F$26,Monthly!$C$22:$BJ$22) -> 12793894
A29: Gross profit | B29: =SUMIF(Monthly!$C$5:$BJ$5,B$26,Monthly!$C$29:$BJ$29) -> 1803006.2 | C29: =SUMIF(Monthly!$C$5:$BJ$5,C$26,Monthly!$C$29:$BJ$29) -> 2345931 | D29: =SUMIF(Monthly!$C$5:$BJ$5,D$26,Monthly!$C$29:$BJ$29) -> 3056789.8 | E29: =SUMIF(Monthly!$C$5:$BJ$5,E$26,Monthly!$C$29:$BJ$29) -> 3988708.6 | F29: =SUMIF(Monthly!$C$5:$BJ$5,F$26,Monthly!$C$29:$BJ$29) -> 5211925.2
A30: Gross margin (contribution) | B30: =IF(B28=0,0,B29/B28) -> 0.40011749 | C30: =IF(C28=0,0,C29/C28) -> 0.40197847 | D30: =IF(D28=0,0,D29/D28) -> 0.40381189 | E30: =IF(E28=0,0,E29/E28) -> 0.40561265 | F30: =IF(F28=0,0,F29/F28) -> 0.40737599
A31: Operating expenses (treated as fixed) | B31: =-SUMIF(Monthly!$C$5:$BJ$5,B$26,Monthly!$C$37:$BJ$37) -> 752400 | C31: =-SUMIF(Monthly!$C$5:$BJ$5,C$26,Monthly!$C$37:$BJ$37) -> 856317 | D31: =-SUMIF(Monthly!$C$5:$BJ$5,D$26,Monthly!$C$37:$BJ$37) -> 982891.4 | E31: =-SUMIF(Monthly!$C$5:$BJ$5,E$26,Monthly!$C$37:$BJ$37) -> 1137191.4 | F31: =-SUMIF(Monthly!$C$5:$BJ$5,F$26,Monthly!$C$37:$BJ$37) -> 1325448.9
A32: Break-even revenue (EBITDA = 0) | B32: =IF(B30>0,B31/B30,"n/a") -> 1880447.7 | C32: =IF(C30>0,C31/C30,"n/a") -> 2130255.9 | D32: =IF(D30>0,D31/D30,"n/a") -> 2434032.8 | E32: =IF(E30>0,E31/E30,"n/a") -> 2803638.8 | F32: =IF(F30>0,F31/F30,"n/a") -> 3253625.6
A33: Margin of safety (revenue above break-even) | B33: =IF(AND(ISNUMBER(B32),B28>0),(B28-B32)/B28,"n/a") -> 0.58269695 | C33: =IF(AND(ISNUMBER(C32),C28>0),(C28-C32)/C28,"n/a") -> 0.63497776 | D33: =IF(AND(ISNUMBER(D32),D28>0),(D28-D32)/D28,"n/a") -> 0.67845634 | E33: =IF(AND(ISNUMBER(E32),E28>0),(E28-E32)/E28,"n/a") -> 0.71489736 | F33: =IF(AND(ISNUMBER(F32),F28>0),(F28-F32)/F28,"n/a") -> 0.74568919
A35: Simplification: cost of sales is treated as variable and operating expenses as fixed, so break-even revenue = operating expenses ÷ gross margin.

Sheet Valuation
A1: Discounted cash flow valuation | H1: =HYPERLINK("#'Cover'!A1","◂ Contents") -> ◂ Contents
A2: Enterprise value at the start of the plan, before the funding raised in period 1. Year-end discounting.
A3: Scenario shown | B3: =CHOOSE(Dashboard!$B$4,"Low","Base","High") -> Base
A5: Assumptions (active scenario, from the Inputs sheet)
A6: Discount rate (WACC) | B6: =Inputs!$E$72 -> 0.16
A7: Terminal growth rate | B7: =Inputs!$E$73 -> 0.02
A8: Exit multiple (EV ÷ final-year EBITDA) | B8: =Inputs!$E$74 -> 5.5
A9: Tax rate (for the interest tax shield) | B9: =Inputs!$E$66 -> 0.21
A10: Sensitivity step: WACC | B10: =Inputs!$E$75 -> 0.01
A11: Sensitivity step: terminal growth | B11: =Inputs!$E$76 -> 0.005
A13: Free cash flow by year
A14: Year # | B14: 1 | C14: 2 | D14: 3 | E14: 4 | F14: 5
B15: Year 1 | C15: Year 2 | D15: Year 3 | E15: Year 4 | F15: Year 5
A16: EBITDA | B16: =SUMIF(Monthly!$C$5:$BJ$5,B$14,Monthly!$C$38:$BJ$38) -> 1050606.2 | C16: =SUMIF(Monthly!$C$5:$BJ$5,C$14,Monthly!$C$38:$BJ$38) -> 1489614 | D16: =SUMIF(Monthly!$C$5:$BJ$5,D$14,Monthly!$C$38:$BJ$38) -> 2073898.4 | E16: =SUMIF(Monthly!$C$5:$BJ$5,E$14,Monthly!$C$38:$BJ$38) -> 2851517.2 | F16: =SUMIF(Monthly!$C$5:$BJ$5,F$14,Monthly!$C$38:$BJ$38) -> 3886476.3
A17: Unlevered free cash flow | B17: =SUMIF(Monthly!$C$5:$BJ$5,B$14,Monthly!$C$86:$BJ$86) -> 321857.67 | C17: =SUMIF(Monthly!$C$5:$BJ$5,C$14,Monthly!$C$86:$BJ$86) -> 1045879.1 | D17: =SUMIF(Monthly!$C$5:$BJ$5,D$14,Monthly!$C$86:$BJ$86) -> 1466791.1 | E17: =SUMIF(Monthly!$C$5:$BJ$5,E$14,Monthly!$C$86:$BJ$86) -> 2027726 | F17: =SUMIF(Monthly!$C$5:$BJ$5,F$14,Monthly!$C$86:$BJ$86) -> 2775193.4
A18: Discount factor | B18: =1/(1+Inputs!$E$72)^B$14 -> 0.86206897 | C18: =1/(1+Inputs!$E$72)^C$14 -> 0.7431629 | D18: =1/(1+Inputs!$E$72)^D$14 -> 0.64065767 | E18: =1/(1+Inputs!$E$72)^E$14 -> 0.5522911 | F18: =1/(1+Inputs!$E$72)^F$14 -> 0.47611302
A19: Present value of free cash flow | B19: =B17*B18 -> 277463.51 | C19: =C17*C18 -> 777258.51 | D19: =D17*D18 -> 939710.99 | E19: =E17*E18 -> 1119895 | F19: =F17*F18 -> 1321305.7
A21: Enterprise value
B22: Perpetual growth | C22: Exit multiple
A23: Present value of the plan's free cash flows | B23: =SUM($B$19:$F$19) -> 4435633.7 | C23: =B23 -> 4435633.7
A24: Final-year free cash flow | final-year EBITDA | B24: =$F$17 -> 2775193.4 | C24: =$F$16 -> 3886476.3
A25: Terminal value at the end of year 5 | B25: =IF($B$6>$B$7,B24*(1+$B$7)/($B$6-$B$7),0) -> 20219266 | C25: =C24*$B$8 -> 21375620
A26: Present value of the terminal value | B26: =B25/(1+$B$6)^$F$14 -> 9626655.7 | C26: =C25/(1+$B$6)^$F$14 -> 10177211
A27: Enterprise value | B27: =B23+B26 -> 14062289 | C27: =C23+C26 -> 14612844
A28: Terminal value share of enterprise value | B28: =IF(B27<>0,B26/B27,0) -> 0.68457243 | C28: =IF(C27<>0,C26/C27,0) -> 0.69645651
A29: Cross-check: implied exit multiple | implied perpetual growth | B29: =IF(C24>0,B25/C24,"n/a") -> 5.2024673 | C29: =IF(C25+B24<>0,(C25*$B$6-B24)/(C25+B24),"n/a") -> 0.026703274
A30: Enterprise value — average of the two methods | B30: =AVERAGE(B27,C27) -> 14337567
A32: Sensitivity: enterprise value (perpetual growth) by WACC and terminal growth
A33: WACC ↓ · terminal growth → | B33: =$B$7+(-2)*$B$11 -> 0.01 | C33: =$B$7+(-1)*$B$11 -> 0.015 | D33: =$B$7+(0)*$B$11 -> 0.02 | E33: =$B$7+(1)*$B$11 -> 0.025 | F33: =$B$7+(2)*$B$11 -> 0.03
A34: =$B$6+(-2)*$B$10 -> 0.14 | B34: =IF($A34>B$33,SUMPRODUCT($B$17:$F$17/(1+$A34)^$B$14:$F$14)+$F$17*(1+B$33)/($A34-B$33)/(1+$A34)^$F$14,"n/a") -> 15917237 | C34: =IF($A34>C$33,SUMPRODUCT($B$17:$F$17/(1+$A34)^$B$14:$F$14)+$F$17*(1+C$33)/($A34-C$33)/(1+$A34)^$F$14,"n/a") -> 16422818 | D34: =IF($A34>D$33,SUMPRODUCT($B$17:$F$17/(1+$A34)^$B$14:$F$14)+$F$17*(1+D$33)/($A34-D$33)/(1+$A34)^$F$14,"n/a") -> 16970531 | E34: =IF($A34>E$33,SUMPRODUCT($B$17:$F$17/(1+$A34)^$B$14:$F$14)+$F$17*(1+E$33)/($A34-E$33)/(1+$A34)^$F$14,"n/a") -> 17565870 | F34: =IF($A34>F$33,SUMPRODUCT($B$17:$F$17/(1+$A34)^$B$14:$F$14)+$F$17*(1+F$33)/($A34-F$33)/(1+$A34)^$F$14,"n/a") -> 18215332
A35: =$B$6+(-1)*$B$10 -> 0.15 | B35: =IF($A35>B$33,SUMPRODUCT($B$17:$F$17/(1+$A35)^$B$14:$F$14)+$F$17*(1+B$33)/($A35-B$33)/(1+$A35)^$F$14,"n/a") -> 14528265 | C35: =IF($A35>C$33,SUMPRODUCT($B$17:$F$17/(1+$A35)^$B$14:$F$14)+$F$17*(1+C$33)/($A35-C$33)/(1+$A35)^$F$14,"n/a") -> 14948034 | D35: =IF($A35>D$33,SUMPRODUCT($B$17:$F$17/(1+$A35)^$B$14:$F$14)+$F$17*(1+D$33)/($A35-D$33)/(1+$A35)^$F$14,"n/a") -> 15400092 | E35: =IF($A35>E$33,SUMPRODUCT($B$17:$F$17/(1+$A35)^$B$14:$F$14)+$F$17*(1+E$33)/($A35-E$33)/(1+$A35)^$F$14,"n/a") -> 15888316 | F35: =IF($A35>F$33,SUMPRODUCT($B$17:$F$17/(1+$A35)^$B$14:$F$14)+$F$17*(1+F$33)/($A35-F$33)/(1+$A35)^$F$14,"n/a") -> 16417224
A36: =$B$6+(0)*$B$10 -> 0.16 | B36: =IF($A36>B$33,SUMPRODUCT($B$17:$F$17/(1+$A36)^$B$14:$F$14)+$F$17*(1+B$33)/($A36-B$33)/(1+$A36)^$F$14,"n/a") -> 13332425 | C36: =IF($A36>C$33,SUMPRODUCT($B$17:$F$17/(1+$A36)^$B$14:$F$14)+$F$17*(1+C$33)/($A36-C$33)/(1+$A36)^$F$14,"n/a") -> 13684774 | D36: =IF($A36>D$33,SUMPRODUCT($B$17:$F$17/(1+$A36)^$B$14:$F$14)+$F$17*(1+D$33)/($A36-D$33)/(1+$A36)^$F$14,"n/a") -> 14062289 | E36: =IF($A36>E$33,SUMPRODUCT($B$17:$F$17/(1+$A36)^$B$14:$F$14)+$F$17*(1+E$33)/($A36-E$33)/(1+$A36)^$F$14,"n/a") -> 14467769 | F36: =IF($A36>F$33,SUMPRODUCT($B$17:$F$17/(1+$A36)^$B$14:$F$14)+$F$17*(1+F$33)/($A36-F$33)/(1+$A36)^$F$14,"n/a") -> 14904440
